# Converted from schematic
# THIS TEMPLATE USES DEFAULTS!  Please edit for corrections.
# If you need help, consult template_rules.txt
biomesToSpawnIn=desert,desert oil field,deserthills,dunes,lush desert,mountainous desert
weight=2
embed_into_distance=1
acceptable_target_blocks=1,2,3,12,13
dimensions=6,7,9
allowable_overhang=0
max_cut_in=2
cut_in_buffer=1
max_leveling=2
leveling_buffer=1
preserve_water=0
preserve_lava=0
preserve_plants=0


rule1=0,100,12
rule2=0,100,24
rule3=0,100,44-1
rule4=0,100,43-1
rule5=0,100,64-3
rule6=0,100,64-1
rule7=0,100,64-11
rule8=0,100,64-9
rule9=0,100,50-2
rule10=0,100,50-3
rule11=0,100,50-1
rule12=0,100,50-4


layer
1,1,1,1,1,1,1,1,1
1,1,1,1,1,1,1,1,1
1,1,2,2,1,2,2,1,1
2,2,2,2,1,2,2,2,2
1,1,2,2,1,2,2,2,2
1,1,1,1,1,1,1,1,1
1,1,1,1,1,1,1,1,1
endlayer

layer
3,2,3,2,3,2,3,2,3
3,2,2,2,2,2,2,2,3
2,2,3,3,2,3,3,2,4
0,6,0,0,2,0,0,5,0
2,2,3,3,2,3,3,2,4
3,2,4,2,2,2,2,2,3
3,2,3,2,3,2,3,2,3
endlayer

layer
0,2,0,2,0,2,0,2,0
0,2,2,2,2,2,2,2,0
2,2,3,3,2,3,3,2,2
0,8,0,0,2,0,0,7,0
2,2,3,3,2,3,3,2,2
0,2,2,2,2,2,2,2,0
0,2,0,2,0,2,0,2,0
endlayer

layer
0,2,9,2,9,2,9,2,0
0,2,2,2,2,2,2,2,0
3,2,3,3,2,3,3,2,3
3,2,12,0,2,0,10,2,3
3,2,3,3,2,3,3,2,3
0,2,2,2,2,2,2,2,0
0,2,11,2,11,2,11,2,0
endlayer

layer
3,2,2,2,2,2,2,2,3
3,4,4,2,2,2,4,4,3
3,4,2,2,2,2,2,4,3
3,4,2,2,2,2,2,4,3
3,4,2,2,2,2,2,4,3
3,4,4,2,2,2,4,4,3
3,2,2,2,2,2,2,2,3
endlayer

layer
0,0,3,2,2,2,3,0,0
0,0,3,4,4,4,3,0,0
0,0,3,4,4,4,3,0,0
0,0,3,4,4,4,3,0,0
0,0,3,4,4,4,3,0,0
0,0,3,4,4,4,3,0,0
0,0,3,2,2,2,3,0,0
endlayer

