# Author: Arrrg
# From: Minecraft Forums

weight=2
embed_into_distance=8
acceptable_target_blocks=1,2,3,12,13,78
dimensions=14,12,12
allowable_overhang=300
unique=0
max_cut_in=0
cut_in_buffer=0
max_leveling=0
leveling_buffer=0
preserve_water=0
preserve_lava=0
preserve_plants=0

rule1=0,100,preserveBlock
rule2=0,100,89
rule3=0,100,80
rule4=0,100,4
rule5=0,100,78
rule6=0,100,79
rule7=0,100,20
rule8=0,100,8
rule9=0,100,HardMobSpawn,42,84
rule10=0,100,MobSpawner:Skeleton





layer
1,1,1,1,1,1,1,1,1,1,1,1
1,1,1,1,1,1,1,1,1,1,1,1
1,1,1,1,1,1,1,1,1,1,1,1
1,1,1,1,1,1,1,1,1,1,1,1
1,1,1,1,1,1,1,1,1,1,1,1
1,1,1,1,1,1,1,1,1,1,1,1
1,1,1,1,1,1,1,1,1,1,1,1
1,1,1,1,1,1,1,1,1,1,1,1
1,1,1,1,1,1,1,1,1,1,1,1
1,1,1,1,1,1,1,1,1,1,1,1
1,1,1,1,1,1,1,1,1,1,1,1
1,1,1,1,1,1,1,1,1,1,1,1
endlayer

layer
1,1,1,1,1,1,1,1,1,1,1,1
1,1,1,0,0,0,0,0,1,1,1,1
1,1,0,0,0,0,0,0,0,1,1,1
1,0,0,0,0,0,0,0,0,0,1,1
1,0,0,0,0,0,0,0,0,0,1,1
1,0,0,0,0,10,0,0,0,0,1,1
1,0,0,0,0,0,0,0,0,0,1,1
1,0,0,0,0,0,0,0,0,0,1,1
1,1,0,0,0,0,0,0,0,1,1,1
1,1,1,0,0,0,0,0,1,1,1,1
1,1,1,1,1,1,1,1,1,1,1,1
1,1,1,1,1,1,1,1,1,1,1,1
endlayer

layer
1,1,1,1,1,1,1,1,1,1,1,1
1,1,1,0,0,0,0,0,1,1,1,1
1,1,0,0,0,0,0,0,0,1,1,1
1,0,0,0,0,0,0,0,0,0,1,1
1,0,0,0,0,0,0,0,0,0,1,1
1,0,0,0,0,0,0,0,0,0,1,1
1,0,0,0,0,0,0,0,0,0,1,1
1,0,0,0,0,0,0,0,0,0,1,1
1,1,0,0,0,0,0,0,0,1,1,1
1,1,1,0,0,0,0,0,1,1,1,1
1,1,1,1,1,1,1,1,1,1,1,1
1,1,1,1,1,1,1,1,1,1,1,1
endlayer

layer
1,1,1,1,1,1,1,1,1,1,1,1
1,1,1,0,0,0,0,0,1,1,1,1
1,1,0,0,0,0,0,0,0,1,1,1
1,0,0,0,0,0,0,0,0,0,1,1
1,0,0,0,0,0,0,0,0,0,1,1
1,0,0,0,0,0,0,0,0,0,1,1
1,0,0,0,0,0,0,0,0,0,1,1
1,0,0,0,0,0,0,0,0,0,1,1
1,1,0,0,0,0,0,0,0,1,1,1
1,1,1,0,0,0,0,0,1,1,1,1
1,1,1,1,1,1,1,1,1,1,1,1
1,1,1,1,1,1,1,1,1,1,1,1
endlayer

layer
1,1,1,1,1,1,1,1,1,1,1,1
1,1,1,0,0,0,0,0,1,1,1,1
1,1,0,0,0,0,0,0,0,1,1,1
1,0,0,0,0,0,0,0,0,0,1,1
1,0,0,0,0,0,0,0,0,0,1,1
1,0,0,0,0,0,0,0,0,0,1,1
1,0,0,0,0,0,0,0,0,0,1,1
1,0,0,0,0,0,0,0,0,0,1,1
1,1,0,0,0,0,0,0,0,1,1,1
1,1,1,0,0,0,0,0,1,1,1,1
1,1,1,1,1,1,1,1,1,1,1,1
1,1,1,1,1,1,1,1,1,1,1,1
endlayer

layer
1,1,1,3,3,3,3,3,1,1,1,1
1,1,3,0,0,0,0,0,3,1,1,1
1,3,0,0,0,0,0,0,0,3,1,1
3,0,0,0,0,0,0,0,0,0,3,1
3,0,0,0,0,0,0,0,0,0,3,1
3,0,0,0,0,0,0,0,0,0,3,1
3,0,0,0,0,0,0,0,0,0,3,1
3,0,0,0,0,0,0,0,0,0,3,1
0,3,0,0,0,0,0,0,0,3,1,1
1,1,3,0,0,0,0,0,3,1,1,1
1,1,1,3,3,3,3,3,1,1,1,1
1,1,1,1,1,1,1,1,1,1,1,1
endlayer

layer
1,1,1,3,3,3,3,3,1,1,1,1
1,1,3,0,0,3,0,0,3,1,1,1
1,3,0,0,0,3,0,0,0,3,1,1
3,0,0,0,0,3,0,0,0,0,3,1
3,0,0,0,0,3,0,0,0,0,3,1
3,0,0,0,0,3,0,0,0,0,3,1
3,0,0,0,0,3,0,0,0,0,3,1
3,0,0,0,0,3,0,0,0,0,3,1
1,3,0,0,0,3,0,0,0,3,1,1
1,1,3,0,0,3,0,0,3,1,1,1
1,1,1,3,3,3,3,3,1,1,1,1
1,1,1,1,4,4,4,1,1,1,1,1
endlayer

layer
1,1,1,3,3,3,3,3,1,1,1,1
1,1,3,5,5,9,5,5,3,1,1,1
1,3,5,5,5,5,5,5,5,3,1,1
3,5,5,5,5,5,5,5,5,5,3,1
3,5,5,5,5,5,5,5,5,5,3,1
3,5,5,5,5,5,5,5,5,5,3,1
3,5,5,5,5,5,5,5,5,5,3,1
3,5,5,5,5,5,5,5,5,5,3,1
1,3,5,5,5,5,5,5,5,3,1,1
1,1,3,5,5,5,5,5,3,1,1,1
1,1,1,3,3,5,3,3,1,1,1,1
1,1,1,1,4,5,4,1,1,1,1,1
endlayer

layer
0,0,0,3,3,3,3,3,0,0,0,0
0,0,3,0,0,5,0,0,3,0,0,0
0,3,0,0,0,0,0,0,0,3,0,0
3,0,0,0,0,0,0,0,0,0,3,0
3,0,0,0,0,0,0,0,0,0,3,0
3,0,0,0,0,0,0,0,0,0,3,0
3,0,0,0,0,0,0,0,0,0,3,0
3,0,0,0,0,0,0,0,0,0,3,0
0,3,0,0,0,0,0,0,0,3,0,0
0,0,3,0,0,0,0,0,3,0,0,0
0,0,0,3,3,0,3,3,0,0,0,0
0,0,0,0,4,0,4,0,0,0,0,0
endlayer

layer
0,0,0,3,3,3,3,3,0,0,0,0
0,0,3,0,0,0,0,0,3,0,0,0
0,3,0,0,0,0,0,0,0,3,0,0
3,0,0,0,0,0,0,0,0,0,3,0
3,0,0,0,0,0,0,0,0,0,3,0
3,0,0,0,0,0,0,0,0,0,3,0
3,0,0,0,0,0,0,0,0,0,3,0
3,0,0,0,0,0,0,0,0,0,3,0
0,3,0,0,0,0,0,0,0,3,0,0
0,0,3,0,0,0,0,0,3,0,0,0
0,0,0,3,3,3,3,3,0,0,0,0
0,0,0,0,4,4,4,0,0,0,0,0
endlayer

layer
0,0,0,0,3,3,3,0,0,0,0,0
0,0,3,3,0,0,0,3,3,0,0,0
0,3,0,0,0,0,0,0,0,3,0,0
0,3,0,0,0,0,0,0,0,3,0,0
3,0,0,0,0,0,0,0,0,0,3,0
3,0,0,0,0,0,0,0,0,0,3,0
3,0,0,0,0,0,0,0,0,0,3,0
0,3,0,0,0,0,0,0,0,3,0,0
0,3,0,0,0,0,0,0,0,3,0,0
0,0,3,3,0,0,0,3,3,0,0,0
0,0,0,0,3,3,3,0,0,0,0,0
0,0,0,0,0,0,0,0,0,0,0,0
endlayer

layer
0,0,0,0,0,0,0,0,0,0,0,0
0,0,0,3,3,3,3,3,0,0,0,0
0,0,3,0,0,0,0,0,3,0,0,0
0,3,0,0,0,0,0,0,0,3,0,0
0,3,0,0,0,0,0,0,0,3,0,0
0,3,0,0,0,0,0,0,0,3,0,0
0,3,0,0,0,0,0,0,0,3,0,0
0,3,0,0,0,0,0,0,0,3,0,0
0,0,3,0,0,0,0,0,3,0,0,0
0,0,0,3,3,3,3,3,0,0,0,0
0,0,0,0,0,0,0,0,0,0,0,0
0,0,0,0,0,0,0,0,0,0,0,0
endlayer

layer
0,0,0,0,0,0,0,0,0,0,0,0
0,0,0,0,0,0,0,0,0,0,0,0
0,0,0,3,3,3,3,3,0,0,0,0
0,0,3,3,0,0,0,3,3,0,0,0
0,0,3,0,0,0,0,0,3,0,0,0
0,0,3,0,0,0,0,0,3,0,0,0
0,0,3,0,0,0,0,0,3,0,0,0
0,0,3,3,0,0,0,3,3,0,0,0
0,0,0,3,3,3,3,3,0,0,0,0
0,0,0,0,0,0,0,0,0,0,0,0
0,0,0,0,0,0,0,0,0,0,0,0
0,0,0,0,0,0,0,0,0,0,0,0
endlayer

layer
0,0,0,0,0,0,0,0,0,0,0,0
0,0,0,0,0,0,0,0,0,0,0,0
0,0,0,0,0,0,0,0,0,0,0,0
0,0,0,0,3,3,3,0,0,0,0,0
0,0,0,3,6,6,6,3,0,0,0,0
0,0,0,3,6,6,6,3,0,0,0,0
0,0,0,3,6,6,6,3,0,0,0,0
0,0,0,0,3,3,3,0,0,0,0,0
0,0,0,0,0,0,0,0,0,0,0,0
0,0,0,0,0,0,0,0,0,0,0,0
0,0,0,0,0,0,0,0,0,0,0,0
0,0,0,0,0,0,0,0,0,0,0,0
endlayer
