biomesToSpawnIn=autumn hills,autumn woods,bamboo forest,birch forest,bog,boneyard,boreal forest,brushland,chaparral,cherry blossom grove,coniferous forest,deciduous forest,extreme hills,extreme hills edge,fen,field,forest,forested field,forested hills,forested island,foresthills,fungi forest,garden,grassland,green hills,green swamplands,grove,heathland,hell,highland,hot springs,jade cliffs,jungle,junglehills,lavender fields,lush redwoods,lush swamp,magical forest,majestic meadow,mangrove,maplewoods,marsh,meadow,meadow forest,mesa,mini jungle,mountain, mountain ridge,mountain taiga,mystic grove,orchard,outback,overgrown beach,overgrown greens,pasture,pasture meadow,pine forest,plains,prarie,quagmire,rainforest,redwood forest,sacred springs,savanna,savanna plateau,scrubland,seasonal forest,seasonal spruce forest,shield,spruce woods,steppe,sublime shrubland,swampland,taiga,taigahills,temperate rainforest,thick shrubland,thicket,thinned mystic grove,thinned pasture,thinned timber,timber,tropical rainforest,tropics mountain,tundra,wonderous woods,woodland,woodlands,wyvern biome,wetland
weight=2
embed_into_distance=11
acceptable_target_blocks=stone,grass,dirt,sand,gravel,sandstone
dimensions=16,6,6
cut_in_buffer=0
max_leveling=2
leveling_buffer=0
preserve_water=0
preserve_lava=0
preserve_plants=0
max_cut_in=10


rule1=0,100,preserveBlock
rule2=0,100,cobblestone
rule3=0,100,water
rule4=0,100,gravel
rule5=0,100,fence


layer
1,1,1,1,1,1
1,2,2,2,2,1
1,2,2,2,2,1
1,2,2,2,2,1
1,2,2,2,2,1
1,1,1,1,1,1
endlayer

layer
1,1,1,1,1,1
1,2,2,2,2,1
1,2,3,3,2,1
1,2,3,3,2,1
1,2,2,2,2,1
1,1,1,1,1,1
endlayer

layer
1,1,1,1,1,1
1,2,2,2,2,1
1,2,3,3,2,1
1,2,3,3,2,1
1,2,2,2,2,1
1,1,1,1,1,1
endlayer

layer
1,1,1,1,1,1
1,2,2,2,2,1
1,2,3,3,2,1
1,2,3,3,2,1
1,2,2,2,2,1
1,1,1,1,1,1
endlayer

layer
1,1,1,1,1,1
1,2,2,2,2,1
1,2,3,3,2,1
1,2,3,3,2,1
1,2,2,2,2,1
1,1,1,1,1,1
endlayer

layer
1,1,1,1,1,1
1,2,2,2,2,1
1,2,3,3,2,1
1,2,3,3,2,1
1,2,2,2,2,1
1,1,1,1,1,1
endlayer

layer
1,1,1,1,1,1
1,2,2,2,2,1
1,2,3,3,2,1
1,2,3,3,2,1
1,2,2,2,2,1
1,1,1,1,1,1
endlayer

layer
1,1,1,1,1,1
1,2,2,2,2,1
1,2,3,3,2,1
1,2,3,3,2,1
1,2,2,2,2,1
1,1,1,1,1,1
endlayer

layer
1,1,1,1,1,1
1,2,2,2,2,1
1,2,3,3,2,1
1,2,3,3,2,1
1,2,2,2,2,1
1,1,1,1,1,1
endlayer

layer
4,4,4,4,4,4
4,2,2,2,2,4
4,2,3,3,2,4
4,2,3,3,2,4
4,2,2,2,2,4
4,4,4,4,4,4
endlayer

layer
4,4,4,4,4,4
4,2,2,2,2,4
4,2,3,3,2,4
4,2,3,3,2,4
4,2,2,2,2,4
4,4,4,4,4,4
endlayer

layer
4,4,4,4,4,4
4,2,2,2,2,4
4,2,3,3,2,4
4,2,3,3,2,4
4,2,2,2,2,4
4,4,4,4,4,4
endlayer

layer
0,0,0,0,0,0
0,2,2,2,2,0
0,2,0,0,2,0
0,2,0,0,2,0
0,2,2,2,2,0
0,0,0,0,0,0
endlayer

layer
0,0,0,0,0,0
0,5,0,0,5,0
0,0,0,0,0,0
0,0,0,0,0,0
0,5,0,0,5,0
0,0,0,0,0,0
endlayer

layer
0,0,0,0,0,0
0,5,0,0,5,0
0,0,0,0,0,0
0,0,0,0,0,0
0,5,0,0,5,0
0,0,0,0,0,0
endlayer

layer
0,0,0,0,0,0
0,2,2,2,2,0
0,2,2,2,2,0
0,2,2,2,2,0
0,2,2,2,2,0
0,0,0,0,0,0
endlayer

