# Converted from schematic
# THIS TEMPLATE USES DEFAULTS!  Please edit for corrections.
# If you need help, consult template_rules.txt
biomesToSpawnIn=autumn hills,autumn woods,bamboo forest,birch forest,bog,boneyard,boreal forest,brushland,chaparral,cherry blossom grove,coniferous forest,deciduous forest,extreme hills,extreme hills edge,fen,field,forest,forested field,forested hills,forested island,foresthills,fungi forest,garden,grassland,green hills,green swamplands,grove,heathland,hell,highland,hot springs,jade cliffs,jungle,junglehills,lavender fields,lush redwoods,lush swamp,magical forest,majestic meadow,mangrove,maplewoods,marsh,meadow,meadow forest,mesa,mini jungle,mountain, mountain ridge,mountain taiga,mystic grove,orchard,outback,overgrown beach,overgrown greens,pasture,pasture meadow,pine forest,plains,prarie,quagmire,rainforest,redwood forest,sacred springs,savanna,savanna plateau,scrubland,seasonal forest,seasonal spruce forest,shield,spruce woods,steppe,sublime shrubland,swampland,taiga,taigahills,temperate rainforest,thick shrubland,thicket,thinned mystic grove,thinned pasture,thinned timber,timber,tropical rainforest,tropics mountain,tundra,wonderous woods,woodland,woodlands,wyvern biome,wetland
weight=1
embed_into_distance=1
acceptable_target_blocks=stone,grass,dirt,sand,gravel
dimensions=6,11,11
allowable_overhang=0
max_cut_in=2
cut_in_buffer=1
max_leveling=2
leveling_buffer=1
preserve_water=0
preserve_lava=0
preserve_plants=0


rule1=0,100,grass
rule2=0,100,dirt
rule3=0,100,planks
rule4=0,100,wool-7
rule5=0,100,stone_slab-2
rule6=0,100,tallgrass-1
rule7=0,100,log
rule8=0,100,bed-10
rule9=0,100,bookshelf
rule10=0,100,wooden_pressure_plate
rule11=0,100,wooden_door-2
rule12=0,100,bed-2
rule13=0,100,fence
rule14=0,100,MediumChest-4
rule15=0,100,cauldron-3
rule16=0,100,wooden_door-3
rule17=0,100,glass
rule18=2,100,torch-1
rule19=0,100,wooden_door-10
rule20=0,100,wooden_door-11
rule21=2,100,torch-3
rule22=2,100,torch-4
rule23=0,100,stone_stairs-2
rule24=0,100,stone_slab-3
rule25=2,100,torch-2
rule26=0,100,double_stone_slab-3
rule27=0,100,stone_stairs-1
rule28=0,100,stone_stairs
rule29=0,100,stone_stairs-3
rule30=0,100,cobblestone


layer
1,1,1,1,1,1,1,1,1,1,1
1,1,1,2,2,2,2,2,2,2,1
1,1,1,2,3,3,3,3,3,2,1
1,1,1,2,3,4,4,4,3,2,1
1,1,1,2,3,4,3,4,3,2,1
1,2,2,3,3,4,4,4,3,2,1
1,3,3,3,3,3,3,3,3,2,1
1,2,2,2,2,2,2,3,3,2,1
1,1,1,1,1,1,1,2,3,2,1
1,1,1,1,1,1,1,2,3,2,1
1,1,1,1,1,1,1,1,1,1,1
endlayer

layer
0,0,0,0,5,5,5,5,5,0,0
6,0,0,7,3,3,3,3,3,7,0
6,0,5,3,15,0,13,12,8,3,5
0,0,5,3,0,13,0,0,0,3,5
6,0,5,3,0,0,0,0,9,3,5
0,7,3,0,0,0,0,0,0,3,5
0,16,10,0,0,14,13,0,0,3,5
0,7,3,3,3,3,3,0,0,3,5
6,6,5,5,5,5,5,3,10,3,0
6,6,6,6,6,6,6,7,11,7,0
6,6,6,6,0,6,6,0,0,0,6
endlayer

layer
0,0,0,0,0,0,0,0,0,0,0
0,0,0,7,17,17,3,17,17,7,0
0,0,0,17,0,0,13,0,0,3,0
0,0,0,17,0,10,0,0,0,17,0
0,0,0,17,0,0,0,0,0,17,0
21,7,3,0,0,0,0,0,0,3,0
0,20,0,0,0,0,13,0,0,17,0
21,7,3,17,17,17,3,0,0,17,0
0,0,0,0,0,0,0,3,0,3,0
0,0,0,0,0,0,0,7,19,7,0
0,0,0,0,0,0,0,18,0,18,0
endlayer

layer
0,0,0,25,5,5,0,5,5,25,0
0,0,21,7,3,3,3,3,3,7,22
0,0,5,3,0,0,13,0,0,3,0
0,0,5,3,0,0,0,0,0,3,5
0,24,24,3,0,0,0,0,0,3,5
24,26,3,5,0,0,0,0,21,3,22
24,26,3,5,0,0,13,5,5,3,5
24,26,3,3,3,3,3,3,3,3,23
0,24,27,27,27,27,27,26,26,26,23
0,0,0,0,0,0,24,26,26,26,24
0,0,0,0,0,0,0,24,24,24,0
endlayer

layer
0,0,0,28,28,28,28,28,28,28,24
0,0,29,3,3,3,3,3,3,26,23
0,0,29,3,13,0,13,0,13,3,23
0,0,29,3,0,21,3,22,0,3,23
0,0,29,3,0,21,3,22,0,3,23
0,0,29,3,13,0,0,0,13,3,23
0,0,29,3,3,3,3,3,3,26,23
0,0,24,27,27,27,27,27,27,27,0
0,0,0,0,0,0,0,24,24,24,0
0,0,0,0,0,0,0,0,0,0,0
0,0,0,0,0,0,0,0,0,0,0
endlayer

layer
0,0,0,0,0,0,0,0,0,0,0
0,0,0,24,28,28,28,28,28,24,0
0,0,0,29,4,4,30,4,4,23,0
0,0,0,29,4,4,30,4,4,23,0
0,0,0,29,4,4,30,4,4,23,0
0,0,0,29,4,4,30,4,4,23,0
0,0,0,24,27,27,27,27,27,24,0
0,0,0,0,0,0,0,0,0,0,0
0,0,0,0,0,0,0,0,0,0,0
0,0,0,0,0,0,0,0,0,0,0
0,0,0,0,0,0,0,0,0,0,0
endlayer

