
# Created by Ruins mod version 1.14.3 Ingame Parser
# authoring Player: maireilla

# TEMPLATE PARAMETER SETTINGS:
#
# criterion expression specifying mod ids required to load template
# may include plus (AND), minus (AND NOT), comma (OR), and parentheses
# all required mods listed must be present; no prohibited mods can be
requiredMods=
#
# likelihood this template will be chosen relative to all others
# e.g., a weight=6 template is chosen 3X as often as one with weight=2
weight=1
#
# list of dimensions in which this template may spawn, even if generic
# one or more dimension names, separated by commas (blank = all)
dimensionsToSpawnIn=
#
# list of other biomes in which this template may spawn
# biome corresponding to directory is always assumed, listed or not
# generic templates should leave this list empty
biomesToSpawnIn=
#
# criterion expression specifying types of biome where template spawns
# this is in addition to those explicitly listed as biomesToSpawnIn
# generic templates should leave this list empty
biomeTypesToSpawnIn=
#
# list of biomes in which this template may not spawn
# takes precedence over biomeTypesToSpawnIn, but NOT biomesToSpawnIn
# should be empty if biomeTypesToSpawnIn is empty
biomesToNotSpawnIn=
#
# depth template is pushed down into the surface when built
# offset is min/max range of random additional bury depth
embed_into_distance=0
random_height_offset=0,0
#
# whitelist/blacklist of block states on which template may be built
# specify one, not both; leave the other empty (both empty = allow all)
# CAUTION: THE DEFAULTS ONLY APPLY TO NON-FLOWING LAVA AND WATER VARIANTS)
acceptable_target_blocks=
unacceptable_target_blocks={Properties:{level:"0"},Name:"minecraft:water"},{Properties:{level:"0"},Name:"minecraft:lava"}
#
# size of template (#layers, #rows per layer, #blocks per row)
dimensions=34,32,32
#
# max number of missing blocks allowed in surface beneath template
allowable_overhang=0
#
# depth/height limit affected by terrain leveling
# also maximum bumpiness tolerated in surface beneath template
max_leveling=2
#
# padding applied to all sides of template horizontal footprint
# expands area affected by terrain leveling (-1 = no leveling)
leveling_buffer=0
#
# do not rotate template randomly when built (1 = no rotation)
preventRotation=0
#
# treat water/lava blocks as air and protect them from rule0 (1 = yes)
preserve_water=0
preserve_lava=0
#
# minimum distance this template must have from instances of itself
uniqueMinDistance=0
#
# min/max distances this template can be from world spawn (0 = no limit)
# only applies to overworld--i.e., dimension 0
spawnMinDistance=0
spawnMaxDistance=0
#
# other template built nearby whenever this one is
# syntax: <name>;<relativeX>;<maxYdifference>;<relativeZ>[;<chance>]
# may be used more than once to specify multiple neighbors
adjoining_template=

rule1=0,100,{Properties:{snowy:"false"},Name:"minecraft:grass_block"}
rule2=0,100,{Properties:{moisture:"7"},Name:"minecraft:farmland"}
rule3=0,100,{Name:"minecraft:grass_path"}
rule4=0,100,{Name:"minecraft:stone_bricks"}
rule5=0,100,{Properties:{level:"0"},Name:"minecraft:water"}
rule6=0,100,{Name:"minecraft:dirt"}
rule7=0,100,{Properties:{east:"true",waterlogged:"false",south:"false",north:"false",west:"false"},Name:"minecraft:dark_oak_fence"}
rule8=0,100,{Properties:{age:"1"},Name:"minecraft:wheat"}
rule9=0,100,{Properties:{age:"0"},Name:"minecraft:wheat"}
rule10=0,100,{Properties:{age:"2"},Name:"minecraft:wheat"}
rule11=0,100,{Properties:{age:"3"},Name:"minecraft:wheat"}
rule12=0,100,{Properties:{east:"true",waterlogged:"false",south:"false",north:"false",west:"true"},Name:"minecraft:dark_oak_fence"}
rule13=0,100,{Properties:{east:"true",waterlogged:"false",south:"true",north:"false",west:"false"},Name:"minecraft:dark_oak_fence"}
rule14=0,100,{Properties:{east:"false",waterlogged:"false",south:"false",north:"true",west:"true"},Name:"minecraft:dark_oak_fence"}
rule15=0,100,{Properties:{east:"false",waterlogged:"false",south:"true",north:"false",west:"true"},Name:"minecraft:dark_oak_fence"}
rule16=0,100,{Properties:{east:"true",waterlogged:"false",south:"false",north:"true",west:"false"},Name:"minecraft:dark_oak_fence"}
rule17=0,100,{Properties:{east:"false",waterlogged:"false",south:"true",north:"true",west:"false"},Name:"minecraft:dark_oak_fence"}
rule18=0,100,{Properties:{east:"false",waterlogged:"false",south:"true",north:"false",west:"false"},Name:"minecraft:dark_oak_fence"}
rule19=0,100,{Properties:{east:"false",waterlogged:"false",south:"false",north:"true",west:"false"},Name:"minecraft:dark_oak_fence"}
rule20=0,100,{Properties:{east:"false",waterlogged:"false",south:"true",north:"true",west:"true"},Name:"minecraft:dark_oak_fence"}
rule21=0,100,{Properties:{east:"true",waterlogged:"false",south:"true",north:"true",west:"false"},Name:"minecraft:dark_oak_fence"}
rule22=0,100,{Properties:{facing:"up",open:"false"},Name:"minecraft:barrel"}
rule23=0,100,{Properties:{east:"true",waterlogged:"false",south:"false",north:"true",west:"true"},Name:"minecraft:dark_oak_fence"}
rule24=0,100,{Properties:{east:"true",waterlogged:"false",south:"true",north:"false",west:"true"},Name:"minecraft:dark_oak_fence"}
rule25=0,100,{Properties:{facing:"west",open:"false"},Name:"minecraft:barrel"}
rule26=0,100,{Properties:{age:"5"},Name:"minecraft:wheat"}
rule27=0,100,{Properties:{facing:"east",open:"false"},Name:"minecraft:barrel"}
rule28=0,100,{Properties:{age:"4"},Name:"minecraft:wheat"}
rule29=0,100,{Properties:{east:"false",waterlogged:"false",south:"false",north:"false",west:"true"},Name:"minecraft:dark_oak_fence"}
rule30=0,100,{Name:"minecraft:torch"}
rule31=0,100,{Properties:{waterlogged:"false",type:"bottom"},Name:"minecraft:stone_brick_slab"}
rule32=0,100,{Properties:{facing:"north",open:"false"},Name:"minecraft:barrel"}
rule33=0,100,{Properties:{facing:"south",open:"false"},Name:"minecraft:barrel"}
rule34=0,100,{Properties:{east:"false",waterlogged:"false",south:"true",north:"true",west:"false"},Name:"minecraft:iron_bars"}
rule35=0,100,{Properties:{east:"true",waterlogged:"false",south:"false",north:"false",west:"true"},Name:"minecraft:iron_bars"}
rule36=0,100,{Properties:{waterlogged:"false",type:"top"},Name:"minecraft:stone_brick_slab"}
rule37=0,100,{Properties:{half:"bottom",waterlogged:"false",shape:"outer_left",facing:"south"},Name:"minecraft:brick_stairs"}
rule38=0,100,{Properties:{half:"bottom",waterlogged:"false",shape:"straight",facing:"east"},Name:"minecraft:brick_stairs"}
rule39=0,100,{Properties:{half:"bottom",waterlogged:"false",shape:"outer_right",facing:"north"},Name:"minecraft:brick_stairs"}
rule40=0,100,{Properties:{half:"bottom",waterlogged:"false",shape:"outer_right",facing:"east"},Name:"minecraft:brick_stairs"}
rule41=0,100,{Properties:{half:"bottom",waterlogged:"false",shape:"inner_left",facing:"south"},Name:"minecraft:brick_stairs"}
rule42=0,100,{Properties:{half:"bottom",waterlogged:"false",shape:"inner_left",facing:"east"},Name:"minecraft:brick_stairs"}
rule43=0,100,{Properties:{half:"bottom",waterlogged:"false",shape:"outer_left",facing:"east"},Name:"minecraft:brick_stairs"}
rule44=0,100,{Properties:{half:"bottom",waterlogged:"false",shape:"straight",facing:"south"},Name:"minecraft:brick_stairs"}
rule45=0,100,{Properties:{half:"bottom",waterlogged:"false",shape:"straight",facing:"north"},Name:"minecraft:brick_stairs"}
rule46=0,100,{Properties:{half:"bottom",waterlogged:"false",shape:"outer_left",facing:"west"},Name:"minecraft:brick_stairs"}
rule47=0,100,{Properties:{half:"bottom",waterlogged:"false",shape:"inner_left",facing:"west"},Name:"minecraft:brick_stairs"}
rule48=0,100,{Properties:{half:"bottom",waterlogged:"false",shape:"inner_left",facing:"north"},Name:"minecraft:brick_stairs"}
rule49=0,100,{Properties:{half:"bottom",waterlogged:"false",shape:"outer_right",facing:"west"},Name:"minecraft:brick_stairs"}
rule50=0,100,{Properties:{half:"bottom",waterlogged:"false",shape:"outer_right",facing:"south"},Name:"minecraft:brick_stairs"}
rule51=0,100,{Properties:{half:"bottom",waterlogged:"false",shape:"straight",facing:"west"},Name:"minecraft:brick_stairs"}
rule52=0,100,{Properties:{half:"bottom",waterlogged:"false",shape:"outer_left",facing:"north"},Name:"minecraft:brick_stairs"}
rule53=0,100,{Name:"minecraft:glowstone"}
rule54=0,100,{Name:"minecraft:bricks"}
rule55=0,100,{Properties:{level:"8"},Name:"minecraft:water"}
rule56=0,100,{Properties:{waterlogged:"false",type:"bottom"},Name:"minecraft:brick_slab"}
rule57=0,100,{Properties:{half:"top",waterlogged:"false",shape:"straight",facing:"east"},Name:"minecraft:stone_brick_stairs"}
rule58=0,100,{Name:"minecraft:red_carpet"}
rule59=0,100,{Properties:{half:"top",waterlogged:"false",shape:"straight",facing:"south"},Name:"minecraft:stone_brick_stairs"}
rule60=0,100,{Properties:{half:"bottom",waterlogged:"false",shape:"straight",facing:"north"},Name:"minecraft:stone_brick_stairs"}
rule61=0,100,{Properties:{half:"bottom",waterlogged:"false",shape:"straight",facing:"south"},Name:"minecraft:stone_brick_stairs"}
rule62=0,100,{Properties:{half:"top",waterlogged:"false",shape:"straight",facing:"north"},Name:"minecraft:stone_brick_stairs"}
rule63=0,100,{Properties:{axis:"y"},Name:"minecraft:dark_oak_wood"}
rule64=0,100,{Name:"minecraft:black_carpet"}
rule65=0,100,{Properties:{half:"bottom",waterlogged:"false",shape:"straight",facing:"west"},Name:"minecraft:stone_brick_stairs"}
rule66=0,100,{Properties:{half:"bottom",waterlogged:"false",shape:"straight",facing:"east"},Name:"minecraft:stone_brick_stairs"}
rule67=0,100,{Properties:{half:"top",waterlogged:"false",shape:"straight",facing:"west"},Name:"minecraft:stone_brick_stairs"}
rule68=0,100,{Properties:{axis:"x"},Name:"minecraft:dark_oak_wood"}
rule69=0,100,{Properties:{axis:"z"},Name:"minecraft:dark_oak_wood"}
rule70=0,100,{Name:"minecraft:white_wool"}
rule71=2*0,100,{Name:"minecraft:blue_wool"}
^0,100,{Name:"minecraft:green_wool"}
^0,100,{Name:"minecraft:red_wool"}
^0,100,{Name:"minecraft:cyan_wool"}
^0,100,{Name:"minecraft:lime_wool"}
rule72=0,100,{Name:"minecraft:lapis_block"}

layer
0,0,0,0,0,0,0,0,0,0,0,0,0,0,0,0,0,0,0,0,0,0,0,0,0,0,0,0,0,0,0,0
0,1,1,1,1,1,1,2,2,2,2,2,2,2,1,3,3,1,2,2,2,2,2,2,2,1,1,1,1,1,1,0
0,1,1,1,4,4,4,2,2,2,2,2,2,2,1,3,3,1,2,2,2,2,2,2,2,4,4,4,1,1,1,0
0,1,1,4,4,4,4,4,2,2,5,2,2,2,1,3,3,1,2,2,2,5,2,2,4,4,4,4,4,1,1,0
0,1,4,4,4,4,4,4,4,2,2,2,2,1,1,3,3,1,1,2,2,2,2,4,4,4,4,4,4,4,1,0
0,1,4,4,4,4,4,4,4,2,2,1,1,1,3,3,3,3,1,1,1,2,2,4,4,4,4,4,4,4,1,0
0,1,4,4,4,4,4,4,4,2,2,1,3,3,3,1,1,3,3,3,1,2,2,4,4,4,4,4,4,4,1,0
0,2,2,4,4,4,4,4,1,1,4,4,4,4,4,6,6,4,4,4,4,4,1,1,4,4,4,4,4,2,2,0
0,2,2,2,4,4,4,1,1,4,4,4,4,4,4,4,4,4,4,4,4,4,4,1,1,4,4,4,2,2,2,0
0,2,2,2,2,2,2,1,4,4,4,4,4,4,4,4,4,4,4,4,4,4,4,4,1,2,2,2,2,2,2,0
0,2,2,5,2,2,2,4,4,4,4,4,4,4,4,4,4,4,4,4,4,4,4,4,4,2,2,2,5,2,2,0
0,2,2,2,2,1,1,4,4,4,4,4,4,4,4,4,4,4,4,4,4,4,4,4,4,1,1,2,2,2,2,0
0,2,2,2,2,1,3,4,4,4,4,4,4,4,4,4,4,4,4,4,4,4,4,4,4,3,1,2,2,2,2,0
0,2,2,2,1,1,3,4,4,4,4,4,4,4,4,4,4,4,4,4,4,4,4,4,4,3,1,1,2,2,2,0
0,1,1,1,1,3,3,4,4,4,4,4,4,4,4,4,4,4,4,4,4,4,4,4,4,3,3,1,1,1,1,0
0,3,3,3,3,3,1,6,4,4,4,4,4,4,4,1,6,4,4,4,4,4,4,4,6,1,3,3,3,3,3,0
0,3,3,3,3,3,1,6,4,4,4,4,4,4,4,4,6,4,4,4,4,4,4,4,6,1,3,3,3,3,3,0
0,1,1,1,1,3,3,4,4,4,4,4,4,4,4,4,4,4,4,4,4,4,4,4,4,3,3,1,1,1,1,0
0,2,2,2,1,1,3,4,4,4,4,4,4,4,4,4,4,4,4,4,4,4,4,4,4,3,1,1,2,2,2,0
0,2,2,2,2,1,3,4,4,4,4,4,4,4,4,4,4,4,4,4,4,4,4,4,4,3,1,2,2,2,2,0
0,2,2,2,2,1,1,4,4,4,4,4,4,4,4,4,4,4,4,4,4,4,4,4,4,1,1,2,2,2,2,0
0,2,2,5,2,2,2,4,4,4,4,4,4,4,4,4,4,4,4,4,4,4,4,4,4,2,2,2,5,2,2,0
0,2,2,2,2,2,2,1,4,4,4,4,4,4,4,4,4,4,4,4,4,4,4,4,1,2,2,2,2,2,2,0
0,2,2,2,4,4,4,1,1,4,4,4,4,4,4,4,4,4,4,4,4,4,4,1,1,4,4,4,2,2,2,0
0,2,2,4,4,4,4,4,1,1,4,4,4,4,4,6,6,4,4,4,4,4,1,1,4,4,4,4,4,2,2,0
0,1,4,4,4,4,4,4,4,2,2,1,3,3,3,1,1,3,3,3,1,2,2,4,4,4,4,4,4,4,1,0
0,1,4,4,4,4,4,4,4,2,2,1,1,1,3,3,3,3,1,1,1,2,2,4,4,4,4,4,4,4,1,0
0,1,4,4,4,4,4,4,4,2,2,2,2,1,1,3,3,1,1,2,2,2,2,4,4,4,4,4,4,4,1,0
0,1,1,4,4,4,4,4,2,2,5,2,2,2,1,3,3,1,2,2,2,5,2,2,4,4,4,4,4,1,1,0
0,1,1,1,4,4,4,2,2,2,2,2,2,2,1,3,3,1,2,2,2,2,2,2,2,4,4,4,1,1,1,0
0,1,1,1,1,1,1,2,2,2,2,2,2,2,1,3,3,1,2,2,2,2,2,2,2,1,1,1,1,1,1,0
0,0,0,0,0,0,0,0,0,0,0,0,0,0,0,0,0,0,0,0,0,0,0,0,0,0,0,0,0,0,0,0
endlayer

layer
0,0,0,0,0,0,0,0,0,0,0,0,0,0,0,0,0,0,0,0,0,0,0,0,0,0,0,0,0,0,0,0
0,0,0,0,0,0,7,8,9,8,9,8,9,8,7,0,0,7,8,10,9,9,8,8,8,7,0,0,0,0,0,0
0,0,0,0,4,4,4,8,9,9,9,9,9,8,12,0,0,12,9,10,8,8,8,11,9,4,4,4,0,0,0,0
0,0,0,4,0,0,0,4,9,8,0,10,10,9,12,0,0,12,9,0,10,0,11,10,4,0,0,0,4,0,0,0
0,0,4,0,0,0,0,0,4,8,9,9,9,16,15,0,0,14,13,9,8,10,9,4,0,0,0,0,0,4,0,0
0,0,4,0,0,0,0,0,4,8,8,16,17,15,0,0,0,0,14,17,13,9,8,4,0,0,0,0,0,4,0,0
0,19,4,0,0,0,0,0,4,8,9,12,0,0,0,16,13,0,0,0,12,10,8,4,0,0,0,0,0,4,18,0
0,9,9,4,0,0,0,4,20,21,4,4,0,4,4,22,22,4,4,0,4,4,21,20,4,0,0,0,4,10,8,0
0,8,10,10,4,4,4,24,0,4,0,0,0,0,0,4,4,0,0,0,0,0,4,0,23,4,4,4,8,8,9,0
0,11,10,10,9,9,9,23,4,0,0,0,0,0,0,4,4,0,0,0,0,0,0,4,24,8,8,9,9,9,8,0
0,8,9,0,9,9,8,4,0,0,0,0,0,0,4,0,0,4,0,0,0,0,0,0,4,9,8,9,0,9,9,0
0,8,10,8,9,16,17,4,0,0,0,0,0,0,0,0,0,0,0,0,0,0,0,0,4,17,13,9,9,10,8,0
0,10,9,0,8,12,0,0,0,0,0,0,0,0,0,0,0,0,0,0,0,0,0,0,0,0,12,9,8,8,9,0
0,9,8,10,16,15,0,4,0,0,0,0,0,0,4,0,0,4,0,0,0,0,0,0,4,0,14,13,9,9,10,0
0,19,17,17,15,0,0,4,0,0,4,0,0,4,4,0,0,4,4,0,0,4,0,0,4,0,0,14,17,17,18,0
0,0,0,0,0,0,16,22,4,4,0,0,0,0,0,4,4,0,0,0,0,0,4,4,25,13,0,0,0,0,0,0
0,0,0,0,0,0,14,22,4,4,0,0,0,0,0,0,4,0,0,0,0,0,4,4,25,15,0,0,0,0,0,0
0,19,17,17,13,0,0,4,0,0,4,0,0,4,4,0,0,4,4,0,0,4,0,0,4,0,0,16,17,17,18,0
0,8,9,8,14,13,0,4,0,0,0,0,0,0,4,0,0,4,0,0,0,0,0,0,4,0,16,15,8,9,8,0
0,10,9,10,8,12,0,0,0,0,0,0,0,0,0,0,0,0,0,0,0,0,0,0,0,0,12,8,0,9,8,0
0,10,9,8,9,14,17,4,0,0,0,0,0,0,0,0,0,0,0,0,0,0,0,0,4,17,15,9,8,8,8,0
0,9,8,0,9,8,9,4,0,0,0,0,0,0,4,0,0,4,0,0,0,0,0,0,4,11,9,11,0,10,9,0
0,11,10,9,8,8,11,23,4,0,0,0,0,0,0,4,4,0,0,0,0,0,0,4,24,9,8,10,26,10,9,0
0,8,9,8,4,4,4,24,0,4,0,0,0,0,0,4,4,0,0,0,0,0,4,0,23,4,4,4,9,10,10,0
0,9,8,4,0,0,0,4,21,20,4,4,0,4,4,27,27,4,4,0,4,4,20,21,4,0,0,0,4,9,9,0
0,19,4,0,0,0,0,0,4,9,10,12,0,0,0,14,15,0,0,0,12,9,9,4,0,0,0,0,0,4,18,0
0,0,4,0,0,0,0,0,4,9,9,14,17,13,0,0,0,0,16,17,15,8,9,4,0,0,0,0,0,4,0,0
0,0,4,0,0,0,0,0,4,8,9,9,9,14,13,0,0,16,15,8,9,8,8,4,0,0,0,0,0,4,0,0
0,0,0,4,0,0,0,4,10,8,0,8,0,9,12,0,0,12,10,8,10,0,9,9,4,0,0,0,4,0,0,0
0,0,0,0,4,4,4,9,28,11,9,8,8,8,12,0,0,12,11,26,9,8,9,9,9,4,4,4,0,0,0,0
0,0,0,0,0,0,29,8,9,9,10,11,9,9,29,0,0,29,28,9,9,9,9,10,8,29,0,0,0,0,0,0
0,0,0,0,0,0,0,0,0,0,0,0,0,0,0,0,0,0,0,0,0,0,0,0,0,0,0,0,0,0,0,0
endlayer

layer
0,0,0,0,0,0,0,0,0,0,0,0,0,0,0,0,0,0,0,0,0,0,0,0,0,0,0,0,0,0,0,0
0,0,0,0,0,0,30,0,0,0,0,0,0,0,30,0,0,30,0,0,0,0,0,0,0,30,0,0,0,0,0,0
0,0,0,0,4,4,4,0,0,0,0,0,0,0,0,0,0,0,0,0,0,0,0,0,0,4,4,4,0,0,0,0
0,0,0,4,0,0,0,4,0,0,0,0,0,0,0,0,0,0,0,0,0,0,0,0,4,0,0,0,4,0,0,0
0,0,4,0,0,0,0,0,4,0,0,0,0,30,0,0,0,0,30,0,0,0,0,4,0,0,0,0,0,4,0,0
0,0,4,0,0,0,0,0,4,0,0,30,0,0,0,0,0,0,0,0,30,0,0,4,0,0,0,0,0,4,0,0
0,30,4,0,0,0,0,0,4,0,0,0,0,0,0,0,0,0,0,0,0,0,0,4,0,0,0,0,0,4,30,0
0,0,0,4,0,0,0,4,0,0,4,31,0,31,4,25,0,4,31,0,31,4,0,0,4,0,0,0,4,0,0,0
0,0,0,0,4,4,4,0,0,4,0,0,0,0,0,4,4,0,0,0,0,0,4,0,0,4,4,4,0,0,0,0
0,0,0,0,0,0,0,0,4,0,0,0,0,0,0,4,4,0,0,0,0,0,0,4,0,0,0,0,0,0,0,0
0,0,0,0,0,0,0,4,0,0,0,0,0,0,4,0,0,4,0,0,0,0,0,0,4,0,0,0,0,0,0,0
0,0,0,0,0,30,0,31,0,0,0,0,0,0,0,0,0,0,0,0,0,0,0,0,31,0,30,0,0,0,0,0
0,0,0,0,0,0,0,0,0,0,0,0,0,0,0,0,0,0,0,0,0,0,0,0,0,0,0,0,0,0,0,0
0,0,0,0,30,0,0,31,0,0,0,0,0,0,4,0,0,4,0,0,0,0,0,0,31,0,0,30,0,0,0,0
0,30,0,0,0,0,0,4,0,0,4,0,0,4,4,0,0,4,4,0,0,4,0,0,4,0,0,0,0,0,30,0
0,0,0,0,0,0,0,22,4,4,0,0,0,0,0,0,4,0,0,0,0,0,4,4,32,0,0,0,0,0,0,0
0,0,0,0,0,0,0,0,4,4,0,0,0,0,0,0,4,0,0,0,0,0,4,4,0,0,0,0,0,0,0,0
0,30,0,0,0,0,0,4,0,0,4,0,0,4,4,0,0,4,4,0,0,4,0,0,4,0,0,0,0,0,30,0
0,0,0,0,30,0,0,31,0,0,0,0,0,0,4,0,0,4,0,0,0,0,0,0,31,0,0,30,0,0,0,0
0,0,0,0,0,0,0,0,0,0,0,0,0,0,0,0,0,0,0,0,0,0,0,0,0,0,0,0,0,0,0,0
0,0,0,0,0,30,0,31,0,0,0,0,0,0,0,0,0,0,0,0,0,0,0,0,31,0,30,0,0,0,0,0
0,0,0,0,0,0,0,4,0,0,0,0,0,0,4,0,0,4,0,0,0,0,0,0,4,0,0,0,0,0,0,0
0,0,0,0,0,0,0,0,4,0,0,0,0,0,0,4,4,0,0,0,0,0,0,4,0,0,0,0,0,0,0,0
0,0,0,0,4,4,4,0,0,4,0,0,0,0,0,4,4,0,0,0,0,0,4,0,0,4,4,4,0,0,0,0
0,0,0,4,0,0,0,4,0,0,4,31,0,31,4,0,33,4,31,0,31,4,0,0,4,0,0,0,4,0,0,0
0,30,4,0,0,0,0,0,4,0,0,0,0,0,0,0,0,0,0,0,0,0,0,4,0,0,0,0,0,4,30,0
0,0,4,0,0,0,0,0,4,0,0,30,0,0,0,0,0,0,0,0,30,0,0,4,0,0,0,0,0,4,0,0
0,0,4,0,0,0,0,0,4,0,0,0,0,30,0,0,0,0,30,0,0,0,0,4,0,0,0,0,0,4,0,0
0,0,0,4,0,0,0,4,0,0,0,0,0,0,0,0,0,0,0,0,0,0,0,0,4,0,0,0,4,0,0,0
0,0,0,0,4,4,4,0,0,0,0,0,0,0,0,0,0,0,0,0,0,0,0,0,0,4,4,4,0,0,0,0
0,0,0,0,0,0,30,0,0,0,0,0,0,0,30,0,0,30,0,0,0,0,0,0,0,30,0,0,0,0,0,0
0,0,0,0,0,0,0,0,0,0,0,0,0,0,0,0,0,0,0,0,0,0,0,0,0,0,0,0,0,0,0,0
endlayer

layer
0,0,0,0,0,0,0,0,0,0,0,0,0,0,0,0,0,0,0,0,0,0,0,0,0,0,0,0,0,0,0,0
0,0,0,0,0,0,0,0,0,0,0,0,0,0,0,0,0,0,0,0,0,0,0,0,0,0,0,0,0,0,0,0
0,0,0,0,4,34,4,0,0,0,0,0,0,0,0,0,0,0,0,0,0,0,0,0,0,4,34,4,0,0,0,0
0,0,0,4,0,0,0,4,0,0,0,0,0,0,0,0,0,0,0,0,0,0,0,0,4,0,0,0,4,0,0,0
0,0,4,0,0,0,0,0,4,0,0,0,0,0,0,0,0,0,0,0,0,0,0,4,0,0,0,0,0,4,0,0
0,0,35,0,0,0,0,0,4,0,0,0,0,0,0,0,0,0,0,0,0,0,0,4,0,0,0,0,0,35,0,0
0,0,4,0,0,0,0,0,4,0,0,0,0,0,0,0,0,0,0,0,0,0,0,4,0,0,0,0,0,4,0,0
0,0,0,4,0,0,0,4,0,0,4,4,36,4,4,0,0,4,4,36,4,4,0,0,4,0,0,0,4,0,0,0
0,0,0,0,4,4,4,0,0,4,0,0,0,0,0,4,4,0,0,0,0,0,4,0,0,4,4,4,0,0,0,0
0,0,0,0,0,0,0,0,4,0,0,0,0,0,0,4,4,0,0,0,0,0,0,4,0,0,0,0,0,0,0,0
0,0,0,0,0,0,0,4,0,0,0,0,0,0,4,0,0,4,0,0,0,0,0,0,4,0,0,0,0,0,0,0
0,0,0,0,0,0,0,4,0,0,0,0,0,0,0,0,0,0,0,0,0,0,0,0,4,0,0,0,0,0,0,0
0,0,0,0,0,0,0,36,0,0,0,0,0,0,0,0,0,0,0,0,0,0,0,0,36,0,0,0,0,0,0,0
0,0,0,0,0,0,0,4,0,0,0,0,0,0,4,0,0,4,0,0,0,0,0,0,4,0,0,0,0,0,0,0
0,0,0,0,0,0,0,4,0,0,4,0,0,4,4,0,0,4,4,0,0,4,0,0,4,0,0,0,0,0,0,0
0,0,0,0,0,0,0,0,4,4,0,0,0,0,0,0,0,0,0,0,0,0,4,4,0,0,0,0,0,0,0,0
0,0,0,0,0,0,0,0,4,4,0,0,0,0,0,0,4,0,0,0,0,0,4,4,0,0,0,0,0,0,0,0
0,0,0,0,0,0,0,4,0,0,4,0,0,4,4,0,0,4,4,0,0,4,0,0,4,0,0,0,0,0,0,0
0,0,0,0,0,0,0,4,0,0,0,0,0,0,4,0,0,4,0,0,0,0,0,0,4,0,0,0,0,0,0,0
0,0,0,0,0,0,0,36,0,0,0,0,0,0,0,0,0,0,0,0,0,0,0,0,36,0,0,0,0,0,0,0
0,0,0,0,0,0,0,4,0,0,0,0,0,0,0,0,0,0,0,0,0,0,0,0,4,0,0,0,0,0,0,0
0,0,0,0,0,0,0,4,0,0,0,0,0,0,4,0,0,4,0,0,0,0,0,0,4,0,0,0,0,0,0,0
0,0,0,0,0,0,0,0,4,0,0,0,0,0,0,4,4,0,0,0,0,0,0,4,0,0,0,0,0,0,0,0
0,0,0,0,4,4,4,0,0,4,0,0,0,0,0,4,4,0,0,0,0,0,4,0,0,4,4,4,0,0,0,0
0,0,0,4,0,0,0,4,0,0,4,4,36,4,4,0,0,4,4,36,4,4,0,0,4,0,0,0,4,0,0,0
0,0,4,0,0,0,0,0,4,0,0,0,0,0,0,0,0,0,0,0,0,0,0,4,0,0,0,0,0,4,0,0
0,0,35,0,0,0,0,0,4,0,0,0,0,0,0,0,0,0,0,0,0,0,0,4,0,0,0,0,0,35,0,0
0,0,4,0,0,0,0,0,4,0,0,0,0,0,0,0,0,0,0,0,0,0,0,4,0,0,0,0,0,4,0,0
0,0,0,4,0,0,0,4,0,0,0,0,0,0,0,0,0,0,0,0,0,0,0,0,4,0,0,0,4,0,0,0
0,0,0,0,4,34,4,0,0,0,0,0,0,0,0,0,0,0,0,0,0,0,0,0,0,4,34,4,0,0,0,0
0,0,0,0,0,0,0,0,0,0,0,0,0,0,0,0,0,0,0,0,0,0,0,0,0,0,0,0,0,0,0,0
0,0,0,0,0,0,0,0,0,0,0,0,0,0,0,0,0,0,0,0,0,0,0,0,0,0,0,0,0,0,0,0
endlayer

layer
0,0,0,0,0,0,0,0,0,0,0,0,0,0,0,0,0,0,0,0,0,0,0,0,0,0,0,0,0,0,0,0
0,0,0,0,0,0,0,0,0,0,0,0,0,0,0,0,0,0,0,0,0,0,0,0,0,0,0,0,0,0,0,0
0,0,0,0,4,34,4,0,0,0,0,0,0,0,0,0,0,0,0,0,0,0,0,0,0,4,34,4,0,0,0,0
0,0,0,4,0,0,0,4,0,0,0,0,0,0,0,0,0,0,0,0,0,0,0,0,4,0,0,0,4,0,0,0
0,0,4,0,0,0,0,0,4,0,0,0,0,0,0,0,0,0,0,0,0,0,0,4,0,0,0,0,0,4,0,0
0,0,35,0,0,0,0,0,4,0,0,0,0,0,0,0,0,0,0,0,0,0,0,4,0,0,0,0,0,35,0,0
0,0,4,0,0,0,0,0,4,0,0,0,0,0,0,0,0,0,0,0,0,0,0,4,0,0,0,0,0,4,0,0
0,0,0,4,0,0,0,4,0,0,4,4,4,4,4,0,0,4,4,4,4,4,0,0,4,0,0,0,4,0,0,0
0,0,0,0,4,4,4,0,0,4,0,0,0,0,0,4,4,0,0,0,0,0,4,0,0,4,4,4,0,0,0,0
0,0,0,0,0,0,0,0,4,0,0,0,0,0,0,4,4,0,0,0,0,0,0,4,0,0,0,0,0,0,0,0
0,0,0,0,0,0,0,4,0,0,0,0,0,0,4,0,0,4,0,0,0,0,0,0,4,0,0,0,0,0,0,0
0,0,0,0,0,0,0,4,0,0,0,0,0,0,4,0,0,4,0,0,0,0,0,0,4,0,0,0,0,0,0,0
0,0,0,0,0,0,0,4,0,0,0,0,0,0,4,0,0,4,0,0,0,0,0,0,4,0,0,0,0,0,0,0
0,0,0,0,0,0,0,4,0,0,0,0,0,0,4,0,0,4,0,0,0,0,0,0,4,0,0,0,0,0,0,0
0,0,0,0,0,0,0,4,0,0,4,4,4,4,4,17,17,4,4,4,4,4,0,0,4,0,0,0,0,0,0,0
0,0,0,0,0,0,0,0,4,4,0,0,0,0,12,0,0,12,0,0,0,0,4,4,0,0,0,0,0,0,0,0
0,0,0,0,0,0,0,0,4,4,0,0,0,0,23,4,0,12,0,0,0,0,4,4,0,0,0,0,0,0,0,0
0,0,0,0,0,0,0,4,0,0,4,4,4,4,4,20,17,4,4,4,4,4,0,0,4,0,0,0,0,0,0,0
0,0,0,0,0,0,0,4,0,0,0,0,0,0,4,0,0,4,0,0,0,0,0,0,4,0,0,0,0,0,0,0
0,0,0,0,0,0,0,4,0,0,0,0,0,0,4,0,0,4,0,0,0,0,0,0,4,0,0,0,0,0,0,0
0,0,0,0,0,0,0,4,0,0,0,0,0,0,4,0,0,4,0,0,0,0,0,0,4,0,0,0,0,0,0,0
0,0,0,0,0,0,0,4,0,0,0,0,0,0,4,0,0,4,0,0,0,0,0,0,4,0,0,0,0,0,0,0
0,0,0,0,0,0,0,0,4,0,0,0,0,0,0,4,4,0,0,0,0,0,0,4,0,0,0,0,0,0,0,0
0,0,0,0,4,4,4,0,0,4,0,0,0,0,0,4,4,0,0,0,0,0,4,0,0,4,4,4,0,0,0,0
0,0,0,4,0,0,0,4,0,0,4,4,4,4,4,0,0,4,4,4,4,4,0,0,4,0,0,0,4,0,0,0
0,0,4,0,0,0,0,0,4,0,0,0,0,0,0,0,0,0,0,0,0,0,0,4,0,0,0,0,0,4,0,0
0,0,35,0,0,0,0,0,4,0,0,0,0,0,0,0,0,0,0,0,0,0,0,4,0,0,0,0,0,35,0,0
0,0,4,0,0,0,0,0,4,0,0,0,0,0,0,0,0,0,0,0,0,0,0,4,0,0,0,0,0,4,0,0
0,0,0,4,0,0,0,4,0,0,0,0,0,0,0,0,0,0,0,0,0,0,0,0,4,0,0,0,4,0,0,0
0,0,0,0,4,34,4,0,0,0,0,0,0,0,0,0,0,0,0,0,0,0,0,0,0,4,34,4,0,0,0,0
0,0,0,0,0,0,0,0,0,0,0,0,0,0,0,0,0,0,0,0,0,0,0,0,0,0,0,0,0,0,0,0
0,0,0,0,0,0,0,0,0,0,0,0,0,0,0,0,0,0,0,0,0,0,0,0,0,0,0,0,0,0,0,0
endlayer

layer
0,0,0,0,0,0,0,0,0,0,0,0,0,0,0,0,0,0,0,0,0,0,0,0,0,0,0,0,0,0,0,0
0,0,0,0,0,0,0,0,0,0,0,0,0,0,0,0,0,0,0,0,0,0,0,0,0,0,0,0,0,0,0,0
0,0,0,0,4,4,4,0,0,0,0,0,0,0,0,0,0,0,0,0,0,0,0,0,0,4,4,4,0,0,0,0
0,0,0,4,0,0,0,4,0,0,0,0,0,0,0,0,0,0,0,0,0,0,0,0,4,0,0,0,4,0,0,0
0,0,4,0,0,0,0,0,4,0,0,0,0,0,0,0,0,0,0,0,0,0,0,4,0,0,0,0,0,4,0,0
0,0,4,0,0,0,0,4,4,0,0,0,0,0,0,0,0,0,0,0,0,0,0,4,0,0,0,0,0,4,0,0
0,0,4,0,0,0,0,0,4,0,0,0,0,0,0,0,0,0,0,0,0,0,0,4,0,0,0,0,0,4,0,0
0,0,0,4,0,0,0,4,0,0,4,4,4,4,4,0,0,4,4,4,4,4,0,0,4,0,4,0,4,0,0,0
0,0,0,0,4,4,4,0,0,4,0,0,0,0,0,4,4,0,0,0,0,0,4,0,0,4,4,4,0,0,0,0
0,0,0,0,0,0,0,0,4,0,0,0,0,0,0,4,4,0,0,0,0,0,0,4,0,0,0,0,0,0,0,0
0,0,0,0,0,0,0,4,0,0,0,0,0,0,4,0,0,4,0,0,0,0,0,0,4,0,0,0,0,0,0,0
0,0,0,0,0,0,0,4,0,0,0,0,0,0,4,0,0,4,0,0,0,0,0,0,4,0,0,0,0,0,0,0
0,0,0,0,0,0,0,4,0,0,0,0,0,0,4,0,0,4,0,0,0,0,0,0,4,0,0,0,0,0,0,0
0,0,0,0,0,0,0,4,0,0,0,0,0,0,4,0,0,4,0,0,0,0,0,0,4,0,0,0,0,0,0,0
0,0,0,0,0,0,0,4,0,0,4,4,4,4,4,21,17,4,4,4,4,4,0,0,4,0,0,0,0,0,0,0
0,0,0,0,0,0,0,0,4,4,0,0,0,0,23,4,0,12,0,0,0,0,4,4,0,0,0,0,0,0,0,0
0,0,0,0,0,0,0,0,4,4,0,0,0,0,12,0,0,12,0,0,0,0,4,4,0,0,0,0,0,0,0,0
0,0,0,0,0,0,0,4,0,0,4,4,4,4,4,17,17,4,4,4,4,4,0,0,4,0,0,0,0,0,0,0
0,0,0,0,0,0,0,4,0,0,0,0,0,0,4,0,0,4,0,0,0,0,0,0,4,0,0,0,0,0,0,0
0,0,0,0,0,0,0,4,0,0,0,0,0,0,4,0,0,4,0,0,0,0,0,0,4,0,0,0,0,0,0,0
0,0,0,0,0,0,0,4,0,0,0,0,0,0,4,0,0,4,0,0,0,0,0,0,4,0,0,0,0,0,0,0
0,0,0,0,0,0,0,4,0,0,0,0,0,0,4,0,0,4,0,0,0,0,0,0,4,0,0,0,0,0,0,0
0,0,0,0,0,0,0,0,4,0,0,0,0,0,0,4,4,0,0,0,0,0,0,4,0,0,0,0,0,0,0,0
0,0,0,0,4,4,4,0,0,4,0,0,0,0,0,4,4,0,0,0,0,0,4,0,0,4,4,4,0,0,0,0
0,0,0,4,0,4,0,4,0,0,4,4,4,4,4,0,0,4,4,4,4,4,0,0,4,0,0,0,4,0,0,0
0,0,4,0,0,0,0,0,4,0,0,0,0,0,0,0,0,0,0,0,0,0,0,4,0,0,0,0,0,4,0,0
0,0,4,0,0,0,0,0,4,0,0,0,0,0,0,0,0,0,0,0,0,0,0,4,4,0,0,0,0,4,0,0
0,0,4,0,0,0,0,0,4,0,0,0,0,0,0,0,0,0,0,0,0,0,0,4,0,0,0,0,0,4,0,0
0,0,0,4,0,0,0,4,0,0,0,0,0,0,0,0,0,0,0,0,0,0,0,0,4,0,0,0,4,0,0,0
0,0,0,0,4,4,4,0,0,0,0,0,0,0,0,0,0,0,0,0,0,0,0,0,0,4,4,4,0,0,0,0
0,0,0,0,0,0,0,0,0,0,0,0,0,0,0,0,0,0,0,0,0,0,0,0,0,0,0,0,0,0,0,0
0,0,0,0,0,0,0,0,0,0,0,0,0,0,0,0,0,0,0,0,0,0,0,0,0,0,0,0,0,0,0,0
endlayer

layer
0,0,0,0,0,0,0,0,0,0,0,0,0,0,0,0,0,0,0,0,0,0,0,0,0,0,0,0,0,0,0,0
0,0,0,0,0,0,0,0,0,0,0,0,0,0,0,0,0,0,0,0,0,0,0,0,0,0,0,0,0,0,0,0
0,0,0,39,38,38,38,37,0,0,0,0,0,0,0,0,0,0,0,0,0,0,0,0,39,38,38,38,37,0,0,0
0,0,43,42,0,0,0,41,40,0,0,0,0,0,0,0,0,0,0,0,0,0,0,43,42,0,0,0,41,40,0,0
0,0,45,0,0,0,0,0,44,0,0,0,0,0,0,0,0,0,0,0,0,0,0,45,0,0,0,0,0,44,0,0
0,0,45,0,0,0,4,4,44,0,0,0,0,0,0,0,0,0,0,0,0,0,0,45,0,0,0,0,0,44,0,0
0,0,45,0,0,0,0,0,44,0,0,0,0,0,0,0,0,0,0,0,0,0,0,45,0,0,4,0,0,44,0,0
0,0,49,48,0,0,0,47,50,0,4,4,4,4,4,0,0,4,4,4,4,4,0,49,48,0,4,0,47,46,0,0
0,0,0,52,51,51,51,50,0,4,0,0,0,0,0,4,4,0,0,0,0,0,4,0,49,51,51,51,50,0,0,0
0,0,0,0,0,0,0,0,4,0,0,0,0,0,0,4,4,0,0,0,0,0,0,4,0,0,0,0,0,0,0,0
0,0,0,0,0,0,0,4,0,0,0,0,0,0,4,0,0,4,0,0,0,0,0,0,4,0,0,0,0,0,0,0
0,0,0,0,0,0,0,4,0,0,0,0,0,0,53,0,0,53,0,0,0,0,0,0,4,0,0,0,0,0,0,0
0,0,0,0,0,0,0,4,0,0,0,0,4,0,4,0,0,4,0,4,0,0,0,0,4,0,0,0,0,0,0,0
0,0,0,0,0,0,0,4,0,0,0,0,0,0,4,0,0,4,0,0,0,0,0,0,4,0,0,0,0,0,0,0
0,0,0,0,0,0,0,4,0,0,4,53,4,4,4,17,21,4,4,4,53,4,0,0,4,0,0,0,0,0,0,0
0,0,0,0,0,0,0,0,4,4,0,0,0,0,12,0,4,24,0,0,0,0,4,4,0,0,0,0,0,0,0,0
0,0,0,0,0,0,0,0,4,4,0,0,0,0,12,0,0,12,0,0,0,0,4,4,0,0,0,0,0,0,0,0
0,0,0,0,0,0,0,4,0,0,4,53,4,4,4,17,17,4,4,4,53,4,0,0,4,0,0,0,0,0,0,0
0,0,0,0,0,0,0,4,0,0,0,0,0,0,4,0,0,4,0,0,0,0,0,0,4,0,0,0,0,0,0,0
0,0,0,0,0,0,0,4,0,0,0,0,4,0,4,0,0,4,0,4,0,0,0,0,4,0,0,0,0,0,0,0
0,0,0,0,0,0,0,4,0,0,0,0,0,0,53,0,0,53,0,0,0,0,0,0,4,0,0,0,0,0,0,0
0,0,0,0,0,0,0,4,0,0,0,0,0,0,4,0,0,4,0,0,0,0,0,0,4,0,0,0,0,0,0,0
0,0,0,0,0,0,0,0,4,0,0,0,0,0,0,4,4,0,0,0,0,0,0,4,0,0,0,0,0,0,0,0
0,0,0,39,38,38,38,40,0,4,0,0,0,0,0,4,4,0,0,0,0,0,4,0,39,38,38,38,37,0,0,0
0,0,43,42,0,4,0,41,40,0,4,4,4,4,4,0,0,4,4,4,4,4,0,39,42,0,0,0,41,40,0,0
0,0,45,0,0,4,0,0,44,0,0,0,0,0,0,0,0,0,0,0,0,0,0,45,0,0,0,0,0,44,0,0
0,0,45,0,0,0,0,0,44,0,0,0,0,0,0,0,0,0,0,0,0,0,0,45,4,4,0,0,0,44,0,0
0,0,45,0,0,0,0,0,44,0,0,0,0,0,0,0,0,0,0,0,0,0,0,45,0,0,0,0,0,44,0,0
0,0,49,48,0,0,0,47,46,0,0,0,0,0,0,0,0,0,0,0,0,0,0,49,48,0,0,0,47,46,0,0
0,0,0,52,51,51,51,50,0,0,0,0,0,0,0,0,0,0,0,0,0,0,0,0,52,51,51,51,50,0,0,0
0,0,0,0,0,0,0,0,0,0,0,0,0,0,0,0,0,0,0,0,0,0,0,0,0,0,0,0,0,0,0,0
0,0,0,0,0,0,0,0,0,0,0,0,0,0,0,0,0,0,0,0,0,0,0,0,0,0,0,0,0,0,0,0
endlayer

layer
0,0,0,0,0,0,0,0,0,0,0,0,0,0,0,0,0,0,0,0,0,0,0,0,0,0,0,0,0,0,0,0
0,0,0,0,0,0,0,0,0,0,0,0,0,0,0,0,0,0,0,0,0,0,0,0,0,0,0,0,0,0,0,0
0,0,0,0,0,0,0,0,0,0,0,0,0,0,0,0,0,0,0,0,0,0,0,0,0,0,0,0,0,0,0,0
0,0,0,0,39,38,38,0,0,0,0,0,0,0,0,0,0,0,0,0,0,0,0,0,0,39,38,38,0,0,0,0
0,0,0,45,54,4,54,44,0,0,0,0,0,0,0,0,0,0,0,0,0,0,0,0,45,54,4,54,40,0,0,0
0,0,0,45,4,4,54,44,0,0,0,0,0,0,0,0,0,0,0,0,0,0,0,0,45,4,4,4,44,0,0,0
0,0,0,49,54,4,54,44,0,0,0,0,0,0,0,0,0,0,0,0,0,0,0,0,49,54,54,54,44,0,0,0
0,0,0,0,51,51,50,0,0,0,4,4,4,4,4,0,0,4,4,4,4,4,0,0,0,51,51,51,0,0,0,0
0,0,0,0,0,0,0,0,0,4,4,4,4,4,4,4,4,4,4,4,4,4,4,0,0,0,0,0,0,0,0,0
0,0,0,0,0,0,0,0,4,4,4,4,4,4,4,4,4,4,4,4,4,4,4,4,0,0,0,0,0,0,0,0
0,0,0,0,0,0,0,4,4,4,4,4,4,4,4,4,4,4,4,4,4,4,4,4,4,0,0,0,0,0,0,0
0,0,0,0,0,0,0,4,4,4,4,4,4,4,55,4,4,55,4,4,4,4,4,4,4,0,0,0,0,0,0,0
0,0,0,0,0,0,0,4,4,4,4,4,0,4,4,4,4,4,4,0,4,4,4,4,4,0,0,0,0,0,0,0
0,0,0,0,0,0,0,4,4,4,4,4,4,4,4,4,4,4,4,4,4,4,4,4,4,0,0,0,0,0,0,0
0,0,0,0,0,0,0,4,4,4,4,55,4,4,4,4,4,4,4,4,55,4,4,4,4,0,0,0,0,0,0,0
0,0,0,0,0,0,0,0,4,4,4,4,4,4,4,0,0,4,4,4,4,4,4,4,0,0,0,0,0,0,0,0
0,0,0,0,0,0,0,0,4,4,4,4,4,4,4,0,4,4,4,4,4,4,4,4,0,0,0,0,0,0,0,0
0,0,0,0,0,0,0,4,4,4,4,55,4,4,4,4,4,4,4,4,55,4,4,4,4,0,0,0,0,0,0,0
0,0,0,0,0,0,0,4,4,4,4,4,4,4,4,4,4,4,4,4,4,4,4,4,4,0,0,0,0,0,0,0
0,0,0,0,0,0,0,4,4,4,4,4,0,4,4,4,4,4,4,0,4,4,4,4,4,0,0,0,0,0,0,0
0,0,0,0,0,0,0,4,4,4,4,4,4,4,55,4,4,55,4,4,4,4,4,4,4,0,0,0,0,0,0,0
0,0,0,0,0,0,0,4,4,4,4,4,4,4,4,4,4,4,4,4,4,4,4,4,4,0,0,0,0,0,0,0
0,0,0,0,0,0,0,0,4,4,4,4,4,4,4,4,4,4,4,4,4,4,4,4,0,0,0,0,0,0,0,0
0,0,0,0,0,0,0,0,0,4,4,4,4,4,4,4,4,4,4,4,4,4,4,0,0,0,0,0,0,0,0,0
0,0,0,0,38,38,38,0,0,0,4,4,4,4,4,0,0,4,4,4,4,4,0,0,0,39,38,38,0,0,0,0
0,0,0,45,54,54,54,40,0,0,0,0,0,0,0,0,0,0,0,0,0,0,0,0,45,54,4,54,40,0,0,0
0,0,0,45,4,4,4,44,0,0,0,0,0,0,0,0,0,0,0,0,0,0,0,0,45,54,4,4,44,0,0,0
0,0,0,49,54,4,54,44,0,0,0,0,0,0,0,0,0,0,0,0,0,0,0,0,45,54,4,54,44,0,0,0
0,0,0,0,51,51,50,0,0,0,0,0,0,0,0,0,0,0,0,0,0,0,0,0,0,51,51,50,0,0,0,0
0,0,0,0,0,0,0,0,0,0,0,0,0,0,0,0,0,0,0,0,0,0,0,0,0,0,0,0,0,0,0,0
0,0,0,0,0,0,0,0,0,0,0,0,0,0,0,0,0,0,0,0,0,0,0,0,0,0,0,0,0,0,0,0
0,0,0,0,0,0,0,0,0,0,0,0,0,0,0,0,0,0,0,0,0,0,0,0,0,0,0,0,0,0,0,0
endlayer

layer
0,0,0,0,0,0,0,0,0,0,0,0,0,0,0,0,0,0,0,0,0,0,0,0,0,0,0,0,0,0,0,0
0,0,0,0,0,0,0,0,0,0,0,0,0,0,0,0,0,0,0,0,0,0,0,0,0,0,0,0,0,0,0,0
0,0,0,0,0,0,0,0,0,0,0,0,0,0,0,0,0,0,0,0,0,0,0,0,0,0,0,0,0,0,0,0
0,0,0,0,0,0,0,0,0,0,0,0,0,0,0,0,0,0,0,0,0,0,0,0,0,0,0,0,0,0,0,0
0,0,0,0,56,54,56,0,0,0,0,0,0,0,0,0,0,0,0,0,0,0,0,0,0,56,54,56,0,0,0,0
0,0,0,0,54,4,54,0,0,0,0,0,0,0,0,0,0,0,0,0,0,0,0,0,0,54,4,54,0,0,0,0
0,0,0,0,56,54,56,0,0,0,57,0,57,0,57,0,0,57,0,57,0,57,0,0,0,56,54,56,0,0,0,0
0,0,0,0,0,0,0,0,0,0,4,17,4,17,4,0,0,4,17,4,17,4,0,0,0,0,0,0,0,0,0,0
0,0,0,0,0,0,0,0,0,0,0,0,58,0,0,0,0,0,58,0,0,58,0,0,0,0,0,0,0,0,0,0
0,0,0,0,0,0,0,0,0,0,58,0,0,58,0,0,0,58,0,0,58,0,0,0,0,0,0,0,0,0,0,0
0,0,0,0,0,0,62,4,58,0,0,58,0,4,61,0,0,60,4,0,0,0,58,0,4,59,0,0,0,0,0,0
0,0,0,0,0,0,0,12,0,58,0,0,63,4,55,0,0,55,4,4,0,58,0,0,12,0,0,0,0,0,0,0
0,0,0,0,0,0,62,4,0,0,0,4,4,4,61,0,0,60,4,4,63,0,0,58,4,59,0,0,0,0,0,0
0,0,0,0,0,0,0,12,58,0,4,4,4,53,64,58,58,64,53,4,4,4,58,0,12,0,0,0,0,0,0,0
0,0,0,0,0,0,62,4,0,58,65,55,65,64,58,64,64,58,64,65,55,65,0,0,4,59,0,0,0,0,0,0
0,0,0,0,0,0,0,0,0,0,0,0,0,58,64,0,0,64,58,0,0,0,0,0,0,0,0,0,0,0,0,0
0,0,0,0,0,0,0,0,0,0,0,0,0,58,64,0,0,64,58,0,0,0,0,0,0,0,0,0,0,0,0,0
0,0,0,0,0,0,62,4,0,0,66,55,66,64,58,64,64,58,64,66,55,66,58,0,4,59,0,0,0,0,0,0
0,0,0,0,0,0,0,12,0,58,4,4,4,53,64,58,58,64,53,4,4,4,0,58,12,0,0,0,0,0,0,0
0,0,0,0,0,0,62,4,58,0,0,63,4,4,61,0,0,60,4,4,4,0,0,0,4,59,0,0,0,0,0,0
0,0,0,0,0,0,0,12,0,0,58,0,4,4,55,0,0,55,4,63,0,0,58,0,12,0,0,0,0,0,0,0
0,0,0,0,0,0,62,4,0,58,0,0,0,4,61,0,0,60,4,0,58,0,0,58,4,59,0,0,0,0,0,0
0,0,0,0,0,0,0,0,0,0,0,58,0,0,58,0,0,0,58,0,0,58,0,0,0,0,0,0,0,0,0,0
0,0,0,0,0,0,0,0,0,0,58,0,0,58,0,0,0,0,0,58,0,0,0,0,0,0,0,0,0,0,0,0
0,0,0,0,0,0,0,0,0,0,4,17,4,17,4,0,0,4,17,4,17,4,0,0,0,0,0,0,0,0,0,0
0,0,0,0,56,54,56,0,0,0,67,0,67,0,67,0,0,67,0,67,0,67,0,0,0,56,54,56,0,0,0,0
0,0,0,0,54,4,54,0,0,0,0,0,0,0,0,0,0,0,0,0,0,0,0,0,0,54,4,54,0,0,0,0
0,0,0,0,56,54,56,0,0,0,0,0,0,0,0,0,0,0,0,0,0,0,0,0,0,56,54,56,0,0,0,0
0,0,0,0,0,0,0,0,0,0,0,0,0,0,0,0,0,0,0,0,0,0,0,0,0,0,0,0,0,0,0,0
0,0,0,0,0,0,0,0,0,0,0,0,0,0,0,0,0,0,0,0,0,0,0,0,0,0,0,0,0,0,0,0
0,0,0,0,0,0,0,0,0,0,0,0,0,0,0,0,0,0,0,0,0,0,0,0,0,0,0,0,0,0,0,0
0,0,0,0,0,0,0,0,0,0,0,0,0,0,0,0,0,0,0,0,0,0,0,0,0,0,0,0,0,0,0,0
endlayer

layer
0,0,0,0,0,0,0,0,0,0,0,0,0,0,0,0,0,0,0,0,0,0,0,0,0,0,0,0,0,0,0,0
0,0,0,0,0,0,0,0,0,0,0,0,0,0,0,0,0,0,0,0,0,0,0,0,0,0,0,0,0,0,0,0
0,0,0,0,0,0,0,0,0,0,0,0,0,0,0,0,0,0,0,0,0,0,0,0,0,0,0,0,0,0,0,0
0,0,0,0,0,0,0,0,0,0,0,0,0,0,0,0,0,0,0,0,0,0,0,0,0,0,0,0,0,0,0,0
0,0,0,0,0,38,0,0,0,0,0,0,0,0,0,0,0,0,0,0,0,0,0,0,0,0,38,0,0,0,0,0
0,0,0,0,45,4,44,0,0,0,0,0,0,0,0,0,0,0,0,0,0,0,0,0,0,45,4,44,0,0,0,0
0,0,0,0,0,51,0,0,0,0,31,0,31,0,31,0,0,31,0,31,0,31,0,0,0,0,51,0,0,0,0,0
0,0,0,0,0,0,0,0,0,0,65,30,65,30,65,0,0,65,30,65,30,65,0,0,0,0,0,0,0,0,0,0
0,0,0,0,0,0,0,0,0,0,0,0,0,0,0,0,0,0,0,0,0,0,0,0,0,0,0,0,0,0,0,0
0,0,0,0,0,0,0,0,0,0,0,0,0,0,0,0,0,0,0,0,0,0,0,0,0,0,0,0,0,0,0,0
0,0,0,0,0,0,31,61,0,0,0,0,0,4,59,0,0,62,4,0,0,0,0,0,60,31,0,0,0,0,0,0
0,0,0,0,0,0,0,30,0,0,0,0,63,4,55,0,0,55,4,4,0,0,0,0,30,0,0,0,0,0,0,0
0,0,0,0,0,0,31,61,0,0,0,4,4,4,59,0,0,62,4,4,63,0,0,0,60,31,0,0,0,0,0,0
0,0,0,0,0,0,0,30,0,0,4,4,4,53,0,0,0,0,53,4,4,4,0,0,30,0,0,0,0,0,0,0
0,0,0,0,0,0,31,61,0,0,67,55,67,0,0,0,0,0,0,67,55,67,0,0,60,31,0,0,0,0,0,0
0,0,0,0,0,0,0,0,0,0,0,0,0,0,0,0,0,0,0,0,0,0,0,0,0,0,0,0,0,0,0,0
0,0,0,0,0,0,0,0,0,0,0,0,0,0,0,0,0,0,0,0,0,0,0,0,0,0,0,0,0,0,0,0
0,0,0,0,0,0,31,61,0,0,57,55,57,0,0,0,0,0,0,57,55,57,0,0,60,31,0,0,0,0,0,0
0,0,0,0,0,0,0,30,0,0,4,4,4,53,0,0,0,0,53,4,4,4,0,0,30,0,0,0,0,0,0,0
0,0,0,0,0,0,31,61,0,0,0,63,4,4,59,0,0,62,4,4,4,0,0,0,60,31,0,0,0,0,0,0
0,0,0,0,0,0,0,30,0,0,0,0,4,4,55,0,0,55,4,63,0,0,0,0,30,0,0,0,0,0,0,0
0,0,0,0,0,0,31,61,0,0,0,0,0,4,59,0,0,62,4,0,0,0,0,0,60,31,0,0,0,0,0,0
0,0,0,0,0,0,0,0,0,0,0,0,0,0,0,0,0,0,0,0,0,0,0,0,0,0,0,0,0,0,0,0
0,0,0,0,0,0,0,0,0,0,0,0,0,0,0,0,0,0,0,0,0,0,0,0,0,0,0,0,0,0,0,0
0,0,0,0,0,0,0,0,0,0,66,30,66,30,66,0,0,66,30,66,30,66,0,0,0,0,0,0,0,0,0,0
0,0,0,0,0,38,0,0,0,0,31,0,31,0,31,0,0,31,0,31,0,31,0,0,0,0,38,0,0,0,0,0
0,0,0,0,45,4,44,0,0,0,0,0,0,0,0,0,0,0,0,0,0,0,0,0,0,45,4,44,0,0,0,0
0,0,0,0,0,51,0,0,0,0,0,0,0,0,0,0,0,0,0,0,0,0,0,0,0,0,51,0,0,0,0,0
0,0,0,0,0,0,0,0,0,0,0,0,0,0,0,0,0,0,0,0,0,0,0,0,0,0,0,0,0,0,0,0
0,0,0,0,0,0,0,0,0,0,0,0,0,0,0,0,0,0,0,0,0,0,0,0,0,0,0,0,0,0,0,0
0,0,0,0,0,0,0,0,0,0,0,0,0,0,0,0,0,0,0,0,0,0,0,0,0,0,0,0,0,0,0,0
0,0,0,0,0,0,0,0,0,0,0,0,0,0,0,0,0,0,0,0,0,0,0,0,0,0,0,0,0,0,0,0
endlayer

layer
0,0,0,0,0,0,0,0,0,0,0,0,0,0,0,0,0,0,0,0,0,0,0,0,0,0,0,0,0,0,0,0
0,0,0,0,0,0,0,0,0,0,0,0,0,0,0,0,0,0,0,0,0,0,0,0,0,0,0,0,0,0,0,0
0,0,0,0,0,0,0,0,0,0,0,0,0,0,0,0,0,0,0,0,0,0,0,0,0,0,0,0,0,0,0,0
0,0,0,0,0,0,0,0,0,0,0,0,0,0,0,0,0,0,0,0,0,0,0,0,0,0,0,0,0,0,0,0
0,0,0,0,0,0,0,0,0,0,0,0,0,0,0,0,0,0,0,0,0,0,0,0,0,0,0,0,0,0,0,0
0,0,0,0,0,63,0,0,0,0,0,0,0,0,0,0,0,0,0,0,0,0,0,0,0,0,63,0,0,0,0,0
0,0,0,0,0,0,0,0,0,0,0,0,0,0,0,0,0,0,0,0,0,0,0,0,0,0,0,0,0,0,0,0
0,0,0,0,0,0,0,0,0,0,0,0,0,0,0,0,0,0,0,0,0,0,0,0,0,0,0,0,0,0,0,0
0,0,0,0,0,0,0,0,0,0,0,0,0,0,0,0,0,0,0,0,0,0,0,0,0,0,0,0,0,0,0,0
0,0,0,0,0,0,0,0,0,0,0,0,0,0,0,0,0,0,0,0,0,0,0,0,0,0,0,0,0,0,0,0
0,0,0,0,0,0,0,0,0,0,0,0,0,4,4,0,4,4,4,0,0,0,0,0,0,0,0,0,0,0,0,0
0,0,0,0,0,0,0,0,0,0,0,0,63,4,5,4,4,5,4,4,0,0,0,0,0,0,0,0,0,0,0,0
0,0,0,0,0,0,0,0,0,0,0,4,4,4,4,0,0,4,4,4,63,0,0,0,0,0,0,0,0,0,0,0
0,0,0,0,0,0,0,0,0,0,4,4,4,53,0,0,0,0,53,4,4,4,0,0,0,0,0,0,0,0,0,0
0,0,0,0,0,0,0,0,0,0,4,5,4,0,0,0,0,0,0,4,5,4,0,0,0,0,0,0,0,0,0,0
0,0,0,0,0,0,0,0,0,0,4,4,0,0,0,0,0,0,0,0,4,0,0,0,0,0,0,0,0,0,0,0
0,0,0,0,0,0,0,0,0,0,0,4,0,0,0,0,0,0,0,0,4,4,0,0,0,0,0,0,0,0,0,0
0,0,0,0,0,0,0,0,0,0,4,5,4,0,0,0,0,0,0,4,5,4,0,0,0,0,0,0,0,0,0,0
0,0,0,0,0,0,0,0,0,0,4,4,4,53,0,0,0,0,53,4,4,4,0,0,0,0,0,0,0,0,0,0
0,0,0,0,0,0,0,0,0,0,0,63,4,4,4,0,0,4,4,4,4,0,0,0,0,0,0,0,0,0,0,0
0,0,0,0,0,0,0,0,0,0,0,0,4,4,5,4,4,5,4,63,0,0,0,0,0,0,0,0,0,0,0,0
0,0,0,0,0,0,0,0,0,0,0,0,0,4,4,4,0,4,4,0,0,0,0,0,0,0,0,0,0,0,0,0
0,0,0,0,0,0,0,0,0,0,0,0,0,0,0,0,0,0,0,0,0,0,0,0,0,0,0,0,0,0,0,0
0,0,0,0,0,0,0,0,0,0,0,0,0,0,0,0,0,0,0,0,0,0,0,0,0,0,0,0,0,0,0,0
0,0,0,0,0,0,0,0,0,0,0,0,0,0,0,0,0,0,0,0,0,0,0,0,0,0,0,0,0,0,0,0
0,0,0,0,0,0,0,0,0,0,0,0,0,0,0,0,0,0,0,0,0,0,0,0,0,0,0,0,0,0,0,0
0,0,0,0,0,63,0,0,0,0,0,0,0,0,0,0,0,0,0,0,0,0,0,0,0,0,63,0,0,0,0,0
0,0,0,0,0,0,0,0,0,0,0,0,0,0,0,0,0,0,0,0,0,0,0,0,0,0,0,0,0,0,0,0
0,0,0,0,0,0,0,0,0,0,0,0,0,0,0,0,0,0,0,0,0,0,0,0,0,0,0,0,0,0,0,0
0,0,0,0,0,0,0,0,0,0,0,0,0,0,0,0,0,0,0,0,0,0,0,0,0,0,0,0,0,0,0,0
0,0,0,0,0,0,0,0,0,0,0,0,0,0,0,0,0,0,0,0,0,0,0,0,0,0,0,0,0,0,0,0
0,0,0,0,0,0,0,0,0,0,0,0,0,0,0,0,0,0,0,0,0,0,0,0,0,0,0,0,0,0,0,0
endlayer

layer
0,0,0,0,0,0,0,0,0,0,0,0,0,0,0,0,0,0,0,0,0,0,0,0,0,0,0,0,0,0,0,0
0,0,0,0,0,0,0,0,0,0,0,0,0,0,0,0,0,0,0,0,0,0,0,0,0,0,0,0,0,0,0,0
0,0,0,0,0,0,0,0,0,0,0,0,0,0,0,0,0,0,0,0,0,0,0,0,0,0,0,0,0,0,0,0
0,0,0,0,0,0,0,0,0,0,0,0,0,0,0,0,0,0,0,0,0,0,0,0,0,0,0,0,0,0,0,0
0,0,0,0,0,0,0,0,0,0,0,0,0,0,0,0,0,0,0,0,0,0,0,0,0,0,0,0,0,0,0,0
0,0,0,0,0,63,0,0,0,0,0,0,0,0,0,0,0,0,0,0,0,0,0,0,0,0,63,0,0,0,0,0
0,0,0,0,0,0,0,0,0,0,0,0,0,0,0,0,0,0,0,0,0,0,0,0,0,0,0,0,0,0,0,0
0,0,0,0,0,0,0,0,0,0,0,0,0,0,0,0,0,0,0,0,0,0,0,0,0,0,0,0,0,0,0,0
0,0,0,0,0,0,0,0,0,0,0,0,0,0,0,0,0,0,0,0,0,0,0,0,0,0,0,0,0,0,0,0
0,0,0,0,0,0,0,0,0,0,0,0,0,0,0,0,0,0,0,0,0,0,0,0,0,0,0,0,0,0,0,0
0,0,0,0,0,0,0,0,0,0,0,0,0,63,63,68,68,68,63,0,0,0,0,0,0,0,0,0,0,0,0,0
0,0,0,0,0,0,0,0,0,0,0,0,63,4,4,4,4,4,4,63,0,0,0,0,0,0,0,0,0,0,0,0
0,0,0,0,0,0,0,0,0,0,0,63,4,4,0,0,0,0,4,4,63,0,0,0,0,0,0,0,0,0,0,0
0,0,0,0,0,0,0,0,0,0,63,4,4,53,0,0,0,0,53,4,4,63,0,0,0,0,0,0,0,0,0,0
0,0,0,0,0,0,0,0,0,0,69,4,0,0,0,0,0,0,0,0,4,63,0,0,0,0,0,0,0,0,0,0
0,0,0,0,0,0,0,0,0,0,69,4,0,0,0,0,0,0,0,0,4,69,0,0,0,0,0,0,0,0,0,0
0,0,0,0,0,0,0,0,0,0,69,4,0,0,0,0,0,0,0,0,4,69,0,0,0,0,0,0,0,0,0,0
0,0,0,0,0,0,0,0,0,0,63,4,0,0,0,0,0,0,0,0,4,69,0,0,0,0,0,0,0,0,0,0
0,0,0,0,0,0,0,0,0,0,63,4,4,53,0,0,0,0,53,4,4,63,0,0,0,0,0,0,0,0,0,0
0,0,0,0,0,0,0,0,0,0,0,63,4,4,0,0,0,0,4,4,63,0,0,0,0,0,0,0,0,0,0,0
0,0,0,0,0,0,0,0,0,0,0,0,63,4,4,4,4,4,4,63,0,0,0,0,0,0,0,0,0,0,0,0
0,0,0,0,0,0,0,0,0,0,0,0,0,63,68,68,68,63,63,0,0,0,0,0,0,0,0,0,0,0,0,0
0,0,0,0,0,0,0,0,0,0,0,0,0,0,0,0,0,0,0,0,0,0,0,0,0,0,0,0,0,0,0,0
0,0,0,0,0,0,0,0,0,0,0,0,0,0,0,0,0,0,0,0,0,0,0,0,0,0,0,0,0,0,0,0
0,0,0,0,0,0,0,0,0,0,0,0,0,0,0,0,0,0,0,0,0,0,0,0,0,0,0,0,0,0,0,0
0,0,0,0,0,0,0,0,0,0,0,0,0,0,0,0,0,0,0,0,0,0,0,0,0,0,0,0,0,0,0,0
0,0,0,0,0,63,0,0,0,0,0,0,0,0,0,0,0,0,0,0,0,0,0,0,0,0,63,0,0,0,0,0
0,0,0,0,0,0,0,0,0,0,0,0,0,0,0,0,0,0,0,0,0,0,0,0,0,0,0,0,0,0,0,0
0,0,0,0,0,0,0,0,0,0,0,0,0,0,0,0,0,0,0,0,0,0,0,0,0,0,0,0,0,0,0,0
0,0,0,0,0,0,0,0,0,0,0,0,0,0,0,0,0,0,0,0,0,0,0,0,0,0,0,0,0,0,0,0
0,0,0,0,0,0,0,0,0,0,0,0,0,0,0,0,0,0,0,0,0,0,0,0,0,0,0,0,0,0,0,0
0,0,0,0,0,0,0,0,0,0,0,0,0,0,0,0,0,0,0,0,0,0,0,0,0,0,0,0,0,0,0,0
endlayer

layer
0,0,0,0,0,0,0,0,0,0,0,0,0,0,0,0,0,0,0,0,0,0,0,0,0,0,0,0,0,0,0,0
0,0,0,0,0,0,0,0,0,0,0,0,0,0,0,0,0,0,0,0,0,0,0,0,0,0,0,0,0,0,0,0
0,0,0,0,70,0,0,0,0,0,0,0,0,0,0,0,0,0,0,0,0,0,0,0,0,0,0,0,0,0,0,0
0,0,0,0,0,71,0,0,0,0,0,0,0,0,0,0,0,0,0,0,0,0,0,0,0,0,0,0,0,0,0,0
0,0,0,0,0,70,0,0,0,0,0,0,0,0,0,0,0,0,0,0,0,0,0,0,0,0,0,0,0,70,0,0
0,0,0,0,0,63,0,0,0,0,0,0,0,0,0,0,0,0,0,0,0,0,0,0,0,0,63,70,71,0,0,0
0,0,0,0,0,0,0,0,0,0,0,0,0,0,0,0,0,0,0,0,0,0,0,0,0,0,0,0,0,0,0,0
0,0,0,0,0,0,0,0,0,0,0,0,0,0,0,0,0,0,0,0,0,0,0,0,0,0,0,0,0,0,0,0
0,0,0,0,0,0,0,0,0,0,0,0,0,0,0,0,0,0,0,0,0,0,0,0,0,0,0,0,0,0,0,0
0,0,0,0,0,0,0,0,0,0,0,0,0,0,0,0,0,0,0,0,0,0,0,0,0,0,0,0,0,0,0,0
0,0,0,0,0,0,0,0,0,0,0,0,0,4,4,4,4,4,4,0,0,0,0,0,0,0,0,0,0,0,0,0
0,0,0,0,0,0,0,0,0,0,0,0,63,4,4,4,4,4,4,4,0,0,0,0,0,0,0,0,0,0,0,0
0,0,0,0,0,0,0,0,0,0,0,4,4,4,0,0,0,0,4,4,63,0,0,0,0,0,0,0,0,0,0,0
0,0,0,0,0,0,0,0,0,0,4,4,4,53,0,0,0,0,53,4,4,4,0,0,0,0,0,0,0,0,0,0
0,0,0,0,0,0,0,0,0,0,4,4,0,0,0,0,0,0,0,0,4,4,0,0,0,0,0,0,0,0,0,0
0,0,0,0,0,0,0,0,0,0,4,4,0,0,0,0,0,0,0,0,4,4,0,0,0,0,0,0,0,0,0,0
0,0,0,0,0,0,0,0,0,0,4,4,0,0,0,0,0,0,0,0,4,4,0,0,0,0,0,0,0,0,0,0
0,0,0,0,0,0,0,0,0,0,4,4,0,0,0,0,0,0,0,0,4,4,0,0,0,0,0,0,0,0,0,0
0,0,0,0,0,0,0,0,0,0,4,4,4,53,0,0,0,0,53,4,4,4,0,0,0,0,0,0,0,0,0,0
0,0,0,0,0,0,0,0,0,0,0,63,4,4,0,0,0,0,4,4,4,0,0,0,0,0,0,0,0,0,0,0
0,0,0,0,0,0,0,0,0,0,0,0,4,4,4,4,4,4,4,63,0,0,0,0,0,0,0,0,0,0,0,0
0,0,0,0,0,0,0,0,0,0,0,0,0,4,4,4,4,4,4,0,0,0,0,0,0,0,0,0,0,0,0,0
0,0,0,0,0,0,0,0,0,0,0,0,0,0,0,0,0,0,0,0,0,0,0,0,0,0,0,0,0,0,0,0
0,0,0,0,0,0,0,0,0,0,0,0,0,0,0,0,0,0,0,0,0,0,0,0,0,0,0,0,0,0,0,0
0,0,0,0,0,0,0,0,0,0,0,0,0,0,0,0,0,0,0,0,0,0,0,0,0,0,0,0,0,0,0,0
0,0,0,0,0,0,0,0,0,0,0,0,0,0,0,0,0,0,0,0,0,0,0,0,0,0,0,0,0,0,0,0
0,0,0,71,70,63,0,0,0,0,0,0,0,0,0,0,0,0,0,0,0,0,0,0,0,0,63,0,0,0,0,0
0,0,70,0,0,0,0,0,0,0,0,0,0,0,0,0,0,0,0,0,0,0,0,0,0,0,70,0,0,0,0,0
0,0,0,0,0,0,0,0,0,0,0,0,0,0,0,0,0,0,0,0,0,0,0,0,0,0,71,0,0,0,0,0
0,0,0,0,0,0,0,0,0,0,0,0,0,0,0,0,0,0,0,0,0,0,0,0,0,0,0,70,0,0,0,0
0,0,0,0,0,0,0,0,0,0,0,0,0,0,0,0,0,0,0,0,0,0,0,0,0,0,0,0,0,0,0,0
0,0,0,0,0,0,0,0,0,0,0,0,0,0,0,0,0,0,0,0,0,0,0,0,0,0,0,0,0,0,0,0
endlayer

layer
0,0,0,0,0,0,0,0,0,0,0,0,0,0,0,0,0,0,0,0,0,0,0,0,0,0,0,0,0,0,0,0
0,0,0,0,0,0,0,0,0,0,0,0,0,0,0,0,0,0,0,0,0,0,0,0,0,0,0,0,0,0,0,0
0,0,0,0,0,0,0,0,0,0,0,0,0,0,0,0,0,0,0,0,0,0,0,0,0,0,0,0,0,0,0,0
0,0,0,0,0,0,0,0,0,0,0,0,0,0,0,0,0,0,0,0,0,0,0,0,0,0,0,0,0,0,0,0
0,0,0,0,0,70,0,0,0,0,0,0,0,0,0,0,0,0,0,0,0,0,0,0,0,0,0,0,0,0,0,0
0,0,0,0,0,72,0,0,0,0,0,0,0,0,0,0,0,0,0,0,0,0,0,0,0,0,72,70,0,0,0,0
0,0,0,0,0,0,0,0,0,0,0,0,0,0,0,0,0,0,0,0,0,0,0,0,0,0,0,0,0,0,0,0
0,0,0,0,0,0,0,0,0,0,0,0,0,0,0,0,0,0,0,0,0,0,0,0,0,0,0,0,0,0,0,0
0,0,0,0,0,0,0,0,0,0,0,0,0,0,0,0,0,0,0,0,0,0,0,0,0,0,0,0,0,0,0,0
0,0,0,0,0,0,0,0,0,0,0,0,0,0,0,0,0,0,0,0,0,0,0,0,0,0,0,0,0,0,0,0
0,0,0,0,0,0,0,0,0,0,0,0,0,4,4,4,4,4,4,0,0,0,0,0,0,0,0,0,0,0,0,0
0,0,0,0,0,0,0,0,0,0,0,0,68,4,4,4,4,4,4,4,0,0,0,0,0,0,0,0,0,0,0,0
0,0,0,0,0,0,0,0,0,0,0,4,4,4,0,0,0,0,4,4,69,0,0,0,0,0,0,0,0,0,0,0
0,0,0,0,0,0,0,0,0,0,4,4,4,53,0,0,0,0,53,4,4,4,0,0,0,0,0,0,0,0,0,0
0,0,0,0,0,0,0,0,0,0,4,4,0,0,0,0,0,0,0,0,4,4,0,0,0,0,0,0,0,0,0,0
0,0,0,0,0,0,0,0,0,0,4,4,0,0,0,0,0,0,0,0,4,4,0,0,0,0,0,0,0,0,0,0
0,0,0,0,0,0,0,0,0,0,4,4,0,0,0,0,0,0,0,0,4,4,0,0,0,0,0,0,0,0,0,0
0,0,0,0,0,0,0,0,0,0,4,4,0,0,0,0,0,0,0,0,4,4,0,0,0,0,0,0,0,0,0,0
0,0,0,0,0,0,0,0,0,0,4,4,4,53,0,0,0,0,53,4,4,4,0,0,0,0,0,0,0,0,0,0
0,0,0,0,0,0,0,0,0,0,0,69,4,4,0,0,0,0,4,4,4,0,0,0,0,0,0,0,0,0,0,0
0,0,0,0,0,0,0,0,0,0,0,0,4,4,4,4,4,4,4,68,0,0,0,0,0,0,0,0,0,0,0,0
0,0,0,0,0,0,0,0,0,0,0,0,0,4,4,4,4,4,4,0,0,0,0,0,0,0,0,0,0,0,0,0
0,0,0,0,0,0,0,0,0,0,0,0,0,0,0,0,0,0,0,0,0,0,0,0,0,0,0,0,0,0,0,0
0,0,0,0,0,0,0,0,0,0,0,0,0,0,0,0,0,0,0,0,0,0,0,0,0,0,0,0,0,0,0,0
0,0,0,0,0,0,0,0,0,0,0,0,0,0,0,0,0,0,0,0,0,0,0,0,0,0,0,0,0,0,0,0
0,0,0,0,0,0,0,0,0,0,0,0,0,0,0,0,0,0,0,0,0,0,0,0,0,0,0,0,0,0,0,0
0,0,0,0,70,72,0,0,0,0,0,0,0,0,0,0,0,0,0,0,0,0,0,0,0,0,72,0,0,0,0,0
0,0,0,0,0,0,0,0,0,0,0,0,0,0,0,0,0,0,0,0,0,0,0,0,0,0,70,0,0,0,0,0
0,0,0,0,0,0,0,0,0,0,0,0,0,0,0,0,0,0,0,0,0,0,0,0,0,0,0,0,0,0,0,0
0,0,0,0,0,0,0,0,0,0,0,0,0,0,0,0,0,0,0,0,0,0,0,0,0,0,0,0,0,0,0,0
0,0,0,0,0,0,0,0,0,0,0,0,0,0,0,0,0,0,0,0,0,0,0,0,0,0,0,0,0,0,0,0
0,0,0,0,0,0,0,0,0,0,0,0,0,0,0,0,0,0,0,0,0,0,0,0,0,0,0,0,0,0,0,0
endlayer

layer
0,0,0,0,0,0,0,0,0,0,0,0,0,0,0,0,0,0,0,0,0,0,0,0,0,0,0,0,0,0,0,0
0,0,0,0,0,0,0,0,0,0,0,0,0,0,0,0,0,0,0,0,0,0,0,0,0,0,0,0,0,0,0,0
0,0,0,0,0,0,0,0,0,0,0,0,0,0,0,0,0,0,0,0,0,0,0,0,0,0,0,0,0,0,0,0
0,0,0,0,0,0,0,0,0,0,0,0,0,0,0,0,0,0,0,0,0,0,0,0,0,0,0,0,0,0,0,0
0,0,0,0,0,0,0,0,0,0,0,0,0,0,0,0,0,0,0,0,0,0,0,0,0,0,0,0,0,0,0,0
0,0,0,0,0,0,0,0,0,0,0,0,0,0,0,0,0,0,0,0,0,0,0,0,0,0,0,0,0,0,0,0
0,0,0,0,0,0,0,0,0,0,0,0,0,0,0,0,0,0,0,0,0,0,0,0,0,0,0,0,0,0,0,0
0,0,0,0,0,0,0,0,0,0,0,0,0,0,0,0,0,0,0,0,0,0,0,0,0,0,0,0,0,0,0,0
0,0,0,0,0,0,0,0,0,0,0,0,0,0,0,0,0,0,0,0,0,0,0,0,0,0,0,0,0,0,0,0
0,0,0,0,0,0,0,0,0,0,0,0,0,0,0,0,0,0,0,0,0,0,0,0,0,0,0,0,0,0,0,0
0,0,0,0,0,0,0,0,0,0,0,0,0,4,4,4,4,4,4,0,0,0,0,0,0,0,0,0,0,0,0,0
0,0,0,0,0,0,0,0,0,0,0,0,68,4,4,4,4,4,4,4,0,0,0,0,0,0,0,0,0,0,0,0
0,0,0,0,0,0,0,0,0,0,0,4,4,4,0,0,0,0,4,4,69,0,0,0,0,0,0,0,0,0,0,0
0,0,0,0,0,0,0,0,0,0,4,4,4,53,0,0,0,0,53,4,4,4,0,0,0,0,0,0,0,0,0,0
0,0,0,0,0,0,0,0,0,0,4,4,0,0,0,0,0,0,0,0,4,4,0,0,0,0,0,0,0,0,0,0
0,0,0,0,0,0,0,0,0,0,4,4,0,0,0,0,0,0,0,0,4,4,0,0,0,0,0,0,0,0,0,0
0,0,0,0,0,0,0,0,0,0,4,4,0,0,0,0,0,0,0,0,4,4,0,0,0,0,0,0,0,0,0,0
0,0,0,0,0,0,0,0,0,0,4,4,0,0,0,0,0,0,0,0,4,4,0,0,0,0,0,0,0,0,0,0
0,0,0,0,0,0,0,0,0,0,4,4,4,53,0,0,0,0,53,4,4,4,0,0,0,0,0,0,0,0,0,0
0,0,0,0,0,0,0,0,0,0,0,69,4,4,0,0,0,0,4,4,4,0,0,0,0,0,0,0,0,0,0,0
0,0,0,0,0,0,0,0,0,0,0,0,4,4,4,4,4,4,4,68,0,0,0,0,0,0,0,0,0,0,0,0
0,0,0,0,0,0,0,0,0,0,0,0,0,4,4,4,4,4,4,0,0,0,0,0,0,0,0,0,0,0,0,0
0,0,0,0,0,0,0,0,0,0,0,0,0,0,0,0,0,0,0,0,0,0,0,0,0,0,0,0,0,0,0,0
0,0,0,0,0,0,0,0,0,0,0,0,0,0,0,0,0,0,0,0,0,0,0,0,0,0,0,0,0,0,0,0
0,0,0,0,0,0,0,0,0,0,0,0,0,0,0,0,0,0,0,0,0,0,0,0,0,0,0,0,0,0,0,0
0,0,0,0,0,0,0,0,0,0,0,0,0,0,0,0,0,0,0,0,0,0,0,0,0,0,0,0,0,0,0,0
0,0,0,0,0,0,0,0,0,0,0,0,0,0,0,0,0,0,0,0,0,0,0,0,0,0,0,0,0,0,0,0
0,0,0,0,0,0,0,0,0,0,0,0,0,0,0,0,0,0,0,0,0,0,0,0,0,0,0,0,0,0,0,0
0,0,0,0,0,0,0,0,0,0,0,0,0,0,0,0,0,0,0,0,0,0,0,0,0,0,0,0,0,0,0,0
0,0,0,0,0,0,0,0,0,0,0,0,0,0,0,0,0,0,0,0,0,0,0,0,0,0,0,0,0,0,0,0
0,0,0,0,0,0,0,0,0,0,0,0,0,0,0,0,0,0,0,0,0,0,0,0,0,0,0,0,0,0,0,0
0,0,0,0,0,0,0,0,0,0,0,0,0,0,0,0,0,0,0,0,0,0,0,0,0,0,0,0,0,0,0,0
endlayer

layer
0,0,0,0,0,0,0,0,0,0,0,0,0,0,0,0,0,0,0,0,0,0,0,0,0,0,0,0,0,0,0,0
0,0,0,0,0,0,0,0,0,0,0,0,0,0,0,0,0,0,0,0,0,0,0,0,0,0,0,0,0,0,0,0
0,0,0,0,0,0,0,0,0,0,0,0,0,0,0,0,0,0,0,0,0,0,0,0,0,0,0,0,0,0,0,0
0,0,0,0,0,0,0,0,0,0,0,0,0,0,0,0,0,0,0,0,0,0,0,0,0,0,0,0,0,0,0,0
0,0,0,0,0,0,0,0,0,0,0,0,0,0,0,0,0,0,0,0,0,0,0,0,0,0,0,0,0,0,0,0
0,0,0,0,0,0,0,0,0,0,0,0,0,0,0,0,0,0,0,0,0,0,0,0,0,0,0,0,0,0,0,0
0,0,0,0,0,0,0,0,0,0,0,0,0,0,0,0,0,0,0,0,0,0,0,0,0,0,0,0,0,0,0,0
0,0,0,0,0,0,0,0,0,0,0,0,0,0,0,0,0,0,0,0,0,0,0,0,0,0,0,0,0,0,0,0
0,0,0,0,0,0,0,0,0,0,0,0,0,0,0,0,0,0,0,0,0,0,0,0,0,0,0,0,0,0,0,0
0,0,0,0,0,0,0,0,0,0,0,0,0,54,54,54,54,54,54,0,0,0,0,0,0,0,0,0,0,0,0,0
0,0,0,0,0,0,0,0,0,0,0,0,54,4,4,4,4,4,4,54,0,0,0,0,0,0,0,0,0,0,0,0
0,0,0,0,0,0,0,0,0,0,0,54,4,4,4,4,4,4,4,4,54,0,0,0,0,0,0,0,0,0,0,0
0,0,0,0,0,0,0,0,0,0,54,4,4,4,0,0,0,0,4,4,4,54,0,0,0,0,0,0,0,0,0,0
0,0,0,0,0,0,0,0,0,54,4,4,4,53,0,0,0,0,53,4,4,4,54,0,0,0,0,0,0,0,0,0
0,0,0,0,0,0,0,0,0,54,4,4,0,0,0,0,0,0,0,0,4,4,54,0,0,0,0,0,0,0,0,0
0,0,0,0,0,0,0,0,0,54,4,4,0,0,0,0,0,0,0,0,4,4,54,0,0,0,0,0,0,0,0,0
0,0,0,0,0,0,0,0,0,54,4,4,0,0,0,0,0,0,0,0,4,4,54,0,0,0,0,0,0,0,0,0
0,0,0,0,0,0,0,0,0,54,4,4,0,0,0,0,0,0,0,0,4,4,54,0,0,0,0,0,0,0,0,0
0,0,0,0,0,0,0,0,0,54,4,4,4,53,0,0,0,0,53,4,4,4,54,0,0,0,0,0,0,0,0,0
0,0,0,0,0,0,0,0,0,0,54,4,4,4,0,0,0,0,4,4,4,54,0,0,0,0,0,0,0,0,0,0
0,0,0,0,0,0,0,0,0,0,0,54,4,4,4,4,4,4,4,4,54,0,0,0,0,0,0,0,0,0,0,0
0,0,0,0,0,0,0,0,0,0,0,0,54,4,4,4,4,4,4,54,0,0,0,0,0,0,0,0,0,0,0,0
0,0,0,0,0,0,0,0,0,0,0,0,0,54,54,54,54,54,54,0,0,0,0,0,0,0,0,0,0,0,0,0
0,0,0,0,0,0,0,0,0,0,0,0,0,0,0,0,0,0,0,0,0,0,0,0,0,0,0,0,0,0,0,0
0,0,0,0,0,0,0,0,0,0,0,0,0,0,0,0,0,0,0,0,0,0,0,0,0,0,0,0,0,0,0,0
0,0,0,0,0,0,0,0,0,0,0,0,0,0,0,0,0,0,0,0,0,0,0,0,0,0,0,0,0,0,0,0
0,0,0,0,0,0,0,0,0,0,0,0,0,0,0,0,0,0,0,0,0,0,0,0,0,0,0,0,0,0,0,0
0,0,0,0,0,0,0,0,0,0,0,0,0,0,0,0,0,0,0,0,0,0,0,0,0,0,0,0,0,0,0,0
0,0,0,0,0,0,0,0,0,0,0,0,0,0,0,0,0,0,0,0,0,0,0,0,0,0,0,0,0,0,0,0
0,0,0,0,0,0,0,0,0,0,0,0,0,0,0,0,0,0,0,0,0,0,0,0,0,0,0,0,0,0,0,0
0,0,0,0,0,0,0,0,0,0,0,0,0,0,0,0,0,0,0,0,0,0,0,0,0,0,0,0,0,0,0,0
0,0,0,0,0,0,0,0,0,0,0,0,0,0,0,0,0,0,0,0,0,0,0,0,0,0,0,0,0,0,0,0
endlayer

layer
0,0,0,0,0,0,0,0,0,0,0,0,0,0,0,0,0,0,0,0,0,0,0,0,0,0,0,0,0,0,0,0
0,0,0,0,0,0,0,0,0,0,0,0,0,0,0,0,0,0,0,0,0,0,0,0,0,0,0,0,0,0,0,0
0,0,0,0,0,0,0,0,0,0,0,0,0,0,0,0,0,0,0,0,0,0,0,0,0,0,0,0,0,0,0,0
0,0,0,0,0,0,0,0,0,0,0,0,0,0,0,0,0,0,0,0,0,0,0,0,0,0,0,0,0,0,0,0
0,0,0,0,0,0,0,0,0,0,0,0,0,0,0,0,0,0,0,0,0,0,0,0,0,0,0,0,0,0,0,0
0,0,0,0,0,0,0,0,0,0,0,0,0,0,0,0,0,0,0,0,0,0,0,0,0,0,0,0,0,0,0,0
0,0,0,0,0,0,0,0,0,0,0,0,0,0,0,0,0,0,0,0,0,0,0,0,0,0,0,0,0,0,0,0
0,0,0,0,0,0,0,0,0,0,0,0,0,0,0,0,0,0,0,0,0,0,0,0,0,0,0,0,0,0,0,0
0,0,0,0,0,0,0,0,0,0,0,0,0,0,0,0,0,0,0,0,0,0,0,0,0,0,0,0,0,0,0,0
0,0,0,0,0,0,0,0,0,0,0,0,0,0,54,54,54,54,0,0,0,0,0,0,0,0,0,0,0,0,0,0
0,0,0,0,0,0,0,0,0,0,0,0,0,54,54,54,54,54,54,0,0,0,0,0,0,0,0,0,0,0,0,0
0,0,0,0,0,0,0,0,0,0,0,0,54,54,54,54,54,54,54,54,0,0,0,0,0,0,0,0,0,0,0,0
0,0,0,0,0,0,0,0,0,0,0,54,54,54,54,0,0,54,54,54,54,0,0,0,0,0,0,0,0,0,0,0
0,0,0,0,0,0,0,0,0,0,54,54,54,53,0,0,0,0,53,54,54,54,0,0,0,0,0,0,0,0,0,0
0,0,0,0,0,0,0,0,0,54,54,54,54,0,0,0,0,0,0,54,54,54,54,0,0,0,0,0,0,0,0,0
0,0,0,0,0,0,0,0,0,54,54,54,0,0,0,0,0,0,0,0,54,54,54,0,0,0,0,0,0,0,0,0
0,0,0,0,0,0,0,0,0,54,54,54,0,0,0,0,0,0,0,0,54,54,54,0,0,0,0,0,0,0,0,0
0,0,0,0,0,0,0,0,0,54,54,54,54,0,0,0,0,0,0,54,54,54,54,0,0,0,0,0,0,0,0,0
0,0,0,0,0,0,0,0,0,0,54,54,54,53,0,0,0,0,53,54,54,54,0,0,0,0,0,0,0,0,0,0
0,0,0,0,0,0,0,0,0,0,0,54,54,54,54,0,0,54,54,54,54,0,0,0,0,0,0,0,0,0,0,0
0,0,0,0,0,0,0,0,0,0,0,0,54,54,54,54,54,54,54,54,0,0,0,0,0,0,0,0,0,0,0,0
0,0,0,0,0,0,0,0,0,0,0,0,0,54,54,54,54,54,54,0,0,0,0,0,0,0,0,0,0,0,0,0
0,0,0,0,0,0,0,0,0,0,0,0,0,0,54,54,54,54,0,0,0,0,0,0,0,0,0,0,0,0,0,0
0,0,0,0,0,0,0,0,0,0,0,0,0,0,0,0,0,0,0,0,0,0,0,0,0,0,0,0,0,0,0,0
0,0,0,0,0,0,0,0,0,0,0,0,0,0,0,0,0,0,0,0,0,0,0,0,0,0,0,0,0,0,0,0
0,0,0,0,0,0,0,0,0,0,0,0,0,0,0,0,0,0,0,0,0,0,0,0,0,0,0,0,0,0,0,0
0,0,0,0,0,0,0,0,0,0,0,0,0,0,0,0,0,0,0,0,0,0,0,0,0,0,0,0,0,0,0,0
0,0,0,0,0,0,0,0,0,0,0,0,0,0,0,0,0,0,0,0,0,0,0,0,0,0,0,0,0,0,0,0
0,0,0,0,0,0,0,0,0,0,0,0,0,0,0,0,0,0,0,0,0,0,0,0,0,0,0,0,0,0,0,0
0,0,0,0,0,0,0,0,0,0,0,0,0,0,0,0,0,0,0,0,0,0,0,0,0,0,0,0,0,0,0,0
0,0,0,0,0,0,0,0,0,0,0,0,0,0,0,0,0,0,0,0,0,0,0,0,0,0,0,0,0,0,0,0
0,0,0,0,0,0,0,0,0,0,0,0,0,0,0,0,0,0,0,0,0,0,0,0,0,0,0,0,0,0,0,0
endlayer

layer
0,0,0,0,0,0,0,0,0,0,0,0,0,0,0,0,0,0,0,0,0,0,0,0,0,0,0,0,0,0,0,0
0,0,0,0,0,0,0,0,0,0,0,0,0,0,0,0,0,0,0,0,0,0,0,0,0,0,0,0,0,0,0,0
0,0,0,0,0,0,0,0,0,0,0,0,0,0,0,0,0,0,0,0,0,0,0,0,0,0,0,0,0,0,0,0
0,0,0,0,0,0,0,0,0,0,0,0,0,0,0,0,0,0,0,0,0,0,0,0,0,0,0,0,0,0,0,0
0,0,0,0,0,0,0,0,0,0,0,0,0,0,0,0,0,0,0,0,0,0,0,0,0,0,0,0,0,0,0,0
0,0,0,0,0,0,0,0,0,0,0,0,0,0,0,0,0,0,0,0,0,0,0,0,0,0,0,0,0,0,0,0
0,0,0,0,0,0,0,0,0,0,0,0,0,0,0,0,0,0,0,0,0,0,0,0,0,0,0,0,0,0,0,0
0,0,0,0,0,0,0,0,0,0,0,0,0,0,0,0,0,0,0,0,0,0,0,0,0,0,0,0,0,0,0,0
0,0,0,0,0,0,0,0,0,0,0,0,0,0,0,0,0,0,0,0,0,0,0,0,0,0,0,0,0,0,0,0
0,0,0,0,0,0,0,0,0,0,0,0,0,0,0,0,0,0,0,0,0,0,0,0,0,0,0,0,0,0,0,0
0,0,0,0,0,0,0,0,0,0,0,0,0,0,54,54,54,54,0,0,0,0,0,0,0,0,0,0,0,0,0,0
0,0,0,0,0,0,0,0,0,0,0,0,0,54,54,54,54,54,54,0,0,0,0,0,0,0,0,0,0,0,0,0
0,0,0,0,0,0,0,0,0,0,0,0,54,54,54,54,54,54,54,54,0,0,0,0,0,0,0,0,0,0,0,0
0,0,0,0,0,0,0,0,0,0,0,54,54,54,0,0,0,0,54,54,54,0,0,0,0,0,0,0,0,0,0,0
0,0,0,0,0,0,0,0,0,0,54,54,54,0,0,0,0,0,0,54,54,54,0,0,0,0,0,0,0,0,0,0
0,0,0,0,0,0,0,0,0,0,54,54,54,0,0,0,0,0,0,54,54,54,0,0,0,0,0,0,0,0,0,0
0,0,0,0,0,0,0,0,0,0,54,54,54,0,0,0,0,0,0,54,54,54,0,0,0,0,0,0,0,0,0,0
0,0,0,0,0,0,0,0,0,0,54,54,54,0,0,0,0,0,0,54,54,54,0,0,0,0,0,0,0,0,0,0
0,0,0,0,0,0,0,0,0,0,0,54,54,54,0,0,0,0,54,54,54,0,0,0,0,0,0,0,0,0,0,0
0,0,0,0,0,0,0,0,0,0,0,0,54,54,54,54,54,54,54,54,0,0,0,0,0,0,0,0,0,0,0,0
0,0,0,0,0,0,0,0,0,0,0,0,0,54,54,54,54,54,54,0,0,0,0,0,0,0,0,0,0,0,0,0
0,0,0,0,0,0,0,0,0,0,0,0,0,0,54,54,54,54,0,0,0,0,0,0,0,0,0,0,0,0,0,0
0,0,0,0,0,0,0,0,0,0,0,0,0,0,0,0,0,0,0,0,0,0,0,0,0,0,0,0,0,0,0,0
0,0,0,0,0,0,0,0,0,0,0,0,0,0,0,0,0,0,0,0,0,0,0,0,0,0,0,0,0,0,0,0
0,0,0,0,0,0,0,0,0,0,0,0,0,0,0,0,0,0,0,0,0,0,0,0,0,0,0,0,0,0,0,0
0,0,0,0,0,0,0,0,0,0,0,0,0,0,0,0,0,0,0,0,0,0,0,0,0,0,0,0,0,0,0,0
0,0,0,0,0,0,0,0,0,0,0,0,0,0,0,0,0,0,0,0,0,0,0,0,0,0,0,0,0,0,0,0
0,0,0,0,0,0,0,0,0,0,0,0,0,0,0,0,0,0,0,0,0,0,0,0,0,0,0,0,0,0,0,0
0,0,0,0,0,0,0,0,0,0,0,0,0,0,0,0,0,0,0,0,0,0,0,0,0,0,0,0,0,0,0,0
0,0,0,0,0,0,0,0,0,0,0,0,0,0,0,0,0,0,0,0,0,0,0,0,0,0,0,0,0,0,0,0
0,0,0,0,0,0,0,0,0,0,0,0,0,0,0,0,0,0,0,0,0,0,0,0,0,0,0,0,0,0,0,0
0,0,0,0,0,0,0,0,0,0,0,0,0,0,0,0,0,0,0,0,0,0,0,0,0,0,0,0,0,0,0,0
endlayer

layer
0,0,0,0,0,0,0,0,0,0,0,0,0,0,0,0,0,0,0,0,0,0,0,0,0,0,0,0,0,0,0,0
0,0,0,0,0,0,0,0,0,0,0,0,0,0,0,0,0,0,0,0,0,0,0,0,0,0,0,0,0,0,0,0
0,0,0,0,0,0,0,0,0,0,0,0,0,0,0,0,0,0,0,0,0,0,0,0,0,0,0,0,0,0,0,0
0,0,0,0,0,0,0,0,0,0,0,0,0,0,0,0,0,0,0,0,0,0,0,0,0,0,0,0,0,0,0,0
0,0,0,0,0,0,0,0,0,0,0,0,0,0,0,0,0,0,0,0,0,0,0,0,0,0,0,0,0,0,0,0
0,0,0,0,0,0,0,0,0,0,0,0,0,0,0,0,0,0,0,0,0,0,0,0,0,0,0,0,0,0,0,0
0,0,0,0,0,0,0,0,0,0,0,0,0,0,0,0,0,0,0,0,0,0,0,0,0,0,0,0,0,0,0,0
0,0,0,0,0,0,0,0,0,0,0,0,0,0,0,0,0,0,0,0,0,0,0,0,0,0,0,0,0,0,0,0
0,0,0,0,0,0,0,0,0,0,0,0,0,0,0,0,0,0,0,0,0,0,0,0,0,0,0,0,0,0,0,0
0,0,0,0,0,0,0,0,0,0,0,0,0,0,0,0,0,0,0,0,0,0,0,0,0,0,0,0,0,0,0,0
0,0,0,0,0,0,0,0,0,0,0,0,0,0,0,0,0,0,0,0,0,0,0,0,0,0,0,0,0,0,0,0
0,0,0,0,0,0,0,0,0,0,0,0,0,0,0,54,54,0,0,0,0,0,0,0,0,0,0,0,0,0,0,0
0,0,0,0,0,0,0,0,0,0,0,0,0,54,54,54,54,54,54,0,0,0,0,0,0,0,0,0,0,0,0,0
0,0,0,0,0,0,0,0,0,0,0,0,54,54,54,54,54,54,54,54,0,0,0,0,0,0,0,0,0,0,0,0
0,0,0,0,0,0,0,0,0,0,0,0,54,54,54,0,0,54,54,54,0,0,0,0,0,0,0,0,0,0,0,0
0,0,0,0,0,0,0,0,0,0,0,54,54,54,0,0,0,0,54,54,54,0,0,0,0,0,0,0,0,0,0,0
0,0,0,0,0,0,0,0,0,0,0,54,54,54,0,0,0,0,54,54,54,0,0,0,0,0,0,0,0,0,0,0
0,0,0,0,0,0,0,0,0,0,0,0,54,54,54,0,0,54,54,54,0,0,0,0,0,0,0,0,0,0,0,0
0,0,0,0,0,0,0,0,0,0,0,0,54,54,54,54,54,54,54,54,0,0,0,0,0,0,0,0,0,0,0,0
0,0,0,0,0,0,0,0,0,0,0,0,0,54,54,54,54,54,54,0,0,0,0,0,0,0,0,0,0,0,0,0
0,0,0,0,0,0,0,0,0,0,0,0,0,0,0,54,54,0,0,0,0,0,0,0,0,0,0,0,0,0,0,0
0,0,0,0,0,0,0,0,0,0,0,0,0,0,0,0,0,0,0,0,0,0,0,0,0,0,0,0,0,0,0,0
0,0,0,0,0,0,0,0,0,0,0,0,0,0,0,0,0,0,0,0,0,0,0,0,0,0,0,0,0,0,0,0
0,0,0,0,0,0,0,0,0,0,0,0,0,0,0,0,0,0,0,0,0,0,0,0,0,0,0,0,0,0,0,0
0,0,0,0,0,0,0,0,0,0,0,0,0,0,0,0,0,0,0,0,0,0,0,0,0,0,0,0,0,0,0,0
0,0,0,0,0,0,0,0,0,0,0,0,0,0,0,0,0,0,0,0,0,0,0,0,0,0,0,0,0,0,0,0
0,0,0,0,0,0,0,0,0,0,0,0,0,0,0,0,0,0,0,0,0,0,0,0,0,0,0,0,0,0,0,0
0,0,0,0,0,0,0,0,0,0,0,0,0,0,0,0,0,0,0,0,0,0,0,0,0,0,0,0,0,0,0,0
0,0,0,0,0,0,0,0,0,0,0,0,0,0,0,0,0,0,0,0,0,0,0,0,0,0,0,0,0,0,0,0
0,0,0,0,0,0,0,0,0,0,0,0,0,0,0,0,0,0,0,0,0,0,0,0,0,0,0,0,0,0,0,0
0,0,0,0,0,0,0,0,0,0,0,0,0,0,0,0,0,0,0,0,0,0,0,0,0,0,0,0,0,0,0,0
0,0,0,0,0,0,0,0,0,0,0,0,0,0,0,0,0,0,0,0,0,0,0,0,0,0,0,0,0,0,0,0
endlayer

layer
0,0,0,0,0,0,0,0,0,0,0,0,0,0,0,0,0,0,0,0,0,0,0,0,0,0,0,0,0,0,0,0
0,0,0,0,0,0,0,0,0,0,0,0,0,0,0,0,0,0,0,0,0,0,0,0,0,0,0,0,0,0,0,0
0,0,0,0,0,0,0,0,0,0,0,0,0,0,0,0,0,0,0,0,0,0,0,0,0,0,0,0,0,0,0,0
0,0,0,0,0,0,0,0,0,0,0,0,0,0,0,0,0,0,0,0,0,0,0,0,0,0,0,0,0,0,0,0
0,0,0,0,0,0,0,0,0,0,0,0,0,0,0,0,0,0,0,0,0,0,0,0,0,0,0,0,0,0,0,0
0,0,0,0,0,0,0,0,0,0,0,0,0,0,0,0,0,0,0,0,0,0,0,0,0,0,0,0,0,0,0,0
0,0,0,0,0,0,0,0,0,0,0,0,0,0,0,0,0,0,0,0,0,0,0,0,0,0,0,0,0,0,0,0
0,0,0,0,0,0,0,0,0,0,0,0,0,0,0,0,0,0,0,0,0,0,0,0,0,0,0,0,0,0,0,0
0,0,0,0,0,0,0,0,0,0,0,0,0,0,0,0,0,0,0,0,0,0,0,0,0,0,0,0,0,0,0,0
0,0,0,0,0,0,0,0,0,0,0,0,0,0,0,0,0,0,0,0,0,0,0,0,0,0,0,0,0,0,0,0
0,0,0,0,0,0,0,0,0,0,0,0,0,0,0,0,0,0,0,0,0,0,0,0,0,0,0,0,0,0,0,0
0,0,0,0,0,0,0,0,0,0,0,0,0,0,0,0,0,0,0,0,0,0,0,0,0,0,0,0,0,0,0,0
0,0,0,0,0,0,0,0,0,0,0,0,0,0,0,54,54,0,0,0,0,0,0,0,0,0,0,0,0,0,0,0
0,0,0,0,0,0,0,0,0,0,0,0,0,54,54,54,54,54,54,0,0,0,0,0,0,0,0,0,0,0,0,0
0,0,0,0,0,0,0,0,0,0,0,0,0,54,54,54,54,54,54,0,0,0,0,0,0,0,0,0,0,0,0,0
0,0,0,0,0,0,0,0,0,0,0,0,54,54,54,0,0,54,54,54,0,0,0,0,0,0,0,0,0,0,0,0
0,0,0,0,0,0,0,0,0,0,0,0,54,54,54,0,0,54,54,54,0,0,0,0,0,0,0,0,0,0,0,0
0,0,0,0,0,0,0,0,0,0,0,0,0,54,54,54,54,54,54,0,0,0,0,0,0,0,0,0,0,0,0,0
0,0,0,0,0,0,0,0,0,0,0,0,0,54,54,54,54,54,54,0,0,0,0,0,0,0,0,0,0,0,0,0
0,0,0,0,0,0,0,0,0,0,0,0,0,0,0,54,54,0,0,0,0,0,0,0,0,0,0,0,0,0,0,0
0,0,0,0,0,0,0,0,0,0,0,0,0,0,0,0,0,0,0,0,0,0,0,0,0,0,0,0,0,0,0,0
0,0,0,0,0,0,0,0,0,0,0,0,0,0,0,0,0,0,0,0,0,0,0,0,0,0,0,0,0,0,0,0
0,0,0,0,0,0,0,0,0,0,0,0,0,0,0,0,0,0,0,0,0,0,0,0,0,0,0,0,0,0,0,0
0,0,0,0,0,0,0,0,0,0,0,0,0,0,0,0,0,0,0,0,0,0,0,0,0,0,0,0,0,0,0,0
0,0,0,0,0,0,0,0,0,0,0,0,0,0,0,0,0,0,0,0,0,0,0,0,0,0,0,0,0,0,0,0
0,0,0,0,0,0,0,0,0,0,0,0,0,0,0,0,0,0,0,0,0,0,0,0,0,0,0,0,0,0,0,0
0,0,0,0,0,0,0,0,0,0,0,0,0,0,0,0,0,0,0,0,0,0,0,0,0,0,0,0,0,0,0,0
0,0,0,0,0,0,0,0,0,0,0,0,0,0,0,0,0,0,0,0,0,0,0,0,0,0,0,0,0,0,0,0
0,0,0,0,0,0,0,0,0,0,0,0,0,0,0,0,0,0,0,0,0,0,0,0,0,0,0,0,0,0,0,0
0,0,0,0,0,0,0,0,0,0,0,0,0,0,0,0,0,0,0,0,0,0,0,0,0,0,0,0,0,0,0,0
0,0,0,0,0,0,0,0,0,0,0,0,0,0,0,0,0,0,0,0,0,0,0,0,0,0,0,0,0,0,0,0
0,0,0,0,0,0,0,0,0,0,0,0,0,0,0,0,0,0,0,0,0,0,0,0,0,0,0,0,0,0,0,0
endlayer

layer
0,0,0,0,0,0,0,0,0,0,0,0,0,0,0,0,0,0,0,0,0,0,0,0,0,0,0,0,0,0,0,0
0,0,0,0,0,0,0,0,0,0,0,0,0,0,0,0,0,0,0,0,0,0,0,0,0,0,0,0,0,0,0,0
0,0,0,0,0,0,0,0,0,0,0,0,0,0,0,0,0,0,0,0,0,0,0,0,0,0,0,0,0,0,0,0
0,0,0,0,0,0,0,0,0,0,0,0,0,0,0,0,0,0,0,0,0,0,0,0,0,0,0,0,0,0,0,0
0,0,0,0,0,0,0,0,0,0,0,0,0,0,0,0,0,0,0,0,0,0,0,0,0,0,0,0,0,0,0,0
0,0,0,0,0,0,0,0,0,0,0,0,0,0,0,0,0,0,0,0,0,0,0,0,0,0,0,0,0,0,0,0
0,0,0,0,0,0,0,0,0,0,0,0,0,0,0,0,0,0,0,0,0,0,0,0,0,0,0,0,0,0,0,0
0,0,0,0,0,0,0,0,0,0,0,0,0,0,0,0,0,0,0,0,0,0,0,0,0,0,0,0,0,0,0,0
0,0,0,0,0,0,0,0,0,0,0,0,0,0,0,0,0,0,0,0,0,0,0,0,0,0,0,0,0,0,0,0
0,0,0,0,0,0,0,0,0,0,0,0,0,0,0,0,0,0,0,0,0,0,0,0,0,0,0,0,0,0,0,0
0,0,0,0,0,0,0,0,0,0,0,0,0,0,0,0,0,0,0,0,0,0,0,0,0,0,0,0,0,0,0,0
0,0,0,0,0,0,0,0,0,0,0,0,0,0,0,0,0,0,0,0,0,0,0,0,0,0,0,0,0,0,0,0
0,0,0,0,0,0,0,0,0,0,0,0,0,0,0,0,0,0,0,0,0,0,0,0,0,0,0,0,0,0,0,0
0,0,0,0,0,0,0,0,0,0,0,0,0,0,54,54,54,54,0,0,0,0,0,0,0,0,0,0,0,0,0,0
0,0,0,0,0,0,0,0,0,0,0,0,0,54,54,54,54,54,54,0,0,0,0,0,0,0,0,0,0,0,0,0
0,0,0,0,0,0,0,0,0,0,0,0,0,54,54,54,54,54,54,0,0,0,0,0,0,0,0,0,0,0,0,0
0,0,0,0,0,0,0,0,0,0,0,0,0,54,54,54,54,54,54,0,0,0,0,0,0,0,0,0,0,0,0,0
0,0,0,0,0,0,0,0,0,0,0,0,0,54,54,54,54,54,54,0,0,0,0,0,0,0,0,0,0,0,0,0
0,0,0,0,0,0,0,0,0,0,0,0,0,0,54,54,54,54,0,0,0,0,0,0,0,0,0,0,0,0,0,0
0,0,0,0,0,0,0,0,0,0,0,0,0,0,0,0,0,0,0,0,0,0,0,0,0,0,0,0,0,0,0,0
0,0,0,0,0,0,0,0,0,0,0,0,0,0,0,0,0,0,0,0,0,0,0,0,0,0,0,0,0,0,0,0
0,0,0,0,0,0,0,0,0,0,0,0,0,0,0,0,0,0,0,0,0,0,0,0,0,0,0,0,0,0,0,0
0,0,0,0,0,0,0,0,0,0,0,0,0,0,0,0,0,0,0,0,0,0,0,0,0,0,0,0,0,0,0,0
0,0,0,0,0,0,0,0,0,0,0,0,0,0,0,0,0,0,0,0,0,0,0,0,0,0,0,0,0,0,0,0
0,0,0,0,0,0,0,0,0,0,0,0,0,0,0,0,0,0,0,0,0,0,0,0,0,0,0,0,0,0,0,0
0,0,0,0,0,0,0,0,0,0,0,0,0,0,0,0,0,0,0,0,0,0,0,0,0,0,0,0,0,0,0,0
0,0,0,0,0,0,0,0,0,0,0,0,0,0,0,0,0,0,0,0,0,0,0,0,0,0,0,0,0,0,0,0
0,0,0,0,0,0,0,0,0,0,0,0,0,0,0,0,0,0,0,0,0,0,0,0,0,0,0,0,0,0,0,0
0,0,0,0,0,0,0,0,0,0,0,0,0,0,0,0,0,0,0,0,0,0,0,0,0,0,0,0,0,0,0,0
0,0,0,0,0,0,0,0,0,0,0,0,0,0,0,0,0,0,0,0,0,0,0,0,0,0,0,0,0,0,0,0
0,0,0,0,0,0,0,0,0,0,0,0,0,0,0,0,0,0,0,0,0,0,0,0,0,0,0,0,0,0,0,0
0,0,0,0,0,0,0,0,0,0,0,0,0,0,0,0,0,0,0,0,0,0,0,0,0,0,0,0,0,0,0,0
endlayer

layer
0,0,0,0,0,0,0,0,0,0,0,0,0,0,0,0,0,0,0,0,0,0,0,0,0,0,0,0,0,0,0,0
0,0,0,0,0,0,0,0,0,0,0,0,0,0,0,0,0,0,0,0,0,0,0,0,0,0,0,0,0,0,0,0
0,0,0,0,0,0,0,0,0,0,0,0,0,0,0,0,0,0,0,0,0,0,0,0,0,0,0,0,0,0,0,0
0,0,0,0,0,0,0,0,0,0,0,0,0,0,0,0,0,0,0,0,0,0,0,0,0,0,0,0,0,0,0,0
0,0,0,0,0,0,0,0,0,0,0,0,0,0,0,0,0,0,0,0,0,0,0,0,0,0,0,0,0,0,0,0
0,0,0,0,0,0,0,0,0,0,0,0,0,0,0,0,0,0,0,0,0,0,0,0,0,0,0,0,0,0,0,0
0,0,0,0,0,0,0,0,0,0,0,0,0,0,0,0,0,0,0,0,0,0,0,0,0,0,0,0,0,0,0,0
0,0,0,0,0,0,0,0,0,0,0,0,0,0,0,0,0,0,0,0,0,0,0,0,0,0,0,0,0,0,0,0
0,0,0,0,0,0,0,0,0,0,0,0,0,0,0,0,0,0,0,0,0,0,0,0,0,0,0,0,0,0,0,0
0,0,0,0,0,0,0,0,0,0,0,0,0,0,0,0,0,0,0,0,0,0,0,0,0,0,0,0,0,0,0,0
0,0,0,0,0,0,0,0,0,0,0,0,0,0,0,0,0,0,0,0,0,0,0,0,0,0,0,0,0,0,0,0
0,0,0,0,0,0,0,0,0,0,0,0,0,0,0,0,0,0,0,0,0,0,0,0,0,0,0,0,0,0,0,0
0,0,0,0,0,0,0,0,0,0,0,0,0,0,0,0,0,0,0,0,0,0,0,0,0,0,0,0,0,0,0,0
0,0,0,0,0,0,0,0,0,0,0,0,0,0,0,54,54,0,0,0,0,0,0,0,0,0,0,0,0,0,0,0
0,0,0,0,0,0,0,0,0,0,0,0,0,0,54,54,54,54,0,0,0,0,0,0,0,0,0,0,0,0,0,0
0,0,0,0,0,0,0,0,0,0,0,0,0,54,54,54,54,54,54,0,0,0,0,0,0,0,0,0,0,0,0,0
0,0,0,0,0,0,0,0,0,0,0,0,0,54,54,54,54,54,54,0,0,0,0,0,0,0,0,0,0,0,0,0
0,0,0,0,0,0,0,0,0,0,0,0,0,0,54,54,54,54,0,0,0,0,0,0,0,0,0,0,0,0,0,0
0,0,0,0,0,0,0,0,0,0,0,0,0,0,0,54,54,0,0,0,0,0,0,0,0,0,0,0,0,0,0,0
0,0,0,0,0,0,0,0,0,0,0,0,0,0,0,0,0,0,0,0,0,0,0,0,0,0,0,0,0,0,0,0
0,0,0,0,0,0,0,0,0,0,0,0,0,0,0,0,0,0,0,0,0,0,0,0,0,0,0,0,0,0,0,0
0,0,0,0,0,0,0,0,0,0,0,0,0,0,0,0,0,0,0,0,0,0,0,0,0,0,0,0,0,0,0,0
0,0,0,0,0,0,0,0,0,0,0,0,0,0,0,0,0,0,0,0,0,0,0,0,0,0,0,0,0,0,0,0
0,0,0,0,0,0,0,0,0,0,0,0,0,0,0,0,0,0,0,0,0,0,0,0,0,0,0,0,0,0,0,0
0,0,0,0,0,0,0,0,0,0,0,0,0,0,0,0,0,0,0,0,0,0,0,0,0,0,0,0,0,0,0,0
0,0,0,0,0,0,0,0,0,0,0,0,0,0,0,0,0,0,0,0,0,0,0,0,0,0,0,0,0,0,0,0
0,0,0,0,0,0,0,0,0,0,0,0,0,0,0,0,0,0,0,0,0,0,0,0,0,0,0,0,0,0,0,0
0,0,0,0,0,0,0,0,0,0,0,0,0,0,0,0,0,0,0,0,0,0,0,0,0,0,0,0,0,0,0,0
0,0,0,0,0,0,0,0,0,0,0,0,0,0,0,0,0,0,0,0,0,0,0,0,0,0,0,0,0,0,0,0
0,0,0,0,0,0,0,0,0,0,0,0,0,0,0,0,0,0,0,0,0,0,0,0,0,0,0,0,0,0,0,0
0,0,0,0,0,0,0,0,0,0,0,0,0,0,0,0,0,0,0,0,0,0,0,0,0,0,0,0,0,0,0,0
0,0,0,0,0,0,0,0,0,0,0,0,0,0,0,0,0,0,0,0,0,0,0,0,0,0,0,0,0,0,0,0
endlayer

layer
0,0,0,0,0,0,0,0,0,0,0,0,0,0,0,0,0,0,0,0,0,0,0,0,0,0,0,0,0,0,0,0
0,0,0,0,0,0,0,0,0,0,0,0,0,0,0,0,0,0,0,0,0,0,0,0,0,0,0,0,0,0,0,0
0,0,0,0,0,0,0,0,0,0,0,0,0,0,0,0,0,0,0,0,0,0,0,0,0,0,0,0,0,0,0,0
0,0,0,0,0,0,0,0,0,0,0,0,0,0,0,0,0,0,0,0,0,0,0,0,0,0,0,0,0,0,0,0
0,0,0,0,0,0,0,0,0,0,0,0,0,0,0,0,0,0,0,0,0,0,0,0,0,0,0,0,0,0,0,0
0,0,0,0,0,0,0,0,0,0,0,0,0,0,0,0,0,0,0,0,0,0,0,0,0,0,0,0,0,0,0,0
0,0,0,0,0,0,0,0,0,0,0,0,0,0,0,0,0,0,0,0,0,0,0,0,0,0,0,0,0,0,0,0
0,0,0,0,0,0,0,0,0,0,0,0,0,0,0,0,0,0,0,0,0,0,0,0,0,0,0,0,0,0,0,0
0,0,0,0,0,0,0,0,0,0,0,0,0,0,0,0,0,0,0,0,0,0,0,0,0,0,0,0,0,0,0,0
0,0,0,0,0,0,0,0,0,0,0,0,0,0,0,0,0,0,0,0,0,0,0,0,0,0,0,0,0,0,0,0
0,0,0,0,0,0,0,0,0,0,0,0,0,0,0,0,0,0,0,0,0,0,0,0,0,0,0,0,0,0,0,0
0,0,0,0,0,0,0,0,0,0,0,0,0,0,0,0,0,0,0,0,0,0,0,0,0,0,0,0,0,0,0,0
0,0,0,0,0,0,0,0,0,0,0,0,0,0,0,0,0,0,0,0,0,0,0,0,0,0,0,0,0,0,0,0
0,0,0,0,0,0,0,0,0,0,0,0,0,0,0,0,0,0,0,0,0,0,0,0,0,0,0,0,0,0,0,0
0,0,0,0,0,0,0,0,0,0,0,0,0,0,0,54,54,0,0,0,0,0,0,0,0,0,0,0,0,0,0,0
0,0,0,0,0,0,0,0,0,0,0,0,0,0,54,54,54,54,0,0,0,0,0,0,0,0,0,0,0,0,0,0
0,0,0,0,0,0,0,0,0,0,0,0,0,0,54,54,54,54,0,0,0,0,0,0,0,0,0,0,0,0,0,0
0,0,0,0,0,0,0,0,0,0,0,0,0,0,0,54,54,0,0,0,0,0,0,0,0,0,0,0,0,0,0,0
0,0,0,0,0,0,0,0,0,0,0,0,0,0,0,0,0,0,0,0,0,0,0,0,0,0,0,0,0,0,0,0
0,0,0,0,0,0,0,0,0,0,0,0,0,0,0,0,0,0,0,0,0,0,0,0,0,0,0,0,0,0,0,0
0,0,0,0,0,0,0,0,0,0,0,0,0,0,0,0,0,0,0,0,0,0,0,0,0,0,0,0,0,0,0,0
0,0,0,0,0,0,0,0,0,0,0,0,0,0,0,0,0,0,0,0,0,0,0,0,0,0,0,0,0,0,0,0
0,0,0,0,0,0,0,0,0,0,0,0,0,0,0,0,0,0,0,0,0,0,0,0,0,0,0,0,0,0,0,0
0,0,0,0,0,0,0,0,0,0,0,0,0,0,0,0,0,0,0,0,0,0,0,0,0,0,0,0,0,0,0,0
0,0,0,0,0,0,0,0,0,0,0,0,0,0,0,0,0,0,0,0,0,0,0,0,0,0,0,0,0,0,0,0
0,0,0,0,0,0,0,0,0,0,0,0,0,0,0,0,0,0,0,0,0,0,0,0,0,0,0,0,0,0,0,0
0,0,0,0,0,0,0,0,0,0,0,0,0,0,0,0,0,0,0,0,0,0,0,0,0,0,0,0,0,0,0,0
0,0,0,0,0,0,0,0,0,0,0,0,0,0,0,0,0,0,0,0,0,0,0,0,0,0,0,0,0,0,0,0
0,0,0,0,0,0,0,0,0,0,0,0,0,0,0,0,0,0,0,0,0,0,0,0,0,0,0,0,0,0,0,0
0,0,0,0,0,0,0,0,0,0,0,0,0,0,0,0,0,0,0,0,0,0,0,0,0,0,0,0,0,0,0,0
0,0,0,0,0,0,0,0,0,0,0,0,0,0,0,0,0,0,0,0,0,0,0,0,0,0,0,0,0,0,0,0
0,0,0,0,0,0,0,0,0,0,0,0,0,0,0,0,0,0,0,0,0,0,0,0,0,0,0,0,0,0,0,0
endlayer

layer
0,0,0,0,0,0,0,0,0,0,0,0,0,0,0,0,0,0,0,0,0,0,0,0,0,0,0,0,0,0,0,0
0,0,0,0,0,0,0,0,0,0,0,0,0,0,0,0,0,0,0,0,0,0,0,0,0,0,0,0,0,0,0,0
0,0,0,0,0,0,0,0,0,0,0,0,0,0,0,0,0,0,0,0,0,0,0,0,0,0,0,0,0,0,0,0
0,0,0,0,0,0,0,0,0,0,0,0,0,0,0,0,0,0,0,0,0,0,0,0,0,0,0,0,0,0,0,0
0,0,0,0,0,0,0,0,0,0,0,0,0,0,0,0,0,0,0,0,0,0,0,0,0,0,0,0,0,0,0,0
0,0,0,0,0,0,0,0,0,0,0,0,0,0,0,0,0,0,0,0,0,0,0,0,0,0,0,0,0,0,0,0
0,0,0,0,0,0,0,0,0,0,0,0,0,0,0,0,0,0,0,0,0,0,0,0,0,0,0,0,0,0,0,0
0,0,0,0,0,0,0,0,0,0,0,0,0,0,0,0,0,0,0,0,0,0,0,0,0,0,0,0,0,0,0,0
0,0,0,0,0,0,0,0,0,0,0,0,0,0,0,0,0,0,0,0,0,0,0,0,0,0,0,0,0,0,0,0
0,0,0,0,0,0,0,0,0,0,0,0,0,0,0,0,0,0,0,0,0,0,0,0,0,0,0,0,0,0,0,0
0,0,0,0,0,0,0,0,0,0,0,0,0,0,0,0,0,0,0,0,0,0,0,0,0,0,0,0,0,0,0,0
0,0,0,0,0,0,0,0,0,0,0,0,0,0,0,0,0,0,0,0,0,0,0,0,0,0,0,0,0,0,0,0
0,0,0,0,0,0,0,0,0,0,0,0,0,0,0,0,0,0,0,0,0,0,0,0,0,0,0,0,0,0,0,0
0,0,0,0,0,0,0,0,0,0,0,0,0,0,0,0,0,0,0,0,0,0,0,0,0,0,0,0,0,0,0,0
0,0,0,0,0,0,0,0,0,0,0,0,0,0,0,54,54,0,0,0,0,0,0,0,0,0,0,0,0,0,0,0
0,0,0,0,0,0,0,0,0,0,0,0,0,0,54,63,63,54,0,0,0,0,0,0,0,0,0,0,0,0,0,0
0,0,0,0,0,0,0,0,0,0,0,0,0,0,54,63,63,54,0,0,0,0,0,0,0,0,0,0,0,0,0,0
0,0,0,0,0,0,0,0,0,0,0,0,0,0,0,54,54,0,0,0,0,0,0,0,0,0,0,0,0,0,0,0
0,0,0,0,0,0,0,0,0,0,0,0,0,0,0,0,0,0,0,0,0,0,0,0,0,0,0,0,0,0,0,0
0,0,0,0,0,0,0,0,0,0,0,0,0,0,0,0,0,0,0,0,0,0,0,0,0,0,0,0,0,0,0,0
0,0,0,0,0,0,0,0,0,0,0,0,0,0,0,0,0,0,0,0,0,0,0,0,0,0,0,0,0,0,0,0
0,0,0,0,0,0,0,0,0,0,0,0,0,0,0,0,0,0,0,0,0,0,0,0,0,0,0,0,0,0,0,0
0,0,0,0,0,0,0,0,0,0,0,0,0,0,0,0,0,0,0,0,0,0,0,0,0,0,0,0,0,0,0,0
0,0,0,0,0,0,0,0,0,0,0,0,0,0,0,0,0,0,0,0,0,0,0,0,0,0,0,0,0,0,0,0
0,0,0,0,0,0,0,0,0,0,0,0,0,0,0,0,0,0,0,0,0,0,0,0,0,0,0,0,0,0,0,0
0,0,0,0,0,0,0,0,0,0,0,0,0,0,0,0,0,0,0,0,0,0,0,0,0,0,0,0,0,0,0,0
0,0,0,0,0,0,0,0,0,0,0,0,0,0,0,0,0,0,0,0,0,0,0,0,0,0,0,0,0,0,0,0
0,0,0,0,0,0,0,0,0,0,0,0,0,0,0,0,0,0,0,0,0,0,0,0,0,0,0,0,0,0,0,0
0,0,0,0,0,0,0,0,0,0,0,0,0,0,0,0,0,0,0,0,0,0,0,0,0,0,0,0,0,0,0,0
0,0,0,0,0,0,0,0,0,0,0,0,0,0,0,0,0,0,0,0,0,0,0,0,0,0,0,0,0,0,0,0
0,0,0,0,0,0,0,0,0,0,0,0,0,0,0,0,0,0,0,0,0,0,0,0,0,0,0,0,0,0,0,0
0,0,0,0,0,0,0,0,0,0,0,0,0,0,0,0,0,0,0,0,0,0,0,0,0,0,0,0,0,0,0,0
endlayer

layer
0,0,0,0,0,0,0,0,0,0,0,0,0,0,0,0,0,0,0,0,0,0,0,0,0,0,0,0,0,0,0,0
0,0,0,0,0,0,0,0,0,0,0,0,0,0,0,0,0,0,0,0,0,0,0,0,0,0,0,0,0,0,0,0
0,0,0,0,0,0,0,0,0,0,0,0,0,0,0,0,0,0,0,0,0,0,0,0,0,0,0,0,0,0,0,0
0,0,0,0,0,0,0,0,0,0,0,0,0,0,0,0,0,0,0,0,0,0,0,0,0,0,0,0,0,0,0,0
0,0,0,0,0,0,0,0,0,0,0,0,0,0,0,0,0,0,0,0,0,0,0,0,0,0,0,0,0,0,0,0
0,0,0,0,0,0,0,0,0,0,0,0,0,0,0,0,0,0,0,0,0,0,0,0,0,0,0,0,0,0,0,0
0,0,0,0,0,0,0,0,0,0,0,0,0,0,0,0,0,0,0,0,0,0,0,0,0,0,0,0,0,0,0,0
0,0,0,0,0,0,0,0,0,0,0,0,0,0,0,0,0,0,0,0,0,0,0,0,0,0,0,0,0,0,0,0
0,0,0,0,0,0,0,0,0,0,0,0,0,0,0,0,0,0,0,0,0,0,0,0,0,0,0,0,0,0,0,0
0,0,0,0,0,0,0,0,0,0,0,0,0,0,0,0,0,0,0,0,0,0,0,0,0,0,0,0,0,0,0,0
0,0,0,0,0,0,0,0,0,0,0,0,0,0,0,0,0,0,0,0,0,0,0,0,0,0,0,0,0,0,0,0
0,0,0,0,0,0,0,0,0,0,0,0,0,0,0,0,0,0,0,0,0,0,0,0,0,0,0,0,0,0,0,0
0,0,0,0,0,0,0,0,0,0,0,0,0,0,0,0,0,0,0,0,0,0,0,0,0,0,0,0,0,0,0,0
0,0,0,0,0,0,0,0,0,0,0,0,0,0,0,0,0,0,0,0,0,0,0,0,0,0,0,0,0,0,0,0
0,0,0,0,0,0,0,0,0,0,0,0,0,0,0,0,0,0,0,0,0,0,0,0,0,0,0,0,0,0,0,0
0,0,0,0,0,0,0,0,0,0,0,0,0,0,0,63,63,0,0,0,0,0,0,0,0,0,0,0,0,0,0,0
0,0,0,0,0,0,0,0,0,0,0,0,0,0,0,63,63,0,0,0,0,0,0,0,0,0,0,0,0,0,0,0
0,0,0,0,0,0,0,0,0,0,0,0,0,0,0,0,0,0,0,0,0,0,0,0,0,0,0,0,0,0,0,0
0,0,0,0,0,0,0,0,0,0,0,0,0,0,0,0,0,0,0,0,0,0,0,0,0,0,0,0,0,0,0,0
0,0,0,0,0,0,0,0,0,0,0,0,0,0,0,0,0,0,0,0,0,0,0,0,0,0,0,0,0,0,0,0
0,0,0,0,0,0,0,0,0,0,0,0,0,0,0,0,0,0,0,0,0,0,0,0,0,0,0,0,0,0,0,0
0,0,0,0,0,0,0,0,0,0,0,0,0,0,0,0,0,0,0,0,0,0,0,0,0,0,0,0,0,0,0,0
0,0,0,0,0,0,0,0,0,0,0,0,0,0,0,0,0,0,0,0,0,0,0,0,0,0,0,0,0,0,0,0
0,0,0,0,0,0,0,0,0,0,0,0,0,0,0,0,0,0,0,0,0,0,0,0,0,0,0,0,0,0,0,0
0,0,0,0,0,0,0,0,0,0,0,0,0,0,0,0,0,0,0,0,0,0,0,0,0,0,0,0,0,0,0,0
0,0,0,0,0,0,0,0,0,0,0,0,0,0,0,0,0,0,0,0,0,0,0,0,0,0,0,0,0,0,0,0
0,0,0,0,0,0,0,0,0,0,0,0,0,0,0,0,0,0,0,0,0,0,0,0,0,0,0,0,0,0,0,0
0,0,0,0,0,0,0,0,0,0,0,0,0,0,0,0,0,0,0,0,0,0,0,0,0,0,0,0,0,0,0,0
0,0,0,0,0,0,0,0,0,0,0,0,0,0,0,0,0,0,0,0,0,0,0,0,0,0,0,0,0,0,0,0
0,0,0,0,0,0,0,0,0,0,0,0,0,0,0,0,0,0,0,0,0,0,0,0,0,0,0,0,0,0,0,0
0,0,0,0,0,0,0,0,0,0,0,0,0,0,0,0,0,0,0,0,0,0,0,0,0,0,0,0,0,0,0,0
0,0,0,0,0,0,0,0,0,0,0,0,0,0,0,0,0,0,0,0,0,0,0,0,0,0,0,0,0,0,0,0
endlayer

layer
0,0,0,0,0,0,0,0,0,0,0,0,0,0,0,0,0,0,0,0,0,0,0,0,0,0,0,0,0,0,0,0
0,0,0,0,0,0,0,0,0,0,0,0,0,0,0,0,0,0,0,0,0,0,0,0,0,0,0,0,0,0,0,0
0,0,0,0,0,0,0,0,0,0,0,0,0,0,0,0,0,0,0,0,0,0,0,0,0,0,0,0,0,0,0,0
0,0,0,0,0,0,0,0,0,0,0,0,0,0,0,0,0,0,0,0,0,0,0,0,0,0,0,0,0,0,0,0
0,0,0,0,0,0,0,0,0,0,0,0,0,0,0,0,0,0,0,0,0,0,0,0,0,0,0,0,0,0,0,0
0,0,0,0,0,0,0,0,0,0,0,0,0,0,0,0,0,0,0,0,0,0,0,0,0,0,0,0,0,0,0,0
0,0,0,0,0,0,0,0,0,0,0,0,0,0,0,0,0,0,0,0,0,0,0,0,0,0,0,0,0,0,0,0
0,0,0,0,0,0,0,0,0,0,0,0,0,0,0,0,0,0,0,0,0,0,0,0,0,0,0,0,0,0,0,0
0,0,0,0,0,0,0,0,0,0,0,0,0,0,0,0,0,0,0,0,0,0,0,0,0,0,0,0,0,0,0,0
0,0,0,0,0,0,0,0,0,0,0,0,0,0,0,0,0,0,0,0,0,0,0,0,0,0,0,0,0,0,0,0
0,0,0,0,0,0,0,0,0,0,0,0,0,0,0,0,0,0,0,0,0,0,0,0,0,0,0,0,0,0,0,0
0,0,0,0,0,0,0,0,0,0,0,0,0,0,0,0,0,0,0,0,0,0,0,0,0,0,0,0,0,0,0,0
0,0,0,0,0,0,0,0,0,0,0,0,0,0,0,0,0,0,0,0,0,0,0,0,0,0,0,0,0,0,0,0
0,0,0,0,0,0,0,0,0,0,0,0,0,0,0,0,0,0,0,0,0,0,0,0,0,0,0,0,0,0,0,0
0,0,0,0,0,0,0,0,0,0,0,0,0,0,0,0,0,0,0,0,0,0,0,0,0,0,0,0,0,0,0,0
0,0,0,0,0,0,0,0,0,0,0,0,0,0,0,63,63,0,0,0,0,0,0,0,0,0,0,0,0,0,0,0
0,0,0,0,0,0,0,0,0,0,0,0,0,0,0,63,63,0,0,0,0,0,0,0,0,0,0,0,0,0,0,0
0,0,0,0,0,0,0,0,0,0,0,0,0,0,0,0,0,0,0,0,0,0,0,0,0,0,0,0,0,0,0,0
0,0,0,0,0,0,0,0,0,0,0,0,0,0,0,0,0,0,0,0,0,0,0,0,0,0,0,0,0,0,0,0
0,0,0,0,0,0,0,0,0,0,0,0,0,0,0,0,0,0,0,0,0,0,0,0,0,0,0,0,0,0,0,0
0,0,0,0,0,0,0,0,0,0,0,0,0,0,0,0,0,0,0,0,0,0,0,0,0,0,0,0,0,0,0,0
0,0,0,0,0,0,0,0,0,0,0,0,0,0,0,0,0,0,0,0,0,0,0,0,0,0,0,0,0,0,0,0
0,0,0,0,0,0,0,0,0,0,0,0,0,0,0,0,0,0,0,0,0,0,0,0,0,0,0,0,0,0,0,0
0,0,0,0,0,0,0,0,0,0,0,0,0,0,0,0,0,0,0,0,0,0,0,0,0,0,0,0,0,0,0,0
0,0,0,0,0,0,0,0,0,0,0,0,0,0,0,0,0,0,0,0,0,0,0,0,0,0,0,0,0,0,0,0
0,0,0,0,0,0,0,0,0,0,0,0,0,0,0,0,0,0,0,0,0,0,0,0,0,0,0,0,0,0,0,0
0,0,0,0,0,0,0,0,0,0,0,0,0,0,0,0,0,0,0,0,0,0,0,0,0,0,0,0,0,0,0,0
0,0,0,0,0,0,0,0,0,0,0,0,0,0,0,0,0,0,0,0,0,0,0,0,0,0,0,0,0,0,0,0
0,0,0,0,0,0,0,0,0,0,0,0,0,0,0,0,0,0,0,0,0,0,0,0,0,0,0,0,0,0,0,0
0,0,0,0,0,0,0,0,0,0,0,0,0,0,0,0,0,0,0,0,0,0,0,0,0,0,0,0,0,0,0,0
0,0,0,0,0,0,0,0,0,0,0,0,0,0,0,0,0,0,0,0,0,0,0,0,0,0,0,0,0,0,0,0
0,0,0,0,0,0,0,0,0,0,0,0,0,0,0,0,0,0,0,0,0,0,0,0,0,0,0,0,0,0,0,0
endlayer

layer
0,0,0,0,0,0,0,0,0,0,0,0,0,0,0,0,0,0,0,0,0,0,0,0,0,0,0,0,0,0,0,0
0,0,0,0,0,0,0,0,0,0,0,0,0,0,0,0,0,0,0,0,0,0,0,0,0,0,0,0,0,0,0,0
0,0,0,0,0,0,0,0,0,0,0,0,0,0,0,0,0,0,0,0,0,0,0,0,0,0,0,0,0,0,0,0
0,0,0,0,0,0,0,0,0,0,0,0,0,0,0,0,0,0,0,0,0,0,0,0,0,0,0,0,0,0,0,0
0,0,0,0,0,0,0,0,0,0,0,0,0,0,0,0,0,0,0,0,0,0,0,0,0,0,0,0,0,0,0,0
0,0,0,0,0,0,0,0,0,0,0,0,0,0,0,0,0,0,0,0,0,0,0,0,0,0,0,0,0,0,0,0
0,0,0,0,0,0,0,0,0,0,0,0,0,0,0,0,0,0,0,0,0,0,0,0,0,0,0,0,0,0,0,0
0,0,0,0,0,0,0,0,0,0,0,0,0,0,0,0,0,0,0,0,0,0,0,0,0,0,0,0,0,0,0,0
0,0,0,0,0,0,0,0,0,0,0,0,0,0,0,0,0,0,0,0,0,0,0,0,0,0,0,0,0,0,0,0
0,0,0,0,0,0,0,0,0,0,0,0,0,0,0,0,0,0,0,0,0,0,0,0,0,0,0,0,0,0,0,0
0,0,0,0,0,0,0,0,0,0,0,0,0,0,0,0,0,0,0,0,0,0,0,0,0,0,0,0,0,0,0,0
0,0,0,0,0,0,0,0,0,0,0,0,0,0,0,0,0,0,0,0,0,0,0,0,0,0,0,0,0,0,0,0
0,0,0,0,0,0,0,0,0,0,0,0,0,0,0,0,0,0,0,0,0,0,0,0,0,0,0,0,0,0,0,0
0,0,0,0,0,0,0,0,0,0,0,0,0,0,0,0,0,0,0,0,0,0,0,0,0,0,0,0,0,0,0,0
0,0,0,0,0,0,0,0,0,0,0,0,0,0,0,0,0,0,0,0,0,0,0,0,0,0,0,0,0,0,0,0
0,0,0,0,0,0,0,0,0,0,0,0,0,0,0,63,63,0,0,0,0,0,0,0,0,0,0,0,0,0,0,0
0,0,0,0,0,0,0,0,0,0,0,0,0,0,0,63,63,0,0,0,0,0,0,0,0,0,0,0,0,0,0,0
0,0,0,0,0,0,0,0,0,0,0,0,0,0,0,0,0,0,0,0,0,0,0,0,0,0,0,0,0,0,0,0
0,0,0,0,0,0,0,0,0,0,0,0,0,0,0,0,0,0,0,0,0,0,0,0,0,0,0,0,0,0,0,0
0,0,0,0,0,0,0,0,0,0,0,0,0,0,0,0,0,0,0,0,0,0,0,0,0,0,0,0,0,0,0,0
0,0,0,0,0,0,0,0,0,0,0,0,0,0,0,0,0,0,0,0,0,0,0,0,0,0,0,0,0,0,0,0
0,0,0,0,0,0,0,0,0,0,0,0,0,0,0,0,0,0,0,0,0,0,0,0,0,0,0,0,0,0,0,0
0,0,0,0,0,0,0,0,0,0,0,0,0,0,0,0,0,0,0,0,0,0,0,0,0,0,0,0,0,0,0,0
0,0,0,0,0,0,0,0,0,0,0,0,0,0,0,0,0,0,0,0,0,0,0,0,0,0,0,0,0,0,0,0
0,0,0,0,0,0,0,0,0,0,0,0,0,0,0,0,0,0,0,0,0,0,0,0,0,0,0,0,0,0,0,0
0,0,0,0,0,0,0,0,0,0,0,0,0,0,0,0,0,0,0,0,0,0,0,0,0,0,0,0,0,0,0,0
0,0,0,0,0,0,0,0,0,0,0,0,0,0,0,0,0,0,0,0,0,0,0,0,0,0,0,0,0,0,0,0
0,0,0,0,0,0,0,0,0,0,0,0,0,0,0,0,0,0,0,0,0,0,0,0,0,0,0,0,0,0,0,0
0,0,0,0,0,0,0,0,0,0,0,0,0,0,0,0,0,0,0,0,0,0,0,0,0,0,0,0,0,0,0,0
0,0,0,0,0,0,0,0,0,0,0,0,0,0,0,0,0,0,0,0,0,0,0,0,0,0,0,0,0,0,0,0
0,0,0,0,0,0,0,0,0,0,0,0,0,0,0,0,0,0,0,0,0,0,0,0,0,0,0,0,0,0,0,0
0,0,0,0,0,0,0,0,0,0,0,0,0,0,0,0,0,0,0,0,0,0,0,0,0,0,0,0,0,0,0,0
endlayer

layer
0,0,0,0,0,0,0,0,0,0,0,0,0,0,0,0,0,0,0,0,0,0,0,0,0,0,0,0,0,0,0,0
0,0,0,0,0,0,0,0,0,0,0,0,0,0,0,0,0,0,0,0,0,0,0,0,0,0,0,0,0,0,0,0
0,0,0,0,0,0,0,0,0,0,0,0,0,0,0,0,0,0,0,0,0,0,0,0,0,0,0,0,0,0,0,0
0,0,0,0,0,0,0,0,0,0,0,0,0,0,0,0,0,0,0,0,0,0,0,0,0,0,0,0,0,0,0,0
0,0,0,0,0,0,0,0,0,0,0,0,0,0,0,0,0,0,0,0,0,0,0,0,0,0,0,0,0,0,0,0
0,0,0,0,0,0,0,0,0,0,0,0,0,0,0,0,0,0,0,0,0,0,0,0,0,0,0,0,0,0,0,0
0,0,0,0,0,0,0,0,0,0,0,0,0,0,0,0,0,0,0,0,0,0,0,0,0,0,0,0,0,0,0,0
0,0,0,0,0,0,0,0,0,0,0,0,0,0,0,0,0,0,0,0,0,0,0,0,0,0,0,0,0,0,0,0
0,0,0,0,0,0,0,0,0,0,0,0,0,0,0,0,0,0,0,0,0,0,0,0,0,0,0,0,0,0,0,0
0,0,0,0,0,0,0,0,0,0,0,0,0,0,0,0,0,0,0,0,0,0,0,0,0,0,0,0,0,0,0,0
0,0,0,0,0,0,0,0,0,0,0,0,0,0,0,0,0,0,0,0,0,0,0,0,0,0,0,0,0,0,0,0
0,0,0,0,0,0,0,0,0,0,0,0,0,0,0,0,0,0,0,0,0,0,0,0,0,0,0,0,0,0,0,0
0,0,0,0,0,0,0,0,0,0,0,0,0,0,0,0,0,0,0,0,0,0,0,0,0,0,0,0,0,0,0,0
0,0,0,0,0,0,0,0,0,0,0,0,0,0,0,0,0,0,0,0,0,0,0,0,0,0,0,0,0,0,0,0
0,0,0,0,0,0,0,0,0,0,0,0,0,0,0,0,0,0,0,0,0,0,0,0,0,0,0,0,0,0,0,0
0,0,0,0,0,0,0,0,0,0,0,0,0,0,0,63,63,0,0,0,0,0,0,0,0,0,0,0,0,0,0,0
0,0,0,0,0,0,0,0,0,0,0,0,0,0,0,63,63,0,0,0,0,0,0,0,0,0,0,0,0,0,0,0
0,0,0,0,0,0,0,0,0,0,0,0,0,0,0,0,0,0,0,0,0,0,0,0,0,0,0,0,0,0,0,0
0,0,0,0,0,0,0,0,0,0,0,0,0,0,0,0,0,0,0,0,0,0,0,0,0,0,0,0,0,0,0,0
0,0,0,0,0,0,0,0,0,0,0,0,0,0,0,0,0,0,0,0,0,0,0,0,0,0,0,0,0,0,0,0
0,0,0,0,0,0,0,0,0,0,0,0,0,0,0,0,0,0,0,0,0,0,0,0,0,0,0,0,0,0,0,0
0,0,0,0,0,0,0,0,0,0,0,0,0,0,0,0,0,0,0,0,0,0,0,0,0,0,0,0,0,0,0,0
0,0,0,0,0,0,0,0,0,0,0,0,0,0,0,0,0,0,0,0,0,0,0,0,0,0,0,0,0,0,0,0
0,0,0,0,0,0,0,0,0,0,0,0,0,0,0,0,0,0,0,0,0,0,0,0,0,0,0,0,0,0,0,0
0,0,0,0,0,0,0,0,0,0,0,0,0,0,0,0,0,0,0,0,0,0,0,0,0,0,0,0,0,0,0,0
0,0,0,0,0,0,0,0,0,0,0,0,0,0,0,0,0,0,0,0,0,0,0,0,0,0,0,0,0,0,0,0
0,0,0,0,0,0,0,0,0,0,0,0,0,0,0,0,0,0,0,0,0,0,0,0,0,0,0,0,0,0,0,0
0,0,0,0,0,0,0,0,0,0,0,0,0,0,0,0,0,0,0,0,0,0,0,0,0,0,0,0,0,0,0,0
0,0,0,0,0,0,0,0,0,0,0,0,0,0,0,0,0,0,0,0,0,0,0,0,0,0,0,0,0,0,0,0
0,0,0,0,0,0,0,0,0,0,0,0,0,0,0,0,0,0,0,0,0,0,0,0,0,0,0,0,0,0,0,0
0,0,0,0,0,0,0,0,0,0,0,0,0,0,0,0,0,0,0,0,0,0,0,0,0,0,0,0,0,0,0,0
0,0,0,0,0,0,0,0,0,0,0,0,0,0,0,0,0,0,0,0,0,0,0,0,0,0,0,0,0,0,0,0
endlayer

layer
0,0,0,0,0,0,0,0,0,0,0,0,0,0,0,0,0,0,0,0,0,0,0,0,0,0,0,0,0,0,0,0
0,0,0,0,0,0,0,0,0,0,0,0,0,0,0,0,0,0,0,0,0,0,0,0,0,0,0,0,0,0,0,0
0,0,0,0,0,0,0,0,0,0,0,0,0,0,0,0,0,0,0,0,0,0,0,0,0,0,0,0,0,0,0,0
0,0,0,0,0,0,0,0,0,0,0,0,0,0,0,0,0,0,0,0,0,0,0,0,0,0,0,0,0,0,0,0
0,0,0,0,0,0,0,0,0,0,0,0,0,0,0,0,0,0,0,0,0,0,0,0,0,0,0,0,0,0,0,0
0,0,0,0,0,0,0,0,0,0,0,0,0,0,0,0,0,0,0,0,0,0,0,0,0,0,0,0,0,0,0,0
0,0,0,0,0,0,0,0,0,0,0,0,0,0,0,0,0,0,0,0,0,0,0,0,0,0,0,0,0,0,0,0
0,0,0,0,0,0,0,0,0,0,0,0,0,0,0,0,0,0,0,0,0,0,0,0,0,0,0,0,0,0,0,0
0,0,0,0,0,0,0,0,0,0,0,0,0,0,0,0,0,0,0,0,0,0,0,0,0,0,0,0,0,0,0,0
0,0,0,0,0,0,0,0,0,0,0,0,0,0,0,0,0,0,0,0,0,0,0,0,0,0,0,0,0,0,0,0
0,0,0,0,0,0,0,0,0,0,0,0,0,0,0,0,0,0,0,0,0,0,0,0,0,0,0,0,0,0,0,0
0,0,0,0,0,0,0,0,0,0,0,0,0,0,0,0,0,0,0,0,0,0,0,0,0,0,0,0,0,0,0,0
0,0,0,0,0,0,0,0,0,0,0,0,0,0,0,0,0,0,0,0,0,0,0,0,0,0,0,0,0,0,0,0
0,0,0,0,0,0,0,0,0,0,0,0,0,0,0,0,0,0,0,0,0,0,0,0,0,0,0,0,0,0,0,0
0,0,0,0,0,0,0,0,0,0,0,0,0,0,0,0,0,0,0,0,0,0,0,0,0,0,0,0,0,0,0,0
0,0,0,0,0,0,0,0,0,0,0,0,0,0,0,63,63,0,0,0,0,0,0,0,0,0,0,0,0,0,0,0
0,0,0,0,0,0,0,0,0,0,0,0,0,0,0,63,63,0,0,0,0,0,0,0,0,0,0,0,0,0,0,0
0,0,0,0,0,0,0,0,0,0,0,0,0,0,0,0,0,0,0,0,0,0,0,0,0,0,0,0,0,0,0,0
0,0,0,0,0,0,0,0,0,0,0,0,0,0,0,0,0,0,0,0,0,0,0,0,0,0,0,0,0,0,0,0
0,0,0,0,0,0,0,0,0,0,0,0,0,0,0,0,0,0,0,0,0,0,0,0,0,0,0,0,0,0,0,0
0,0,0,0,0,0,0,0,0,0,0,0,0,0,0,0,0,0,0,0,0,0,0,0,0,0,0,0,0,0,0,0
0,0,0,0,0,0,0,0,0,0,0,0,0,0,0,0,0,0,0,0,0,0,0,0,0,0,0,0,0,0,0,0
0,0,0,0,0,0,0,0,0,0,0,0,0,0,0,0,0,0,0,0,0,0,0,0,0,0,0,0,0,0,0,0
0,0,0,0,0,0,0,0,0,0,0,0,0,0,0,0,0,0,0,0,0,0,0,0,0,0,0,0,0,0,0,0
0,0,0,0,0,0,0,0,0,0,0,0,0,0,0,0,0,0,0,0,0,0,0,0,0,0,0,0,0,0,0,0
0,0,0,0,0,0,0,0,0,0,0,0,0,0,0,0,0,0,0,0,0,0,0,0,0,0,0,0,0,0,0,0
0,0,0,0,0,0,0,0,0,0,0,0,0,0,0,0,0,0,0,0,0,0,0,0,0,0,0,0,0,0,0,0
0,0,0,0,0,0,0,0,0,0,0,0,0,0,0,0,0,0,0,0,0,0,0,0,0,0,0,0,0,0,0,0
0,0,0,0,0,0,0,0,0,0,0,0,0,0,0,0,0,0,0,0,0,0,0,0,0,0,0,0,0,0,0,0
0,0,0,0,0,0,0,0,0,0,0,0,0,0,0,0,0,0,0,0,0,0,0,0,0,0,0,0,0,0,0,0
0,0,0,0,0,0,0,0,0,0,0,0,0,0,0,0,0,0,0,0,0,0,0,0,0,0,0,0,0,0,0,0
0,0,0,0,0,0,0,0,0,0,0,0,0,0,0,0,0,0,0,0,0,0,0,0,0,0,0,0,0,0,0,0
endlayer

layer
0,0,0,0,0,0,0,0,0,0,0,0,0,0,0,0,0,0,0,0,0,0,0,0,0,0,0,0,0,0,0,0
0,0,0,0,0,0,0,0,0,0,0,0,0,0,0,0,0,0,0,0,0,0,0,0,0,0,0,0,0,0,0,0
0,0,0,0,0,0,0,0,0,0,0,0,0,0,0,0,0,0,0,0,0,0,0,0,0,0,0,0,0,0,0,0
0,0,0,0,0,0,0,0,0,0,0,0,0,0,0,0,0,0,0,0,0,0,0,0,0,0,0,0,0,0,0,0
0,0,0,0,0,0,0,0,0,0,0,0,0,0,0,0,0,0,0,0,0,0,0,0,0,0,0,0,0,0,0,0
0,0,0,0,0,0,0,0,0,0,0,0,0,0,0,0,0,0,0,0,0,0,0,0,0,0,0,0,0,0,0,0
0,0,0,0,0,0,0,0,0,0,0,0,0,0,0,0,0,0,0,0,0,0,0,0,0,0,0,0,0,0,0,0
0,0,0,0,0,0,0,0,0,0,0,0,0,0,0,0,0,0,0,0,0,0,0,0,0,0,0,0,0,0,0,0
0,0,0,0,0,0,0,0,0,0,0,0,0,0,0,0,0,0,0,0,0,0,0,0,0,0,0,0,0,0,0,0
0,0,0,0,0,0,0,0,0,0,0,0,0,0,0,0,0,0,0,0,0,0,0,0,0,0,0,0,0,0,0,0
0,0,0,0,0,0,0,0,0,0,0,0,0,0,0,0,0,0,0,0,0,0,0,0,0,0,0,0,0,0,0,0
0,0,0,0,0,0,0,0,0,0,0,0,0,0,0,0,0,0,0,0,0,0,0,0,0,0,0,0,0,0,0,0
0,0,0,0,0,0,0,0,0,0,0,0,0,0,0,0,0,0,0,0,0,0,0,0,0,0,0,0,0,0,0,0
0,0,0,0,0,0,0,0,0,0,0,0,0,0,0,0,0,0,0,0,0,0,0,0,0,0,0,0,0,0,0,0
0,0,0,0,0,0,0,0,0,0,0,0,0,0,0,0,0,0,0,0,0,0,0,0,0,0,0,0,0,0,0,0
0,0,0,0,0,0,0,0,0,0,0,0,0,0,0,63,63,0,0,0,0,0,0,0,0,0,0,0,0,0,0,0
0,0,0,0,0,0,0,0,0,0,0,0,0,0,70,63,63,0,0,0,0,0,0,0,0,0,0,0,0,0,0,0
0,0,0,0,0,0,0,0,0,0,0,0,0,0,71,0,0,0,0,0,0,0,0,0,0,0,0,0,0,0,0,0
0,0,0,0,0,0,0,0,0,0,0,0,0,71,0,0,0,0,0,0,0,0,0,0,0,0,0,0,0,0,0,0
0,0,0,0,0,0,0,0,0,0,0,0,70,0,0,0,0,0,0,0,0,0,0,0,0,0,0,0,0,0,0,0
0,0,0,0,0,0,0,0,0,0,70,70,0,0,0,0,0,0,0,0,0,0,0,0,0,0,0,0,0,0,0,0
0,0,0,0,0,0,0,0,0,70,0,0,0,0,0,0,0,0,0,0,0,0,0,0,0,0,0,0,0,0,0,0
0,0,0,0,0,0,0,0,0,0,0,0,0,0,0,0,0,0,0,0,0,0,0,0,0,0,0,0,0,0,0,0
0,0,0,0,0,0,0,0,0,0,0,0,0,0,0,0,0,0,0,0,0,0,0,0,0,0,0,0,0,0,0,0
0,0,0,0,0,0,0,0,0,0,0,0,0,0,0,0,0,0,0,0,0,0,0,0,0,0,0,0,0,0,0,0
0,0,0,0,0,0,0,0,0,0,0,0,0,0,0,0,0,0,0,0,0,0,0,0,0,0,0,0,0,0,0,0
0,0,0,0,0,0,0,0,0,0,0,0,0,0,0,0,0,0,0,0,0,0,0,0,0,0,0,0,0,0,0,0
0,0,0,0,0,0,0,0,0,0,0,0,0,0,0,0,0,0,0,0,0,0,0,0,0,0,0,0,0,0,0,0
0,0,0,0,0,0,0,0,0,0,0,0,0,0,0,0,0,0,0,0,0,0,0,0,0,0,0,0,0,0,0,0
0,0,0,0,0,0,0,0,0,0,0,0,0,0,0,0,0,0,0,0,0,0,0,0,0,0,0,0,0,0,0,0
0,0,0,0,0,0,0,0,0,0,0,0,0,0,0,0,0,0,0,0,0,0,0,0,0,0,0,0,0,0,0,0
0,0,0,0,0,0,0,0,0,0,0,0,0,0,0,0,0,0,0,0,0,0,0,0,0,0,0,0,0,0,0,0
endlayer

layer
0,0,0,0,0,0,0,0,0,0,0,0,0,0,0,0,0,0,0,0,0,0,0,0,0,0,0,0,0,0,0,0
0,0,0,0,0,0,0,0,0,0,0,0,0,0,0,0,0,0,0,0,0,0,0,0,0,0,0,0,0,0,0,0
0,0,0,0,0,0,0,0,0,0,0,0,0,0,0,0,0,0,0,0,0,0,0,0,0,0,0,0,0,0,0,0
0,0,0,0,0,0,0,0,0,0,0,0,0,0,0,0,0,0,0,0,0,0,0,0,0,0,0,0,0,0,0,0
0,0,0,0,0,0,0,0,0,0,0,0,0,0,0,0,0,0,0,0,0,0,0,0,0,0,0,0,0,0,0,0
0,0,0,0,0,0,0,0,0,0,0,0,0,0,0,0,0,0,0,0,0,0,0,0,0,0,0,0,0,0,0,0
0,0,0,0,0,0,0,0,0,0,0,0,0,0,0,0,0,0,0,0,0,0,0,0,0,0,0,0,0,0,0,0
0,0,0,0,0,0,0,0,0,0,0,0,0,0,0,0,0,0,0,0,0,0,0,0,0,0,0,0,0,0,0,0
0,0,0,0,0,0,0,0,0,0,0,0,0,0,0,0,0,0,0,0,0,0,0,0,0,0,0,0,0,0,0,0
0,0,0,0,0,0,0,0,0,0,0,0,0,0,0,0,0,0,0,0,0,0,0,0,0,0,0,0,0,0,0,0
0,0,0,0,0,0,0,0,0,0,0,0,0,0,0,0,0,0,0,0,0,0,0,0,0,0,0,0,0,0,0,0
0,0,0,0,0,0,0,0,0,0,0,0,0,0,0,0,0,0,0,0,0,0,0,0,0,0,0,0,0,0,0,0
0,0,0,0,0,0,0,0,0,0,0,0,0,0,0,0,0,0,0,0,0,0,0,0,0,0,0,0,0,0,0,0
0,0,0,0,0,0,0,0,0,0,0,0,0,0,0,0,0,0,0,0,0,0,0,0,0,0,0,0,0,0,0,0
0,0,0,0,0,0,0,0,0,0,0,0,0,0,0,0,0,0,0,0,0,0,0,0,0,0,0,0,0,0,0,0
0,0,0,0,0,0,0,0,0,0,0,0,0,0,0,63,63,0,0,0,0,0,0,0,0,0,0,0,0,0,0,0
0,0,0,0,0,0,0,0,0,0,0,0,0,0,0,63,63,0,0,0,0,0,0,0,0,0,0,0,0,0,0,0
0,0,0,0,0,0,0,0,0,0,0,0,0,70,70,0,0,0,0,0,0,0,0,0,0,0,0,0,0,0,0,0
0,0,0,0,0,0,0,0,0,0,0,0,71,70,0,0,0,0,0,0,0,0,0,0,0,0,0,0,0,0,0,0
0,0,0,0,0,0,0,0,0,0,0,70,70,0,0,0,0,0,0,0,0,0,0,0,0,0,0,0,0,0,0,0
0,0,0,0,0,0,0,0,0,0,0,70,0,0,0,0,0,0,0,0,0,0,0,0,0,0,0,0,0,0,0,0
0,0,0,0,0,0,0,0,0,0,0,0,0,0,0,0,0,0,0,0,0,0,0,0,0,0,0,0,0,0,0,0
0,0,0,0,0,0,0,0,0,0,0,0,0,0,0,0,0,0,0,0,0,0,0,0,0,0,0,0,0,0,0,0
0,0,0,0,0,0,0,0,0,0,0,0,0,0,0,0,0,0,0,0,0,0,0,0,0,0,0,0,0,0,0,0
0,0,0,0,0,0,0,0,0,0,0,0,0,0,0,0,0,0,0,0,0,0,0,0,0,0,0,0,0,0,0,0
0,0,0,0,0,0,0,0,0,0,0,0,0,0,0,0,0,0,0,0,0,0,0,0,0,0,0,0,0,0,0,0
0,0,0,0,0,0,0,0,0,0,0,0,0,0,0,0,0,0,0,0,0,0,0,0,0,0,0,0,0,0,0,0
0,0,0,0,0,0,0,0,0,0,0,0,0,0,0,0,0,0,0,0,0,0,0,0,0,0,0,0,0,0,0,0
0,0,0,0,0,0,0,0,0,0,0,0,0,0,0,0,0,0,0,0,0,0,0,0,0,0,0,0,0,0,0,0
0,0,0,0,0,0,0,0,0,0,0,0,0,0,0,0,0,0,0,0,0,0,0,0,0,0,0,0,0,0,0,0
0,0,0,0,0,0,0,0,0,0,0,0,0,0,0,0,0,0,0,0,0,0,0,0,0,0,0,0,0,0,0,0
0,0,0,0,0,0,0,0,0,0,0,0,0,0,0,0,0,0,0,0,0,0,0,0,0,0,0,0,0,0,0,0
endlayer

layer
0,0,0,0,0,0,0,0,0,0,0,0,0,0,0,0,0,0,0,0,0,0,0,0,0,0,0,0,0,0,0,0
0,0,0,0,0,0,0,0,0,0,0,0,0,0,0,0,0,0,0,0,0,0,0,0,0,0,0,0,0,0,0,0
0,0,0,0,0,0,0,0,0,0,0,0,0,0,0,0,0,0,0,0,0,0,0,0,0,0,0,0,0,0,0,0
0,0,0,0,0,0,0,0,0,0,0,0,0,0,0,0,0,0,0,0,0,0,0,0,0,0,0,0,0,0,0,0
0,0,0,0,0,0,0,0,0,0,0,0,0,0,0,0,0,0,0,0,0,0,0,0,0,0,0,0,0,0,0,0
0,0,0,0,0,0,0,0,0,0,0,0,0,0,0,0,0,0,0,0,0,0,0,0,0,0,0,0,0,0,0,0
0,0,0,0,0,0,0,0,0,0,0,0,0,0,0,0,0,0,0,0,0,0,0,0,0,0,0,0,0,0,0,0
0,0,0,0,0,0,0,0,0,0,0,0,0,0,0,0,0,0,0,0,0,0,0,0,0,0,0,0,0,0,0,0
0,0,0,0,0,0,0,0,0,0,0,0,0,0,0,0,0,0,0,0,0,0,0,0,0,0,0,0,0,0,0,0
0,0,0,0,0,0,0,0,0,0,0,0,0,0,0,0,0,0,0,0,0,0,0,0,0,0,0,0,0,0,0,0
0,0,0,0,0,0,0,0,0,0,0,0,0,0,0,0,0,0,0,0,0,0,0,0,0,0,0,0,0,0,0,0
0,0,0,0,0,0,0,0,0,0,0,0,0,0,0,0,0,0,0,0,0,0,0,0,0,0,0,0,0,0,0,0
0,0,0,0,0,0,0,0,0,0,0,0,0,0,0,0,0,0,0,0,0,0,0,0,0,0,0,0,0,0,0,0
0,0,0,0,0,0,0,0,0,0,0,0,0,0,0,0,0,0,0,0,0,0,0,0,0,0,0,0,0,0,0,0
0,0,0,0,0,0,0,0,0,0,0,0,0,0,0,0,0,0,0,0,0,0,0,0,0,0,0,0,0,0,0,0
0,0,0,0,0,0,0,0,0,0,0,0,0,0,0,63,63,0,0,0,0,0,0,0,0,0,0,0,0,0,0,0
0,0,0,0,0,0,0,0,0,0,0,0,0,0,70,63,63,0,0,0,0,0,0,0,0,0,0,0,0,0,0,0
0,0,0,0,0,0,0,0,0,0,0,0,0,71,70,70,0,0,0,0,0,0,0,0,0,0,0,0,0,0,0,0
0,0,0,0,0,0,0,0,0,0,0,0,70,70,0,0,0,0,0,0,0,0,0,0,0,0,0,0,0,0,0,0
0,0,0,0,0,0,0,0,0,0,0,0,70,0,0,0,0,0,0,0,0,0,0,0,0,0,0,0,0,0,0,0
0,0,0,0,0,0,0,0,0,0,0,0,0,0,0,0,0,0,0,0,0,0,0,0,0,0,0,0,0,0,0,0
0,0,0,0,0,0,0,0,0,0,0,0,0,0,0,0,0,0,0,0,0,0,0,0,0,0,0,0,0,0,0,0
0,0,0,0,0,0,0,0,0,0,0,0,0,0,0,0,0,0,0,0,0,0,0,0,0,0,0,0,0,0,0,0
0,0,0,0,0,0,0,0,0,0,0,0,0,0,0,0,0,0,0,0,0,0,0,0,0,0,0,0,0,0,0,0
0,0,0,0,0,0,0,0,0,0,0,0,0,0,0,0,0,0,0,0,0,0,0,0,0,0,0,0,0,0,0,0
0,0,0,0,0,0,0,0,0,0,0,0,0,0,0,0,0,0,0,0,0,0,0,0,0,0,0,0,0,0,0,0
0,0,0,0,0,0,0,0,0,0,0,0,0,0,0,0,0,0,0,0,0,0,0,0,0,0,0,0,0,0,0,0
0,0,0,0,0,0,0,0,0,0,0,0,0,0,0,0,0,0,0,0,0,0,0,0,0,0,0,0,0,0,0,0
0,0,0,0,0,0,0,0,0,0,0,0,0,0,0,0,0,0,0,0,0,0,0,0,0,0,0,0,0,0,0,0
0,0,0,0,0,0,0,0,0,0,0,0,0,0,0,0,0,0,0,0,0,0,0,0,0,0,0,0,0,0,0,0
0,0,0,0,0,0,0,0,0,0,0,0,0,0,0,0,0,0,0,0,0,0,0,0,0,0,0,0,0,0,0,0
0,0,0,0,0,0,0,0,0,0,0,0,0,0,0,0,0,0,0,0,0,0,0,0,0,0,0,0,0,0,0,0
endlayer

layer
0,0,0,0,0,0,0,0,0,0,0,0,0,0,0,0,0,0,0,0,0,0,0,0,0,0,0,0,0,0,0,0
0,0,0,0,0,0,0,0,0,0,0,0,0,0,0,0,0,0,0,0,0,0,0,0,0,0,0,0,0,0,0,0
0,0,0,0,0,0,0,0,0,0,0,0,0,0,0,0,0,0,0,0,0,0,0,0,0,0,0,0,0,0,0,0
0,0,0,0,0,0,0,0,0,0,0,0,0,0,0,0,0,0,0,0,0,0,0,0,0,0,0,0,0,0,0,0
0,0,0,0,0,0,0,0,0,0,0,0,0,0,0,0,0,0,0,0,0,0,0,0,0,0,0,0,0,0,0,0
0,0,0,0,0,0,0,0,0,0,0,0,0,0,0,0,0,0,0,0,0,0,0,0,0,0,0,0,0,0,0,0
0,0,0,0,0,0,0,0,0,0,0,0,0,0,0,0,0,0,0,0,0,0,0,0,0,0,0,0,0,0,0,0
0,0,0,0,0,0,0,0,0,0,0,0,0,0,0,0,0,0,0,0,0,0,0,0,0,0,0,0,0,0,0,0
0,0,0,0,0,0,0,0,0,0,0,0,0,0,0,0,0,0,0,0,0,0,0,0,0,0,0,0,0,0,0,0
0,0,0,0,0,0,0,0,0,0,0,0,0,0,0,0,0,0,0,0,0,0,0,0,0,0,0,0,0,0,0,0
0,0,0,0,0,0,0,0,0,0,0,0,0,0,0,0,0,0,0,0,0,0,0,0,0,0,0,0,0,0,0,0
0,0,0,0,0,0,0,0,0,0,0,0,0,0,0,0,0,0,0,0,0,0,0,0,0,0,0,0,0,0,0,0
0,0,0,0,0,0,0,0,0,0,0,0,0,0,0,0,0,0,0,0,0,0,0,0,0,0,0,0,0,0,0,0
0,0,0,0,0,0,0,0,0,0,0,0,0,0,0,0,0,0,0,0,0,0,0,0,0,0,0,0,0,0,0,0
0,0,0,0,0,0,0,0,0,0,0,0,0,0,0,0,0,0,0,0,0,0,0,0,0,0,0,0,0,0,0,0
0,0,0,0,0,0,0,0,0,0,0,0,0,0,0,63,63,0,0,0,0,0,0,0,0,0,0,0,0,0,0,0
0,0,0,0,0,0,0,0,0,0,0,0,0,0,70,63,63,0,0,0,0,0,0,0,0,0,0,0,0,0,0,0
0,0,0,0,0,0,0,0,0,0,0,0,0,0,71,70,0,0,0,0,0,0,0,0,0,0,0,0,0,0,0,0
0,0,0,0,0,0,0,0,0,0,0,0,0,70,0,0,0,0,0,0,0,0,0,0,0,0,0,0,0,0,0,0
0,0,0,0,0,0,0,0,0,0,0,0,0,0,0,0,0,0,0,0,0,0,0,0,0,0,0,0,0,0,0,0
0,0,0,0,0,0,0,0,0,0,0,0,0,0,0,0,0,0,0,0,0,0,0,0,0,0,0,0,0,0,0,0
0,0,0,0,0,0,0,0,0,0,0,0,0,0,0,0,0,0,0,0,0,0,0,0,0,0,0,0,0,0,0,0
0,0,0,0,0,0,0,0,0,0,0,0,0,0,0,0,0,0,0,0,0,0,0,0,0,0,0,0,0,0,0,0
0,0,0,0,0,0,0,0,0,0,0,0,0,0,0,0,0,0,0,0,0,0,0,0,0,0,0,0,0,0,0,0
0,0,0,0,0,0,0,0,0,0,0,0,0,0,0,0,0,0,0,0,0,0,0,0,0,0,0,0,0,0,0,0
0,0,0,0,0,0,0,0,0,0,0,0,0,0,0,0,0,0,0,0,0,0,0,0,0,0,0,0,0,0,0,0
0,0,0,0,0,0,0,0,0,0,0,0,0,0,0,0,0,0,0,0,0,0,0,0,0,0,0,0,0,0,0,0
0,0,0,0,0,0,0,0,0,0,0,0,0,0,0,0,0,0,0,0,0,0,0,0,0,0,0,0,0,0,0,0
0,0,0,0,0,0,0,0,0,0,0,0,0,0,0,0,0,0,0,0,0,0,0,0,0,0,0,0,0,0,0,0
0,0,0,0,0,0,0,0,0,0,0,0,0,0,0,0,0,0,0,0,0,0,0,0,0,0,0,0,0,0,0,0
0,0,0,0,0,0,0,0,0,0,0,0,0,0,0,0,0,0,0,0,0,0,0,0,0,0,0,0,0,0,0,0
0,0,0,0,0,0,0,0,0,0,0,0,0,0,0,0,0,0,0,0,0,0,0,0,0,0,0,0,0,0,0,0
endlayer

layer
0,0,0,0,0,0,0,0,0,0,0,0,0,0,0,0,0,0,0,0,0,0,0,0,0,0,0,0,0,0,0,0
0,0,0,0,0,0,0,0,0,0,0,0,0,0,0,0,0,0,0,0,0,0,0,0,0,0,0,0,0,0,0,0
0,0,0,0,0,0,0,0,0,0,0,0,0,0,0,0,0,0,0,0,0,0,0,0,0,0,0,0,0,0,0,0
0,0,0,0,0,0,0,0,0,0,0,0,0,0,0,0,0,0,0,0,0,0,0,0,0,0,0,0,0,0,0,0
0,0,0,0,0,0,0,0,0,0,0,0,0,0,0,0,0,0,0,0,0,0,0,0,0,0,0,0,0,0,0,0
0,0,0,0,0,0,0,0,0,0,0,0,0,0,0,0,0,0,0,0,0,0,0,0,0,0,0,0,0,0,0,0
0,0,0,0,0,0,0,0,0,0,0,0,0,0,0,0,0,0,0,0,0,0,0,0,0,0,0,0,0,0,0,0
0,0,0,0,0,0,0,0,0,0,0,0,0,0,0,0,0,0,0,0,0,0,0,0,0,0,0,0,0,0,0,0
0,0,0,0,0,0,0,0,0,0,0,0,0,0,0,0,0,0,0,0,0,0,0,0,0,0,0,0,0,0,0,0
0,0,0,0,0,0,0,0,0,0,0,0,0,0,0,0,0,0,0,0,0,0,0,0,0,0,0,0,0,0,0,0
0,0,0,0,0,0,0,0,0,0,0,0,0,0,0,0,0,0,0,0,0,0,0,0,0,0,0,0,0,0,0,0
0,0,0,0,0,0,0,0,0,0,0,0,0,0,0,0,0,0,0,0,0,0,0,0,0,0,0,0,0,0,0,0
0,0,0,0,0,0,0,0,0,0,0,0,0,0,0,0,0,0,0,0,0,0,0,0,0,0,0,0,0,0,0,0
0,0,0,0,0,0,0,0,0,0,0,0,0,0,0,0,0,0,0,0,0,0,0,0,0,0,0,0,0,0,0,0
0,0,0,0,0,0,0,0,0,0,0,0,0,0,0,0,0,0,0,0,0,0,0,0,0,0,0,0,0,0,0,0
0,0,0,0,0,0,0,0,0,0,0,0,0,0,0,0,0,0,0,0,0,0,0,0,0,0,0,0,0,0,0,0
0,0,0,0,0,0,0,0,0,0,0,0,0,0,0,70,0,0,0,0,0,0,0,0,0,0,0,0,0,0,0,0
0,0,0,0,0,0,0,0,0,0,0,0,0,0,70,0,0,0,0,0,0,0,0,0,0,0,0,0,0,0,0,0
0,0,0,0,0,0,0,0,0,0,0,0,0,0,0,0,0,0,0,0,0,0,0,0,0,0,0,0,0,0,0,0
0,0,0,0,0,0,0,0,0,0,0,0,0,0,0,0,0,0,0,0,0,0,0,0,0,0,0,0,0,0,0,0
0,0,0,0,0,0,0,0,0,0,0,0,0,0,0,0,0,0,0,0,0,0,0,0,0,0,0,0,0,0,0,0
0,0,0,0,0,0,0,0,0,0,0,0,0,0,0,0,0,0,0,0,0,0,0,0,0,0,0,0,0,0,0,0
0,0,0,0,0,0,0,0,0,0,0,0,0,0,0,0,0,0,0,0,0,0,0,0,0,0,0,0,0,0,0,0
0,0,0,0,0,0,0,0,0,0,0,0,0,0,0,0,0,0,0,0,0,0,0,0,0,0,0,0,0,0,0,0
0,0,0,0,0,0,0,0,0,0,0,0,0,0,0,0,0,0,0,0,0,0,0,0,0,0,0,0,0,0,0,0
0,0,0,0,0,0,0,0,0,0,0,0,0,0,0,0,0,0,0,0,0,0,0,0,0,0,0,0,0,0,0,0
0,0,0,0,0,0,0,0,0,0,0,0,0,0,0,0,0,0,0,0,0,0,0,0,0,0,0,0,0,0,0,0
0,0,0,0,0,0,0,0,0,0,0,0,0,0,0,0,0,0,0,0,0,0,0,0,0,0,0,0,0,0,0,0
0,0,0,0,0,0,0,0,0,0,0,0,0,0,0,0,0,0,0,0,0,0,0,0,0,0,0,0,0,0,0,0
0,0,0,0,0,0,0,0,0,0,0,0,0,0,0,0,0,0,0,0,0,0,0,0,0,0,0,0,0,0,0,0
0,0,0,0,0,0,0,0,0,0,0,0,0,0,0,0,0,0,0,0,0,0,0,0,0,0,0,0,0,0,0,0
0,0,0,0,0,0,0,0,0,0,0,0,0,0,0,0,0,0,0,0,0,0,0,0,0,0,0,0,0,0,0,0
endlayer

