
# Created by Ruins mod version 1.14.3 Ingame Parser
# authoring Player: maireilla

# TEMPLATE PARAMETER SETTINGS:
#
# criterion expression specifying mod ids required to load template
# may include plus (AND), minus (AND NOT), comma (OR), and parentheses
# all required mods listed must be present; no prohibited mods can be
requiredMods=
#
# likelihood this template will be chosen relative to all others
# e.g., a weight=6 template is chosen 3X as often as one with weight=2
weight=1
#
# list of dimensions in which this template may spawn, even if generic
# one or more dimension names, separated by commas (blank = all)
dimensionsToSpawnIn=overworld
#
# list of other biomes in which this template may spawn
# biome corresponding to directory is always assumed, listed or not
# generic templates should leave this list empty
biomesToSpawnIn=
#
# criterion expression specifying types of biome where template spawns
# this is in addition to those explicitly listed as biomesToSpawnIn
# generic templates should leave this list empty
biomeTypesToSpawnIn=
#
# list of biomes in which this template may not spawn
# takes precedence over biomeTypesToSpawnIn, but NOT biomesToSpawnIn
# should be empty if biomeTypesToSpawnIn is empty
biomesToNotSpawnIn=
#
# depth template is pushed down into the surface when built
# offset is min/max range of random additional bury depth
embed_into_distance=0
random_height_offset=0,0
#
# whitelist/blacklist of block states on which template may be built
# specify one, not both; leave the other empty (both empty = allow all)
# CAUTION: THE DEFAULTS ONLY APPLY TO NON-FLOWING LAVA AND WATER VARIANTS)
acceptable_target_blocks=
unacceptable_target_blocks={Properties:{level:"0"},Name:"minecraft:water"},{Properties:{level:"0"},Name:"minecraft:lava"}
#
# size of template (#layers, #rows per layer, #blocks per row)
dimensions=42,36,42
#
# max number of missing blocks allowed in surface beneath template
allowable_overhang=0
#
# depth/height limit affected by terrain leveling
# also maximum bumpiness tolerated in surface beneath template
max_leveling=6
#
# padding applied to all sides of template horizontal footprint
# expands area affected by terrain leveling (-1 = no leveling)
leveling_buffer=0
#
# do not rotate template randomly when built (1 = no rotation)
preventRotation=0
#
# treat water/lava blocks as air and protect them from rule0 (1 = yes)
preserve_water=0
preserve_lava=0
#
# minimum distance this template must have from instances of itself
uniqueMinDistance=0
#
# min/max distances this template can be from world spawn (0 = no limit)
# only applies to overworld--i.e., dimension 0
spawnMinDistance=0
spawnMaxDistance=0
#
# other template built nearby whenever this one is
# syntax: <name>;<relativeX>;<maxYdifference>;<relativeZ>[;<chance>]
# may be used more than once to specify multiple neighbors
adjoining_template=

rule1=0,100,{Properties:{distance:"7",persistent:"true"},Name:"minecraft:spruce_leaves"}
rule2=0,100,{Name:"minecraft:mossy_cobblestone"}
rule3=0,100,{Name:"minecraft:mossy_stone_brick_wall"}
rule4=0,100,{Name:"minecraft:mossy_stone_brick_wall"}
rule5=0,100,{Name:"minecraft:cobweb"}
rule6=0,100,{Name:"minecraft:mossy_stone_brick_wall"}
rule7=0,100,{Name:"minecraft:stone"}
rule8=0,100,{Name:"minecraft:mossy_stone_brick_wall"}
rule9=0,100,{Name:"minecraft:mossy_stone_brick_wall"}
rule10=0,100,{Properties:{distance:"7",persistent:"true"},Name:"minecraft:jungle_leaves"}
rule11=0,100,{Name:"minecraft:chiseled_stone_bricks"}
rule12=0,100,{Name:"minecraft:mossy_stone_brick_wall"}
rule13=0,100,{Name:"minecraft:andesite"}
rule14=0,100,{Name:"minecraft:mossy_stone_brick_wall"}
rule15=0,100,{Properties:{waterlogged:"false",type:"bottom"},Name:"minecraft:stone_slab"}
rule16=0,100,{Name:"minecraft:mossy_stone_brick_wall"}
rule17=0,100,{Name:"minecraft:mossy_stone_brick_wall"}
rule18=0,100,{Name:"minecraft:mossy_stone_brick_wall"}
rule19=0,100,{Name:"minecraft:mossy_cobblestone_wall"}
rule20=0,100,{Name:"minecraft:mossy_cobblestone_wall"}
rule21=0,100,{Name:"minecraft:mossy_stone_bricks"}
rule22=0,100,{Name:"minecraft:mossy_cobblestone_wall"}
rule23=0,100,{Ruins:{entity:{LootTable:"minecraft:chests/simple_dungeon",LootTableSeed:-4494075730637359517L}},Properties:{waterlogged:"false",facing:north,type:"single"},Name:"minecraft:chest"}{Ruins:{entity:{LootTable:"minecraft:chests/jungle_temple"}},Properties:{waterlogged:"false",facing:north,type:"single"},Name:"minecraft:chest"}{Ruins:{entity:{ForgeData:{LootTable:"minecraft:chests/desert_pyramid"},Items:[],Lock:""}},Properties:{waterlogged:"false",facing:north,type:"single"},Name:"minecraft:chest"}
rule24=0,100,{Ruins:{entity:{SpawnPotentials:[{weight:1,data:{entity:{id:"minecraft:zombie"}}}]}}, Name:"minecraft:spawner"}{Ruins:{entity:{SpawnPotentials:[{weight:1,data:{entity:{id:"minecraft:skeleton"}}}]}}, Name:"minecraft:spawner"}{Ruins:{entity:{SpawnPotentials:[{weight:1,data:{entity:{id:"minecraft:spider"}}}]}}, Name:"minecraft:spawner"}{Ruins:{entity:{SpawnPotentials:[{weight:1,data:{entity:{id:"minecraft:cave_spider"}}}]}}, Name:"minecraft:spawner"}
rule25=0,100,{Name:"minecraft:mossy_stone_brick_wall"}
rule26=0,100,{Properties:{half:"bottom",waterlogged:"false",shape:"straight",facing:"south"},Name:"minecraft:stone_brick_stairs"}
rule27=0,100,{Properties:{half:"bottom",waterlogged:"false",shape:"straight",facing:"north"},Name:"minecraft:stone_brick_stairs"}
rule28=0,100,{Name:"minecraft:mossy_stone_brick_wall"}
rule29=0,100,{Name:"minecraft:mossy_stone_brick_wall"}
rule30=0,100,{Ruins:{entity:{LootTable:"minecraft:chests/simple_dungeon",LootTableSeed:-4494073760631239517L}},Properties:{waterlogged:"false",facing:north,type:"single"},Name:"minecraft:chest"}{Ruins:{entity:{LootTable:"minecraft:chests/jungle_temple"}},Properties:{waterlogged:"false",facing:north,type:"single"},Name:"minecraft:chest"}{Ruins:{entity:{ForgeData:{LootTable:"minecraft:chests/desert_pyramid"},Items:[],Lock:""}},Properties:{waterlogged:"false",facing:north,type:"single"},Name:"minecraft:chest"}
rule31=0,100,{Name:"minecraft:mossy_cobblestone_wall"}
rule32=0,100,{Name:"minecraft:mossy_cobblestone_wall"}
rule33=0,100,{Name:"minecraft:mossy_stone_brick_wall"}
rule34=0,100,{Name:"minecraft:mossy_stone_brick_wall"}
rule35=0,100,{Properties:{east:"false",waterlogged:"false",south:"true",north:"true",west:"false"},Name:"minecraft:iron_bars"}
rule36=0,100,{Properties:{east:"true",waterlogged:"false",south:"false",north:"false",west:"true"},Name:"minecraft:iron_bars"}
rule37=0,100,{Name:"minecraft:mossy_cobblestone_wall"}
rule38=0,100,{Name:"minecraft:mossy_cobblestone_wall"}
rule39=0,100,{Properties:{lit:"true",facing:"north"},Name:"minecraft:redstone_wall_torch"}
rule40=0,100,{Properties:{east:"false",waterlogged:"false",south:"false",north:"true",west:"true"},Name:"minecraft:iron_bars"}
rule41=0,100,{Name:"minecraft:mossy_cobblestone_wall"}
rule42=0,100,{Properties:{east:"true",waterlogged:"false",south:"true",north:"false",west:"false"},Name:"minecraft:iron_bars"}
rule43=0,100,{Name:"minecraft:mossy_cobblestone_wall"}
rule44=0,100,{Name:"minecraft:mossy_cobblestone_wall"}
rule45=0,100,{Name:"minecraft:mossy_cobblestone_wall"}
rule46=0,100,{Properties:{lit:"true",facing:"south"},Name:"minecraft:redstone_wall_torch"}
rule47=0,100,{Name:"minecraft:mossy_stone_brick_wall"}
rule48=0,100,{Name:"minecraft:mossy_cobblestone_wall"}
rule49=0,100,{Properties:{half:"bottom",waterlogged:"false",shape:"straight",facing:"east"},Name:"minecraft:stone_brick_stairs"}
rule50=0,100,{Properties:{half:"bottom",waterlogged:"false",shape:"straight",facing:"west"},Name:"minecraft:stone_brick_stairs"}
rule51=0,100,{Properties:{half:"bottom",waterlogged:"false",shape:"inner_left",facing:"west"},Name:"minecraft:stone_brick_stairs"}
rule52=0,100,{Ruins:{entity:{LootTable:"minecraft:chests/simple_dungeon",LootTableSeed:-1114073760637359517L}},Properties:{waterlogged:"false",facing:north,type:"single"},Name:"minecraft:chest"}{Ruins:{entity:{LootTable:"minecraft:chests/jungle_temple"}},Properties:{waterlogged:"false",facing:north,type:"single"},Name:"minecraft:chest"}{Ruins:{entity:{ForgeData:{LootTable:"minecraft:chests/desert_pyramid"},Items:[],Lock:""}},Properties:{waterlogged:"false",facing:north,type:"single"},Name:"minecraft:chest"}
rule53=0,100,{Properties:{east:"false",waterlogged:"false",south:"true",north:"false",west:"false"},Name:"minecraft:iron_bars"}
rule54=0,100,{Properties:{east:"false",waterlogged:"false",south:"false",north:"false",west:"false"},Name:"minecraft:iron_bars"}
rule55=0,100,{Properties:{east:"true",waterlogged:"false",south:"true",north:"false",west:"true"},Name:"minecraft:iron_bars"}
rule56=0,100,{Ruins:{entity:{LootTable:"minecraft:chests/simple_dungeon",LootTableSeed:-3334073760637359517L}},Properties:{waterlogged:"false",facing:north,type:"single"},Name:"minecraft:chest"}{Ruins:{entity:{LootTable:"minecraft:chests/jungle_temple"}},Properties:{waterlogged:"false",facing:north,type:"single"},Name:"minecraft:chest"}{Ruins:{entity:{ForgeData:{LootTable:"minecraft:chests/desert_pyramid"},Items:[],Lock:""}},Properties:{waterlogged:"false",facing:north,type:"single"},Name:"minecraft:chest"}
rule57=0,100,{Properties:{lit:"true",facing:"east"},Name:"minecraft:redstone_wall_torch"}
rule58=0,100,{Properties:{waterlogged:"false",type:"double"},Name:"minecraft:smooth_stone_slab"}
rule59=0,100,{Name:"minecraft:cobblestone"}
rule60=0,100,{Properties:{east:"true",waterlogged:"false",south:"false",north:"true",west:"true"},Name:"minecraft:iron_bars"}
rule61=0,100,{Properties:{lit:"true",facing:"west"},Name:"minecraft:redstone_wall_torch"}
rule62=0,100,{Properties:{waterlogged:"false",type:"bottom"},Name:"minecraft:smooth_stone_slab"}
rule63=0,100,{Properties:{east:"false",waterlogged:"false",south:"false",north:"true",west:"false"},Name:"minecraft:iron_bars"}
rule64=0,100,{Properties:{east:"true",waterlogged:"false",south:"true",north:"true",west:"false"},Name:"minecraft:iron_bars"}
rule65=0,100,{Properties:{waterlogged:"false",type:"top"},Name:"minecraft:smooth_stone_slab"}

layer
0,0,0,0,0,0,0,0,0,0,0,0,0,0,0,0,0,0,0,0,0,0,0,0,0,0,0,0,0,0,0,0,0,0,0,0,0,0,0,0,0,0
0,0,0,0,0,0,0,0,0,0,0,0,0,0,0,0,0,0,0,0,0,0,0,0,0,0,0,0,0,0,0,0,0,0,0,0,0,0,0,0,0,0
0,0,0,0,0,0,0,0,0,0,0,0,0,0,0,0,0,0,0,0,0,0,0,0,0,0,0,0,0,0,0,0,0,0,0,0,0,0,0,0,0,0
0,0,0,0,0,0,0,0,0,0,1,1,0,1,0,1,0,1,0,1,0,1,0,1,1,0,0,0,0,0,0,0,0,0,0,0,0,0,0,0,0,0
0,0,0,0,0,0,0,0,0,1,2,2,3,2,3,2,3,2,3,2,3,2,3,2,2,1,0,0,0,0,0,0,0,0,0,0,0,0,0,0,0,0
0,0,0,0,0,0,0,0,0,1,2,0,0,0,0,0,0,0,0,0,0,0,0,0,2,1,0,0,0,0,0,0,0,0,0,0,0,0,0,0,0,0
0,0,0,0,0,0,0,0,0,0,4,0,0,0,0,0,0,0,0,0,0,0,0,0,4,0,0,0,0,0,0,0,0,0,0,0,0,0,0,0,0,0
0,0,0,0,0,0,0,0,0,1,2,0,0,0,0,0,0,0,0,0,0,0,0,0,2,1,0,0,0,0,0,0,0,0,0,0,0,0,0,0,0,0
0,0,0,0,0,0,0,0,0,0,4,0,0,0,0,0,0,0,0,0,0,0,0,0,4,0,0,0,0,0,0,0,0,0,0,0,0,0,0,0,0,0
0,0,0,0,0,0,0,0,0,1,2,0,0,0,0,0,0,0,0,0,0,0,0,0,2,1,0,0,0,0,0,0,0,0,0,0,0,0,0,0,0,0
0,0,0,0,0,0,0,0,0,0,4,0,0,0,0,0,0,0,0,0,0,0,0,0,4,0,0,0,0,0,0,0,0,0,0,0,0,0,0,0,0,0
0,0,0,0,0,0,0,0,0,1,2,0,0,0,0,0,0,0,0,0,0,0,0,0,2,1,0,0,0,0,0,0,0,0,0,0,0,0,0,0,0,0
0,0,0,0,0,0,0,0,0,0,4,0,0,0,0,0,0,0,0,0,0,0,0,0,4,0,0,0,0,0,0,0,0,0,0,0,0,0,0,0,0,0
0,0,8,7,6,0,0,0,0,1,2,5,0,0,0,0,0,0,0,0,0,0,5,0,2,1,0,0,0,0,0,0,0,0,0,0,0,0,0,0,0,0
0,8,7,0,7,6,1,0,1,0,4,0,0,0,0,0,0,0,0,0,0,0,0,0,9,7,0,0,0,0,0,0,0,0,0,0,0,0,0,0,0,0
0,7,0,0,0,7,2,3,2,1,2,0,5,0,0,0,0,0,0,0,0,0,0,0,2,2,2,7,10,0,1,7,1,0,0,0,0,0,0,0,0,0
0,12,7,0,0,0,0,0,0,0,0,0,0,5,0,0,0,0,0,0,0,0,0,0,0,0,0,2,11,7,2,2,2,7,1,0,0,0,0,0,0,0
0,0,12,7,0,0,0,0,0,0,0,0,0,0,0,0,0,0,0,0,0,0,0,0,13,0,0,0,2,2,0,0,0,2,2,7,0,0,0,0,0,0
0,0,1,2,0,0,0,0,0,0,0,0,0,0,0,2,3,2,3,2,14,2,0,0,13,0,0,0,0,0,0,0,0,0,0,2,1,0,0,0,0,0
0,0,0,4,0,0,0,0,0,0,0,0,0,0,0,1,0,1,0,1,7,2,0,0,0,0,0,0,0,0,0,0,0,0,0,2,7,0,0,0,0,0
0,0,1,2,0,0,0,0,0,0,0,0,0,0,0,2,1,0,0,0,0,2,0,0,0,0,0,0,0,0,0,0,0,0,0,0,2,1,0,0,0,0
0,0,0,4,0,0,0,0,0,0,0,0,0,0,0,4,0,0,0,0,0,7,2,0,0,0,0,0,0,0,0,0,0,0,0,0,2,7,0,0,0,0
0,0,1,2,0,0,0,0,0,0,0,0,0,0,0,2,1,0,0,0,0,10,11,2,0,0,0,0,0,0,0,0,0,0,0,0,2,1,0,0,0,0
0,0,0,4,0,0,0,0,0,0,0,0,0,0,0,4,0,0,0,0,0,0,10,7,2,2,7,2,0,0,0,0,0,0,0,2,7,0,0,0,0,0
0,0,1,2,0,5,0,0,0,0,0,0,5,0,0,2,1,0,0,0,0,0,0,0,0,7,1,2,0,0,0,0,0,0,0,2,1,0,0,0,0,0
0,0,0,4,0,0,0,0,0,0,0,0,0,0,0,4,0,0,0,0,0,0,0,0,0,0,0,7,2,2,0,0,0,2,2,7,0,0,0,0,0,0
0,0,1,2,0,0,0,0,0,0,0,0,0,0,0,2,1,0,0,0,0,0,0,0,0,0,0,0,1,7,2,2,2,7,1,0,0,0,0,0,0,0
0,0,0,4,0,0,0,0,0,0,0,0,0,0,0,4,5,0,0,0,0,0,0,0,0,0,0,0,0,0,1,7,1,0,0,0,0,0,0,0,0,0
0,0,1,2,0,0,0,0,0,0,0,0,0,0,0,2,1,0,0,0,0,0,0,0,0,0,0,0,0,0,0,0,0,0,0,0,0,0,0,0,0,0
0,0,0,4,0,0,0,0,0,0,0,0,0,0,0,4,0,0,0,0,0,0,0,0,0,0,0,0,0,0,0,0,0,0,0,0,0,0,0,0,0,0
0,0,1,2,0,0,0,0,0,0,0,0,0,0,5,2,1,0,0,0,0,0,0,0,0,0,0,0,0,0,0,0,0,0,0,0,0,0,0,0,0,0
0,0,1,2,2,3,2,3,2,3,2,3,2,3,2,2,1,0,0,0,0,0,0,0,0,0,0,0,0,0,0,0,0,0,0,0,0,0,0,0,0,0
0,0,0,1,1,0,1,0,1,0,1,0,1,0,1,1,0,0,0,0,0,0,0,0,0,0,0,0,0,0,0,0,0,0,0,0,0,0,0,0,0,0
0,0,0,0,0,0,0,0,0,0,0,0,0,0,0,0,0,0,0,0,0,0,0,0,0,0,0,0,0,0,0,0,0,0,0,0,0,0,0,0,0,0
0,0,0,0,0,0,0,0,0,0,0,0,0,0,0,0,0,0,0,0,0,0,0,0,0,0,0,0,0,0,0,0,0,0,0,0,0,0,0,0,0,0
0,0,0,0,0,0,0,0,0,5,0,0,0,0,0,0,0,0,0,0,0,0,0,0,0,0,0,0,0,0,0,0,0,0,0,0,0,0,0,0,0,0
endlayer

layer
0,0,0,0,0,0,0,0,0,0,0,0,0,0,0,0,0,0,0,0,0,0,0,0,0,0,0,0,0,0,0,0,0,0,0,0,0,0,0,0,0,0
0,0,0,0,0,0,0,0,0,0,0,0,0,0,0,0,0,0,0,0,0,0,0,0,0,0,0,0,0,0,0,0,0,0,0,0,0,0,0,0,0,0
0,0,0,0,0,0,0,0,0,0,0,0,0,0,0,0,0,0,0,0,0,0,0,0,0,0,0,0,0,0,0,0,0,0,0,0,0,0,0,0,0,0
0,0,0,0,0,0,0,0,0,0,1,15,0,15,0,15,0,15,0,15,0,15,0,15,1,0,0,0,0,0,0,0,0,0,0,0,0,0,0,0,0,0
0,0,0,0,0,0,0,0,0,1,2,7,14,7,14,7,14,7,14,7,14,7,14,7,2,1,0,0,0,0,0,0,0,0,0,0,0,0,0,0,0,0
0,0,0,0,0,0,0,0,0,15,7,13,13,13,13,13,13,13,13,13,13,13,13,13,7,15,0,0,0,0,0,0,0,0,0,0,0,0,0,0,0,0
0,0,0,0,0,0,0,0,0,0,9,13,13,13,13,13,13,13,13,13,13,13,13,13,16,0,0,0,0,0,0,0,0,0,0,0,0,0,0,0,0,0
0,0,0,0,0,0,0,0,0,15,7,13,13,13,13,13,13,13,13,13,13,13,13,13,7,15,0,0,0,0,0,0,0,0,0,0,0,0,0,0,0,0
0,0,0,0,0,0,0,0,0,0,9,13,13,13,13,13,13,13,13,13,13,13,13,13,16,0,0,0,0,0,0,0,0,0,0,0,0,0,0,0,0,0
0,0,0,0,0,0,0,0,0,15,7,13,13,13,13,13,13,13,13,13,13,13,13,13,7,15,0,0,0,0,0,0,0,0,0,0,0,0,0,0,0,0
0,0,0,0,0,0,0,0,0,0,9,13,13,13,13,13,13,13,13,13,13,13,13,13,16,0,0,0,0,0,0,0,0,0,0,0,0,0,0,0,0,0
0,0,0,0,0,0,0,0,0,15,7,13,13,13,13,13,13,13,13,13,13,13,13,13,7,15,0,0,0,0,0,0,0,0,0,0,0,0,0,0,0,0
0,0,0,0,0,0,0,0,0,0,9,13,13,13,13,13,13,13,13,13,13,13,13,13,16,0,0,0,0,0,0,0,0,0,0,0,0,0,0,0,0,0
0,0,2,14,2,0,0,0,0,15,7,13,13,13,13,13,13,13,13,13,13,13,13,13,7,15,0,0,0,0,0,0,0,0,0,0,0,0,0,0,0,0
0,2,13,13,13,2,15,0,15,0,15,13,13,13,13,13,13,13,13,13,13,13,13,13,16,1,0,0,0,0,0,0,0,0,0,0,0,0,0,0,0,0
0,9,13,13,13,17,7,14,7,15,7,13,13,13,13,13,13,13,13,13,13,13,13,13,7,7,2,1,0,0,0,1,0,0,0,0,0,0,0,0,0,0
0,2,13,13,13,13,13,13,13,13,13,13,13,13,13,13,13,13,13,13,13,13,13,13,13,13,13,2,11,1,2,7,2,1,0,0,0,0,0,0,0,0
0,0,2,17,13,13,13,13,13,13,13,13,13,13,13,13,13,13,13,13,13,13,13,13,13,13,13,13,2,7,13,13,13,7,2,1,0,0,0,0,0,0
0,0,15,7,13,13,13,13,13,13,13,13,13,13,13,7,15,7,18,7,18,7,13,13,13,13,13,13,13,13,13,13,13,13,13,2,0,0,0,0,0,0
0,0,0,9,13,13,13,13,13,13,13,13,13,13,13,15,0,15,0,15,1,7,13,13,13,13,13,13,13,13,13,13,13,13,13,7,1,0,0,0,0,0
0,0,15,7,13,13,13,13,13,13,13,13,13,13,13,7,15,0,0,0,0,2,13,13,13,13,13,13,13,13,13,13,13,13,13,13,2,0,0,0,0,0
0,0,0,9,13,13,13,13,13,13,13,13,13,13,13,16,0,0,0,0,0,1,2,13,13,13,13,13,13,13,13,13,13,13,13,13,7,1,0,0,0,0
0,0,15,7,13,13,13,13,13,13,13,13,13,13,13,7,15,0,0,0,0,0,11,2,13,13,13,13,13,13,13,13,13,13,13,13,2,0,0,0,0,0
0,0,0,9,13,13,13,13,13,13,13,13,13,13,13,16,0,0,0,0,0,0,0,1,2,7,2,7,13,13,13,13,13,13,13,7,1,0,0,0,0,0
0,0,15,7,13,13,13,13,13,13,13,13,13,13,13,7,15,0,0,0,0,0,0,0,0,1,0,2,13,13,13,13,13,13,13,2,0,0,0,0,0,0
0,0,0,9,13,13,13,13,13,13,13,13,13,13,13,16,0,0,0,0,0,0,0,0,0,0,0,1,2,7,13,13,13,7,2,1,0,0,0,0,0,0
0,0,15,7,13,13,13,13,13,13,13,13,13,13,13,7,15,0,0,0,0,0,0,0,0,0,0,0,0,1,2,7,2,1,0,0,0,0,0,0,0,0
0,0,0,9,13,13,13,13,13,13,13,13,13,13,13,16,0,0,0,0,0,0,0,0,0,0,0,0,0,0,0,1,0,0,0,0,0,0,0,0,0,0
0,0,15,7,13,13,13,13,13,13,13,13,13,13,13,7,15,0,0,0,0,0,0,0,0,0,0,0,0,0,0,0,0,0,0,0,0,0,0,0,0,0
0,0,0,9,13,13,13,13,13,13,13,13,13,13,13,16,0,0,0,0,0,0,0,0,0,0,0,0,0,0,0,0,0,0,0,0,0,0,0,0,0,0
0,0,15,7,13,13,13,13,13,13,13,13,13,13,13,7,15,0,0,0,0,0,0,0,0,0,0,0,0,0,0,0,0,0,0,0,0,0,0,0,0,0
0,0,1,2,7,18,7,18,7,18,7,18,7,18,7,2,1,0,0,0,0,0,0,0,0,0,0,0,0,0,0,0,0,0,0,0,0,0,0,0,0,0
0,0,0,1,15,0,15,0,15,0,15,0,15,0,15,1,0,0,0,0,0,0,0,0,0,0,0,0,0,0,0,0,0,0,0,0,0,0,0,0,0,0
0,0,0,0,0,0,0,0,0,0,0,0,0,0,0,0,0,0,0,0,0,0,0,0,0,0,0,0,0,0,0,0,0,0,0,0,0,0,0,0,0,0
0,0,0,0,0,0,0,0,0,0,0,0,0,0,0,0,0,0,0,0,0,0,0,0,0,0,0,0,0,0,0,0,0,0,0,0,0,0,0,0,0,0
0,0,0,0,0,0,0,0,5,0,0,0,0,0,0,0,0,0,0,0,0,0,0,0,0,0,0,0,0,0,0,0,0,0,0,0,0,0,0,0,0,0
endlayer

layer
0,0,0,0,0,0,0,0,0,0,0,0,0,0,0,0,0,0,0,0,0,0,0,0,0,0,0,0,0,0,0,0,0,0,0,0,0,0,0,0,0,0
0,0,0,0,0,0,0,0,0,0,0,0,0,0,0,0,0,0,0,0,0,0,0,0,0,0,0,0,0,0,0,0,0,0,0,0,0,0,0,0,0,0
0,0,0,0,0,0,0,0,0,0,0,0,0,0,0,0,0,0,0,0,0,0,0,0,0,0,0,0,0,0,0,0,0,0,0,0,0,0,0,0,0,0
0,0,0,0,0,0,0,0,0,0,19,0,0,0,0,0,0,0,0,0,0,0,0,0,19,0,0,0,0,0,0,0,0,0,0,0,0,0,0,0,0,0
0,0,0,0,0,0,0,0,0,22,11,21,21,21,21,21,21,21,21,21,21,21,21,21,11,20,5,0,0,0,0,0,0,0,0,0,0,0,0,0,0,0
0,0,0,0,0,0,0,0,0,0,21,0,0,0,0,0,0,0,0,0,0,0,0,0,21,0,0,0,0,0,0,0,0,0,0,0,0,0,0,0,0,0
0,0,0,0,0,0,0,0,0,0,21,0,0,0,0,0,0,0,0,0,0,0,0,0,21,0,0,0,0,0,0,0,0,0,0,0,0,0,0,0,0,0
0,0,0,0,0,0,0,0,0,0,21,0,0,0,0,0,0,0,0,0,0,0,0,5,21,0,0,0,0,0,0,0,0,0,0,0,0,0,0,0,0,0
0,0,0,0,0,0,0,0,0,0,21,0,0,0,21,23,0,0,0,0,0,0,0,0,21,0,0,0,0,0,0,0,0,0,0,0,0,0,0,0,0,0
0,0,0,0,0,0,0,0,0,0,21,0,0,21,24,21,0,0,0,0,0,0,0,0,21,0,0,0,0,0,0,0,0,0,0,0,0,0,0,0,0,0
0,0,0,0,0,0,0,0,0,0,21,0,0,0,21,0,0,0,0,0,0,0,0,0,21,0,0,0,0,0,0,0,0,0,0,0,0,0,0,0,0,0
0,0,0,0,0,0,0,0,0,0,21,0,0,0,0,0,0,0,0,0,0,0,0,0,21,0,0,0,0,0,0,0,0,0,0,0,0,0,0,0,0,0
0,0,0,0,0,0,0,0,0,0,21,0,0,0,0,0,0,21,0,0,0,0,0,0,21,0,0,0,0,0,0,0,0,0,0,0,0,0,0,0,0,0
0,11,21,21,21,11,0,0,0,0,21,0,0,0,0,0,21,24,21,0,0,0,0,0,21,0,0,0,0,0,0,0,0,0,0,0,0,0,0,0,0,0
0,21,0,0,0,21,6,0,25,0,21,0,0,0,0,0,0,21,0,0,0,0,0,0,21,7,1,0,0,0,0,0,0,0,0,0,0,0,0,0,0,0
0,21,0,0,0,21,11,21,11,21,11,0,0,0,0,0,0,0,0,0,0,0,0,0,2,7,2,15,0,0,0,15,0,0,0,0,0,0,0,0,0,0
0,21,0,0,0,0,0,0,0,0,0,0,0,0,0,0,0,0,0,0,0,0,0,0,0,0,0,2,2,2,2,2,2,2,1,0,0,0,0,0,0,0
0,11,21,21,0,0,0,0,0,0,0,0,0,0,0,0,0,0,0,0,0,0,0,0,0,0,0,0,2,2,0,0,0,2,2,2,0,0,0,0,0,0
0,0,12,21,0,0,0,0,0,0,0,0,0,0,0,21,21,21,21,21,21,2,0,5,0,0,0,0,0,0,0,0,0,0,0,2,1,0,0,0,0,0
0,0,0,27,0,0,0,0,0,0,0,0,0,0,0,26,0,0,0,0,7,7,0,0,0,0,0,0,0,0,0,0,0,0,0,2,2,0,0,0,0,0
0,0,29,21,0,0,0,0,0,0,0,0,0,0,0,21,28,0,0,0,1,2,0,0,0,0,0,0,0,21,0,0,0,0,0,0,2,0,0,0,0,0
0,0,0,27,0,0,0,0,0,0,0,0,0,0,0,26,0,0,0,0,0,15,2,0,0,0,0,0,21,24,21,0,0,0,0,5,2,15,0,0,0,0
0,0,29,21,0,0,0,0,21,0,0,0,0,0,0,21,28,0,0,0,0,0,2,2,0,0,0,0,0,21,0,0,0,0,0,0,2,0,0,0,0,0
0,0,0,27,0,0,0,21,24,21,0,0,0,0,0,26,0,0,0,0,0,0,0,15,2,7,2,2,0,0,0,0,0,0,0,2,2,0,0,0,0,0
0,0,29,21,0,0,0,0,21,0,0,0,0,0,0,21,28,0,0,0,0,0,0,0,1,7,1,2,5,0,0,0,0,0,0,2,1,0,0,0,0,0
0,0,0,27,0,0,0,0,0,0,0,0,0,0,0,26,0,0,0,0,0,0,0,0,0,0,0,2,2,2,0,0,0,2,2,2,0,0,0,0,0,0
0,0,29,21,0,0,0,0,0,0,0,0,0,0,0,21,28,0,0,0,0,0,0,0,0,0,0,0,1,2,2,2,2,2,1,0,0,0,0,0,0,0
0,0,0,27,0,0,0,0,0,0,0,0,0,0,0,26,0,0,0,0,0,0,0,0,0,0,0,0,0,0,0,15,0,0,0,0,0,0,0,0,0,0
0,0,29,21,0,0,0,0,0,0,0,0,0,0,0,21,28,0,0,0,0,0,0,0,0,0,0,0,0,0,0,0,0,0,0,0,0,0,0,0,0,0
0,0,0,27,0,0,0,0,0,0,0,0,0,0,0,26,0,0,0,0,0,0,0,0,0,0,0,0,0,0,0,0,0,0,0,0,0,0,0,0,0,0
0,0,8,21,0,0,0,0,0,0,0,0,0,0,30,21,6,0,0,0,0,0,0,0,0,0,0,0,0,0,0,0,0,0,0,0,0,0,0,0,0,0
0,0,32,11,11,21,11,21,11,21,11,21,11,21,11,11,31,0,0,0,0,0,0,0,0,0,0,0,0,0,0,0,0,0,0,0,0,0,0,0,0,0
0,0,0,32,34,0,33,0,33,0,33,0,33,0,12,31,0,0,0,0,0,0,0,0,0,0,0,0,0,0,0,0,0,0,0,0,0,0,0,0,0,0
0,0,0,0,0,0,0,0,0,0,0,0,0,0,0,0,0,0,0,0,0,0,0,0,0,0,0,0,0,0,0,0,0,0,0,0,0,0,0,0,0,0
0,0,0,0,0,0,0,0,0,0,0,0,0,0,0,0,0,0,0,0,0,0,0,0,0,0,0,0,0,0,0,0,0,0,0,0,0,0,0,0,0,0
0,0,0,0,0,0,0,0,0,0,0,0,0,0,0,0,0,0,0,0,0,0,0,0,0,0,0,0,0,0,0,0,0,0,0,0,0,0,0,0,0,0
endlayer

layer
0,0,0,0,0,0,0,0,0,0,0,0,0,0,0,0,0,0,0,0,0,0,0,0,0,0,0,0,0,0,0,0,0,0,0,0,0,0,0,0,0,0
0,0,0,0,0,0,0,0,0,0,0,0,0,0,0,0,0,0,0,0,0,0,0,0,0,0,0,0,0,0,0,0,0,0,0,0,0,0,0,0,0,0
0,0,0,0,0,0,0,0,0,0,0,0,0,0,0,0,0,0,0,0,0,0,0,0,0,0,0,0,0,0,0,0,0,0,0,0,0,0,0,0,0,0
0,0,0,0,0,0,0,0,0,0,19,10,19,0,19,10,19,0,19,10,19,0,19,10,19,5,0,0,0,0,0,0,0,0,0,0,0,0,0,0,0,0
0,0,0,0,0,0,0,0,0,22,11,21,21,35,21,21,21,35,21,21,21,35,21,21,11,20,0,0,0,0,0,0,0,0,0,0,0,0,0,0,0,0
0,0,0,0,0,0,0,0,0,10,21,0,0,0,0,0,0,0,0,0,0,0,0,0,21,10,0,0,0,0,0,0,0,0,0,0,0,0,0,0,0,0
0,0,0,0,0,0,0,0,0,22,21,0,0,0,0,0,0,0,0,0,0,0,0,0,21,20,0,0,0,0,0,0,0,0,0,0,0,0,0,0,0,0
0,0,0,0,0,0,0,0,0,0,36,0,0,0,0,0,0,0,0,0,0,0,0,0,36,0,0,0,0,0,0,0,0,0,0,0,0,0,0,0,0,0
0,0,0,0,0,0,0,0,0,22,21,0,0,0,21,0,0,0,0,0,0,0,0,0,21,20,0,0,0,0,0,0,0,0,0,0,0,0,0,0,0,0
0,0,0,0,0,0,0,0,0,10,21,0,0,21,21,21,0,0,0,0,0,0,5,0,21,10,0,0,0,0,0,0,0,0,0,0,0,0,0,0,0,0
0,0,0,0,0,0,0,0,0,22,21,0,0,0,21,0,0,0,0,0,0,0,0,0,21,20,0,0,0,0,0,0,0,0,0,0,0,0,0,0,0,0
0,0,0,0,0,0,0,0,0,0,36,0,0,0,0,0,0,0,0,0,0,0,0,0,36,0,0,0,0,0,0,0,0,0,0,0,0,0,0,0,0,0
0,0,0,0,0,0,0,0,0,22,21,0,0,0,0,0,0,21,0,0,0,0,0,0,21,20,0,0,0,0,0,0,0,0,0,0,0,0,0,0,0,0
0,10,21,35,21,10,0,0,0,10,21,0,0,0,0,0,21,21,21,0,0,0,0,0,21,10,0,0,0,0,0,0,0,0,0,0,0,0,0,0,0,0
0,21,0,0,0,21,10,0,10,22,21,0,0,0,0,0,0,21,0,0,0,0,0,0,21,37,1,0,0,0,0,0,0,0,0,0,0,0,0,0,0,0
0,36,0,0,0,40,11,35,11,35,11,39,0,0,0,0,0,0,0,0,5,0,0,0,2,38,2,0,0,0,0,0,0,0,0,0,0,0,0,0,0,0
0,21,0,0,0,0,0,0,0,0,0,0,0,0,0,0,0,0,0,0,0,0,0,0,0,0,0,2,1,2,41,2,41,2,10,0,0,0,0,0,0,0
0,10,21,42,0,0,0,0,0,5,0,0,0,0,0,0,0,0,0,0,0,0,0,0,0,0,0,0,2,1,0,0,0,1,2,1,0,0,0,0,0,0
0,0,10,21,0,0,0,0,0,0,0,0,0,0,0,21,21,35,21,21,21,2,0,0,0,0,0,0,0,0,0,0,0,0,0,2,10,0,0,0,0,0
0,0,0,36,0,0,0,0,0,0,0,0,0,0,0,36,44,0,44,10,32,43,0,0,0,0,0,0,0,0,0,0,0,0,0,1,2,0,0,0,0,0
0,0,10,21,0,0,0,0,0,0,0,0,0,0,0,21,10,0,0,0,1,2,0,0,0,0,0,0,0,21,0,0,0,0,0,0,45,0,0,0,0,0
0,0,0,36,0,0,0,0,0,0,0,0,0,0,0,36,0,0,0,0,0,0,2,0,0,0,0,0,21,21,21,0,0,0,0,46,2,0,0,0,0,0
0,0,10,21,0,0,0,0,21,0,0,0,0,0,0,21,10,0,0,0,0,0,1,2,0,0,0,0,0,21,0,0,0,0,0,0,45,0,0,0,0,0
0,0,0,36,0,0,0,21,21,21,0,0,0,0,0,36,0,0,0,0,0,0,0,0,2,41,2,1,0,0,0,0,0,0,5,1,2,0,0,0,0,0
0,0,10,21,0,0,0,0,21,0,0,0,0,0,0,21,10,0,0,0,0,0,0,0,1,0,1,2,0,0,0,0,0,0,0,2,10,0,0,0,0,0
0,0,0,36,0,0,0,0,0,0,0,0,0,0,0,36,0,0,0,0,0,0,0,0,0,0,0,1,2,1,0,0,0,1,2,1,0,0,0,0,0,0
0,0,10,21,39,0,0,0,0,0,0,0,0,0,0,21,10,0,0,0,0,0,0,0,0,0,0,0,10,2,41,2,41,2,10,0,0,0,0,0,0,0
0,0,0,36,0,0,0,5,0,0,0,0,0,0,0,36,0,0,0,0,0,0,0,0,0,0,0,0,0,0,0,0,0,0,0,0,0,0,0,0,0,0
0,0,10,21,0,0,0,0,0,0,0,0,0,0,0,21,10,0,0,0,0,0,0,0,0,0,0,0,0,0,0,0,0,0,0,0,0,0,0,0,0,0
0,0,0,36,0,0,0,0,0,0,0,0,0,0,0,36,0,0,0,0,0,0,0,0,0,0,0,0,0,0,0,0,0,0,0,0,0,0,0,0,0,0
0,0,10,21,0,0,0,0,0,0,0,0,0,0,0,21,10,0,0,0,0,0,0,0,0,0,0,0,0,0,0,0,0,0,0,0,0,0,0,0,0,0
0,0,22,11,11,35,11,35,11,35,11,35,11,35,11,11,20,0,0,0,0,0,0,0,0,0,0,0,0,0,0,0,0,0,0,0,0,0,0,0,0,0
0,0,0,44,10,0,10,0,10,0,10,0,10,0,10,44,0,0,0,0,0,0,0,0,0,0,0,0,0,0,0,0,0,0,0,0,0,0,0,0,0,0
0,0,0,0,0,0,0,0,0,0,0,0,0,0,0,0,0,0,0,0,0,0,0,0,0,0,0,0,0,0,0,0,0,0,0,0,0,0,0,0,0,0
0,0,0,0,0,0,0,0,0,0,0,0,0,0,0,0,0,0,0,0,0,0,0,0,0,0,0,0,0,0,0,0,0,0,0,0,0,0,0,0,0,0
0,0,0,0,0,0,0,0,0,0,0,0,0,0,0,0,0,0,0,0,0,0,0,0,0,0,0,0,0,0,0,0,0,0,0,0,0,0,0,0,0,0
endlayer

layer
0,0,0,0,0,0,0,0,0,0,0,0,0,0,0,0,0,0,0,0,0,0,0,0,0,0,0,0,0,0,0,0,0,0,0,0,0,0,0,0,0,0
0,0,0,0,0,0,0,0,0,0,0,0,0,0,0,0,0,0,0,0,0,0,0,0,0,0,0,0,0,0,0,0,0,0,0,0,0,0,0,0,0,0
0,0,0,0,0,0,0,0,0,0,0,0,0,0,0,0,0,0,0,0,0,0,0,0,0,0,0,0,0,0,0,0,0,0,0,0,0,0,0,0,0,0
0,0,0,0,0,0,0,0,0,0,19,10,19,0,19,10,19,0,19,10,19,0,19,10,19,0,0,0,0,0,0,0,0,0,0,0,0,0,0,0,0,0
0,0,0,0,0,0,0,0,0,22,11,21,21,35,21,21,21,35,21,21,21,35,21,21,11,20,0,0,0,0,0,0,0,0,0,0,0,0,0,0,0,0
0,0,0,0,0,0,0,0,0,10,21,0,0,0,0,0,0,0,0,0,0,0,0,0,21,10,0,0,0,0,0,0,0,0,0,0,0,0,0,0,0,0
0,0,0,0,0,0,0,0,0,22,21,0,0,0,0,0,0,0,0,0,0,0,0,0,21,20,0,0,0,0,0,0,0,0,0,0,0,0,0,0,0,0
0,0,0,0,0,0,0,0,0,0,36,0,0,0,5,0,0,0,0,0,0,0,0,0,36,0,0,0,0,0,0,0,0,0,0,0,0,0,0,0,0,0
0,0,0,0,0,0,0,0,0,22,21,0,0,0,21,0,0,0,0,0,0,0,0,0,21,20,0,0,0,0,0,0,0,0,0,0,0,0,0,0,0,0
0,0,0,0,0,0,0,0,0,10,21,0,0,21,21,21,0,0,0,0,0,0,0,0,21,10,0,0,0,0,0,0,0,0,0,0,0,0,0,0,0,0
0,0,0,0,0,0,0,0,0,22,21,0,0,0,21,0,0,0,0,0,0,0,0,0,21,20,0,0,0,0,0,0,0,0,0,0,0,0,0,0,0,0
0,0,0,0,0,0,0,0,0,0,36,0,0,0,0,0,0,0,0,0,0,0,0,0,36,0,0,0,0,0,0,0,0,0,0,0,0,0,0,0,0,0
0,0,0,0,0,0,0,0,0,22,21,0,0,0,0,0,0,21,0,0,0,0,0,0,21,20,0,0,0,0,0,0,0,0,0,0,0,0,0,0,0,0
0,10,21,35,21,10,0,0,0,10,21,0,0,0,0,0,21,21,21,0,0,0,0,0,21,10,0,0,0,0,0,0,0,0,0,0,0,0,0,0,0,0
0,21,0,0,0,21,10,0,10,22,21,0,0,0,0,0,0,21,0,0,0,0,0,0,21,37,1,0,0,0,0,0,0,0,0,0,0,0,0,0,0,0
0,36,0,0,0,40,11,35,11,35,11,0,0,0,0,0,0,0,0,0,0,0,0,0,2,38,2,10,0,0,0,0,0,0,0,0,0,0,0,0,0,0
0,21,0,0,0,0,0,0,0,0,0,0,0,0,0,0,0,0,0,0,0,0,0,0,0,0,0,2,1,2,41,2,41,2,10,0,0,0,0,0,0,0
0,10,21,42,0,0,0,0,0,0,0,0,0,0,0,0,0,0,0,0,0,0,0,0,0,0,0,0,2,1,0,0,0,1,2,1,0,0,0,0,0,0
0,0,10,21,0,0,0,0,0,0,0,0,0,0,0,21,21,35,21,21,21,2,0,0,0,0,0,0,0,0,0,0,0,0,0,2,10,0,0,0,0,0
0,0,0,36,0,0,0,0,5,0,0,0,0,0,0,36,44,0,44,10,32,43,0,0,0,0,0,0,0,0,0,0,0,0,5,1,2,0,0,0,0,0
0,0,10,21,0,0,0,0,0,0,0,0,0,0,0,21,10,0,0,0,1,2,0,0,0,0,0,0,0,21,0,0,0,0,0,0,45,0,0,0,0,0
0,0,0,36,0,0,0,0,0,0,0,0,0,0,0,36,0,0,0,0,0,10,2,0,0,0,0,0,21,21,21,0,0,0,0,0,2,0,0,0,0,0
0,0,10,21,0,0,0,0,21,0,0,0,0,0,0,21,10,0,0,0,0,0,1,2,0,0,0,0,0,21,0,0,0,0,0,0,45,0,0,0,0,0
0,0,0,36,0,0,0,21,21,21,0,0,0,0,0,36,0,0,0,0,0,0,0,10,2,41,2,1,0,0,0,0,0,0,0,1,2,0,0,0,0,0
0,0,10,21,0,0,0,0,21,0,0,0,0,0,0,21,10,0,0,0,0,0,0,0,1,0,1,2,0,0,0,0,0,0,0,2,10,0,0,0,0,0
0,0,0,36,0,0,0,0,0,0,0,0,0,0,0,36,0,0,0,0,0,0,0,0,0,0,0,1,2,1,0,0,0,1,2,1,0,0,0,0,0,0
0,0,10,21,0,0,0,0,0,0,0,0,0,0,0,21,10,0,0,0,0,0,0,0,0,0,0,0,10,2,41,2,41,2,10,0,0,0,0,0,0,0
0,0,0,36,0,0,0,0,0,0,0,0,0,0,0,36,0,0,0,0,0,0,0,0,0,0,0,0,0,0,0,0,0,0,0,0,0,0,0,0,0,0
0,0,10,21,0,0,0,0,0,0,0,0,0,0,0,21,10,0,0,0,0,0,0,0,0,0,0,0,0,0,0,0,0,0,0,0,0,0,0,0,0,0
0,0,0,36,0,0,0,0,0,0,0,0,0,0,0,36,0,0,0,0,0,0,0,0,0,0,0,0,0,0,0,0,0,0,0,0,0,0,0,0,0,0
0,0,10,21,0,0,0,0,0,0,0,0,0,0,0,21,10,0,0,0,0,0,0,0,0,0,0,0,0,0,0,0,0,0,0,0,0,0,0,0,0,0
0,0,22,11,11,35,11,35,11,35,11,35,11,35,11,11,20,0,0,0,0,0,0,0,0,0,0,0,0,0,0,0,0,0,0,0,0,0,0,0,0,0
0,0,0,44,10,0,10,0,10,0,10,0,10,0,10,44,0,0,0,0,0,0,0,0,0,0,0,0,0,0,0,0,0,0,0,0,0,0,0,0,0,0
0,0,0,0,0,0,0,0,0,0,0,0,0,0,0,0,0,0,0,0,0,0,0,0,0,0,0,0,0,0,0,0,0,0,0,0,0,0,0,0,0,0
0,0,0,0,0,0,0,0,0,0,0,0,0,0,0,0,0,0,0,0,0,0,0,0,0,0,0,0,0,0,0,0,0,0,0,0,0,0,0,0,0,0
0,0,0,0,0,0,0,0,0,0,0,0,0,0,0,0,0,0,0,0,0,0,0,0,0,0,0,0,0,0,0,0,0,0,0,0,0,0,0,0,0,0
endlayer

layer
0,0,0,0,0,0,0,0,0,0,0,0,0,0,0,0,0,0,0,0,0,0,0,0,0,0,0,0,0,0,0,0,0,0,0,0,0,0,0,0,0,0
0,0,0,0,0,0,0,0,0,0,0,0,0,0,0,0,0,0,0,0,0,0,0,0,0,0,0,0,0,0,0,0,0,0,0,0,0,0,0,0,0,0
0,0,0,0,0,0,0,0,0,0,0,0,0,0,0,0,0,0,0,0,0,0,0,0,0,0,0,0,0,0,0,0,0,0,0,0,0,0,0,0,0,0
0,0,0,0,0,0,0,0,0,0,48,28,0,0,0,47,0,0,0,47,0,0,0,29,37,0,0,0,0,0,0,0,0,0,0,0,0,0,0,0,0,0
0,0,0,0,0,0,0,0,0,48,11,49,49,49,49,49,49,49,49,49,49,49,49,49,11,37,0,0,0,0,0,0,0,0,0,0,0,0,0,0,0,0
0,0,0,0,0,0,0,0,0,33,27,13,13,13,13,13,13,13,13,13,13,13,13,13,26,33,0,0,0,0,0,0,0,0,0,0,0,0,0,0,0,0
0,0,0,0,0,0,0,0,0,0,27,13,13,13,13,13,13,13,13,13,13,13,13,13,26,0,0,0,0,0,0,0,0,0,0,0,0,0,0,0,0,0
0,0,0,0,0,0,0,0,0,0,27,13,13,13,13,13,13,13,13,13,13,13,13,13,26,0,0,0,0,0,0,0,0,0,0,0,0,0,0,0,0,0
0,0,0,0,0,0,0,0,0,0,27,13,13,13,13,13,13,13,13,13,13,13,13,13,26,0,0,0,0,0,0,0,0,0,0,0,0,0,0,0,0,0
0,0,0,0,0,0,0,0,0,47,27,13,13,13,13,13,13,13,13,13,13,13,13,13,26,47,0,0,0,0,0,0,0,0,0,0,0,0,0,0,0,0
0,0,0,0,0,0,0,0,0,0,27,13,13,13,13,13,13,13,13,13,13,13,13,13,26,0,0,0,0,0,0,0,0,0,0,0,0,0,0,0,0,0
0,0,0,0,0,0,0,0,0,0,27,13,13,13,13,13,13,13,13,13,13,13,13,13,26,0,0,0,0,0,0,0,0,0,0,0,0,0,0,0,0,0
0,0,0,0,0,0,0,0,0,0,27,13,13,13,13,13,13,13,13,13,13,13,13,13,26,0,0,0,0,0,0,0,0,0,0,0,0,0,0,0,0,0
0,11,21,21,21,11,0,0,0,47,27,13,13,13,13,13,13,13,13,13,13,13,13,13,26,47,5,0,0,0,0,0,0,0,0,0,0,0,0,0,0,0
0,21,13,13,13,21,6,0,25,0,27,13,13,13,13,13,13,13,13,13,13,13,13,13,26,0,1,0,0,0,0,0,0,0,0,0,0,0,0,0,0,0
0,21,13,13,13,21,11,49,11,49,11,13,13,13,13,13,13,13,13,13,13,13,13,13,2,7,2,10,10,0,0,0,0,0,0,0,0,0,0,0,0,0
0,21,13,13,13,13,13,13,13,13,13,13,13,13,13,13,13,13,13,13,13,13,13,13,7,7,7,2,2,2,2,2,2,2,1,0,0,0,0,0,0,0
0,11,21,21,13,13,13,13,13,13,13,13,13,13,13,13,13,13,13,13,13,13,13,13,13,13,13,2,2,2,7,7,7,2,2,2,0,0,0,0,0,0
0,0,12,21,13,13,13,13,13,13,13,13,13,13,13,51,50,50,50,50,50,2,7,13,13,13,13,13,7,7,13,13,13,7,7,2,1,0,0,0,0,0
0,0,0,27,13,13,13,13,13,13,13,13,13,13,13,26,0,0,0,47,0,7,7,13,13,13,13,13,7,13,13,13,13,13,7,2,2,0,0,0,0,0
0,0,29,21,13,13,13,13,13,13,13,13,13,13,13,21,28,0,0,0,1,2,7,13,13,13,13,13,13,13,13,13,13,13,13,7,2,0,0,0,0,0
0,0,0,27,13,13,13,13,13,13,13,13,13,13,13,26,0,0,0,0,0,10,2,7,13,13,13,7,13,13,13,13,13,13,13,7,2,0,0,0,0,0
0,0,29,21,13,13,13,13,13,13,13,13,13,13,13,21,28,0,0,0,0,10,2,2,7,7,2,7,13,13,13,13,13,13,13,7,2,0,0,0,0,0
0,0,0,27,13,13,13,13,13,13,13,13,13,13,13,26,0,0,0,0,0,0,10,10,2,7,2,2,7,13,13,13,13,13,7,2,2,0,0,0,0,0
0,0,29,21,13,13,13,13,13,13,13,13,13,13,13,21,28,0,0,0,0,0,0,0,1,0,1,2,7,7,13,13,13,7,7,2,1,0,0,0,0,0
0,0,0,27,13,13,13,13,13,13,13,13,13,13,13,26,0,0,0,0,0,0,0,0,0,0,0,2,2,2,7,7,7,2,2,2,0,0,0,0,0,0
0,0,29,21,13,13,13,13,13,13,13,13,13,13,13,21,28,0,0,0,0,0,0,0,0,0,0,0,1,2,2,2,2,2,1,0,0,0,0,0,0,0
0,0,0,27,13,13,13,13,13,13,13,13,13,13,13,26,0,0,0,0,0,0,0,0,0,0,0,0,0,0,0,0,0,0,0,0,0,0,0,0,0,0
0,0,29,21,13,13,13,13,13,13,13,13,13,13,13,21,28,0,0,0,0,0,0,0,0,0,0,0,0,0,0,0,0,0,0,0,0,0,0,0,0,0
0,0,0,27,13,13,13,13,13,13,13,13,13,13,13,26,0,0,0,0,0,0,0,0,0,0,0,0,0,0,0,0,0,0,0,0,0,0,0,0,0,0
0,0,8,21,13,13,13,13,13,13,13,13,13,13,13,21,6,0,0,0,0,0,0,0,0,0,0,0,0,0,0,0,0,0,0,0,0,0,0,0,0,0
0,0,32,11,11,50,11,50,11,50,11,50,11,50,11,11,31,0,0,0,0,0,0,0,0,0,0,0,0,0,0,0,0,0,0,0,0,0,0,0,0,0
0,0,0,32,34,0,33,0,33,0,33,0,33,0,12,31,0,0,0,0,0,0,0,0,0,0,0,0,0,0,0,0,0,0,0,0,0,0,0,0,0,0
0,5,0,5,0,0,0,0,0,0,0,0,0,5,0,0,0,0,0,0,0,0,0,0,0,0,0,0,0,0,0,0,0,0,0,0,0,0,0,0,0,0
0,0,0,0,0,0,0,0,0,0,0,0,0,0,0,0,0,0,0,0,0,0,0,0,0,0,0,0,0,0,0,0,0,0,0,0,0,0,0,0,0,0
0,0,0,0,0,0,0,0,0,0,0,0,0,0,0,0,0,0,0,0,0,0,0,0,0,0,0,0,0,0,0,0,0,0,0,0,0,0,0,0,0,0
endlayer

layer
0,0,0,0,0,0,0,0,0,0,0,0,0,0,0,0,0,0,0,0,0,0,0,0,0,0,0,0,0,0,0,0,0,0,0,0,0,0,0,0,0,0
0,0,0,0,0,0,0,0,0,0,0,0,0,0,0,0,0,0,0,0,0,0,0,0,0,0,0,0,0,0,0,0,0,0,0,0,0,0,0,0,0,0
0,0,0,0,0,0,0,0,0,0,0,0,0,0,0,0,0,0,0,0,0,0,0,0,0,0,0,0,0,0,0,0,0,0,0,0,0,0,0,0,0,0
0,0,0,0,0,0,0,0,0,0,19,0,0,0,0,0,0,0,0,0,0,0,0,0,19,0,0,0,0,0,0,0,0,0,0,0,0,0,0,0,0,0
0,0,0,0,0,0,0,0,0,22,11,21,21,21,21,21,21,21,21,21,21,21,21,21,11,20,0,0,0,0,0,0,0,0,0,0,0,0,0,0,0,0
0,0,0,0,0,0,0,0,0,0,21,0,0,0,0,0,0,0,0,0,0,0,0,0,21,0,0,0,0,0,0,0,0,0,0,0,0,0,0,0,0,0
0,0,0,0,0,0,0,0,0,0,21,0,0,0,0,0,0,0,0,0,0,0,0,0,21,0,0,0,0,0,0,0,0,0,0,0,0,0,0,0,0,0
0,0,0,0,0,0,0,0,0,0,21,0,0,0,0,0,0,0,0,0,0,0,0,0,21,0,0,0,0,0,0,0,0,0,0,0,0,0,0,0,0,0
0,0,0,0,0,0,0,0,0,0,21,0,0,0,0,0,0,0,0,0,0,0,0,0,21,0,0,0,0,0,0,0,0,0,0,0,0,0,0,0,0,0
0,0,0,0,0,0,0,0,0,0,21,0,0,0,5,0,0,0,0,0,0,0,0,0,21,0,0,0,0,0,0,0,0,0,0,0,0,0,0,0,0,0
0,0,0,0,0,0,0,0,0,0,21,0,0,0,0,0,0,0,0,0,0,0,0,0,21,0,0,0,0,0,0,0,0,0,0,0,0,0,0,0,0,0
0,0,0,0,0,0,0,0,0,0,21,0,0,0,0,0,0,0,0,0,0,0,0,0,21,0,0,0,0,0,0,0,0,0,0,0,0,0,0,0,0,0
0,0,0,0,0,0,0,0,0,0,21,0,0,0,0,0,0,0,0,21,0,0,0,0,21,0,0,0,0,0,0,0,0,0,0,0,0,0,0,0,0,0
0,11,21,21,21,11,0,0,0,0,21,0,0,0,0,0,0,0,21,24,21,0,0,0,21,0,0,0,0,0,0,0,0,0,0,0,0,0,0,0,0,0
0,21,0,0,0,21,6,0,25,0,21,0,0,0,0,0,0,0,0,21,0,0,0,0,21,7,15,0,0,0,0,0,0,0,0,0,0,0,0,0,0,0
0,21,0,0,0,21,11,21,11,21,11,0,0,0,0,0,0,0,0,0,0,0,0,0,21,21,21,15,15,0,0,0,0,0,0,0,0,0,0,0,0,0
0,21,0,0,0,0,0,0,0,0,0,0,0,21,0,0,0,0,0,0,0,0,0,0,0,0,52,21,11,15,21,21,21,0,15,0,0,0,0,0,0,0
0,11,7,21,0,0,0,0,0,0,0,0,21,24,21,0,0,0,0,0,0,0,0,0,0,0,0,0,21,21,21,0,21,21,21,7,0,0,0,0,0,0
0,0,15,21,23,0,0,0,0,0,0,0,0,21,0,21,21,21,21,21,21,21,0,0,0,0,0,0,0,0,0,0,0,0,0,21,15,0,0,0,0,0
0,0,7,27,0,0,0,0,0,0,0,0,0,0,0,26,7,0,0,0,7,21,0,0,0,0,0,0,0,0,0,0,21,0,0,21,0,0,0,0,0,0
0,0,15,21,0,0,0,0,0,0,0,0,0,0,0,21,15,0,0,0,15,21,0,0,0,0,0,0,0,0,0,21,24,21,0,21,21,0,0,0,0,0
0,0,7,27,0,0,0,0,21,0,0,0,0,0,0,26,7,0,0,0,0,15,21,0,0,0,0,0,0,0,0,0,21,0,0,0,21,0,0,0,0,0
0,0,15,21,0,0,0,21,24,21,0,0,0,0,0,21,15,0,0,0,0,15,11,21,0,5,0,21,0,0,0,0,0,0,0,21,21,0,0,0,0,0
0,0,7,27,0,0,0,0,21,0,0,0,0,0,0,26,7,0,0,0,0,0,15,15,21,21,21,21,0,0,0,0,0,0,0,21,0,0,0,0,0,0
0,0,15,21,0,0,0,0,0,0,0,0,0,0,0,21,15,0,0,0,0,5,0,0,15,7,15,21,0,0,0,0,0,30,0,21,15,0,0,0,0,0
0,0,7,27,0,0,0,0,0,0,0,0,0,0,0,26,7,0,0,0,0,0,0,0,0,0,0,7,21,21,21,0,21,21,21,7,0,0,0,0,0,0
0,0,15,21,0,0,0,0,0,0,0,0,0,0,0,21,15,0,0,0,0,0,0,0,0,0,0,0,15,0,21,21,21,0,15,0,0,0,0,0,0,0
0,0,7,27,0,0,0,0,0,0,0,0,0,0,0,26,7,0,0,0,0,0,0,0,0,0,0,0,0,0,0,0,0,0,0,0,0,0,0,0,0,0
0,0,15,21,0,0,0,0,0,0,0,0,0,0,0,21,15,0,0,0,0,0,0,0,0,0,0,0,0,0,0,0,0,0,0,0,0,0,0,0,0,0
0,0,7,27,0,0,5,0,0,0,0,0,0,0,0,26,7,0,0,0,0,0,0,0,0,0,0,0,0,0,0,0,0,0,0,0,0,0,0,0,0,0
0,0,15,21,0,0,0,0,0,0,0,0,0,5,0,21,15,0,0,0,0,0,0,0,0,0,0,0,0,0,0,0,0,0,0,0,0,0,0,0,0,0
0,0,22,11,11,21,11,21,11,21,11,21,11,21,11,11,20,0,0,0,0,0,0,0,0,0,0,0,0,0,0,0,0,0,0,0,0,0,0,0,0,0
0,0,0,32,34,0,33,0,33,0,33,0,33,0,12,31,0,0,0,0,0,0,0,0,0,0,0,0,0,0,0,0,0,0,0,0,0,0,0,0,0,0
0,0,0,0,0,0,0,0,0,0,0,0,0,0,0,0,0,0,0,0,0,0,0,0,0,0,0,0,0,0,0,0,0,0,0,0,0,0,0,0,0,0
0,0,0,0,0,0,0,0,0,0,0,0,0,0,0,0,0,0,0,0,0,0,0,0,0,0,0,0,0,0,0,0,0,0,0,0,0,0,0,0,0,0
0,0,0,0,0,0,0,0,0,0,0,0,0,0,0,0,0,0,0,0,0,0,0,0,0,0,0,0,0,0,0,0,0,0,0,0,0,0,0,0,0,0
endlayer

layer
0,0,0,0,0,0,0,0,0,0,0,0,0,0,0,0,0,0,0,0,0,0,0,0,0,0,0,0,0,0,0,0,0,0,0,0,0,0,0,0,0,0
0,0,0,0,0,0,0,0,0,0,0,0,0,0,0,0,0,0,0,0,0,0,0,0,0,0,0,0,0,0,0,0,0,0,0,0,0,0,0,0,0,0
0,0,0,0,0,0,0,0,0,0,0,0,0,0,0,0,0,0,0,0,0,0,0,0,0,0,0,0,0,0,0,0,0,0,0,0,0,0,0,0,0,0
0,0,0,0,0,0,0,0,0,0,19,10,19,0,19,10,19,0,19,10,19,0,19,10,19,0,0,0,0,0,0,0,0,0,0,0,0,0,0,0,0,0
0,0,0,0,0,0,0,0,0,22,11,21,21,35,21,21,21,35,21,21,21,35,21,21,11,20,0,0,0,0,0,0,0,0,0,0,0,0,0,0,0,0
0,0,0,0,0,0,0,0,0,10,21,0,0,0,0,0,0,0,0,0,0,0,0,0,21,10,5,0,0,0,0,0,0,0,0,0,0,0,0,0,0,0
0,0,0,0,0,0,0,0,0,22,21,0,0,0,0,0,0,0,0,0,0,0,0,0,21,20,0,0,0,0,0,0,0,0,0,0,0,0,0,0,0,0
0,0,0,0,0,0,0,0,0,0,36,0,0,0,0,0,0,0,0,0,0,0,0,0,36,0,0,0,0,0,0,0,0,0,0,0,0,0,0,0,0,0
0,0,0,0,0,0,0,0,0,22,21,0,0,0,0,0,0,0,0,0,0,0,0,0,21,20,0,0,0,0,0,0,0,0,0,0,0,0,0,0,0,0
0,0,0,0,0,0,0,0,0,10,21,0,0,0,0,0,0,0,0,0,0,0,0,0,21,10,0,0,0,0,0,0,0,0,0,0,0,0,0,0,0,0
0,0,0,0,0,0,0,0,0,22,21,0,0,0,0,0,0,0,0,0,0,0,0,0,21,20,0,0,0,0,0,0,0,0,0,0,0,0,0,0,0,0
0,0,0,0,0,0,0,0,0,0,36,0,0,0,0,0,0,0,0,0,0,0,0,0,36,0,0,0,0,0,0,0,0,0,0,0,0,0,0,0,0,0
0,0,0,0,0,0,0,0,0,22,21,0,0,0,0,0,0,0,0,21,0,0,0,0,21,20,0,0,0,0,0,0,0,0,0,0,0,0,0,0,0,0
0,10,21,35,21,10,0,0,0,10,21,0,0,0,0,0,0,0,21,21,21,0,0,0,21,10,0,0,0,0,0,0,0,0,0,0,0,0,0,0,0,0
0,21,0,0,0,21,10,0,10,22,21,0,0,0,0,0,0,0,0,21,0,0,0,0,21,20,0,0,0,0,0,0,0,0,0,0,0,0,0,0,0,0
0,36,5,0,0,40,11,35,11,35,11,0,0,0,0,0,0,0,0,0,0,0,0,0,27,53,27,10,5,0,0,0,0,0,0,0,0,0,0,0,0,0
0,21,0,0,0,0,0,0,0,0,0,0,0,21,0,0,0,0,0,0,0,0,0,0,0,0,0,21,6,0,21,35,21,0,0,0,0,0,0,0,0,0
0,10,21,42,0,0,0,0,0,0,0,0,21,21,21,0,0,0,0,0,0,0,0,0,0,0,0,0,21,35,21,0,21,35,21,10,0,0,0,0,0,0
0,0,10,21,0,0,0,0,0,0,0,0,0,21,0,21,21,35,21,21,21,27,0,0,0,0,0,0,0,0,0,0,0,0,0,21,0,0,0,0,0,0
0,0,0,36,0,0,0,0,0,0,0,0,0,0,0,36,44,0,44,10,44,54,0,0,0,0,0,0,0,0,0,0,21,0,0,36,0,0,0,0,0,0
0,0,10,21,0,0,0,0,0,0,0,0,0,0,0,21,10,0,0,0,0,27,0,0,0,0,0,0,0,0,0,21,21,21,0,21,21,0,0,0,0,0
0,0,0,36,0,0,0,0,21,0,0,0,0,0,0,36,0,0,0,0,0,10,21,0,0,0,5,0,0,0,0,0,21,0,0,0,36,0,0,0,0,0
0,0,10,21,0,0,0,21,21,21,0,0,0,0,0,21,10,0,0,0,0,0,12,21,0,0,0,21,0,0,0,0,0,0,0,21,21,0,0,0,0,0
0,0,0,36,0,0,0,0,21,0,0,0,0,0,0,36,0,0,5,0,0,0,0,10,27,53,27,55,0,0,0,0,0,0,0,36,0,0,0,0,0,0
0,0,10,21,0,0,0,0,0,0,0,0,0,0,0,21,10,0,0,0,0,0,0,0,0,0,0,21,0,0,0,0,0,0,0,21,0,0,0,0,0,0
0,0,0,36,0,0,0,0,0,0,0,0,0,0,0,36,0,0,0,0,0,0,0,0,0,0,0,10,21,35,21,0,21,35,21,10,0,0,0,0,0,0
0,0,10,21,0,0,0,0,0,0,0,0,5,0,5,21,10,0,0,0,0,0,0,0,0,0,0,0,0,0,21,35,21,0,0,0,0,0,0,0,0,0
0,0,0,36,0,0,0,0,0,0,0,0,0,0,0,36,0,0,0,0,0,0,0,0,0,0,0,0,0,0,0,0,0,0,0,0,0,0,0,0,0,0
0,0,10,21,0,0,0,0,0,0,0,0,0,0,0,21,10,0,0,0,0,0,0,0,0,0,0,0,0,0,0,0,0,0,0,0,0,0,0,0,0,0
0,0,0,36,0,0,0,0,0,0,0,0,0,0,0,36,0,0,0,0,0,0,0,0,0,0,0,0,0,0,0,0,0,0,0,0,0,0,0,0,0,0
0,0,10,21,0,0,0,0,0,0,0,0,0,0,0,21,10,0,0,0,0,0,0,0,0,0,0,0,0,0,0,0,0,0,0,0,0,0,0,0,0,0
0,0,22,11,11,35,11,35,11,35,11,35,11,35,11,11,20,0,0,0,0,0,0,0,0,0,0,0,0,0,0,0,0,0,0,0,0,0,0,0,0,0
0,0,0,44,10,0,10,0,10,0,10,0,10,0,10,44,0,0,0,0,0,0,0,0,0,0,0,0,0,0,0,0,0,0,0,0,0,0,0,0,0,0
0,0,0,0,0,0,0,0,0,0,0,0,0,0,0,0,0,0,0,0,0,0,0,0,0,0,0,0,0,0,0,0,0,0,0,0,0,0,0,0,0,0
0,0,0,0,0,0,0,0,0,0,0,0,0,0,0,0,0,0,0,0,0,0,0,0,0,0,0,0,0,0,0,0,0,0,0,0,0,0,0,0,0,0
0,0,0,0,0,0,0,0,0,0,0,0,0,0,0,0,0,0,0,0,0,0,0,0,0,0,0,0,0,0,0,0,0,0,0,0,0,0,0,0,0,0
endlayer

layer
0,0,0,0,0,0,0,0,0,0,0,0,0,0,0,0,0,0,0,0,0,0,0,0,0,0,0,0,0,0,0,0,0,0,0,0,0,0,0,0,0,0
0,0,0,0,0,0,0,0,0,0,0,0,0,0,0,0,0,0,0,0,0,0,0,0,0,0,0,0,0,0,0,0,0,0,0,0,0,0,0,0,0,0
0,0,0,0,0,0,0,0,0,0,0,0,0,0,0,0,0,0,0,0,0,0,0,0,0,0,0,0,0,0,0,0,0,0,0,0,0,0,0,0,0,0
0,0,0,0,0,0,0,0,0,0,19,10,19,0,19,10,19,0,19,10,19,0,19,10,19,0,0,0,0,0,0,0,0,0,0,0,0,0,0,0,0,0
0,0,0,0,0,0,0,0,0,22,11,21,21,35,21,21,21,35,21,21,21,35,21,21,11,20,0,0,0,0,0,0,0,0,0,0,0,0,0,0,0,0
0,0,0,0,0,0,0,0,0,10,21,0,0,0,0,0,0,0,0,0,0,0,0,0,21,10,0,0,0,0,0,0,0,0,0,0,0,0,0,0,0,0
0,0,0,0,0,0,0,0,0,22,21,0,0,0,0,0,0,0,0,0,0,0,0,0,21,20,0,0,0,0,0,0,0,0,0,0,0,0,0,0,0,0
0,0,0,0,0,0,0,0,0,0,36,0,0,0,0,0,0,0,0,0,0,0,0,0,36,0,0,0,0,0,0,0,0,0,0,0,0,0,0,0,0,0
0,0,0,0,0,0,0,0,0,22,21,0,0,0,0,0,0,0,0,0,0,0,0,0,21,20,0,0,0,0,0,0,0,0,0,0,0,0,0,0,0,0
0,0,0,0,0,0,0,0,0,10,21,0,0,0,0,0,0,0,0,0,0,0,0,0,21,10,0,0,0,0,0,0,0,0,0,0,0,0,0,0,0,0
0,0,0,0,0,0,0,0,0,22,21,0,0,0,0,0,0,0,0,0,0,0,0,0,21,20,0,0,0,0,0,0,0,0,0,0,0,0,0,0,0,0
0,0,0,0,0,0,0,0,0,0,36,0,0,0,0,0,0,0,0,0,0,0,5,0,36,0,0,0,0,0,0,0,0,0,0,0,0,0,0,0,0,0
0,0,0,0,0,0,0,0,0,22,21,5,0,0,0,0,0,0,0,21,0,0,0,0,21,20,0,0,0,0,0,0,0,0,0,0,0,0,0,0,0,0
0,10,21,35,21,10,0,0,0,10,21,0,0,0,0,0,0,0,21,21,21,0,0,0,21,10,5,0,0,0,0,0,0,0,0,0,0,0,0,0,0,0
0,21,0,0,0,21,10,0,10,22,21,0,0,0,0,0,0,0,0,21,0,0,0,0,21,20,0,0,0,0,0,0,0,0,0,0,0,0,0,0,0,0
0,36,0,0,0,40,11,35,11,35,11,0,0,0,0,0,0,0,0,0,0,0,0,0,27,53,27,10,0,0,0,0,0,0,0,0,0,0,0,0,0,0
0,21,0,0,0,0,5,0,0,0,0,0,0,21,0,0,0,0,0,0,0,0,0,0,0,0,0,21,28,0,27,53,27,0,0,0,0,0,0,0,0,0
0,10,21,42,0,0,0,0,0,0,0,0,21,21,21,0,0,0,0,0,0,0,0,0,0,0,0,0,27,53,27,0,27,53,27,10,0,0,0,0,0,0
0,0,10,21,0,0,0,0,0,0,0,0,0,21,0,21,21,35,21,21,21,27,0,0,0,0,0,0,0,0,0,5,0,0,0,27,0,0,0,0,0,0
0,0,0,36,0,0,0,0,0,0,5,0,0,0,0,36,44,0,44,10,44,54,0,0,0,0,0,0,0,0,0,0,21,0,0,54,0,0,0,0,0,0
0,0,10,21,0,0,0,0,0,0,0,0,0,0,0,21,10,0,0,0,0,27,0,0,0,0,0,0,0,0,0,21,21,21,0,27,27,0,0,0,0,0
0,0,0,36,0,0,0,0,21,0,0,0,0,0,0,36,0,0,0,0,0,10,21,0,0,0,0,0,0,0,0,0,21,0,0,0,54,0,0,0,0,0
0,0,10,21,0,0,0,21,21,21,0,0,0,0,0,21,10,0,0,0,0,0,12,21,0,0,0,27,0,0,0,0,0,0,0,27,27,0,0,0,0,0
0,0,0,36,0,0,0,0,21,0,0,0,0,0,0,36,0,0,0,0,0,0,0,10,27,53,27,53,0,0,0,0,0,0,0,54,0,0,0,0,0,0
0,0,10,21,0,0,0,0,0,0,0,0,0,0,0,21,10,0,0,0,0,0,0,0,0,0,0,27,0,0,0,0,0,0,0,27,0,0,0,0,0,0
0,0,0,36,0,0,0,0,0,0,0,0,0,0,0,36,0,0,0,0,0,0,0,0,0,0,0,10,27,53,27,0,27,53,27,10,0,0,0,0,0,0
0,0,10,21,0,0,0,0,0,0,0,0,0,0,0,21,10,0,0,0,0,0,0,0,0,0,0,5,0,0,27,53,27,0,0,0,0,0,0,0,0,0
0,0,0,36,0,0,0,0,0,0,0,0,0,0,0,36,0,0,0,0,0,0,0,0,0,0,0,0,0,0,0,0,0,0,0,0,0,0,0,0,0,0
0,0,10,21,0,0,0,0,0,0,0,0,0,0,0,21,10,0,0,0,0,0,0,0,0,0,0,0,0,0,0,0,0,0,0,0,0,0,0,0,0,0
0,0,0,36,0,0,0,0,0,0,0,0,0,0,0,36,0,0,0,0,0,0,0,0,0,0,0,0,0,0,0,0,0,0,0,0,0,0,0,0,0,0
0,0,10,21,0,0,0,0,0,0,0,0,0,0,0,21,10,0,0,0,0,0,0,0,0,0,0,0,0,0,0,0,0,0,0,0,0,0,0,0,0,0
0,0,22,11,11,35,11,35,11,35,11,35,11,35,11,11,20,0,0,0,0,0,0,0,0,0,0,0,0,0,0,0,0,0,0,0,0,0,0,0,0,0
0,0,0,44,10,0,10,0,10,0,10,0,10,0,10,44,0,0,0,0,0,0,0,0,0,0,0,0,0,0,0,0,0,0,0,0,0,0,0,0,0,0
0,0,0,0,0,0,0,0,0,0,0,0,0,0,0,0,0,0,0,0,0,0,0,0,0,0,0,0,0,0,0,0,0,0,0,0,0,0,0,0,0,0
0,0,0,0,0,0,0,0,0,0,0,0,0,0,0,0,0,0,0,0,0,0,0,0,0,0,0,0,0,0,0,0,0,0,0,0,0,0,0,0,0,0
0,0,0,0,0,0,0,0,0,0,0,0,0,0,0,0,0,0,0,0,0,0,0,0,0,0,0,0,0,0,0,0,0,0,0,0,0,0,0,0,0,0
endlayer

layer
0,0,0,0,0,0,0,0,0,0,0,0,0,0,0,0,0,0,0,0,0,0,0,0,0,0,0,0,0,0,0,0,0,0,0,0,0,0,0,0,0,0
0,0,0,0,0,0,0,0,0,0,0,0,0,0,0,0,0,0,0,0,0,0,0,0,0,0,0,0,0,0,0,0,0,0,0,0,0,0,0,0,0,0
0,0,0,0,0,0,0,0,0,0,0,0,0,0,0,0,0,0,0,0,0,0,0,0,0,0,0,0,0,0,0,0,0,0,0,0,0,0,0,0,0,0
0,0,0,0,0,0,0,0,0,0,48,28,0,0,0,47,0,0,0,47,0,0,0,29,37,0,0,0,0,0,0,0,0,0,0,0,0,0,0,0,0,0
0,0,0,0,0,0,0,0,0,48,11,49,49,49,49,49,49,49,49,49,49,49,49,49,11,37,0,0,0,0,0,0,0,0,0,0,0,0,0,0,0,0
0,0,0,0,0,0,0,0,0,33,27,13,13,13,13,13,13,13,13,13,13,13,13,13,26,33,0,0,0,0,0,0,0,0,0,0,0,0,0,0,0,0
0,0,0,0,0,0,0,0,0,0,27,13,13,13,13,13,13,13,13,13,13,13,13,13,26,0,0,0,0,0,0,0,0,0,0,0,0,0,0,0,0,0
0,0,0,0,0,0,0,0,0,0,27,13,13,13,13,13,13,13,13,13,13,13,13,13,26,0,0,0,0,0,0,0,0,0,0,0,0,0,0,0,0,0
0,0,0,0,0,0,0,0,0,0,27,13,13,13,13,13,13,13,13,13,13,13,13,13,26,0,0,0,0,0,0,0,0,0,0,0,0,0,0,0,0,0
0,0,0,0,0,0,0,0,0,47,27,13,13,13,13,13,13,13,13,13,13,13,13,13,26,47,0,0,0,0,0,0,0,0,0,0,0,0,0,0,0,0
0,0,0,0,0,0,0,0,0,0,27,13,13,13,13,13,13,13,13,13,13,13,13,13,26,0,0,0,0,0,0,0,0,0,0,0,0,0,0,0,0,0
0,0,0,0,0,0,0,0,0,0,27,13,13,13,13,13,13,13,13,13,13,13,13,13,26,0,0,0,0,0,0,0,0,0,0,0,0,0,0,0,0,0
0,0,0,0,0,0,0,0,0,0,27,13,13,13,13,13,13,13,13,13,13,13,13,13,26,0,0,0,0,0,0,0,0,0,0,0,0,0,0,0,0,0
0,11,21,21,21,11,0,0,0,47,27,13,13,13,13,13,13,13,13,13,13,13,13,13,26,47,0,0,0,0,0,0,0,0,0,0,0,0,0,0,0,0
0,21,13,13,13,21,6,0,25,0,27,13,13,13,13,13,13,13,13,13,13,13,13,13,26,0,0,0,0,0,0,0,0,0,0,0,0,0,0,0,0,0
0,21,13,13,13,21,11,49,11,49,11,13,13,13,13,13,13,13,13,13,13,13,13,13,26,21,21,10,0,0,0,0,0,0,0,0,0,0,0,0,0,0
0,21,13,13,13,13,13,13,13,13,13,13,13,13,13,13,13,13,13,13,13,13,13,13,13,13,13,21,11,0,21,21,21,0,0,0,0,0,0,0,0,0
0,11,21,21,13,13,13,13,13,13,13,13,13,13,13,13,13,13,13,13,13,13,13,13,13,13,13,13,21,21,13,13,13,21,21,6,0,0,0,0,0,0
0,0,12,21,13,13,13,13,13,13,13,13,13,13,13,51,50,50,50,50,50,50,13,13,13,13,13,13,13,13,13,13,13,13,13,21,0,0,0,0,0,0
0,0,0,27,13,13,13,13,13,13,13,13,13,13,13,26,0,0,0,47,0,21,13,13,13,13,13,13,13,13,13,13,13,13,13,21,0,0,0,0,0,0
0,0,29,21,13,13,13,13,13,13,13,13,13,13,13,21,28,0,0,0,0,21,13,13,13,13,13,13,13,13,13,13,13,13,13,13,21,0,0,0,0,0
0,0,0,27,13,13,13,13,13,13,13,13,13,13,13,26,0,0,0,0,0,10,21,13,13,13,13,13,13,13,13,13,13,13,13,13,21,0,0,0,0,0
0,0,29,21,13,13,13,13,13,13,13,13,13,13,13,21,28,0,0,0,0,0,11,21,13,13,13,13,13,13,13,13,13,13,13,13,21,0,0,0,0,0
0,0,0,27,13,13,13,13,13,13,13,13,13,13,13,26,0,0,0,0,0,0,0,10,21,21,21,21,13,13,13,13,13,13,13,21,0,0,0,0,0,0
0,0,29,21,13,13,13,13,13,13,13,13,13,13,13,21,28,0,0,0,0,0,0,0,0,0,0,21,13,13,13,13,13,13,13,21,0,0,0,0,0,0
0,0,0,27,13,13,13,13,13,13,13,13,13,13,13,26,0,0,0,0,0,0,0,0,0,0,0,12,21,21,13,13,13,21,21,34,0,0,0,0,0,0
0,0,29,21,13,13,13,13,13,13,13,13,13,13,13,21,28,0,0,0,0,0,0,0,0,0,0,0,0,0,21,21,21,0,0,0,0,0,0,0,0,0
0,0,0,27,13,13,13,13,13,13,13,13,13,13,13,26,0,0,0,0,0,0,0,0,0,0,0,0,0,0,0,0,0,0,0,0,0,0,0,0,0,0
0,0,29,21,13,13,13,13,13,13,13,13,13,13,13,21,28,5,0,0,0,0,0,0,0,0,0,0,0,0,0,0,0,0,0,0,0,0,0,0,0,0
0,0,0,27,13,13,13,13,13,13,13,13,13,13,13,26,0,0,0,0,0,0,0,0,0,0,0,0,0,0,0,0,0,0,0,0,0,0,0,0,0,0
0,0,8,21,13,13,13,13,13,13,13,13,13,13,13,21,6,0,0,0,0,0,0,0,0,0,0,0,0,0,0,0,0,0,0,0,0,0,0,0,0,0
0,0,32,11,11,50,11,50,11,50,11,50,11,50,11,11,31,0,0,0,0,0,0,0,0,0,0,0,0,0,0,0,0,0,0,0,0,0,0,0,0,0
0,0,0,32,34,0,33,0,33,0,33,0,33,0,12,31,0,0,0,0,0,0,0,0,0,0,0,0,0,0,0,0,0,0,0,0,0,0,0,0,0,0
0,0,0,0,0,0,0,0,0,0,0,0,0,0,0,0,0,0,0,0,0,0,0,0,0,0,0,0,0,0,0,0,0,0,0,0,0,0,0,0,0,0
0,0,0,0,0,0,0,0,0,0,0,0,0,0,0,0,0,0,0,0,0,0,0,0,0,0,0,0,0,0,0,0,0,0,0,0,0,0,0,0,0,0
0,0,0,0,0,0,0,0,0,0,0,0,0,0,0,0,0,0,0,0,0,0,0,0,0,0,0,0,0,0,0,0,0,0,0,0,0,0,0,0,0,0
endlayer

layer
0,0,0,0,0,0,0,0,0,0,0,0,0,0,0,0,0,0,0,0,0,0,0,0,0,0,0,0,0,0,0,0,0,0,0,0,0,0,0,0,0,0
0,0,0,0,0,0,0,0,0,0,0,0,0,0,0,0,0,0,0,0,0,0,0,0,0,0,0,0,0,0,0,0,0,0,0,0,0,0,0,0,0,0
0,0,0,0,0,0,0,0,0,0,0,0,0,0,0,0,0,0,0,0,0,0,0,0,0,0,0,0,0,0,0,0,0,0,0,0,0,0,0,0,0,0
0,0,0,0,0,0,0,0,0,0,19,0,0,0,0,0,0,0,0,0,0,0,0,0,19,0,0,0,0,0,0,0,0,0,0,0,0,0,0,0,0,0
0,0,0,0,0,0,0,0,0,22,11,21,21,21,21,21,21,21,21,21,21,21,21,21,11,20,0,0,0,0,0,0,0,0,0,0,0,0,0,0,0,0
0,0,0,0,0,0,0,0,0,0,21,0,0,0,0,0,0,0,0,0,0,0,0,0,21,0,0,0,0,0,0,0,0,0,0,0,0,0,0,0,0,0
0,0,0,0,0,0,0,0,0,0,21,0,0,0,0,0,0,0,0,0,0,0,0,0,21,0,0,0,0,0,0,0,0,0,0,0,0,0,0,0,0,0
0,0,0,0,0,0,0,0,0,0,21,0,0,0,0,0,0,0,0,0,0,0,0,0,21,0,0,0,0,0,0,0,0,0,0,0,0,0,0,0,0,0
0,0,0,0,0,0,0,0,0,0,21,0,0,56,21,0,0,0,0,21,0,0,0,0,21,0,0,0,0,0,0,0,0,0,0,0,0,0,0,0,0,0
0,0,0,0,0,0,0,0,0,0,21,0,0,21,21,21,0,0,21,21,21,0,0,0,21,0,0,0,0,0,0,0,0,0,0,0,0,0,0,0,0,0
0,0,0,0,0,0,0,0,0,0,21,0,0,0,21,0,0,0,0,21,0,0,0,0,21,0,0,0,0,0,0,0,0,0,0,0,0,0,0,0,0,0
0,0,0,0,0,0,0,0,0,0,21,0,0,0,0,0,0,0,0,0,0,0,0,0,21,0,0,0,0,0,0,0,0,0,0,0,0,0,0,0,0,0
0,0,0,0,0,0,0,0,0,0,21,0,0,0,5,0,0,0,21,23,0,0,0,0,21,5,0,0,0,0,0,0,0,0,0,0,0,0,0,0,0,0
0,11,21,21,21,11,0,0,0,0,21,0,0,0,0,0,0,21,24,21,0,0,0,0,21,0,0,0,0,0,0,0,0,0,0,0,0,0,0,0,0,0
0,21,0,0,0,21,6,0,25,0,21,0,0,21,0,0,0,0,21,0,0,0,0,0,21,0,1,0,0,0,0,0,0,0,0,0,0,0,0,0,0,0
0,21,0,0,0,21,11,21,11,21,11,0,21,24,21,0,0,0,0,0,0,0,0,0,2,7,2,0,0,0,0,0,0,0,0,0,0,0,0,0,0,0
0,21,0,0,0,0,0,0,0,0,0,0,0,21,0,0,0,0,0,0,0,0,0,0,0,0,0,2,2,2,2,2,2,2,1,0,0,0,0,0,0,0
0,11,7,21,0,0,0,0,0,0,0,0,0,0,0,0,0,0,0,0,0,0,5,0,0,0,0,0,2,2,0,0,0,2,2,2,0,0,0,0,0,0
0,0,15,21,0,0,0,0,0,0,0,0,0,0,0,21,21,21,21,21,21,2,0,0,0,0,0,0,0,0,0,0,0,0,0,2,1,0,0,0,0,0
0,0,7,27,0,0,0,5,0,0,0,0,0,0,0,26,7,0,0,0,0,7,0,0,0,0,0,0,0,0,21,0,0,0,0,2,2,0,0,0,0,0
0,0,15,21,0,0,0,0,0,0,0,0,0,0,0,21,15,0,0,0,1,2,0,0,0,0,0,0,0,21,21,21,0,0,0,0,2,0,0,0,0,0
0,0,7,27,0,0,21,0,0,0,0,0,0,0,0,26,7,0,0,0,0,0,2,0,0,0,0,0,0,0,21,0,0,0,0,0,2,0,0,0,0,0
0,0,15,21,0,21,24,21,0,0,0,0,0,0,0,21,15,0,0,0,0,0,2,2,0,0,0,0,0,0,0,0,0,0,0,0,2,0,0,0,0,0
0,0,7,27,0,0,21,0,0,0,0,0,0,0,0,26,7,0,0,0,0,0,0,0,2,7,2,2,0,0,0,0,0,0,0,2,2,0,0,0,0,0
0,0,15,21,0,0,0,0,0,0,0,0,0,0,0,21,15,0,0,0,0,0,0,0,1,0,1,2,0,0,0,0,0,0,0,2,1,0,0,0,0,0
0,0,7,27,0,0,0,0,0,0,0,0,0,0,0,26,7,0,0,0,0,0,0,0,0,0,0,2,2,2,0,0,0,2,2,2,0,0,0,0,0,0
0,0,15,21,5,0,0,0,30,21,0,0,0,0,0,21,15,0,0,0,0,0,0,0,0,0,0,0,1,2,2,2,2,2,1,0,0,0,0,0,0,0
0,0,7,27,0,0,0,0,21,24,21,0,0,0,0,26,7,0,0,0,0,0,0,0,0,0,0,0,0,0,0,0,0,0,0,0,0,0,0,0,0,0
0,0,15,21,0,0,0,0,0,21,0,0,0,0,0,21,15,0,0,0,0,0,0,0,0,0,0,0,0,0,0,0,0,0,0,0,0,0,0,0,0,0
0,0,7,27,0,0,0,0,0,0,0,0,0,0,0,26,7,0,0,0,0,0,0,0,0,0,0,0,0,0,0,0,0,0,0,0,0,0,0,0,0,0
0,0,15,21,0,0,0,0,0,0,0,0,0,0,0,21,15,0,0,0,0,0,0,0,0,0,0,0,0,0,0,0,0,0,0,0,0,0,0,0,0,0
0,0,22,11,11,21,11,21,11,21,11,21,11,21,11,11,20,0,0,0,0,0,0,0,0,0,0,0,0,0,0,0,0,0,0,0,0,0,0,0,0,0
0,0,0,32,34,0,33,0,33,0,33,0,33,0,12,31,0,0,0,0,0,0,0,0,0,0,0,0,0,0,0,0,0,0,0,0,0,0,0,0,0,0
0,0,0,0,0,0,0,0,0,0,0,0,0,0,0,0,0,0,0,0,0,0,0,0,0,0,0,0,0,0,0,0,0,0,0,0,0,0,0,0,0,0
0,0,0,0,0,0,0,0,0,0,0,0,0,0,0,0,0,0,0,0,0,0,0,0,0,0,0,0,0,0,0,0,0,0,0,0,0,0,0,0,0,0
0,0,0,0,0,0,0,0,0,0,0,0,0,0,0,0,0,0,0,0,0,0,0,0,0,0,0,0,0,0,0,0,0,0,0,0,0,0,0,0,0,0
endlayer

layer
0,0,0,0,0,0,0,0,0,0,0,0,0,0,0,0,0,0,0,0,0,0,0,0,0,0,0,0,0,0,0,0,0,0,0,0,0,0,0,0,0,0
0,0,0,0,0,0,0,0,0,0,0,0,0,0,0,0,0,0,0,0,0,0,0,0,0,0,0,0,0,0,0,0,0,0,0,0,0,0,0,0,0,0
0,0,0,0,0,0,0,0,0,0,0,0,0,0,0,0,0,0,0,0,0,0,0,0,0,0,0,0,0,0,0,0,0,0,0,0,0,0,0,0,0,0
0,0,0,0,0,0,0,0,0,0,19,10,19,0,19,10,19,0,19,10,19,0,19,10,19,0,0,0,0,0,0,0,0,0,0,0,0,0,0,0,0,0
0,0,0,0,0,0,0,0,0,22,11,21,21,35,21,21,21,35,21,21,21,35,21,21,11,20,0,0,0,0,0,0,0,0,0,0,0,0,0,0,0,0
0,0,0,0,0,0,0,0,0,10,21,0,0,0,0,0,0,0,0,0,0,0,0,0,21,10,0,0,0,0,0,0,0,0,0,0,0,0,0,0,0,0
0,0,0,0,0,0,0,0,0,22,21,0,0,0,0,0,0,0,0,0,0,0,0,0,21,20,0,0,0,0,0,0,0,0,0,0,0,0,0,0,0,0
0,0,0,0,0,0,0,0,0,0,36,0,0,0,0,0,0,0,0,0,0,0,0,0,36,0,0,0,0,0,0,0,0,0,0,0,0,0,0,0,0,0
0,0,0,0,0,0,0,0,0,22,21,0,0,0,21,0,0,0,0,21,0,0,0,0,21,20,0,0,0,0,0,0,0,0,0,0,0,0,0,0,0,0
0,0,0,0,0,0,0,0,0,10,21,0,0,21,21,21,0,0,21,21,21,0,0,0,21,10,0,0,0,0,0,0,0,0,0,0,0,0,0,0,0,0
0,0,0,0,0,0,0,0,0,22,21,0,0,0,21,0,0,0,0,21,0,0,0,0,21,20,0,0,0,0,0,0,0,0,0,0,0,0,0,0,0,0
0,0,0,0,0,0,0,0,0,0,36,0,0,0,0,0,0,0,0,0,0,0,0,0,36,0,0,0,0,0,0,0,0,0,0,0,0,0,0,0,0,0
0,0,0,0,0,0,0,0,0,22,21,0,0,0,0,0,0,0,21,0,0,0,0,0,21,20,0,0,0,0,0,0,0,0,0,0,0,0,0,0,0,0
0,10,21,35,21,10,0,0,0,10,21,0,0,0,0,0,0,21,21,21,0,0,0,0,21,10,0,0,0,0,0,0,0,0,0,0,0,0,0,0,0,0
0,21,0,0,0,21,10,0,10,22,21,0,0,21,0,0,0,0,21,0,0,0,0,0,21,37,1,0,0,0,0,0,0,0,0,0,0,0,0,0,0,0
0,36,0,0,0,40,11,35,11,35,11,0,21,21,21,0,0,0,0,0,0,0,0,0,2,38,2,0,0,0,0,0,0,0,0,0,0,0,0,0,0,0
0,21,0,0,0,5,0,0,0,0,0,0,0,21,0,0,0,0,0,5,0,0,0,0,0,0,0,2,1,2,41,2,41,2,10,0,0,0,0,0,0,0
0,10,21,42,0,0,0,0,0,0,0,0,0,0,0,0,0,0,0,0,0,0,0,0,0,0,0,0,2,1,0,0,0,1,2,1,0,0,0,0,0,0
0,0,10,21,0,0,0,0,0,0,0,0,0,0,0,21,21,35,21,21,21,2,0,0,0,0,0,0,0,0,0,0,0,0,0,2,10,0,0,0,0,0
0,0,0,36,0,0,0,0,0,0,0,0,0,0,0,36,44,0,44,10,32,43,0,0,0,0,0,0,0,0,21,0,0,0,0,1,2,0,0,0,0,0
0,0,10,21,0,0,0,0,0,0,0,0,0,0,0,21,10,0,0,0,1,2,0,0,0,5,0,0,0,21,21,21,0,0,0,0,45,0,0,0,0,0
0,5,0,36,0,0,21,0,0,0,0,0,0,0,0,36,0,0,0,0,0,0,2,0,0,0,0,0,0,0,21,0,0,0,0,0,2,0,0,0,0,0
0,0,10,21,0,21,21,21,0,0,0,0,0,0,0,21,10,0,0,0,0,0,1,2,0,0,0,0,0,0,0,0,0,0,0,0,45,0,0,0,0,0
0,0,0,36,0,0,21,0,0,0,0,0,0,0,0,36,0,0,0,0,0,0,0,0,2,41,2,1,0,0,0,0,0,0,0,1,2,0,0,0,0,0
0,0,10,21,0,0,0,0,0,0,0,0,0,0,0,21,10,0,0,0,0,0,0,0,1,0,1,2,0,0,0,0,0,0,0,2,10,0,0,0,0,0
0,0,0,36,0,0,0,0,0,0,0,0,0,0,0,36,0,0,0,0,0,0,0,0,0,0,0,1,2,1,0,0,0,1,2,1,0,0,0,0,0,0
0,0,10,21,0,0,0,0,0,21,0,0,0,5,0,21,10,0,0,0,0,0,0,0,0,0,0,0,10,2,41,2,41,2,10,0,0,0,0,0,0,0
0,0,0,36,0,0,0,0,21,21,21,0,0,0,0,36,0,0,0,0,0,0,0,0,0,0,0,0,0,0,0,0,0,0,0,0,0,0,0,0,0,0
0,0,10,21,0,0,0,0,0,21,0,0,0,0,0,21,10,0,0,0,0,0,0,0,0,0,0,0,0,0,0,0,0,0,0,0,0,0,0,0,0,0
0,0,0,36,0,0,0,0,0,0,0,0,0,0,0,36,0,0,0,0,0,0,0,0,0,0,0,0,0,0,0,0,0,0,0,0,0,0,0,0,0,0
0,0,10,21,0,0,0,0,0,0,0,0,0,0,0,21,10,0,0,0,0,0,0,0,0,0,0,0,0,0,0,0,0,0,0,0,0,0,0,0,0,0
0,0,22,11,11,35,11,35,11,35,11,35,11,35,11,11,20,0,0,0,0,0,0,0,0,0,0,0,0,0,0,0,0,0,0,0,0,0,0,0,0,0
0,0,0,44,10,0,10,0,10,0,10,0,10,0,10,44,0,0,0,0,0,0,0,0,0,0,0,0,0,0,0,0,0,0,0,0,0,0,0,0,0,0
0,0,0,0,0,0,0,0,0,0,0,0,0,0,0,0,0,0,0,0,0,0,0,0,0,0,0,0,0,0,0,0,0,0,0,0,0,0,0,0,0,0
0,0,0,0,0,0,0,0,0,0,0,0,0,0,0,0,0,0,0,0,0,0,0,0,0,0,0,0,0,0,0,0,0,0,0,0,0,0,0,0,0,0
0,0,0,0,0,0,0,0,0,0,0,0,0,0,0,0,0,0,0,0,0,0,0,0,0,0,0,0,0,0,0,0,0,0,0,0,0,0,0,0,0,0
endlayer

layer
0,0,0,0,0,0,0,0,0,0,0,0,0,0,0,0,0,0,0,0,0,0,0,0,0,0,0,0,0,0,0,0,0,0,0,0,0,0,0,0,0,0
0,0,0,0,0,0,0,0,0,0,0,0,0,0,0,0,0,0,0,0,0,0,0,0,0,0,0,0,0,0,0,0,0,0,0,0,0,0,0,0,0,0
0,0,0,0,0,0,0,0,0,0,0,0,0,0,0,0,0,0,0,0,0,0,0,0,0,0,0,0,0,0,0,0,0,0,0,0,0,0,0,0,0,0
0,0,0,0,0,0,0,0,0,0,19,10,19,0,19,10,19,0,19,10,19,0,19,10,19,0,0,0,0,0,0,0,0,0,0,0,0,0,0,0,0,0
0,0,0,0,0,0,0,0,0,22,11,21,21,35,21,21,21,35,21,21,21,35,21,21,11,20,0,0,0,0,0,0,0,0,0,0,0,0,0,0,0,0
0,0,0,0,0,0,0,0,0,10,21,0,0,0,0,0,0,0,0,0,0,0,0,13,21,10,0,0,0,0,0,0,0,0,0,0,0,0,0,0,0,0
0,0,0,0,0,0,0,0,0,22,21,0,0,0,0,0,0,0,0,0,0,0,0,0,21,20,0,0,0,0,0,0,0,0,0,0,0,0,0,0,0,0
0,0,0,0,0,0,0,0,0,0,36,0,0,0,0,0,0,0,0,0,0,0,0,0,36,0,0,0,0,0,0,0,0,0,0,0,0,0,0,0,0,0
0,0,0,0,0,0,0,0,0,22,21,0,0,0,21,0,0,0,0,21,0,0,0,0,21,20,0,0,0,0,0,0,0,0,0,0,0,0,0,0,0,0
0,0,0,0,0,0,0,0,0,10,21,0,0,21,21,21,0,0,21,21,21,0,0,0,21,10,0,0,0,0,0,0,0,0,0,0,0,0,0,0,0,0
0,0,0,0,0,0,0,0,0,22,21,0,0,0,21,0,0,0,0,21,0,0,0,0,21,20,0,0,0,0,0,0,0,0,0,0,0,0,0,0,0,0
0,0,0,0,0,0,0,0,0,0,36,0,0,0,0,0,0,0,0,0,0,0,0,0,36,0,0,0,0,0,0,0,0,0,0,0,0,0,0,0,0,0
0,0,0,0,0,0,0,0,0,22,21,0,0,0,0,0,0,0,21,0,0,0,0,0,21,20,0,0,0,0,0,0,0,0,0,0,0,0,0,0,0,0
0,10,21,35,21,10,0,0,0,10,21,0,0,0,0,0,0,21,21,21,0,0,0,0,21,10,0,0,0,0,0,0,0,0,0,0,0,0,0,0,0,0
0,21,0,0,0,21,10,0,10,22,21,0,0,21,0,0,0,0,21,0,0,0,0,0,21,37,1,0,0,0,0,0,0,0,0,0,0,0,0,0,0,0
0,36,0,0,0,40,11,35,11,35,11,0,21,21,21,0,0,0,0,0,0,0,0,0,2,38,2,10,0,0,0,0,0,0,0,0,0,0,0,0,0,0
0,21,0,0,0,0,0,0,5,0,0,0,0,21,0,0,0,0,0,0,0,0,0,0,0,0,0,2,1,2,41,2,41,2,10,0,0,0,0,0,0,0
0,10,21,42,0,0,0,0,0,0,0,0,0,0,0,0,0,0,0,0,0,0,0,0,0,0,0,0,2,1,0,0,0,1,2,1,0,0,0,0,0,0
0,0,10,21,0,0,0,0,0,0,0,0,0,0,0,21,21,35,21,21,21,2,0,0,0,0,0,0,0,0,0,0,0,0,0,2,10,0,0,0,0,0
0,0,0,36,0,0,0,0,0,0,0,0,0,0,0,36,44,0,44,10,32,43,0,0,0,0,0,0,0,0,21,0,0,0,0,1,2,0,0,0,0,0
0,0,10,21,0,0,0,0,0,0,0,0,0,0,0,21,10,0,0,0,1,2,2,0,0,0,0,0,0,21,21,21,0,0,0,0,45,0,0,0,0,0
0,0,0,36,0,0,21,0,0,0,0,0,0,0,0,36,0,0,0,0,0,10,2,0,0,0,0,0,0,0,21,0,0,0,0,0,2,0,0,0,0,0
0,0,10,21,0,21,21,21,0,0,0,0,0,0,0,21,10,0,0,0,0,0,1,2,0,0,0,0,0,0,0,0,0,0,0,0,45,0,0,0,0,0
0,0,0,36,0,0,21,0,0,0,0,0,0,0,0,36,0,0,0,0,0,0,0,10,2,41,2,1,0,0,0,0,0,0,0,1,2,0,0,0,0,0
0,0,10,21,0,0,5,0,0,0,0,0,0,0,0,21,10,0,0,0,0,0,0,0,1,0,1,2,2,0,0,0,0,0,0,2,10,0,0,0,0,0
0,0,0,36,0,0,0,0,0,0,0,0,0,0,0,36,0,0,0,0,0,0,0,0,0,0,0,1,2,1,0,0,0,1,2,1,0,0,0,0,0,0
0,0,10,21,0,0,0,0,0,21,0,0,0,0,0,21,10,0,0,0,0,0,0,0,0,0,0,0,10,2,41,2,41,2,10,0,0,0,0,0,0,0
0,0,0,36,0,0,0,0,21,21,21,0,0,0,0,36,0,0,0,0,0,0,0,0,0,0,0,0,0,0,0,0,0,0,0,0,0,0,0,0,0,0
0,0,10,21,0,0,0,0,0,21,0,0,0,0,0,21,10,0,0,0,0,0,0,0,0,0,0,0,0,0,0,0,0,0,0,0,0,0,0,0,0,0
0,0,0,36,0,0,0,0,0,0,0,0,0,0,0,36,0,0,0,0,0,0,0,0,0,0,0,0,0,0,0,0,0,0,0,0,0,0,0,0,0,0
0,0,10,21,0,0,0,0,0,0,0,0,0,0,0,21,10,0,0,0,0,0,0,0,0,0,0,0,0,0,0,0,0,0,0,0,0,0,0,0,0,0
0,0,22,11,11,35,11,35,11,35,11,35,11,35,11,11,20,0,0,0,0,0,0,0,0,0,0,0,0,0,0,0,0,0,0,0,0,0,0,0,0,0
0,0,0,44,10,0,10,0,10,0,10,0,10,0,10,44,0,0,0,0,0,0,0,0,0,0,0,0,0,0,0,0,0,0,0,0,0,0,0,0,0,0
0,0,0,0,0,0,0,0,0,5,0,0,0,0,0,0,0,0,0,0,0,0,0,0,0,0,0,0,0,0,0,0,0,0,0,0,0,0,0,0,0,0
0,0,0,0,0,0,0,0,0,0,0,0,0,0,0,0,0,0,0,0,0,0,0,0,0,0,0,0,0,0,0,0,0,0,0,0,0,0,0,0,0,0
0,0,0,0,0,0,0,0,0,0,0,0,0,0,0,0,0,0,0,0,0,0,0,0,0,0,0,0,0,0,0,0,0,0,0,0,0,0,0,0,0,0
endlayer

layer
0,0,0,0,0,0,0,0,0,0,0,0,0,0,0,0,0,0,0,0,0,0,0,0,0,0,0,0,0,0,0,0,0,0,0,0,0,0,0,0,0,0
0,0,0,0,0,0,0,0,0,0,0,0,0,0,0,0,0,0,0,0,0,0,0,0,0,0,0,0,0,0,0,0,0,0,0,0,0,0,0,0,0,0
0,0,0,0,0,0,0,0,0,0,0,0,0,0,0,0,0,0,0,0,0,0,0,0,0,0,0,0,0,0,0,0,0,0,0,0,0,0,0,0,0,0
0,0,0,0,0,0,0,0,0,0,48,28,0,0,0,47,0,0,0,47,0,0,0,29,37,0,0,0,0,0,0,0,0,0,0,0,0,0,0,0,0,0
0,0,0,0,0,0,0,0,0,48,11,49,49,49,49,49,49,49,49,49,49,49,49,49,11,37,0,0,0,0,0,0,0,0,0,0,0,0,0,0,0,0
0,0,0,0,0,0,0,0,0,33,27,13,13,13,13,13,13,13,13,13,13,13,13,24,26,33,0,0,0,0,0,0,0,0,0,0,0,0,0,0,0,0
0,0,0,0,0,0,0,0,0,0,27,13,13,13,13,13,13,13,13,13,13,13,13,13,26,0,0,0,0,0,0,0,0,0,0,0,0,0,0,0,0,0
0,0,0,0,0,0,0,0,0,0,27,13,13,13,13,13,13,13,13,13,13,13,13,13,26,0,0,0,0,0,0,0,0,0,0,0,0,0,0,0,0,0
0,0,0,0,0,0,0,0,0,0,27,13,13,13,13,13,13,13,13,13,13,13,13,13,26,0,0,0,0,0,0,0,0,0,0,0,0,0,0,0,0,0
0,0,0,0,0,0,0,0,0,47,27,13,13,13,13,13,13,13,13,13,13,13,13,13,26,47,0,0,0,0,0,0,0,0,0,0,0,0,0,0,0,0
0,0,0,0,0,0,0,0,0,0,27,13,13,13,13,13,13,13,13,13,13,13,13,13,26,0,0,0,0,0,0,0,0,0,0,0,0,0,0,0,0,0
0,0,0,0,0,0,0,0,0,0,27,13,13,13,13,13,13,13,13,13,13,13,13,13,26,0,0,0,0,0,0,0,0,0,0,0,0,0,0,0,0,0
0,0,0,0,0,0,0,0,0,0,27,13,13,13,13,13,13,13,13,13,13,13,13,13,26,0,0,0,0,0,0,0,0,0,0,0,0,0,0,0,0,0
0,11,21,21,21,11,0,0,0,47,27,13,13,13,13,13,13,13,13,13,13,13,13,13,26,47,0,0,0,0,0,0,0,0,0,0,0,0,0,0,0,0
0,21,13,13,13,21,6,0,25,0,27,13,13,13,13,13,13,13,13,13,13,13,13,13,26,0,1,0,0,0,0,0,0,0,0,0,0,0,0,0,0,0
0,21,13,13,13,24,11,49,11,49,11,13,13,13,13,13,13,13,13,13,13,13,13,13,2,7,2,10,10,0,0,0,0,0,5,0,0,0,0,0,0,0
0,21,13,13,13,13,13,13,13,13,13,13,13,13,13,13,13,13,13,13,13,13,13,13,7,7,7,2,2,2,2,2,2,2,1,0,0,0,0,0,0,0
0,11,21,21,13,13,13,13,13,13,13,13,13,13,13,13,13,13,13,13,13,13,13,13,13,13,13,2,2,2,7,7,7,2,2,2,0,0,0,0,0,0
0,0,12,21,13,13,13,13,13,13,13,13,13,13,13,51,50,50,50,50,50,2,7,13,13,13,13,13,7,7,13,13,13,7,7,2,1,0,0,0,0,0
0,5,0,27,13,13,13,13,13,13,13,13,13,13,13,26,0,0,5,47,0,7,7,13,13,13,13,13,7,13,13,13,13,13,7,2,2,0,0,0,0,0
0,0,29,21,13,13,13,13,13,13,13,13,13,13,13,21,28,0,0,0,1,2,24,13,13,13,13,13,13,13,13,13,13,13,13,7,2,0,0,0,0,0
0,0,0,27,13,13,13,13,13,13,13,13,13,13,13,26,0,0,0,0,0,10,2,7,13,13,13,7,13,13,13,13,13,13,13,7,2,0,0,0,0,0
0,0,29,21,13,13,13,13,13,13,13,13,13,13,13,21,28,0,0,0,0,10,2,2,7,7,2,7,13,13,13,13,13,13,13,7,2,0,0,0,0,0
0,0,0,27,13,13,13,13,13,13,13,13,13,13,13,26,0,0,0,0,0,0,10,10,2,7,2,2,7,13,13,13,13,13,7,2,2,0,0,0,0,0
0,0,29,21,13,13,13,13,13,13,13,13,13,13,13,21,28,0,0,0,0,0,0,0,1,0,1,2,24,7,13,13,13,7,7,2,1,0,0,0,0,0
0,0,0,27,13,13,13,13,13,13,13,13,13,13,13,26,0,0,0,0,0,0,0,0,0,0,0,2,2,2,7,7,7,2,2,2,0,0,0,0,0,0
0,0,29,21,13,13,13,13,13,13,13,13,13,13,13,21,28,0,0,0,0,0,0,0,0,0,0,0,1,2,2,2,2,2,1,0,0,0,0,0,0,0
0,0,0,27,13,13,13,13,13,13,13,13,13,13,13,26,0,0,0,0,0,0,0,0,0,0,0,0,0,0,0,0,0,0,0,0,0,0,0,0,0,0
0,0,29,21,13,13,13,13,13,13,13,13,13,13,13,21,28,0,0,0,0,0,0,0,0,0,0,0,0,0,0,0,0,0,0,0,0,0,0,0,0,0
0,0,0,27,13,13,13,13,13,13,13,13,13,13,13,26,0,0,0,0,0,0,0,0,0,0,0,0,0,0,0,0,0,0,0,0,0,0,0,0,0,0
0,0,8,21,13,13,13,13,13,13,13,13,13,13,13,21,6,0,0,0,0,0,0,0,0,0,0,0,0,0,0,0,0,0,0,0,0,0,0,0,0,0
0,0,32,11,11,50,11,50,11,50,11,50,11,50,11,11,31,0,0,0,0,0,0,0,0,0,0,0,0,0,0,0,0,0,0,0,0,0,0,0,0,0
0,0,0,32,34,0,33,0,33,0,33,0,33,0,12,31,0,0,0,0,0,0,0,0,0,0,0,0,0,0,0,0,0,0,0,0,0,0,0,0,0,0
0,0,0,0,0,0,0,0,0,0,0,0,0,0,0,0,0,0,0,0,0,0,0,0,0,0,0,0,0,0,0,0,0,0,0,0,0,0,0,0,0,0
0,0,0,0,0,0,0,0,0,0,0,0,0,0,0,0,0,0,0,0,0,0,0,0,0,0,0,0,0,0,0,0,0,0,0,0,0,0,0,0,0,0
0,0,0,0,0,0,0,0,0,0,0,0,0,0,0,0,0,0,0,0,0,0,0,0,0,0,0,0,0,0,0,0,0,0,0,0,0,0,0,0,0,0
endlayer

layer
0,0,0,0,0,0,0,0,0,0,0,0,0,0,0,0,0,0,0,0,0,0,0,0,0,0,0,0,0,0,0,0,0,0,0,0,0,0,0,0,0,0
0,0,0,0,0,0,0,0,0,0,0,0,0,0,0,0,0,0,0,0,0,0,0,0,0,0,0,0,0,0,0,0,0,0,0,0,0,0,0,0,0,0
0,0,0,0,0,0,0,0,0,0,0,0,0,0,0,0,0,0,0,0,0,0,0,0,0,0,0,0,0,0,0,0,0,0,0,0,0,0,0,0,0,0
0,0,0,0,0,0,0,0,0,0,19,0,0,0,0,0,0,0,0,0,0,0,0,0,19,0,0,0,0,0,0,0,0,0,0,0,0,0,0,0,0,0
0,0,0,0,0,0,0,0,0,22,11,21,21,21,21,21,21,21,21,21,21,21,21,21,11,20,0,0,0,0,0,0,0,0,0,0,0,0,0,0,0,0
0,0,0,0,0,0,0,0,0,0,21,0,0,0,0,0,0,0,0,0,0,0,0,13,21,0,0,0,0,0,0,0,0,0,0,0,0,0,0,0,0,0
0,0,0,0,0,0,0,0,0,0,21,0,0,0,0,0,0,0,0,0,0,0,0,0,21,0,0,0,0,0,0,0,0,0,0,0,0,0,0,0,0,0
0,0,0,0,0,0,0,0,0,0,21,0,0,0,0,0,0,0,0,0,0,0,0,0,21,0,0,0,0,0,0,0,0,0,0,0,0,0,0,0,0,0
0,0,0,0,0,0,0,0,0,0,21,0,0,0,0,0,0,0,0,0,0,0,0,0,21,0,0,0,0,0,0,0,0,0,0,0,0,0,0,0,0,0
0,0,0,0,0,0,0,0,0,0,21,0,24,0,0,21,0,0,0,0,0,0,0,0,21,0,0,0,0,0,0,0,0,0,0,0,0,0,0,0,0,0
0,0,0,0,0,0,0,0,0,0,21,0,0,0,21,24,21,0,0,0,0,0,0,0,21,0,0,0,0,0,0,0,0,0,0,0,0,0,0,0,0,0
0,0,0,0,0,0,0,0,0,0,21,0,0,0,0,21,0,0,0,0,0,0,0,0,21,0,0,0,0,0,0,0,0,0,0,0,0,0,0,0,0,0
0,0,0,0,0,0,0,0,0,0,21,0,0,0,0,0,0,0,0,0,0,0,0,0,21,0,0,0,0,0,0,0,0,0,0,0,0,0,0,0,0,0
0,11,21,21,21,11,0,47,0,0,21,0,0,0,0,0,0,0,21,0,0,0,0,0,21,0,0,0,0,0,0,0,0,0,0,0,0,0,0,0,0,0
0,21,23,0,0,21,0,10,0,0,21,0,0,0,0,0,0,21,21,21,0,0,0,0,21,7,15,0,0,0,0,0,0,0,0,0,0,0,0,0,0,0
0,21,0,0,0,21,21,21,21,21,21,0,0,0,0,0,0,0,21,0,0,0,0,0,21,21,21,15,15,0,0,0,0,0,0,0,0,0,0,0,0,0
0,21,0,0,0,2,0,21,0,0,0,0,0,0,0,0,0,0,0,0,0,0,0,0,0,0,0,21,11,15,21,21,21,0,15,0,0,0,0,0,0,0
0,11,7,21,0,0,21,0,0,0,0,0,0,0,0,0,0,0,0,0,0,0,0,0,0,0,0,0,21,21,21,0,21,21,21,7,0,0,0,0,0,0
0,0,15,21,21,0,0,0,0,0,0,0,0,0,0,21,21,21,21,21,21,21,0,0,0,0,0,0,0,0,0,0,0,0,0,21,15,0,0,0,0,0
0,0,7,21,0,0,0,0,0,0,0,0,0,0,0,21,7,0,0,0,7,21,0,0,0,0,0,0,0,0,0,0,0,0,0,21,0,0,0,0,0,0
0,0,15,21,0,0,0,0,0,0,0,0,0,0,0,21,15,0,0,0,15,21,13,0,0,0,0,0,0,0,0,0,0,0,0,21,21,0,0,0,0,0
0,0,7,21,0,0,0,0,0,0,0,0,0,0,0,21,7,0,0,0,0,15,21,0,0,0,0,0,0,0,0,0,0,0,0,0,21,0,0,0,0,0
0,0,15,21,0,5,0,0,52,0,0,0,0,0,0,21,15,0,0,0,0,15,11,21,0,0,0,21,0,0,0,0,0,0,0,21,21,0,0,0,0,0
0,0,7,21,0,0,0,0,0,0,0,0,0,0,0,21,7,0,0,0,0,0,15,15,21,21,21,21,0,0,0,0,0,0,0,21,0,0,0,0,0,0
0,0,15,21,0,0,0,21,0,0,0,0,0,0,0,21,15,0,0,0,0,0,0,0,15,7,15,21,2,0,0,0,0,0,0,21,15,0,0,0,0,0
0,0,7,21,0,0,21,24,21,0,0,0,0,0,0,21,7,0,0,0,0,0,0,0,0,0,0,7,21,21,21,0,21,21,21,7,0,0,0,0,0,0
0,0,15,21,0,0,0,21,0,0,0,0,0,0,0,21,15,0,0,0,0,0,0,0,0,0,0,0,15,0,21,21,21,0,15,0,0,0,0,0,0,0
0,0,7,21,0,0,0,0,0,0,0,0,0,0,0,21,7,0,0,0,0,0,0,0,0,0,0,0,0,0,0,0,0,0,0,0,0,0,0,0,0,0
0,0,15,21,0,0,0,0,0,0,0,0,0,0,0,21,15,0,0,0,0,0,0,0,0,0,0,0,0,0,0,0,0,0,0,0,0,0,0,0,0,0
0,0,7,21,0,0,0,0,0,0,0,0,0,0,0,21,7,0,0,0,0,0,0,0,0,0,0,0,0,0,0,0,0,0,0,0,0,0,0,0,0,0
0,0,15,21,0,0,0,0,0,0,0,0,0,0,0,21,15,0,0,0,0,0,0,0,0,0,0,0,0,0,0,0,0,0,0,0,0,0,0,0,0,0
0,0,29,21,21,21,21,21,21,21,21,21,21,21,21,21,28,0,0,0,0,0,0,0,0,0,0,0,0,0,0,0,0,0,0,0,0,0,0,0,0,0
0,0,0,33,0,0,0,10,0,0,0,10,0,0,0,33,0,0,0,0,0,0,0,0,0,0,0,0,0,0,0,0,0,0,0,0,0,0,0,0,0,0
0,5,0,0,0,0,0,47,0,0,0,47,0,0,0,0,0,0,0,0,0,0,0,0,0,0,0,0,0,0,0,0,0,0,0,0,0,0,0,0,0,0
0,0,0,0,0,0,0,0,0,0,0,0,0,0,0,0,0,0,0,0,0,0,0,0,0,0,0,0,0,0,0,0,0,0,0,0,0,0,0,0,0,0
0,0,0,0,0,0,0,0,0,0,0,0,0,0,0,0,0,0,0,0,0,0,0,0,0,0,0,0,0,0,0,0,0,0,0,0,0,0,0,0,0,0
endlayer

layer
0,0,0,0,0,0,0,0,0,0,0,0,0,0,0,0,0,0,0,0,0,0,0,0,0,0,0,0,0,0,0,0,0,0,0,0,0,0,0,0,0,0
0,0,0,0,0,0,0,0,0,0,0,0,0,0,0,0,0,0,0,0,0,0,0,0,0,0,0,0,0,0,0,0,0,0,0,0,0,0,0,0,0,0
0,0,0,0,0,0,0,0,0,0,0,0,0,0,0,0,0,0,0,0,0,0,0,0,0,0,0,0,0,0,0,0,0,0,0,0,0,0,0,0,0,0
0,0,0,0,0,0,0,0,0,0,19,10,19,0,19,10,19,0,19,10,19,0,19,10,19,0,0,0,0,0,0,0,0,0,0,0,0,0,0,0,0,0
0,0,0,0,0,0,0,0,0,22,11,21,21,35,21,21,21,35,21,21,21,35,21,21,11,20,0,0,0,0,0,0,0,0,0,0,0,0,0,0,0,0
0,0,0,0,0,0,0,0,0,10,21,0,0,0,0,0,57,0,0,0,0,0,0,0,21,10,0,0,0,0,0,0,0,0,0,0,0,0,0,0,0,0
0,0,0,0,0,0,0,0,0,22,21,0,0,0,0,0,0,0,0,0,0,0,0,0,21,20,0,0,0,0,0,0,0,0,0,0,0,0,0,0,0,0
0,0,0,0,0,0,0,0,0,0,36,0,0,0,0,0,0,0,0,0,0,0,0,0,36,0,0,0,0,0,0,0,0,0,0,0,0,0,0,0,0,0
0,0,0,0,0,0,0,0,0,22,21,0,0,0,0,0,0,0,0,0,0,0,0,0,21,20,0,0,0,0,0,0,0,0,0,0,0,0,0,0,0,0
0,0,0,0,0,0,0,0,0,10,21,0,0,0,0,21,0,0,0,0,0,0,0,0,21,10,0,0,0,0,0,0,0,0,0,0,0,0,0,0,0,0
0,0,0,0,0,0,0,0,0,22,21,0,0,0,21,21,21,0,0,0,0,0,0,0,21,20,0,0,0,0,0,0,0,0,0,0,0,0,0,0,0,0
0,0,0,0,0,0,0,0,0,0,36,0,0,0,0,21,0,0,0,0,0,0,0,0,36,0,0,0,0,0,0,0,0,0,0,0,0,0,0,0,0,0
0,0,0,0,0,0,0,0,0,48,21,39,0,0,0,0,0,0,0,0,0,0,0,0,21,20,0,0,0,0,0,0,0,0,0,0,0,0,0,0,0,0
0,10,21,35,21,10,0,11,11,11,11,0,0,0,0,0,0,0,21,0,0,0,0,46,21,10,0,0,0,0,0,0,0,0,0,0,0,0,0,0,0,0
0,21,0,0,0,21,58,11,21,21,21,0,0,0,0,0,0,21,21,21,0,0,0,0,21,20,0,0,0,0,0,0,0,0,0,0,0,0,0,0,0,0
0,36,0,0,0,60,59,59,21,21,21,0,0,0,0,0,0,0,21,0,0,0,0,0,27,53,27,10,0,0,0,0,0,0,0,0,0,0,0,0,0,0
0,21,0,0,0,2,0,0,0,0,0,0,0,0,0,0,0,0,0,0,0,0,0,0,0,0,0,21,6,0,21,35,21,0,0,0,0,0,0,0,0,0
0,10,21,42,0,0,0,0,0,0,0,0,0,0,0,0,0,0,0,0,0,0,0,0,0,0,0,0,21,35,21,0,21,35,21,10,0,0,0,0,0,0
0,0,58,59,21,0,0,0,0,0,0,0,0,0,0,21,21,35,21,21,21,27,0,0,0,0,0,0,0,0,0,0,0,0,0,21,0,0,0,0,0,0
0,0,58,59,0,0,0,0,0,0,0,0,0,0,0,59,58,0,44,10,44,54,0,0,0,0,0,0,0,0,0,0,0,0,0,36,0,0,0,0,0,0
0,0,58,59,0,0,0,0,0,0,0,0,0,0,0,59,58,0,0,0,0,27,0,0,0,0,0,0,0,0,0,0,0,0,46,21,21,0,0,0,0,0
0,0,58,59,0,0,0,0,0,0,0,0,0,0,0,59,58,0,0,0,0,10,21,61,0,0,0,0,0,0,0,0,0,0,0,0,36,0,0,0,0,0
0,0,58,59,0,0,0,0,0,0,0,0,0,0,0,59,58,0,0,0,0,5,12,21,0,0,0,21,0,0,0,0,0,0,0,21,21,0,0,0,0,0
0,0,58,59,5,0,0,0,0,0,0,0,0,0,0,59,58,0,0,0,0,0,0,10,27,53,27,55,0,0,0,0,0,0,0,36,0,0,0,0,0,0
0,0,58,59,0,0,0,21,0,0,0,0,0,0,0,59,58,0,0,0,0,0,0,0,0,0,0,21,0,0,61,0,0,0,0,21,0,0,0,0,0,0
0,0,58,59,0,0,21,21,21,0,0,0,5,0,0,59,58,0,0,0,0,0,0,0,0,0,0,10,21,35,21,0,21,35,21,10,0,0,0,0,0,0
0,0,58,59,0,0,0,21,0,0,0,0,0,0,0,59,58,0,0,0,0,0,0,0,0,0,0,0,0,0,21,35,21,0,0,0,0,0,0,0,0,0
0,0,58,59,0,0,0,0,0,0,0,0,0,0,0,59,58,0,0,0,0,0,0,0,0,0,0,0,0,0,0,0,0,0,0,0,0,0,0,0,0,0
0,0,58,59,0,0,0,0,0,0,0,0,0,0,0,59,58,0,0,0,0,0,0,0,0,0,0,0,0,0,0,0,0,0,0,0,0,0,0,0,0,0
0,0,58,59,0,0,0,0,0,0,0,0,0,0,0,59,58,0,0,0,0,0,0,0,0,0,0,0,0,0,0,0,0,0,0,0,0,0,0,0,0,0
0,0,58,59,0,0,0,0,0,0,61,0,0,0,0,59,58,0,0,0,0,0,0,0,0,0,0,0,0,0,0,0,0,0,0,0,0,0,0,0,0,0
0,0,58,59,59,59,59,59,21,21,21,59,59,59,59,59,58,0,0,0,0,0,0,0,0,0,0,0,0,0,0,0,0,0,0,0,0,0,0,0,0,0
0,0,62,58,58,58,58,11,21,21,21,11,58,58,58,58,62,0,0,0,0,0,0,0,0,0,0,0,0,0,0,0,0,0,0,0,0,0,0,0,0,0
0,0,0,0,0,0,0,11,11,11,11,11,0,0,0,0,0,0,0,0,0,0,0,0,0,0,0,0,0,0,0,0,0,0,0,0,0,0,0,0,0,0
0,0,0,0,0,0,0,0,0,0,0,0,0,0,0,0,0,0,0,0,0,0,0,0,0,0,0,0,0,0,0,0,0,0,0,0,0,0,0,0,0,0
0,0,0,0,0,0,0,0,0,0,0,0,0,0,0,0,0,0,0,0,0,0,0,0,0,0,0,0,0,0,0,0,0,0,0,0,0,0,0,0,0,0
endlayer

layer
0,0,0,0,0,0,0,0,0,0,0,0,0,0,0,0,0,0,0,0,0,0,0,0,0,0,0,0,0,0,0,0,0,0,0,0,0,0,0,0,0,0
0,0,0,0,0,0,0,0,0,0,0,0,0,0,0,0,0,0,0,0,0,0,0,0,0,0,0,0,0,0,0,0,0,0,0,0,0,0,0,0,0,0
0,0,0,0,0,0,0,0,0,0,0,0,0,0,0,0,0,0,0,0,0,0,0,0,0,0,0,0,0,0,0,0,0,0,0,0,0,0,0,0,0,0
0,0,0,0,0,0,0,0,0,0,19,10,19,0,19,10,19,0,19,10,19,0,19,10,19,0,0,0,0,0,0,0,0,0,0,0,0,0,0,0,0,0
0,0,0,0,0,0,0,0,0,22,11,21,21,35,21,21,21,35,21,21,21,35,21,21,11,20,0,0,0,0,0,0,0,0,0,0,0,0,0,0,0,0
0,0,0,0,0,0,0,0,0,10,21,0,5,0,0,0,0,0,0,0,0,0,0,0,21,10,0,0,0,0,0,0,0,0,0,0,0,0,0,0,0,0
0,0,0,0,0,0,0,0,0,22,21,0,0,0,0,0,0,0,0,0,0,0,0,0,21,20,0,0,0,0,0,0,0,0,0,0,0,0,0,0,0,0
0,0,0,0,0,0,0,0,0,0,36,0,0,0,0,0,0,0,0,0,0,0,0,0,36,0,0,0,0,0,0,0,0,0,0,0,0,0,0,0,0,0
0,0,0,0,0,0,0,0,0,22,21,0,0,0,0,0,0,0,0,0,0,0,0,0,21,20,0,0,0,0,0,0,0,0,0,0,0,0,0,0,0,0
0,0,0,0,0,0,0,0,0,10,21,0,0,0,0,21,0,0,0,0,0,0,0,0,21,10,0,0,0,0,0,0,0,0,0,0,0,0,0,0,0,0
0,0,0,0,0,0,0,0,0,22,21,0,0,0,21,21,21,0,0,0,0,0,0,0,21,20,0,0,0,0,0,0,0,0,0,0,0,0,0,0,0,0
0,0,0,0,0,0,0,0,0,0,36,0,0,0,0,21,0,0,0,0,0,0,0,0,36,0,0,0,0,0,0,0,0,0,0,0,0,0,0,0,0,0
0,0,0,0,0,0,0,0,0,22,21,0,0,0,0,0,0,0,0,0,0,0,0,0,21,20,0,0,0,0,0,0,0,0,0,0,0,0,0,0,0,0
0,10,21,35,21,10,0,10,10,10,21,0,0,0,0,0,0,0,21,0,0,0,0,0,21,10,0,0,0,0,0,0,0,0,0,0,0,0,0,0,0,0
0,21,0,0,0,21,0,10,0,22,21,0,0,0,0,0,0,21,21,21,0,0,0,0,21,20,0,0,0,0,0,0,0,0,0,0,0,0,0,0,0,0
0,36,0,0,0,40,59,58,21,35,21,0,0,0,0,0,0,0,21,0,0,0,0,0,27,53,27,10,0,0,0,0,0,0,0,0,0,0,0,0,0,0
0,21,0,0,21,0,0,0,0,0,0,0,0,0,0,0,0,0,0,0,0,0,0,0,0,0,0,21,28,0,27,53,27,0,0,0,0,0,0,0,0,0
0,10,21,42,0,0,0,0,0,0,0,0,0,0,0,0,0,0,0,0,0,0,0,0,0,0,0,0,27,53,27,5,27,53,27,10,0,0,0,0,0,0
0,0,0,59,0,0,0,0,0,0,0,0,0,0,0,21,21,35,21,21,21,27,0,0,0,0,0,0,0,0,0,0,0,0,0,27,0,0,0,0,0,0
0,0,0,59,0,0,0,0,0,0,0,0,0,0,0,59,31,0,44,10,44,54,0,0,0,0,0,0,0,0,0,0,0,0,0,54,0,0,0,0,0,0
0,0,0,59,0,0,0,0,0,0,0,0,0,0,0,59,0,0,0,0,0,27,0,0,0,0,0,0,0,0,0,0,0,0,0,27,27,0,0,0,0,0
0,0,0,59,0,0,0,0,0,0,0,0,5,0,0,59,0,0,0,0,0,10,21,0,0,0,0,0,0,0,0,0,0,0,0,0,54,0,0,0,0,0
0,0,0,59,0,0,0,0,0,0,0,0,0,0,0,59,0,0,0,0,0,0,12,21,0,0,0,27,0,0,0,0,0,0,0,27,27,0,0,0,0,0
0,0,0,59,0,0,0,0,0,0,0,0,0,0,0,59,0,0,0,0,0,0,0,10,27,53,27,53,0,0,0,0,0,0,0,54,0,0,0,0,0,0
0,0,0,59,0,0,0,21,0,0,0,0,0,0,0,59,0,0,0,0,0,0,0,0,0,0,0,27,0,0,0,0,0,0,0,27,0,0,0,0,0,0
0,0,0,59,0,0,21,21,21,0,0,0,0,0,0,59,0,0,0,0,0,0,0,0,0,0,0,10,27,53,27,0,27,53,27,10,0,0,0,0,0,0
0,0,0,59,0,0,0,21,0,0,0,0,0,0,0,59,0,0,0,0,0,0,0,0,0,0,0,0,0,0,27,53,27,0,0,0,0,0,0,0,0,0
0,0,0,59,0,0,0,0,0,0,0,0,0,0,0,59,0,0,0,0,0,0,0,0,0,0,0,0,0,0,0,0,0,0,0,0,0,0,0,0,0,0
0,0,0,59,0,0,0,0,0,0,0,0,0,0,0,59,0,0,0,0,0,0,0,0,0,0,0,0,0,0,0,0,0,0,0,0,0,0,0,0,0,0
0,0,0,59,0,0,0,0,0,0,0,0,0,0,0,59,0,0,0,0,0,0,0,0,0,0,0,0,0,0,0,0,0,0,0,0,0,0,0,0,0,0
0,0,0,59,0,0,0,0,5,0,0,0,0,0,0,59,0,0,0,0,0,0,0,0,0,0,0,0,0,0,0,0,0,0,0,0,0,0,0,0,0,0
0,0,5,12,59,59,59,58,21,35,21,58,59,59,59,34,0,0,0,0,0,0,0,0,0,0,0,0,0,0,0,0,0,0,0,0,0,0,0,0,0,0
0,0,0,0,0,0,0,10,0,0,0,10,0,0,0,0,0,0,0,0,0,0,0,0,0,0,0,0,0,0,0,0,0,0,0,0,0,0,0,0,0,0
0,0,0,0,0,0,0,10,10,10,10,10,0,0,0,0,0,0,0,0,0,0,0,0,0,0,0,0,0,0,0,0,0,0,0,0,0,0,0,0,0,0
0,0,0,0,0,0,0,0,0,0,0,0,0,0,0,0,0,0,0,0,0,0,0,0,0,0,0,0,0,0,0,0,0,0,0,0,0,0,0,0,0,0
0,0,0,0,0,0,0,0,0,0,0,0,0,0,0,0,0,0,0,0,0,0,0,0,0,0,0,0,0,0,0,0,0,0,0,0,0,0,0,0,0,0
endlayer

layer
0,0,0,0,0,0,0,0,0,0,0,0,0,0,0,0,0,0,0,0,0,0,0,0,0,0,0,0,0,0,0,0,0,0,0,0,0,0,0,0,0,0
0,0,0,0,0,0,0,0,0,0,0,0,0,0,0,0,0,0,0,0,0,0,0,0,0,0,0,0,0,0,0,0,0,0,0,0,0,0,0,0,0,0
0,0,0,0,0,0,0,0,0,0,0,0,0,0,0,0,0,0,0,0,0,0,0,0,0,0,0,0,0,0,0,0,0,0,0,0,0,0,0,0,0,0
0,0,0,0,0,0,0,0,0,0,48,28,0,0,0,47,0,0,0,47,0,0,0,29,37,0,0,0,0,0,0,0,0,0,0,0,0,0,0,0,0,0
0,0,0,0,0,0,0,0,0,48,11,49,49,49,49,49,49,49,49,49,49,49,49,49,11,37,0,0,0,0,0,0,0,0,0,0,0,0,0,0,0,0
0,0,0,0,0,0,0,0,0,33,27,13,13,13,13,13,13,13,13,13,13,13,13,13,26,33,0,0,0,0,0,0,0,0,0,0,0,0,0,0,0,0
0,0,0,0,0,0,0,0,0,0,27,13,13,13,13,13,13,13,13,13,13,13,13,13,26,0,0,0,0,0,0,0,0,0,0,0,0,0,0,0,0,0
0,0,0,0,0,0,0,0,0,0,27,13,13,13,13,13,13,13,13,13,13,13,13,13,26,0,0,0,0,0,0,0,0,0,0,0,0,0,0,0,0,0
0,0,0,0,0,0,0,0,0,0,27,13,13,13,13,13,13,13,13,13,13,13,13,13,26,0,0,0,0,0,0,0,0,0,0,0,0,0,0,0,0,0
0,0,0,0,0,0,0,0,0,47,27,13,13,13,13,13,13,13,13,13,13,13,13,13,26,47,0,0,0,0,0,0,0,0,0,0,0,0,0,0,0,0
0,0,0,0,0,0,0,0,0,0,27,13,13,13,13,13,13,13,13,13,13,13,13,13,26,0,0,0,0,0,0,0,0,0,0,0,0,0,0,0,0,0
0,0,0,0,0,0,0,0,0,0,27,13,13,13,13,13,13,13,13,13,13,13,13,13,26,0,0,0,0,0,0,0,0,0,0,0,0,0,0,0,0,0
0,0,0,0,0,0,0,0,0,0,27,13,13,13,13,13,13,13,13,13,13,13,13,13,26,0,0,0,0,0,0,0,0,0,0,0,0,0,0,0,0,0
0,11,21,21,21,11,0,0,0,47,27,13,13,13,13,13,13,13,13,13,13,13,13,13,26,47,0,0,0,0,0,0,0,0,0,0,0,0,0,0,0,0
0,21,13,13,13,21,0,0,10,0,27,13,13,13,13,13,13,13,13,13,13,13,13,13,26,0,0,0,0,0,0,0,0,0,0,0,0,0,0,0,0,0
0,21,13,13,13,21,59,58,21,53,27,13,13,13,13,13,13,13,13,13,13,13,13,13,26,21,21,10,0,0,0,0,0,0,0,0,0,0,0,0,0,0
0,21,13,13,13,0,0,0,0,0,0,13,13,13,13,13,13,13,13,13,13,13,13,13,13,13,13,21,11,0,21,21,21,0,0,0,0,0,0,0,0,0
0,11,21,21,0,0,5,0,0,0,0,13,13,13,13,13,13,13,13,13,13,13,13,13,13,13,13,13,21,21,13,13,13,21,21,6,0,0,0,0,0,0
0,0,0,59,0,0,0,0,0,0,0,0,0,0,0,50,50,50,50,50,50,50,13,13,13,13,13,13,13,13,13,13,13,13,13,21,0,0,0,0,0,0
0,0,0,59,0,0,0,0,0,0,0,0,0,0,0,59,0,0,0,47,0,21,13,13,13,13,13,13,13,13,13,13,13,13,13,21,0,0,0,0,0,0
0,5,0,59,0,0,0,0,0,0,0,0,0,0,0,59,0,0,0,0,0,21,13,13,13,13,13,13,13,13,13,13,13,13,13,13,21,0,0,0,0,0
0,0,0,59,0,0,0,0,0,0,0,0,0,0,0,59,0,0,0,0,0,10,21,13,13,13,13,13,13,13,13,13,13,13,13,13,21,0,0,0,0,0
0,0,0,59,0,0,0,0,0,0,0,0,0,0,0,59,0,0,0,0,0,0,11,21,13,13,13,13,13,13,13,13,13,13,13,13,21,0,0,0,0,0
0,0,0,59,0,0,0,0,0,0,0,0,0,0,0,59,0,5,0,0,0,0,0,10,21,21,21,21,13,13,13,13,13,13,13,21,0,0,0,0,0,0
0,0,0,59,0,0,0,21,0,0,0,0,0,0,0,59,0,0,0,0,0,0,0,0,0,5,0,21,13,13,13,13,13,13,13,21,0,0,0,0,0,0
0,0,0,59,0,0,21,13,13,0,0,0,0,0,0,59,0,0,0,0,0,0,0,0,0,0,0,12,21,21,13,13,13,21,21,34,0,0,0,0,0,0
0,0,0,59,0,0,0,21,0,0,0,0,0,0,0,59,0,0,0,0,0,0,0,0,0,0,0,0,0,0,21,21,21,0,0,0,0,0,0,0,0,0
0,0,0,59,0,0,0,0,0,0,0,0,0,0,0,59,0,0,0,0,0,0,0,0,0,0,0,0,0,0,0,0,0,0,0,0,0,0,0,0,0,0
0,0,0,59,0,0,0,0,0,0,0,0,0,0,0,59,0,0,0,0,0,0,0,0,0,0,0,0,0,0,0,0,0,0,0,0,0,0,0,0,0,0
0,5,0,59,0,0,0,0,0,0,0,0,0,0,0,59,0,0,0,0,0,0,0,0,0,0,0,0,0,0,0,0,0,0,0,0,0,0,0,0,0,0
0,0,0,59,59,0,0,0,0,0,0,0,0,0,59,59,0,0,0,0,0,0,0,0,0,0,0,0,0,0,0,0,0,0,0,0,0,0,0,0,0,0
0,0,0,12,59,59,59,58,21,35,21,58,59,59,59,34,0,0,0,0,0,0,0,0,0,0,0,0,0,0,0,0,0,0,0,0,0,0,0,0,0,0
0,0,0,0,0,0,0,0,10,0,10,0,0,0,0,0,0,0,0,0,0,0,0,0,0,0,0,0,0,0,0,0,0,0,0,0,0,0,0,0,0,0
0,0,0,0,0,0,0,0,0,0,0,0,0,0,0,0,0,0,0,0,0,0,0,0,0,0,0,0,0,0,0,0,0,0,0,0,0,0,0,0,0,0
0,0,0,0,0,0,0,0,0,0,0,0,0,0,0,0,0,0,0,0,0,0,0,0,0,0,0,0,0,0,0,0,0,0,0,0,0,0,0,0,0,0
0,0,0,0,0,0,0,0,0,0,0,0,0,0,0,5,0,0,0,0,0,0,0,0,0,0,0,0,0,0,0,0,0,0,0,0,0,0,0,0,0,0
endlayer

layer
0,0,0,0,0,0,0,0,0,0,0,0,0,0,0,0,0,0,0,0,0,0,0,0,0,0,0,0,0,0,0,0,0,0,0,0,0,0,0,0,0,0
0,0,0,0,0,0,0,0,0,0,0,0,0,0,0,0,0,0,0,0,0,0,0,0,0,0,0,0,0,0,0,0,0,0,0,0,0,0,0,0,0,0
0,0,0,0,0,0,0,0,0,0,0,0,0,0,0,0,0,0,0,0,0,0,0,0,0,0,0,0,0,0,0,0,0,0,0,0,0,0,0,0,0,0
0,0,0,0,0,0,0,0,0,0,19,0,0,0,0,0,0,0,0,0,0,0,0,0,19,0,0,0,0,0,0,0,0,0,0,0,0,0,0,0,0,0
0,0,0,0,0,0,0,0,0,22,11,21,21,21,21,21,21,21,21,21,21,21,21,21,11,20,5,0,0,0,0,0,0,0,0,0,0,0,0,0,0,0
0,0,0,0,0,0,0,0,0,0,21,0,0,0,0,0,0,0,0,0,0,0,0,0,21,0,5,0,0,0,0,0,0,0,0,0,0,0,0,0,0,0
0,0,0,0,0,0,0,0,0,0,21,0,0,0,0,0,0,0,0,0,0,0,0,30,21,0,0,0,0,0,0,0,0,0,0,0,0,0,0,0,0,0
0,0,0,0,0,0,0,0,0,0,21,23,0,0,0,0,0,0,0,0,0,0,0,0,21,0,0,0,0,0,0,0,0,0,0,0,0,0,0,0,0,0
0,0,0,0,0,0,0,0,0,0,21,0,0,0,0,0,0,0,0,0,0,0,0,0,21,0,0,0,0,0,0,0,0,0,0,0,0,0,0,0,0,0
0,0,0,0,0,0,0,0,0,0,21,21,21,21,0,0,0,21,0,0,0,0,0,0,21,0,0,0,0,0,0,0,0,0,0,0,0,0,0,0,0,0
0,0,0,0,0,0,0,0,0,0,21,0,0,0,0,0,21,24,21,0,0,0,0,0,21,0,0,0,0,0,0,0,0,0,0,0,0,0,0,0,0,0
0,0,0,0,0,0,0,0,0,0,21,0,0,0,0,0,0,21,0,0,0,0,0,0,21,0,0,0,0,0,0,0,0,0,0,0,0,0,0,0,0,0
0,0,0,0,0,0,0,0,0,0,21,0,0,0,0,0,0,0,30,21,0,0,0,0,21,0,0,0,0,0,0,0,0,0,0,0,0,0,0,0,0,0
0,62,58,14,58,62,0,0,0,0,21,0,0,0,0,0,0,0,21,24,21,0,0,0,21,0,0,0,0,0,0,0,0,0,0,0,0,0,0,0,0,0
0,58,59,59,59,58,0,0,25,0,21,0,0,0,0,0,0,0,0,21,0,0,0,0,21,0,1,0,0,0,0,0,0,0,0,0,0,0,0,0,0,0
0,9,59,59,59,16,0,58,21,21,21,0,0,0,0,0,0,5,0,0,0,0,0,0,2,7,2,0,0,0,0,0,5,0,0,0,0,0,0,0,0,0
0,58,59,59,59,58,59,59,59,59,21,53,0,0,0,0,0,0,0,0,0,0,0,0,0,0,0,2,2,2,2,2,2,2,1,0,0,0,0,0,0,0
0,62,58,18,58,0,0,0,0,0,0,0,63,35,42,0,0,0,0,0,0,0,0,0,0,0,0,0,2,2,0,0,0,2,2,2,0,0,0,0,0,0
0,0,0,0,59,0,5,0,0,0,0,5,0,0,21,21,21,21,21,21,21,2,0,0,0,0,0,0,0,0,0,0,0,0,0,2,1,0,0,0,0,0
0,0,0,0,59,0,0,0,0,0,0,0,0,0,59,0,0,0,0,0,0,7,0,0,0,0,0,0,0,21,23,0,0,0,0,2,2,0,0,0,0,0
0,0,0,0,59,0,0,0,0,0,0,0,0,0,59,0,0,0,0,0,1,2,0,0,0,0,0,0,21,24,21,0,0,0,0,0,2,0,0,0,0,0
0,0,0,0,59,0,0,0,0,0,0,0,0,0,59,0,0,0,0,0,0,0,2,0,0,0,0,0,0,21,0,0,0,0,0,0,2,0,0,0,0,0
0,0,0,0,59,0,0,0,0,0,0,0,0,0,59,0,0,0,0,0,0,0,2,2,0,0,0,0,0,0,0,0,0,0,0,0,2,0,0,0,0,0
0,0,0,0,59,0,0,0,0,0,0,0,0,0,59,0,0,0,0,0,0,0,0,0,2,7,2,2,0,0,0,0,0,0,0,2,2,0,0,0,0,0
0,0,0,0,59,0,0,21,0,0,0,0,0,0,59,0,0,0,0,0,0,0,0,5,1,5,1,2,0,0,0,0,0,0,0,2,1,0,0,0,0,0
0,0,0,0,59,0,21,21,21,0,0,0,0,0,59,0,0,0,0,0,0,0,0,0,0,0,0,2,2,2,0,0,0,2,2,2,0,0,0,0,0,0
0,0,0,0,59,0,0,21,0,0,0,0,0,0,59,0,0,0,0,0,0,0,0,0,0,0,0,5,1,2,2,2,2,2,1,0,0,0,0,0,0,0
0,0,0,0,59,0,0,0,0,0,0,0,0,0,59,0,0,0,0,0,0,0,0,0,0,0,0,0,0,0,0,0,0,0,0,0,0,0,0,0,0,0
0,0,0,0,59,0,0,0,0,0,0,0,0,0,59,0,0,0,0,0,0,0,0,0,0,0,0,0,0,0,0,0,0,0,0,0,0,0,0,0,0,0
0,0,0,0,59,0,0,0,0,0,0,0,0,0,59,0,0,0,0,0,0,0,0,0,0,0,0,0,0,0,0,0,0,0,0,0,0,0,0,0,0,0
0,0,0,0,12,59,59,59,59,59,59,59,59,59,34,0,0,0,0,0,0,0,0,0,0,0,0,0,0,0,0,0,0,0,0,0,0,0,0,0,0,0
0,0,0,62,0,0,0,58,21,21,21,58,0,0,0,62,0,0,0,0,0,0,0,0,0,0,0,0,0,0,0,0,0,0,0,0,0,0,0,0,0,0
0,0,0,0,0,0,0,0,33,0,33,0,0,0,0,0,0,0,0,0,0,0,0,0,0,0,0,0,0,0,0,0,0,0,0,0,0,0,0,0,0,0
0,0,0,0,0,0,0,0,0,0,0,0,0,0,0,0,0,0,0,0,0,0,0,0,0,0,0,0,0,0,0,0,0,0,0,0,0,0,0,0,0,0
0,0,0,0,0,0,0,0,0,0,0,0,0,0,0,0,0,0,0,0,0,0,0,0,0,0,0,0,0,0,0,0,0,0,0,0,0,0,0,0,0,0
0,0,0,0,0,0,0,0,0,0,0,0,0,0,0,0,0,0,0,0,0,0,0,0,0,0,0,0,0,0,0,0,0,0,0,0,0,0,0,0,0,0
endlayer

layer
0,0,0,0,0,0,0,0,0,0,0,0,0,0,0,0,0,0,0,0,0,0,0,0,0,0,0,0,0,0,0,0,0,0,0,0,0,0,0,0,0,0
0,0,0,0,0,0,0,0,0,0,0,0,0,0,0,0,0,0,0,0,0,0,0,0,0,0,0,0,0,0,0,0,0,0,0,0,0,0,0,0,0,0
0,0,0,0,0,0,0,0,0,0,0,0,0,0,0,0,0,0,0,0,0,0,0,0,0,0,0,0,0,0,0,0,0,0,0,0,0,0,0,0,0,0
0,0,0,0,0,0,0,0,0,0,19,10,19,0,19,10,19,0,19,10,19,0,19,10,19,0,0,0,0,0,0,0,0,0,0,0,0,0,0,0,0,0
0,0,0,0,0,0,0,0,0,22,11,21,21,35,21,21,21,35,21,21,21,35,21,21,11,20,0,0,0,0,0,0,0,0,0,0,0,0,0,0,0,0
0,0,0,0,0,0,0,0,0,10,21,5,0,0,0,0,0,0,0,0,0,0,0,0,21,10,0,0,0,0,0,0,0,0,0,0,0,0,0,0,0,0
0,0,0,0,0,0,0,0,0,22,21,0,0,0,0,0,0,0,0,0,0,0,0,0,21,20,0,0,0,0,0,0,0,0,0,0,0,0,0,0,0,0
0,0,0,0,0,0,0,0,0,0,36,0,0,0,0,0,0,0,0,0,0,0,0,0,36,0,0,0,0,0,0,0,0,0,0,0,0,0,0,0,0,0
0,0,0,0,0,0,0,0,0,22,21,0,0,0,0,0,0,0,0,0,0,0,0,0,21,20,0,0,0,0,0,0,0,0,0,0,0,0,0,0,0,0
0,0,0,0,0,0,0,0,0,10,21,21,21,21,0,0,0,21,0,0,0,0,0,0,21,10,0,0,0,0,0,0,0,0,0,0,0,0,0,0,0,0
0,0,0,0,0,0,0,0,0,22,21,0,0,57,0,0,21,21,21,0,0,0,0,0,21,20,0,0,0,0,0,0,0,0,0,0,0,0,0,0,0,0
0,0,0,0,0,0,0,0,0,0,36,0,5,0,0,0,0,21,0,0,0,0,0,0,36,0,0,0,0,0,0,0,0,0,0,0,0,0,0,0,0,0
0,0,0,0,0,0,0,0,0,22,21,0,0,0,0,0,0,0,0,21,0,0,0,0,21,20,0,0,0,0,0,0,0,0,0,0,0,0,0,0,0,0
0,0,0,62,0,0,0,0,0,10,21,0,0,0,0,0,0,0,21,21,21,0,0,0,21,10,0,0,0,0,0,0,0,0,0,0,0,0,0,0,0,0
0,0,59,59,59,0,0,62,58,62,21,0,0,0,0,0,0,0,0,21,39,0,0,0,21,37,1,0,0,0,0,0,0,0,0,0,0,0,0,0,0,0
0,62,59,59,59,62,0,62,58,58,55,0,0,0,0,0,0,0,0,0,0,0,0,0,2,38,2,0,0,0,0,0,0,0,0,0,0,0,0,0,0,0
0,0,59,59,59,59,59,59,59,59,21,0,0,0,0,0,0,0,0,0,0,0,0,0,0,0,0,2,1,2,41,2,41,2,10,0,0,0,0,0,0,0
0,0,0,62,59,0,0,0,0,0,0,0,0,0,0,0,0,0,0,0,0,0,0,0,0,0,0,0,2,1,0,0,0,1,2,1,0,0,0,0,0,0
0,0,0,0,59,0,0,0,0,0,5,0,0,0,21,21,21,35,21,21,21,2,39,0,0,0,0,0,0,0,0,0,0,0,0,2,10,0,0,0,0,0
0,0,0,0,59,5,0,0,0,0,0,0,0,0,59,10,44,0,44,10,32,43,0,0,0,0,0,0,0,21,0,0,0,0,0,1,2,0,0,0,0,0
0,0,0,0,59,0,0,0,0,0,0,0,0,0,59,0,0,0,0,0,1,2,0,0,0,0,0,0,21,21,21,0,0,0,0,0,45,0,0,0,0,0
0,0,0,0,59,0,0,0,0,0,0,0,0,0,59,0,0,0,0,0,0,0,2,0,0,0,0,0,0,21,0,0,0,0,0,46,2,0,0,0,0,0
0,0,0,0,59,0,0,0,0,0,0,0,0,0,59,0,0,0,0,0,0,0,1,2,0,0,0,0,0,0,0,0,0,0,0,0,45,0,0,0,0,0
0,0,0,0,59,0,0,0,0,0,0,0,0,0,59,0,0,0,0,0,0,0,0,0,2,41,2,1,0,0,0,0,0,0,5,1,2,0,0,0,0,0
0,0,5,0,59,0,0,21,0,0,0,0,0,0,59,0,0,0,0,0,0,0,0,0,1,0,1,2,0,0,0,0,0,0,0,2,10,0,0,0,0,0
0,0,0,0,59,0,21,21,21,0,0,0,0,0,59,0,0,0,0,0,0,0,0,0,0,0,0,1,2,1,0,0,0,1,2,1,0,0,0,0,0,0
0,0,0,0,59,0,0,21,0,0,5,0,0,0,59,0,0,0,0,0,0,0,0,0,0,0,0,0,10,2,41,2,41,2,10,0,0,0,0,0,0,0
0,0,0,0,59,0,0,0,0,0,0,0,0,0,59,0,0,0,0,0,0,0,0,0,0,0,0,0,0,0,0,0,0,0,0,0,0,0,0,0,0,0
0,0,0,0,59,0,0,0,0,0,0,0,0,0,59,0,0,0,0,0,0,0,0,0,0,0,0,0,0,0,0,0,0,0,0,0,0,0,0,0,0,0
0,0,0,0,59,0,0,0,0,0,0,0,0,0,59,0,0,0,0,0,0,0,0,0,0,0,0,0,0,0,0,0,0,0,0,0,0,0,0,0,0,0
0,0,0,0,12,59,59,59,59,59,59,59,59,59,34,0,0,0,0,0,0,0,0,0,0,0,0,0,0,0,0,0,0,0,0,0,0,0,0,0,0,0
0,0,0,0,0,0,0,62,58,58,58,62,0,0,0,0,0,0,0,0,0,0,0,0,0,0,0,0,0,0,0,0,0,0,0,0,0,0,0,0,0,0
0,0,0,0,5,0,0,62,58,62,58,62,0,0,0,0,0,0,0,0,0,0,0,0,0,0,0,0,0,0,0,0,0,0,0,0,0,0,0,0,0,0
0,0,0,0,0,0,0,0,0,0,0,0,0,0,0,0,0,0,0,0,0,0,0,0,0,0,0,0,0,0,0,0,0,0,0,0,0,0,0,0,0,0
0,0,0,0,0,0,0,0,0,0,0,0,0,0,0,0,0,0,0,0,0,0,0,0,0,0,0,0,0,0,0,0,0,0,0,0,0,0,0,0,0,0
0,0,0,0,0,0,0,0,0,0,0,0,0,0,0,0,0,0,0,0,0,0,0,0,0,0,0,0,0,0,0,0,0,0,0,0,0,0,0,0,0,0
endlayer

layer
0,0,0,0,0,0,0,0,0,0,0,0,0,0,0,0,0,0,0,0,0,0,0,0,0,0,0,0,0,0,0,0,0,0,0,0,0,0,0,0,0,0
0,0,0,0,0,0,0,0,0,0,0,0,0,0,0,0,0,0,0,0,0,0,0,0,0,0,0,0,0,0,0,0,0,0,0,0,0,0,0,0,0,0
0,0,0,0,0,0,0,0,0,0,0,0,0,0,0,0,0,0,0,0,0,0,0,0,0,0,0,0,0,0,0,0,0,0,0,0,0,0,0,0,0,0
0,0,0,0,0,0,0,0,0,0,19,10,19,0,19,10,19,0,19,10,19,0,19,10,19,0,0,0,0,0,0,0,0,0,0,0,0,0,0,0,0,0
0,0,0,0,0,0,0,0,0,22,11,21,21,35,21,21,21,35,21,21,21,35,21,21,11,20,0,0,0,0,0,0,0,0,0,0,0,0,0,0,0,0
0,0,0,0,0,0,0,0,0,10,21,0,0,0,0,0,0,0,0,0,0,0,0,0,21,10,0,0,0,0,0,0,0,0,0,0,0,0,0,0,0,0
0,0,0,0,0,0,0,0,0,22,21,0,0,0,0,0,0,0,0,0,0,0,0,0,21,20,0,0,0,0,0,0,0,0,0,0,0,0,0,0,0,0
0,0,0,0,0,0,0,0,0,0,36,5,0,5,0,0,0,0,0,0,0,0,0,0,36,0,0,0,0,0,0,0,0,0,0,0,0,0,0,0,0,0
0,0,0,0,0,0,0,0,0,22,21,0,0,0,0,0,0,0,0,0,0,0,0,0,21,20,0,0,0,0,0,0,0,0,0,0,0,0,0,0,0,0
0,0,0,0,0,0,0,0,0,10,21,21,21,21,0,0,0,21,0,0,0,0,0,0,21,10,0,0,0,0,0,0,0,0,0,0,0,0,0,0,0,0
0,0,0,0,0,0,0,0,0,22,21,0,0,0,0,0,21,21,21,0,0,0,0,0,21,20,0,0,0,0,0,0,0,0,0,0,0,0,0,0,0,0
0,0,0,0,0,0,0,0,0,0,36,0,0,0,0,0,0,21,0,0,0,0,0,0,36,0,0,0,0,0,0,0,0,0,0,0,0,0,0,0,0,0
0,0,0,0,0,0,0,0,0,22,21,0,0,0,0,0,0,0,0,21,0,0,0,0,21,20,0,0,0,0,0,0,0,0,0,0,0,0,0,0,0,0
0,0,0,0,0,0,0,0,0,10,21,0,0,0,0,0,0,0,21,21,21,0,0,0,21,10,0,0,0,0,0,0,0,0,0,0,0,0,0,0,0,0
0,0,0,59,0,0,0,0,0,62,21,0,0,0,0,0,0,0,0,21,0,0,0,0,21,37,1,0,0,0,0,0,0,0,0,0,0,0,0,0,0,0
0,0,59,59,59,0,0,0,0,62,36,0,0,0,0,0,0,0,0,0,0,0,0,0,2,38,2,10,0,0,0,0,0,0,0,0,0,0,0,0,0,0
0,0,0,59,62,0,0,0,0,62,21,0,0,0,0,0,0,0,0,0,0,0,0,0,0,0,0,2,1,2,41,2,41,2,10,0,0,0,0,0,0,0
0,0,0,0,0,59,59,59,59,59,21,0,0,0,0,0,0,0,0,0,0,0,0,0,0,0,0,13,2,1,0,0,0,1,2,1,0,0,0,0,0,0
0,0,0,0,0,59,59,59,59,59,11,21,21,64,21,21,21,35,21,21,21,2,0,0,0,0,0,0,0,0,0,0,0,0,0,2,10,0,0,0,0,0
0,0,0,0,0,59,59,59,59,59,59,59,59,59,31,10,44,0,44,10,32,43,0,0,0,0,0,0,0,21,0,0,0,0,0,1,2,0,0,0,0,0
0,0,0,0,0,59,59,59,59,59,59,59,59,59,0,0,0,0,0,0,1,2,0,0,0,0,0,0,21,21,21,0,0,0,0,0,45,0,0,0,0,0
0,0,0,0,0,59,59,59,59,59,59,59,59,59,0,0,0,0,0,0,0,10,2,0,0,0,0,0,0,21,0,0,0,0,0,0,2,0,0,0,0,0
0,0,0,0,0,59,59,59,59,59,59,59,59,59,0,0,0,0,0,0,0,0,1,2,0,0,0,0,0,0,0,0,0,0,0,0,45,0,0,0,0,0
0,0,0,0,0,59,59,59,59,59,59,59,59,59,0,0,0,0,0,0,0,0,0,10,2,41,2,1,0,0,0,0,0,0,0,1,2,0,0,0,0,0
0,0,0,0,0,59,59,59,59,59,59,59,59,59,0,0,0,0,0,0,0,0,0,0,1,0,1,2,0,0,0,0,0,0,0,2,10,0,0,0,0,0
0,0,0,0,0,59,59,59,59,59,59,59,59,59,0,0,0,0,0,0,0,0,0,0,0,0,0,1,2,1,0,0,0,1,2,1,0,0,0,0,0,0
0,0,0,0,0,59,59,59,59,59,59,59,59,59,0,0,0,0,0,0,0,0,0,0,0,0,0,0,10,2,41,2,41,2,10,0,0,0,0,0,0,0
0,0,0,0,0,59,59,59,59,59,59,59,59,59,0,0,5,0,0,0,0,0,0,0,0,0,0,0,0,0,0,0,0,0,0,0,0,0,0,0,0,0
0,0,5,0,0,59,59,59,59,59,59,59,59,59,0,0,0,0,0,0,0,0,0,0,0,0,0,0,0,0,0,0,0,0,0,0,0,0,0,0,0,0
0,0,0,0,0,59,59,59,59,59,59,59,59,59,0,0,0,0,0,0,0,0,0,0,0,0,0,0,0,0,0,0,0,0,0,0,0,0,0,0,0,0
0,0,0,0,62,0,0,0,0,62,0,5,0,0,62,0,0,0,0,0,0,0,0,0,0,0,0,0,0,0,0,0,0,0,0,0,0,0,0,0,0,0
0,0,0,0,0,0,0,0,0,62,0,0,0,0,0,0,0,0,0,0,0,0,0,0,0,0,0,0,0,0,0,0,0,0,0,0,0,0,0,0,0,0
0,0,5,0,0,0,0,0,0,62,0,0,0,0,0,0,0,0,0,0,0,0,0,0,0,0,0,0,0,0,0,0,0,0,0,0,0,0,0,0,0,0
0,0,0,0,0,0,0,0,0,0,0,0,0,0,0,0,0,0,0,0,0,0,0,0,0,0,0,0,0,0,0,0,0,0,0,0,0,0,0,0,0,0
0,0,0,0,0,0,0,5,0,0,0,0,0,0,0,0,0,0,0,0,0,0,0,0,0,0,0,0,0,0,0,0,0,0,0,0,0,0,0,0,0,0
0,0,0,0,0,0,0,0,0,0,0,0,0,0,0,0,0,5,0,0,0,0,0,0,0,0,0,0,0,0,0,0,0,0,0,0,0,0,0,0,0,0
endlayer

layer
0,0,0,0,0,0,0,0,0,0,0,0,0,0,0,0,0,0,0,0,0,0,0,0,0,0,0,0,0,0,0,0,0,0,0,0,0,0,0,0,0,0
0,0,0,0,0,0,0,0,0,0,0,0,0,0,0,0,0,0,0,0,0,0,0,0,0,0,0,0,0,0,0,0,0,0,0,0,0,0,0,0,0,0
0,0,0,0,0,0,0,0,0,0,0,0,0,0,0,0,0,0,0,0,0,0,0,0,0,0,0,0,0,0,0,0,0,0,0,0,0,0,0,0,0,0
0,0,0,0,0,0,0,0,0,0,48,28,0,0,0,47,0,0,0,47,0,0,0,29,37,0,0,0,0,0,0,0,0,0,0,0,0,0,0,0,0,0
0,0,0,0,0,0,0,0,0,48,11,49,49,49,49,49,49,49,49,49,49,49,49,49,11,37,0,0,0,0,0,0,0,0,0,0,0,0,0,0,0,0
0,0,0,0,0,0,0,0,0,33,27,13,13,13,13,13,13,13,13,13,13,13,13,13,26,33,0,0,0,0,0,0,0,0,0,0,0,0,0,0,0,0
0,0,0,0,0,0,0,0,0,0,27,13,13,13,13,13,13,13,13,13,13,13,13,13,26,0,0,0,0,0,0,0,0,0,0,0,0,0,0,0,0,0
0,0,0,0,0,0,0,0,0,0,27,13,13,13,13,13,13,13,13,13,13,13,13,13,26,0,0,0,0,0,0,0,0,0,0,0,0,0,0,0,0,0
0,0,0,0,0,0,0,0,0,0,27,13,13,13,13,13,13,13,13,13,13,13,13,13,26,0,0,0,0,0,0,0,0,0,0,0,0,0,0,0,0,0
0,0,0,0,0,0,0,0,0,47,27,13,13,13,13,13,13,13,13,13,13,13,13,13,26,47,0,0,0,0,0,0,0,0,0,0,0,0,0,0,0,0
0,0,0,0,0,0,0,0,0,0,27,13,13,13,13,13,13,13,13,13,13,13,13,13,26,0,0,0,0,0,0,0,0,0,0,0,0,0,0,0,0,0
0,0,0,0,0,0,0,0,0,0,27,13,13,13,13,13,13,13,13,13,13,13,13,13,26,0,0,0,0,0,0,0,0,0,0,0,0,0,0,0,0,0
0,0,0,0,0,0,0,0,0,0,27,13,13,13,13,13,13,13,13,13,13,13,13,13,26,0,0,0,0,0,0,0,0,0,0,0,0,0,0,0,0,0
0,0,0,0,0,0,0,0,0,47,27,13,13,13,13,13,13,13,13,13,13,13,13,13,26,47,0,0,0,0,0,0,0,0,0,0,0,0,0,0,0,0
0,0,0,25,0,0,0,0,0,0,27,13,13,13,13,13,13,13,13,13,13,13,13,13,2,0,1,0,0,0,0,0,0,0,0,0,0,0,0,0,0,0
0,0,29,59,28,0,0,0,0,0,27,13,13,13,13,13,13,13,13,13,13,13,13,13,2,7,2,10,10,0,0,0,0,0,0,0,0,0,0,0,0,0
0,0,0,33,0,0,0,0,0,0,27,13,13,13,13,13,13,13,13,13,13,13,13,13,7,7,7,2,2,2,2,2,2,2,1,0,0,0,0,0,0,0
0,0,0,0,0,0,0,0,0,25,27,13,13,13,13,13,13,13,13,13,13,13,13,13,13,13,13,24,2,2,7,7,7,2,2,2,0,0,0,0,0,0
0,0,0,0,0,0,0,0,0,32,11,50,50,50,50,50,50,50,50,50,50,2,7,13,13,13,13,13,7,7,13,13,13,7,7,2,1,0,0,0,0,0
0,0,0,0,0,0,0,0,0,0,32,28,0,0,0,47,0,0,0,47,0,7,7,13,13,13,13,13,13,13,13,13,13,13,7,2,2,0,0,0,0,0
0,0,0,0,0,0,0,0,0,0,0,0,0,0,0,0,0,0,0,0,1,2,7,13,13,13,13,13,13,13,13,13,13,13,13,7,2,0,0,0,0,0
0,0,0,0,0,0,0,0,0,0,0,0,0,0,0,0,0,0,0,0,0,10,2,7,13,13,13,7,13,13,13,13,13,13,13,7,2,0,0,0,0,0
0,0,0,0,0,0,0,0,0,0,0,0,0,0,0,0,0,0,0,0,0,10,2,2,7,7,2,7,13,13,13,13,13,13,13,7,2,0,0,0,0,0
0,0,0,0,0,0,0,0,0,0,0,0,0,0,0,0,0,0,0,0,0,0,10,10,2,7,2,2,7,13,13,13,13,13,7,2,2,0,0,0,0,0
0,0,0,0,0,0,0,0,0,0,0,0,0,0,0,0,0,0,0,0,0,0,0,0,1,0,1,2,7,7,13,13,13,7,7,2,1,0,0,0,0,0
0,0,0,0,0,0,0,0,0,0,0,0,0,0,0,0,0,0,0,0,0,0,0,0,0,0,5,2,2,2,7,7,7,2,2,2,0,0,0,0,0,0
0,0,0,0,0,0,0,0,0,0,0,0,0,0,0,0,0,0,0,0,0,0,0,0,0,0,5,0,1,2,2,2,2,2,1,0,0,0,0,0,0,0
0,0,0,0,0,0,0,0,0,0,0,0,0,0,0,0,0,0,0,0,0,0,0,0,0,0,0,0,0,0,0,0,0,0,0,0,0,0,0,0,0,0
0,0,0,0,0,0,0,0,0,0,0,0,0,0,0,0,0,0,0,0,0,0,0,0,0,0,0,0,0,0,0,0,0,0,0,0,0,0,0,0,0,0
0,0,0,0,0,0,0,0,0,0,0,0,0,0,0,0,0,0,0,0,0,0,0,0,0,0,0,0,0,0,0,0,0,0,0,0,0,0,0,0,0,0
0,0,0,0,0,0,0,0,0,0,0,0,0,0,0,0,0,0,0,0,0,0,0,0,0,0,0,0,0,0,0,0,0,0,0,0,0,0,0,0,0,0
0,0,0,0,0,0,0,0,0,0,0,0,0,0,0,0,0,0,0,0,0,0,0,0,0,0,0,0,0,0,0,0,0,0,0,0,0,0,0,0,0,0
0,0,0,0,0,0,0,0,0,0,0,0,0,0,0,0,0,0,0,0,0,0,0,0,0,0,0,0,0,0,0,0,0,0,0,0,0,0,0,0,0,0
0,0,0,0,0,0,0,0,0,0,0,0,0,0,0,0,0,0,0,0,0,0,0,0,0,0,0,0,0,0,0,0,0,0,0,0,0,0,0,0,0,0
0,0,0,0,0,0,0,0,0,0,0,0,0,0,0,0,0,0,0,0,0,0,0,0,0,0,0,0,0,0,0,0,0,0,0,0,0,0,0,0,0,0
0,0,0,0,0,0,0,0,0,0,0,0,0,0,0,0,0,0,0,0,0,0,0,0,0,0,0,0,0,0,0,0,0,0,0,0,0,0,0,0,0,0
endlayer

layer
0,0,0,0,0,0,0,0,0,0,0,0,0,0,0,0,0,0,0,0,0,0,0,0,0,0,0,0,0,0,0,0,0,0,0,0,0,0,0,0,0,0
0,0,0,0,0,0,0,0,0,0,0,0,0,0,0,0,0,0,0,0,0,0,0,0,0,0,0,0,0,0,0,0,0,0,0,0,0,0,0,0,0,0
0,0,0,0,0,0,0,0,0,0,0,0,0,0,0,0,0,0,0,0,0,0,0,0,0,0,0,0,0,0,0,0,0,0,0,0,0,0,0,0,0,0
0,0,0,0,0,0,0,0,0,0,19,0,0,0,0,0,0,0,0,0,0,0,0,0,19,0,0,0,0,0,0,0,0,0,0,0,0,0,0,0,0,0
0,0,0,0,0,0,0,0,0,22,11,21,21,21,21,21,21,21,21,21,21,21,21,21,11,20,0,0,0,0,0,0,0,0,0,0,0,0,0,0,0,0
0,0,0,0,0,0,0,0,0,0,21,0,0,0,0,0,0,0,0,52,0,0,5,0,21,0,0,0,0,0,0,0,0,0,0,0,0,0,0,0,0,0
0,0,0,0,0,0,0,0,0,0,21,0,0,0,0,0,0,0,0,0,0,0,0,0,21,0,0,0,0,0,0,0,0,0,0,0,0,0,0,0,0,0
0,0,0,0,0,0,0,0,0,0,21,5,0,0,0,0,0,0,0,0,0,0,0,0,21,0,0,0,0,0,0,0,0,0,0,0,0,0,0,0,0,0
0,0,0,0,0,0,0,0,0,0,21,0,0,0,0,0,0,0,0,0,0,0,0,0,21,0,0,0,0,0,0,0,0,0,0,0,0,0,0,0,0,0
0,0,0,0,0,0,0,0,0,0,21,0,0,0,0,0,5,0,0,0,0,0,0,0,21,0,0,0,0,0,0,0,0,0,0,0,0,0,0,0,0,0
0,0,0,0,0,0,0,0,0,0,21,0,0,0,21,0,0,0,0,0,0,0,0,0,21,0,0,0,0,0,0,0,0,0,0,0,0,0,0,0,0,0
0,0,0,0,0,0,0,0,0,0,21,0,0,21,24,21,0,0,0,0,0,0,0,0,21,0,0,0,0,0,0,0,0,0,0,0,0,0,0,0,0,0
0,0,0,0,0,0,0,0,0,0,21,0,0,0,21,0,0,0,0,0,0,0,0,0,21,0,0,0,0,0,0,0,0,0,0,0,0,0,0,0,0,0
0,0,0,0,0,0,0,0,0,0,21,0,0,0,0,0,0,0,0,0,0,0,0,0,21,0,0,0,0,0,0,0,0,0,0,0,0,0,0,0,0,0
0,0,0,62,0,0,0,0,0,0,21,0,0,0,0,0,0,0,0,0,0,0,0,0,21,7,15,0,0,0,0,0,0,0,0,0,0,0,0,0,0,0
0,0,62,59,62,0,0,0,0,0,21,0,0,5,0,0,0,0,0,0,0,0,0,0,21,21,21,15,15,0,0,0,0,0,0,0,0,0,0,0,0,0
0,0,0,62,0,0,0,0,0,0,21,0,0,0,0,0,0,0,0,0,0,0,0,0,0,0,0,21,11,15,21,21,21,0,15,0,0,0,0,0,0,0
0,0,0,0,0,0,0,0,0,0,21,0,0,0,5,0,0,0,0,0,0,0,0,0,0,0,0,13,21,21,21,0,21,21,21,7,0,0,0,0,0,0
0,0,0,0,0,0,0,0,0,22,11,21,21,21,21,21,21,21,21,21,21,21,0,0,0,0,0,0,0,0,0,0,0,0,0,21,15,0,0,0,0,0
0,0,0,0,0,0,0,0,0,0,44,0,0,0,0,0,0,0,0,0,7,21,0,0,0,0,0,0,0,0,0,21,0,0,0,21,0,0,0,0,0,0
0,0,0,0,0,0,0,0,0,0,0,0,0,0,0,0,0,0,0,0,15,21,0,0,0,5,0,0,0,0,21,24,21,0,0,21,21,0,0,0,0,0
0,0,0,0,0,0,0,0,0,0,0,0,0,0,0,0,0,0,0,0,0,15,21,0,0,0,0,0,0,0,0,21,52,0,0,0,21,0,0,0,0,0
0,0,0,0,0,0,0,0,0,0,0,0,0,0,0,0,0,0,0,0,0,15,11,21,0,0,0,21,0,0,0,0,0,0,0,21,21,0,0,0,0,0
0,0,0,0,0,0,0,0,0,0,0,0,0,0,0,0,0,0,0,0,0,0,15,15,21,21,21,21,0,0,5,0,0,0,0,21,0,0,0,0,0,0
0,0,0,0,0,0,0,0,0,0,0,0,0,0,0,0,0,0,0,0,0,0,0,0,15,7,15,21,0,0,0,0,0,0,0,21,15,0,0,0,0,0
0,0,0,0,0,0,0,0,0,0,0,0,0,0,0,0,0,0,0,0,0,0,0,0,0,0,0,7,21,21,21,0,21,21,21,7,0,0,0,0,0,0
0,0,0,0,0,0,0,0,0,0,0,0,0,0,0,0,0,0,0,0,0,0,0,0,0,0,0,0,15,0,21,21,21,0,15,0,0,0,0,0,0,0
0,0,0,0,0,0,0,0,0,0,0,0,0,0,0,0,0,0,0,0,0,0,0,0,0,0,0,0,0,0,0,0,0,0,0,0,0,0,0,0,0,0
0,0,0,0,0,0,0,0,0,0,0,0,0,0,0,0,0,0,0,0,0,0,0,0,0,0,0,0,0,0,0,0,0,0,0,0,0,0,0,0,0,0
0,0,0,0,0,0,0,0,0,0,0,0,0,0,0,0,0,0,0,0,0,0,0,0,0,0,0,0,0,0,0,0,0,0,0,0,0,0,0,0,0,0
0,0,0,0,0,0,0,0,0,0,0,0,0,0,0,0,0,0,0,0,0,0,0,0,0,0,0,0,0,0,0,0,0,0,0,0,0,0,0,0,0,0
0,0,0,0,0,0,0,0,0,0,0,0,0,0,0,0,0,0,0,0,0,0,0,0,0,0,0,0,0,0,0,0,0,0,0,0,0,0,0,0,0,0
0,0,0,0,0,0,0,0,0,0,0,0,0,0,0,0,0,0,0,0,0,0,0,0,0,0,0,0,0,0,0,0,0,0,0,0,0,0,0,0,0,0
0,0,0,0,0,0,0,0,0,0,0,0,0,0,0,0,0,0,0,0,0,0,0,0,0,0,0,0,0,0,0,0,0,0,0,0,0,0,0,0,0,0
0,0,0,0,0,0,0,0,0,0,0,0,0,0,0,0,0,0,0,0,0,0,0,0,0,0,0,0,0,0,0,0,0,0,0,0,0,0,0,0,0,0
0,0,0,0,0,0,0,0,0,0,0,0,0,0,0,0,0,0,0,0,0,0,0,0,0,0,0,0,0,0,0,0,0,0,0,0,0,0,0,0,0,0
endlayer

layer
0,0,0,0,0,0,0,0,0,0,0,0,0,0,0,0,0,0,0,0,0,0,0,0,0,0,0,0,0,0,0,0,0,0,0,0,0,0,0,0,0,0
0,0,0,0,0,0,0,0,0,0,0,0,0,0,0,0,0,0,0,0,0,0,0,0,0,0,0,0,0,0,0,0,0,0,0,0,0,0,0,0,0,0
0,0,0,0,0,0,0,0,0,0,0,0,0,0,0,0,0,0,0,0,0,0,0,0,0,0,0,0,0,0,0,0,0,0,0,0,0,0,0,0,0,0
0,0,0,0,0,0,0,0,0,0,19,10,19,0,19,10,19,0,19,10,19,0,19,10,19,0,0,0,0,0,0,0,0,0,0,0,0,0,0,0,0,0
0,0,0,0,0,0,0,0,0,22,11,21,21,35,21,21,21,35,21,21,21,35,21,21,11,20,0,0,0,0,0,0,0,0,0,0,0,0,0,0,0,0
0,0,0,0,0,0,0,0,0,10,21,0,0,0,0,0,0,0,0,0,0,0,0,0,21,10,0,0,0,0,0,0,0,0,0,0,0,0,0,0,0,0
0,0,0,0,0,0,0,0,0,22,21,0,0,0,0,0,0,0,0,0,0,0,0,0,21,20,0,0,0,0,0,0,0,0,0,0,0,0,0,0,0,0
0,0,0,0,0,0,0,0,0,0,36,0,0,0,0,0,0,0,0,0,0,0,0,0,36,0,0,0,0,0,0,0,0,0,0,0,0,0,0,0,0,0
0,0,0,0,0,0,0,0,0,22,21,0,0,0,0,0,0,0,0,0,0,0,0,46,21,20,0,0,0,0,0,0,0,0,0,0,0,0,0,0,0,0
0,0,0,0,0,0,0,0,0,10,21,0,0,0,5,0,0,0,0,0,0,0,0,0,21,10,0,0,0,0,0,0,0,0,0,0,0,0,0,0,0,0
0,0,0,0,0,0,0,0,0,22,21,0,0,0,21,0,0,0,0,0,0,0,0,0,21,20,0,0,0,0,0,0,0,0,0,0,0,0,0,0,0,0
0,0,0,0,0,0,0,0,0,0,36,0,0,21,21,21,0,0,0,5,0,0,0,0,36,0,0,0,0,0,0,0,0,0,0,0,0,0,0,0,0,0
0,0,0,0,0,0,0,0,0,22,21,0,0,0,21,0,0,0,0,0,0,0,0,0,21,20,0,0,0,0,0,0,0,0,0,0,0,0,0,0,0,0
0,0,0,0,0,0,0,0,0,10,21,0,0,0,0,0,0,0,0,0,0,0,5,0,21,10,0,0,0,0,0,0,0,0,0,0,0,0,0,0,0,0
0,0,0,0,0,0,0,0,0,22,21,0,0,0,0,0,0,0,0,0,0,0,0,0,21,20,0,0,0,0,0,0,0,0,0,0,0,0,0,0,0,0
0,0,0,59,0,0,0,0,0,0,36,0,0,0,0,0,0,0,0,0,0,0,0,0,27,53,27,10,0,0,0,0,0,0,0,0,0,0,0,0,0,0
0,0,0,0,0,0,0,0,0,22,21,0,0,0,0,0,0,0,0,0,0,0,0,0,0,0,46,21,6,0,21,35,21,0,0,0,0,0,0,0,0,0
0,0,0,0,0,0,0,0,0,10,21,0,0,0,0,61,0,0,0,0,0,0,0,0,0,0,0,0,21,35,21,0,21,35,21,10,0,0,0,0,0,0
0,0,0,0,0,0,0,0,0,22,11,21,21,35,21,21,21,35,21,21,21,27,0,0,0,0,0,0,0,0,0,0,0,0,0,21,0,0,0,0,0,0
0,0,0,0,0,0,0,0,0,0,44,10,44,0,44,10,44,0,44,10,44,54,0,0,0,0,5,0,0,0,0,21,0,0,0,36,0,0,0,0,0,0
0,0,0,0,0,0,0,0,0,0,0,0,0,0,0,0,0,0,0,0,0,27,0,0,0,0,0,0,0,0,21,21,21,0,0,21,21,0,0,0,0,0
0,0,0,0,0,0,0,0,0,0,0,0,0,0,0,0,0,0,0,0,0,10,21,0,0,0,0,0,0,0,0,21,0,0,0,0,36,0,0,0,0,0
0,0,0,0,0,0,0,0,0,0,0,0,0,0,0,0,0,0,0,0,0,0,12,21,0,0,0,21,0,0,0,0,0,0,0,21,21,0,0,0,0,0
0,0,0,0,0,0,0,0,0,0,0,0,0,0,0,0,0,0,0,0,0,0,0,10,27,53,27,55,0,0,0,0,0,0,0,36,0,0,0,0,0,0
0,0,0,0,0,0,0,0,0,0,0,0,0,0,0,0,0,0,0,0,0,0,0,0,0,0,0,21,0,0,0,0,0,0,61,21,0,0,0,0,0,0
0,0,0,0,0,0,0,0,0,0,0,0,0,0,0,0,0,0,0,0,0,0,0,0,0,0,0,10,21,35,21,0,21,35,21,10,0,0,0,0,0,0
0,0,0,0,0,0,0,0,0,0,0,0,0,0,0,0,0,0,0,0,0,0,0,0,0,0,0,0,0,0,21,35,21,0,0,0,0,0,0,0,0,0
0,0,0,0,0,0,0,0,0,0,0,0,0,0,0,0,0,0,0,0,0,0,0,0,0,0,0,0,0,0,0,0,0,0,0,0,0,0,0,0,0,0
0,0,0,0,0,0,0,0,0,0,0,0,0,0,0,0,0,0,0,0,0,0,0,0,0,0,0,0,0,0,0,0,0,0,0,0,0,0,0,0,0,0
0,0,0,0,0,0,0,0,0,0,0,0,0,0,0,0,0,0,0,0,0,0,0,0,0,0,0,0,0,0,0,0,0,0,0,0,0,0,0,0,0,0
0,0,0,0,0,0,0,0,0,0,0,0,0,0,0,0,0,0,0,0,0,0,0,0,0,0,0,0,0,0,0,0,0,0,0,0,0,0,0,0,0,0
0,0,0,0,0,0,0,0,0,0,0,0,0,0,0,0,0,0,0,0,0,0,0,0,0,0,0,0,0,0,0,0,0,0,0,0,0,0,0,0,0,0
0,0,0,0,0,0,0,0,0,0,0,0,0,0,0,0,0,0,0,0,0,0,0,0,0,0,0,0,0,0,0,0,0,0,0,0,0,0,0,0,0,0
0,0,0,0,0,0,0,0,0,0,0,0,0,0,0,0,0,0,0,0,0,0,0,0,0,0,0,0,0,0,0,0,0,0,0,0,0,0,0,0,0,0
0,0,0,0,0,0,0,0,0,0,0,0,0,0,0,0,0,0,0,0,0,0,0,0,0,0,0,0,0,0,0,0,0,0,0,0,0,0,0,0,0,0
0,0,0,0,0,0,0,0,0,0,0,0,0,0,0,0,0,0,0,0,0,0,0,0,0,0,0,0,0,0,0,0,0,0,0,0,0,0,0,0,0,0
endlayer

layer
0,0,0,0,0,0,0,0,0,0,0,0,0,0,0,0,0,0,0,0,0,0,0,0,0,0,0,0,0,0,0,0,0,0,0,0,0,0,0,0,0,0
0,0,0,0,0,0,0,0,0,0,0,0,0,0,0,0,0,0,0,0,0,0,0,0,0,0,0,0,0,0,0,0,0,0,0,0,0,0,0,0,0,0
0,0,0,0,0,0,0,0,0,0,0,0,0,0,0,0,0,0,0,0,0,0,0,0,0,0,0,0,0,0,0,0,0,0,0,0,0,0,0,0,0,0
0,0,0,0,0,0,0,0,0,0,19,10,19,0,19,10,19,0,19,10,19,0,19,10,19,0,0,0,0,0,0,0,0,0,0,0,0,0,0,0,0,0
0,0,0,0,0,0,0,0,0,22,11,21,21,35,21,21,21,35,21,21,21,35,21,21,11,20,0,0,0,0,0,0,0,0,0,0,0,0,0,0,0,0
0,0,0,0,0,0,0,0,0,10,21,0,0,0,0,0,0,0,0,0,5,0,0,0,21,10,0,0,0,0,0,0,0,0,0,0,0,0,0,0,0,0
0,0,0,0,0,0,0,0,0,22,21,0,0,0,0,0,0,0,0,0,0,0,0,0,21,20,0,0,0,0,0,0,0,0,0,0,0,0,0,0,0,0
0,0,0,0,0,0,0,0,0,0,36,0,0,0,0,0,0,0,0,0,0,0,0,0,36,0,0,0,0,0,0,0,0,0,0,0,0,0,0,0,0,0
0,0,0,0,0,0,0,0,0,22,21,0,0,0,0,0,0,0,0,0,0,0,0,0,21,20,0,0,0,0,0,0,0,0,0,0,0,0,0,0,0,0
0,0,0,0,0,0,0,0,0,10,21,0,0,0,0,0,0,0,0,0,0,0,0,0,21,10,0,0,0,0,0,0,0,0,0,0,0,0,0,0,0,0
0,0,0,0,0,0,0,0,0,22,21,0,0,0,21,0,0,0,0,0,0,0,0,0,21,20,0,0,0,0,0,0,0,0,0,0,0,0,0,0,0,0
0,0,0,0,0,0,0,0,0,0,36,0,0,21,21,21,0,0,0,0,0,0,0,0,36,0,0,0,0,0,0,0,0,0,0,0,0,0,0,0,0,0
0,0,0,0,0,0,0,0,0,22,21,0,0,0,21,0,0,0,0,0,0,0,0,0,21,20,0,0,0,0,0,0,0,0,0,0,0,0,0,0,0,0
0,0,0,0,0,0,0,0,0,10,21,0,0,0,0,0,0,0,0,0,0,0,0,0,21,10,0,0,0,0,0,0,0,0,0,0,0,0,0,0,0,0
0,0,0,0,0,0,0,0,0,22,21,0,0,0,0,0,0,0,0,0,0,0,0,0,21,20,0,0,0,0,0,0,0,0,0,0,0,0,0,0,0,0
0,0,0,47,0,0,0,0,0,0,36,0,0,0,0,0,0,0,0,0,0,0,0,0,27,53,27,10,0,0,0,0,0,0,0,0,0,0,0,0,0,0
0,0,0,0,0,0,0,0,0,22,21,0,0,0,0,0,0,0,0,0,0,0,0,0,0,0,0,21,28,0,27,53,27,0,0,0,0,0,0,0,0,0
0,0,0,0,0,0,0,0,0,10,21,0,0,0,0,0,0,0,0,0,0,0,0,0,0,0,0,0,27,53,27,0,27,53,27,10,0,0,0,0,0,0
0,0,0,0,0,0,0,0,0,22,11,21,21,35,21,21,21,35,21,21,21,27,0,0,0,0,0,0,0,0,0,0,0,0,0,27,0,0,0,0,0,0
0,0,0,0,0,0,0,0,0,0,44,10,44,0,44,10,44,0,44,10,44,54,0,0,0,0,0,0,0,0,0,21,0,0,0,54,0,0,0,0,0,0
0,0,0,0,0,0,0,0,0,0,0,0,0,0,0,0,0,0,0,0,0,27,0,0,0,0,0,0,0,0,21,21,21,0,0,27,27,0,0,0,0,0
0,0,0,0,0,0,0,0,0,0,0,0,0,0,0,0,0,0,0,0,0,10,21,0,0,0,0,0,0,0,0,21,0,0,0,0,54,0,0,0,0,0
0,0,0,0,0,0,0,0,0,0,0,0,0,0,0,0,0,0,0,0,0,0,12,21,0,0,0,27,0,0,0,0,0,0,0,27,27,0,0,0,0,0
0,0,0,0,0,0,0,0,0,0,0,0,0,0,0,0,0,0,0,0,0,0,0,10,27,53,27,53,0,0,0,0,0,0,0,54,0,0,0,0,0,0
0,0,0,0,0,0,0,0,0,0,0,0,0,0,0,0,0,0,0,0,0,0,0,0,0,0,0,27,0,0,0,0,0,0,0,27,0,0,0,0,0,0
0,0,0,0,0,0,0,0,0,0,0,0,0,0,0,0,0,0,0,0,0,0,0,0,0,0,5,10,27,53,27,0,27,53,27,10,0,0,0,0,0,0
0,0,0,0,0,0,0,0,0,0,0,0,0,0,0,0,0,0,0,0,0,0,0,0,0,0,0,0,0,0,27,53,27,0,0,0,0,0,0,0,0,0
0,0,0,0,0,0,0,0,0,0,0,0,0,0,0,0,0,0,0,0,0,0,0,0,0,0,0,0,0,0,0,0,0,0,0,0,0,0,0,0,0,0
0,0,0,0,0,0,0,0,0,0,0,0,0,0,0,0,0,0,0,0,0,0,0,0,0,0,0,0,0,0,0,0,0,0,0,0,0,0,0,0,0,0
0,0,0,0,0,0,0,0,0,0,0,0,0,0,0,0,0,0,0,0,0,0,0,0,0,0,0,0,0,0,0,0,0,0,0,0,0,0,0,0,0,0
0,0,0,0,0,0,0,0,0,0,0,0,0,0,0,0,0,0,0,0,0,0,0,0,0,0,0,0,0,0,0,0,0,0,0,0,0,0,0,0,0,0
0,0,0,0,0,0,0,0,0,0,0,0,0,0,0,0,0,0,0,0,0,0,0,0,0,0,0,0,0,0,0,0,0,0,0,0,0,0,0,0,0,0
0,0,0,0,0,0,0,0,0,0,0,0,0,0,0,0,0,0,0,0,0,0,0,0,0,0,0,0,0,0,0,0,0,0,0,0,0,0,0,0,0,0
0,0,0,0,0,0,0,0,0,0,0,0,0,0,0,0,0,0,0,0,0,0,0,0,0,0,0,0,0,0,0,0,0,0,0,0,0,0,0,0,0,0
0,0,0,0,0,0,0,0,0,0,0,0,0,0,0,0,0,0,0,0,0,0,0,0,0,0,0,0,0,0,0,0,0,0,0,0,0,0,0,0,0,0
0,0,0,0,0,0,0,0,0,0,0,0,0,0,0,0,0,0,0,0,0,0,0,0,0,0,0,0,0,0,0,0,0,0,0,0,0,0,0,0,0,0
endlayer

layer
0,0,0,0,0,0,0,0,0,0,0,0,0,0,0,0,0,0,0,0,0,0,0,0,0,0,0,0,0,0,0,0,0,0,0,0,0,0,0,0,0,0
0,0,0,0,0,0,0,0,0,0,0,0,0,0,0,0,0,0,0,0,0,0,0,0,0,0,0,0,0,0,0,0,0,0,0,0,0,0,0,0,0,0
0,0,0,0,0,0,0,0,0,0,0,0,0,0,0,0,0,0,0,0,0,0,0,0,0,0,0,0,0,0,0,0,0,0,0,0,0,0,0,0,0,0
0,0,0,0,0,0,0,0,0,0,48,28,0,0,0,47,0,0,0,47,0,0,0,29,37,0,0,0,0,0,0,0,0,0,0,0,0,0,0,0,0,0
0,0,0,0,0,0,0,0,0,48,11,49,49,49,49,49,49,49,49,49,49,49,49,49,11,37,0,0,0,0,0,0,0,0,0,0,0,0,0,0,0,0
0,0,0,0,0,0,0,0,0,33,27,13,13,13,13,13,13,13,13,13,13,13,13,13,26,33,0,0,0,0,0,0,0,0,0,0,0,0,0,0,0,0
0,0,0,0,0,0,0,0,0,0,27,13,13,13,13,13,13,13,13,13,13,13,13,13,26,5,0,0,0,0,0,0,0,0,0,0,0,0,0,0,0,0
0,0,0,0,0,0,0,0,0,0,27,13,13,13,13,13,13,13,13,13,13,13,13,13,26,0,0,0,0,0,0,0,0,0,0,0,0,0,0,0,0,0
0,0,0,0,0,0,0,0,0,0,27,13,13,13,13,13,13,13,13,13,13,13,13,13,26,0,0,0,0,0,0,0,0,0,0,0,0,0,0,0,0,0
0,0,0,0,0,0,0,0,0,47,27,13,13,13,13,13,13,13,13,13,13,13,13,13,26,47,0,0,0,0,0,0,0,0,0,0,0,0,0,0,0,0
0,0,0,0,0,0,0,0,0,0,27,13,13,13,13,13,13,13,13,13,13,13,13,13,26,0,0,0,0,0,0,0,0,0,0,0,0,0,0,0,0,0
0,0,0,0,0,0,0,0,0,0,27,13,13,13,13,13,13,13,13,13,13,13,13,13,26,0,0,0,0,0,0,0,0,0,0,0,0,0,0,0,0,0
0,0,0,0,0,0,0,0,0,0,27,13,13,13,13,13,13,13,13,13,13,13,13,13,26,0,0,0,0,0,0,0,0,0,0,0,0,0,0,0,0,0
0,0,0,0,0,0,0,0,0,47,27,13,13,13,13,13,13,13,13,13,13,13,13,13,26,47,0,0,0,0,0,0,0,0,0,0,0,0,0,0,0,0
0,0,0,0,0,0,0,0,0,0,27,13,13,13,13,13,13,13,13,13,13,13,13,13,26,0,0,0,0,0,0,0,0,0,0,0,0,0,0,0,0,0
0,0,0,47,0,0,0,0,0,0,27,13,13,13,13,13,13,13,13,13,13,13,13,13,26,21,21,10,0,0,0,0,0,0,0,0,0,0,0,0,0,0
0,0,0,0,0,0,0,0,0,0,27,13,13,13,13,13,13,13,13,13,13,13,13,13,13,13,13,21,11,0,21,21,21,0,0,0,0,0,0,0,0,0
0,0,0,0,0,0,0,0,0,25,27,13,13,13,13,13,13,13,13,13,13,13,13,13,13,13,13,13,21,21,13,13,13,21,21,6,0,0,0,0,0,0
0,0,0,0,0,0,0,0,0,32,11,50,50,50,50,50,50,50,50,50,50,50,13,13,13,13,13,13,13,13,13,13,13,13,13,21,0,0,0,0,0,0
0,0,0,0,0,0,0,0,0,0,32,28,0,0,0,47,0,0,5,47,0,21,13,13,13,13,13,13,13,13,13,13,13,13,13,21,0,0,0,0,0,0
0,0,0,0,0,0,0,0,0,0,0,0,0,0,0,0,0,0,0,0,0,21,13,13,13,13,13,13,13,13,13,13,13,13,13,13,21,0,0,0,0,0
0,0,0,0,0,0,0,0,0,0,0,0,0,0,0,0,0,0,0,0,0,10,21,13,13,13,13,13,13,13,13,13,13,13,13,13,21,0,0,0,0,0
0,0,0,0,0,0,0,0,0,0,0,0,0,0,0,0,0,0,0,0,0,0,11,21,13,13,13,13,13,13,13,13,13,13,13,13,21,0,0,0,0,0
0,0,0,0,0,0,0,0,0,0,0,0,0,0,0,0,0,0,0,0,0,0,0,10,21,21,21,21,13,13,13,13,13,13,13,21,0,0,0,0,0,0
0,0,0,0,0,0,0,0,0,0,0,0,0,0,0,0,0,0,0,0,0,0,0,0,0,0,0,21,13,13,13,13,13,13,13,21,0,0,0,0,0,0
0,0,0,0,0,0,0,0,0,0,0,0,0,0,0,0,0,0,0,0,0,0,0,0,0,0,0,12,21,21,13,13,13,21,21,34,0,0,0,0,0,0
0,0,0,0,0,0,0,0,0,0,0,0,0,0,0,0,0,0,0,0,0,0,0,0,0,0,0,0,0,0,21,21,21,0,0,0,0,0,0,0,0,0
0,0,0,0,0,0,0,0,0,0,0,0,0,0,0,0,0,0,0,0,0,0,0,0,0,0,0,0,0,0,0,0,0,0,0,0,0,0,0,0,0,0
0,0,0,0,0,0,0,0,0,0,0,0,0,0,0,0,0,0,0,0,0,0,0,0,0,0,0,0,0,0,0,0,0,0,0,0,0,0,0,0,0,0
0,0,0,0,0,0,0,0,0,0,0,0,0,0,0,0,0,0,0,0,0,0,0,0,0,0,0,0,0,0,0,0,0,0,0,0,0,0,0,0,0,0
0,0,0,0,0,0,0,0,0,0,0,0,0,0,0,0,0,0,0,0,0,0,0,0,0,0,0,0,0,0,0,0,0,0,0,0,0,0,0,0,0,0
0,0,0,0,0,0,0,0,0,0,0,0,0,0,0,0,0,0,0,0,0,0,0,0,0,0,0,0,0,0,0,0,0,0,0,0,0,0,0,0,0,0
0,0,0,0,0,0,0,0,0,0,0,0,0,0,0,0,0,0,0,0,0,0,0,0,0,0,0,0,0,0,0,0,0,0,0,0,0,0,0,0,0,0
0,0,0,0,0,0,0,0,0,0,0,0,0,0,0,0,0,0,0,0,0,0,0,0,0,0,0,0,0,0,0,0,0,0,0,0,0,0,0,0,0,0
0,0,0,0,0,0,0,0,0,0,0,0,0,0,0,0,0,0,0,0,0,0,0,0,0,0,0,0,0,0,0,0,0,0,0,0,0,0,0,0,0,0
0,0,0,0,0,0,0,0,0,0,0,0,0,0,0,0,0,0,0,0,0,0,0,0,0,0,0,0,0,0,0,0,0,0,0,0,0,0,0,0,0,0
endlayer

layer
0,0,0,0,0,0,0,0,0,0,0,0,0,0,0,0,0,0,0,0,0,0,0,0,0,0,0,0,0,0,0,0,0,0,0,0,0,0,0,0,0,0
0,0,0,0,0,0,0,0,0,0,0,0,0,0,0,0,0,0,0,0,0,0,0,0,0,0,0,0,0,0,0,0,0,0,0,0,0,0,0,0,0,0
0,0,0,0,0,0,0,0,0,0,0,0,0,0,0,0,0,0,0,0,0,0,0,0,0,0,0,0,0,0,0,0,0,0,0,0,0,0,0,0,0,0
0,0,0,0,0,0,0,0,0,0,19,0,0,0,0,0,0,0,0,0,5,0,0,0,19,0,0,0,0,0,0,0,0,0,0,0,0,0,0,0,0,0
0,0,0,0,0,0,0,0,0,22,11,21,21,21,21,21,21,21,21,21,21,21,21,21,11,20,0,0,0,0,0,0,0,0,0,0,0,0,0,0,0,0
0,0,0,0,0,0,0,0,0,0,21,0,0,0,0,0,0,0,0,0,0,0,0,5,21,0,0,0,0,0,0,0,0,0,0,0,0,0,0,0,0,0
0,0,0,0,0,0,0,0,0,0,21,0,0,0,0,0,0,0,0,0,0,0,0,0,21,0,0,0,0,0,0,0,0,0,0,0,0,0,0,0,0,0
0,0,0,0,0,0,0,0,0,0,21,0,0,0,23,0,0,0,0,0,0,24,0,0,21,0,0,0,0,0,0,0,0,0,0,0,0,0,0,0,0,0
0,0,0,0,0,0,0,0,0,0,21,0,0,0,0,0,0,0,0,0,0,0,0,0,21,0,0,0,0,0,0,0,0,0,0,0,0,0,0,0,0,0
0,0,0,0,0,0,0,0,0,0,21,0,0,0,0,0,0,0,0,0,0,0,0,0,21,0,0,0,0,0,0,0,0,0,0,0,0,0,0,0,0,0
0,0,0,0,0,0,0,0,0,0,21,0,0,0,0,0,0,0,0,0,0,0,0,0,21,0,0,0,0,0,0,0,0,0,0,0,0,0,0,0,0,0
0,0,0,0,0,0,0,0,0,0,21,0,0,0,0,0,0,0,0,0,0,0,0,0,21,0,0,0,0,0,0,0,0,0,0,0,0,0,0,0,0,0
0,0,0,0,0,0,0,0,0,0,21,0,0,0,0,0,0,0,0,0,0,0,0,0,21,0,0,0,0,0,0,0,0,0,0,0,0,0,0,0,0,0
0,0,0,0,0,0,0,0,0,0,21,0,0,0,0,0,0,56,0,0,0,0,0,0,21,0,0,0,0,0,0,0,0,0,0,0,0,0,0,0,0,0
0,0,0,0,0,0,0,0,0,0,21,0,0,0,24,0,0,0,0,0,0,0,0,0,21,0,25,0,0,0,0,0,0,0,0,0,0,0,0,0,0,0
0,0,0,0,0,0,0,0,0,0,21,0,0,0,0,0,0,0,0,0,0,0,0,0,11,59,11,0,25,0,0,0,0,0,0,0,0,0,0,0,0,0
0,0,0,0,0,0,0,0,0,0,21,0,0,0,0,0,0,0,0,0,0,0,0,0,21,0,0,59,11,2,2,2,2,2,1,0,0,0,0,0,0,0
0,0,0,0,0,0,0,0,0,0,21,0,0,0,0,0,0,0,0,0,0,0,0,0,21,0,0,2,2,2,0,5,0,2,2,2,0,0,0,0,0,0
0,0,0,0,0,0,0,0,0,22,11,21,21,21,21,21,21,21,21,21,21,11,21,21,13,20,1,2,0,0,0,0,0,0,0,2,1,0,0,0,0,0
0,0,0,0,0,0,0,0,0,0,44,0,0,0,0,0,0,5,0,0,0,59,0,0,44,0,2,2,0,0,0,0,0,0,0,2,2,0,0,0,0,0
0,0,0,0,0,0,0,0,0,0,0,0,0,0,0,0,0,0,0,0,29,11,0,0,0,0,2,0,0,0,0,0,0,0,0,0,2,0,0,0,0,0
0,0,0,0,0,0,0,0,0,0,0,0,0,0,0,0,0,0,0,0,0,0,59,0,0,0,2,0,0,0,0,0,0,0,0,0,2,0,0,0,0,0
0,0,0,0,0,0,0,0,0,0,0,0,0,0,0,0,0,0,0,0,0,29,11,59,0,0,2,0,0,0,0,0,0,0,0,0,2,0,0,0,0,0
0,0,0,0,0,0,0,0,0,0,0,0,0,0,0,0,0,0,0,0,0,0,33,0,11,59,11,2,0,0,0,0,0,0,0,2,2,0,0,0,0,0
0,0,0,0,0,0,0,0,0,0,0,0,0,0,0,0,0,0,0,0,0,0,0,0,33,0,1,2,0,0,0,0,0,0,0,2,1,0,0,0,0,0
0,0,0,0,0,0,0,0,0,0,0,0,0,0,0,0,0,0,0,0,0,0,0,0,0,0,0,2,2,2,0,0,0,2,2,2,0,0,0,0,0,0
0,0,0,0,0,0,0,0,0,0,0,0,0,0,0,0,0,0,0,0,0,0,0,0,0,0,0,0,1,2,2,2,2,2,1,0,0,0,0,0,0,0
0,0,0,0,0,0,0,0,0,0,0,0,0,0,0,0,0,0,0,0,0,0,0,0,0,0,0,0,0,0,0,0,0,0,0,0,0,0,0,0,0,0
0,0,0,0,0,0,0,0,0,0,0,0,0,0,0,0,0,0,0,0,0,0,0,0,0,0,0,0,0,0,0,0,0,0,0,0,0,0,0,0,0,0
0,0,0,0,0,0,0,0,0,0,0,0,0,0,0,0,0,0,0,0,0,0,0,0,0,0,0,0,0,0,0,0,0,0,0,0,0,0,0,0,0,0
0,0,0,0,0,0,0,0,0,0,0,0,0,0,0,0,0,0,0,0,0,0,0,0,0,0,0,0,0,0,0,0,0,0,0,0,0,0,0,0,0,0
0,0,0,0,0,0,0,0,0,0,0,0,0,0,0,0,0,0,0,0,0,0,0,0,0,0,0,0,0,0,0,0,0,0,0,0,0,0,0,0,0,0
0,0,0,0,0,0,0,0,0,0,0,0,0,0,0,0,0,0,0,0,0,0,0,0,0,0,0,0,0,0,0,0,0,0,0,0,0,0,0,0,0,0
0,0,0,0,0,0,0,0,0,0,0,0,0,0,0,0,0,0,0,0,0,0,0,0,0,0,0,0,0,0,0,0,0,0,0,0,0,0,0,0,0,0
0,0,0,0,0,0,0,0,0,0,0,0,0,0,0,0,0,0,0,0,0,0,0,0,0,0,0,0,0,0,0,0,0,0,0,0,0,0,0,0,0,0
0,0,0,0,0,0,0,0,0,0,0,0,0,0,0,0,0,0,0,0,0,0,0,0,0,0,0,0,0,0,0,0,0,0,0,0,0,0,0,0,0,0
endlayer

layer
0,0,0,0,0,0,0,0,0,0,0,0,0,0,0,0,0,0,0,0,0,0,0,0,0,0,0,0,0,0,0,0,0,0,0,0,0,0,0,0,0,0
0,0,0,0,0,0,0,0,0,0,0,0,0,0,0,0,0,0,0,0,0,0,0,0,0,0,0,0,0,0,0,0,0,0,0,0,0,0,0,0,0,0
0,0,0,0,0,0,0,0,0,0,0,0,0,0,0,0,0,0,0,0,0,0,0,0,0,0,0,0,0,0,0,0,0,0,0,0,0,0,0,0,0,0
0,0,0,0,0,0,0,0,0,0,19,10,19,0,19,10,19,0,19,10,19,0,19,10,19,0,0,0,0,0,0,0,0,0,0,0,0,0,0,0,0,0
0,0,0,0,0,0,0,0,0,22,11,21,21,35,21,21,21,35,21,21,21,35,21,21,11,20,0,0,0,0,0,0,0,0,0,0,0,0,0,0,0,0
0,0,0,0,0,0,0,0,0,10,21,0,0,0,0,0,0,0,0,57,0,0,0,0,21,10,0,0,0,0,0,0,0,0,0,0,0,0,0,0,0,0
0,0,0,0,0,0,0,0,0,22,21,0,0,0,0,0,0,0,0,0,0,0,0,0,21,20,0,0,0,0,0,0,0,0,0,0,0,0,0,0,0,0
0,0,0,0,0,0,0,0,0,0,36,0,0,0,0,0,0,0,0,0,0,0,0,0,36,0,0,0,0,0,0,0,0,0,0,0,0,0,0,0,0,0
0,0,0,0,0,0,0,0,0,22,21,0,0,0,0,0,0,0,0,0,0,0,0,0,21,20,0,0,0,0,0,0,0,0,0,0,0,0,0,0,0,0
0,0,0,0,0,0,0,0,0,10,21,0,0,0,0,0,0,0,0,0,0,0,0,0,21,10,0,0,0,0,0,0,0,0,0,0,0,0,0,0,0,0
0,0,0,0,0,0,0,0,0,22,21,0,0,0,0,0,0,0,0,0,0,0,0,0,21,20,0,0,0,0,0,0,0,0,0,0,0,0,0,0,0,0
