
# Created by Ruins mod version 1.14.3 Ingame Parser
# authoring Player: maireilla

# TEMPLATE PARAMETER SETTINGS:
#
# criterion expression specifying mod ids required to load template
# may include plus (AND), minus (AND NOT), comma (OR), and parentheses
# all required mods listed must be present; no prohibited mods can be
requiredMods=
#
# likelihood this template will be chosen relative to all others
# e.g., a weight=6 template is chosen 3X as often as one with weight=2
weight=1
#
# list of dimensions in which this template may spawn, even if generic
# one or more dimension names, separated by commas (blank = all)
dimensionsToSpawnIn=overworld
#
# list of other biomes in which this template may spawn
# biome corresponding to directory is always assumed, listed or not
# generic templates should leave this list empty
biomesToSpawnIn=
#
# criterion expression specifying types of biome where template spawns
# this is in addition to those explicitly listed as biomesToSpawnIn
# generic templates should leave this list empty
biomeTypesToSpawnIn=
#
# list of biomes in which this template may not spawn
# takes precedence over biomeTypesToSpawnIn, but NOT biomesToSpawnIn
# should be empty if biomeTypesToSpawnIn is empty
biomesToNotSpawnIn=
#
# depth template is pushed down into the surface when built
# offset is min/max range of random additional bury depth
embed_into_distance=0
random_height_offset=0,0
#
# whitelist/blacklist of block states on which template may be built
# specify one, not both; leave the other empty (both empty = allow all)
# CAUTION: THE DEFAULTS ONLY APPLY TO NON-FLOWING LAVA AND WATER VARIANTS)
acceptable_target_blocks=
unacceptable_target_blocks={Properties:{level:"0"},id:"minecraft:water"},{Properties:{level:"0"},id:"minecraft:lava"}
#
# size of template (#layers, #rows per layer, #blocks per row)
dimensions=16,29,29
#
# max number of missing blocks allowed in surface beneath template
allowable_overhang=0
#
# depth/height limit affected by terrain leveling
# also maximum bumpiness tolerated in surface beneath template
max_leveling=4
#
# padding applied to all sides of template horizontal footprint
# expands area affected by terrain leveling (-1 = no leveling)
leveling_buffer=0
#
# do not rotate template randomly when built (1 = no rotation)
preventRotation=0
#
# treat water/lava blocks as air and protect them from rule0 (1 = yes)
preserve_water=0
preserve_lava=0
#
# minimum distance this template must have from instances of itself
uniqueMinDistance=0
#
# min/max distances this template can be from world spawn (0 = no limit)
# only applies to overworld--i.e., dimension 0
spawnMinDistance=0
spawnMaxDistance=0
#
# other template built nearby whenever this one is
# syntax: <name>;<relativeX>;<maxYdifference>;<relativeZ>[;<chance>]
# may be used more than once to specify multiple neighbors
adjoining_template=

rule1=0,100,{id:"minecraft:brick_wall"}
rule2=0,100,{Properties:{waterlogged:"false",type:"bottom"},id:"minecraft:stone_slab"}
rule3=0,100,{id:"minecraft:bricks"}
rule4=0,100,{id:"minecraft:polished_granite"}
rule5=0,100,{id:"minecraft:brick_wall"}
rule6=0,100,{id:"minecraft:brick_wall"}
rule7=0,100,{id:"minecraft:brick_wall"}
rule8=0,100,{Properties:{half:"top",waterlogged:"false",powered:"false",facing:"west",open:"true"},id:"minecraft:oak_trapdoor"}
rule9=0,100,{id:"minecraft:stone_brick_wall"}
rule10=0,100,{Properties:{axis:"y"},id:"minecraft:quartz_pillar"}
rule11=0,100,{Properties:{axis:"z"},id:"minecraft:quartz_pillar"}
rule12=0,100,{id:"minecraft:stone_brick_wall"}
rule13=0,100,{Properties:{half:"top",waterlogged:"false",powered:"false",facing:"north",open:"true"},id:"minecraft:oak_trapdoor"}
rule14=0,100,{id:"minecraft:smooth_stone"}
rule15=0,100,{Properties:{half:"top",waterlogged:"false",powered:"false",facing:"south",open:"true"},id:"minecraft:oak_trapdoor"}
rule16=0,100,{Properties:{axis:"x"},id:"minecraft:quartz_pillar"}
rule17=0,100,{id:"minecraft:stone_brick_wall"}
rule18=0,100,{id:"minecraft:stone_brick_wall"}
rule19=0,100,{Properties:{half:"top",waterlogged:"false",powered:"false",facing:"east",open:"true"},id:"minecraft:oak_trapdoor"}
rule20=0,100,{id:"minecraft:stone_brick_wall"}
rule21=0,100,{id:"minecraft:brick_wall"}
rule22=0,100,{id:"minecraft:light_gray_concrete"}
rule23=0,100,{id:"minecraft:light_gray_wool"}
rule24=0,100,{id:"minecraft:brick_wall"}
rule25=0,100,{id:"minecraft:stone_brick_wall"}
rule26=0,100,{id:"minecraft:stone_brick_wall"}
rule27=0,100,{Ruins:{entity:{SpawnPotentials:[{weight:1,data:{entity:{id:"minecraft:zombie"}}}]}}, id:"minecraft:spawner"}{Ruins:{entity:{SpawnPotentials:[{weight:1,data:{entity:{id:"minecraft:skeleton"}}}]}}, id:"minecraft:spawner"}{Ruins:{entity:{SpawnPotentials:[{weight:1,data:{entity:{id:"minecraft:spider"}}}]}}, id:"minecraft:spawner"}{Ruins:{entity:{SpawnPotentials:[{weight:1,data:{entity:{id:"minecraft:cave_spider"}}}]}}, id:"minecraft:spawner"}
rule28=0,100,{id:"minecraft:brick_wall"}
rule29=0,100,{id:"minecraft:brick_wall"}
rule30=0,100,{id:"minecraft:stone_brick_wall"}
rule31=0,100,{Properties:{east:"true",waterlogged:"false",south:"false",north:"false",west:"false"},id:"minecraft:dark_oak_fence"}
rule32=0,100,{Properties:{east:"false",waterlogged:"false",south:"true",north:"true",west:"false"},id:"minecraft:black_stained_glass_pane"}
rule33=0,100,{Properties:{east:"false",waterlogged:"false",south:"true",north:"false",west:"false"},id:"minecraft:dark_oak_fence"}
rule34=0,100,{Properties:{east:"false",waterlogged:"false",south:"false",north:"true",west:"false"},id:"minecraft:dark_oak_fence"}
rule35=0,100,{Properties:{east:"true",waterlogged:"false",south:"false",north:"false",west:"true"},id:"minecraft:black_stained_glass_pane"}
rule36=0,100,{Properties:{east:"false",waterlogged:"false",south:"false",north:"false",west:"true"},id:"minecraft:dark_oak_fence"}
rule37=0,100,{Ruins:{entity:{LootTable:"minecraft:chests/simple_dungeon",LootTableSeed:-4494073760637353317L}},Properties:{waterlogged:"false",facing:north,type:"single"},id:"minecraft:chest"}{Ruins:{entity:{LootTable:"minecraft:chests/jungle_temple"}},Properties:{waterlogged:"false",facing:north,type:"single"},id:"minecraft:chest"}{Ruins:{entity:{ForgeData:{LootTable:"minecraft:chests/desert_pyramid"},Items:[],Lock:""}},Properties:{waterlogged:"false",facing:north,type:"single"},id:"minecraft:chest"}
rule38=0,100,{Ruins:{entity:{LootTable:"minecraft:chests/simple_dungeon",LootTableSeed:-4494073760644359517L}},Properties:{waterlogged:"false",facing:north,type:"single"},id:"minecraft:chest"}{Ruins:{entity:{LootTable:"minecraft:chests/jungle_temple"}},Properties:{waterlogged:"false",facing:north,type:"single"},id:"minecraft:chest"}{Ruins:{entity:{ForgeData:{LootTable:"minecraft:chests/desert_pyramid"},Items:[],Lock:""}},Properties:{waterlogged:"false",facing:north,type:"single"},id:"minecraft:chest"}
rule39=0,100,{id:"minecraft:stone_brick_wall"}
rule40=0,100,{Properties:{waterlogged:"false",type:"top"},id:"minecraft:quartz_slab"}
rule41=0,100,{id:"minecraft:smooth_quartz"}
rule42=0,100,{Properties:{waterlogged:"false",type:"bottom"},id:"minecraft:quartz_slab"}
rule43=0,100,{id:"minecraft:stone"}

layer
0,0,0,0,0,0,0,0,0,0,0,0,0,0,0,0,0,0,0,0,0,0,0,0,0,0,0,0,0
0,0,0,1,0,1,0,1,0,1,0,1,0,1,0,1,0,1,0,1,0,1,0,1,0,1,0,0,0
0,2,3,4,4,4,4,4,4,4,4,4,4,4,4,4,4,4,4,4,4,4,4,4,4,4,3,2,0
0,6,4,0,0,0,0,0,0,0,0,0,0,0,0,0,0,0,0,0,0,0,0,0,0,0,4,5,0
0,0,4,0,0,0,0,0,0,0,0,0,0,0,0,0,0,0,0,0,0,0,0,0,0,0,4,0,0
0,6,4,0,0,0,0,0,0,0,0,0,0,0,0,0,0,0,0,0,0,0,0,0,0,0,4,5,0
0,0,4,0,0,0,0,0,0,0,0,0,0,0,0,0,0,0,0,0,0,0,0,0,0,0,4,0,0
0,6,4,0,0,0,0,0,0,0,0,0,0,0,0,0,0,0,0,0,0,0,0,0,0,0,4,5,0
0,0,4,0,0,0,0,0,0,0,0,0,0,0,0,0,0,0,0,0,0,0,0,0,0,0,4,0,0
0,6,4,0,0,0,0,0,0,0,0,0,0,0,0,0,0,0,0,0,0,0,0,0,0,0,4,5,0
0,0,4,0,0,0,0,0,0,0,0,0,0,0,0,0,0,0,0,0,0,0,0,0,0,0,4,0,0
0,6,4,0,0,0,0,0,0,0,0,0,0,0,0,0,0,0,0,0,0,0,0,0,0,0,4,5,0
0,0,4,0,0,0,0,0,0,0,0,0,0,0,0,0,0,0,0,0,0,0,0,0,0,0,4,0,0
0,6,4,0,0,0,0,0,0,0,0,0,0,0,0,0,0,0,0,0,0,0,0,0,0,0,4,5,0
0,0,4,0,0,0,0,0,0,0,0,0,0,0,0,0,0,0,0,0,0,0,0,0,0,0,4,0,0
0,6,4,0,0,0,0,0,0,0,0,0,0,0,0,0,0,0,0,0,0,0,0,0,0,0,4,5,0
0,0,4,0,0,0,0,0,0,0,0,0,0,0,0,0,0,0,0,0,0,0,0,0,0,0,4,0,0
0,6,4,0,0,0,0,0,0,0,0,0,0,0,0,0,0,0,0,0,0,0,0,0,0,0,4,5,0
0,0,4,0,0,0,0,0,0,0,0,0,0,0,0,0,0,0,0,0,0,0,0,0,0,0,4,0,0
0,6,4,0,0,0,0,0,0,0,0,0,0,0,0,0,0,0,0,0,0,0,0,0,0,0,4,5,0
0,0,4,0,0,0,0,0,0,0,0,0,0,0,0,0,0,0,0,0,0,0,0,0,0,0,4,0,0
0,6,4,0,0,0,0,0,0,0,0,0,0,0,0,0,0,0,0,0,0,0,0,0,0,0,4,5,0
0,0,4,0,0,0,0,0,0,0,0,0,0,0,0,0,0,0,0,0,0,0,0,0,0,0,4,0,0
0,6,4,0,0,0,0,0,0,0,0,0,0,0,0,0,0,0,0,0,0,0,0,0,0,0,4,5,0
0,0,4,0,0,0,0,0,0,0,0,0,0,0,0,0,0,0,0,0,0,0,0,0,0,0,4,0,0
0,6,4,0,0,0,0,0,0,0,0,0,0,0,0,0,0,0,0,0,0,0,0,0,0,0,4,5,0
0,2,3,4,4,4,4,4,4,4,4,4,4,4,4,4,4,4,4,4,4,4,4,4,4,4,3,2,0
0,0,0,7,0,7,0,7,0,7,0,7,0,7,0,7,0,7,0,7,0,7,0,7,0,7,0,0,0
0,0,0,0,0,0,0,0,0,0,0,0,0,0,0,0,0,0,0,0,0,0,0,0,0,0,0,0,0
endlayer

layer
0,0,0,0,0,0,0,0,0,0,0,0,0,0,0,0,0,0,0,0,0,0,0,0,0,0,0,0,0
0,0,0,8,8,8,8,8,8,8,8,8,8,8,8,8,8,8,8,8,8,8,8,8,8,8,0,0,0
0,0,12,10,11,10,11,10,11,10,11,10,11,10,11,10,11,10,11,10,11,10,11,10,11,10,9,0,0
0,15,10,14,14,14,14,14,14,14,14,14,14,14,14,14,14,14,14,14,14,14,14,14,14,14,10,13,0
0,15,16,14,14,14,14,14,14,14,14,14,14,14,14,14,14,14,14,14,14,14,14,14,14,14,16,13,0
0,15,10,14,14,14,14,14,14,14,14,14,14,14,14,14,14,14,14,14,14,14,14,14,14,14,10,13,0
0,15,16,14,14,14,14,14,14,14,14,14,14,14,14,14,14,14,14,14,14,14,14,14,14,14,16,13,0
0,15,10,14,14,14,14,14,14,14,14,14,14,14,14,14,14,14,14,14,14,14,14,14,14,14,10,13,0
0,15,16,14,14,14,14,14,14,14,14,14,14,14,14,14,14,14,14,14,14,14,14,14,14,14,16,13,0
0,15,10,14,14,14,14,14,14,14,14,14,14,14,14,14,14,14,14,14,14,14,14,14,14,14,10,13,0
0,15,16,14,14,14,14,14,14,14,14,14,14,14,14,14,14,14,14,14,14,14,14,14,14,14,16,13,0
0,15,10,14,14,14,14,14,14,14,14,14,14,14,14,14,14,14,14,14,14,14,14,14,14,14,10,13,0
0,15,16,14,14,14,14,14,14,14,14,14,14,14,14,14,14,14,14,14,14,14,14,14,14,14,16,13,0
0,15,10,14,14,14,14,14,14,14,14,14,14,14,14,14,14,14,14,14,14,14,14,14,14,14,10,13,0
0,15,16,14,14,14,14,14,14,14,14,14,14,14,14,14,14,14,14,14,14,14,14,14,14,14,16,13,0
0,15,10,14,14,14,14,14,14,14,14,14,14,14,14,14,14,14,14,14,14,14,14,14,14,14,10,13,0
0,15,16,14,14,14,14,14,14,14,14,14,14,14,14,14,14,14,14,14,14,14,14,14,14,14,16,13,0
0,15,10,14,14,14,14,14,14,14,14,14,14,14,14,14,14,14,14,14,14,14,14,14,14,14,10,13,0
0,15,16,14,14,14,14,14,14,14,14,14,14,14,14,14,14,14,14,14,14,14,14,14,14,14,16,13,0
0,15,10,14,14,14,14,14,14,14,14,14,14,14,14,14,14,14,14,14,14,14,14,14,14,14,10,13,0
0,15,16,14,14,14,14,14,14,14,14,14,14,14,14,14,14,14,14,14,14,14,14,14,14,14,16,13,0
0,15,10,14,14,14,14,14,14,14,14,14,14,14,14,14,14,14,14,14,14,14,14,14,14,14,10,13,0
0,15,16,14,14,14,14,14,14,14,14,14,14,14,14,14,14,14,14,14,14,14,14,14,14,14,16,13,0
0,15,10,14,14,14,14,14,14,14,14,14,14,14,14,14,14,14,14,14,14,14,14,14,14,14,10,13,0
0,15,16,14,14,14,14,14,14,14,14,14,14,14,14,14,14,14,14,14,14,14,14,14,14,14,16,13,0
0,15,10,14,14,14,14,14,14,14,14,14,14,14,14,14,14,14,14,14,14,14,14,14,14,14,10,13,0
0,0,18,10,11,10,11,10,11,10,11,10,11,10,11,10,11,10,11,10,11,10,11,10,11,10,17,0,0
0,0,0,19,19,19,19,19,19,19,19,19,19,19,19,19,19,19,19,19,19,19,19,19,19,19,0,0,0
0,0,0,0,0,0,0,0,0,0,0,0,0,0,0,0,0,0,0,0,0,0,0,0,0,0,0,0,0
endlayer

layer
0,0,0,0,0,0,0,0,0,0,0,0,0,0,0,0,0,0,0,0,0,0,0,0,0,0,0,0,0
0,0,0,20,0,20,0,20,0,20,0,20,0,20,0,20,0,20,0,20,0,20,0,20,0,20,0,0,0
0,0,24,22,23,22,23,22,23,22,23,22,23,22,23,22,23,22,23,22,23,22,23,22,23,22,21,0,0
0,26,22,0,0,0,0,0,0,0,0,0,0,0,0,0,0,0,0,0,0,0,0,0,0,0,22,25,0
0,0,23,0,0,0,0,0,0,0,0,0,0,0,0,0,0,0,0,0,0,0,0,0,0,0,23,0,0
0,26,22,0,0,0,0,0,0,0,0,0,0,0,0,0,0,0,0,0,0,0,0,0,0,0,22,25,0
0,0,23,0,0,0,0,0,0,0,0,0,0,0,0,0,0,0,0,0,0,0,0,0,0,0,23,0,0
0,26,22,0,0,0,0,0,0,0,0,0,0,0,0,0,0,0,0,0,0,0,0,0,0,0,22,25,0
0,0,23,0,0,0,0,0,0,0,0,0,0,0,0,0,0,0,0,0,0,0,0,0,0,0,23,0,0
0,26,22,0,0,0,0,0,0,0,0,0,0,0,0,0,0,0,0,0,0,0,0,0,0,0,22,25,0
0,0,23,0,0,0,0,0,0,0,27,0,0,0,0,0,0,0,0,0,0,0,0,0,0,0,23,0,0
0,26,22,0,0,0,0,0,0,0,0,0,0,0,0,0,0,0,0,0,0,0,0,0,0,0,22,25,0
0,0,23,0,0,0,0,0,0,0,0,0,0,0,0,0,0,0,0,0,0,0,0,0,0,0,23,0,0
0,26,22,0,0,0,0,0,0,0,0,0,0,0,0,0,0,0,0,0,0,0,0,0,0,0,22,25,0
0,0,23,0,0,0,0,0,0,0,0,0,0,0,0,0,0,0,0,0,0,0,0,0,0,0,23,0,0
0,26,22,0,0,0,0,0,0,0,0,0,0,0,0,0,0,0,0,0,0,0,0,0,0,0,22,25,0
0,0,23,0,0,0,0,0,0,0,0,0,0,0,0,0,0,0,0,0,0,0,0,0,0,0,23,0,0
0,26,22,0,0,0,0,0,0,0,0,0,0,0,0,0,0,0,0,0,0,0,0,0,0,0,22,25,0
0,0,23,0,0,0,0,0,0,0,0,0,0,0,0,0,0,0,0,0,0,0,0,0,0,0,23,0,0
0,26,22,0,0,0,0,0,0,0,0,0,0,0,0,0,0,0,0,0,0,0,0,0,0,0,22,25,0
0,0,23,0,0,0,0,0,0,0,0,0,0,0,0,0,0,0,0,27,0,0,0,0,0,0,23,0,0
0,26,22,0,0,0,0,0,0,0,0,0,0,0,0,0,0,0,0,0,0,0,0,0,0,0,22,25,0
0,0,23,0,0,0,0,0,0,0,0,0,0,0,0,0,0,0,0,0,0,0,0,0,0,0,23,0,0
0,26,22,0,0,0,0,0,0,0,0,0,0,0,0,0,0,0,0,0,0,0,0,0,0,0,22,25,0
0,0,23,0,0,0,0,0,0,0,0,0,0,0,0,0,0,0,0,0,0,0,0,0,0,0,23,0,0
0,26,22,0,0,0,0,0,0,0,0,0,0,0,0,0,0,0,0,0,0,0,0,0,0,0,22,25,0
0,0,29,22,23,22,23,22,23,22,23,22,23,22,23,22,23,22,23,22,23,22,23,22,23,22,28,0,0
0,0,0,30,0,30,0,30,0,30,0,30,0,30,0,30,0,30,0,30,0,30,0,30,0,30,0,0,0
0,0,0,0,0,0,0,0,0,0,0,0,0,0,0,0,0,0,0,0,0,0,0,0,0,0,0,0,0
endlayer

layer
0,0,0,0,0,0,0,0,0,0,0,0,0,0,0,0,0,0,0,0,0,0,0,0,0,0,0,0,0
0,0,0,31,0,31,0,31,0,31,0,31,0,31,0,31,0,31,0,31,0,31,0,31,0,31,0,0,0
0,0,24,22,32,22,32,22,32,22,32,22,32,22,32,22,32,22,32,22,32,22,32,22,32,22,21,0,0
0,34,22,0,0,0,0,0,0,0,0,0,0,0,0,0,0,0,0,0,0,0,0,0,0,0,22,33,0
0,0,35,0,0,0,0,0,0,0,0,0,0,0,0,0,0,0,0,0,0,0,0,0,0,0,35,0,0
0,34,22,0,0,0,0,0,0,0,0,0,0,0,0,0,0,0,0,0,0,0,0,0,0,0,22,33,0
0,0,35,0,0,0,0,0,0,0,0,0,0,0,0,0,0,0,0,0,0,0,0,0,0,0,35,0,0
0,34,22,0,0,0,0,0,0,0,0,0,0,0,0,0,0,0,0,0,0,0,0,0,0,0,22,33,0
0,0,35,0,0,0,0,0,0,0,0,0,0,0,0,0,0,0,0,0,0,0,0,0,0,0,35,0,0
0,34,22,0,0,0,0,0,0,0,0,0,0,0,0,0,0,0,0,0,0,0,0,0,0,0,22,33,0
0,0,35,0,0,0,0,0,0,0,0,0,0,0,0,0,0,0,0,0,0,0,0,0,0,0,35,0,0
0,34,22,0,0,0,0,0,0,0,0,0,0,0,0,0,0,0,0,0,0,0,0,0,0,0,22,33,0
0,0,35,0,0,0,0,0,0,0,0,0,0,0,0,0,0,0,0,0,0,0,0,0,0,0,35,0,0
0,34,22,0,0,0,0,0,0,0,0,0,0,0,0,0,0,0,0,0,0,0,0,0,0,0,22,33,0
0,0,35,0,0,0,0,0,0,0,0,0,0,0,0,0,0,0,0,0,0,0,0,0,0,0,35,0,0
0,34,22,0,0,0,0,0,0,0,0,0,0,0,0,0,0,0,0,0,0,0,0,0,0,0,22,33,0
0,0,35,0,0,0,0,0,0,0,0,0,0,0,0,0,0,0,0,0,0,0,0,0,0,0,35,0,0
0,34,22,0,0,0,0,0,0,0,0,0,0,0,0,0,0,0,0,0,0,0,0,0,0,0,22,33,0
0,0,35,0,0,0,0,0,0,0,0,0,0,0,0,0,0,0,0,0,0,0,0,0,0,0,35,0,0
0,34,22,0,0,0,0,0,0,0,0,0,0,0,0,0,0,0,0,0,0,0,0,0,0,0,22,33,0
0,0,35,0,0,0,0,0,0,0,0,0,0,0,0,0,0,0,0,0,0,0,0,0,0,0,35,0,0
0,34,22,0,0,0,0,0,0,0,0,0,0,0,0,0,0,0,0,0,0,0,0,0,0,0,22,33,0
0,0,35,0,0,0,0,0,0,0,0,0,0,0,0,0,0,0,0,0,0,0,0,0,0,0,35,0,0
0,34,22,0,0,0,0,0,0,0,0,0,0,0,0,0,0,0,0,0,0,0,0,0,0,0,22,33,0
0,0,35,0,0,0,0,0,0,0,0,0,0,0,0,0,0,0,0,0,0,0,0,0,0,0,35,0,0
0,34,22,0,0,0,0,0,0,0,0,0,0,0,0,0,0,0,0,0,0,0,0,0,0,0,22,33,0
0,0,29,22,32,22,32,22,32,22,32,22,32,22,32,22,32,22,32,22,32,22,32,22,32,22,28,0,0
0,0,0,36,0,36,0,36,0,36,0,36,0,36,0,36,0,36,0,36,0,36,0,36,0,36,0,0,0
0,0,0,0,0,0,0,0,0,0,0,0,0,0,0,0,0,0,0,0,0,0,0,0,0,0,0,0,0
endlayer

layer
0,0,0,0,0,0,0,0,0,0,0,0,0,0,0,0,0,0,0,0,0,0,0,0,0,0,0,0,0
0,0,0,20,0,20,0,20,0,20,0,20,0,20,0,20,0,20,0,20,0,20,0,20,0,20,0,0,0
0,0,24,22,32,22,32,22,32,22,32,22,32,22,32,22,32,22,32,22,32,22,32,22,32,22,21,0,0
0,26,22,0,0,0,0,0,0,0,0,0,0,0,0,0,0,0,0,0,0,0,0,0,0,0,22,25,0
0,0,35,0,0,0,0,0,0,0,0,0,0,0,0,0,0,0,0,0,0,0,0,0,0,0,35,0,0
0,26,22,0,0,0,0,0,0,0,0,0,0,0,0,0,0,0,0,0,0,0,0,0,0,0,22,25,0
0,0,35,0,0,0,0,0,0,0,0,0,0,0,0,0,0,0,0,0,0,0,0,0,0,0,35,0,0
0,26,22,0,0,0,0,0,0,0,0,0,0,0,0,0,0,0,0,0,0,0,0,0,0,0,22,25,0
0,0,35,0,0,0,0,0,0,0,0,0,0,0,0,0,0,0,0,0,0,0,0,0,0,0,35,0,0
0,26,22,0,0,0,0,0,0,0,0,0,0,0,0,0,0,0,0,0,0,0,0,0,0,0,22,25,0
0,0,35,0,0,0,0,0,0,0,0,0,0,0,0,0,0,0,0,0,0,0,0,0,0,0,35,0,0
0,26,22,0,0,0,0,0,0,0,0,0,0,0,0,0,0,0,0,0,0,0,0,0,0,0,22,25,0
0,0,35,0,0,0,0,0,0,0,0,0,0,0,0,0,0,0,0,0,0,0,0,0,0,0,35,0,0
0,26,22,0,0,0,0,0,0,0,0,0,0,0,0,0,0,0,0,0,0,0,0,0,0,0,22,25,0
0,0,35,0,0,0,0,0,0,0,0,0,0,0,0,0,0,0,0,0,0,0,0,0,0,0,35,0,0
0,26,22,0,0,0,0,0,0,0,0,0,0,0,0,0,0,0,0,0,0,0,0,0,0,0,22,25,0
0,0,35,0,0,0,0,0,0,0,0,0,0,0,0,0,0,0,0,0,0,0,0,0,0,0,35,0,0
0,26,22,0,0,0,0,0,0,0,0,0,0,0,0,0,0,0,0,0,0,0,0,0,0,0,22,25,0
0,0,35,0,0,0,0,0,0,0,0,0,0,0,0,0,0,0,0,0,0,0,0,0,0,0,35,0,0
0,26,22,0,0,0,0,0,0,0,0,0,0,0,0,0,0,0,0,0,0,0,0,0,0,0,22,25,0
0,0,35,0,0,0,0,0,0,0,0,0,0,0,0,0,0,0,0,0,0,0,0,0,0,0,35,0,0
0,26,22,0,0,0,0,0,0,0,0,0,0,0,0,0,0,0,0,0,0,0,0,0,0,0,22,25,0
0,0,35,0,0,0,0,0,0,0,0,0,0,0,0,0,0,0,0,0,0,0,0,0,0,0,35,0,0
0,26,22,0,0,0,0,0,0,0,0,0,0,0,0,0,0,0,0,0,0,0,0,0,0,0,22,25,0
0,0,35,0,0,0,0,0,0,0,0,0,0,0,0,0,0,0,0,0,0,0,0,0,0,0,35,0,0
0,26,22,0,0,0,0,0,0,0,0,0,0,0,0,0,0,0,0,0,0,0,0,0,0,0,22,25,0
0,0,29,22,32,22,32,22,32,22,32,22,32,22,32,22,32,22,32,22,32,22,32,22,32,22,28,0,0
0,0,0,30,0,30,0,30,0,30,0,30,0,30,0,30,0,30,0,30,0,30,0,30,0,30,0,0,0
0,0,0,0,0,0,0,0,0,0,0,0,0,0,0,0,0,0,0,0,0,0,0,0,0,0,0,0,0
endlayer

layer
0,0,0,0,0,0,0,0,0,0,0,0,0,0,0,0,0,0,0,0,0,0,0,0,0,0,0,0,0
0,0,0,22,8,22,8,22,8,22,8,22,8,22,8,22,8,22,8,22,8,22,8,22,8,22,0,0,0
0,0,24,22,23,22,23,22,23,22,23,22,23,22,23,22,23,22,23,22,23,22,23,22,23,22,21,0,0
0,22,22,14,14,14,14,14,14,14,14,14,14,14,14,14,14,14,14,14,14,14,14,14,14,14,22,22,0
0,15,23,14,14,14,14,14,14,14,14,14,14,14,14,14,14,14,14,14,14,14,14,14,14,14,23,13,0
0,22,22,14,14,14,14,14,14,14,14,14,14,14,14,14,14,14,14,14,14,14,14,14,14,14,22,22,0
0,15,23,14,14,14,14,14,14,14,14,14,14,14,14,14,14,14,14,14,14,14,14,14,14,14,23,13,0
0,22,22,14,14,14,14,14,14,14,14,14,14,14,14,14,14,14,14,14,14,14,14,14,14,14,22,22,0
0,15,23,14,14,14,14,14,14,14,14,14,14,14,14,14,14,14,14,14,14,14,14,14,14,14,23,13,0
0,22,22,14,14,14,14,14,14,14,14,14,14,14,14,14,14,14,14,14,14,14,14,14,14,14,22,22,0
0,15,23,14,14,14,14,14,14,14,14,14,14,14,14,14,14,14,14,14,14,14,14,14,14,14,23,13,0
0,22,22,14,14,14,14,14,14,14,14,14,14,14,14,14,14,14,14,14,14,14,14,14,14,14,22,22,0
0,15,23,14,14,14,14,14,14,14,14,14,14,14,14,14,14,14,14,14,14,14,14,14,14,14,23,13,0
0,22,22,14,14,14,14,14,14,14,14,14,14,14,14,14,14,14,14,14,14,14,14,14,14,14,22,22,0
0,15,23,14,14,14,14,14,14,14,14,14,14,14,14,14,14,14,14,14,14,14,14,14,14,14,23,13,0
0,22,22,14,14,14,14,14,14,14,14,14,14,14,14,14,14,14,14,14,14,14,14,14,14,14,22,22,0
0,15,23,14,14,14,14,14,14,14,14,14,14,14,14,14,14,14,14,14,14,14,14,14,14,14,23,13,0
0,22,22,14,14,14,14,14,14,14,14,14,14,14,14,14,14,14,14,14,14,14,14,14,14,14,22,22,0
0,15,23,14,14,14,14,14,14,14,14,14,14,14,14,14,14,14,14,14,14,14,14,14,14,14,23,13,0
0,22,22,14,14,14,14,14,14,14,14,14,14,14,14,14,14,14,14,14,14,14,14,14,14,14,22,22,0
0,15,23,14,14,14,14,14,14,14,14,14,14,14,14,14,14,14,14,14,14,14,14,14,14,14,23,13,0
0,22,22,14,14,14,14,14,14,14,14,14,14,14,14,14,14,14,14,14,14,14,14,14,14,14,22,22,0
0,15,23,14,14,14,14,14,14,14,14,14,14,14,14,14,14,14,14,14,14,14,14,14,14,14,23,13,0
0,22,22,14,14,14,14,14,14,14,14,14,14,14,14,14,14,14,14,14,14,14,14,14,14,14,22,22,0
0,15,23,14,14,14,14,14,14,14,14,14,14,14,14,14,14,14,14,14,14,14,14,14,14,14,23,13,0
0,22,22,14,14,14,14,14,14,14,14,14,14,14,14,14,14,14,14,14,14,14,14,14,14,14,22,22,0
0,0,29,22,23,22,23,22,23,22,23,22,23,22,23,22,23,22,23,22,23,22,23,22,23,22,28,0,0
0,0,0,22,19,22,19,22,19,22,19,22,19,22,19,22,19,22,19,22,19,22,19,22,19,22,0,0,0
0,0,0,0,0,0,0,0,0,0,0,0,0,0,0,0,0,0,0,0,0,0,0,0,0,0,0,0,0
endlayer

layer
0,0,0,0,0,0,0,0,0,0,0,0,0,0,0,0,0,0,0,0,0,0,0,0,0,0,0,0,0
0,0,0,20,0,20,0,20,0,20,0,20,0,20,0,20,0,20,0,20,0,20,0,20,0,20,0,0,0
0,0,24,22,23,22,23,22,23,22,23,22,23,22,23,22,23,22,23,22,23,22,23,22,23,22,21,0,0
0,26,22,0,0,0,0,0,0,0,0,0,0,0,0,0,0,0,0,0,0,0,0,0,0,0,22,25,0
0,0,23,0,0,0,0,0,0,0,0,0,0,0,0,0,0,0,0,0,0,0,0,0,0,0,23,0,0
0,26,22,0,0,0,0,0,0,0,0,0,0,0,0,0,0,0,0,0,0,0,0,0,0,0,22,25,0
0,0,23,0,0,0,0,0,0,0,0,0,0,0,0,0,0,0,0,0,0,0,0,0,0,0,23,0,0
0,26,22,0,0,0,0,0,0,0,0,0,0,0,0,0,0,0,0,0,0,0,0,0,0,0,22,25,0
0,0,23,0,0,0,0,0,0,0,0,0,0,0,0,0,0,0,0,0,0,0,0,0,0,0,23,0,0
0,26,22,0,0,0,0,0,0,0,0,0,0,0,0,0,0,0,0,0,0,0,0,0,0,0,22,25,0
0,0,23,0,0,0,0,0,0,0,0,0,0,0,0,0,0,0,0,0,0,0,0,0,0,0,23,0,0
0,26,22,0,0,0,0,0,0,0,0,0,0,0,0,0,0,0,0,37,0,0,0,0,0,0,22,25,0
0,0,23,0,0,0,0,0,27,0,0,0,0,0,0,0,0,0,0,0,0,0,0,0,0,0,23,0,0
0,26,22,0,0,0,0,0,0,0,0,0,0,0,0,0,0,0,0,0,0,0,0,0,0,0,22,25,0
0,0,23,0,0,0,0,0,0,0,0,0,0,0,0,0,0,0,0,0,0,0,0,0,0,0,23,0,0
0,26,22,0,0,0,0,0,0,0,0,0,0,0,0,0,0,0,0,0,0,0,0,0,0,0,22,25,0
0,0,23,0,0,0,0,0,0,0,0,0,0,0,0,0,0,0,0,0,0,0,0,0,0,0,23,0,0
0,26,22,0,0,0,0,0,0,0,0,0,0,0,0,0,0,0,0,27,0,0,0,0,0,0,22,25,0
0,0,23,0,0,0,0,0,0,38,0,0,0,0,0,0,0,0,0,0,0,0,0,0,0,0,23,0,0
0,26,22,0,0,0,0,0,0,0,0,0,0,0,0,0,0,0,0,0,0,0,0,0,0,0,22,25,0
0,0,23,0,0,0,0,0,0,0,0,0,0,0,0,0,0,0,0,0,0,0,0,0,0,0,23,0,0
0,26,22,0,0,0,0,0,0,0,0,0,0,0,0,0,0,0,0,0,0,0,0,0,0,0,22,25,0
0,0,23,0,0,0,0,0,0,0,0,0,0,0,0,0,0,0,0,0,0,0,0,0,0,0,23,0,0
0,26,22,0,0,0,0,0,0,0,0,0,0,0,0,0,0,0,0,0,0,0,0,0,0,0,22,25,0
0,0,23,0,0,0,0,0,0,0,0,0,0,0,0,0,0,0,0,0,0,0,0,0,0,0,23,0,0
0,26,22,0,0,0,0,0,0,0,0,0,0,0,0,0,0,0,0,0,0,0,0,0,0,0,22,25,0
0,0,29,22,23,22,23,22,23,22,23,22,23,22,23,22,23,22,23,22,23,22,23,22,23,22,28,0,0
0,0,0,30,0,30,0,30,0,30,0,30,0,30,0,30,0,30,0,30,0,30,0,30,0,30,0,0,0
0,0,0,0,0,0,0,0,0,0,0,0,0,0,0,0,0,0,0,0,0,0,0,0,0,0,0,0,0
endlayer

layer
0,0,0,0,0,0,0,0,0,0,0,0,0,0,0,0,0,0,0,0,0,0,0,0,0,0,0,0,0
0,0,0,31,0,31,0,31,0,31,0,31,0,31,0,31,0,31,0,31,0,31,0,31,0,31,0,0,0
0,0,24,22,32,22,32,22,32,22,32,22,32,22,32,22,32,22,32,22,32,22,32,22,32,22,21,0,0
0,34,22,0,0,0,0,0,0,0,0,0,0,0,0,0,0,0,0,0,0,0,0,0,0,0,22,33,0
0,0,35,0,0,0,0,0,0,0,0,0,0,0,0,0,0,0,0,0,0,0,0,0,0,0,35,0,0
0,34,22,0,0,0,0,0,0,0,0,0,0,0,0,0,0,0,0,0,0,0,0,0,0,0,22,33,0
0,0,35,0,0,0,0,0,0,0,0,0,0,0,0,0,0,0,0,0,0,0,0,0,0,0,35,0,0
0,34,22,0,0,0,0,0,0,0,0,0,0,0,0,0,0,0,0,0,0,0,0,0,0,0,22,33,0
0,0,35,0,0,0,0,0,0,0,0,0,0,0,0,0,0,0,0,0,0,0,0,0,0,0,35,0,0
0,34,22,0,0,0,0,0,0,0,0,0,0,0,0,0,0,0,0,0,0,0,0,0,0,0,22,33,0
0,0,35,0,0,0,0,0,0,0,0,0,0,0,0,0,0,0,0,0,0,0,0,0,0,0,35,0,0
0,34,22,0,0,0,0,0,0,0,0,0,0,0,0,0,0,0,0,0,0,0,0,0,0,0,22,33,0
0,0,35,0,0,0,0,0,0,0,0,0,0,0,0,0,0,0,0,0,0,0,0,0,0,0,35,0,0
0,34,22,0,0,0,0,0,0,0,0,0,0,0,0,0,0,0,0,0,0,0,0,0,0,0,22,33,0
0,0,35,0,0,0,0,0,0,0,0,0,0,0,0,0,0,0,0,0,0,0,0,0,0,0,35,0,0
0,34,22,0,0,0,0,0,0,0,0,0,0,0,0,0,0,0,0,0,0,0,0,0,0,0,22,33,0
0,0,35,0,0,0,0,0,0,0,0,0,0,0,0,0,0,0,0,0,0,0,0,0,0,0,35,0,0
0,34,22,0,0,0,0,0,0,0,0,0,0,0,0,0,0,0,0,0,0,0,0,0,0,0,22,33,0
0,0,35,0,0,0,0,0,0,0,0,0,0,0,0,0,0,0,0,0,0,0,0,0,0,0,35,0,0
0,34,22,0,0,0,0,0,0,0,0,0,0,0,0,0,0,0,0,0,0,0,0,0,0,0,22,33,0
0,0,35,0,0,0,0,0,0,0,0,0,0,0,0,0,0,0,0,0,0,0,0,0,0,0,35,0,0
0,34,22,0,0,0,0,0,0,0,0,0,0,0,0,0,0,0,0,0,0,0,0,0,0,0,22,33,0
0,0,35,0,0,0,0,0,0,0,0,0,0,0,0,0,0,0,0,0,0,0,0,0,0,0,35,0,0
0,34,22,0,0,0,0,0,0,0,0,0,0,0,0,0,0,0,0,0,0,0,0,0,0,0,22,33,0
0,0,35,0,0,0,0,0,0,0,0,0,0,0,0,0,0,0,0,0,0,0,0,0,0,0,35,0,0
0,34,22,0,0,0,0,0,0,0,0,0,0,0,0,0,0,0,0,0,0,0,0,0,0,0,22,33,0
0,0,29,22,32,22,32,22,32,22,32,22,32,22,32,22,32,22,32,22,32,22,32,22,32,22,28,0,0
0,0,0,36,0,36,0,36,0,36,0,36,0,36,0,36,0,36,0,36,0,36,0,36,0,36,0,0,0
0,0,0,0,0,0,0,0,0,0,0,0,0,0,0,0,0,0,0,0,0,0,0,0,0,0,0,0,0
endlayer

layer
0,0,0,0,0,0,0,0,0,0,0,0,0,0,0,0,0,0,0,0,0,0,0,0,0,0,0,0,0
0,0,0,20,0,20,0,20,0,20,0,20,0,20,0,20,0,20,0,20,0,20,0,20,0,20,0,0,0
0,0,24,22,32,22,32,22,32,22,32,22,32,22,32,22,32,22,32,22,32,22,32,22,32,22,21,0,0
0,26,22,0,0,0,0,0,0,0,0,0,0,0,0,0,0,0,0,0,0,0,0,0,0,0,22,25,0
0,0,35,0,0,0,0,0,0,0,0,0,0,0,0,0,0,0,0,0,0,0,0,0,0,0,35,0,0
0,26,22,0,0,0,0,0,0,0,0,0,0,0,0,0,0,0,0,0,0,0,0,0,0,0,22,25,0
0,0,35,0,0,0,0,0,0,0,0,0,0,0,0,0,0,0,0,0,0,0,0,0,0,0,35,0,0
0,26,22,0,0,0,0,0,0,0,0,0,0,0,0,0,0,0,0,0,0,0,0,0,0,0,22,25,0
0,0,35,0,0,0,0,0,0,0,0,0,0,0,0,0,0,0,0,0,0,0,0,0,0,0,35,0,0
0,26,22,0,0,0,0,0,0,0,0,0,0,0,0,0,0,0,0,0,0,0,0,0,0,0,22,25,0
0,0,35,0,0,0,0,0,0,0,0,0,0,0,0,0,0,0,0,0,0,0,0,0,0,0,35,0,0
0,26,22,0,0,0,0,0,0,0,0,0,0,0,0,0,0,0,0,0,0,0,0,0,0,0,22,25,0
0,0,35,0,0,0,0,0,0,0,0,0,0,0,0,0,0,0,0,0,0,0,0,0,0,0,35,0,0
0,26,22,0,0,0,0,0,0,0,0,0,0,0,0,0,0,0,0,0,0,0,0,0,0,0,22,25,0
0,0,35,0,0,0,0,0,0,0,0,0,0,0,0,0,0,0,0,0,0,0,0,0,0,0,35,0,0
0,26,22,0,0,0,0,0,0,0,0,0,0,0,0,0,0,0,0,0,0,0,0,0,0,0,22,25,0
0,0,35,0,0,0,0,0,0,0,0,0,0,0,0,0,0,0,0,0,0,0,0,0,0,0,35,0,0
0,26,22,0,0,0,0,0,0,0,0,0,0,0,0,0,0,0,0,0,0,0,0,0,0,0,22,25,0
0,0,35,0,0,0,0,0,0,0,0,0,0,0,0,0,0,0,0,0,0,0,0,0,0,0,35,0,0
0,26,22,0,0,0,0,0,0,0,0,0,0,0,0,0,0,0,0,0,0,0,0,0,0,0,22,25,0
0,0,35,0,0,0,0,0,0,0,0,0,0,0,0,0,0,0,0,0,0,0,0,0,0,0,35,0,0
0,26,22,0,0,0,0,0,0,0,0,0,0,0,0,0,0,0,0,0,0,0,0,0,0,0,22,25,0
0,0,35,0,0,0,0,0,0,0,0,0,0,0,0,0,0,0,0,0,0,0,0,0,0,0,35,0,0
0,26,22,0,0,0,0,0,0,0,0,0,0,0,0,0,0,0,0,0,0,0,0,0,0,0,22,25,0
0,0,35,0,0,0,0,0,0,0,0,0,0,0,0,0,0,0,0,0,0,0,0,0,0,0,35,0,0
0,26,22,0,0,0,0,0,0,0,0,0,0,0,0,0,0,0,0,0,0,0,0,0,0,0,22,25,0
0,0,29,22,32,22,32,22,32,22,32,22,32,22,32,22,32,22,32,22,32,22,32,22,32,22,28,0,0
0,0,0,30,0,30,0,30,0,30,0,30,0,30,0,30,0,30,0,30,0,30,0,30,0,30,0,0,0
0,0,0,0,0,0,0,0,0,0,0,0,0,0,0,0,0,0,0,0,0,0,0,0,0,0,0,0,0
endlayer

layer
0,0,0,0,0,0,0,0,0,0,0,0,0,0,0,0,0,0,0,0,0,0,0,0,0,0,0,0,0
0,0,0,22,8,22,8,22,8,22,8,22,8,22,8,22,8,22,8,22,8,22,8,22,8,22,0,0,0
0,0,24,22,23,22,23,22,23,22,23,22,23,22,23,22,23,22,23,22,23,22,23,22,23,22,21,0,0
0,22,22,14,14,14,14,14,14,14,14,14,14,14,14,14,14,14,14,14,14,14,14,14,14,14,22,22,0
0,15,23,14,14,14,14,14,14,14,14,14,14,14,14,14,14,14,14,14,14,14,14,14,14,14,23,13,0
0,22,22,14,14,14,14,14,14,14,14,14,14,14,14,14,14,14,14,14,14,14,14,14,14,14,22,22,0
0,15,23,14,14,14,14,14,14,14,14,14,14,14,14,14,14,14,14,14,14,14,14,14,14,14,23,13,0
0,22,22,14,14,14,14,14,14,14,14,14,14,14,14,14,14,14,14,14,14,14,14,14,14,14,22,22,0
0,15,23,14,14,14,14,14,14,14,14,14,14,14,14,14,14,14,14,14,14,14,14,14,14,14,23,13,0
0,22,22,14,14,14,14,14,14,14,14,14,14,14,14,14,14,14,14,14,14,14,14,14,14,14,22,22,0
0,15,23,14,14,14,14,14,14,14,14,14,14,14,14,14,14,14,14,14,14,14,14,14,14,14,23,13,0
0,22,22,14,14,14,14,14,14,14,14,14,14,14,14,14,14,14,14,14,14,14,14,14,14,14,22,22,0
0,15,23,14,14,14,14,14,14,14,14,14,14,14,14,14,14,14,14,14,14,14,14,14,14,14,23,13,0
0,22,22,14,14,14,14,14,14,14,14,14,14,14,14,14,14,14,14,14,14,14,14,14,14,14,22,22,0
0,15,23,14,14,14,14,14,14,14,14,14,14,14,14,14,14,14,14,14,14,14,14,14,14,14,23,13,0
0,22,22,14,14,14,14,14,14,14,14,14,14,14,14,14,14,14,14,14,14,14,14,14,14,14,22,22,0
0,15,23,14,14,14,14,14,14,14,14,14,14,14,14,14,14,14,14,14,14,14,14,14,14,14,23,13,0
0,22,22,14,14,14,14,14,14,14,14,14,14,14,14,14,14,14,14,14,14,14,14,14,14,14,22,22,0
0,15,23,14,14,14,14,14,14,14,14,14,14,14,14,14,14,14,14,14,14,14,14,14,14,14,23,13,0
0,22,22,14,14,14,14,14,14,14,14,14,14,14,14,14,14,14,14,14,14,14,14,14,14,14,22,22,0
0,15,23,14,14,14,14,14,14,14,14,14,14,14,14,14,14,14,14,14,14,14,14,14,14,14,23,13,0
0,22,22,14,14,14,14,14,14,14,14,14,14,14,14,14,14,14,14,14,14,14,14,14,14,14,22,22,0
0,15,23,14,14,14,14,14,14,14,14,14,14,14,14,14,14,14,14,14,14,14,14,14,14,14,23,13,0
0,22,22,14,14,14,14,14,14,14,14,14,14,14,14,14,14,14,14,14,14,14,14,14,14,14,22,22,0
0,15,23,14,14,14,14,14,14,14,14,14,14,14,14,14,14,14,14,14,14,14,14,14,14,14,23,13,0
0,22,22,14,14,14,14,14,14,14,14,14,14,14,14,14,14,14,14,14,14,14,14,14,14,14,22,22,0
0,0,29,22,23,22,23,22,23,22,23,22,23,22,23,22,23,22,23,22,23,22,23,22,23,22,28,0,0
0,0,0,22,19,22,19,22,19,22,19,22,19,22,19,22,19,22,19,22,19,22,19,22,19,22,0,0,0
0,0,0,0,0,0,0,0,0,0,0,0,0,0,0,0,0,0,0,0,0,0,0,0,0,0,0,0,0
endlayer

layer
0,0,0,0,0,0,0,0,0,0,0,0,0,0,0,0,0,0,0,0,0,0,0,0,0,0,0,0,0
0,0,0,20,0,20,0,20,0,20,0,20,0,20,0,20,0,20,0,20,0,20,0,20,0,20,0,0,0
0,0,24,22,23,22,23,22,23,22,23,22,23,22,23,22,23,22,23,22,23,22,23,22,23,22,21,0,0
0,26,22,0,0,0,0,0,0,0,0,0,0,0,0,0,0,0,0,0,0,0,0,0,0,0,22,25,0
0,0,23,0,0,0,0,0,0,0,0,0,0,0,0,0,0,0,0,0,0,0,0,0,0,0,23,0,0
0,26,22,0,0,0,0,0,0,0,0,0,0,0,0,0,0,0,0,0,0,0,0,0,0,0,22,25,0
0,0,23,0,0,0,0,0,0,0,0,0,0,0,0,0,0,0,0,0,0,0,0,0,0,0,23,0,0
0,26,22,0,0,0,0,0,0,0,0,0,0,0,0,0,0,0,0,0,0,0,0,0,0,0,22,25,0
0,0,23,0,0,0,0,0,0,0,0,0,0,0,0,0,0,0,0,0,0,0,0,0,0,0,23,0,0
0,26,22,0,0,0,0,0,0,0,0,0,0,0,0,0,0,0,0,0,0,0,0,37,0,0,22,25,0
0,0,23,0,0,0,0,0,0,0,0,0,0,0,0,0,0,0,0,0,0,0,0,0,0,0,23,0,0
0,26,22,0,0,0,0,0,0,0,0,0,0,0,0,0,0,0,0,0,0,0,0,0,0,0,22,25,0
0,0,23,0,0,0,0,0,0,0,0,0,0,0,0,0,0,0,0,0,0,0,0,0,0,0,23,0,0
0,26,22,0,0,0,0,0,0,27,0,0,0,0,0,0,0,0,0,0,0,0,0,0,0,0,22,25,0
0,0,23,0,0,0,0,0,0,0,0,0,0,0,0,0,0,0,0,0,0,0,0,0,0,0,23,0,0
0,26,22,0,0,0,0,0,0,0,0,0,0,0,0,0,0,0,0,0,0,0,0,0,0,0,22,25,0
0,0,23,0,0,0,0,0,0,0,0,0,0,0,0,0,0,0,0,0,0,0,0,0,0,0,23,0,0
0,26,22,0,0,0,0,0,0,0,0,0,0,0,0,0,0,0,0,0,0,0,0,0,0,0,22,25,0
0,0,23,0,0,0,0,0,0,0,0,0,0,0,0,0,0,27,0,0,0,0,0,0,0,0,23,0,0
0,26,22,0,0,0,0,0,0,0,0,0,0,0,0,0,0,0,0,0,0,0,0,0,0,0,22,25,0
0,0,23,0,0,0,0,0,0,38,0,0,0,0,0,0,0,0,0,0,0,0,0,0,0,0,23,0,0
0,26,22,0,0,0,0,0,0,0,0,0,0,0,0,0,0,0,0,0,0,0,0,0,0,0,22,25,0
0,0,23,0,0,0,0,0,0,0,0,0,0,0,0,0,0,0,0,0,0,0,0,0,0,0,23,0,0
0,26,22,0,0,0,0,0,0,0,0,0,0,0,0,0,0,0,0,0,0,0,0,0,0,0,22,25,0
0,0,23,0,0,0,0,0,0,0,0,0,0,0,0,0,0,0,0,0,0,0,0,0,0,0,23,0,0
0,26,22,0,0,0,0,0,0,0,0,0,0,0,0,0,0,0,0,0,0,0,0,0,0,0,22,25,0
0,0,29,22,23,22,23,22,23,22,23,22,23,22,23,22,23,22,23,22,23,22,23,22,23,22,28,0,0
0,0,0,30,0,30,0,30,0,30,0,30,0,30,0,30,0,30,0,30,0,30,0,30,0,30,0,0,0
0,0,0,0,0,0,0,0,0,0,0,0,0,0,0,0,0,0,0,0,0,0,0,0,0,0,0,0,0
endlayer

layer
0,0,0,0,0,0,0,0,0,0,0,0,0,0,0,0,0,0,0,0,0,0,0,0,0,0,0,0,0
0,0,0,31,0,31,0,31,0,31,0,31,0,31,0,31,0,31,0,31,0,31,0,31,0,31,0,0,0
0,0,24,22,32,22,32,22,32,22,32,22,32,22,32,22,32,22,32,22,32,22,32,22,32,22,21,0,0
0,34,22,0,0,0,0,0,0,0,0,0,0,0,0,0,0,0,0,0,0,0,0,0,0,0,22,33,0
0,0,35,0,0,0,0,0,0,0,0,0,0,0,0,0,0,0,0,0,0,0,0,0,0,0,35,0,0
0,34,22,0,0,0,0,0,0,0,0,0,0,0,0,0,0,0,0,0,0,0,0,0,0,0,22,33,0
0,0,35,0,0,0,0,0,0,0,0,0,0,0,0,0,0,0,0,0,0,0,0,0,0,0,35,0,0
0,34,22,0,0,0,0,0,0,0,0,0,0,0,0,0,0,0,0,0,0,0,0,0,0,0,22,33,0
0,0,35,0,0,0,0,0,0,0,0,0,0,0,0,0,0,0,0,0,0,0,0,0,0,0,35,0,0
0,34,22,0,0,0,0,0,0,0,0,0,0,0,0,0,0,0,0,0,0,0,0,0,0,0,22,33,0
0,0,35,0,0,0,0,0,0,0,0,0,0,0,0,0,0,0,0,0,0,0,0,0,0,0,35,0,0
0,34,22,0,0,0,0,0,0,0,0,0,0,0,0,0,0,0,0,0,0,0,0,0,0,0,22,33,0
0,0,35,0,0,0,0,0,0,0,0,0,0,0,0,0,0,0,0,0,0,0,0,0,0,0,35,0,0
0,34,22,0,0,0,0,0,0,0,0,0,0,0,0,0,0,0,0,0,0,0,0,0,0,0,22,33,0
0,0,35,0,0,0,0,0,0,0,0,0,0,0,0,0,0,0,0,0,0,0,0,0,0,0,35,0,0
0,34,22,0,0,0,0,0,0,0,0,0,0,0,0,0,0,0,0,0,0,0,0,0,0,0,22,33,0
0,0,35,0,0,0,0,0,0,0,0,0,0,0,0,0,0,0,0,0,0,0,0,0,0,0,35,0,0
0,34,22,0,0,0,0,0,0,0,0,0,0,0,0,0,0,0,0,0,0,0,0,0,0,0,22,33,0
0,0,35,0,0,0,0,0,0,0,0,0,0,0,0,0,0,0,0,0,0,0,0,0,0,0,35,0,0
0,34,22,0,0,0,0,0,0,0,0,0,0,0,0,0,0,0,0,0,0,0,0,0,0,0,22,33,0
0,0,35,0,0,0,0,0,0,0,0,0,0,0,0,0,0,0,0,0,0,0,0,0,0,0,35,0,0
0,34,22,0,0,0,0,0,0,0,0,0,0,0,0,0,0,0,0,0,0,0,0,0,0,0,22,33,0
0,0,35,0,0,0,0,0,0,0,0,0,0,0,0,0,0,0,0,0,0,0,0,0,0,0,35,0,0
0,34,22,0,0,0,0,0,0,0,0,0,0,0,0,0,0,0,0,0,0,0,0,0,0,0,22,33,0
0,0,35,0,0,0,0,0,0,0,0,0,0,0,0,0,0,0,0,0,0,0,0,0,0,0,35,0,0
0,34,22,0,0,0,0,0,0,0,0,0,0,0,0,0,0,0,0,0,0,0,0,0,0,0,22,33,0
0,0,29,22,32,22,32,22,32,22,32,22,32,22,32,22,32,22,32,22,32,22,32,22,32,22,28,0,0
0,0,0,36,0,36,0,36,0,36,0,36,0,36,0,36,0,36,0,36,0,36,0,36,0,36,0,0,0
0,0,0,0,0,0,0,0,0,0,0,0,0,0,0,0,0,0,0,0,0,0,0,0,0,0,0,0,0
endlayer

layer
0,0,0,0,0,0,0,0,0,0,0,0,0,0,0,0,0,0,0,0,0,0,0,0,0,0,0,0,0
0,0,0,20,0,20,0,20,0,20,0,20,0,20,0,20,0,20,0,20,0,20,0,20,0,20,0,0,0
0,0,24,22,32,22,32,22,32,22,32,22,32,22,32,22,32,22,32,22,32,22,32,22,32,22,21,0,0
0,26,22,0,0,0,0,0,0,0,0,0,0,0,0,0,0,0,0,0,0,0,0,0,0,0,22,25,0
0,0,35,0,0,0,0,0,0,0,0,0,0,0,0,0,0,0,0,0,0,0,0,0,0,0,35,0,0
0,26,22,0,0,0,0,0,0,0,0,0,0,0,0,0,0,0,0,0,0,0,0,0,0,0,22,25,0
0,0,35,0,0,0,0,0,0,0,0,0,0,0,0,0,0,0,0,0,0,0,0,0,0,0,35,0,0
0,26,22,0,0,0,0,0,0,0,0,0,0,0,0,0,0,0,0,0,0,0,0,0,0,0,22,25,0
0,0,35,0,0,0,0,0,0,0,0,0,0,0,0,0,0,0,0,0,0,0,0,0,0,0,35,0,0
0,26,22,0,0,0,0,0,0,0,0,0,0,0,0,0,0,0,0,0,0,0,0,0,0,0,22,25,0
0,0,35,0,0,0,0,0,0,0,0,0,0,0,0,0,0,0,0,0,0,0,0,0,0,0,35,0,0
0,26,22,0,0,0,0,0,0,0,0,0,0,0,0,0,0,0,0,0,0,0,0,0,0,0,22,25,0
0,0,35,0,0,0,0,0,0,0,0,0,0,0,0,0,0,0,0,0,0,0,0,0,0,0,35,0,0
0,26,22,0,0,0,0,0,0,0,0,0,0,0,0,0,0,0,0,0,0,0,0,0,0,0,22,25,0
0,0,35,0,0,0,0,0,0,0,0,0,0,0,0,0,0,0,0,0,0,0,0,0,0,0,35,0,0
0,26,22,0,0,0,0,0,0,0,0,0,0,0,0,0,0,0,0,0,0,0,0,0,0,0,22,25,0
0,0,35,0,0,0,0,0,0,0,0,0,0,0,0,0,0,0,0,0,0,0,0,0,0,0,35,0,0
0,26,22,0,0,0,0,0,0,0,0,0,0,0,0,0,0,0,0,0,0,0,0,0,0,0,22,25,0
0,0,35,0,0,0,0,0,0,0,0,0,0,0,0,0,0,0,0,0,0,0,0,0,0,0,35,0,0
0,26,22,0,0,0,0,0,0,0,0,0,0,0,0,0,0,0,0,0,0,0,0,0,0,0,22,25,0
0,0,35,0,0,0,0,0,0,0,0,0,0,0,0,0,0,0,0,0,0,0,0,0,0,0,35,0,0
0,26,22,0,0,0,0,0,0,0,0,0,0,0,0,0,0,0,0,0,0,0,0,0,0,0,22,25,0
0,0,35,0,0,0,0,0,0,0,0,0,0,0,0,0,0,0,0,0,0,0,0,0,0,0,35,0,0
0,26,22,0,0,0,0,0,0,0,0,0,0,0,0,0,0,0,0,0,0,0,0,0,0,0,22,25,0
0,0,35,0,0,0,0,0,0,0,0,0,0,0,0,0,0,0,0,0,0,0,0,0,0,0,35,0,0
0,26,22,0,0,0,0,0,0,0,0,0,0,0,0,0,0,0,0,0,0,0,0,0,0,0,22,25,0
0,0,29,22,32,22,32,22,32,22,32,22,32,22,32,22,32,22,32,22,32,22,32,22,32,22,28,0,0
0,0,0,30,0,30,0,30,0,30,0,30,0,30,0,30,0,30,0,30,0,30,0,30,0,30,0,0,0
0,0,0,0,0,0,0,0,0,0,0,0,0,0,0,0,0,0,0,0,0,0,0,0,0,0,0,0,0
endlayer

layer
0,0,0,0,0,0,0,0,0,0,0,0,0,0,0,0,0,0,0,0,0,0,0,0,0,0,0,0,0
0,0,0,22,8,22,8,22,8,22,8,22,8,22,8,22,8,22,8,22,8,22,8,22,8,22,0,0,0
0,0,24,22,23,22,23,22,23,22,23,22,23,22,23,22,23,22,23,22,23,22,23,22,23,22,21,0,0
0,22,22,14,14,14,14,14,14,14,14,14,14,14,14,14,14,14,14,14,14,14,14,14,14,14,22,22,0
0,15,23,14,14,14,14,14,14,14,14,14,14,14,14,14,14,14,14,14,14,14,14,14,14,14,23,13,0
0,22,22,14,14,14,14,14,14,14,14,14,14,14,14,14,14,14,14,14,14,14,14,14,14,14,22,22,0
0,15,23,14,14,14,14,14,14,14,14,14,14,14,14,14,14,14,14,14,14,14,14,14,14,14,23,13,0
0,22,22,14,14,14,14,14,14,14,14,14,14,14,14,14,14,14,14,14,14,14,14,14,14,14,22,22,0
0,15,23,14,14,14,14,14,14,14,14,14,14,14,14,14,14,14,14,14,14,14,14,14,14,14,23,13,0
0,22,22,14,14,14,14,14,14,14,14,14,14,14,14,14,14,14,14,14,14,14,14,14,14,14,22,22,0
0,15,23,14,14,14,14,14,14,14,14,14,14,14,14,14,14,14,14,14,14,14,14,14,14,14,23,13,0
0,22,22,14,14,14,14,14,14,14,14,14,14,14,14,14,14,14,14,14,14,14,14,14,14,14,22,22,0
0,15,23,14,14,14,14,14,14,14,14,14,14,14,14,14,14,14,14,14,14,14,14,14,14,14,23,13,0
0,22,22,14,14,14,14,14,14,14,14,14,14,14,14,14,14,14,14,14,14,14,14,14,14,14,22,22,0
0,15,23,14,14,14,14,14,14,14,14,14,14,14,14,14,14,14,14,14,14,14,14,14,14,14,23,13,0
0,22,22,14,14,14,14,14,14,14,14,14,14,14,14,14,14,14,14,14,14,14,14,14,14,14,22,22,0
0,15,23,14,14,14,14,14,14,14,14,14,14,14,14,14,14,14,14,14,14,14,14,14,14,14,23,13,0
0,22,22,14,14,14,14,14,14,14,14,14,14,14,14,14,14,14,14,14,14,14,14,14,14,14,22,22,0
0,15,23,14,14,14,14,14,14,14,14,14,14,14,14,14,14,14,14,14,14,14,14,14,14,14,23,13,0
0,22,22,14,14,14,14,14,14,14,14,14,14,14,14,14,14,14,14,14,14,14,14,14,14,14,22,22,0
0,15,23,14,14,14,14,14,14,14,14,14,14,14,14,14,14,14,14,14,14,14,14,14,14,14,23,13,0
0,22,22,14,14,14,14,14,14,14,14,14,14,14,14,14,14,14,14,14,14,14,14,14,14,14,22,22,0
0,15,23,14,14,14,14,14,14,14,14,14,14,14,14,14,14,14,14,14,14,14,14,14,14,14,23,13,0
0,22,22,14,14,14,14,14,14,14,14,14,14,14,14,14,14,14,14,14,14,14,14,14,14,14,22,22,0
0,15,23,14,14,14,14,14,14,14,14,14,14,14,14,14,14,14,14,14,14,14,14,14,14,14,23,13,0
0,22,22,14,14,14,14,14,14,14,14,14,14,14,14,14,14,14,14,14,14,14,14,14,14,14,22,22,0
0,0,29,22,23,22,23,22,23,22,23,22,23,22,23,22,23,22,23,22,23,22,23,22,23,22,28,0,0
0,0,0,22,19,22,19,22,19,22,19,22,19,22,19,22,19,22,19,22,19,22,19,22,19,22,0,0,0
0,0,0,0,0,0,0,0,0,0,0,0,0,0,0,0,0,0,0,0,0,0,0,0,0,0,0,0,0
endlayer

layer
0,0,0,0,0,0,0,0,0,0,0,0,0,0,0,0,0,0,0,0,0,0,0,0,0,0,0,0,0
0,39,40,0,0,0,0,0,0,0,0,0,0,0,0,0,0,0,0,0,0,0,0,0,0,0,40,39,0
0,40,22,22,22,22,22,22,22,22,22,22,22,22,22,22,22,22,22,22,22,22,22,22,22,22,22,40,0
0,0,22,0,0,0,0,0,0,0,0,0,0,0,0,0,0,0,0,0,0,0,0,0,0,0,22,0,0
0,0,22,0,0,0,0,0,0,0,0,0,0,0,0,0,0,0,0,0,0,0,0,0,0,0,22,0,0
0,0,22,0,0,0,0,0,0,0,0,0,0,0,0,0,0,0,0,0,0,0,0,0,0,0,22,0,0
0,0,22,0,0,0,0,0,0,0,0,0,0,0,0,0,0,0,0,0,0,0,0,0,0,0,22,0,0
0,0,22,0,0,0,0,0,0,0,0,0,0,0,0,0,0,0,0,0,0,0,0,0,0,0,22,0,0
0,0,22,0,0,0,0,0,0,0,0,0,0,0,0,0,0,0,0,0,0,0,0,0,0,0,22,0,0
0,0,22,0,0,0,0,0,0,0,0,0,0,0,0,0,0,0,0,0,0,0,0,0,0,0,22,0,0
0,0,22,0,0,0,0,0,0,0,0,0,0,0,0,0,0,0,0,0,0,0,0,0,0,0,22,0,0
0,0,22,0,0,0,0,0,0,0,0,0,0,0,0,0,0,0,0,0,0,0,0,0,0,0,22,0,0
0,0,22,0,0,0,0,0,0,0,0,0,0,0,0,0,0,0,0,0,0,0,0,0,0,0,22,0,0
0,0,22,0,0,0,0,0,0,0,0,0,0,0,0,0,0,0,0,0,0,0,0,0,0,0,22,0,0
0,0,22,0,0,0,0,0,0,0,0,0,0,0,0,0,0,0,0,0,0,0,0,0,0,0,22,0,0
0,0,22,0,0,0,0,0,0,0,0,0,0,0,0,0,0,0,0,0,0,0,0,0,0,0,22,0,0
0,0,22,0,0,0,0,0,0,0,0,0,0,0,0,0,0,0,0,0,0,0,0,0,0,0,22,0,0
0,0,22,0,0,0,0,0,0,0,0,0,0,0,0,0,0,0,0,0,0,0,0,0,0,0,22,0,0
0,0,22,0,0,0,0,0,0,0,0,0,0,0,0,0,0,0,0,0,0,0,0,0,0,0,22,0,0
0,0,22,0,0,0,0,0,0,0,0,0,0,0,0,0,0,0,0,0,0,0,0,0,0,0,22,0,0
0,0,22,0,0,0,0,0,0,0,0,0,0,0,0,0,0,0,0,0,0,0,0,0,0,0,22,0,0
0,0,22,0,0,0,0,0,0,0,0,0,0,0,0,0,0,0,0,0,0,0,0,0,0,0,22,0,0
0,0,22,0,0,0,0,0,0,0,0,0,0,0,0,0,0,0,0,0,0,0,0,0,0,0,22,0,0
0,0,22,0,0,0,0,0,0,0,0,0,0,0,0,0,0,0,0,0,0,0,0,0,0,0,22,0,0
0,0,22,0,0,0,0,0,0,0,0,0,0,0,0,0,0,0,0,0,0,0,0,0,0,0,22,0,0
0,0,22,0,0,0,0,0,0,0,0,0,0,0,0,0,0,0,0,0,0,0,0,0,0,0,22,0,0
0,40,22,22,22,22,22,22,22,22,22,22,22,22,22,22,22,22,22,22,22,22,22,22,22,22,22,40,0
0,39,40,0,0,0,0,0,0,0,0,0,0,0,0,0,0,0,0,0,0,0,0,0,0,0,40,39,0
0,0,0,0,0,0,0,0,0,0,0,0,0,0,0,0,0,0,0,0,0,0,0,0,0,0,0,0,0
endlayer

layer
0,0,0,0,0,0,0,0,0,0,0,0,0,0,0,0,0,0,0,0,0,0,0,0,0,0,0,0,0
0,41,42,42,42,42,42,42,42,42,42,42,42,42,42,42,42,42,42,42,42,42,42,42,42,42,42,41,0
0,42,42,42,42,42,42,42,42,42,42,42,42,42,42,42,42,42,42,42,42,42,42,42,42,42,42,42,0
0,42,42,43,43,43,43,43,43,43,43,43,43,43,43,43,43,43,43,43,43,43,43,43,43,43,42,42,0
0,42,42,43,43,43,43,43,43,43,43,43,43,43,43,43,43,43,43,43,43,43,43,43,43,43,42,42,0
0,42,42,43,43,43,43,43,43,43,43,43,43,43,43,43,43,43,43,43,43,43,43,43,43,43,42,42,0
0,42,42,43,43,43,43,43,43,43,43,43,43,43,43,43,43,43,43,43,43,43,43,43,43,43,42,42,0
0,42,42,43,43,43,43,43,43,43,43,43,43,43,43,43,43,43,43,43,43,43,43,43,43,43,42,42,0
0,42,42,43,43,43,43,43,43,43,43,43,43,43,43,43,43,43,43,43,43,43,43,43,43,43,42,42,0
0,42,42,43,43,43,43,43,43,43,43,43,43,43,43,43,43,43,43,43,43,43,43,43,43,43,42,42,0
0,42,42,43,43,43,43,43,43,43,43,43,43,43,43,43,43,43,43,43,43,43,43,43,43,43,42,42,0
0,42,42,43,43,43,43,43,43,43,43,43,43,43,43,43,43,43,43,43,43,43,43,43,43,43,42,42,0
0,42,42,43,43,43,43,43,43,43,43,43,43,43,43,43,43,43,43,43,43,43,43,43,43,43,42,42,0
0,42,42,43,43,43,43,43,43,43,43,43,43,43,43,43,43,43,43,43,43,43,43,43,43,43,42,42,0
0,42,42,43,43,43,43,43,43,43,43,43,43,43,43,43,43,43,43,43,43,43,43,43,43,43,42,42,0
0,42,42,43,43,43,43,43,43,43,43,43,43,43,43,43,43,43,43,43,43,43,43,43,43,43,42,42,0
0,42,42,43,43,43,43,43,43,43,43,43,43,43,43,43,43,43,43,43,43,43,43,43,43,43,42,42,0
0,42,42,43,43,43,43,43,43,43,43,43,43,43,43,43,43,43,43,43,43,43,43,43,43,43,42,42,0
0,42,42,43,43,43,43,43,43,43,43,43,43,43,43,43,43,43,43,43,43,43,43,43,43,43,42,42,0
0,42,42,43,43,43,43,43,43,43,43,43,43,43,43,43,43,43,43,43,43,43,43,43,43,43,42,42,0
0,42,42,43,43,43,43,43,43,43,43,43,43,43,43,43,43,43,43,43,43,43,43,43,43,43,42,42,0
0,42,42,43,43,43,43,43,43,43,43,43,43,43,43,43,43,43,43,43,43,43,43,43,43,43,42,42,0
0,42,42,43,43,43,43,43,43,43,43,43,43,43,43,43,43,43,43,43,43,43,43,43,43,43,42,42,0
0,42,42,43,43,43,43,43,43,43,43,43,43,43,43,43,43,43,43,43,43,43,43,43,43,43,42,42,0
0,42,42,43,43,43,43,43,43,43,43,43,43,43,43,43,43,43,43,43,43,43,43,43,43,43,42,42,0
0,42,42,43,43,43,43,43,43,43,43,43,43,43,43,43,43,43,43,43,43,43,43,43,43,43,42,42,0
0,42,42,42,42,42,42,42,42,42,42,42,42,42,42,42,42,42,42,42,42,42,42,42,42,42,42,42,0
0,41,42,42,42,42,42,42,42,42,42,42,42,42,42,42,42,42,42,42,42,42,42,42,42,42,42,41,0
0,0,0,0,0,0,0,0,0,0,0,0,0,0,0,0,0,0,0,0,0,0,0,0,0,0,0,0,0
endlayer

