
# Created by Ruins mod version 1.14.3 Ingame Parser
# authoring Player: maireilla

# TEMPLATE PARAMETER SETTINGS:
#
# criterion expression specifying mod ids required to load template
# may include plus (AND), minus (AND NOT), comma (OR), and parentheses
# all required mods listed must be present; no prohibited mods can be
requiredMods=
#
# likelihood this template will be chosen relative to all others
# e.g., a weight=6 template is chosen 3X as often as one with weight=2
weight=1
#
# list of dimensions in which this template may spawn, even if generic
# one or more dimension names, separated by commas (blank = all)
dimensionsToSpawnIn=overworld
#
# list of other biomes in which this template may spawn
# biome corresponding to directory is always assumed, listed or not
# generic templates should leave this list empty
biomesToSpawnIn=
#
# criterion expression specifying types of biome where template spawns
# this is in addition to those explicitly listed as biomesToSpawnIn
# generic templates should leave this list empty
biomeTypesToSpawnIn=
#
# list of biomes in which this template may not spawn
# takes precedence over biomeTypesToSpawnIn, but NOT biomesToSpawnIn
# should be empty if biomeTypesToSpawnIn is empty
biomesToNotSpawnIn=
#
# depth template is pushed down into the surface when built
# offset is min/max range of random additional bury depth
embed_into_distance=0
random_height_offset=0,0
#
# whitelist/blacklist of block states on which template may be built
# specify one, not both; leave the other empty (both empty = allow all)
# CAUTION: THE DEFAULTS ONLY APPLY TO NON-FLOWING LAVA AND WATER VARIANTS)
acceptable_target_blocks=
unacceptable_target_blocks={Properties:{level:"0"},Name:"minecraft:water"},{Properties:{level:"0"},Name:"minecraft:lava"}
#
# size of template (#layers, #rows per layer, #blocks per row)
dimensions=24,21,21
#
# max number of missing blocks allowed in surface beneath template
allowable_overhang=0
#
# depth/height limit affected by terrain leveling
# also maximum bumpiness tolerated in surface beneath template
max_leveling=2
#
# padding applied to all sides of template horizontal footprint
# expands area affected by terrain leveling (-1 = no leveling)
leveling_buffer=0
#
# do not rotate template randomly when built (1 = no rotation)
preventRotation=0
#
# treat water/lava blocks as air and protect them from rule0 (1 = yes)
preserve_water=0
preserve_lava=0
#
# minimum distance this template must have from instances of itself
uniqueMinDistance=0
#
# min/max distances this template can be from world spawn (0 = no limit)
# only applies to overworld--i.e., dimension 0
spawnMinDistance=0
spawnMaxDistance=0
#
# other template built nearby whenever this one is
# syntax: <name>;<relativeX>;<maxYdifference>;<relativeZ>[;<chance>]
# may be used more than once to specify multiple neighbors
adjoining_template=

rule1=0,100,{Name:"minecraft:mossy_cobblestone"}
rule2=0,100,{Name:"minecraft:cobblestone"}
rule3=0,100,{Ruins:{entity:{SpawnPotentials:[{Entity:{id:skeleton},Weight:1}],Delay:-1}}, Name:"minecraft:spawner"}
rule4=0,100,{Properties:{lit:"true",facing:"west"},Name:"minecraft:redstone_wall_torch"}
rule5=0,100,{Properties:{lit:"true",facing:"south"},Name:"minecraft:redstone_wall_torch"}
rule6=0,100,{Properties:{lit:"true",facing:"north"},Name:"minecraft:redstone_wall_torch"}
rule7=0,100,{Properties:{lit:"true",facing:"east"},Name:"minecraft:redstone_wall_torch"}
rule8=0,100,{Properties:{lit:"true"},Name:"minecraft:redstone_torch"}
rule9=0,100,{Properties:{unstable:"false"},Name:"minecraft:tnt"}
rule10=0,100,{Properties:{half:"bottom",waterlogged:"false",shape:"straight",facing:"east"},Name:"minecraft:cobblestone_stairs"}
rule11=0,100,{Properties:{half:"bottom",waterlogged:"false",shape:"straight",facing:"south"},Name:"minecraft:cobblestone_stairs"}
rule12=0,100,{Properties:{half:"bottom",waterlogged:"false",shape:"straight",facing:"north"},Name:"minecraft:cobblestone_stairs"}
rule13=0,100,{Properties:{half:"bottom",waterlogged:"false",shape:"straight",facing:"west"},Name:"minecraft:cobblestone_stairs"}
rule14=0,100,{Properties:{east:"false",waterlogged:"false",south:"true",north:"true",west:"false"},Name:"minecraft:iron_bars"}
rule15=0,100,{Properties:{east:"true",waterlogged:"false",south:"false",north:"false",west:"true"},Name:"minecraft:iron_bars"}
rule16=0,100,{Ruins:{entity:{ForgeData:{LootTable:"minecraft:chests/end_city_treasure"},Items:[],Lock:""}},Properties:{waterlogged:"false",facing:north,type:"single"},Name:"minecraft:trapped_chest"}
rule17=0,100,{Ruins:{entity:{SpawnPotentials:[{Entity:{id:cave_spider},Weight:1}],Delay:-1}}, Name:"minecraft:spawner"}
rule18=0,100,{Ruins:{entity:{ForgeData:{LootTable:"minecraft:chests/simple_dungeon"},Items:[],Lock:""}},Properties:{waterlogged:"false",facing:north,type:"single"},Name:"minecraft:chest"}


layer
0,0,0,0,0,0,0,2,2,2,2,2,1,1,0,0,0,0,0,0,0
0,0,0,0,0,2,2,2,2,2,2,2,1,2,2,2,0,0,0,0,0
0,0,0,0,1,1,2,2,2,2,2,2,2,0,2,2,2,0,0,0,0
0,0,0,0,1,2,2,2,2,2,1,2,1,2,2,2,2,1,0,0,0
0,0,2,2,2,1,2,2,2,2,2,1,2,2,2,2,1,1,2,0,0
0,2,1,2,2,2,2,2,2,2,2,2,2,2,2,2,2,2,2,1,0
0,2,2,2,2,2,2,2,2,2,1,2,1,2,2,2,2,2,1,2,0
2,2,2,2,2,2,2,1,1,2,2,2,1,2,2,2,1,0,0,2,2
1,2,1,2,2,2,2,2,2,1,2,1,2,1,2,2,2,2,2,2,0
2,2,1,2,2,2,1,2,2,1,2,2,2,2,2,2,2,2,1,1,1
2,1,2,2,1,2,2,2,2,1,2,2,2,2,1,2,2,2,1,2,2
2,2,2,2,1,2,2,2,1,2,2,2,2,2,2,2,2,2,2,2,2
1,1,1,2,2,2,2,2,2,1,2,2,1,2,2,2,2,1,2,2,2
0,2,2,2,2,2,2,2,1,1,2,2,2,2,2,2,2,1,2,1,1
0,2,1,2,1,1,2,2,2,2,2,1,2,2,2,2,2,1,1,2,0
0,0,2,2,1,2,2,2,1,2,2,2,1,1,2,2,2,2,2,2,0
0,0,1,2,2,2,2,2,2,2,2,1,2,2,1,2,2,2,2,0,0
0,0,0,2,2,2,1,2,2,2,2,2,2,1,1,2,2,2,0,0,0
0,0,0,0,2,2,2,2,2,2,2,2,2,2,2,2,1,0,0,0,0
0,0,0,0,0,1,2,1,2,2,1,2,2,2,2,2,0,0,0,0,0
0,0,0,0,0,0,0,2,2,1,1,2,2,2,0,0,0,0,0,0,0
endlayer

layer
0,0,0,0,0,0,0,2,2,2,2,2,2,2,0,0,0,0,0,0,0
0,0,0,0,0,2,1,0,0,0,0,0,0,0,2,2,0,0,0,0,0
0,0,0,0,2,0,0,0,0,0,0,0,0,0,0,0,2,0,0,0,0
0,0,0,1,0,0,0,0,2,2,0,2,1,0,0,0,0,2,0,0,0
0,0,2,0,0,0,1,1,0,0,0,0,0,2,2,0,0,0,2,0,0
0,2,0,0,0,2,0,0,0,0,0,0,0,0,0,1,0,0,0,2,0
0,2,0,0,2,0,0,0,0,0,0,0,0,0,0,0,2,0,0,2,0
2,0,0,0,2,0,0,0,0,0,0,0,0,0,0,0,2,0,0,0,0
2,0,0,2,0,0,0,0,0,0,0,0,0,0,0,0,2,2,0,0,2
0,0,0,2,0,0,0,0,0,0,2,0,0,0,0,0,2,2,0,0,2
0,0,0,2,0,0,0,0,0,2,3,2,0,0,0,0,2,1,0,0,2
0,0,0,1,0,0,0,0,0,0,2,0,0,0,0,0,2,2,0,0,2
2,0,0,1,0,0,0,0,0,0,0,0,0,0,0,0,2,2,0,0,2
2,0,0,0,2,0,0,0,0,0,0,0,0,0,0,0,2,0,0,0,2
0,1,0,0,2,0,0,0,0,0,0,0,0,0,0,0,2,0,0,2,0
0,2,0,0,0,2,0,0,0,0,0,0,0,0,0,2,0,0,0,2,0
0,0,2,0,0,0,2,1,0,0,0,0,0,2,2,0,0,0,1,0,0
0,0,0,2,0,0,0,0,1,2,2,0,1,0,0,0,0,2,0,0,0
0,0,0,0,0,0,0,0,0,0,0,0,0,0,0,0,0,0,0,0,0
0,0,0,0,0,2,2,0,0,0,0,0,0,0,1,1,0,0,0,0,0
0,0,0,0,0,0,0,2,2,1,2,1,2,2,0,0,0,0,0,0,0
endlayer

layer
0,0,0,0,0,0,0,0,2,1,2,1,2,2,0,0,0,0,0,0,0
0,0,0,0,0,1,2,0,0,0,0,0,0,0,2,1,0,0,0,0,0
0,0,0,0,2,0,0,0,0,0,0,0,0,0,0,0,2,0,0,0,0
0,0,0,2,0,0,0,0,2,2,0,2,2,0,0,0,0,2,0,0,0
0,0,2,0,0,0,2,2,0,0,0,0,0,2,2,0,0,0,1,0,0
0,2,0,0,0,2,0,0,0,0,0,0,0,0,0,2,0,0,0,2,0
0,0,0,0,2,0,0,0,0,0,0,0,0,0,0,0,2,0,0,2,0
2,0,0,0,2,0,0,0,0,0,0,0,0,0,0,0,2,4,0,0,2
2,0,5,2,0,0,0,0,0,0,0,0,0,0,0,0,0,2,0,0,2
0,0,0,2,0,0,0,0,0,0,2,0,0,0,0,0,2,2,0,0,2
0,0,0,0,0,0,0,0,0,2,3,2,0,0,0,0,2,2,0,0,1
0,0,0,1,0,0,0,0,0,0,2,0,0,0,0,0,2,2,0,0,1
2,0,0,2,0,0,0,0,0,0,0,0,0,0,0,0,2,1,0,0,2
2,0,0,0,2,0,0,0,0,0,0,0,0,0,0,0,2,0,0,0,2
0,2,0,0,2,0,0,0,0,0,0,0,0,0,0,0,0,0,0,1,0
0,2,0,0,0,2,0,0,0,0,0,0,0,0,0,2,0,0,0,2,0
0,0,2,0,0,0,2,2,0,0,0,0,0,2,1,0,0,0,2,0,0
0,0,0,2,0,0,0,0,2,2,1,2,2,0,0,0,0,2,0,0,0
0,0,0,0,1,0,0,0,0,0,0,0,0,0,0,0,2,0,0,0,0
0,0,0,0,0,1,2,0,0,0,0,0,0,0,2,1,0,0,0,0,0
0,0,0,0,0,0,0,0,2,0,1,2,2,2,0,0,0,0,0,0,0
endlayer

layer
0,0,0,0,0,0,0,0,2,2,0,2,2,2,0,0,0,0,0,0,0
0,0,0,0,0,2,2,0,0,0,0,0,0,0,1,2,0,0,0,0,0
0,0,0,0,0,0,0,0,0,0,0,0,4,0,0,0,1,0,0,0,0
0,0,0,2,0,0,0,5,2,1,0,2,2,0,0,0,0,2,0,0,0
0,0,1,0,0,0,2,1,0,0,0,0,0,2,2,0,0,0,2,0,0
0,1,0,0,0,2,0,0,0,0,0,0,0,0,0,2,0,0,0,2,0
0,0,0,0,2,6,0,0,0,0,0,0,0,0,0,0,2,0,0,1,0
2,0,0,0,2,0,0,0,0,0,0,0,0,0,0,0,1,0,0,0,1
1,0,0,0,0,0,0,0,0,0,0,0,0,0,0,0,0,2,0,0,0
2,0,0,2,0,0,0,0,0,0,0,0,0,0,0,0,0,1,0,0,2
0,0,0,2,0,0,0,0,0,0,18,0,0,0,0,0,2,2,0,0,2
2,0,0,0,0,0,0,0,0,0,0,0,0,0,0,0,2,1,6,0,1
2,0,0,2,0,0,0,0,0,0,0,0,0,0,0,0,2,2,0,0,2
2,0,0,0,0,0,0,0,0,0,0,0,0,0,0,0,2,0,0,0,0
0,2,0,0,2,0,0,0,0,0,0,0,0,0,0,0,2,0,0,0,0
0,2,0,0,0,1,0,0,0,0,0,0,0,0,0,2,0,0,0,0,0
0,0,1,0,0,0,2,0,0,0,0,0,0,0,2,0,0,0,2,0,0
0,0,0,2,0,0,0,0,2,2,1,2,1,0,0,0,0,2,0,0,0
0,0,0,0,2,0,0,0,0,0,0,0,0,0,0,0,1,0,0,0,0
0,0,0,0,0,2,2,0,0,0,0,0,0,0,2,1,0,0,0,0,0
0,0,0,0,0,0,0,2,1,2,2,1,2,1,0,0,0,0,0,0,0
endlayer

layer
0,0,0,0,0,0,0,2,2,2,2,2,2,2,0,0,0,0,0,0,0
0,0,0,0,0,2,2,0,0,0,0,0,0,0,2,2,0,0,0,0,0
0,0,0,0,0,0,0,0,0,0,0,0,0,0,0,0,2,0,0,0,0
0,0,0,2,0,0,0,0,2,1,2,1,2,0,0,0,0,1,0,0,0
0,0,2,0,0,0,2,2,0,0,0,7,0,0,2,0,0,0,2,0,0
0,2,0,0,0,2,0,0,0,0,0,0,0,0,0,0,0,0,0,2,0
0,0,0,0,2,0,0,0,0,0,0,0,0,0,0,0,2,0,0,2,0
2,0,0,0,0,0,0,0,0,0,0,0,0,0,0,0,2,0,0,0,2
1,0,0,2,0,0,0,0,0,0,0,0,0,0,0,0,0,2,0,0,2
2,0,0,0,0,0,0,0,0,0,0,0,0,0,0,0,0,2,0,0,2
1,0,0,2,0,0,0,0,0,0,8,0,0,0,0,0,0,2,0,0,2
2,0,0,2,0,0,0,0,0,0,0,0,0,0,0,0,2,2,0,0,1
2,0,0,2,0,0,0,0,0,0,0,0,0,0,0,0,2,1,0,0,2
0,0,0,0,2,0,0,0,0,0,0,0,0,0,0,0,2,0,0,0,2
0,2,0,0,2,0,0,0,0,0,0,0,0,0,0,0,2,6,0,0,0
0,2,0,0,0,1,0,0,0,0,0,0,0,0,0,2,0,0,0,2,0
0,0,2,0,0,0,2,2,0,4,0,0,0,2,2,0,0,0,2,0,0
0,0,0,2,0,0,0,0,2,2,2,2,0,0,0,0,0,2,0,0,0
0,0,0,0,2,0,0,0,0,7,0,0,0,0,0,0,2,0,0,0,0
0,0,0,0,0,2,2,0,0,0,0,0,0,0,2,1,0,0,0,0,0
0,0,0,0,0,0,0,1,2,0,2,2,1,2,0,0,0,0,0,0,0
endlayer

layer
0,0,0,0,0,0,0,2,2,0,1,0,2,2,0,0,0,0,0,0,0
0,0,0,0,0,1,2,0,0,0,0,0,0,0,1,2,0,0,0,0,0
0,0,0,0,1,0,0,0,0,0,0,0,0,0,0,0,2,0,0,0,0
0,0,0,2,0,0,0,0,2,2,2,1,2,0,0,0,0,2,0,0,0
0,0,2,0,0,0,0,1,0,0,0,0,0,0,1,0,0,0,2,0,0
0,1,0,0,0,0,0,0,0,0,0,0,0,0,0,1,0,0,0,2,0
0,2,0,0,1,0,0,0,0,0,0,0,0,0,0,0,2,0,0,2,0
2,0,0,0,0,0,0,0,0,0,0,0,0,0,0,0,2,0,0,0,2
1,0,0,2,0,0,0,0,0,0,0,0,0,0,0,0,0,1,0,0,1
2,0,0,1,0,0,0,0,0,0,0,0,0,0,0,0,0,2,0,0,0
2,0,0,0,0,0,0,0,0,0,0,0,0,0,0,0,0,2,0,0,2
1,0,0,2,0,0,0,0,0,0,0,0,0,0,0,0,0,2,0,0,2
1,0,0,0,0,0,0,0,0,0,0,0,0,0,0,0,2,2,0,0,2
2,0,0,0,2,0,0,0,0,0,0,0,0,0,0,0,1,0,0,0,0
0,2,0,0,2,0,0,0,0,0,0,0,0,0,0,0,2,0,0,2,0
0,2,0,0,0,2,0,0,0,0,0,0,0,0,0,2,0,0,0,2,0
0,0,0,0,0,0,2,2,0,0,0,0,0,2,2,0,0,0,2,0,0
0,0,0,2,0,0,0,0,2,2,2,2,2,7,0,0,0,2,0,0,0
0,0,0,0,2,0,0,0,0,0,0,0,0,0,0,0,2,0,0,0,0
0,0,0,0,0,2,2,0,0,0,0,0,0,0,0,2,0,0,0,0,0
0,0,0,0,0,0,0,1,2,2,2,2,2,2,0,0,0,0,0,0,0
endlayer

layer
0,0,0,0,0,0,0,2,2,2,2,2,2,0,0,0,0,0,0,0,0
0,0,0,0,0,2,1,0,0,0,0,0,0,0,2,2,0,0,0,0,0
0,0,0,0,2,0,0,0,0,0,0,0,0,0,0,0,2,0,0,0,0
0,0,0,1,0,0,0,0,2,1,2,0,2,0,0,0,0,2,0,0,0
0,0,2,0,0,0,2,2,2,0,0,2,1,1,2,0,0,0,2,0,0
0,2,0,0,0,2,2,1,2,0,1,1,2,1,2,2,0,0,0,2,0
0,2,0,0,1,2,2,2,2,2,2,2,2,2,1,2,2,0,0,2,0
2,0,0,0,2,2,0,2,2,2,1,2,1,2,2,2,2,0,0,0,2
2,0,0,2,2,1,2,2,2,2,1,2,2,2,2,2,2,2,0,0,0
2,0,0,2,1,2,2,2,2,0,2,2,2,2,2,2,1,1,0,0,1
2,0,0,2,1,1,2,1,1,2,2,1,2,2,2,1,0,2,0,0,2
2,0,0,2,2,2,0,1,2,2,2,2,2,2,2,1,0,0,0,0,2
2,0,0,2,1,0,2,1,2,2,2,2,1,2,2,2,0,2,0,0,2
2,0,0,0,1,2,1,2,2,2,1,2,2,2,2,1,2,0,0,0,2
0,2,0,0,1,2,2,2,0,2,0,2,2,1,2,0,2,0,0,1,0
0,1,0,0,0,2,2,1,2,1,2,2,2,2,2,0,0,0,0,2,0
0,0,2,0,0,0,1,2,2,2,2,2,2,2,2,0,0,0,2,0,0
0,0,0,2,0,0,0,0,2,2,2,2,2,0,0,0,0,2,0,0,0
0,0,0,0,2,0,0,0,0,0,0,0,0,0,0,0,2,0,0,0,0
0,0,0,0,0,1,2,0,0,0,0,0,0,0,0,0,0,0,0,0,0
0,0,0,0,0,0,0,2,0,2,0,1,2,2,0,0,0,0,0,0,0
endlayer

layer
0,0,0,0,0,0,0,0,2,2,2,2,1,2,0,0,0,0,0,0,0
0,0,0,0,0,1,2,0,0,0,0,0,0,0,2,2,0,0,0,0,0
0,0,0,0,2,0,0,0,0,0,0,0,0,0,0,0,2,0,0,0,0
0,0,0,2,0,0,0,0,2,2,2,2,2,0,0,0,0,2,0,0,0
0,0,2,0,0,0,2,2,0,0,0,0,0,2,2,0,0,0,1,0,0
0,0,0,0,0,2,0,0,0,0,0,0,0,0,0,2,0,0,0,2,0
0,2,0,0,2,0,0,7,0,0,0,0,0,17,0,0,0,0,0,1,0
2,0,0,0,2,0,0,0,0,0,0,0,0,0,0,0,1,0,0,0,2
1,0,0,2,2,0,0,0,0,0,0,0,0,0,0,0,0,2,0,0,2
2,0,0,0,0,0,0,0,0,0,0,0,0,0,0,0,0,2,0,0,2
2,0,0,2,2,0,0,0,0,0,0,8,0,0,0,0,0,2,0,0,2
1,0,0,2,2,0,0,0,0,0,0,0,0,0,0,0,0,1,0,0,2
2,0,0,2,2,0,0,0,0,0,0,0,0,0,0,0,0,2,0,0,1
2,0,0,0,0,0,0,0,0,0,0,0,0,0,0,0,1,0,0,0,2
0,2,0,0,2,0,0,3,0,0,0,0,0,7,0,0,1,0,0,2,0
0,2,0,0,0,2,0,0,0,0,0,0,0,0,0,2,0,0,0,2,0
0,0,1,0,0,0,0,2,0,0,0,0,0,2,2,0,0,0,1,0,0
0,0,0,2,0,0,0,0,2,2,2,2,2,0,0,0,0,2,0,0,0
0,0,0,0,2,0,0,0,0,0,0,0,0,0,0,0,2,0,0,0,0
0,0,0,0,0,1,2,0,0,0,0,0,0,0,2,2,0,0,0,0,0
0,0,0,0,0,0,0,2,1,2,2,2,2,2,0,0,0,0,0,0,0
endlayer

layer
0,0,0,0,0,0,0,2,2,1,1,2,2,1,0,0,0,0,0,0,0
0,0,0,0,0,1,2,0,0,0,0,0,0,0,2,2,0,0,0,0,0
0,0,0,0,1,0,0,0,0,0,0,0,0,0,0,0,2,0,0,0,0
0,0,0,2,0,0,0,0,0,1,2,2,2,0,0,0,0,2,0,0,0
0,0,2,0,0,0,2,2,0,0,0,0,0,2,1,0,0,0,2,0,0
0,2,0,0,0,0,0,0,0,0,0,0,0,0,0,2,0,0,0,2,0
0,2,0,0,2,0,0,0,0,0,0,0,0,0,0,0,2,0,0,2,0
1,0,0,0,2,0,0,0,0,0,0,0,0,0,0,0,2,0,0,0,2
2,0,0,2,2,0,0,0,0,0,0,0,0,0,0,0,0,2,0,0,0
2,0,0,2,2,0,0,0,0,0,0,0,0,0,0,0,0,1,0,0,2
1,0,0,2,2,0,0,0,0,0,0,0,0,0,0,0,0,2,0,0,0
2,0,0,2,2,0,0,0,0,0,0,0,0,0,0,0,0,2,0,0,1
2,0,0,2,0,0,0,0,0,0,0,0,0,0,0,0,0,2,0,0,0
2,0,0,0,2,0,0,0,0,0,0,0,0,0,0,0,2,0,0,0,2
0,1,0,0,1,0,0,0,0,0,0,0,0,0,0,0,2,0,0,1,0
0,1,0,0,0,2,0,0,0,0,0,0,0,0,0,2,0,0,0,2,0
0,0,2,0,0,0,2,2,0,0,0,0,0,2,2,0,0,0,2,0,0
0,0,0,2,0,0,0,0,2,2,2,2,2,0,0,0,0,2,0,0,0
0,0,0,0,2,0,0,0,0,0,0,0,0,0,0,0,2,0,0,0,0
0,0,0,0,0,2,2,0,0,0,0,0,0,0,2,1,0,0,0,0,0
0,0,0,0,0,0,0,2,2,2,2,2,2,2,0,0,0,0,0,0,0
endlayer

layer
0,0,0,0,0,0,0,2,2,0,2,1,2,1,0,0,0,0,0,0,0
0,0,0,0,0,1,2,0,0,0,0,0,0,0,1,2,0,0,0,0,0
0,0,0,0,2,0,0,0,0,0,0,0,0,0,0,0,2,0,0,0,0
0,0,0,2,0,0,0,0,2,2,2,2,2,0,0,0,0,2,0,0,0
0,0,2,0,0,0,1,2,0,0,0,7,0,0,2,0,0,0,0,0,0
0,2,0,0,0,1,0,0,0,0,0,0,0,0,0,2,0,0,0,2,0
0,2,0,0,2,0,0,0,0,0,0,0,0,0,0,0,2,0,0,2,0
0,0,0,0,2,0,0,0,0,0,0,0,0,0,0,0,2,0,0,0,2
2,0,0,2,2,0,0,0,0,0,0,0,0,0,0,0,0,0,0,0,2
1,0,0,1,2,0,0,0,0,0,0,0,0,0,0,0,0,2,0,0,1
2,0,0,2,2,0,0,0,0,0,0,0,0,0,0,0,0,2,0,0,2
2,0,0,2,0,0,0,0,0,0,0,0,0,0,0,0,0,2,0,0,1
1,0,0,2,0,0,0,0,0,0,0,0,0,0,0,0,0,2,0,0,2
2,0,0,0,2,0,0,0,0,0,0,0,0,0,0,0,1,0,0,0,2
0,2,0,0,2,0,0,0,0,0,0,0,0,0,0,0,1,0,0,1,0
0,0,0,0,0,2,0,0,0,0,0,0,0,0,0,1,0,0,0,2,0
0,0,2,0,0,0,2,2,0,0,0,0,0,2,2,0,0,0,2,0,0
0,0,0,0,0,0,0,0,1,2,1,2,1,0,0,0,0,2,0,0,0
0,0,0,0,1,0,0,0,0,0,0,0,0,0,0,0,2,0,0,0,0
0,0,0,0,0,2,2,0,0,0,0,0,0,0,1,2,0,0,0,0,0
0,0,0,0,0,0,0,2,2,2,1,0,2,2,0,0,0,0,0,0,0
endlayer

layer
0,0,0,0,0,0,0,2,1,2,2,2,2,2,0,0,0,0,0,0,0
0,0,0,0,0,2,2,0,0,0,0,0,0,0,0,2,0,0,0,0,0
0,0,0,0,2,0,0,0,0,0,0,0,0,0,0,0,1,0,0,0,0
0,0,0,2,0,0,0,0,1,2,1,0,2,0,0,0,0,1,0,0,0
0,0,0,0,0,0,2,2,0,0,0,0,0,2,1,0,0,0,0,0,0
0,2,0,0,0,1,0,0,0,0,0,0,0,0,0,2,0,0,0,2,0
0,1,0,0,1,0,0,0,0,0,0,0,0,0,0,0,1,0,0,2,0
2,0,0,0,2,0,0,0,0,0,0,0,0,0,0,0,2,0,0,0,1
2,0,0,1,2,0,0,0,0,0,0,0,0,0,0,0,0,2,0,0,2
2,0,0,1,2,0,0,0,0,0,0,0,0,0,0,0,0,2,0,0,2
2,0,0,2,0,0,0,0,0,0,0,0,0,0,0,0,0,2,0,0,1
2,0,0,2,0,0,0,0,0,0,0,0,0,0,0,0,0,2,0,0,2
2,0,0,2,0,0,0,0,0,0,0,0,0,0,0,0,0,2,0,0,1
2,0,0,0,2,0,0,0,0,0,0,0,0,0,0,0,2,0,0,0,2
0,2,0,0,2,0,0,0,0,0,0,0,0,0,0,0,2,0,0,2,0
0,2,0,0,0,2,0,0,0,0,0,0,0,0,0,2,0,0,0,1,0
0,0,2,0,0,0,0,0,0,0,4,0,0,2,2,0,0,0,2,0,0
0,0,0,1,0,0,0,0,1,2,1,2,2,0,0,0,0,2,0,0,0
0,0,0,0,2,0,0,0,0,0,0,0,0,0,0,0,2,0,0,0,0
0,0,0,0,0,1,1,0,0,0,0,0,0,0,2,2,0,0,0,0,0
0,0,0,0,0,0,0,2,2,2,0,1,2,2,0,0,0,0,0,0,0
endlayer

layer
0,0,0,0,0,0,0,2,2,1,2,0,2,2,0,0,0,0,0,0,0
0,0,0,0,0,0,2,0,0,0,0,0,0,0,0,2,0,0,0,0,0
0,0,0,0,2,0,0,0,0,0,0,0,0,0,0,0,1,0,0,0,0
0,0,0,2,0,0,0,0,2,2,2,1,2,0,0,0,0,2,0,0,0
0,0,2,0,0,0,2,2,0,0,0,0,0,2,2,0,0,0,1,0,0
0,2,0,0,0,2,0,0,0,0,0,0,0,0,0,2,0,0,0,1,0
0,2,0,0,2,0,0,0,0,0,0,0,0,0,0,0,2,0,0,0,0
2,0,0,0,2,0,0,0,0,0,0,0,0,0,0,0,2,0,0,0,0
2,0,0,2,2,0,0,0,0,0,0,0,0,0,0,0,0,1,0,0,1
2,0,0,1,0,0,0,0,0,0,0,0,0,0,0,0,0,2,0,0,2
2,0,0,2,0,0,0,0,0,0,0,0,0,0,0,0,0,2,0,0,2
0,0,0,2,0,0,0,0,0,0,0,0,0,0,0,0,0,1,0,0,1
2,0,0,2,0,0,0,0,0,0,0,0,0,0,0,0,0,0,0,0,1
1,0,0,0,2,0,0,0,0,0,0,0,0,0,0,0,2,0,0,0,2
0,2,0,0,2,0,0,0,0,0,0,0,0,0,0,0,2,0,0,2,0
0,2,0,0,0,2,0,0,0,0,0,0,0,0,0,2,0,0,0,2,0
0,0,2,0,0,0,1,2,0,0,0,0,0,2,2,0,0,0,2,0,0
0,0,0,2,0,0,0,0,2,1,2,1,1,0,0,0,0,1,0,0,0
0,0,0,0,0,0,0,0,0,0,0,0,0,0,0,0,2,0,0,0,0
0,0,0,0,0,2,2,0,0,0,0,0,0,0,2,2,0,0,0,0,0
0,0,0,0,0,0,0,1,1,2,0,1,2,2,0,0,0,0,0,0,0
endlayer

layer
0,0,0,0,0,0,0,1,2,2,2,0,1,2,0,0,0,0,0,0,0
0,0,0,0,0,1,2,0,0,0,0,0,0,0,2,1,0,0,0,0,0
0,0,0,0,2,0,0,0,0,0,0,0,0,0,0,0,2,0,0,0,0
0,0,0,2,0,0,0,0,0,2,0,1,2,0,0,0,0,2,0,0,0
0,0,2,0,0,0,2,2,0,2,2,2,2,2,2,0,0,0,2,0,0
0,2,0,0,0,2,1,0,2,2,1,2,2,2,2,2,0,0,0,2,0
0,1,0,0,2,2,1,1,2,2,2,1,2,2,1,2,2,0,0,2,0
2,0,0,0,2,2,2,2,2,2,2,2,1,2,2,2,2,0,0,0,2
2,0,0,0,0,2,2,1,2,2,2,2,2,2,2,0,1,1,0,0,2
2,0,0,2,0,2,2,2,2,1,1,0,2,2,1,2,2,2,0,0,2
2,0,0,1,0,2,2,2,1,1,2,1,2,1,2,1,1,2,0,0,0
1,0,0,2,1,2,2,1,2,1,2,1,1,1,2,2,1,2,0,0,2
2,0,0,2,2,2,2,2,2,2,2,1,2,1,2,2,2,2,0,0,2
2,0,0,0,2,1,2,2,1,2,1,2,2,1,2,2,1,0,0,0,2
0,2,0,0,2,2,2,2,1,2,1,2,0,0,2,2,2,0,0,2,0
0,2,0,0,0,2,2,1,2,2,2,2,2,2,2,1,0,0,0,2,0
0,0,2,0,0,0,2,2,1,2,2,2,2,2,2,0,0,0,0,0,0
0,0,0,0,0,0,0,0,2,2,2,2,2,0,0,0,0,2,0,0,0
0,0,0,0,2,0,0,0,0,0,0,0,0,0,0,0,0,0,0,0,0
0,0,0,0,0,2,2,0,0,0,0,0,0,0,2,1,0,0,0,0,0
0,0,0,0,0,0,0,2,2,1,2,2,2,2,0,0,0,0,0,0,0
endlayer

layer
0,0,0,0,0,0,0,1,2,2,1,1,2,2,0,0,0,0,0,0,0
0,0,0,0,0,2,2,0,0,0,0,0,0,0,2,0,0,0,0,0,0
0,0,0,0,2,0,0,0,0,0,0,0,0,0,0,0,2,0,0,0,0
0,0,0,2,0,0,0,0,0,2,1,2,1,0,0,0,0,1,0,0,0
0,0,1,0,0,0,2,0,0,0,0,0,0,2,2,0,0,0,2,0,0
0,2,0,0,0,1,0,0,0,0,0,0,0,0,0,0,0,0,0,1,0
0,2,0,0,2,0,0,0,0,0,0,0,0,0,0,0,2,0,0,2,0
1,0,0,0,2,0,0,0,17,0,0,0,18,0,0,0,1,0,0,0,1
2,0,0,1,0,0,0,0,0,0,0,0,0,0,0,0,0,0,0,0,2
2,0,0,2,0,0,0,0,0,0,0,0,0,0,0,0,2,1,0,0,1
2,0,0,2,0,0,0,0,0,0,0,0,0,0,0,0,2,2,0,0,2
2,0,0,2,0,0,0,0,0,0,0,0,0,0,0,0,0,2,0,0,2
1,0,0,2,0,0,0,0,0,0,0,0,0,0,0,0,0,0,0,0,0
2,0,0,0,1,0,0,0,0,17,0,0,0,7,0,0,1,0,0,0,2
0,2,0,0,0,0,0,0,0,0,0,0,0,0,0,0,2,0,0,2,0
0,2,0,0,0,2,0,0,0,0,0,0,0,0,0,2,0,0,0,2,0
0,0,1,0,0,0,2,2,0,0,0,0,0,2,2,0,0,0,2,0,0
0,0,0,2,0,0,0,0,0,2,1,2,2,0,0,0,0,2,0,0,0
0,0,0,0,2,0,0,0,0,0,0,0,0,0,0,0,0,0,0,0,0
0,0,0,0,0,1,2,0,0,0,0,0,0,0,2,2,0,0,0,0,0
0,0,0,0,0,0,0,1,2,2,2,1,2,2,0,0,0,0,0,0,0
endlayer

layer
0,0,0,0,0,0,0,1,2,1,2,2,2,0,0,0,0,0,0,0,0
0,0,0,0,0,2,2,0,0,0,0,0,0,0,1,2,0,0,0,0,0
0,0,0,0,2,0,0,0,0,0,0,0,0,0,0,0,2,0,0,0,0
0,0,0,2,0,0,0,0,2,2,2,1,2,0,0,0,0,2,0,0,0
0,0,2,0,0,0,0,2,0,0,0,0,0,2,1,0,0,0,2,0,0
0,1,0,0,0,2,0,0,0,0,0,0,0,0,0,1,0,0,0,0,0
0,2,0,0,2,0,0,0,0,0,0,0,0,0,0,0,1,0,0,2,0
2,0,0,0,2,0,0,0,0,0,0,0,0,0,0,0,2,0,0,0,2
2,0,0,2,0,0,0,0,0,0,0,0,0,0,0,0,0,2,0,0,2
1,0,0,2,0,0,0,0,0,0,0,0,0,0,0,0,0,2,0,0,2
2,0,0,2,0,0,0,0,0,0,0,0,0,0,0,0,2,1,0,0,2
1,0,0,2,0,0,0,0,0,0,0,0,0,0,0,0,0,2,0,0,2
1,0,0,2,0,0,0,0,0,0,0,0,0,0,0,0,0,2,0,0,2
1,0,0,0,2,0,0,0,0,0,0,0,0,0,0,0,2,0,0,0,1
0,2,0,0,2,0,0,0,0,0,0,0,0,0,0,0,2,0,0,0,0
0,2,0,0,0,2,0,0,0,0,0,0,0,0,0,2,0,0,0,1,0
0,0,2,0,0,0,2,2,0,0,0,0,0,2,1,0,0,0,2,0,0
0,0,0,1,0,0,0,0,2,2,2,1,1,0,0,0,0,2,0,0,0
0,0,0,0,2,0,0,0,0,0,0,0,0,0,0,0,2,0,0,0,0
0,0,0,0,0,2,2,0,0,0,0,0,0,0,1,2,0,0,0,0,0
0,0,0,0,0,0,0,2,1,0,2,2,2,1,0,0,0,0,0,0,0
endlayer

layer
0,0,0,0,0,0,0,2,2,2,2,1,2,2,0,0,0,0,0,0,0
0,0,0,0,0,2,2,0,0,0,0,0,0,0,2,2,0,0,0,0,0
0,0,0,0,2,0,0,0,0,0,0,0,0,0,0,0,2,0,0,0,0
0,0,0,1,0,0,0,0,2,1,2,0,2,0,0,0,0,2,0,0,0
0,0,2,0,0,0,0,2,0,0,7,0,0,2,2,0,0,0,2,0,0
0,1,0,0,0,2,0,0,0,0,0,0,0,0,0,2,0,0,0,2,0
0,1,0,0,2,0,0,0,0,0,0,0,0,0,0,0,0,0,0,1,0
2,0,0,0,2,0,0,0,0,0,0,0,0,0,0,0,2,0,0,0,0
2,0,0,2,0,0,0,0,0,0,0,0,0,0,0,0,0,2,0,0,2
2,0,0,1,0,0,0,0,0,0,0,0,0,0,0,0,0,0,0,0,2
2,0,0,0,0,0,0,0,0,0,0,0,0,0,0,0,0,2,0,0,1
0,0,0,2,0,0,0,0,0,0,0,0,0,0,0,0,2,2,0,0,2
2,0,0,2,0,0,0,0,0,0,0,0,0,0,0,0,0,1,0,0,1
2,0,0,0,1,0,0,0,0,0,0,0,0,0,0,0,2,0,0,0,2
0,0,0,0,0,0,0,0,0,0,0,0,0,0,0,0,2,0,0,2,0
0,2,0,0,0,2,0,0,0,0,0,0,0,0,0,2,0,0,0,2,0
0,0,0,0,0,0,2,1,0,0,0,4,0,1,2,0,0,0,2,0,0
0,0,0,1,0,0,0,0,2,2,1,2,1,0,0,0,0,2,0,0,0
0,0,0,0,1,0,0,0,0,0,0,0,0,0,0,0,2,0,0,0,0
0,0,0,0,0,2,1,0,0,0,0,0,0,0,2,2,0,0,0,0,0
0,0,0,0,0,0,0,2,2,0,2,2,2,2,0,0,0,0,0,0,0
endlayer

layer
0,0,0,0,0,0,0,0,2,2,1,2,2,2,0,0,0,0,0,0,0
0,0,0,0,0,2,1,0,0,0,0,0,0,0,2,2,0,0,0,0,0
0,0,0,0,2,0,0,0,0,0,0,0,0,0,0,0,2,0,0,0,0
0,0,0,2,0,0,0,0,2,2,0,1,2,0,0,0,0,2,0,0,0
0,0,2,0,0,0,2,2,0,0,0,0,0,2,2,0,0,0,2,0,0
0,1,0,0,0,2,0,0,0,0,0,0,0,0,0,0,0,0,0,2,0
0,2,0,0,2,0,0,0,0,0,0,0,0,0,0,0,2,0,0,2,0
2,0,0,0,2,0,0,0,0,0,0,0,0,0,0,0,2,0,0,0,2
2,0,0,2,0,0,0,0,0,0,0,0,0,0,0,0,0,2,0,0,1
2,0,0,2,0,0,0,0,0,0,0,0,0,0,0,0,0,2,0,0,2
2,0,0,2,0,0,0,0,0,0,0,0,0,0,0,0,0,2,0,0,1
1,0,0,1,0,0,0,0,0,0,0,0,0,0,0,0,0,2,0,0,1
1,0,0,2,0,0,0,0,0,0,0,0,0,0,0,0,2,1,0,0,2
2,0,0,0,2,0,0,0,0,0,0,0,0,0,0,0,1,0,0,0,2
0,2,0,0,2,0,0,0,0,0,0,0,0,0,0,0,2,0,0,2,0
0,2,0,0,0,2,0,0,0,0,0,0,0,0,0,0,0,0,0,0,0
0,0,2,0,0,0,1,1,0,0,0,0,0,2,2,0,0,0,1,0,0
0,0,0,2,0,0,0,0,2,2,1,2,2,0,0,0,0,2,0,0,0
0,0,0,0,2,0,0,0,0,0,0,0,0,0,0,0,1,0,0,0,0
0,0,0,0,0,2,1,0,0,0,0,0,0,0,1,2,0,0,0,0,0
0,0,0,0,0,0,0,2,2,2,1,2,1,2,0,0,0,0,0,0,0
endlayer

layer
0,0,0,0,0,0,0,0,0,2,2,2,2,2,0,0,0,0,0,0,0
0,0,0,0,0,2,2,0,0,0,0,0,0,0,2,1,0,0,0,0,0
0,0,0,0,2,0,0,0,0,0,0,0,0,0,0,0,2,0,0,0,0
0,0,0,2,0,0,0,0,1,0,1,2,2,2,0,0,0,2,0,0,0
0,0,2,0,0,0,2,2,2,2,2,2,2,1,1,2,0,0,1,0,0
0,0,0,0,0,1,1,2,2,2,2,2,2,2,2,2,2,0,0,2,0
0,2,0,0,2,2,1,2,2,2,1,2,2,2,0,2,2,1,0,2,0
1,0,0,0,1,0,2,0,2,2,2,2,2,2,1,2,2,2,0,0,2
2,0,0,2,2,2,2,1,2,2,1,2,2,2,2,0,1,2,2,0,2
2,0,0,2,2,2,2,2,1,2,2,2,2,2,1,2,0,2,2,0,0
1,0,0,2,2,0,2,2,2,2,2,2,2,0,2,2,0,0,1,0,2
2,0,0,2,2,2,2,1,2,2,2,2,2,2,2,2,0,2,2,0,2
2,0,0,0,0,2,2,0,2,2,2,2,2,2,2,2,0,0,1,0,0
2,0,0,0,2,2,1,0,1,2,2,2,2,2,0,1,2,2,0,0,2
0,2,0,0,2,1,1,2,2,2,2,2,2,2,2,0,2,2,0,2,0
0,0,0,0,0,2,1,2,2,2,1,1,2,2,2,1,2,0,0,2,0
0,0,2,0,0,0,2,1,1,2,1,1,2,2,2,2,0,0,1,0,0
0,0,0,2,0,0,0,0,1,2,0,2,2,2,0,0,0,2,0,0,0
0,0,0,0,2,0,0,0,0,0,0,0,0,0,0,0,0,0,0,0,0
0,0,0,0,0,1,2,0,0,0,0,0,0,0,2,1,0,0,0,0,0
0,0,0,0,0,0,0,2,0,2,2,1,1,2,0,0,0,0,0,0,0
endlayer

layer
0,0,0,0,0,0,0,1,2,2,2,2,2,2,0,0,0,0,0,0,0
0,0,0,0,0,2,2,0,0,0,0,0,0,0,2,2,0,0,0,0,0
0,0,0,0,1,0,0,0,0,0,0,0,0,0,0,0,1,0,0,0,0
0,0,0,2,0,0,0,0,0,0,0,0,0,0,0,0,0,1,0,0,0
0,0,1,0,0,0,0,0,0,0,0,0,0,0,0,0,0,0,2,0,0
0,0,0,0,0,0,0,0,0,0,0,0,0,0,0,0,0,0,0,2,0
0,2,0,0,0,0,0,0,0,0,0,0,0,0,0,0,0,0,0,2,0
2,0,0,0,0,0,0,0,18,0,0,0,0,0,0,0,0,0,0,0,2
2,0,0,0,0,0,0,0,0,0,0,0,0,0,0,0,0,0,0,0,2
1,0,0,0,0,0,0,0,0,0,0,0,0,0,0,0,0,0,0,0,2
2,0,0,0,0,0,0,0,0,0,0,0,0,0,0,0,0,0,0,0,2
2,0,0,0,0,0,0,0,0,0,0,0,0,0,0,0,0,0,0,0,1
2,0,0,0,0,0,0,0,0,0,0,0,0,0,0,0,0,0,0,0,1
2,0,0,0,0,0,0,0,0,0,0,0,0,0,0,0,0,0,0,0,1
0,2,0,0,0,0,0,0,0,0,0,0,0,0,0,0,0,0,0,2,0
0,2,0,0,0,0,0,0,0,0,2,2,0,0,0,0,0,0,0,1,0
0,0,1,0,0,0,0,0,0,0,0,0,0,0,0,0,0,0,2,0,0
0,0,0,2,0,0,0,0,0,0,0,0,0,0,0,0,0,1,0,0,0
0,0,0,0,2,0,0,0,0,0,0,0,0,0,0,0,2,0,0,0,0
0,0,0,0,0,2,0,0,0,0,0,0,0,0,2,2,0,0,0,0,0
0,0,0,0,0,0,0,1,2,2,1,2,0,2,0,0,0,0,0,0,0
endlayer

layer
0,0,0,0,0,0,0,2,2,1,1,1,2,1,0,0,0,0,0,0,0
0,0,0,0,0,2,2,0,0,0,0,0,0,0,2,2,0,0,0,0,0
0,0,0,0,2,0,0,0,0,0,0,0,0,0,0,0,2,0,0,0,0
0,0,0,1,0,0,0,0,0,0,0,0,0,0,0,0,0,2,0,0,0
0,0,2,0,0,0,0,0,0,0,0,0,0,0,0,0,0,0,2,0,0
0,2,0,0,0,0,0,0,0,0,0,0,0,0,0,0,0,0,0,2,0
0,2,0,0,0,0,0,0,0,0,0,0,0,0,0,0,0,0,0,1,0
1,0,0,0,0,0,0,0,0,0,0,0,0,0,0,0,0,0,0,0,2
1,0,0,0,0,0,0,0,0,0,0,0,0,0,0,0,0,0,0,0,2
2,0,0,0,0,0,0,0,2,0,0,0,0,0,0,0,0,0,0,0,2
1,0,0,0,0,0,0,2,2,2,0,0,0,0,0,0,0,0,0,0,2
2,0,0,0,0,0,0,0,2,2,0,0,0,0,0,0,0,0,0,0,2
1,0,0,0,0,0,0,0,0,0,0,0,0,0,0,0,0,0,0,0,2
2,0,0,0,0,0,0,0,0,0,0,0,0,0,0,0,0,0,0,0,2
0,0,0,0,0,0,0,0,0,0,0,0,0,0,0,0,0,0,0,0,0
0,2,0,0,0,0,0,0,0,0,2,0,0,0,0,0,0,0,0,1,0
0,0,2,0,0,0,0,0,0,0,0,0,0,0,0,0,0,0,2,0,0
0,0,0,2,0,0,0,0,0,0,0,0,0,0,0,0,0,2,0,0,0
0,0,0,0,2,0,0,0,0,0,0,0,0,0,0,0,2,0,0,0,0
0,0,0,0,0,2,2,0,0,0,0,0,0,0,2,2,0,0,0,0,0
0,0,0,0,0,0,0,2,2,2,0,2,2,1,0,0,0,0,0,0,0
endlayer

layer
0,0,0,0,0,0,0,2,2,2,0,2,0,2,0,0,0,0,0,0,0
0,0,0,0,0,2,2,2,2,2,0,2,0,2,2,0,0,0,0,0,0
0,0,0,0,1,2,2,2,2,2,2,2,2,2,2,1,2,0,0,0,0
0,0,0,2,2,0,2,1,2,0,2,2,2,1,2,1,1,1,0,0,0
0,0,1,1,0,1,2,2,2,2,0,2,2,1,2,2,2,2,2,0,0
0,2,0,2,2,2,2,2,2,0,2,2,2,2,0,1,2,1,2,2,0
0,2,1,2,2,2,2,2,1,2,2,2,1,2,2,2,2,0,1,2,0
2,2,1,2,2,2,2,2,1,2,2,2,0,2,2,2,2,1,1,2,2
2,0,1,2,2,2,2,2,2,2,2,2,2,2,2,2,2,2,2,2,1
1,2,2,2,2,2,2,2,9,2,2,0,2,2,2,2,2,2,2,2,2
2,1,1,2,2,2,1,9,9,9,2,2,2,0,2,2,2,1,1,1,2
1,0,2,1,2,2,1,2,9,2,2,2,2,2,1,2,2,2,2,2,2
1,1,2,1,2,2,2,0,2,2,0,2,1,2,2,0,2,2,2,1,2
2,2,2,0,2,2,1,2,2,2,2,2,1,2,2,2,2,2,2,2,2
0,1,2,2,2,2,2,2,0,2,2,2,2,1,0,2,2,2,2,2,0
0,2,2,2,2,0,2,2,2,2,0,0,0,2,2,1,0,2,0,2,0
0,0,1,2,2,1,2,2,2,2,2,1,1,2,0,1,2,2,1,0,0
0,0,0,2,0,1,2,1,1,2,0,2,2,2,2,1,2,2,0,0,0
0,0,0,0,2,2,2,2,2,2,2,2,2,2,2,2,2,0,0,0,0
0,0,0,0,0,0,1,1,2,2,2,2,2,2,2,2,0,0,0,0,0
0,0,0,0,0,0,0,2,2,0,0,2,1,2,0,0,0,0,0,0,0
endlayer

layer
0,0,0,0,0,0,0,10,0,10,0,10,0,10,0,0,0,0,0,0,0
0,0,0,0,0,10,0,0,0,0,0,0,0,0,0,10,0,0,0,0,0
0,0,0,0,0,0,0,0,0,0,0,0,0,0,0,0,0,0,0,0,0
0,0,0,10,0,0,0,0,0,0,0,0,0,0,0,0,0,11,0,0,0
0,0,0,0,0,0,0,0,0,0,0,0,0,0,0,0,0,0,0,0,0
0,12,0,0,0,0,0,0,0,0,0,0,0,0,0,0,0,0,0,11,0
0,0,0,0,0,0,0,0,0,0,0,0,0,0,0,0,0,0,0,0,0
12,0,0,0,0,0,0,0,0,0,0,0,0,0,0,0,0,0,0,0,11
0,0,0,0,0,0,0,0,0,0,0,0,0,0,0,0,0,0,0,0,0
12,0,0,0,0,0,0,2,2,2,0,0,0,0,0,0,0,0,0,0,11
0,0,0,0,0,0,0,2,2,2,0,0,0,0,0,0,0,0,0,0,0
12,0,0,0,0,0,0,2,2,2,0,0,0,0,0,0,0,0,0,0,11
0,0,0,0,0,0,0,0,0,0,0,0,0,0,0,0,0,0,0,0,0
12,0,0,0,0,0,0,0,0,0,0,0,0,0,0,0,0,0,0,0,11
0,0,0,0,0,0,0,0,0,0,0,0,0,0,0,0,0,0,0,0,0
0,12,0,0,0,0,0,0,0,0,0,0,0,0,0,0,0,0,0,11,0
0,0,0,0,0,0,0,0,0,0,0,0,0,0,0,0,0,0,0,0,0
0,0,0,12,0,0,0,0,0,0,0,0,0,0,0,0,0,13,0,0,0
0,0,0,0,0,0,0,0,0,0,0,0,0,0,0,0,0,0,0,0,0
0,0,0,0,0,13,0,0,0,0,0,0,0,0,0,13,0,0,0,0,0
0,0,0,0,0,0,0,13,0,13,0,13,0,13,0,0,0,0,0,0,0
endlayer

layer
0,0,0,0,0,0,0,0,0,0,0,0,0,0,0,0,0,0,0,0,0
0,0,0,0,0,0,0,0,0,0,0,0,0,0,0,0,0,0,0,0,0
0,0,0,0,0,0,0,0,0,0,0,0,0,0,0,0,0,0,0,0,0
0,0,0,0,0,0,0,0,0,0,0,0,0,0,0,0,0,0,0,0,0
0,0,0,0,0,0,0,0,0,0,0,0,0,0,0,0,0,0,0,0,0
0,0,0,0,0,0,0,0,0,0,0,0,0,0,0,0,0,0,0,0,0
0,0,0,0,0,0,0,0,0,0,0,0,0,0,0,0,0,0,0,0,0
0,0,0,0,0,0,0,0,0,0,0,0,0,0,0,0,0,0,0,0,0
0,0,0,0,0,0,0,0,0,0,0,0,0,0,0,0,0,0,0,0,0
0,0,0,0,0,0,0,2,14,2,0,0,0,0,0,0,0,0,0,0,0
0,0,0,0,0,0,0,15,16,15,0,0,0,0,0,0,0,0,0,0,0
0,0,0,0,0,0,0,2,14,2,0,0,0,0,0,0,0,0,0,0,0
0,0,0,0,0,0,0,0,0,0,0,0,0,0,0,0,0,0,0,0,0
0,0,0,0,0,0,0,0,0,0,0,0,0,0,0,0,0,0,0,0,0
0,0,0,0,0,0,0,0,0,0,0,0,0,0,0,0,0,0,0,0,0
0,0,0,0,0,0,0,0,0,0,0,0,0,0,0,0,0,0,0,0,0
0,0,0,0,0,0,0,0,0,0,0,0,0,0,0,0,0,0,0,0,0
0,0,0,0,0,0,0,0,0,0,0,0,0,0,0,0,0,0,0,0,0
0,0,0,0,0,0,0,0,0,0,0,0,0,0,0,0,0,0,0,0,0
0,0,0,0,0,0,0,0,0,0,0,0,0,0,0,0,0,0,0,0,0
0,0,0,0,0,0,0,0,0,0,0,0,0,0,0,0,0,0,0,0,0
endlayer

layer
0,0,0,0,0,0,0,0,0,0,0,0,0,0,0,0,0,0,0,0,0
0,0,0,0,0,0,0,0,0,0,0,0,0,0,0,0,0,0,0,0,0
0,0,0,0,0,0,0,0,0,0,0,0,0,0,0,0,0,0,0,0,0
0,0,0,0,0,0,0,0,0,0,0,0,0,0,0,0,0,0,0,0,0
0,0,0,0,0,0,0,0,0,0,0,0,0,0,0,0,0,0,0,0,0
0,0,0,0,0,0,0,0,0,0,0,0,0,0,0,0,0,0,0,0,0
0,0,0,0,0,0,0,0,0,0,0,0,0,0,0,0,0,0,0,0,0
0,0,0,0,0,0,0,0,0,0,0,0,0,0,0,0,0,0,0,0,0
0,0,0,0,0,0,0,0,0,0,0,0,0,0,0,0,0,0,0,0,0
0,0,0,0,0,0,0,2,2,2,0,0,0,0,0,0,0,0,0,0,0
0,0,0,0,0,0,0,2,9,2,0,0,0,0,0,0,0,0,0,0,0
0,0,0,0,0,0,0,2,2,2,0,0,0,0,0,0,0,0,0,0,0
0,0,0,0,0,0,0,0,0,0,0,0,0,0,0,0,0,0,0,0,0
0,0,0,0,0,0,0,0,0,0,0,0,0,0,0,0,0,0,0,0,0
0,0,0,0,0,0,0,0,0,0,0,0,0,0,0,0,0,0,0,0,0
0,0,0,0,0,0,0,0,0,0,0,0,0,0,0,0,0,0,0,0,0
0,0,0,0,0,0,0,0,0,0,0,0,0,0,0,0,0,0,0,0,0
0,0,0,0,0,0,0,0,0,0,0,0,0,0,0,0,0,0,0,0,0
0,0,0,0,0,0,0,0,0,0,0,0,0,0,0,0,0,0,0,0,0
0,0,0,0,0,0,0,0,0,0,0,0,0,0,0,0,0,0,0,0,0
0,0,0,0,0,0,0,0,0,0,0,0,0,0,0,0,0,0,0,0,0
endlayer

