
# Created by Ruins mod version 1.14.3 Ingame Parser
# authoring Player: maireilla

# TEMPLATE PARAMETER SETTINGS:
#
# criterion expression specifying mod ids required to load template
# may include plus (AND), minus (AND NOT), comma (OR), and parentheses
# all required mods listed must be present; no prohibited mods can be
requiredMods=
#
# likelihood this template will be chosen relative to all others
# e.g., a weight=6 template is chosen 3X as often as one with weight=2
weight=1
#
# list of dimensions in which this template may spawn, even if generic
# one or more dimension names, separated by commas (blank = all)
dimensionsToSpawnIn=overworld
#
# list of other biomes in which this template may spawn
# biome corresponding to directory is always assumed, listed or not
# generic templates should leave this list empty
biomesToSpawnIn=
#
# criterion expression specifying types of biome where template spawns
# this is in addition to those explicitly listed as biomesToSpawnIn
# generic templates should leave this list empty
biomeTypesToSpawnIn=
#
# list of biomes in which this template may not spawn
# takes precedence over biomeTypesToSpawnIn, but NOT biomesToSpawnIn
# should be empty if biomeTypesToSpawnIn is empty
biomesToNotSpawnIn=
#
# depth template is pushed down into the surface when built
# offset is min/max range of random additional bury depth
embed_into_distance=0
random_height_offset=0,0
#
# whitelist/blacklist of block states on which template may be built
# specify one, not both; leave the other empty (both empty = allow all)
# CAUTION: THE DEFAULTS ONLY APPLY TO NON-FLOWING LAVA AND WATER VARIANTS)
acceptable_target_blocks=
unacceptable_target_blocks={Properties:{level:"0"},Name:"minecraft:water"},{Properties:{level:"0"},Name:"minecraft:lava"}
#
# size of template (#layers, #rows per layer, #blocks per row)
dimensions=12,15,16
#
# max number of missing blocks allowed in surface beneath template
allowable_overhang=0
#
# depth/height limit affected by terrain leveling
# also maximum bumpiness tolerated in surface beneath template
max_leveling=2
#
# padding applied to all sides of template horizontal footprint
# expands area affected by terrain leveling (-1 = no leveling)
leveling_buffer=0
#
# do not rotate template randomly when built (1 = no rotation)
preventRotation=0
#
# treat water/lava blocks as air and protect them from rule0 (1 = yes)
preserve_water=0
preserve_lava=0
#
# minimum distance this template must have from instances of itself
uniqueMinDistance=0
#
# min/max distances this template can be from world spawn (0 = no limit)
# only applies to overworld--i.e., dimension 0
spawnMinDistance=0
spawnMaxDistance=0
#
# other template built nearby whenever this one is
# syntax: <name>;<relativeX>;<maxYdifference>;<relativeZ>[;<chance>]
# may be used more than once to specify multiple neighbors
adjoining_template=

rule1=0,100,{Name:"minecraft:cobweb"}
rule2=0,100,{Properties:{waterlogged:"false",type:"bottom"},Name:"minecraft:brick_slab"}
rule3=0,100,{Properties:{distance:"7",persistent:"true"},Name:"minecraft:birch_leaves"}
rule4=0,100,{Properties:{half:"bottom",waterlogged:"false",shape:"straight",facing:"east"},Name:"minecraft:brick_stairs"}
rule5=0,100,{Properties:{distance:"1",persistent:"true"},Name:"minecraft:birch_leaves"}
rule6=0,100,{Properties:{axis:"y"},Name:"minecraft:acacia_log"}
rule7=0,100,{Name:"minecraft:acacia_planks"}
rule8=0,100,{Properties:{distance:"3",persistent:"true"},Name:"minecraft:birch_leaves"}
rule9=0,100,{Properties:{distance:"2",persistent:"true"},Name:"minecraft:birch_leaves"}
rule10=0,100,{Properties:{east:"false",south:"false",north:"false",west:"true",up:"false"},Name:"minecraft:vine"}
rule11=0,100,{Properties:{east:"false",south:"true",north:"false",west:"false",up:"false"},Name:"minecraft:vine"}
rule12=0,100,{Properties:{east:"false",south:"false",north:"true",west:"false",up:"false"},Name:"minecraft:vine"}
rule13=0,100,{Ruins:{entity:{SpawnPotentials:[{Entity:{id:cave_spider},Weight:1}],Delay:-1}}, Name:"minecraft:spawner"}
rule14=0,100,{Properties:{waterlogged:"false",type:"top"},Name:"minecraft:brick_slab"}
rule15=0,100,{Properties:{half:"top",waterlogged:"false",shape:"straight",facing:"east"},Name:"minecraft:brick_stairs"}
rule16=0,100,{Properties:{axis:"z"},Name:"minecraft:acacia_log"}
rule17=0,100,{Properties:{half:"bottom",waterlogged:"false",shape:"outer_left",facing:"south"},Name:"minecraft:brick_stairs"}
rule18=0,100,{Properties:{half:"bottom",waterlogged:"false",shape:"outer_right",facing:"north"},Name:"minecraft:brick_stairs"}
rule19=0,100,{Properties:{half:"bottom",waterlogged:"false",shape:"straight",facing:"south"},Name:"minecraft:brick_stairs"}
rule20=0,100,{Properties:{half:"bottom",waterlogged:"false",shape:"inner_left",facing:"east"},Name:"minecraft:brick_stairs"}
rule21=0,100,{Properties:{half:"bottom",waterlogged:"false",shape:"straight",facing:"north"},Name:"minecraft:brick_stairs"}
rule22=0,100,{Properties:{half:"bottom",waterlogged:"false",shape:"inner_right",facing:"west"},Name:"minecraft:brick_stairs"}
rule23=0,100,{Properties:{half:"bottom",waterlogged:"false",shape:"outer_left",facing:"north"},Name:"minecraft:brick_stairs"}
rule24=0,100,{Properties:{half:"bottom",waterlogged:"false",shape:"outer_left",facing:"west"},Name:"minecraft:brick_stairs"}
rule25=0,100,{Properties:{half:"bottom",waterlogged:"false",shape:"straight",facing:"west"},Name:"minecraft:brick_stairs"}
rule26=0,100,{Properties:{half:"bottom",waterlogged:"false",shape:"outer_right",facing:"south"},Name:"minecraft:brick_stairs"}
rule27=0,100,{Properties:{axis:"x"},Name:"minecraft:acacia_log"}
rule28=0,100,{Properties:{half:"bottom",waterlogged:"false",shape:"outer_left",facing:"east"},Name:"minecraft:brick_stairs"}
rule29=0,100,{Ruins:{entity:{ForgeData:{LootTable:"minecraft:chests/simple_dungeon"},Items:[],Lock:""}},Properties:{waterlogged:"false",facing:north,type:"single"},Name:"minecraft:trapped_chest"}
rule30=0,100,{Properties:{half:"bottom",waterlogged:"false",shape:"inner_left",facing:"north"},Name:"minecraft:brick_stairs"}
rule31=0,100,{Properties:{half:"bottom",waterlogged:"false",shape:"outer_right",facing:"west"},Name:"minecraft:brick_stairs"}

layer
0,0,0,0,0,0,0,0,2,1,0,0,0,0,0,0
0,0,0,0,0,0,0,0,1,2,0,0,0,0,0,0
0,0,0,0,0,0,0,5,4,4,0,3,3,0,0,0
0,0,0,0,5,0,0,6,7,7,6,7,7,6,5,0
0,0,0,5,6,7,7,7,7,7,7,7,7,7,7,8
0,0,0,0,7,7,7,7,7,7,7,7,7,7,7,9
0,0,0,9,7,7,7,7,7,7,7,7,7,7,6,5
0,0,0,5,6,7,7,7,7,7,7,7,7,7,7,9
0,0,0,9,7,7,7,7,7,7,7,7,7,7,7,0
0,0,0,0,7,7,7,7,7,7,7,7,7,7,7,9
0,0,0,5,6,7,7,7,7,7,7,7,7,7,6,5
0,0,0,9,10,7,7,7,7,7,7,7,7,7,7,9
0,0,0,0,0,0,6,7,7,6,7,7,7,7,7,0
0,0,0,0,0,0,10,0,0,0,7,7,6,7,10,0
0,0,0,0,0,0,0,0,0,0,0,10,0,0,0,0
endlayer

layer
0,0,0,0,0,0,0,0,0,0,0,0,0,0,0,0
0,0,0,0,0,0,0,0,0,0,0,0,0,0,0,0
0,0,0,0,0,0,0,0,0,0,0,3,1,5,0,0
0,0,0,0,0,0,5,6,0,1,6,7,7,6,1,0
0,0,0,0,6,7,7,0,0,0,0,0,0,1,7,0
0,0,0,0,1,1,0,0,0,0,0,0,0,0,7,11
0,0,0,9,7,0,0,0,1,0,0,0,0,0,6,5
0,0,0,5,6,0,0,0,0,0,0,0,1,0,7,0
0,0,0,12,1,0,0,0,1,0,0,0,0,0,7,3
0,0,0,12,7,1,0,0,13,0,1,0,0,0,7,0
0,0,0,5,6,0,0,0,0,0,0,0,0,0,6,11
0,0,0,0,12,7,1,0,0,0,0,0,0,0,7,0
0,0,0,0,0,12,6,7,7,6,0,1,0,0,7,3
0,0,0,0,0,0,0,0,0,0,7,7,6,1,10,10
0,0,0,0,0,0,0,0,0,0,10,10,10,0,0,0
endlayer

layer
0,0,0,0,0,0,0,0,0,0,0,0,0,0,0,0
0,0,0,0,0,0,0,0,0,0,0,0,0,0,0,0
0,0,0,0,0,0,0,0,0,0,0,0,3,0,0,0
0,0,0,0,0,0,0,6,1,0,6,7,7,6,0,0
0,0,0,0,6,7,7,0,0,0,0,1,0,0,7,3
0,0,0,0,7,0,0,0,0,0,0,0,0,0,7,11
0,0,0,0,1,0,0,0,0,0,0,0,0,0,6,0
0,0,0,0,6,0,0,0,0,0,0,0,0,0,1,0
0,0,0,12,7,0,0,0,0,0,0,0,0,0,7,11
0,0,0,0,1,0,0,0,1,1,0,0,0,0,1,3
0,0,0,0,6,0,0,0,0,0,0,0,0,0,6,0
0,0,0,0,0,7,0,0,0,0,0,0,0,0,7,3
0,0,0,0,0,12,6,1,7,6,0,0,0,0,7,0
0,0,0,0,0,0,10,0,0,0,7,7,6,7,0,0
0,0,0,0,0,0,0,0,0,0,0,0,10,0,0,0
endlayer

layer
0,0,0,0,0,0,0,0,0,0,0,0,0,0,0,0
0,0,0,0,0,0,0,0,0,0,0,0,0,0,0,0
0,0,0,0,0,0,14,15,4,4,15,14,14,14,0,0
0,0,0,14,14,14,14,6,16,16,6,7,7,6,14,0
0,0,0,14,6,7,7,0,0,0,0,0,0,0,7,14
0,0,0,14,7,0,1,0,0,0,0,0,0,0,7,14
0,0,0,14,7,0,0,0,0,0,0,0,0,0,6,14
0,0,0,14,6,0,0,0,0,0,0,0,0,0,7,14
0,0,0,14,7,0,0,0,0,0,0,0,0,0,7,14
0,0,0,14,7,0,0,0,0,0,0,0,0,0,7,14
0,0,0,14,6,0,0,0,0,0,0,0,0,0,6,14
0,0,0,0,14,7,0,0,0,0,0,0,0,0,7,14
0,0,0,0,0,14,6,7,7,6,0,0,0,0,7,14
0,0,0,0,0,0,14,14,14,14,7,1,6,7,14,0
0,0,0,0,0,0,0,0,0,0,14,14,14,14,0,0
endlayer

layer
0,0,0,0,0,0,0,0,0,0,0,0,0,0,0,0
0,0,0,0,0,0,0,0,0,0,0,0,0,0,0,0
0,0,0,0,0,0,0,0,0,0,0,0,0,0,0,0
0,0,0,0,0,0,18,4,4,4,4,4,4,4,17,0
0,0,0,0,18,4,20,7,7,7,7,7,7,7,19,0
0,0,0,0,21,7,7,0,0,0,0,0,0,7,19,0
0,0,0,0,21,7,0,0,0,0,0,0,0,7,19,0
0,0,0,0,21,7,0,0,0,0,0,0,0,7,19,0
0,0,0,0,21,7,0,0,0,0,0,0,0,7,19,0
0,0,0,0,21,7,0,0,0,0,0,0,0,7,19,0
0,0,0,0,21,7,0,0,0,0,0,0,0,7,19,0
0,0,0,0,23,22,7,7,7,7,0,0,0,7,19,0
0,0,0,0,0,23,25,25,25,22,7,7,7,7,24,0
0,0,0,0,0,0,0,0,0,23,25,25,25,25,26,0
0,0,0,0,0,0,0,0,0,0,0,0,0,0,0,0
endlayer

layer
0,0,0,0,0,0,0,0,0,0,0,0,0,0,0,0
0,0,0,0,0,0,0,0,0,0,0,0,0,0,0,0
0,0,0,0,0,0,0,0,0,0,0,0,0,0,0,0
0,0,0,0,0,0,0,0,0,0,0,0,0,0,0,0
0,0,0,0,0,0,0,4,4,4,4,4,4,2,0,0
0,0,0,0,0,18,4,14,7,7,7,7,7,19,0,0
0,0,0,0,0,21,7,7,0,0,0,0,7,19,0,0
0,0,0,0,0,21,7,0,0,0,0,0,7,19,0,0
0,0,0,0,0,21,7,0,0,0,0,0,7,19,0,0
0,0,0,0,0,21,7,0,0,0,0,0,7,19,0,0
0,0,0,0,0,21,14,7,7,7,7,0,7,19,0,0
0,0,0,0,0,0,25,25,25,25,14,7,7,19,0,0
0,0,0,0,0,0,0,0,0,0,25,25,25,2,0,0
0,0,0,0,0,0,0,0,0,0,0,0,0,0,0,0
0,0,0,0,0,0,0,0,0,0,0,0,0,0,0,0
endlayer

layer
0,0,0,0,0,0,0,0,0,0,0,0,0,0,0,0
0,0,0,0,0,0,0,0,0,0,0,0,0,0,0,0
0,0,0,0,0,0,0,0,0,0,0,0,0,0,0,0
0,0,0,0,0,0,0,0,0,0,0,0,0,0,0,0
0,0,0,0,0,0,0,0,0,0,0,0,0,0,0,0
0,0,0,0,0,0,0,0,4,4,4,4,17,0,0,0
0,0,0,0,0,0,28,4,14,7,7,27,19,0,0,0
0,0,0,0,0,0,21,27,7,13,7,7,19,0,0,0
0,0,0,0,0,0,21,7,0,7,0,7,19,0,0,0
0,0,0,0,0,0,21,14,27,7,7,27,19,0,0,0
0,0,0,0,0,0,0,25,25,25,25,14,19,0,0,0
0,0,0,0,0,0,0,0,0,0,0,25,24,0,0,0
0,0,0,0,0,0,0,0,0,0,0,0,0,0,0,0
0,0,0,0,0,0,0,0,0,0,0,0,0,0,0,0
0,0,0,0,0,0,0,0,0,0,0,0,0,0,0,0
endlayer

layer
0,0,0,0,0,0,0,0,0,0,0,0,0,0,0,0
0,0,0,0,0,0,0,0,0,0,0,0,0,0,0,0
0,0,0,0,0,0,0,0,0,0,0,0,0,0,0,0
0,0,0,0,0,0,0,0,0,0,0,0,0,0,0,0
0,0,0,0,0,0,0,0,0,0,0,0,0,0,0,0
0,0,0,0,0,0,0,0,0,0,0,0,0,0,0,0
0,0,0,0,0,0,0,0,7,7,7,6,0,0,0,0
0,0,0,0,0,0,0,6,29,0,0,7,0,0,0,0
0,0,0,0,0,0,0,1,0,0,0,7,0,0,0,0
0,0,0,0,0,0,0,0,6,7,1,6,0,0,0,0
0,0,0,0,0,0,0,0,0,0,0,0,0,0,0,0
0,0,0,0,0,0,0,0,0,0,0,0,0,0,0,0
0,0,0,0,0,0,0,0,0,0,0,0,0,0,0,0
0,0,0,0,0,0,0,0,0,0,0,0,0,0,0,0
0,0,0,0,0,0,0,0,0,0,0,0,0,0,0,0
endlayer

layer
0,0,0,0,0,0,0,0,0,0,0,0,0,0,0,0
0,0,0,0,0,0,0,0,0,0,0,0,0,0,0,0
0,0,0,0,0,0,0,0,0,0,0,0,0,0,0,0
0,0,0,0,0,0,0,0,0,0,0,0,0,0,0,0
0,0,0,0,0,0,0,0,0,0,0,0,0,0,0,0
0,0,0,0,0,0,0,0,0,0,0,0,0,0,0,0
0,0,0,0,0,0,0,0,7,1,7,6,0,0,0,0
0,0,0,0,0,0,0,6,0,0,0,1,0,0,0,0
0,0,0,0,0,0,0,7,0,0,0,7,0,0,0,0
0,0,0,0,0,0,0,0,6,7,7,6,0,0,0,0
0,0,0,0,0,0,0,0,0,0,0,0,0,0,0,0
0,0,0,0,0,0,0,0,0,0,0,0,0,0,0,0
0,0,0,0,0,0,0,0,0,0,0,0,0,0,0,0
0,0,0,0,0,0,0,0,0,0,0,0,0,0,0,0
0,0,0,0,0,0,0,0,0,0,0,0,0,0,0,0
endlayer

layer
0,0,0,0,0,0,0,0,0,0,0,0,0,0,0,0
0,0,0,0,0,0,0,0,0,0,0,0,0,0,0,0
0,0,0,0,0,0,0,0,0,0,0,0,0,0,0,0
0,0,0,0,0,0,0,0,0,0,0,0,0,0,0,0
0,0,0,0,0,0,0,0,0,0,0,0,0,0,0,0
0,0,0,0,0,0,0,0,18,4,4,4,17,0,0,0
0,0,0,0,0,0,28,4,20,7,7,6,19,0,0,0
0,0,0,0,0,0,21,6,7,0,0,7,19,0,0,0
0,0,0,0,0,0,21,7,0,0,0,7,19,0,0,0
0,0,0,0,0,0,31,30,6,7,7,6,19,0,0,0
0,0,0,0,0,0,0,23,25,25,25,25,24,0,0,0
0,0,0,0,0,0,0,0,0,0,0,0,0,0,0,0
0,0,0,0,0,0,0,0,0,0,0,0,0,0,0,0
0,0,0,0,0,0,0,0,0,0,0,0,0,0,0,0
0,0,0,0,0,0,0,0,0,0,0,0,0,0,0,0
endlayer

layer
0,0,0,0,0,0,0,0,0,0,0,0,0,0,0,0
0,0,0,0,0,0,0,0,0,0,0,0,0,0,0,0
0,0,0,0,0,0,0,0,0,0,0,0,0,0,0,0
0,0,0,0,0,0,0,0,0,0,0,0,0,0,0,0
0,0,0,0,0,0,0,0,0,0,0,0,0,0,0,0
0,0,0,0,0,0,0,0,0,0,0,0,0,0,0,0
0,0,0,0,0,0,0,0,18,4,4,17,0,0,0,0
0,0,0,0,0,0,0,18,20,0,0,19,0,0,0,0
0,0,0,0,0,0,0,2,14,0,0,19,0,0,0,0
0,0,0,0,0,0,0,0,2,25,25,26,0,0,0,0
0,0,0,0,0,0,0,0,0,0,0,0,0,0,0,0
0,0,0,0,0,0,0,0,0,0,0,0,0,0,0,0
0,0,0,0,0,0,0,0,0,0,0,0,0,0,0,0
0,0,0,0,0,0,0,0,0,0,0,0,0,0,0,0
0,0,0,0,0,0,0,0,0,0,0,0,0,0,0,0
endlayer

layer
0,0,0,0,0,0,0,0,0,0,0,0,0,0,0,0
0,0,0,0,0,0,0,0,0,0,0,0,0,0,0,0
0,0,0,0,0,0,0,0,0,0,0,0,0,0,0,0
0,0,0,0,0,0,0,0,0,0,0,0,0,0,0,0
0,0,0,0,0,0,0,0,0,0,0,0,0,0,0,0
0,0,0,0,0,0,0,0,0,0,0,0,0,0,0,0
0,0,0,0,0,0,0,0,0,0,0,0,0,0,0,0
0,0,0,0,0,0,0,0,0,2,2,0,0,0,0,0
0,0,0,0,0,0,0,0,0,2,2,0,0,0,0,0
0,0,0,0,0,0,0,0,0,0,0,0,0,0,0,0
0,0,0,0,0,0,0,0,0,0,0,0,0,0,0,0
0,0,0,0,0,0,0,0,0,0,0,0,0,0,0,0
0,0,0,0,0,0,0,0,0,0,0,0,0,0,0,0
0,0,0,0,0,0,0,0,0,0,0,0,0,0,0,0
0,0,0,0,0,0,0,0,0,0,0,0,0,0,0,0
endlayer

