


weight=2
embed_into_distance=0

unacceptable_target_blocks=flowing_water,water,flowing_lava,lava,Natura:Cloud,red_mushroom_block,brown_mushroom_block,planks,cobblestone,end_stone,obsidian,purpur_block,iron_bars,purpur_slab,purpur_pillar,netherrack,soul_sand,quartz_ore

dimensions=8,10,12
allowable_overhang=1
max_leveling=2
leveling_buffer=0
preserve_water=0
preserve_lava=0
preserve_plants=1


rule1=0,100,double_stone_slab
rule2=0,100,planks
rule3=0,100,cobblestone
rule4=0,100,grass
rule5=0,100,stone_stairs
rule6=0,100,stone_stairs-1
rule7=0,100,stone_stairs-2
rule8=0,100,stone_stairs-3


layer
1,3,3,3,3,3,3,3,3,3,3,1
3,0,0,0,2,2,2,2,2,2,2,2
3,0,0,0,0,0,2,2,2,2,2,3
3,0,0,2,0,0,2,2,0,2,2,3
3,0,2,2,2,2,2,2,2,2,2,3
3,2,2,2,2,2,3,3,3,3,3,1
3,2,2,0,2,2,3,4,4,4,4,4
3,2,2,0,2,2,3,4,4,4,4,4
3,2,0,0,2,0,3,4,4,4,4,4
1,3,3,3,3,3,1,4,4,4,4,4
endlayer

layer
1,3,3,3,3,3,3,3,3,0,3,1
3,0,0,0,0,0,0,0,0,0,0,0
3,0,0,0,0,0,0,0,0,0,0,3
0,0,0,0,0,0,0,0,0,0,0,3
3,0,0,0,0,0,0,0,0,0,0,0
3,3,0,3,3,3,3,3,3,3,3,1
3,0,0,0,0,0,3,0,0,0,0,0
3,0,0,0,0,0,3,0,0,0,0,0
3,0,0,0,0,0,3,0,0,0,0,0
1,3,3,3,3,3,1,0,0,0,0,0
endlayer

layer
1,3,0,0,0,3,3,3,0,0,3,1
3,0,0,0,0,0,0,0,0,0,0,0
0,0,0,0,0,0,0,0,0,0,0,3
0,0,0,0,0,0,0,0,0,0,0,0
3,0,0,0,0,0,0,0,0,0,0,0
3,3,0,3,3,3,0,3,0,0,0,0
3,0,0,0,0,0,0,0,0,0,0,0
0,0,0,0,0,0,0,0,0,0,0,0
3,0,0,0,0,0,3,0,0,0,0,0
1,3,0,0,0,3,1,0,0,0,0,0
endlayer

layer
0,3,0,0,0,0,0,0,0,0,3,1
3,0,0,0,0,0,0,0,0,0,0,0
0,0,0,0,0,0,0,0,0,0,0,3
0,0,0,0,0,0,0,0,0,0,0,0
3,0,0,0,0,0,0,0,0,0,0,0
3,3,0,0,0,3,3,3,0,0,0,0
3,0,0,0,0,0,3,0,0,0,0,0
0,0,0,0,0,0,0,0,0,0,0,0
0,0,0,0,0,0,0,0,0,0,0,0
1,3,0,0,0,3,1,0,0,0,0,0
endlayer

layer
0,3,3,3,3,0,0,0,3,3,3,0
0,0,0,0,0,0,0,0,0,0,0,0
0,0,0,0,0,0,0,0,0,0,0,3
0,0,0,0,0,0,0,0,0,0,0,0
3,0,0,0,0,0,0,0,0,0,0,0
3,3,0,0,0,3,3,3,3,3,0,0
0,0,0,0,0,0,3,0,0,0,0,0
0,0,0,0,0,0,3,0,0,0,0,0
0,0,0,0,0,0,0,0,0,0,0,0
0,3,0,0,0,3,1,0,0,0,0,0
endlayer

layer
0,5,5,5,5,0,0,0,5,5,0,0
0,3,0,0,0,0,0,0,3,0,0,0
3,0,0,0,0,0,0,0,0,0,0,3
0,0,0,0,0,0,0,0,0,0,0,3
3,0,0,0,0,0,0,3,3,3,3,0
3,3,0,0,0,0,0,6,6,6,0,0
0,0,0,0,0,0,7,0,0,0,0,0
0,0,0,0,0,0,7,0,0,0,0,0
0,0,0,0,0,0,0,0,0,0,0,0
0,3,3,0,3,3,7,0,0,0,0,0
endlayer

layer
0,0,0,0,0,0,0,0,0,0,0,0
0,5,0,5,5,5,5,5,0,0,0,0
3,3,3,3,3,3,0,3,0,0,0,0
3,0,0,3,3,0,3,3,0,0,0,3
6,3,3,3,0,0,0,6,0,0,0,6
0,8,3,3,3,0,0,0,0,0,0,0
0,8,0,0,0,0,0,0,0,0,0,0
0,8,0,0,0,0,0,0,0,0,0,0
0,0,0,0,0,0,0,0,0,0,0,0
0,8,3,3,3,7,0,0,0,0,0,0
endlayer

layer
0,0,0,0,0,0,0,0,0,0,0,0
0,0,0,0,0,0,0,0,0,0,0,0
5,5,0,5,5,5,5,5,0,0,0,0
6,0,0,0,3,6,6,6,0,0,0,6
0,0,8,3,7,0,0,0,0,0,0,0
0,0,8,3,0,0,0,0,0,0,0,0
0,0,8,3,7,0,0,0,0,0,0,0
0,0,0,0,0,0,0,0,0,0,0,0
0,0,8,0,7,0,0,0,0,0,0,0
0,0,8,3,7,0,0,0,0,0,0,0
endlayer

