weight=5
embed_into_distance=9
acceptable_target_blocks=1,2,3,12,13
dimensions=9,11,11
allowable_overhang=8
max_cut_in=0
cut_in_buffer=0
max_leveling=0
leveling_buffer=0
preserve_water=0
preserve_lava=0
preserve_plants=1


rule1=0,100,98,98,98,98,98,98-2,98-2,98-1
rule2=0,100,26-9
rule3=0,100,26-1
rule4=0,100,HardMobSpawn,0
rule5=0,100,26-10
rule6=0,100,26-2
rule7=0,100,43
rule8=0,100,44-5
rule9=0,100,109-2
rule10=0,100,109
rule11=0,100,11
rule12=0,100,109-1
rule13=0,100,HardMobSpawn,0
rule14=0,100,101
rule15=0,100,61-2
rule16=0,100,98-3
rule17=0,0,35-5


layer
1,1,1,1,1,1,1,1,1,1,1
1,1,1,1,1,1,1,1,1,1,1
1,1,1,1,1,1,1,1,1,1,1
1,1,1,1,1,1,1,1,1,1,1
1,1,1,1,1,1,1,1,1,1,1
1,1,1,1,1,1,1,1,1,1,1
1,1,1,1,1,1,1,1,1,1,1
1,1,1,1,1,1,1,1,1,1,1
1,1,1,1,1,1,1,1,1,1,1
1,1,1,1,1,1,1,1,1,1,1
1,1,1,1,1,1,1,1,1,1,1
endlayer

layer
1,1,1,1,1,0,0,1,1,1,1
1,10,8,0,0,0,0,1,0,2,1
1,11,9,0,7,0,0,1,0,3,1
1,12,8,0,0,0,0,1,0,4,1
1,1,1,1,0,0,0,1,0,1,1
0,0,0,0,0,0,0,0,0,0,0
0,0,0,0,0,0,0,0,0,0,0
1,1,0,1,0,0,0,1,1,1,1
1,13,0,4,1,0,0,0,0,0,1
1,13,0,4,1,0,0,1,6,5,1
1,1,1,1,1,0,0,1,1,1,1
endlayer

layer
1,1,1,1,1,0,0,1,1,1,1
15,0,0,0,0,0,0,1,0,0,1
1,0,0,0,0,0,0,1,0,0,1
15,0,0,0,0,0,0,1,0,0,1
1,14,14,14,0,0,0,1,0,1,1
0,0,0,0,0,0,0,0,0,0,0
0,0,0,0,0,0,0,0,0,0,0
1,1,0,1,0,0,0,1,1,1,1
1,0,0,0,1,0,0,0,0,0,1
1,0,0,0,1,0,0,1,0,0,1
1,1,1,1,1,0,0,1,1,1,1
endlayer

layer
1,1,1,1,1,1,1,1,1,1,1
1,1,1,1,1,1,1,1,1,1,1
1,0,0,0,0,0,0,1,1,1,1
1,0,0,0,0,0,0,1,1,1,1
1,1,1,1,0,0,0,1,16,1,1
1,1,0,0,0,0,0,0,0,1,1
1,1,0,0,0,0,0,0,0,1,1
1,1,16,1,1,0,0,1,1,1,1
1,0,0,0,1,0,0,16,1,1,1
1,0,0,0,1,1,1,1,1,1,1
1,1,1,1,1,1,1,1,1,1,1
endlayer

layer
17,17,17,17,17,17,17,17,17,17,17
17,17,17,17,17,17,17,17,17,17,17
17,17,17,17,17,17,17,17,17,17,17
17,17,17,17,17,17,17,17,17,17,17
17,17,17,17,17,17,17,17,17,17,17
17,17,17,17,17,17,17,17,17,17,17
17,17,17,17,17,17,17,17,17,17,17
17,17,17,17,17,17,17,17,17,17,17
17,17,17,17,17,17,17,17,17,17,17
17,17,17,17,17,17,17,17,17,17,17
17,17,17,17,17,17,17,17,17,17,17
endlayer

layer
17,17,17,17,17,17,17,17,17,17,17
17,17,17,17,17,17,17,17,17,17,17
17,17,17,17,17,17,17,17,17,17,17
17,17,17,17,17,17,17,17,17,17,17
17,17,17,17,17,17,17,17,17,17,17
17,17,17,17,17,17,17,17,17,17,17
17,17,17,17,17,17,17,17,17,17,17
17,17,17,17,17,17,17,17,17,17,17
17,17,17,17,17,17,17,17,17,17,17
17,17,17,17,17,17,17,17,17,17,17
17,17,17,17,17,17,17,17,17,17,17
endlayer

layer
17,17,17,17,17,17,17,17,17,17,17
17,17,17,17,17,17,17,17,17,17,17
17,17,17,17,17,17,17,17,17,17,17
17,17,17,17,17,17,17,17,17,17,17
17,17,17,17,17,17,17,17,17,17,17
17,17,17,17,17,17,17,17,17,17,17
17,17,17,17,17,17,17,17,17,17,17
17,17,17,17,17,17,17,17,17,17,17
17,17,17,17,17,17,17,17,17,17,17
17,17,17,17,17,17,17,17,17,17,17
17,17,17,17,17,17,17,17,17,17,17
endlayer

layer
17,17,17,17,17,17,17,17,17,17,17
17,17,17,17,17,17,17,17,17,17,17
17,17,17,17,17,17,17,17,17,17,17
17,17,17,17,17,17,17,17,17,17,17
17,17,17,17,17,17,17,17,17,17,17
17,17,17,17,17,17,17,17,17,17,17
17,17,17,17,17,17,17,17,17,17,17
17,17,17,17,17,17,17,17,17,17,17
17,17,17,17,17,17,17,17,17,17,17
17,17,17,17,17,17,17,17,17,17,17
17,17,17,17,17,17,17,17,17,17,17
endlayer

layer
17,17,17,17,17,17,17,17,17,17,17
17,17,17,17,17,17,17,17,17,17,17
17,17,17,17,17,17,17,17,17,17,17
17,17,17,17,17,17,17,17,17,17,17
17,17,17,17,17,17,17,17,17,17,17
17,17,17,17,17,17,17,17,17,17,17
17,17,17,17,17,17,17,17,17,17,17
17,17,17,17,17,17,17,17,17,17,17
17,17,17,17,17,17,17,17,17,17,17
17,17,17,17,17,17,17,17,17,17,17
17,17,17,17,17,17,17,17,17,17,17
endlayer

