# Author: ksheep
# From: Minecraft Forums

weight=2
embed_into_distance=1
acceptable_target_blocks=87,88,10,11
dimensions=5,7,8
allowable_overhang=28
max_cut_in=2
cut_in_buffer=1
max_leveling=2
leveling_buffer=1
preserve_water=0
preserve_lava=0
preserve_plants=0

rule1=0,100,87,87,88
rule2=0,100,49
rule3=1,75,89
rule4=1,50,87
rule5=2,75,89
rule6=1,20,51-0

layer
5,1,1,1,1,1,1,5
1,1,1,1,1,1,1,1
1,1,1,1,1,1,1,1
1,1,2,2,2,2,1,1
1,1,1,1,1,1,1,1
1,1,1,1,1,1,1,1
5,1,1,1,1,1,1,5
endlayer

layer
5,4,4,6,6,4,4,5
4,4,6,6,6,6,4,4
4,6,6,6,6,6,6,4
6,6,2,6,6,2,6,0
4,6,6,6,6,6,6,4
4,4,6,6,6,6,4,4
5,4,4,6,6,4,4,5
endlayer

layer
5,4,5,0,0,5,4,5
4,5,0,0,0,0,5,4
5,0,0,0,0,0,0,5
0,0,2,0,0,2,0,0
5,0,0,0,0,0,0,5
4,5,0,0,0,0,5,4
5,4,5,0,0,5,4,5
endlayer

layer
5,3,0,0,0,0,3,5
3,0,0,0,0,0,0,3
0,0,0,0,0,0,0,0
0,0,2,0,0,2,0,0
0,0,0,0,0,0,0,0
3,0,0,0,0,0,0,3
5,3,0,0,0,0,3,5
endlayer


layer
3,0,0,0,0,0,0,3
0,0,0,0,0,0,0,0
0,0,0,0,0,0,0,0
0,0,2,2,2,2,0,0
0,0,0,0,0,0,0,0
0,0,0,0,0,0,0,0
3,0,0,0,0,0,0,3
endlayer