#Fishing Shack
# Author: Mosslander
# From: Town Pack

weight=10
embed_into_distance=10
acceptable_target_blocks=8,9,79
dimensions=14,6,7
allowable_overhang=7
max_cut_in=9
cut_in_buffer=0
max_leveling=0
leveling_buffer=0
preserve_water=0
preserve_lava=0
preserve_plants=0

rule1=0,100,5
rule2=0,100,60
rule3=0,100,20
rule4=0,100,44
rule5=0,100,50
rule6=0,100,54
rule7=0,100,58
rule8=0,100,17
rule9=0,100,17-1
rule10=0,100,300
rule11=0,100,53-3
rule12=0,100,53-2

layer
10,10,10,10,10,10,10
10,9,10,10,10,9,10
10,10,10,10,10,10,10
10,10,10,10,10,10,10
10,9,10,10,10,9,10
10,10,10,10,10,10,10
endlayer

layer
10,10,10,10,10,10,10
10,9,10,10,10,9,10
10,10,10,10,10,10,10
10,10,10,10,10,10,10
10,9,10,10,10,9,10
10,10,10,10,10,10,10
endlayer

layer
10,10,10,10,10,10,10
10,9,10,10,10,9,10
10,10,10,10,10,10,10
10,10,10,10,10,10,10
10,9,10,10,10,9,10
10,10,10,10,10,10,10
endlayer

layer
10,10,10,10,10,10,10
10,9,10,10,10,9,10
10,10,10,10,10,10,10
10,10,10,10,10,10,10
10,9,10,10,10,9,10
10,10,10,10,10,10,10
endlayer

layer
10,10,10,10,10,10,10
10,9,10,10,10,9,10
10,10,10,10,10,10,10
10,10,10,10,10,10,10
10,9,10,10,10,9,10
10,10,10,10,10,10,10
endlayer

layer
10,10,10,10,10,10,10
10,9,10,10,10,9,10
10,10,10,10,10,10,10
10,10,10,10,10,10,10
10,9,10,10,10,9,10
10,10,10,10,10,10,10
endlayer

layer
10,10,10,10,10,10,10
10,9,10,10,10,9,10
10,10,10,10,10,10,10
10,10,10,10,10,10,10
10,9,10,10,10,9,10
10,10,10,10,10,10,10
endlayer

layer
10,10,10,10,10,10,10
10,9,10,10,10,9,10
10,10,10,10,10,10,10
10,10,10,10,10,10,10
10,9,10,10,10,9,10
10,10,10,10,10,10,10
endlayer

layer
10,10,10,10,10,10,10
10,9,10,10,10,9,10
10,10,10,10,10,10,10
10,10,10,10,10,10,10
10,9,10,10,10,9,10
10,10,10,10,10,10,10
endlayer

layer
1,1,1,1,1,1,1
1,1,1,1,1,1,1
1,1,1,10,1,1,1
1,1,6,1,7,1,1
1,1,1,1,1,1,1
1,1,1,1,1,1,1
endlayer

layer
0,0,0,0,0,0,0
0,9,8,8,8,9,0
0,8,12,0,11,8,0
0,8,0,0,0,8,0
0,9,8,0,8,9,0
0,0,0,0,0,0,0
endlayer

layer
0,0,0,0,0,0,0
0,9,8,3,8,9,0
0,8,0,0,0,8,0
0,8,0,0,5,8,0
0,9,8,0,8,9,0
0,0,0,0,0,0,0
endlayer

layer
0,0,0,0,0,0,0
0,9,8,8,8,9,0
0,8,0,0,0,8,0
0,8,0,0,0,8,0
0,9,8,8,8,9,0
0,0,0,0,0,0,0
endlayer

layer
0,0,0,0,0,0,0
0,4,4,4,4,4,0
0,4,4,4,4,4,0
0,4,4,4,4,4,0
0,4,4,4,4,4,0
0,0,0,0,0,0,0
endlayer
