# Author: RoofFiddler
# From: Minecraft Forums

weight=5
embed_into_distance=1
acceptable_target_blocks=1,3,12,13,82
dimensions=7,9,15
allowable_overhang=2
max_cut_in=7
cut_in_buffer=0
max_leveling=2
leveling_buffer=0
preserve_water=1
preserve_lava=0
preserve_plants=0

rule1=0,100,0,4,48
rule2=0,100,4,48
rule3=1,80,4,48
rule4=1,75,4,48
rule5=2,75,4,48
rule6=2,50,4,48

layer
1,1,1,1,1,1,1,1,1,1,1,1,1,1,1
1,1,1,1,1,1,1,1,1,1,1,1,1,1,1
1,1,1,1,1,1,1,1,1,1,1,1,1,1,1
1,1,1,1,1,1,1,1,1,1,1,1,1,1,1
1,1,1,1,1,1,1,1,1,1,1,1,1,1,1
1,1,1,1,1,1,1,1,1,1,1,1,1,1,1
1,1,1,1,1,1,1,1,1,1,1,1,1,1,1
1,1,1,1,1,1,1,1,1,1,1,1,1,1,1
1,1,1,1,1,1,1,1,1,1,1,1,1,1,1
endlayer

layer
0,3,0,0,0,0,0,3,0,0,0,0,0,3,0
3,2,3,0,0,0,3,2,3,0,0,0,3,2,3
0,3,0,0,0,0,0,3,0,0,0,0,0,3,0
0,0,0,0,0,0,0,0,0,0,0,0,0,0,0
0,0,0,0,0,0,0,0,0,0,0,0,0,0,0
0,0,0,0,0,0,0,0,0,0,0,0,0,0,0
0,3,0,0,0,0,0,3,0,0,0,0,0,3,0
3,2,3,0,0,0,3,2,3,0,0,0,3,2,3
0,3,0,0,0,0,0,3,0,0,0,0,0,3,0
endlayer

layer
0,0,0,0,0,0,0,0,0,0,0,0,0,0,0
0,3,0,0,0,0,0,3,0,0,0,0,0,3,0
0,0,0,0,0,0,0,0,0,0,0,0,0,0,0
0,0,0,0,0,0,0,0,0,0,0,0,0,0,0
0,0,0,0,0,0,0,0,0,0,0,0,0,0,0
0,0,0,0,0,0,0,0,0,0,0,0,0,0,0
0,0,0,0,0,0,0,0,0,0,0,0,0,0,0
0,3,0,0,0,0,0,3,0,0,0,0,0,3,0
0,0,0,0,0,0,0,0,0,0,0,0,0,0,0
endlayer

layer
0,0,0,0,0,0,0,0,0,0,0,0,0,0,0
0,3,0,0,0,0,0,3,0,0,0,0,0,3,0
0,0,0,0,0,0,0,0,0,0,0,0,0,0,0
0,0,0,0,0,0,0,0,0,0,0,0,0,0,0
0,0,0,0,0,0,0,0,0,0,0,0,0,0,0
0,0,0,0,0,0,0,0,0,0,0,0,0,0,0
0,0,0,0,0,0,0,0,0,0,0,0,0,0,0
0,3,0,0,0,0,0,3,0,0,0,0,0,3,0
0,0,0,0,0,0,0,0,0,0,0,0,0,0,0
endlayer

layer
0,0,0,0,0,0,0,0,0,0,0,0,0,0,0
5,3,5,0,0,0,5,3,5,0,0,0,5,3,5
0,5,0,0,0,0,0,5,0,0,0,0,0,5,0
0,0,0,0,0,0,0,0,0,0,0,0,0,0,0
0,0,0,0,0,0,0,0,0,0,0,0,0,0,0
0,0,0,0,0,0,0,0,0,0,0,0,0,0,0
0,5,0,0,0,0,0,5,0,0,0,0,0,5,0
5,3,5,0,0,0,5,3,5,0,0,0,5,3,5
0,0,0,0,0,0,0,0,0,0,0,0,0,0,0
endlayer

layer
0,0,0,0,0,0,0,0,0,0,0,0,0,0,0
4,0,4,5,0,5,4,0,4,5,0,5,4,0,4
0,4,0,0,0,0,0,4,0,0,0,0,0,4,0
0,5,0,0,0,0,0,5,0,0,0,0,0,5,0
0,0,0,0,0,0,0,0,0,0,0,0,0,0,0
0,5,0,0,0,0,0,5,0,0,0,0,0,5,0
0,4,0,0,0,0,0,4,0,0,0,0,0,4,0
4,0,4,5,0,5,4,0,4,5,0,5,4,0,4
0,0,0,0,0,0,0,4,0,0,0,0,0,0,0
endlayer

layer
0,0,0,0,0,0,0,0,0,0,0,0,0,0,0
0,0,0,4,6,4,0,0,0,4,6,4,0,0,0
0,0,0,0,0,0,0,0,0,0,0,0,0,0,0
0,4,0,0,0,0,0,4,0,0,0,0,0,4,0
0,6,0,0,0,0,0,6,0,0,0,0,0,6,0
0,4,0,0,0,0,0,4,0,0,0,0,0,4,0
0,0,0,0,0,0,0,0,0,0,0,0,0,0,0
0,0,0,4,6,4,0,0,0,4,6,4,0,0,0
0,0,0,0,0,0,0,0,0,0,0,0,0,0,0
endlayer
