# Author: d00dv4d3r
# From: Default Template

weight=12
embed_into_distance=1
acceptable_target_blocks=1,3,12,13,82
dimensions=5,7,7
allowable_overhang=2
max_cut_in=2
cut_in_buffer=0
max_leveling=2
leveling_buffer=0
preserve_water=1
preserve_lava=0
preserve_plants=0

rule1=0,100,0,4,48,44-3
rule2=0,100,4,48
rule3=1,50,4,48
rule4=2,50,4,48
rule5=0,100,preserveBlock

layer
5,5,2,2,2,5,5
5,2,1,1,1,2,5
2,1,1,1,1,1,2
2,1,1,1,1,1,2
2,1,1,1,1,1,2
5,2,1,1,1,2,5
5,5,2,2,2,5,5
endlayer

layer
0,0,3,3,3,0,0
0,3,0,0,0,3,0
3,0,0,0,0,0,3
3,0,0,0,0,0,3
3,0,0,0,0,0,3
0,3,0,0,0,3,0
0,0,3,3,3,0,0
endlayer

layer
0,0,3,3,3,0,0
0,3,0,0,0,3,0
3,0,0,0,0,0,3
3,0,0,0,0,0,3
3,0,0,0,0,0,3
0,3,0,0,0,3,0
0,0,3,3,3,0,0
endlayer

layer
0,0,3,3,3,0,0
0,3,0,0,0,3,0
3,0,0,0,0,0,3
3,0,0,0,0,0,3
3,0,0,0,0,0,3
0,3,0,0,0,3,0
0,0,3,3,3,0,0
endlayer

layer
0,0,3,3,3,0,0
0,3,4,4,4,3,0
3,4,4,4,4,4,3
3,4,4,4,4,4,3
3,4,4,4,4,4,3
0,3,4,4,4,3,0
0,0,3,3,3,0,0
endlayer
