weight=5
embed_into_distance=7
acceptable_target_blocks=1,2,3,12,13
dimensions=7,11,11
cut_in_buffer=0
max_leveling=0
leveling_buffer=0
preserve_water=0
preserve_lava=0
preserve_plants=0
max_cut_in=2


rule1=0,100,preserveBlock
rule2=0,100,4,4,4,48
rule3=0,100,13
rule4=0,100,67-3
rule5=0,100,67-1
rule6=0,100,67
rule7=0,100,67-2
rule8=0,50,4,48
rule9=0,100,44-3


layer
1,1,1,1,1,1,1,1,1,1,1
1,1,1,1,2,2,2,1,1,1,1
1,1,1,2,2,2,2,2,1,1,1
1,1,2,2,3,3,3,2,2,1,1
1,2,2,3,3,3,3,3,2,2,1
1,2,2,3,3,3,3,3,2,2,1
1,2,2,3,3,3,3,3,2,2,1
1,1,2,2,3,3,3,2,2,1,1
1,1,1,2,2,2,2,2,1,1,1
1,1,1,1,2,2,2,1,1,1,1
1,1,1,1,1,1,1,1,1,1,1
endlayer

layer
1,1,1,1,1,1,1,1,1,1,1
1,1,1,1,2,2,2,1,1,1,1
1,1,1,2,2,2,2,2,1,1,1
1,1,2,2,0,0,0,2,2,1,1
1,2,2,0,0,0,0,0,2,2,1
1,2,2,0,0,0,0,0,2,2,1
1,2,2,0,0,0,0,0,2,2,1
1,1,2,2,0,0,0,2,2,1,1
1,1,1,2,2,2,2,2,1,1,1
1,1,1,1,2,2,2,1,1,1,1
1,1,1,1,1,1,1,1,1,1,1
endlayer

layer
1,1,1,1,1,1,1,1,1,1,1
1,1,1,1,2,2,2,1,1,1,1
1,1,1,2,0,0,0,2,1,1,1
1,1,2,2,0,0,0,2,2,1,1
1,2,0,0,0,0,0,0,0,2,1
1,2,0,0,0,0,0,0,0,2,1
1,2,0,0,0,0,0,0,0,2,1
1,1,2,2,0,0,0,2,2,1,1
1,1,1,2,0,0,0,2,1,1,1
1,1,1,1,2,2,2,1,1,1,1
1,1,1,1,1,1,1,1,1,1,1
endlayer

layer
1,1,1,1,1,1,1,1,1,1,1
1,1,1,1,2,2,2,1,1,1,1
1,1,1,2,2,0,2,2,1,1,1
1,1,2,2,0,0,0,2,2,1,1
1,2,2,0,0,0,0,0,2,2,1
1,2,0,0,0,0,0,0,0,2,1
1,2,2,0,0,0,0,0,2,2,1
1,1,2,2,0,0,0,2,2,1,1
1,1,1,2,2,0,2,2,1,1,1
1,1,1,1,2,2,2,1,1,1,1
1,1,1,1,1,1,1,1,1,1,1
endlayer

layer
1,1,1,1,1,1,1,1,1,1,1
1,1,1,1,2,2,2,1,1,1,1
1,1,1,2,2,2,2,2,1,1,1
1,1,2,2,0,0,0,2,2,1,1
1,2,2,0,0,0,0,0,2,2,1
1,2,2,0,0,0,0,0,2,2,1
1,2,2,0,0,0,0,0,2,2,1
1,1,2,2,0,0,0,2,2,1,1
1,1,1,2,2,2,2,2,1,1,1
1,1,1,1,2,2,2,1,1,1,1
1,1,1,1,1,1,1,1,1,1,1
endlayer

layer
1,1,1,1,1,1,1,1,1,1,1
1,1,1,2,2,2,2,2,1,1,1
1,1,2,2,2,2,2,2,2,1,1
1,2,2,2,5,5,5,2,2,2,1
1,2,2,7,0,0,0,4,2,2,1
1,2,2,7,0,0,0,4,2,2,1
1,2,2,7,0,0,0,4,2,2,1
1,2,2,2,6,6,6,2,2,2,1
1,1,2,2,2,2,2,2,2,1,1
1,1,1,2,2,2,2,2,1,1,1
1,1,1,1,1,1,1,1,1,1,1
endlayer

layer
1,1,8,8,8,8,8,8,8,1,1
1,8,2,5,5,5,5,5,2,8,1
8,2,9,0,0,0,0,0,9,2,8
8,7,0,0,0,0,0,0,0,4,8
8,7,0,0,0,0,0,0,0,4,8
8,7,0,0,0,0,0,0,0,4,8
8,7,0,0,0,0,0,0,0,4,8
8,7,0,0,0,0,0,0,0,4,8
8,2,9,0,0,0,0,0,9,2,8
1,8,2,6,6,6,6,6,2,8,1
1,1,8,8,8,8,8,8,8,1,1
endlayer

