weight=17
embed_into_distance=1
acceptable_target_blocks=1,2,3,13
dimensions=4,9,9
max_leveling=2
cut_in_buffer=0
max_leveling=2
leveling_buffer=1
preserve_water=0
preserve_lava=0
preserve_plants=0
max_cut_in=10

rule1=0,100,preserveBlock
rule2=0,100,98-1,98-1,98-2,98-2,98,preserveBlock,preserveBlock,preserveBlock
rule3=0,100,13
rule4=0,100,98-1,98-1,98-2,98-2,98
rule5=0,100,109-2,109-2,109-2,109-2,98-1,98-2
rule6=0,50,44-5
rule7=0,100,9,9,9,9,9,9,9,9,9,9,9,9,9,13
rule8=0,100,109-1,109-1,109-1,109-1,98-1,98-2
rule9=0,100,109,109,109,109,98-1,98-2
rule10=0,100,109-3,109-3,109-3,109-3,98-1,98-2
rule11=0,15,111
rule12=0,75,98-1,98-1,98-2,98-2,98
rule13=1,40,8


layer
2,2,2,2,2,2,2,1,1
2,3,3,3,3,3,2,1,1
2,3,3,3,3,3,2,2,2
2,3,3,3,3,3,3,3,2
2,3,3,3,3,3,3,3,2
2,3,3,3,3,3,3,3,2
2,2,2,3,3,3,3,3,2
1,1,2,3,3,3,3,3,2
1,1,2,2,2,2,2,2,2
endlayer

layer
0,0,0,0,0,0,0,0,0
0,4,9,9,9,4,0,0,0
0,10,7,7,7,4,6,0,0
0,10,7,4,7,4,4,4,0
0,10,7,7,7,7,7,5,0
0,4,4,4,7,4,7,5,0
0,0,6,4,7,7,7,5,0
0,0,0,4,8,8,8,4,0
0,0,0,0,0,0,0,0,0
endlayer

layer
0,0,0,0,0,0,0,0,0
0,0,0,0,0,0,0,0,0
0,0,11,11,11,0,0,0,0
0,0,11,12,11,0,0,0,0
0,0,11,11,11,11,11,0,0
0,0,0,0,11,12,11,0,0
0,0,0,0,11,11,11,0,0
0,0,0,0,0,0,0,0,0
0,0,0,0,0,0,0,0,0
endlayer

layer
0,0,0,0,0,0,0,0,0
0,0,0,0,0,0,0,0,0
0,0,0,0,0,0,0,0,0
0,0,0,13,0,0,0,0,0
0,0,0,0,0,0,0,0,0
0,0,0,0,0,13,0,0,0
0,0,0,0,0,0,0,0,0
0,0,0,0,0,0,0,0,0
0,0,0,0,0,0,0,0,0
endlayer

