
# Created by Ruins mod version 13.0 Ingame Parser
# authoring Player: AtomicStryker
# Updated to MC 1.9: 21 Apr 2016

biomesToSpawnIn=ocean,deep ocean,kelp forest,ocean oil field,oceanic abyss,coral reef
weight=5
embed_into_distance=1
acceptable_target_blocks=

unacceptable_target_blocks=flowing_lava,lava,Natura:Cloud

dimensions=13,26,8
allowable_overhang=12
max_leveling=5
leveling_buffer=0
preserve_water=1
preserve_lava=0
preserve_plants=0

rule1=0,100,minecraft:mossy_cobblestone-0
rule2=0,100,minecraft:planks-0
rule3=0,25,ChestGenHook:chests/simple_dungeon:3-5
rule4=0,25,ChestGenHook:chests/simple_dungeon:3-4
rule5=0,100,minecraft:log-0
rule6=0,100,preserveBlock

layer
6,6,6,6,6,6,6,6
6,6,6,1,1,1,6,6
6,1,6,1,1,1,1,6
6,1,1,1,1,1,1,6
6,1,1,1,1,1,1,6
6,6,6,6,2,1,1,6
6,6,6,6,2,1,6,6
6,6,6,6,2,6,6,6
6,6,6,6,2,6,6,6
6,6,6,1,2,6,6,6
6,6,1,1,2,6,6,6
6,6,1,1,2,6,6,6
6,6,1,1,2,6,6,6
6,6,6,6,2,1,6,6
6,6,6,6,2,1,1,1
6,6,6,6,2,1,6,6
6,6,6,6,2,6,6,6
6,6,6,6,2,6,6,6
6,6,6,6,2,6,6,6
6,6,1,1,2,6,6,6
6,1,1,1,2,6,6,6
6,6,1,1,2,6,6,6
6,6,6,6,2,1,1,1
6,6,6,6,2,1,1,6
6,6,1,1,2,1,6,6
6,6,1,1,1,1,6,6
endlayer

layer
6,6,6,6,6,6,6,6
6,6,6,6,6,6,6,6
6,6,6,6,6,1,1,6
6,6,1,1,1,1,1,6
6,6,6,6,2,1,6,6
6,6,6,2,2,2,6,6
6,6,6,2,2,2,6,6
6,6,6,2,2,2,6,6
6,6,2,2,2,2,2,6
6,6,2,2,2,2,2,6
6,6,6,6,2,2,2,6
6,6,2,6,6,2,2,6
6,6,2,2,2,2,2,6
6,6,2,2,2,2,2,6
6,6,2,2,2,2,2,6
6,6,2,2,2,2,2,6
6,6,2,2,2,2,2,6
6,6,2,2,2,2,2,6
6,6,2,2,2,2,2,6
6,6,2,2,2,2,2,6
6,6,2,2,2,2,2,6
6,6,2,2,2,2,2,6
6,6,2,2,2,2,2,6
6,6,2,2,2,2,2,6
6,6,2,2,2,2,2,6
6,6,6,6,6,6,6,6
endlayer

layer
6,6,6,6,6,6,6,6
6,6,6,6,6,6,6,6
6,6,6,6,1,1,1,6
6,6,1,1,2,1,6,6
6,6,6,2,3,2,6,6
6,6,6,2,6,2,6,6
6,6,6,6,6,2,6,6
6,6,2,6,6,6,2,6
6,6,2,6,6,6,2,6
6,6,2,6,6,6,2,6
6,6,6,6,6,6,2,6
6,6,2,6,6,6,2,6
6,6,2,6,6,6,6,6
6,6,2,6,6,6,2,6
6,6,2,6,6,6,2,6
6,6,2,6,6,6,2,6
6,6,2,6,6,2,2,6
6,6,2,6,6,2,2,6
6,6,2,6,6,2,6,6
6,6,2,6,6,6,6,6
6,6,2,2,6,2,2,6
6,6,2,6,6,6,2,6
6,6,2,6,2,6,2,6
6,6,2,4,2,4,2,6
6,6,2,2,2,2,2,6
6,6,6,6,6,6,6,6
endlayer

layer
6,6,6,6,6,6,6,6
6,6,6,6,6,6,6,6
6,6,1,1,1,1,6,6
6,6,1,1,2,1,6,6
6,6,1,2,6,2,6,6
6,6,6,6,6,2,6,6
6,6,6,6,6,2,6,6
6,6,2,6,6,6,2,6
6,6,2,6,6,6,2,6
6,6,2,6,6,6,2,6
6,6,6,6,6,6,2,6
6,6,6,6,6,6,6,6
6,6,2,6,6,6,6,6
6,6,2,6,6,6,2,6
6,6,2,6,6,6,2,6
6,6,2,6,6,6,2,6
6,6,2,6,6,6,2,6
6,6,2,6,6,2,2,6
6,6,2,6,6,2,6,6
6,6,2,6,6,6,6,6
6,6,2,2,6,2,2,6
6,6,2,6,6,6,2,6
6,6,2,6,6,6,2,6
6,6,2,6,2,6,2,6
6,6,2,2,2,2,2,6
6,6,6,6,6,6,6,6
endlayer

layer
6,6,6,6,6,6,6,6
6,6,6,6,6,6,6,6
6,6,1,1,2,6,6,6
6,6,1,2,2,2,6,6
6,6,6,6,2,2,6,6
6,6,6,6,2,2,6,6
6,6,2,6,6,2,2,6
6,6,2,2,2,2,2,6
6,6,2,2,2,2,2,6
6,6,2,2,2,2,2,6
6,6,6,6,6,6,6,6
6,6,6,6,6,6,6,6
6,6,6,6,6,6,6,6
6,6,2,2,2,2,2,6
6,6,2,2,2,2,2,6
6,6,2,2,2,6,2,6
6,6,2,6,2,6,2,6
6,6,6,6,2,6,2,6
6,6,2,2,2,2,2,6
6,6,2,2,2,2,2,6
6,6,2,2,2,2,2,6
6,6,2,2,6,2,2,6
6,6,2,2,6,2,2,6
6,6,2,2,6,2,2,6
6,6,2,2,2,2,2,6
6,6,6,6,6,6,6,6
endlayer

layer
6,6,6,6,6,6,6,6
6,6,6,1,2,6,6,6
6,6,1,1,3,2,6,6
6,6,6,2,6,2,6,6
6,6,6,6,6,2,6,6
6,6,6,6,6,6,2,6
6,6,2,6,6,6,2,6
6,6,2,2,2,6,2,6
6,6,6,6,2,6,6,6
6,6,6,6,2,6,6,6
6,6,6,6,6,6,6,6
6,6,6,6,6,6,6,6
6,6,6,6,6,6,6,6
6,6,6,6,6,6,6,6
6,6,6,6,5,6,6,6
6,6,6,6,6,6,6,6
6,6,6,6,6,6,6,6
6,6,6,6,6,6,6,6
6,6,6,6,6,6,6,6
6,6,6,6,6,6,6,6
6,2,2,2,2,2,2,2
6,2,3,6,6,6,3,2
6,2,6,6,6,6,6,2
6,2,6,6,6,6,6,2
6,2,6,6,6,6,6,6
6,2,2,2,2,2,2,6
endlayer

layer
6,6,6,6,6,6,6,6
6,6,6,1,2,6,6,6
6,6,6,2,6,2,6,6
6,6,6,2,6,2,6,6
6,6,6,6,6,2,6,6
6,6,2,6,6,6,2,6
6,6,2,6,6,6,2,6
6,6,2,2,2,6,2,6
6,6,6,6,2,6,6,6
6,6,6,6,6,6,6,6
6,6,6,6,6,6,6,6
6,6,6,6,6,6,6,6
6,6,6,6,6,6,6,6
6,6,6,6,6,6,6,6
6,6,6,6,5,6,6,6
6,6,6,6,6,6,6,6
6,6,6,6,6,6,6,6
6,6,6,6,6,6,6,6
6,6,6,6,6,6,6,6
6,6,6,6,6,6,6,6
6,2,2,6,2,2,2,2
6,2,6,6,6,6,6,2
6,2,6,6,6,6,6,2
6,2,6,6,6,6,6,2
6,2,6,6,6,6,6,6
6,2,2,2,2,2,2,6
endlayer

layer
6,6,6,6,5,6,6,6
6,6,6,1,5,6,6,6
6,6,6,2,2,2,6,6
6,6,6,2,2,2,6,6
6,6,2,2,2,2,2,6
6,6,2,2,2,2,2,6
6,6,2,2,2,2,2,6
6,6,2,2,2,2,2,6
6,6,6,6,6,6,6,6
6,6,6,6,6,6,6,6
6,6,6,6,6,6,6,6
6,6,6,6,6,6,6,6
6,6,6,6,6,6,6,6
6,6,6,6,6,6,6,6
6,6,6,6,5,6,6,6
6,6,6,6,6,6,6,6
6,6,6,6,6,6,6,6
6,6,6,6,6,6,6,6
6,6,6,6,6,6,6,6
6,6,6,6,6,6,6,6
6,2,2,6,2,2,2,2
6,2,6,6,6,6,6,2
6,2,6,6,6,6,6,2
6,2,6,6,6,6,6,2
6,2,6,6,6,6,6,2
6,2,2,2,2,2,2,2
endlayer

layer
6,6,6,6,6,6,6,6
6,6,6,6,6,6,6,6
6,6,6,6,6,6,6,6
6,6,6,2,6,6,6,6
6,6,6,6,6,6,2,6
6,6,6,6,6,6,6,6
6,6,2,6,6,6,6,6
6,6,6,6,6,6,6,6
6,6,6,6,6,6,6,6
6,6,6,6,6,6,6,6
6,6,6,6,6,6,6,6
6,6,6,6,6,6,6,6
6,6,6,6,6,6,6,6
6,6,6,6,6,6,6,6
6,6,6,6,5,6,6,6
6,6,6,6,6,6,6,6
6,6,6,6,6,6,6,6
6,6,6,6,6,6,6,6
6,6,6,6,6,6,6,6
6,6,6,6,6,6,6,6
6,2,2,6,2,2,2,2
6,2,2,6,2,2,2,2
6,2,2,2,2,2,2,2
6,2,2,2,2,2,2,2
6,2,2,2,2,2,2,2
6,2,2,2,2,2,2,2
endlayer

layer
6,6,6,6,6,6,6,6
6,6,6,6,6,6,6,6
6,6,6,6,6,6,6,6
6,6,6,6,6,6,6,6
6,6,6,6,6,6,6,6
6,6,6,6,6,6,6,6
6,6,6,6,6,6,6,6
6,6,6,6,6,6,6,6
6,6,6,6,6,6,6,6
6,6,6,6,6,6,6,6
6,6,6,6,6,6,6,6
6,6,6,6,6,6,6,6
6,6,6,6,6,6,6,6
6,6,6,6,6,6,6,6
6,6,6,6,5,6,6,6
6,6,6,6,6,6,6,6
6,6,6,6,6,6,6,6
6,6,6,6,6,6,6,6
6,6,6,6,6,6,6,6
6,6,6,6,6,6,6,6
6,6,6,6,6,6,6,2
6,2,6,6,6,6,6,6
6,6,6,6,6,6,6,2
6,6,6,6,6,6,6,6
6,2,6,6,6,6,6,6
6,6,6,6,6,2,6,6
endlayer

layer
6,6,6,6,6,6,6,6
6,6,6,6,6,6,6,6
6,6,6,6,6,6,6,6
6,6,6,6,6,6,6,6
6,6,6,6,6,6,6,6
6,6,6,6,6,6,6,6
6,6,6,6,6,6,6,6
6,6,6,6,6,6,6,6
6,6,6,6,6,6,6,6
6,6,6,6,6,6,6,6
6,6,6,6,6,6,6,6
6,6,6,6,6,6,6,6
6,6,6,6,6,6,6,6
6,6,6,6,6,6,6,6
5,5,5,5,5,5,5,6
6,6,6,6,6,6,6,6
6,6,6,6,6,6,6,6
6,6,6,6,6,6,6,6
6,6,6,6,6,6,6,6
6,6,6,6,6,6,6,6
6,6,6,6,6,6,6,6
6,6,6,6,6,6,6,6
6,6,6,6,6,6,6,6
6,6,6,6,6,6,6,6
6,6,6,6,6,6,6,6
6,6,6,6,6,6,6,6
endlayer

layer
6,6,6,6,6,6,6,6
6,6,6,6,6,6,6,6
6,6,6,6,6,6,6,6
6,6,6,6,6,6,6,6
6,6,6,6,6,6,6,6
6,6,6,6,6,6,6,6
6,6,6,6,6,6,6,6
6,6,6,6,6,6,6,6
6,6,6,6,6,6,6,6
6,6,6,6,6,6,6,6
6,6,6,6,6,6,6,6
6,6,6,6,6,6,6,6
6,6,6,6,6,6,6,6
6,6,6,6,6,6,6,6
6,6,6,6,5,6,6,6
6,6,6,6,6,6,6,6
6,6,6,6,6,6,6,6
6,6,6,6,6,6,6,6
6,6,6,6,6,6,6,6
6,6,6,6,6,6,6,6
6,6,6,6,6,6,6,6
6,6,6,6,6,6,6,6
6,6,6,6,6,6,6,6
6,6,6,6,6,6,6,6
6,6,6,6,6,6,6,6
6,6,6,6,6,6,6,6
endlayer

layer
6,6,6,6,6,6,6,6
6,6,6,6,6,6,6,6
6,6,6,6,6,6,6,6
6,6,6,6,6,6,6,6
6,6,6,6,6,6,6,6
6,6,6,6,6,6,6,6
6,6,6,6,6,6,6,6
6,6,6,6,6,6,6,6
6,6,6,6,6,6,6,6
6,6,6,6,6,6,6,6
6,6,6,6,6,6,6,6
6,6,6,6,6,6,6,6
6,6,6,6,6,6,6,6
6,6,6,6,6,6,6,6
6,6,6,6,5,6,6,6
6,6,6,6,6,6,6,6
6,6,6,6,6,6,6,6
6,6,6,6,6,6,6,6
6,6,6,6,6,6,6,6
6,6,6,6,6,6,6,6
6,6,6,6,6,6,6,6
6,6,6,6,6,6,6,6
6,6,6,6,6,6,6,6
6,6,6,6,6,6,6,6
6,6,6,6,6,6,6,6
6,6,6,6,6,6,6,6
endlayer

