# Author: Arrrg
# From: Minecraft Forums

weight=1
embed_into_distance=60
acceptable_target_blocks=1,13
dimensions=83,3,3
allowable_overhang=0
unique=0
max_cut_in=0
cut_in_buffer=0
max_leveling=60
leveling_buffer=0
preserve_water=0
preserve_lava=0
preserve_plants=0

rule1=0,100,preserveBlock
rule2=1,75,44-2
rule3=2,100,50
rule4=0,100,1
rule5=0,100,85
rule6=2,90,53-0
rule7=2,90,53-1
rule8=0,100,8
rule9=2,100,65-5
rule10=2,100,65-4
rule11=2,100,65-2
rule12=2,100,65-3
rule13=0,100,13
rule14=0,100,89

layer
4,4,4,
4,4,4,
4,4,4,
endlayer
 
layer
8,8,8,
8,8,8,
8,8,8,
endlayer
 
layer
8,8,8,
8,8,8,
8,8,8,
endlayer
 
layer
0,0,0,
0,0,0,
0,0,0,
endlayer
 
layer
0,0,0,
0,0,0,
0,0,0,
endlayer
 
layer
0,0,0,
0,0,0,
0,0,0,
endlayer
 
layer
0,0,0,
0,0,0,
0,0,0,
endlayer
 
layer
0,0,0,
0,0,0,
0,0,0,
endlayer
 
layer
0,0,0,
0,0,0,
0,0,0,
endlayer
 
layer
0,0,0,
0,0,0,
0,0,0,
endlayer
 
layer
0,0,0,
0,0,0,
0,0,0,
endlayer
 
layer
0,0,0,
0,0,0,
0,0,0,
endlayer
 
layer
0,0,0,
0,0,0,
0,0,0,
endlayer
 
layer
0,0,0,
0,0,0,
0,0,0,
endlayer
 
layer
0,0,0,
0,0,0,
0,0,0,
endlayer
 
layer
0,0,0,
0,0,0,
0,0,0,
endlayer
 
layer
0,0,0,
0,0,0,
0,0,0,
endlayer
 
layer
0,0,0,
0,0,0,
0,0,0,
endlayer
 
layer
0,0,0,
0,0,0,
0,0,0,
endlayer
 
layer
0,0,0,
0,0,0,
0,0,0,
endlayer
 
layer
0,0,0,
0,0,0,
0,0,0,
endlayer
 
layer
0,0,0,
0,0,0,
0,0,0,
endlayer
 
layer
0,0,0,
0,0,0,
0,0,0,
endlayer
 
layer
0,0,0,
0,0,0,
0,0,0,
endlayer
 
layer
0,0,0,
0,0,0,
0,0,0,
endlayer
 
layer
0,0,0,
0,0,0,
0,0,0,
endlayer
 
layer
0,0,0,
0,0,0,
0,0,0,
endlayer
 
layer
0,0,0,
0,0,0,
0,0,0,
endlayer
 
layer
0,0,0,
0,0,0,
0,0,0,
endlayer
 
layer
0,0,0,
0,0,0,
0,0,0,
endlayer
 
layer
0,0,0,
0,0,0,
0,0,0,
endlayer
 
layer
0,0,0,
0,0,0,
0,0,0,
endlayer
 
layer
0,0,0,
0,0,0,
0,0,0,
endlayer
 
layer
0,0,0,
0,0,0,
0,0,0,
endlayer
 
layer
0,0,0,
0,0,0,
0,0,0,
endlayer
 
layer
0,0,0,
0,0,0,
0,0,0,
endlayer
 
layer
0,0,0,
0,0,0,
0,0,0,
endlayer
 
layer
0,0,0,
0,0,0,
0,0,0,
endlayer
 
layer
0,0,0,
0,0,0,
0,0,0,
endlayer
 
layer
0,0,0,
0,0,0,
0,0,0,
endlayer
 
layer
0,0,0,
0,0,0,
0,0,0,
endlayer
 
layer
0,0,0,
0,0,0,
0,0,0,
endlayer
 
layer
0,0,0,
0,0,0,
0,0,0,
endlayer
 
layer
0,0,0,
0,0,0,
0,0,0,
endlayer
 
layer
0,0,0,
0,0,0,
0,0,0,
endlayer
 
layer
0,0,0,
0,0,0,
0,0,0,
endlayer
 
layer
0,0,0,
0,0,0,
0,0,0,
endlayer
 
layer
0,0,0,
0,0,0,
0,0,0,
endlayer
 
layer
0,0,0,
0,0,0,
0,0,0,
endlayer
 
layer
0,0,0,
0,0,0,
0,0,0,
endlayer
 
layer
0,0,0,
0,0,0,
0,0,0,
endlayer
 
layer
0,0,0,
0,0,0,
0,0,0,
endlayer
 
layer
0,0,0,
0,0,0,
0,0,0,
endlayer
 
layer
0,0,0,
0,0,0,
0,0,0,
endlayer
 
layer
0,0,0,
0,0,0,
0,0,0,
endlayer
 
layer
0,0,0,
0,0,0,
0,0,0,
endlayer
 
layer
0,0,0,
0,0,0,
0,0,0,
endlayer
 
layer
0,0,0,
0,0,0,
0,0,0,
endlayer
 
layer
11,9,9,
11,0,12,
10,10,12,
endlayer
 
layer
8,8,8,
8,4,8,
8,8,8,
endlayer
 
layer
1,1,1,
1,4,1,
1,1,1,
endlayer
 
layer
0,0,0,
0,14,0,
0,0,0,
endlayer
 
layer
1,1,1,
1,4,1,
1,1,1,
endlayer
 
layer
1,1,1,
1,4,1,
1,1,1,
endlayer
 
layer
1,1,1,
1,4,1,
1,1,1,
endlayer
 
layer
1,1,1,
1,4,1,
1,1,1,
endlayer
 
layer
1,1,1,
1,4,1,
1,1,1,
endlayer
 
layer
1,1,1,
1,4,1,
1,1,1,
endlayer
 
layer
1,1,1,
1,4,1,
1,1,1,
endlayer
 
layer
1,1,1,
1,4,1,
1,1,1,
endlayer
 
layer
1,1,1,
1,4,1,
1,1,1,
endlayer
 
layer
1,1,1,
1,4,1,
1,1,1,
endlayer
 
layer
1,1,1,
1,4,1,
1,1,1,
endlayer
 
layer
1,1,1,
1,4,1,
1,1,1,
endlayer
 
layer
1,1,1,
1,4,1,
1,1,1,
endlayer
 
layer
1,1,1,
1,4,1,
1,1,1,
endlayer
 
layer
1,1,1,
1,4,1,
1,1,1,
endlayer
 
layer
1,1,1,
1,4,1,
1,1,1,
endlayer
 
layer
1,1,1,
1,4,1,
1,1,1,
endlayer
 
layer
1,1,1,
1,4,1,
1,1,1,
endlayer
 
layer
1,1,1,
1,4,1,
1,1,1,
endlayer
 
layer
1,1,1,
1,4,1,
1,1,1,
endlayer
 
 
layer
1,1,1,
1,14,1,
1,1,1,
endlayer
