# Author: BlinkyZero
# From: Minecraft Forums

weight=5
embed_into_distance=2
acceptable_target_blocks=1,2,3,12,13
dimensions=9,10,9
allowable_overhang=2
max_cut_in=2
cut_in_buffer=1
max_leveling=2
leveling_buffer=1
preserve_water=0
preserve_lava=0
preserve_plants=0

rule1=0,100,4
rule2=0,100,5
rule3=0,100,preserveBlock
rule4=0,100,50-3
rule5=0,100,50-5

layer
3,3,3,3,3,3,3,3,3
3,1,1,1,1,1,1,1,3
3,1,1,1,1,1,1,1,3
3,1,1,1,1,1,1,1,3
3,1,1,1,1,1,1,1,3
3,1,1,1,1,1,1,1,3
3,1,1,1,1,1,1,1,3
3,1,1,1,1,1,1,1,3
3,3,3,3,1,3,3,3,3
3,3,3,3,3,3,3,3,3
endlayer

layer
0,0,2,0,0,0,2,0,0
0,1,1,1,1,1,1,1,0
2,1,2,0,0,0,2,1,2
0,1,0,0,0,0,0,1,0
0,1,0,0,1,0,0,1,0
0,1,0,0,0,0,0,1,0
2,1,2,0,0,0,2,1,2
0,1,1,1,0,1,1,1,0
0,0,2,1,0,1,2,0,0
0,0,2,0,0,0,2,0,0
endlayer

layer
0,0,2,0,0,0,2,0,0
0,1,1,1,1,1,1,1,0
2,1,2,0,0,0,2,1,2
0,1,0,0,0,0,0,1,0
0,1,0,0,5,0,0,1,0
0,1,0,0,0,0,0,1,0
2,1,2,0,0,0,2,1,2
0,1,1,1,0,1,1,1,0
0,0,2,1,0,1,2,0,0
0,0,2,4,0,4,2,0,0
endlayer

layer
0,0,2,0,0,0,2,0,0
0,1,1,1,1,1,1,1,0
2,1,2,0,0,0,2,1,2
0,1,0,0,0,0,0,1,0
0,1,0,0,0,0,0,1,0
0,1,0,0,0,0,0,1,0
2,1,2,0,0,0,2,1,2
0,1,1,1,1,1,1,1,0
0,0,2,1,1,1,2,0,0
0,0,2,0,0,0,2,0,0
endlayer

layer
2,2,2,2,2,2,2,2,2
2,1,1,1,1,1,1,1,2
2,1,2,2,2,2,2,1,2
2,1,2,0,0,0,2,1,2
2,1,2,0,0,0,2,1,2
2,1,2,0,0,0,2,1,2
2,1,2,2,2,2,2,1,2
2,1,1,1,1,1,1,1,2
2,2,2,2,2,2,2,2,2
0,0,2,2,2,2,2,0,0
endlayer

layer
2,0,0,0,0,0,0,0,2
0,1,1,1,1,1,1,1,0
0,1,1,1,1,1,1,1,0
0,1,1,1,1,1,1,1,0
0,1,1,1,1,1,1,1,0
0,1,1,1,1,1,1,1,0
0,1,1,1,1,1,1,1,0
0,1,1,1,1,1,1,1,0
2,0,0,0,0,0,0,0,2
0,0,0,0,0,0,0,0,0
endlayer

layer
2,2,2,2,2,2,2,2,2
2,1,1,1,1,1,1,1,2
2,1,1,1,1,1,1,1,2
2,1,1,1,1,1,1,1,2
2,1,1,1,1,1,1,1,2
2,1,1,1,1,1,1,1,2
2,1,1,1,1,1,1,1,2
2,1,1,1,1,1,1,1,2
2,2,2,2,2,2,2,2,2
0,0,0,0,0,0,0,0,0
endlayer

layer
0,0,0,0,0,0,0,0,0
0,1,0,0,0,0,0,1,0
0,0,0,0,0,0,0,0,0
0,0,0,0,0,0,0,0,0
0,0,0,0,0,0,0,0,0
0,0,0,0,0,0,0,0,0
0,0,0,0,0,0,0,0,0
0,1,0,0,0,0,0,1,0
0,0,0,0,0,0,0,0,0
0,0,0,0,0,0,0,0,0
endlayer

layer
0,0,0,0,0,0,0,0,0
0,5,0,0,0,0,0,5,0
0,0,0,0,0,0,0,0,0
0,0,0,0,0,0,0,0,0
0,0,0,0,0,0,0,0,0
0,0,0,0,0,0,0,0,0
0,0,0,0,0,0,0,0,0
0,5,0,0,0,0,0,5,0
0,0,0,0,0,0,0,0,0
0,0,0,0,0,0,0,0,0
endlayer
