weight=5
embed_into_distance=1
acceptable_target_blocks=1,2,3,12,13,24
dimensions=8,7,7
allowable_overhang=0
max_cut_in=2
cut_in_buffer=0
max_leveling=1
leveling_buffer=0
preserve_water=0
preserve_lava=0
preserve_plants=1



rule1=0,0,35-3
rule2=0,100,1
rule3=0,75,1
rule4=1,75,1
rule5=1,75,1,16
rule6=1,50,1,15
rule7=1,25,1,14


layer
1,2,2,2,2,2,1
2,2,2,2,2,2,2
2,2,2,2,2,2,2
2,2,2,2,2,2,2
2,2,2,2,2,2,2
2,2,2,2,2,2,2
1,2,2,2,2,2,1
endlayer

layer
0,3,3,3,3,3,0
3,3,2,2,2,3,3
3,2,2,2,2,2,3
3,2,2,2,2,2,3
3,2,2,2,2,2,3
3,3,2,2,2,3,3
0,3,3,3,3,3,0
endlayer

layer
0,0,4,4,4,0,0
0,4,2,2,2,4,0
4,2,2,2,2,2,4
4,2,2,2,2,2,4
4,2,2,2,2,2,4
0,4,2,2,2,4,0
0,0,4,4,4,0,0
endlayer

layer
0,0,0,0,0,0,0
0,0,4,4,4,0,0
0,4,2,2,2,4,0
0,4,2,2,2,4,0
0,4,2,2,2,4,0
0,0,4,4,4,0,0
0,0,0,0,0,0,0
endlayer

layer
0,0,0,0,0,0,0
0,0,5,5,5,0,0
0,5,4,4,4,5,0
0,5,4,2,4,5,0
0,5,4,4,4,5,0
0,0,5,5,5,0,0
0,0,0,0,0,0,0
endlayer

layer
0,0,0,0,0,0,0
0,0,6,6,6,0,0
0,6,5,5,5,6,0
0,6,5,4,5,6,0
0,6,5,5,5,6,0
0,0,6,6,6,0,0
0,0,0,0,0,0,0
endlayer

layer
0,0,0,0,0,0,0
0,0,0,0,0,0,0
0,0,6,6,6,0,0
0,0,6,6,6,0,0
0,0,6,6,6,0,0
0,0,0,0,0,0,0
0,0,0,0,0,0,0
endlayer

layer
0,0,0,0,0,0,0
0,0,0,0,0,0,0
0,0,7,7,7,0,0
0,0,7,7,7,0,0
0,0,7,7,7,0,0
0,0,0,0,0,0,0
0,0,0,0,0,0,0
endlayer

