weight=1
embed_into_distance=1
acceptable_target_blocks=1,2,3,12,13,24
dimensions=6,6,5
cut_in_buffer=1
max_leveling=2
leveling_buffer=1
preserve_water=0
preserve_lava=0
preserve_plants=0
max_cut_in=10


rule1=0,100,preserveBlock
rule2=0,100,13
rule3=0,100,4
rule4=0,100,67-1
rule5=0,100,5
rule6=0,100,102
rule7=0,100,50-2
rule8=0,100,17


layer
1,1,1,1,1
1,1,1,1,1
1,1,1,1,1
1,1,1,1,1
1,1,1,1,1
2,2,2,2,2
endlayer

layer
3,3,3,3,3
3,3,3,3,3
3,3,3,3,3
3,3,3,3,3
3,3,3,3,3
0,0,4,0,0
endlayer

layer
3,5,5,5,3
5,0,0,0,5
5,0,0,0,5
5,0,0,0,5
3,5,0,5,3
0,0,0,0,0
endlayer

layer
3,5,6,5,3
5,0,0,0,5
6,0,0,0,6
5,0,0,0,5
3,5,0,5,3
0,0,0,0,0
endlayer

layer
3,5,5,5,3
5,0,0,0,5
5,0,0,0,5
5,0,7,0,5
3,5,5,5,3
0,0,0,0,0
endlayer

layer
8,8,8,8,8
8,5,5,5,8
8,5,5,5,8
8,5,5,5,8
8,8,8,8,8
0,0,0,0,0
endlayer

