# Gazebo
# Author: Arrrg
# From: Minecraft Forums

weight=4
embed_into_distance=1
acceptable_target_blocks=2,3
dimensions=13,17,17
allowable_overhang=1200
unique=0
max_cut_in=12
cut_in_buffer=0
max_leveling=1
leveling_buffer=0
preserve_water=0
preserve_lava=0
preserve_plants=0

rule1=0,100,preserveBlock
rule2=0,100,1
rule3=0,100,3
rule4=0,100,4
rule5=0,100,45
rule6=0,100,85
rule7=0,100,78
rule8=0,100,8
rule9=0,100,16
rule10=0,100,10
rule11=0,100,56
rule12=0,100,12
rule13=0,100,13
rule14=0,100,65-5
rule15=0,100,65-4
rule16=0,100,65-3
rule17=0,100,65-2

layer
1,1,1,1,1,1,2,2,2,2,2,1,1,1,1,1,1
1,1,1,1,2,2,5,2,2,2,5,2,2,1,1,1,1
1,1,1,2,2,2,2,2,2,2,2,2,2,2,1,1,1
1,1,2,5,2,2,2,2,2,2,2,2,2,5,2,1,1
1,2,2,2,2,2,2,2,2,2,2,2,2,2,2,2,1
1,2,2,2,2,2,2,2,2,2,2,2,2,2,2,2,1
2,5,2,2,2,2,2,2,2,2,2,2,2,2,2,5,2
2,2,2,2,2,2,2,2,2,2,2,2,2,2,2,2,2
2,2,2,2,2,2,2,2,2,2,2,2,2,2,2,2,2
2,2,2,2,2,2,2,2,2,2,2,2,2,2,2,2,2
2,5,2,2,2,2,2,2,2,2,2,2,2,2,2,5,2
1,2,2,2,2,2,2,2,2,2,2,2,2,2,2,2,1
1,2,2,2,2,2,2,2,2,2,2,2,2,2,2,2,1
1,1,2,5,2,2,2,2,2,2,2,2,2,5,2,1,1
1,1,1,2,2,2,2,2,2,2,2,2,2,2,1,1,1
1,1,1,1,2,2,5,2,2,2,5,2,2,1,1,1,1
1,1,1,1,1,1,2,2,2,2,2,1,1,1,1,1,1
endlayer

layer
1,1,1,1,1,1,1,1,1,1,1,1,1,1,1,1,1
1,1,1,1,1,1,5,0,0,0,5,1,1,1,1,1,1
1,1,1,1,0,0,0,0,0,0,0,0,0,1,1,1,1
1,1,1,5,0,0,0,0,0,0,0,0,0,5,1,1,1
1,1,0,0,0,0,0,0,0,0,0,0,0,0,0,1,1
1,1,0,0,0,0,0,0,0,0,0,0,0,0,0,1,1
1,5,0,0,0,0,0,0,0,0,0,0,0,0,0,5,1
1,0,0,0,0,0,0,0,0,0,0,0,0,0,0,0,1
1,0,0,0,0,0,0,0,0,0,0,0,0,0,0,0,1
1,0,0,0,0,0,0,0,0,0,0,0,0,0,0,0,1
1,5,0,0,0,0,0,0,0,0,0,0,0,0,0,5,1
1,1,0,0,0,0,0,0,0,0,0,0,0,0,0,1,1
1,1,0,0,0,0,0,0,0,0,0,0,0,0,0,1,1
1,1,1,5,0,0,0,0,0,0,0,0,0,5,1,1,1
1,1,1,1,0,0,0,0,0,0,0,0,0,1,1,1,1
1,1,1,1,1,1,5,0,0,0,5,1,1,1,1,1,1
1,1,1,1,1,1,1,1,1,1,1,1,1,1,1,1,1
endlayer

layer
1,1,1,1,1,1,1,1,1,1,1,1,1,1,1,1,1
1,1,1,1,1,1,5,0,0,0,5,1,1,1,1,1,1
1,1,1,1,0,0,0,0,0,0,0,0,0,1,1,1,1
1,1,1,5,0,0,0,0,0,0,0,0,0,5,1,1,1
1,1,0,0,0,0,0,0,0,0,0,0,0,0,0,1,1
1,1,0,0,0,0,0,0,0,0,0,0,0,0,0,1,1
1,5,0,0,0,0,0,0,0,0,0,0,0,0,0,5,1
1,0,0,0,0,0,0,0,0,0,0,0,0,0,0,0,1
1,0,0,0,0,0,0,0,0,0,0,0,0,0,0,0,1
1,0,0,0,0,0,0,0,0,0,0,0,0,0,0,0,1
1,5,0,0,0,0,0,0,0,0,0,0,0,0,0,5,1
1,1,0,0,0,0,0,0,0,0,0,0,0,0,0,1,1
1,1,0,0,0,0,0,0,0,0,0,0,0,0,0,1,1
1,1,1,5,0,0,0,0,0,0,0,0,0,5,1,1,1
1,1,1,1,0,0,0,0,0,0,0,0,0,1,1,1,1
1,1,1,1,1,1,5,0,0,0,5,1,1,1,1,1,1
1,1,1,1,1,1,1,1,1,1,1,1,1,1,1,1,1
endlayer

layer
1,1,1,1,1,1,1,1,1,1,1,1,1,1,1,1,1
1,1,1,1,1,1,5,0,0,0,5,1,1,1,1,1,1
1,1,1,1,0,0,0,0,0,0,0,0,0,1,1,1,1
1,1,1,5,0,0,0,0,0,0,0,0,0,5,1,1,1
1,1,0,0,0,0,0,0,0,0,0,0,0,0,0,1,1
1,1,0,0,0,0,0,0,0,0,0,0,0,0,0,1,1
1,5,0,0,0,0,0,0,0,0,0,0,0,0,0,5,1
1,0,0,0,0,0,0,0,0,0,0,0,0,0,0,0,1
1,0,0,0,0,0,0,0,0,0,0,0,0,0,0,0,1
1,0,0,0,0,0,0,0,0,0,0,0,0,0,0,0,1
1,5,0,0,0,0,0,0,0,0,0,0,0,0,0,5,1
1,1,0,0,0,0,0,0,0,0,0,0,0,0,0,1,1
1,1,0,0,0,0,0,0,0,0,0,0,0,0,0,1,1
1,1,1,5,0,0,0,0,0,0,0,0,0,5,1,1,1
1,1,1,1,0,0,0,0,0,0,0,0,0,1,1,1,1
1,1,1,1,1,1,5,0,0,0,5,1,1,1,1,1,1
1,1,1,1,1,1,1,1,1,1,1,1,1,1,1,1,1
endlayer

layer
1,1,1,1,1,1,1,1,1,1,1,1,1,1,1,1,1
1,1,1,1,1,1,5,0,0,0,5,1,1,1,1,1,1
1,1,1,1,0,0,0,0,0,0,0,0,0,1,1,1,1
1,1,1,5,0,0,0,0,0,0,0,0,0,5,1,1,1
1,1,0,0,0,0,0,0,0,0,0,0,0,0,0,1,1
1,1,0,0,0,0,0,0,0,0,0,0,0,0,0,1,1
1,5,0,0,0,0,0,0,0,0,0,0,0,0,0,5,1
1,0,0,0,0,0,0,0,0,0,0,0,0,0,0,0,1
1,0,0,0,0,0,0,0,0,0,0,0,0,0,0,0,1
1,0,0,0,0,0,0,0,0,0,0,0,0,0,0,0,1
1,5,0,0,0,0,0,0,0,0,0,0,0,0,0,5,1
1,1,0,0,0,0,0,0,0,0,0,0,0,0,0,1,1
1,1,0,0,0,0,0,0,0,0,0,0,0,0,0,1,1
1,1,1,5,0,0,0,0,0,0,0,0,0,5,1,1,1
1,1,1,1,0,0,0,0,0,0,0,0,0,1,1,1,1
1,1,1,1,1,1,5,0,0,0,5,1,1,1,1,1,1
1,1,1,1,1,1,1,1,1,1,1,1,1,1,1,1,1
endlayer

layer
1,1,1,1,1,1,1,1,1,1,1,1,1,1,1,1,1
1,1,1,1,1,1,5,0,0,0,5,1,1,1,1,1,1
1,1,1,1,0,0,0,0,0,0,0,0,0,1,1,1,1
1,1,1,5,0,0,0,0,0,0,0,0,0,5,1,1,1
1,1,0,0,0,0,0,0,0,0,0,0,0,0,0,1,1
1,1,0,0,0,0,0,0,0,0,0,0,0,0,0,1,1
1,5,0,0,0,0,0,0,0,0,0,0,0,0,0,5,1
1,0,0,0,0,0,0,0,9,0,0,0,0,0,0,0,1
1,0,0,0,0,0,0,11,0,11,0,0,0,0,0,0,1
1,0,0,0,0,0,0,0,9,0,0,0,0,0,0,0,1
1,5,0,0,0,0,0,0,0,0,0,0,0,0,0,5,1
1,1,0,0,0,0,0,0,0,0,0,0,0,0,0,1,1
1,1,0,0,0,0,0,0,0,0,0,0,0,0,0,1,1
1,1,1,5,0,0,0,0,0,0,0,0,0,5,1,1,1
1,1,1,1,0,0,0,0,0,0,0,0,0,1,1,1,1
1,1,1,1,1,1,5,0,0,0,5,1,1,1,1,1,1
1,1,1,1,1,1,1,1,1,1,1,1,1,1,1,1,1
endlayer

layer
1,1,1,1,1,1,4,4,4,4,4,1,1,1,1,1,1
1,1,1,1,4,4,4,4,4,4,4,4,4,1,1,1,1
1,1,1,4,4,4,4,4,4,4,4,4,4,4,1,1,1
1,1,4,4,4,4,4,4,4,4,4,4,4,4,4,1,1
1,4,4,4,4,4,7,7,7,7,7,4,4,4,4,4,1
1,4,4,4,4,7,7,7,7,7,7,7,4,4,4,4,1
4,4,4,4,7,7,7,7,7,7,7,7,7,4,4,4,4
4,4,4,4,7,7,7,7,7,7,7,7,7,4,4,4,4
4,4,4,4,7,7,7,7,7,7,7,7,7,4,4,4,4
4,4,4,4,7,7,7,7,7,7,7,7,7,4,4,4,4
4,4,4,4,7,7,7,7,7,7,7,7,7,4,4,4,4
1,4,4,4,4,7,7,7,7,7,7,7,4,4,4,4,1
1,4,4,4,4,4,7,7,7,7,7,4,4,4,4,4,1
1,1,4,4,4,4,4,4,4,4,4,4,4,4,4,1,1
1,1,1,4,4,4,4,4,4,4,4,4,4,4,1,1,1
1,1,1,1,4,4,4,4,4,4,4,4,4,1,1,1,1
1,1,1,1,1,1,4,4,4,4,4,1,1,1,1,1,1
endlayer

layer
1,1,1,1,1,1,4,4,4,4,4,1,1,1,1,1,1
1,1,1,1,4,4,4,4,4,4,4,4,4,1,1,1,1
1,1,1,4,4,4,4,4,4,4,4,4,4,4,1,1,1
1,1,4,4,4,4,4,4,4,4,4,4,4,4,4,1,1
1,4,4,4,4,4,13,13,13,13,13,4,4,4,4,4,1
1,4,4,4,4,13,13,13,13,13,13,13,4,4,4,4,1
4,4,4,4,13,13,13,13,13,13,13,13,13,4,4,4,4
4,4,4,4,13,13,13,13,13,13,13,13,13,4,4,4,4
4,4,4,4,13,13,13,13,13,13,13,13,13,4,4,4,4
4,4,4,4,13,13,13,13,13,13,13,13,13,4,4,4,4
4,4,4,4,13,13,13,13,13,13,13,13,13,4,4,4,4
1,4,4,4,4,13,13,13,13,13,13,13,4,4,4,4,1
1,4,4,4,4,4,13,13,13,13,13,4,4,4,4,4,1
1,1,4,4,4,4,4,4,4,4,4,4,4,4,4,1,1
1,1,1,4,4,4,4,4,4,4,4,4,4,4,1,1,1
1,1,1,1,4,4,4,4,4,4,4,4,4,1,1,1,1
1,1,1,1,1,1,4,4,4,4,4,1,1,1,1,1,1
endlayer

layer
1,1,1,1,1,1,1,1,1,1,1,1,1,1,1,1,1
1,1,1,1,1,1,4,4,4,4,4,1,1,1,1,1,1
1,1,1,1,4,4,4,4,4,4,4,4,4,1,1,1,1
1,1,1,4,4,4,0,0,10,0,0,4,4,4,1,1,1
1,1,4,4,4,4,13,13,13,13,13,4,4,4,4,1,1
1,1,4,4,4,13,13,13,13,13,13,13,4,4,4,1,1
1,4,4,0,13,13,13,13,13,13,13,13,13,0,4,4,1
1,4,4,0,13,13,13,13,13,13,13,13,13,0,4,4,1
1,4,4,10,13,13,13,13,13,13,13,13,13,10,4,4,1
1,4,4,0,13,13,13,13,13,13,13,13,13,0,4,4,1
1,4,4,0,13,13,13,13,13,13,13,13,13,0,4,4,1
1,1,4,4,4,13,13,13,13,13,13,13,4,4,4,1,1
1,1,4,4,4,4,13,13,13,13,13,4,4,4,4,1,1
1,1,1,4,4,4,0,0,10,0,0,4,4,4,1,1,1
1,1,1,1,4,4,4,4,4,4,4,4,4,1,1,1,1
1,1,1,1,1,1,4,4,4,4,4,1,1,1,1,1,1
1,1,1,1,1,1,1,1,1,1,1,1,1,1,1,1,1
endlayer

layer
1,1,1,1,1,1,1,1,1,1,1,1,1,1,1,1,1
1,1,1,1,1,1,4,4,4,4,4,1,1,1,1,1,1
1,1,1,1,4,4,4,4,4,4,4,4,4,1,1,1,1
1,1,1,4,4,4,4,4,4,4,4,4,4,4,1,1,1
1,1,4,4,4,4,13,13,13,13,13,4,4,4,4,1,1
1,1,4,4,4,13,13,13,13,13,13,13,4,4,4,1,1
1,4,4,4,13,13,13,13,13,13,13,13,13,4,4,4,1
1,4,4,4,13,13,13,13,13,13,13,13,13,4,4,4,1
1,4,4,4,13,13,13,13,13,13,13,13,13,4,4,4,1
1,4,4,4,13,13,13,13,13,13,13,13,13,4,4,4,1
1,4,4,4,13,13,13,13,13,13,13,13,13,4,4,4,1
1,1,4,4,4,13,13,13,13,13,13,13,4,4,4,1,1
1,1,4,4,4,4,13,13,13,13,13,4,4,4,4,1,1
1,1,1,4,4,4,4,4,4,4,4,4,4,4,1,1,1
1,1,1,1,4,4,4,4,4,4,4,4,4,1,1,1,1
1,1,1,1,1,1,4,4,4,4,4,1,1,1,1,1,1
1,1,1,1,1,1,1,1,1,1,1,1,1,1,1,1,1
endlayer

layer
1,1,1,1,1,1,1,1,1,1,1,1,1,1,1,1,1
1,1,1,1,1,1,1,1,1,1,1,1,1,1,1,1,1
1,1,1,1,1,1,4,4,4,4,4,1,1,1,1,1,1
1,1,1,1,4,4,4,4,4,4,4,4,4,1,1,1,1
1,1,1,4,4,4,13,13,13,13,13,4,4,4,1,1,1
1,1,1,4,4,13,13,13,13,13,13,13,4,4,1,1,1
1,1,4,4,13,13,13,13,13,13,13,13,13,4,4,1,1
1,1,4,4,13,13,13,13,13,13,13,13,13,4,4,1,1
1,1,4,4,13,13,13,13,13,13,13,13,13,4,4,1,1
1,1,4,4,13,13,13,13,13,13,13,13,13,4,4,1,1
1,1,4,4,13,13,13,13,13,13,13,13,13,4,4,1,1
1,1,1,4,4,13,13,13,13,13,13,13,4,4,1,1,1
1,1,1,4,4,4,13,13,13,13,13,4,4,4,1,1,1
1,1,1,1,4,4,4,4,4,4,4,4,4,1,1,1,1
1,1,1,1,1,1,4,4,4,4,4,1,1,1,1,1,1
1,1,1,1,1,1,1,1,1,1,1,1,1,1,1,1,1
1,1,1,1,1,1,1,1,1,1,1,1,1,1,1,1,1
endlayer

layer
1,1,1,1,1,1,1,1,1,1,1,1,1,1,1,1,1
1,1,1,1,1,1,1,1,1,1,1,1,1,1,1,1,1
1,1,1,1,1,1,1,1,1,1,1,1,1,1,1,1,1
1,1,1,1,1,1,4,4,4,4,4,1,1,1,1,1,1
1,1,1,1,4,4,13,13,13,13,13,4,4,1,1,1,1
1,1,1,1,4,13,13,13,13,13,13,13,4,1,1,1,1
1,1,1,4,13,13,13,13,13,13,13,13,13,4,1,1,1
1,1,1,4,13,13,13,13,13,13,13,13,13,4,1,1,1
1,1,1,4,13,13,13,13,13,13,13,13,13,4,1,1,1
1,1,1,4,13,13,13,13,13,13,13,13,13,4,1,1,1
1,1,1,4,13,13,13,13,13,13,13,13,13,4,1,1,1
1,1,1,1,4,13,13,13,13,13,13,13,4,1,1,1,1
1,1,1,1,4,4,13,13,13,13,13,4,4,1,1,1,1
1,1,1,1,1,1,4,4,4,4,4,1,1,1,1,1,1
1,1,1,1,1,1,1,1,1,1,1,1,1,1,1,1,1
1,1,1,1,1,1,1,1,1,1,1,1,1,1,1,1,1
1,1,1,1,1,1,1,1,1,1,1,1,1,1,1,1,1
endlayer

layer
1,1,1,1,1,1,1,1,1,1,1,1,1,1,1,1,1
1,1,1,1,1,1,1,1,1,1,1,1,1,1,1,1,1
1,1,1,1,1,1,1,1,1,1,1,1,1,1,1,1,1
1,1,1,1,1,1,1,1,1,1,1,1,1,1,1,1,1
1,1,1,1,1,1,1,1,1,1,1,1,1,1,1,1,1
1,1,1,1,1,1,4,4,4,4,4,1,1,1,1,1,1
1,1,1,1,1,4,4,4,4,4,4,4,1,1,1,1,1
1,1,1,1,1,4,4,4,4,4,4,4,1,1,1,1,1
1,1,1,1,1,4,4,4,4,4,4,4,1,1,1,1,1
1,1,1,1,1,4,4,4,4,4,4,4,1,1,1,1,1
1,1,1,1,1,4,4,4,4,4,4,4,1,1,1,1,1
1,1,1,1,1,1,4,4,4,4,4,1,1,1,1,1,1
1,1,1,1,1,1,1,1,1,1,1,1,1,1,1,1,1
1,1,1,1,1,1,1,1,1,1,1,1,1,1,1,1,1
1,1,1,1,1,1,1,1,1,1,1,1,1,1,1,1,1
1,1,1,1,1,1,1,1,1,1,1,1,1,1,1,1,1
1,1,1,1,1,1,1,1,1,1,1,1,1,1,1,1,1
endlayer
