weight=2
embed_into_distance=1
acceptable_target_blocks=1,2,3,12,13,24
dimensions=6,6,5
cut_in_buffer=1
max_leveling=2
leveling_buffer=1
preserve_water=0
preserve_lava=0
preserve_plants=0
max_cut_in=10


rule1=0,100,preserveBlock
rule2=0,90,4,4,4,4,48,97-1
rule3=0,50,67-1
rule4=0,90,5
rule5=0,10,102
rule6=0,60,17
rule7=2,50,5


layer
1,1,1,1,1
1,1,1,1,1
1,1,1,1,1
1,1,1,1,1
1,1,1,1,1
1,1,1,1,1
endlayer

layer
2,2,2,2,2
2,2,2,2,2
2,2,2,2,2
2,2,2,2,2
2,2,2,2,2
0,0,3,0,0
endlayer

layer
2,4,4,4,2
4,0,0,0,4
4,0,0,0,4
4,0,0,0,4
2,4,0,4,2
0,0,0,0,0
endlayer

layer
2,4,5,4,2
4,0,0,0,4
5,0,0,0,5
4,0,0,0,4
2,4,0,4,2
0,0,0,0,0
endlayer

layer
2,4,4,4,2
4,0,0,0,4
4,0,0,0,4
4,0,0,0,4
2,4,4,4,2
0,0,0,0,0
endlayer

layer
6,6,6,6,6
6,7,7,7,6
6,7,7,7,6
6,7,7,7,6
6,6,6,6,6
0,0,0,0,0
endlayer

