weight=1
unique=1
embed_into_distance=6
unacceptable_target_blocks=flowing_water,water,flowing_lava,lava
dimensions=8,12,10
allowable_overhang=0
max_cut_in=0
cut_in_buffer=0
max_leveling=1
leveling_buffer=0
preserve_water=0
preserve_lava=0
preserve_plants=1


rule1=0,100,stone
rule2=0,100,lava
rule3=0,100,redstone_wire
rule4=0,100,stonebrick-1
rule5=0,100,redstone_wire-15
rule6=0,100,redstone_torch-5
rule7=0,100,redstone_wire-14
rule8=0,100,redstone_wire-11
rule9=0,100,powered_repeater-1
rule10=0,100,sticky_piston-13
rule11=0,100,piston_head-13
rule12=0,100,piston_head-12
rule13=0,100,sticky_piston-12
rule14=0,100,powered_repeater-3
rule15=0,100,redstone_wire-12
rule16=0,100,redstone_wire-13
rule17=0,100,MediumChest
rule18=0,100,stone_pressure_plate
rule19=0,100,preserveBlock
rule20=0,100,vine-2
rule21=0,100,vine-1
rule22=0,100,vine-4


layer
1,1,1,1,1,1,1,1,1,1
1,1,1,1,1,1,1,1,1,1
1,1,3,1,1,1,1,1,1,1
1,1,3,1,1,1,1,1,1,1
1,1,1,1,1,1,1,1,1,1
1,1,1,1,1,2,2,2,1,1
1,1,1,1,1,2,2,2,1,1
1,1,1,1,1,1,1,1,1,1
1,1,3,1,1,1,1,1,1,1
1,1,3,1,1,1,1,1,1,1
1,1,1,1,1,1,1,1,1,1
1,1,1,1,1,1,1,1,1,1
endlayer

layer
1,1,1,1,1,1,1,1,1,1
1,1,6,5,1,1,1,1,1,1
1,1,0,0,1,1,1,1,1,1
1,1,0,3,1,1,1,1,1,1
1,1,1,1,4,4,4,4,4,1
1,1,1,1,4,0,0,0,4,1
1,1,1,1,4,0,0,0,4,1
1,1,1,1,4,4,4,4,4,1
1,1,0,3,1,1,1,1,1,1
1,1,0,0,1,1,1,1,1,1
1,1,6,5,1,1,1,1,1,1
1,1,1,1,1,1,1,1,1,1
endlayer

layer
1,1,1,1,1,1,1,1,1,1
1,1,0,0,7,1,1,1,1,1
1,1,0,0,0,1,1,1,1,1
1,1,0,0,1,1,1,1,1,1
1,1,1,3,4,4,4,4,4,1
1,1,1,3,4,0,0,0,4,1
1,1,1,3,4,0,0,0,4,1
1,1,1,3,4,4,4,4,4,1
1,1,0,0,1,1,1,1,1,1
1,1,0,0,1,1,1,1,1,1
1,1,0,0,7,1,1,1,1,1
1,1,1,1,1,1,1,1,1,1
endlayer

layer
1,1,1,1,1,1,1,1,1,1
1,1,1,1,0,16,15,8,1,1
1,1,1,1,0,9,9,9,1,1
1,1,1,1,1,10,10,10,1,1
1,1,1,0,1,11,11,11,1,1
1,1,1,1,1,1,1,1,1,1
1,1,1,1,1,1,1,1,1,1
1,1,1,0,1,12,12,12,1,1
1,1,1,1,1,13,13,13,1,1
1,1,1,1,0,14,14,14,1,1
1,1,1,1,0,16,15,8,1,1
1,1,1,1,1,1,1,1,1,1
endlayer

layer
1,1,1,1,1,1,1,1,1,1
4,4,4,4,4,4,4,4,4,4
4,4,4,4,4,4,4,4,4,4
4,1,1,1,1,4,4,4,4,4
4,4,4,4,4,4,4,4,4,4
4,4,4,18,0,0,0,0,17,4
4,4,4,18,0,0,0,0,17,4
4,4,4,4,4,4,4,4,4,4
4,1,1,1,1,4,4,4,4,4
4,4,4,4,4,4,4,4,4,4
4,4,4,4,4,4,4,4,4,4
1,1,1,1,1,1,1,1,1,1
endlayer

layer
19,19,19,19,19,19,19,19,19,19
19,19,19,19,19,19,19,19,19,19
19,19,19,19,19,19,19,19,19,19
4,4,4,4,4,4,4,19,19,19
4,4,4,4,4,4,4,4,4,4
4,0,0,0,0,0,0,0,0,4
4,0,0,0,0,0,0,0,0,4
4,4,4,4,4,4,4,4,4,4
4,4,4,4,4,4,4,19,19,19
19,19,19,19,19,19,19,19,19,19
19,19,19,19,19,19,19,19,19,19
19,19,19,19,19,19,19,19,19,19
endlayer

layer
0,0,0,0,0,0,0,0,0,0
0,0,0,0,0,0,0,0,0,0
0,0,0,0,0,0,0,0,0,0
0,0,0,0,0,0,0,0,0,0
0,4,4,4,4,4,4,4,0,0
0,0,0,0,4,4,4,4,4,0
0,0,0,0,4,4,4,4,4,0
0,4,4,4,4,4,4,4,0,0
0,0,0,0,0,20,0,0,0,0
0,0,0,0,0,0,0,0,0,0
0,0,0,0,0,0,0,0,0,0
0,0,0,0,0,0,0,0,0,0
endlayer

layer
0,0,0,0,0,0,0,0,0,0
0,0,0,0,0,0,0,0,0,0
0,0,0,0,0,0,0,0,0,0
0,0,0,0,0,0,0,0,0,0
0,0,0,0,0,0,0,0,0,0
0,0,0,22,4,4,4,4,21,0
0,0,0,22,4,4,4,4,21,0
0,0,0,0,0,0,20,0,0,0
0,0,0,0,0,0,0,0,0,0
0,0,0,0,0,0,0,0,0,0
0,0,0,0,0,0,0,0,0,0
0,0,0,0,0,0,0,0,0,0
endlayer

