


weight=2
embed_into_distance=2

unacceptable_target_blocks=flowing_water,water,flowing_lava,lava,Natura:Cloud,red_mushroom_block,brown_mushroom_block,planks,cobblestone,end_stone,obsidian,purpur_block,iron_bars,purpur_slab,purpur_pillar,netherrack,soul_sand,quartz_ore

dimensions=10,13,13
allowable_overhang=0
max_leveling=3
leveling_buffer=-1
preserve_water=0
preserve_lava=0
preserve_plants=0


rule1=0,100,preserveBlock
rule2=0,100,stone
rule3=0,100,flowing_lava
rule4=0,75,stone
rule5=1,70,stone
rule6=0,100,preserveBlock


layer
1,1,2,2,2,2,2,2,2,2,2,1,1
1,2,2,2,2,2,2,2,2,2,2,2,1
2,2,2,2,2,2,2,2,2,2,2,2,2
2,2,2,2,2,2,2,2,2,2,2,2,2
2,2,2,2,2,2,2,2,2,2,2,2,2
2,2,2,2,2,2,2,2,2,2,2,2,2
2,2,2,2,2,2,3,2,2,2,2,2,2
2,2,2,2,2,2,2,2,2,2,2,2,2
2,2,2,2,2,2,2,2,2,2,2,2,2
2,2,2,2,2,2,2,2,2,2,2,2,2
2,2,2,2,2,2,2,2,2,2,2,2,2
1,2,2,2,2,2,2,2,2,2,2,2,1
1,1,2,2,2,2,2,2,2,2,2,1,1
endlayer

layer
6,6,4,4,4,4,4,4,4,4,4,6,6
6,4,4,2,2,2,2,2,2,2,4,4,6
4,4,2,2,2,2,2,2,2,2,2,4,4
4,2,2,2,2,2,2,2,2,2,2,2,4
4,2,2,2,2,2,2,2,2,2,2,2,4
4,2,2,2,2,2,2,2,2,2,2,2,4
4,2,2,2,2,2,3,2,2,2,2,2,4
4,2,2,2,2,2,2,2,2,2,2,2,4
4,2,2,2,2,2,2,2,2,2,2,2,4
4,2,2,2,2,2,2,2,2,2,2,2,4
4,4,2,2,2,2,2,2,2,2,2,4,4
6,4,4,2,2,2,2,2,2,2,4,4,6
6,6,4,4,4,4,4,4,4,4,4,6,6
endlayer

layer
6,6,6,5,5,5,5,5,5,5,6,6,6
6,6,5,4,4,4,4,4,4,4,5,6,6
6,5,4,2,2,2,2,2,2,2,4,5,6
5,4,2,2,2,2,2,2,2,2,2,4,5
5,4,2,2,2,2,2,2,2,2,2,4,5
5,4,2,2,2,2,2,2,2,2,2,4,5
5,4,2,2,2,2,3,2,2,2,2,4,5
5,4,2,2,2,2,2,2,2,2,2,4,5
5,4,2,2,2,2,2,2,2,2,2,4,5
5,4,2,2,2,2,2,2,2,2,2,4,5
6,5,4,2,2,2,2,2,2,2,4,5,6
6,6,5,4,4,4,4,4,4,4,5,6,6
6,6,6,5,5,5,5,5,5,5,6,6,6
endlayer

layer
6,6,6,6,6,6,6,6,6,6,6,6,6
6,6,6,5,5,5,5,5,5,5,6,6,6
6,6,5,2,2,2,2,2,2,2,5,6,6
6,5,2,2,2,2,2,2,2,2,2,5,6
6,5,2,2,2,2,2,2,2,2,2,5,6
6,5,2,2,2,2,2,2,2,2,2,5,6
6,5,2,2,2,2,3,2,2,2,2,5,6
6,5,2,2,2,2,2,2,2,2,2,5,6
6,5,2,2,2,2,2,2,2,2,2,5,6
6,5,2,2,2,2,2,2,2,2,2,5,6
6,6,5,2,2,2,2,2,2,2,5,6,6
6,6,6,5,5,5,5,5,5,5,6,6,6
6,6,6,6,6,6,6,6,6,6,6,6,6
endlayer

layer
6,6,6,6,6,6,6,6,6,6,6,6,6
6,6,6,5,5,5,5,5,5,5,6,6,6
6,6,5,4,4,4,4,4,4,4,5,6,6
6,5,4,2,2,2,2,2,2,2,4,5,6
6,5,4,2,2,2,2,2,2,2,4,5,6
6,5,4,2,2,2,2,2,2,2,4,5,6
6,5,4,2,2,2,3,2,2,2,4,5,6
6,5,4,2,2,2,2,2,2,2,4,5,6
6,5,4,2,2,2,2,2,2,2,4,5,6
6,5,4,2,2,2,2,2,2,2,4,5,6
6,6,5,4,4,4,4,4,4,4,5,6,6
6,6,6,5,5,5,5,5,5,5,6,6,6
6,6,6,6,6,6,6,6,6,6,6,6,6
endlayer

layer
6,6,6,6,6,6,6,6,6,6,6,6,6
6,6,6,6,6,6,6,6,6,6,6,6,6
6,6,6,5,5,5,5,5,5,5,6,6,6
6,6,5,2,2,2,2,2,2,2,5,6,6
6,6,5,2,2,2,2,2,2,2,5,6,6
6,6,5,2,2,2,2,2,2,2,5,6,6
6,6,5,2,2,2,3,2,2,2,5,6,6
6,6,5,2,2,2,2,2,2,2,5,6,6
6,6,5,2,2,2,2,2,2,2,5,6,6
6,6,5,2,2,2,2,2,2,2,5,6,6
6,6,6,5,5,5,5,5,5,5,6,6,6
6,6,6,6,6,6,6,6,6,6,6,6,6
6,6,6,6,6,6,6,6,6,6,6,6,6
endlayer

layer
6,6,6,6,6,6,6,6,6,6,6,6,6
6,6,6,6,6,6,6,6,6,6,6,6,6
6,6,6,5,5,5,5,5,5,5,6,6,6
6,6,5,4,4,4,4,4,4,4,5,6,6
6,6,5,4,2,2,2,2,2,4,5,6,6
6,6,5,4,2,2,2,2,2,4,5,6,6
6,6,5,4,2,2,3,2,2,4,5,6,6
6,6,5,4,2,2,2,2,2,4,5,6,6
6,6,5,4,2,2,2,2,2,4,5,6,6
6,6,5,4,4,4,4,4,4,4,5,6,6
6,6,6,5,5,5,5,5,5,5,6,6,6
6,6,6,6,6,6,6,6,6,6,6,6,6
6,6,6,6,6,6,6,6,6,6,6,6,6
endlayer

layer
6,6,6,6,6,6,6,6,6,6,6,6,6
6,6,6,6,6,6,6,6,6,6,6,6,6
6,6,6,6,6,6,6,6,6,6,6,6,6
6,6,6,5,5,5,5,5,5,5,6,6,6
6,6,6,5,2,2,2,2,2,5,6,6,6
6,6,6,5,2,2,2,2,2,5,6,6,6
6,6,6,5,2,2,3,2,2,5,6,6,6
6,6,6,5,2,2,2,2,2,5,6,6,6
6,6,6,5,2,2,2,2,2,5,6,6,6
6,6,6,5,5,5,5,5,5,5,6,6,6
6,6,6,6,6,6,6,6,6,6,6,6,6
6,6,6,6,6,6,6,6,6,6,6,6,6
6,6,6,6,6,6,6,6,6,6,6,6,6
endlayer

layer
6,6,6,6,6,6,6,6,6,6,6,6,6
6,6,6,6,6,6,6,6,6,6,6,6,6
6,6,6,6,6,6,6,6,6,6,6,6,6
6,6,6,6,5,5,5,5,5,6,6,6,6
6,6,6,5,4,4,4,4,4,5,6,6,6
6,6,6,5,4,2,2,2,4,5,6,6,6
6,6,6,5,4,2,3,2,4,5,6,6,6
6,6,6,5,4,2,2,2,4,5,6,6,6
6,6,6,5,4,4,4,4,4,5,6,6,6
6,6,6,6,5,5,5,5,5,6,6,6,6
6,6,6,6,6,6,6,6,6,6,6,6,6
6,6,6,6,6,6,6,6,6,6,6,6,6
6,6,6,6,6,6,6,6,6,6,6,6,6
endlayer

layer
6,6,6,6,6,6,6,6,6,6,6,6,6
6,6,6,6,6,6,6,6,6,6,6,6,6
6,6,6,6,6,6,6,6,6,6,6,6,6
6,6,6,6,6,6,6,6,6,6,6,6,6
6,6,6,6,5,5,5,5,5,6,6,6,6
6,6,6,6,5,3,3,3,5,6,6,6,6
6,6,6,6,5,3,3,3,5,6,6,6,6
6,6,6,6,5,3,3,3,5,6,6,6,6
6,6,6,6,5,5,5,5,5,6,6,6,6
6,6,6,6,6,6,6,6,6,6,6,6,6
6,6,6,6,6,6,6,6,6,6,6,6,6
6,6,6,6,6,6,6,6,6,6,6,6,6
6,6,6,6,6,6,6,6,6,6,6,6,6
endlayer

