weight=1
embed_into_distance=2
acceptable_target_blocks=1,2,3,12,13
dimensions=4,12,12
cut_in_buffer=0
max_leveling=2
leveling_buffer=1
preserve_water=0
preserve_lava=0
preserve_plants=1
max_cut_in=10


rule1=0,100,13
rule2=0,100,9,4,48,4,48,preserveBlock,preserveBlock
rule3=0,100,9,9,9,4,4,48,48
rule4=0,100,9,9,9,9,9,9,9,9,9,9,9,9,9,13,2
rule5=0,100,4,48
rule6=0,30,44-3
rule7=0,30,111
rule8=0,75,4,48
rule9=1,50,4,48,4,48,8


layer
1,1,1,1,1,1,1,1,1,1,1,1
1,1,1,1,1,1,1,1,1,1,1,1
1,1,1,1,1,1,1,1,1,1,1,1
1,1,1,1,1,1,1,1,1,1,1,1
1,1,1,1,1,1,1,1,1,1,1,1
1,1,1,1,1,1,1,1,1,1,1,1
1,1,1,1,1,1,1,1,1,1,1,1
1,1,1,1,1,1,1,1,1,1,1,1
1,1,1,1,1,1,1,1,1,1,1,1
1,1,1,1,1,1,1,1,1,1,1,1
1,1,1,1,1,1,1,1,1,1,1,1
1,1,1,1,1,1,1,1,1,1,1,1
endlayer

layer
2,2,2,2,2,2,2,2,2,2,2,2
2,3,3,3,3,3,3,3,3,3,3,2
2,3,4,4,4,4,4,4,4,4,3,2
2,3,4,4,4,4,4,4,4,4,3,2
2,3,4,4,5,4,4,4,4,4,3,2
2,3,4,4,4,4,4,4,4,4,3,2
2,3,4,4,4,4,4,4,4,4,3,2
2,3,4,4,4,4,4,5,4,4,3,2
2,3,4,4,4,4,4,4,4,4,3,2
2,3,4,4,4,4,4,4,4,4,3,2
2,3,3,3,3,3,3,3,3,3,3,2
2,2,2,2,2,2,2,2,2,2,2,2
endlayer

layer
0,0,0,0,0,0,0,0,0,0,0,0
0,6,6,6,6,6,6,6,6,6,6,0
0,6,7,7,7,7,7,7,7,7,6,0
0,6,7,7,7,7,7,7,7,7,6,0
0,6,7,7,8,7,7,7,7,7,6,0
0,6,7,7,7,7,7,7,7,7,6,0
0,6,7,7,7,7,7,7,7,7,6,0
0,6,7,7,7,7,7,8,7,7,6,0
0,6,7,7,7,7,7,7,7,7,6,0
0,6,7,7,7,7,7,7,7,7,6,0
0,6,6,6,6,6,6,6,6,6,6,0
0,0,0,0,0,0,0,0,0,0,0,0
endlayer

layer
0,0,0,0,0,0,0,0,0,0,0,0
0,0,0,0,0,0,0,0,0,0,0,0
0,0,0,0,0,0,0,0,0,0,0,0
0,0,0,0,0,0,0,0,0,0,0,0
0,0,0,0,9,0,0,0,0,0,0,0
0,0,0,0,0,0,0,0,0,0,0,0
0,0,0,0,0,0,0,0,0,0,0,0
0,0,0,0,0,0,0,9,0,0,0,0
0,0,0,0,0,0,0,0,0,0,0,0
0,0,0,0,0,0,0,0,0,0,0,0
0,0,0,0,0,0,0,0,0,0,0,0
0,0,0,0,0,0,0,0,0,0,0,0
endlayer

