# Author: Malgor
# From: Minecraft Forums

weight=6
embed_into_distance=1
acceptable_target_blocks=2,3
dimensions=3,7,7
allowable_overhang=2
max_cut_in=2
cut_in_buffer=1
max_leveling=2
leveling_buffer=1
preserve_water=0
preserve_lava=0
preserve_plants=1

rule1=0,100,2,2,3
rule2=1,95,8,8,8,8,3
rule3=0,80,60
rule4=1,70,59-1,59-2,59-3
rule5=1,40,85

layer
1,1,1,1,1,1,1
1,3,3,2,3,3,1
1,3,3,2,3,3,1
1,2,2,2,2,2,1
1,3,3,2,3,3,1
1,3,3,2,3,3,1
1,1,1,1,1,1,1
endlayer

layer
5,5,5,5,5,5,5
5,4,4,0,4,4,5
5,4,4,0,4,4,5
5,0,0,0,0,0,5
5,4,4,0,4,4,5
5,4,4,0,4,4,5
5,5,5,5,5,5,5
endlayer

layer
0,0,0,0,0,0,0
0,0,0,0,0,0,0
0,0,0,0,0,0,0
0,0,0,0,0,0,0
0,0,0,0,0,0,0
0,0,0,0,0,0,0
0,0,0,0,0,0,0
endlayer