weight=1
embed_into_distance=1
acceptable_target_blocks=1,2,3,12,13,24
dimensions=6,5,5
cut_in_buffer=1
max_leveling=2
leveling_buffer=1
preserve_water=0
preserve_lava=0
preserve_plants=0
max_cut_in=10


rule1=0,100,4
rule2=0,100,5
rule3=0,100,65-5
rule4=0,100,102
rule5=0,100,50-2
rule6=0,100,17
rule7=0,100,85


layer
1,1,1,1,1
1,1,1,1,1
1,1,1,1,1
1,1,1,1,1
1,1,1,1,1
endlayer

layer
1,2,2,2,1
2,0,0,3,2
2,0,0,0,2
2,0,0,0,2
1,2,0,2,1
endlayer

layer
1,2,4,2,1
2,0,0,3,2
4,0,0,0,4
2,0,0,0,2
1,2,0,2,1
endlayer

layer
1,2,2,2,1
2,0,0,3,2
2,0,0,0,2
2,0,5,0,2
1,2,2,2,1
endlayer

layer
6,6,6,6,6
6,2,2,3,6
6,2,2,2,6
6,2,2,2,6
6,6,6,6,6
endlayer

layer
7,7,7,7,7
7,0,0,0,7
7,0,0,0,7
7,0,0,0,7
7,7,7,7,7
endlayer

