# Author: Malgor
# From: Minecraft Forums

weight=1
embed_into_distance=4
acceptable_target_blocks=1,2,3
dimensions=10,12,12
allowable_overhang=2
max_cut_in=2
cut_in_buffer=1
max_leveling=2
leveling_buffer=1
preserve_water=0
preserve_lava=0
preserve_plants=0

rule1=1,85,1,1,1,1,1,1,1,1,1,4,48,48
rule2=2,70,1,1,1,1,1,1,1,1,1,4,48,48
rule3=0,100,300

layer
3,3,3,3,3,3,3,3,3,3,3,3
3,1,1,3,1,3,3,1,3,1,1,3
3,1,1,3,3,3,3,3,3,1,1,3
3,3,3,3,3,3,3,3,3,3,3,3
3,1,3,3,1,3,3,1,3,3,1,3
3,3,3,3,3,3,3,3,3,3,3,3
3,3,3,3,3,3,3,3,3,3,3,3
3,1,3,3,1,3,3,1,3,3,1,3
3,3,3,3,3,3,3,3,3,3,3,3
3,1,1,3,3,3,3,3,3,1,1,3
3,1,1,3,1,3,3,1,3,1,1,3
3,3,3,3,3,3,3,3,3,3,3,3
endlayer

layer
3,3,3,3,3,3,3,3,3,3,3,3
3,1,1,3,1,3,3,1,3,1,1,3
3,1,1,3,3,3,3,3,3,1,1,3
3,3,3,3,3,3,3,3,3,3,3,3
3,1,3,3,1,3,3,1,3,3,1,3
3,3,3,3,3,3,3,3,3,3,3,3
3,3,3,3,3,3,3,3,3,3,3,3
3,1,3,3,1,3,3,1,3,3,1,3
3,3,3,3,3,3,3,3,3,3,3,3
3,1,1,3,3,3,3,3,3,1,1,3
3,1,1,3,1,3,3,1,3,1,1,3
3,3,3,3,3,3,3,3,3,3,3,3
endlayer

layer
3,3,3,3,3,3,3,3,3,3,3,3
3,1,1,3,1,3,3,1,3,1,1,3
3,1,1,3,3,3,3,3,3,1,1,3
3,3,3,3,3,3,3,3,3,3,3,3
3,1,3,3,1,3,3,1,3,3,1,3
3,3,3,3,3,3,3,3,3,3,3,3
3,3,3,3,3,3,3,3,3,3,3,3
3,1,3,3,1,3,3,1,3,3,1,3
3,3,3,3,3,3,3,3,3,3,3,3
3,1,1,3,3,3,3,3,3,1,1,3
3,1,1,3,1,3,3,1,3,1,1,3
3,3,3,3,3,3,3,3,3,3,3,3
endlayer

layer
3,3,3,3,3,3,3,3,3,3,3,3
3,1,1,3,1,3,3,1,3,1,1,3
3,1,1,3,3,3,3,3,3,1,1,3
3,3,3,3,3,3,3,3,3,3,3,3
3,1,3,3,1,3,3,1,3,3,1,3
3,3,3,3,3,3,3,3,3,3,3,3
3,3,3,3,3,3,3,3,3,3,3,3
3,1,3,3,1,3,3,1,3,3,1,3
3,3,3,3,3,3,3,3,3,3,3,3
3,1,1,3,3,3,3,3,3,1,1,3
3,1,1,3,1,3,3,1,3,1,1,3
3,3,3,3,3,3,3,3,3,3,3,3
endlayer

layer
3,3,3,3,3,3,3,3,3,3,3,3
3,1,1,3,1,3,3,1,3,1,1,3
3,1,1,3,3,3,3,3,3,1,1,3
3,3,3,3,3,3,3,3,3,3,3,3
3,1,3,3,1,3,3,1,3,3,1,3
3,3,3,3,3,3,3,3,3,3,3,3
3,3,3,3,3,3,3,3,3,3,3,3
3,1,3,3,1,3,3,1,3,3,1,3
3,3,3,3,3,3,3,3,3,3,3,3
3,1,1,3,3,3,3,3,3,1,1,3
3,1,1,3,1,3,3,1,3,1,1,3
3,3,3,3,3,3,3,3,3,3,3,3
endlayer

layer
0,0,0,0,0,0,0,0,0,0,0,0
0,1,1,0,1,0,0,1,0,1,1,0
0,1,1,0,0,0,0,0,0,1,1,0
0,0,0,0,0,0,0,0,0,0,0,0
0,1,0,0,1,0,0,1,0,0,1,0
0,0,0,0,0,0,0,0,0,0,0,0
0,0,0,0,0,0,0,0,0,0,0,0
0,1,0,0,1,0,0,1,0,0,1,0
0,0,0,0,0,0,0,0,0,0,0,0
0,1,1,0,0,0,0,0,0,1,1,0
0,1,1,0,1,0,0,1,0,1,1,0
0,0,0,0,0,0,0,0,0,0,0,0
endlayer

layer
0,0,0,0,0,0,0,0,0,0,0,0
0,1,1,0,1,0,0,1,0,1,1,0
0,1,1,0,0,0,0,0,0,1,1,0
0,0,0,0,0,0,0,0,0,0,0,0
0,1,0,0,1,0,0,1,0,0,1,0
0,0,0,0,0,0,0,0,0,0,0,0
0,0,0,0,0,0,0,0,0,0,0,0
0,1,0,0,1,0,0,1,0,0,1,0
0,0,0,0,0,0,0,0,0,0,0,0
0,1,1,0,0,0,0,0,0,1,1,0
0,1,1,0,1,0,0,1,0,1,1,0
0,0,0,0,0,0,0,0,0,0,0,0
endlayer

layer
0,0,0,0,0,0,0,0,0,0,0,0
0,1,1,0,1,2,2,1,0,1,1,0
0,1,1,0,0,0,0,0,0,1,1,0
0,0,0,0,0,0,0,0,0,0,0,0
0,1,0,0,1,2,2,1,0,0,1,0
0,2,0,0,0,0,0,0,0,0,2,0
0,2,0,0,0,0,0,0,0,0,2,0
0,1,0,0,1,2,2,1,0,0,1,0
0,0,0,0,0,0,0,0,0,0,0,0
0,1,1,0,0,0,0,0,0,1,1,0
0,1,1,0,1,2,2,1,0,1,1,0
0,0,0,0,0,0,0,0,0,0,0,0
endlayer

layer
0,0,0,0,0,0,0,0,0,0,0,0
0,1,1,0,0,0,0,0,0,1,1,0
0,1,1,0,0,0,0,0,0,1,1,0
0,0,0,0,0,0,0,0,0,0,0,0
0,0,0,0,1,0,0,1,0,0,0,0
0,0,0,0,2,0,0,2,0,0,0,0
0,0,0,0,2,0,0,2,0,0,0,0
0,0,0,0,1,0,0,1,0,0,0,0
0,0,0,0,0,0,0,0,0,0,0,0
0,1,1,0,0,0,0,0,0,1,1,0
0,1,1,0,0,0,0,0,0,1,1,0
0,0,0,0,0,0,0,0,0,0,0,0
endlayer

layer
0,0,0,0,0,0,0,0,0,0,0,0
0,0,0,0,0,0,0,0,0,0,0,0
0,1,1,0,0,0,0,0,0,1,1,0
0,2,2,0,0,0,0,0,0,2,2,0
0,2,2,0,0,0,0,0,0,2,2,0
0,2,2,0,1,2,2,1,0,2,2,0
0,2,2,0,1,2,2,1,0,2,2,0
0,2,2,0,0,0,0,0,0,2,2,0
0,2,2,0,0,0,0,0,0,2,2,0
0,1,1,0,0,0,0,0,0,1,1,0
0,0,0,0,0,0,0,0,0,0,0,0
0,0,0,0,0,0,0,0,0,0,0,0
endlayer