package com.sirolf2009.necromancy.generation;

import java.util.Random;

import net.minecraft.init.Blocks;
import net.minecraft.world.World;
import net.minecraft.world.gen.feature.WorldGenerator;

import com.sirolf2009.necromancy.block.RegistryBlocksNecromancy;

public class WorldGenNetherChalice extends WorldGenerator
{

    @Override
    public boolean generate(World world, Random rand, int i, int j, int k)
    {
        if (world.getBlock(i, j, k) != Blocks.lava || world.getBlock(i, j + 1, k) != Blocks.air)
            return false;

        world.setBlock(i + 0, j + 19, k + 1, Blocks.nether_brick_fence, 0, 2);
        world.setBlock(i + 0, j + 19, k + 2, Blocks.nether_brick_stairs, 4, 2);

        world.setBlock(i + 0, j + 19, k + 3, Blocks.nether_brick_stairs, 4, 2);
        world.setBlock(i + 0, j + 19, k + 4, Blocks.nether_brick_stairs, 4, 2);
        world.setBlock(i + 0, j + 19, k + 5, Blocks.nether_brick_fence);
        world.setBlock(i + 0, j + 20, k + 1, Blocks.nether_brick_fence);
        world.setBlock(i + 0, j + 20, k + 2, Blocks.nether_brick);
        world.setBlock(i + 0, j + 20, k + 3, Blocks.nether_brick);
        world.setBlock(i + 0, j + 20, k + 4, Blocks.nether_brick);
        world.setBlock(i + 0, j + 20, k + 5, Blocks.nether_brick_fence);
        world.setBlock(i + 0, j + 21, k + 1, Blocks.nether_brick_fence);
        world.setBlock(i + 0, j + 21, k + 2, Blocks.nether_brick_fence);
        world.setBlock(i + 0, j + 21, k + 3, Blocks.nether_brick_fence);
        world.setBlock(i + 0, j + 21, k + 4, Blocks.nether_brick_fence);
        world.setBlock(i + 0, j + 21, k + 5, Blocks.nether_brick_fence);
        world.setBlock(i + 1, j + 18, k + 1, Blocks.nether_brick_fence);
        world.setBlock(i + 1, j + 18, k + 2, Blocks.nether_brick_stairs, 4, 2);
        world.setBlock(i + 1, j + 18, k + 3, Blocks.nether_brick_stairs, 4, 2);
        world.setBlock(i + 1, j + 18, k + 4, Blocks.nether_brick_stairs, 4, 2);
        world.setBlock(i + 1, j + 18, k + 5, Blocks.nether_brick_fence);
        world.setBlock(i + 1, j + 19, k + 0, Blocks.nether_brick_fence);
        world.setBlock(i + 1, j + 19, k + 1, Blocks.nether_brick);
        world.setBlock(i + 1, j + 19, k + 2, Blocks.nether_brick);
        world.setBlock(i + 1, j + 19, k + 3, Blocks.nether_brick);
        world.setBlock(i + 1, j + 19, k + 4, Blocks.nether_brick);
        world.setBlock(i + 1, j + 19, k + 5, Blocks.nether_brick);
        world.setBlock(i + 1, j + 19, k + 6, Blocks.nether_brick_fence);
        world.setBlock(i + 1, j + 20, k + 0, Blocks.nether_brick_fence);
        world.setBlock(i + 1, j + 20, k + 1, Blocks.nether_brick);
        world.setBlock(i + 1, j + 20, k + 5, Blocks.nether_brick);
        world.setBlock(i + 1, j + 20, k + 6, Blocks.nether_brick_fence);
        world.setBlock(i + 1, j + 21, k + 0, Blocks.nether_brick_fence);
        world.setBlock(i + 1, j + 21, k + 1, Blocks.nether_brick_fence);
        world.setBlock(i + 1, j + 21, k + 5, Blocks.nether_brick_fence);
        world.setBlock(i + 1, j + 21, k + 6, Blocks.nether_brick_fence);
        world.setBlock(i + 2, j + 0, k + 2, Blocks.iron_bars);
        world.setBlock(i + 2, j + 0, k + 3, Blocks.iron_bars);
        world.setBlock(i + 2, j + 0, k + 4, Blocks.iron_bars);
        world.setBlock(i + 2, j + 1, k + 2, Blocks.iron_bars);
        world.setBlock(i + 2, j + 1, k + 3, Blocks.iron_bars);
        world.setBlock(i + 2, j + 1, k + 4, Blocks.iron_bars);
        world.setBlock(i + 2, j + 2, k + 2, Blocks.iron_bars);
        world.setBlock(i + 2, j + 2, k + 3, Blocks.iron_bars);
        world.setBlock(i + 2, j + 2, k + 4, Blocks.iron_bars);
        world.setBlock(i + 2, j + 3, k + 2, Blocks.iron_bars);
        world.setBlock(i + 2, j + 3, k + 3, Blocks.iron_bars);
        world.setBlock(i + 2, j + 3, k + 4, Blocks.iron_bars);
        world.setBlock(i + 2, j + 4, k + 2, Blocks.iron_bars);
        world.setBlock(i + 2, j + 4, k + 3, Blocks.iron_bars);
        world.setBlock(i + 2, j + 4, k + 4, Blocks.iron_bars);
        world.setBlock(i + 2, j + 5, k + 2, Blocks.iron_bars);
        world.setBlock(i + 2, j + 5, k + 3, Blocks.iron_bars);
        world.setBlock(i + 2, j + 5, k + 4, Blocks.iron_bars);
        world.setBlock(i + 2, j + 6, k + 2, Blocks.iron_bars);
        world.setBlock(i + 2, j + 6, k + 3, Blocks.iron_bars);
        world.setBlock(i + 2, j + 6, k + 4, Blocks.iron_bars);
        world.setBlock(i + 2, j + 7, k + 2, Blocks.iron_bars);
        world.setBlock(i + 2, j + 7, k + 3, Blocks.iron_bars);
        world.setBlock(i + 2, j + 7, k + 4, Blocks.iron_bars);
        world.setBlock(i + 2, j + 8, k + 2, Blocks.iron_bars);
        world.setBlock(i + 2, j + 8, k + 3, Blocks.iron_bars);
        world.setBlock(i + 2, j + 8, k + 4, Blocks.iron_bars);
        world.setBlock(i + 2, j + 9, k + 2, Blocks.iron_bars);
        world.setBlock(i + 2, j + 9, k + 3, Blocks.iron_bars);
        world.setBlock(i + 2, j + 9, k + 4, Blocks.iron_bars);
        world.setBlock(i + 2, j + 10, k + 2, Blocks.iron_bars);
        world.setBlock(i + 2, j + 10, k + 3, Blocks.iron_bars);
        world.setBlock(i + 2, j + 10, k + 4, Blocks.iron_bars);
        world.setBlock(i + 2, j + 11, k + 2, Blocks.iron_bars);
        world.setBlock(i + 2, j + 11, k + 3, Blocks.iron_bars);
        world.setBlock(i + 2, j + 11, k + 4, Blocks.iron_bars);
        world.setBlock(i + 2, j + 12, k + 2, Blocks.iron_bars);
        world.setBlock(i + 2, j + 12, k + 3, Blocks.iron_bars);
        world.setBlock(i + 2, j + 12, k + 4, Blocks.iron_bars);
        world.setBlock(i + 2, j + 13, k + 2, Blocks.iron_bars);
        world.setBlock(i + 2, j + 13, k + 3, Blocks.iron_bars);
        world.setBlock(i + 2, j + 13, k + 4, Blocks.iron_bars);
        world.setBlock(i + 2, j + 14, k + 2, Blocks.iron_bars);
        world.setBlock(i + 2, j + 14, k + 3, Blocks.iron_bars);
        world.setBlock(i + 2, j + 14, k + 4, Blocks.iron_bars);
        world.setBlock(i + 2, j + 15, k + 2, Blocks.iron_bars);
        world.setBlock(i + 2, j + 15, k + 3, Blocks.iron_bars);
        world.setBlock(i + 2, j + 15, k + 4, Blocks.iron_bars);
        world.setBlock(i + 2, j + 16, k + 2, Blocks.iron_bars);
        world.setBlock(i + 2, j + 16, k + 3, Blocks.iron_bars);
        world.setBlock(i + 2, j + 16, k + 4, Blocks.iron_bars);
        world.setBlock(i + 2, j + 17, k + 2, Blocks.iron_bars);
        world.setBlock(i + 2, j + 17, k + 3, Blocks.iron_bars);
        world.setBlock(i + 2, j + 17, k + 4, Blocks.iron_bars);
        world.setBlock(i + 2, j + 18, k + 1, Blocks.nether_brick_stairs, 6, 2);
        world.setBlock(i + 2, j + 18, k + 2, Blocks.nether_brick);
        world.setBlock(i + 2, j + 18, k + 3, Blocks.nether_brick);
        world.setBlock(i + 2, j + 18, k + 4, Blocks.nether_brick);
        world.setBlock(i + 2, j + 18, k + 5, Blocks.nether_brick_stairs, 7, 2);
        world.setBlock(i + 2, j + 19, k + 0, Blocks.nether_brick_stairs, 6, 2);
        world.setBlock(i + 2, j + 19, k + 1, Blocks.nether_brick);
        world.setBlock(i + 2, j + 19, k + 5, Blocks.nether_brick);
        world.setBlock(i + 2, j + 19, k + 6, Blocks.nether_brick_stairs, 7, 2);
        world.setBlock(i + 2, j + 20, k + 0, Blocks.nether_brick);
        world.setBlock(i + 2, j + 20, k + 6, Blocks.nether_brick);
        world.setBlock(i + 2, j + 21, k + 0, Blocks.nether_brick_fence);
        world.setBlock(i + 2, j + 21, k + 6, Blocks.nether_brick_fence);
        world.setBlock(i + 3, j + 0, k + 2, Blocks.iron_bars);
        world.setBlock(i + 3, j + 0, k + 4, Blocks.iron_bars);
        world.setBlock(i + 3, j + 1, k + 2, Blocks.iron_bars);
        world.setBlock(i + 3, j + 1, k + 4, Blocks.iron_bars);
        world.setBlock(i + 3, j + 2, k + 2, Blocks.iron_bars);
        world.setBlock(i + 3, j + 2, k + 4, Blocks.iron_bars);
        world.setBlock(i + 3, j + 3, k + 2, Blocks.iron_bars);
        world.setBlock(i + 3, j + 3, k + 4, Blocks.iron_bars);
        world.setBlock(i + 3, j + 4, k + 2, Blocks.iron_bars);
        world.setBlock(i + 3, j + 4, k + 4, Blocks.iron_bars);
        world.setBlock(i + 3, j + 5, k + 2, Blocks.iron_bars);
        world.setBlock(i + 3, j + 5, k + 4, Blocks.iron_bars);
        world.setBlock(i + 3, j + 6, k + 2, Blocks.iron_bars);
        world.setBlock(i + 3, j + 6, k + 4, Blocks.iron_bars);
        world.setBlock(i + 3, j + 7, k + 2, Blocks.iron_bars);
        world.setBlock(i + 3, j + 7, k + 4, Blocks.iron_bars);
        world.setBlock(i + 3, j + 8, k + 2, Blocks.iron_bars);
        world.setBlock(i + 3, j + 8, k + 4, Blocks.iron_bars);
        world.setBlock(i + 3, j + 9, k + 2, Blocks.iron_bars);
        world.setBlock(i + 3, j + 9, k + 4, Blocks.iron_bars);
        world.setBlock(i + 3, j + 10, k + 2, Blocks.iron_bars);
        world.setBlock(i + 3, j + 10, k + 4, Blocks.iron_bars);
        world.setBlock(i + 3, j + 11, k + 2, Blocks.iron_bars);
        world.setBlock(i + 3, j + 11, k + 4, Blocks.iron_bars);
        world.setBlock(i + 3, j + 12, k + 2, Blocks.iron_bars);
        world.setBlock(i + 3, j + 12, k + 4, Blocks.iron_bars);
        world.setBlock(i + 3, j + 13, k + 2, Blocks.iron_bars);
        world.setBlock(i + 3, j + 13, k + 4, Blocks.iron_bars);
        world.setBlock(i + 3, j + 14, k + 2, Blocks.iron_bars);
        world.setBlock(i + 3, j + 14, k + 4, Blocks.iron_bars);
        world.setBlock(i + 3, j + 15, k + 2, Blocks.iron_bars);
        world.setBlock(i + 3, j + 15, k + 4, Blocks.iron_bars);
        world.setBlock(i + 3, j + 16, k + 2, Blocks.iron_bars);
        world.setBlock(i + 3, j + 16, k + 4, Blocks.iron_bars);
        world.setBlock(i + 3, j + 17, k + 2, Blocks.iron_bars);
        world.setBlock(i + 3, j + 17, k + 4, Blocks.iron_bars);
        world.setBlock(i + 3, j + 18, k + 1, Blocks.nether_brick_stairs, 6, 2);
        world.setBlock(i + 3, j + 18, k + 2, Blocks.nether_brick);
        world.setBlock(i + 3, j + 18, k + 4, Blocks.nether_brick);
        world.setBlock(i + 3, j + 18, k + 5, Blocks.nether_brick_stairs, 7, 2);
        world.setBlock(i + 3, j + 19, k + 0, Blocks.nether_brick_stairs, 6, 2);
        world.setBlock(i + 3, j + 19, k + 1, Blocks.nether_brick);
        world.setBlock(i + 3, j + 19, k + 5, Blocks.nether_brick);
        world.setBlock(i + 3, j + 19, k + 6, Blocks.nether_brick_stairs, 7, 2);
        world.setBlock(i + 3, j + 20, k + 0, Blocks.nether_brick);
        world.setBlock(i + 3, j + 20, k + 6, Blocks.nether_brick);
        world.setBlock(i + 3, j + 21, k + 0, Blocks.nether_brick_fence);
        world.setBlock(i + 3, j + 21, k + 6, Blocks.nether_brick_fence);
        world.setBlock(i + 4, j + 0, k + 2, Blocks.iron_bars);
        world.setBlock(i + 4, j + 0, k + 3, Blocks.iron_bars);
        world.setBlock(i + 4, j + 0, k + 4, Blocks.iron_bars);
        world.setBlock(i + 4, j + 1, k + 2, Blocks.iron_bars);
        world.setBlock(i + 4, j + 1, k + 3, Blocks.iron_bars);
        world.setBlock(i + 4, j + 1, k + 4, Blocks.iron_bars);
        world.setBlock(i + 4, j + 2, k + 2, Blocks.iron_bars);
        world.setBlock(i + 4, j + 2, k + 3, Blocks.iron_bars);
        world.setBlock(i + 4, j + 2, k + 4, Blocks.iron_bars);
        world.setBlock(i + 4, j + 3, k + 2, Blocks.iron_bars);
        world.setBlock(i + 4, j + 3, k + 3, Blocks.iron_bars);
        world.setBlock(i + 4, j + 3, k + 4, Blocks.iron_bars);
        world.setBlock(i + 4, j + 4, k + 2, Blocks.iron_bars);
        world.setBlock(i + 4, j + 4, k + 3, Blocks.iron_bars);
        world.setBlock(i + 4, j + 4, k + 4, Blocks.iron_bars);
        world.setBlock(i + 4, j + 5, k + 2, Blocks.iron_bars);
        world.setBlock(i + 4, j + 5, k + 3, Blocks.iron_bars);
        world.setBlock(i + 4, j + 5, k + 4, Blocks.iron_bars);
        world.setBlock(i + 4, j + 6, k + 2, Blocks.iron_bars);
        world.setBlock(i + 4, j + 6, k + 3, Blocks.iron_bars);
        world.setBlock(i + 4, j + 6, k + 4, Blocks.iron_bars);
        world.setBlock(i + 4, j + 7, k + 2, Blocks.iron_bars);
        world.setBlock(i + 4, j + 7, k + 3, Blocks.iron_bars);
        world.setBlock(i + 4, j + 7, k + 4, Blocks.iron_bars);
        world.setBlock(i + 4, j + 8, k + 2, Blocks.iron_bars);
        world.setBlock(i + 4, j + 8, k + 3, Blocks.iron_bars);
        world.setBlock(i + 4, j + 8, k + 4, Blocks.iron_bars);
        world.setBlock(i + 4, j + 9, k + 2, Blocks.iron_bars);
        world.setBlock(i + 4, j + 9, k + 3, Blocks.iron_bars);
        world.setBlock(i + 4, j + 9, k + 4, Blocks.iron_bars);
        world.setBlock(i + 4, j + 10, k + 2, Blocks.iron_bars);
        world.setBlock(i + 4, j + 10, k + 3, Blocks.iron_bars);
        world.setBlock(i + 4, j + 10, k + 4, Blocks.iron_bars);
        world.setBlock(i + 4, j + 11, k + 2, Blocks.iron_bars);
        world.setBlock(i + 4, j + 11, k + 3, Blocks.iron_bars);
        world.setBlock(i + 4, j + 11, k + 4, Blocks.iron_bars);
        world.setBlock(i + 4, j + 12, k + 2, Blocks.iron_bars);
        world.setBlock(i + 4, j + 12, k + 3, Blocks.iron_bars);
        world.setBlock(i + 4, j + 12, k + 4, Blocks.iron_bars);
        world.setBlock(i + 4, j + 13, k + 2, Blocks.iron_bars);
        world.setBlock(i + 4, j + 13, k + 3, Blocks.iron_bars);
        world.setBlock(i + 4, j + 13, k + 4, Blocks.iron_bars);
        world.setBlock(i + 4, j + 14, k + 2, Blocks.iron_bars);
        world.setBlock(i + 4, j + 14, k + 3, Blocks.iron_bars);
        world.setBlock(i + 4, j + 14, k + 4, Blocks.iron_bars);
        world.setBlock(i + 4, j + 15, k + 2, Blocks.iron_bars);
        world.setBlock(i + 4, j + 15, k + 3, Blocks.iron_bars);
        world.setBlock(i + 4, j + 15, k + 4, Blocks.iron_bars);
        world.setBlock(i + 4, j + 16, k + 2, Blocks.iron_bars);
        world.setBlock(i + 4, j + 16, k + 3, Blocks.iron_bars);
        world.setBlock(i + 4, j + 16, k + 4, Blocks.iron_bars);
        world.setBlock(i + 4, j + 17, k + 2, Blocks.iron_bars);
        world.setBlock(i + 4, j + 17, k + 3, Blocks.iron_bars);
        world.setBlock(i + 4, j + 17, k + 4, Blocks.iron_bars);
        world.setBlock(i + 4, j + 18, k + 1, Blocks.nether_brick_stairs, 6, 2);
        world.setBlock(i + 4, j + 18, k + 2, Blocks.nether_brick);
        world.setBlock(i + 4, j + 18, k + 3, Blocks.nether_brick);
        world.setBlock(i + 4, j + 18, k + 4, Blocks.nether_brick);
        world.setBlock(i + 4, j + 18, k + 5, Blocks.nether_brick_stairs, 7, 2);
        world.setBlock(i + 4, j + 19, k + 0, Blocks.nether_brick_stairs, 6, 2);
        world.setBlock(i + 4, j + 19, k + 1, Blocks.nether_brick);
        world.setBlock(i + 4, j + 19, k + 5, Blocks.nether_brick);
        world.setBlock(i + 4, j + 19, k + 6, Blocks.nether_brick_stairs, 7, 2);
        world.setBlock(i + 4, j + 20, k + 0, Blocks.nether_brick);
        world.setBlock(i + 4, j + 20, k + 6, Blocks.nether_brick);
        world.setBlock(i + 4, j + 21, k + 0, Blocks.nether_brick_fence);
        world.setBlock(i + 4, j + 21, k + 6, Blocks.nether_brick_fence);
        world.setBlock(i + 5, j + 18, k + 1, Blocks.nether_brick_fence);
        world.setBlock(i + 5, j + 18, k + 2, Blocks.nether_brick_stairs, 5, 2);
        world.setBlock(i + 5, j + 18, k + 3, Blocks.nether_brick_stairs, 5, 2);
        world.setBlock(i + 5, j + 18, k + 4, Blocks.nether_brick_stairs, 5, 2);
        world.setBlock(i + 5, j + 18, k + 5, Blocks.nether_brick_fence);
        world.setBlock(i + 5, j + 19, k + 0, Blocks.nether_brick_fence);
        world.setBlock(i + 5, j + 19, k + 1, Blocks.nether_brick);
        world.setBlock(i + 5, j + 19, k + 2, Blocks.nether_brick);
        world.setBlock(i + 5, j + 19, k + 3, Blocks.nether_brick);
        world.setBlock(i + 5, j + 19, k + 4, Blocks.nether_brick);
        world.setBlock(i + 5, j + 19, k + 5, Blocks.nether_brick);
        world.setBlock(i + 5, j + 19, k + 6, Blocks.nether_brick_fence);
        world.setBlock(i + 5, j + 20, k + 0, Blocks.nether_brick_fence);
        world.setBlock(i + 5, j + 20, k + 1, Blocks.nether_brick);
        world.setBlock(i + 5, j + 20, k + 5, Blocks.nether_brick);
        world.setBlock(i + 5, j + 20, k + 6, Blocks.nether_brick_fence);
        world.setBlock(i + 5, j + 21, k + 0, Blocks.nether_brick_fence);
        world.setBlock(i + 5, j + 21, k + 1, Blocks.nether_brick_fence);
        world.setBlock(i + 5, j + 21, k + 5, Blocks.nether_brick_fence);
        world.setBlock(i + 5, j + 21, k + 6, Blocks.nether_brick_fence);
        world.setBlock(i + 6, j + 19, k + 1, Blocks.nether_brick_fence);
        world.setBlock(i + 6, j + 19, k + 2, Blocks.nether_brick_stairs, 5, 2);
        world.setBlock(i + 6, j + 19, k + 3, Blocks.nether_brick_stairs, 5, 2);
        world.setBlock(i + 6, j + 19, k + 4, Blocks.nether_brick_stairs, 5, 2);
        world.setBlock(i + 6, j + 19, k + 5, Blocks.nether_brick_fence);
        world.setBlock(i + 6, j + 20, k + 1, Blocks.nether_brick_fence);
        world.setBlock(i + 6, j + 20, k + 2, Blocks.nether_brick);
        world.setBlock(i + 6, j + 20, k + 3, Blocks.nether_brick);
        world.setBlock(i + 6, j + 20, k + 4, Blocks.nether_brick);
        world.setBlock(i + 6, j + 20, k + 5, Blocks.nether_brick_fence);
        world.setBlock(i + 6, j + 21, k + 1, Blocks.nether_brick_fence);
        world.setBlock(i + 6, j + 21, k + 2, Blocks.nether_brick_fence);
        world.setBlock(i + 6, j + 21, k + 3, Blocks.nether_brick_fence);
        world.setBlock(i + 6, j + 21, k + 4, Blocks.nether_brick_fence);
        world.setBlock(i + 6, j + 21, k + 5, Blocks.nether_brick_fence);
        world.setBlock(i + 0, j + 22, k + 1, Blocks.redstone_torch, 5, 2);
        world.setBlock(i + 0, j + 22, k + 5, Blocks.redstone_torch, 5, 2);
        world.setBlock(i + 1, j + 20, k + 2, RegistryBlocksNecromancy.blood);
        world.setBlock(i + 1, j + 20, k + 3, RegistryBlocksNecromancy.blood);
        world.setBlock(i + 1, j + 20, k + 4, RegistryBlocksNecromancy.blood);
        world.setBlock(i + 1, j + 22, k + 0, Blocks.redstone_torch, 5, 2);
        world.setBlock(i + 1, j + 22, k + 6, Blocks.redstone_torch, 5, 2);
        world.setBlock(i + 2, j + 19, k + 2, RegistryBlocksNecromancy.blood, 9, 2);
        world.setBlock(i + 2, j + 19, k + 3, RegistryBlocksNecromancy.blood, 9, 2);
        world.setBlock(i + 2, j + 19, k + 4, RegistryBlocksNecromancy.blood, 9, 2);
        world.setBlock(i + 2, j + 20, k + 1, RegistryBlocksNecromancy.blood);
        world.setBlock(i + 2, j + 20, k + 2, RegistryBlocksNecromancy.blood, 1, 2);
        world.setBlock(i + 2, j + 20, k + 3, RegistryBlocksNecromancy.blood, 1, 2);
        world.setBlock(i + 2, j + 20, k + 4, RegistryBlocksNecromancy.blood, 1, 2);
        world.setBlock(i + 2, j + 20, k + 5, RegistryBlocksNecromancy.blood);
        world.setBlock(i + 3, j + 0, k + 3, RegistryBlocksNecromancy.blood, 9, 2);
        world.setBlock(i + 3, j + 1, k + 3, RegistryBlocksNecromancy.blood, 9, 2);
        world.setBlock(i + 3, j + 2, k + 3, RegistryBlocksNecromancy.blood, 9, 2);
        world.setBlock(i + 3, j + 3, k + 3, RegistryBlocksNecromancy.blood, 9, 2);
        world.setBlock(i + 3, j + 4, k + 3, RegistryBlocksNecromancy.blood, 9, 2);
        world.setBlock(i + 3, j + 5, k + 3, RegistryBlocksNecromancy.blood, 9, 2);
        world.setBlock(i + 3, j + 6, k + 3, RegistryBlocksNecromancy.blood, 9, 2);
        world.setBlock(i + 3, j + 7, k + 3, RegistryBlocksNecromancy.blood, 9, 2);
        world.setBlock(i + 3, j + 8, k + 3, RegistryBlocksNecromancy.blood, 9, 2);
        world.setBlock(i + 3, j + 9, k + 3, RegistryBlocksNecromancy.blood, 9, 2);
        world.setBlock(i + 3, j + 10, k + 3, RegistryBlocksNecromancy.blood, 9, 2);
        world.setBlock(i + 3, j + 11, k + 3, RegistryBlocksNecromancy.blood, 9, 2);
        world.setBlock(i + 3, j + 12, k + 3, RegistryBlocksNecromancy.blood, 9, 2);
        world.setBlock(i + 3, j + 13, k + 3, RegistryBlocksNecromancy.blood, 9, 2);
        world.setBlock(i + 3, j + 14, k + 3, RegistryBlocksNecromancy.blood, 9, 2);
        world.setBlock(i + 3, j + 15, k + 3, RegistryBlocksNecromancy.blood, 9, 2);
        world.setBlock(i + 3, j + 16, k + 3, RegistryBlocksNecromancy.blood, 9, 2);
        world.setBlock(i + 3, j + 17, k + 3, RegistryBlocksNecromancy.blood, 9, 2);
        world.setBlock(i + 3, j + 18, k + 3, RegistryBlocksNecromancy.blood, 9, 2);
        world.setBlock(i + 3, j + 19, k + 2, RegistryBlocksNecromancy.blood, 9, 2);
        world.setBlock(i + 3, j + 19, k + 3, RegistryBlocksNecromancy.blood, 1, 2);
        world.setBlock(i + 3, j + 19, k + 4, RegistryBlocksNecromancy.blood, 9, 2);
        world.setBlock(i + 3, j + 20, k + 1, RegistryBlocksNecromancy.blood);
        world.setBlock(i + 3, j + 20, k + 2, RegistryBlocksNecromancy.blood, 1, 2);
        world.setBlock(i + 3, j + 20, k + 4, RegistryBlocksNecromancy.blood, 1, 2);
        world.setBlock(i + 3, j + 20, k + 5, RegistryBlocksNecromancy.blood);
        world.setBlock(i + 4, j + 19, k + 2, RegistryBlocksNecromancy.blood, 9, 2);
        world.setBlock(i + 4, j + 19, k + 3, RegistryBlocksNecromancy.blood, 9, 2);
        world.setBlock(i + 4, j + 19, k + 4, RegistryBlocksNecromancy.blood, 9, 2);
        world.setBlock(i + 4, j + 20, k + 1, RegistryBlocksNecromancy.blood);
        world.setBlock(i + 4, j + 20, k + 2, RegistryBlocksNecromancy.blood, 1, 2);
        world.setBlock(i + 4, j + 20, k + 3, RegistryBlocksNecromancy.blood, 1, 2);
        world.setBlock(i + 4, j + 20, k + 4, RegistryBlocksNecromancy.blood, 1, 2);
        world.setBlock(i + 4, j + 20, k + 5, RegistryBlocksNecromancy.blood);
        world.setBlock(i + 5, j + 20, k + 2, RegistryBlocksNecromancy.blood);
        world.setBlock(i + 5, j + 20, k + 3, RegistryBlocksNecromancy.blood);
        world.setBlock(i + 5, j + 20, k + 4, RegistryBlocksNecromancy.blood);
        world.setBlock(i + 5, j + 22, k + 0, Blocks.redstone_torch, 5, 2);
        world.setBlock(i + 5, j + 22, k + 6, Blocks.redstone_torch, 5, 2);
        world.setBlock(i + 6, j + 22, k + 1, Blocks.redstone_torch, 5, 2);
        world.setBlock(i + 6, j + 22, k + 5, Blocks.redstone_torch, 5, 2);

        return true;
    }
}