weight=10
embed_into_distance=3
acceptable_target_blocks=1,2,3,12,13,24
dimensions=24,12,12
allowable_overhang=0
max_cut_in=24
cut_in_buffer=0
max_leveling=0
leveling_buffer=0
preserve_water=0
preserve_lava=0
preserve_plants=1


rule1=0,0,35-14
#lower main blocks
rule2=0,75,48,4
#lower window blocks
rule3=0,80,48,4
#lower floor
rule4=2,70,43
#spawners
rule5=0,50,MediumMobSpawn
#chest pedestal
rule6=0,100,43
#lower stairs
rule7=2,75,67-1
#chests
rule8=0,75,HardMobSpawn,MediumChest,54,54
#upper main blocks
rule9=1,80,48,4
#upper window blocks
rule10=2,80,48,4
#upper floor
rule11=2,50,43
#upper stairs
rule12=2,50,67-1


layer
1,1,1,1,2,3,3,2,1,1,1,1
1,2,2,2,2,2,2,2,2,2,1,1
2,2,2,2,2,2,2,2,2,2,2,1
2,2,2,2,2,2,2,2,2,2,2,1
2,2,2,2,2,2,2,2,2,2,2,2
2,2,2,2,2,2,2,2,2,2,2,3
2,2,2,2,2,2,2,2,2,2,2,3
2,2,2,2,2,2,2,2,2,2,2,2
2,2,2,2,2,2,2,2,2,2,2,1
2,2,2,2,2,2,2,2,2,2,2,1
1,2,2,2,2,2,2,2,2,2,1,1
1,1,1,1,2,3,3,2,1,1,1,1
endlayer

layer
1,1,1,1,2,3,3,2,1,1,1,1
1,2,2,2,2,2,2,2,2,2,1,1
2,2,2,2,2,2,2,2,2,2,2,1
2,2,2,2,2,2,2,2,2,2,2,1
2,2,2,2,2,2,2,2,2,2,2,2
2,2,2,2,2,2,2,2,2,2,2,3
2,2,2,2,2,2,2,2,2,2,2,3
2,2,2,2,2,2,2,2,2,2,2,2
2,2,2,2,2,2,2,2,2,2,2,1
2,2,2,2,2,2,2,2,2,2,2,1
1,2,2,2,2,2,2,2,2,2,1,1
1,1,1,1,2,3,3,2,1,1,1,1
endlayer

layer
1,1,1,1,2,3,3,2,1,1,1,1
1,2,2,2,4,4,4,4,2,2,1,1
2,4,4,4,4,4,4,4,4,4,2,1
2,4,2,4,4,4,4,4,4,4,2,1
2,4,2,4,4,4,4,4,4,4,4,2
2,4,2,4,4,4,4,4,4,4,4,3
2,4,2,4,4,4,4,4,4,4,4,3
2,4,2,4,4,4,4,4,4,4,4,2
2,4,2,4,4,4,4,4,4,4,2,1
2,4,4,4,4,4,4,4,4,4,2,1
1,2,2,2,4,4,4,4,2,2,1,1
1,1,1,1,2,3,3,2,1,1,1,1
endlayer

layer
1,1,1,1,2,3,3,2,1,1,1,1
1,2,2,2,0,0,0,0,2,2,1,1
2,0,2,0,0,0,0,0,0,0,2,1
2,0,2,0,0,0,0,0,5,0,2,1
2,0,2,0,0,0,0,0,0,0,0,2
2,0,2,0,6,0,0,0,0,0,0,3
2,0,2,0,6,0,0,0,0,0,0,3
2,0,2,0,0,0,0,0,0,0,0,2
2,7,2,0,0,0,0,0,5,0,2,1
2,0,0,0,0,0,0,0,0,0,2,1
1,2,2,2,0,0,0,0,2,2,1,1
1,1,1,1,2,3,3,2,1,1,1,1
endlayer

layer
1,1,1,1,2,0,0,2,1,1,1,1
1,2,2,2,0,0,0,0,2,2,1,1
2,0,2,0,0,0,0,0,0,0,2,1
2,0,2,0,0,0,0,0,0,0,2,1
2,0,2,0,0,0,0,0,0,0,0,2
2,0,2,0,8,0,0,0,0,0,0,0
2,0,2,0,8,0,0,0,0,0,0,0
2,7,2,0,0,0,0,0,0,0,0,2
2,0,2,0,0,0,0,0,0,0,2,1
2,0,0,0,0,0,0,0,0,0,2,1
1,2,2,2,0,0,0,0,2,2,1,1
1,1,1,1,2,0,0,2,1,1,1,1
endlayer

layer
1,1,1,1,2,0,0,2,1,1,1,1
1,2,2,2,0,0,0,0,2,2,1,1
2,0,2,0,0,0,0,0,0,0,2,1
2,0,2,0,0,0,0,0,0,0,2,1
2,0,2,0,0,0,0,0,0,0,0,2
2,0,2,0,0,0,0,0,0,0,0,0
2,7,2,0,0,0,0,0,0,0,0,0
2,0,2,0,0,0,0,0,0,0,0,2
2,0,2,0,0,0,0,0,0,0,2,1
2,0,0,0,0,0,0,0,0,0,2,1
1,2,2,2,0,0,0,0,2,2,1,1
1,1,1,1,2,0,0,2,1,1,1,1
endlayer

layer
1,1,1,1,2,0,0,2,1,1,1,1
1,2,2,2,0,0,0,0,2,2,1,1
2,0,2,0,0,0,0,0,0,0,2,1
2,0,2,0,0,0,0,0,0,0,2,1
2,0,2,0,0,0,0,0,0,0,0,2
2,7,2,0,0,0,0,0,0,0,0,0
2,0,2,0,0,0,0,0,0,0,0,0
2,0,2,0,0,0,0,0,0,0,0,2
2,0,2,0,0,0,0,0,0,0,2,1
2,0,0,0,0,0,0,0,0,0,2,1
1,2,2,2,0,0,0,0,2,2,1,1
1,1,1,1,2,0,0,2,1,1,1,1
endlayer

layer
1,1,1,1,2,0,0,2,1,1,1,1
1,2,2,2,0,0,0,0,2,2,1,1
2,0,2,0,0,0,0,0,0,0,2,1
2,0,2,0,0,0,0,0,0,0,2,1
2,7,2,0,0,0,0,0,0,0,0,2
2,0,2,0,0,0,0,0,0,0,0,0
2,0,2,0,0,0,0,0,0,0,0,0
2,0,2,0,0,0,0,0,0,0,0,2
2,0,2,0,0,0,0,0,0,0,2,1
2,0,0,0,0,0,0,0,0,0,2,1
1,2,2,2,0,0,0,0,2,2,1,1
1,1,1,1,2,0,0,2,1,1,1,1
endlayer

layer
1,1,1,1,2,3,3,2,1,1,1,1
1,2,2,2,0,0,0,0,2,2,1,1
2,0,2,0,0,0,0,0,0,0,2,1
2,7,2,0,0,0,0,0,0,0,2,1
2,0,2,0,0,0,0,0,0,0,0,2
2,0,2,0,0,0,0,0,0,0,0,3
2,0,2,0,0,0,0,0,0,0,0,3
2,0,2,0,0,0,0,0,0,0,0,2
2,0,2,0,0,0,0,0,0,0,2,1
2,0,0,0,0,0,0,0,0,0,2,1
1,2,2,2,0,0,0,0,2,2,1,1
1,1,1,1,2,3,3,2,1,1,1,1
endlayer

layer
1,1,1,1,2,3,3,2,1,1,1,1
1,2,2,2,4,4,4,4,2,2,1,1
2,7,4,4,4,4,4,4,4,4,2,1
2,0,2,4,4,4,4,4,4,4,2,1
2,0,2,4,4,4,4,4,4,4,4,2
2,0,2,4,4,4,4,4,4,4,4,3
2,0,2,4,4,4,4,4,4,4,4,3
2,0,2,4,4,4,4,4,4,4,4,2
2,0,2,4,4,4,4,4,4,4,2,1
2,4,4,4,4,4,4,4,4,4,2,1
1,2,2,2,4,4,4,4,2,2,1,1
1,1,1,1,2,3,3,2,1,1,1,1
endlayer

layer
1,1,1,1,2,3,3,2,1,1,1,1
1,2,2,2,0,0,0,0,2,2,1,1
2,0,0,0,0,0,0,0,0,0,2,1
2,0,2,0,0,0,0,0,5,0,2,1
2,0,2,0,0,0,0,0,0,0,0,2
2,0,2,0,6,0,0,0,0,0,0,3
2,0,2,0,6,0,0,0,0,0,0,3
2,0,2,0,0,0,0,0,0,0,0,2
2,7,2,0,0,0,0,0,5,0,2,1
2,0,0,0,0,0,0,0,0,0,2,1
1,2,2,2,0,0,0,0,2,2,1,1
1,1,1,1,2,3,3,2,1,1,1,1
endlayer

layer
1,1,1,1,2,0,0,2,1,1,1,1
1,2,2,2,0,0,0,0,2,2,1,1
2,0,0,0,0,0,0,0,0,0,2,1
2,0,2,0,0,0,0,0,0,0,2,1
2,0,2,0,0,0,0,0,0,0,0,2
2,0,2,0,8,0,0,0,0,0,0,0
2,0,2,0,8,0,0,0,0,0,0,0
2,7,2,0,0,0,0,0,0,0,0,2
2,0,2,0,0,0,0,0,0,0,2,1
2,0,0,0,0,0,0,0,0,0,2,1
1,2,2,2,0,0,0,0,2,2,1,1
1,1,1,1,2,0,0,2,1,1,1,1
endlayer

layer
1,1,1,1,2,0,0,2,1,1,1,1
1,2,2,2,0,0,0,0,2,2,1,1
2,0,0,0,0,0,0,0,0,0,2,1
2,0,2,0,0,0,0,0,0,0,2,1
2,0,2,0,0,0,0,0,0,0,0,2
2,0,2,0,0,0,0,0,0,0,0,0
2,7,2,0,0,0,0,0,0,0,0,0
2,0,2,0,0,0,0,0,0,0,0,2
2,0,2,0,0,0,0,0,0,0,2,1
2,0,0,0,0,0,0,0,0,0,2,1
1,2,2,2,0,0,0,0,2,2,1,1
1,1,1,1,2,0,0,2,1,1,1,1
endlayer

layer
1,1,1,1,2,0,0,2,1,1,1,1
1,2,2,2,0,0,0,0,2,2,1,1
2,0,0,0,0,0,0,0,0,0,2,1
2,0,2,0,0,0,0,0,0,0,2,1
2,0,2,0,0,0,0,0,0,0,0,2
2,7,2,0,0,0,0,0,0,0,0,0
2,0,2,0,0,0,0,0,0,0,0,0
2,0,2,0,0,0,0,0,0,0,0,2
2,0,2,0,0,0,0,0,0,0,2,1
2,0,0,0,0,0,0,0,0,0,2,1
1,2,2,2,0,0,0,0,2,2,1,1
1,1,1,1,2,0,0,2,1,1,1,1
endlayer

layer
1,1,1,1,9,0,0,9,1,1,1,1
1,9,9,9,0,0,0,0,9,9,1,1
9,0,0,0,0,0,0,0,0,0,9,1
9,0,9,0,0,0,0,0,0,0,9,1
9,7,9,0,0,0,0,0,0,0,0,9
9,0,9,0,0,0,0,0,0,0,0,0
9,0,9,0,0,0,0,0,0,0,0,0
9,0,9,0,0,0,0,0,0,0,0,9
9,0,9,0,0,0,0,0,0,0,9,1
9,0,0,0,0,0,0,0,0,0,9,1
1,9,9,9,0,0,0,0,9,9,1,1
1,1,1,1,9,0,0,9,1,1,1,1
endlayer

layer
1,1,1,1,9,10,10,9,1,1,1,1
1,9,9,9,0,0,0,0,9,9,1,1
9,0,0,0,0,0,0,0,0,0,9,1
9,7,9,0,0,0,0,0,0,0,9,1
9,0,9,0,0,0,0,0,0,0,0,9
9,0,9,0,0,0,0,0,0,0,0,10
9,0,9,0,0,0,0,0,0,0,0,10
9,0,9,0,0,0,0,0,0,0,0,9
9,0,9,0,0,0,0,0,0,0,9,1
9,0,0,0,0,0,0,0,0,0,9,1
1,9,9,9,0,0,0,0,9,9,1,1
1,1,1,1,9,10,10,9,1,1,1,1
endlayer

layer
1,1,1,1,9,10,10,9,1,1,1,1
1,9,9,9,11,11,11,11,9,9,1,1
9,12,11,11,11,11,11,11,11,11,9,1
9,0,9,11,11,11,11,11,11,11,9,1
9,0,9,11,11,11,11,11,11,11,11,9
9,0,9,11,11,11,11,11,11,11,11,10
9,0,9,11,11,11,11,11,11,11,11,10
9,0,9,11,11,11,11,11,11,11,11,9
9,0,9,11,11,11,11,11,11,11,9,1
9,11,11,11,11,11,11,11,11,11,9,1
1,9,9,9,11,11,11,11,9,9,1,1
1,1,1,1,9,10,10,9,1,1,1,1
endlayer

layer
1,1,1,1,9,10,10,9,1,1,1,1
1,9,9,9,0,0,0,0,9,9,1,1
9,0,0,0,0,0,0,0,0,0,9,1
9,0,9,0,0,0,0,0,0,0,9,1
9,0,9,0,0,0,0,0,0,0,0,9
9,0,9,0,0,0,0,0,0,0,0,10
9,0,9,0,0,0,0,0,0,0,0,10
9,0,9,0,0,0,0,0,0,0,0,9
9,12,9,0,0,0,0,0,0,0,9,1
9,0,0,0,0,0,0,0,0,0,9,1
1,9,9,9,0,0,0,0,9,9,1,1
1,1,1,1,9,10,10,9,1,1,1,1
endlayer

layer
1,1,1,1,9,0,0,9,1,1,1,1
1,9,9,9,0,0,0,0,9,9,1,1
9,0,0,0,0,0,0,0,0,0,9,1
9,0,9,0,0,0,0,0,0,0,9,1
9,0,9,0,0,0,0,0,0,0,0,9
9,0,9,0,0,0,0,0,0,0,0,0
9,0,9,0,0,0,0,0,0,0,0,0
9,12,9,0,0,0,0,0,0,0,0,9
9,0,9,0,0,0,0,0,0,0,9,1
9,0,0,0,0,0,0,0,0,0,9,1
1,9,9,9,0,0,0,0,9,9,1,1
1,1,1,1,9,0,0,9,1,1,1,1
endlayer

layer
1,1,1,1,9,0,0,9,1,1,1,1
1,9,9,9,0,0,0,0,9,9,1,1
9,0,0,0,0,0,0,0,0,0,9,1
9,0,9,0,0,0,0,0,0,0,9,1
9,0,9,0,0,0,0,0,0,0,0,9
9,0,9,0,0,0,0,0,0,0,0,0
9,12,9,0,0,0,0,0,0,0,0,0
9,0,9,0,0,0,0,0,0,0,0,9
9,0,9,0,0,0,0,0,0,0,9,1
9,0,0,0,0,0,0,0,0,0,9,1
1,9,9,9,0,0,0,0,9,9,1,1
1,1,1,1,9,0,0,9,1,1,1,1
endlayer

layer
1,1,1,1,9,0,0,9,1,1,1,1
1,9,9,9,0,0,0,0,9,9,1,1
9,0,0,0,0,0,0,0,0,0,9,1
9,0,9,0,0,0,0,0,0,0,9,1
9,0,9,0,0,0,0,0,0,0,0,9
9,12,9,0,0,0,0,0,0,0,0,0
9,0,9,0,0,0,0,0,0,0,0,0
9,0,9,0,0,0,0,0,0,0,0,9
9,0,9,0,0,0,0,0,0,0,9,1
9,0,0,0,0,0,0,0,0,0,9,1
1,9,9,9,0,0,0,0,9,9,1,1
1,1,1,1,9,0,0,9,1,1,1,1
endlayer

layer
1,1,1,1,9,0,0,9,1,1,1,1
1,9,9,9,0,0,0,0,9,9,1,1
9,0,0,0,0,0,0,0,0,0,9,1
9,0,9,0,0,0,0,0,0,0,9,1
9,12,9,0,0,0,0,0,0,0,0,9
9,0,9,0,0,0,0,0,0,0,0,0
9,0,9,0,0,0,0,0,0,0,0,0
9,0,9,0,0,0,0,0,0,0,0,9
9,0,9,0,0,0,0,0,0,0,9,1
9,0,0,0,0,0,0,0,0,0,9,1
1,9,9,9,0,0,0,0,9,9,1,1
1,1,1,1,9,0,0,9,1,1,1,1
endlayer

layer
1,1,1,1,9,10,10,9,1,1,1,1
1,9,9,9,0,0,0,0,9,9,1,1
9,0,0,0,0,0,0,0,0,0,9,1
9,12,9,0,0,0,0,0,0,0,9,1
9,0,9,0,0,0,0,0,0,0,0,9
9,0,9,0,0,0,0,0,0,0,0,10
9,0,9,0,0,0,0,0,0,0,0,10
9,0,9,0,0,0,0,0,0,0,0,9
9,0,9,0,0,0,0,0,0,0,9,1
9,0,0,0,0,0,0,0,0,0,9,1
1,9,9,9,0,0,0,0,9,9,1,1
1,1,1,1,9,10,10,9,1,1,1,1
endlayer

layer
1,1,1,1,9,10,10,9,1,1,1,1
1,9,9,9,11,11,11,11,9,9,1,1
9,12,11,11,11,11,11,11,11,11,9,1
9,0,9,11,11,11,11,11,11,11,9,1
9,0,9,11,11,11,11,11,11,11,11,9
9,0,9,11,11,11,11,11,11,11,11,10
9,0,9,11,11,11,11,11,11,11,11,10
9,0,9,11,11,11,11,11,11,11,11,9
9,0,9,11,11,11,11,11,11,11,9,1
9,11,11,11,11,11,11,11,11,11,9,1
1,9,9,9,11,11,11,11,9,9,1,1
1,1,1,1,9,10,10,9,1,1,1,1
endlayer

layer
1,1,1,1,9,10,10,9,1,1,1,1
1,9,9,9,0,0,0,0,9,9,1,1
9,0,0,0,0,0,0,0,0,0,9,1
9,0,9,0,0,0,0,0,0,0,9,1
9,0,9,0,0,0,0,0,0,0,0,9
9,0,9,0,0,0,0,0,0,0,0,10
9,0,9,0,0,0,0,0,0,0,0,10
9,0,9,0,0,0,0,0,0,0,0,9
9,12,9,0,0,0,0,0,0,0,9,1
9,0,0,0,0,0,0,0,0,0,9,1
1,9,9,9,0,0,0,0,9,9,1,1
1,1,1,1,9,10,10,9,1,1,1,1
endlayer

layer
1,1,1,1,9,0,0,9,1,1,1,1
1,9,9,9,0,0,0,0,9,9,1,1
9,0,0,0,0,0,0,0,0,0,9,1
9,0,9,0,0,0,0,0,0,0,9,1
9,0,9,0,0,0,0,0,0,0,0,9
9,0,9,0,0,0,0,0,0,0,0,0
9,0,9,0,0,0,0,0,0,0,0,0
9,12,9,0,0,0,0,0,0,0,0,9
9,0,9,0,0,0,0,0,0,0,9,1
9,0,0,0,0,0,0,0,0,0,9,1
1,9,9,9,0,0,0,0,9,9,1,1
1,1,1,1,9,0,0,9,1,1,1,1
endlayer

layer
1,1,1,1,9,0,0,9,1,1,1,1
1,9,9,9,0,0,0,0,9,9,1,1
9,0,0,0,0,0,0,0,0,0,9,1
9,0,9,0,0,0,0,0,0,0,9,1
9,0,9,0,0,0,0,0,0,0,0,9
9,0,9,0,0,0,0,0,0,0,0,0
9,12,9,0,0,0,0,0,0,0,0,0
9,0,9,0,0,0,0,0,0,0,0,9
9,0,9,0,0,0,0,0,0,0,9,1
9,0,0,0,0,0,0,0,0,0,9,1
1,9,9,9,0,0,0,0,9,9,1,1
1,1,1,1,9,0,0,9,1,1,1,1
endlayer

layer
1,1,1,1,9,0,0,9,1,1,1,1
1,9,9,9,0,0,0,0,9,9,1,1
9,0,0,0,0,0,0,0,0,0,9,1
9,0,9,0,0,0,0,0,0,0,9,1
9,0,9,0,0,0,0,0,0,0,0,9
9,12,9,0,0,0,0,0,0,0,0,0
9,0,9,0,0,0,0,0,0,0,0,0
9,0,9,0,0,0,0,0,0,0,0,9
9,0,9,0,0,0,0,0,0,0,9,1
9,0,0,0,0,0,0,0,0,0,9,1
1,9,9,9,0,0,0,0,9,9,1,1
1,1,1,1,9,0,0,9,1,1,1,1
endlayer

layer
1,1,1,1,9,0,0,9,1,1,1,1
1,9,9,9,0,0,0,0,9,9,1,1
9,0,0,0,0,0,0,0,0,0,9,1
9,0,9,0,0,0,0,0,0,0,9,1
9,12,9,0,0,0,0,0,0,0,0,9
9,0,9,0,0,0,0,0,0,0,0,0
9,0,9,0,0,0,0,0,0,0,0,0
9,0,9,0,0,0,0,0,0,0,0,9
9,0,9,0,0,0,0,0,0,0,9,1
9,0,0,0,0,0,0,0,0,0,9,1
1,9,9,9,0,0,0,0,9,9,1,1
1,1,1,1,9,0,0,9,1,1,1,1
endlayer

layer
1,1,1,1,9,10,10,9,1,1,1,1
1,9,9,9,0,0,0,0,9,9,1,1
9,0,0,0,0,0,0,0,0,0,9,1
9,12,9,0,0,0,0,0,0,0,9,1
9,0,9,0,0,0,0,0,0,0,0,9
9,0,9,0,0,0,0,0,0,0,0,10
9,0,9,0,0,0,0,0,0,0,0,10
9,0,9,0,0,0,0,0,0,0,0,9
9,0,9,0,0,0,0,0,0,0,9,1
9,0,0,0,0,0,0,0,0,0,9,1
1,9,9,9,0,0,0,0,9,9,1,1
1,1,1,1,9,10,10,9,1,1,1,1
endlayer

layer
1,1,1,1,9,10,10,9,1,1,1,1
1,9,9,9,11,11,11,11,9,9,1,1
9,12,11,11,11,11,11,11,11,11,9,1
9,0,9,11,11,11,11,11,11,11,9,1
9,0,9,11,11,11,11,11,11,11,11,9
9,0,9,11,11,11,11,11,11,11,11,10
9,0,9,11,11,11,11,11,11,11,11,10
9,0,9,11,11,11,11,11,11,11,11,9
9,0,9,11,11,11,11,11,11,11,9,1
9,11,11,11,11,11,11,11,11,11,9,1
1,9,9,9,11,11,11,11,9,9,1,1
1,1,1,1,9,10,10,9,1,1,1,1
endlayer

