biomesToSpawnIn=autumn hills,autumn woods,bamboo forest,birch forest,bog,boneyard,boreal forest,brushland,chaparral,cherry blossom grove,coniferous forest,deciduous forest,extreme hills,extreme hills edge,fen,field,forest,forested field,forested hills,forested island,foresthills,fungi forest,garden,grassland,green hills,green swamplands,grove,heathland,hell,highland,hot springs,jade cliffs,jungle,junglehills,lavender fields,lush redwoods,lush swamp,magical forest,majestic meadow,mangrove,maplewoods,marsh,meadow,meadow forest,mesa,mini jungle,mountain, mountain ridge,mountain taiga,mystic grove,orchard,outback,overgrown beach,overgrown greens,pasture,pasture meadow,pine forest,plains,prarie,quagmire,rainforest,redwood forest,sacred springs,savanna,savanna plateau,scrubland,seasonal forest,seasonal spruce forest,shield,spruce woods,steppe,sublime shrubland,swampland,taiga,taigahills,temperate rainforest,thick shrubland,thicket,thinned mystic grove,thinned pasture,thinned timber,timber,tropical rainforest,tropics mountain,tundra,wonderous woods,woodland,woodlands,wyvern biome,wetland,crag,badlands,dead forest,dead swamp,deadlands,ominous woods,canyon,canyon ravine,thick ominous woods,volcano,wasteland,desert,desert oil field,deserthills,dunes,lush desert,mountainous desert
weight=1
unique=1
embed_into_distance=1
acceptable_target_blocks=stone,grass,dirt,sand,gravel,sandstone
dimensions=33,13,13
allowable_overhang=0
max_cut_in=0
cut_in_buffer=0
max_leveling=1
leveling_buffer=0
preserve_water=0
preserve_lava=0
preserve_plants=1


rule1=0,0,wool-5
rule2=0,100,stone
rule3=0,75,stone
rule4=1,75,stone
rule5=1,75,stone,stone,coal_ore
rule6=0,100,stone,stone,stone,coal_ore
rule7=1,75,stone,stone,stone,iron_ore
rule8=0,100,stone,stone,stone,stone,iron_ore
rule9=1,75,stone,stone,stone,stone,redstone_ore
rule10=0,100,stone,stone,stone,stone,stone,redstone_ore
rule11=1,75,stone,stone,stone,stone,stone,lapis_ore
rule12=0,100,stone,stone,stone,stone,stone,stone,lapis_ore
rule13=1,75,stone,stone,stone,stone,stone,stone,gold_ore
rule14=0,100,stone,stone,stone,stone,stone,stone,stone,gold_ore
rule15=1,100,stone,stone,stone,stone,stone,stone,stone,stone,diamond_ore


layer
1,2,2,2,2,2,2,2,2,2,2,2,1
2,2,2,2,2,2,2,2,2,2,2,2,2
2,2,2,2,2,2,2,2,2,2,2,2,2
2,2,2,2,2,2,2,2,2,2,2,2,2
2,2,2,2,2,2,2,2,2,2,2,2,2
2,2,2,2,2,2,2,2,2,2,2,2,2
2,2,2,2,2,2,2,2,2,2,2,2,2
2,2,2,2,2,2,2,2,2,2,2,2,2
2,2,2,2,2,2,2,2,2,2,2,2,2
2,2,2,2,2,2,2,2,2,2,2,2,2
2,2,2,2,2,2,2,2,2,2,2,2,2
2,2,2,2,2,2,2,2,2,2,2,2,2
1,2,2,2,2,2,2,2,2,2,2,2,1
endlayer

layer
0,3,3,3,3,3,3,3,3,3,3,3,0
3,3,2,2,2,2,2,2,2,2,2,3,3
3,2,2,2,2,2,2,2,2,2,2,2,3
3,2,2,2,2,2,2,2,2,2,2,2,3
3,2,2,2,2,2,2,2,2,2,2,2,3
3,2,2,2,2,2,2,2,2,2,2,2,3
3,2,2,2,2,2,2,2,2,2,2,2,3
3,2,2,2,2,2,2,2,2,2,2,2,3
3,2,2,2,2,2,2,2,2,2,2,2,3
3,2,2,2,2,2,2,2,2,2,2,2,3
3,2,2,2,2,2,2,2,2,2,2,2,3
3,3,2,2,2,2,2,2,2,2,2,3,3
0,3,3,3,3,3,3,3,3,3,3,3,0
endlayer

layer
0,4,4,4,4,4,4,4,4,4,4,4,0
4,4,2,2,2,2,2,2,2,2,2,4,4
4,2,2,2,2,2,2,2,2,2,2,2,4
4,2,2,2,2,2,2,2,2,2,2,2,4
4,2,2,2,2,2,2,2,2,2,2,2,4
4,2,2,2,2,2,2,2,2,2,2,2,4
4,2,2,2,2,2,2,2,2,2,2,2,4
4,2,2,2,2,2,2,2,2,2,2,2,4
4,2,2,2,2,2,2,2,2,2,2,2,4
4,2,2,2,2,2,2,2,2,2,2,2,4
4,2,2,2,2,2,2,2,2,2,2,2,4
4,4,2,2,2,2,2,2,2,2,2,4,4
0,4,4,4,4,4,4,4,4,4,4,4,0
endlayer

layer
0,4,4,4,4,4,4,4,4,4,4,4,0
4,4,2,2,2,2,2,2,2,2,2,4,4
4,2,2,2,2,2,2,2,2,2,2,2,4
4,2,2,2,2,2,2,2,2,2,2,2,4
4,2,2,2,2,2,2,2,2,2,2,2,4
4,2,2,2,2,2,2,2,2,2,2,2,4
4,2,2,2,2,2,2,2,2,2,2,2,4
4,2,2,2,2,2,2,2,2,2,2,2,4
4,2,2,2,2,2,2,2,2,2,2,2,4
4,2,2,2,2,2,2,2,2,2,2,2,4
4,2,2,2,2,2,2,2,2,2,2,2,4
4,4,2,2,2,2,2,2,2,2,2,4,4
0,4,4,4,4,4,4,4,4,4,4,4,0
endlayer

layer
0,4,4,4,4,4,4,4,4,4,4,4,0
4,4,2,2,2,2,2,2,2,2,2,4,4
4,2,2,2,2,2,2,2,2,2,2,2,4
4,2,2,2,2,2,2,2,2,2,2,2,4
4,2,2,2,2,2,2,2,2,2,2,2,4
4,2,2,2,2,2,2,2,2,2,2,2,4
4,2,2,2,2,2,2,2,2,2,2,2,4
4,2,2,2,2,2,2,2,2,2,2,2,4
4,2,2,2,2,2,2,2,2,2,2,2,4
4,2,2,2,2,2,2,2,2,2,2,2,4
4,2,2,2,2,2,2,2,2,2,2,2,4
4,4,2,2,2,2,2,2,2,2,2,4,4
0,4,4,4,4,4,4,4,4,4,4,4,0
endlayer

layer
0,4,4,4,4,4,4,4,4,4,4,4,0
4,4,3,3,3,3,3,3,3,3,3,4,4
4,3,3,2,2,2,2,2,2,2,3,3,4
4,3,2,2,2,2,2,2,2,2,2,3,4
4,3,2,2,2,2,2,2,2,2,2,3,4
4,3,2,2,2,2,2,2,2,2,2,3,4
4,3,2,2,2,2,2,2,2,2,2,3,4
4,3,2,2,2,2,2,2,2,2,2,3,4
4,3,2,2,2,2,2,2,2,2,2,3,4
4,3,2,2,2,2,2,2,2,2,2,3,4
4,3,3,2,2,2,2,2,2,2,3,3,4
4,4,3,3,3,3,3,3,3,3,3,4,4
0,4,4,4,4,4,4,4,4,4,4,4,0
endlayer

layer
0,0,0,0,0,0,0,0,0,0,0,0,0
0,0,5,5,5,5,5,5,5,5,5,0,0
0,5,5,6,6,6,6,6,6,6,5,5,0
0,5,6,2,2,2,2,2,2,2,6,5,0
0,5,6,2,2,2,2,2,2,2,6,5,0
0,5,6,2,2,2,2,2,2,2,6,5,0
0,5,6,2,2,2,2,2,2,2,6,5,0
0,5,6,2,2,2,2,2,2,2,6,5,0
0,5,6,2,2,2,2,2,2,2,6,5,0
0,5,6,2,2,2,2,2,2,2,6,5,0
0,5,5,6,6,6,6,6,6,6,5,5,0
0,0,5,5,5,5,5,5,5,5,5,0,0
0,0,0,0,0,0,0,0,0,0,0,0,0
endlayer

layer
0,0,0,0,0,0,0,0,0,0,0,0,0
0,0,5,5,5,5,5,5,5,5,5,0,0
0,5,5,6,6,6,6,6,6,6,5,5,0
0,5,6,2,2,2,2,2,2,2,6,5,0
0,5,6,2,2,2,2,2,2,2,6,5,0
0,5,6,2,2,2,2,2,2,2,6,5,0
0,5,6,2,2,2,2,2,2,2,6,5,0
0,5,6,2,2,2,2,2,2,2,6,5,0
0,5,6,2,2,2,2,2,2,2,6,5,0
0,5,6,2,2,2,2,2,2,2,6,5,0
0,5,5,6,6,6,6,6,6,6,5,5,0
0,0,5,5,5,5,5,5,5,5,5,0,0
0,0,0,0,0,0,0,0,0,0,0,0,0
endlayer

layer
0,0,0,0,0,0,0,0,0,0,0,0,0
0,0,5,5,5,5,5,5,5,5,5,0,0
0,5,5,6,6,6,6,6,6,6,5,5,0
0,5,6,2,2,2,2,2,2,2,6,5,0
0,5,6,2,2,2,2,2,2,2,6,5,0
0,5,6,2,2,2,2,2,2,2,6,5,0
0,5,6,2,2,2,2,2,2,2,6,5,0
0,5,6,2,2,2,2,2,2,2,6,5,0
0,5,6,2,2,2,2,2,2,2,6,5,0
0,5,6,2,2,2,2,2,2,2,6,5,0
0,5,5,6,6,6,6,6,6,6,5,5,0
0,0,5,5,5,5,5,5,5,5,5,0,0
0,0,0,0,0,0,0,0,0,0,0,0,0
endlayer

layer
0,0,0,0,0,0,0,0,0,0,0,0,0
0,0,5,5,5,5,5,5,5,5,5,0,0
0,5,5,6,6,6,6,6,6,6,5,5,0
0,5,6,2,2,2,2,2,2,2,6,5,0
0,5,6,2,2,2,2,2,2,2,6,5,0
0,5,6,2,2,2,2,2,2,2,6,5,0
0,5,6,2,2,2,2,2,2,2,6,5,0
0,5,6,2,2,2,2,2,2,2,6,5,0
0,5,6,2,2,2,2,2,2,2,6,5,0
0,5,6,2,2,2,2,2,2,2,6,5,0
0,5,5,6,6,6,6,6,6,6,5,5,0
0,0,5,5,5,5,5,5,5,5,5,0,0
0,0,0,0,0,0,0,0,0,0,0,0,0
endlayer

layer
0,0,0,0,0,0,0,0,0,0,0,0,0
0,0,5,5,5,5,5,5,5,5,5,0,0
0,5,5,3,3,3,3,3,3,3,5,5,0
0,5,3,3,2,2,2,2,2,3,3,5,0
0,5,3,2,2,2,2,2,2,2,3,5,0
0,5,3,2,2,2,2,2,2,2,3,5,0
0,5,3,2,2,2,2,2,2,2,3,5,0
0,5,3,2,2,2,2,2,2,2,3,5,0
0,5,3,2,2,2,2,2,2,2,3,5,0
0,5,3,3,2,2,2,2,2,3,3,5,0
0,5,5,3,3,3,3,3,3,3,5,5,0
0,0,5,5,5,5,5,5,5,5,5,0,0
0,0,0,0,0,0,0,0,0,0,0,0,0
endlayer

layer
0,0,0,0,0,0,0,0,0,0,0,0,0
0,0,0,0,0,0,0,0,0,0,0,0,0
0,0,0,7,7,7,7,7,7,7,0,0,0
0,0,7,7,8,8,8,8,8,7,7,0,0
0,0,7,8,2,2,2,2,2,8,7,0,0
0,0,7,8,2,2,2,2,2,8,7,0,0
0,0,7,8,2,2,2,2,2,8,7,0,0
0,0,7,8,2,2,2,2,2,8,7,0,0
0,0,7,8,2,2,2,2,2,8,7,0,0
0,0,7,7,8,8,8,8,8,7,7,0,0
0,0,0,7,7,7,7,7,7,7,0,0,0
0,0,0,0,0,0,0,0,0,0,0,0,0
0,0,0,0,0,0,0,0,0,0,0,0,0
endlayer

layer
0,0,0,0,0,0,0,0,0,0,0,0,0
0,0,0,0,0,0,0,0,0,0,0,0,0
0,0,0,7,7,7,7,7,7,7,0,0,0
0,0,7,7,8,8,8,8,8,7,7,0,0
0,0,7,8,2,2,2,2,2,8,7,0,0
0,0,7,8,2,2,2,2,2,8,7,0,0
0,0,7,8,2,2,2,2,2,8,7,0,0
0,0,7,8,2,2,2,2,2,8,7,0,0
0,0,7,8,2,2,2,2,2,8,7,0,0
0,0,7,7,8,8,8,8,8,7,7,0,0
0,0,0,7,7,7,7,7,7,7,0,0,0
0,0,0,0,0,0,0,0,0,0,0,0,0
0,0,0,0,0,0,0,0,0,0,0,0,0
endlayer

layer
0,0,0,0,0,0,0,0,0,0,0,0,0
0,0,0,0,0,0,0,0,0,0,0,0,0
0,0,0,7,7,7,7,7,7,7,0,0,0
0,0,7,7,8,8,8,8,8,7,7,0,0
0,0,7,8,2,2,2,2,2,8,7,0,0
0,0,7,8,2,2,2,2,2,8,7,0,0
0,0,7,8,2,2,2,2,2,8,7,0,0
0,0,7,8,2,2,2,2,2,8,7,0,0
0,0,7,8,2,2,2,2,2,8,7,0,0
0,0,7,7,8,8,8,8,8,7,7,0,0
0,0,0,7,7,7,7,7,7,7,0,0,0
0,0,0,0,0,0,0,0,0,0,0,0,0
0,0,0,0,0,0,0,0,0,0,0,0,0
endlayer

layer
0,0,0,0,0,0,0,0,0,0,0,0,0
0,0,0,0,0,0,0,0,0,0,0,0,0
0,0,0,7,7,7,7,7,7,7,0,0,0
0,0,7,7,8,8,8,8,8,7,7,0,0
0,0,7,8,2,2,2,2,2,8,7,0,0
0,0,7,8,2,2,2,2,2,8,7,0,0
0,0,7,8,2,2,2,2,2,8,7,0,0
0,0,7,8,2,2,2,2,2,8,7,0,0
0,0,7,8,2,2,2,2,2,8,7,0,0
0,0,7,7,8,8,8,8,8,7,7,0,0
0,0,0,7,7,7,7,7,7,7,0,0,0
0,0,0,0,0,0,0,0,0,0,0,0,0
0,0,0,0,0,0,0,0,0,0,0,0,0
endlayer

layer
0,0,0,0,0,0,0,0,0,0,0,0,0
0,0,0,0,0,0,0,0,0,0,0,0,0
0,0,0,7,7,7,7,7,7,7,0,0,0
0,0,7,7,3,3,3,3,3,7,7,0,0
0,0,7,3,3,2,2,2,3,3,7,0,0
0,0,7,3,2,2,2,2,2,3,7,0,0
0,0,7,3,2,2,2,2,2,3,7,0,0
0,0,7,3,2,2,2,2,2,3,7,0,0
0,0,7,3,3,2,2,2,3,3,7,0,0
0,0,7,7,3,3,3,3,3,7,7,0,0
0,0,0,7,7,7,7,7,7,7,0,0,0
0,0,0,0,0,0,0,0,0,0,0,0,0
0,0,0,0,0,0,0,0,0,0,0,0,0
endlayer

layer
0,0,0,0,0,0,0,0,0,0,0,0,0
0,0,0,0,0,0,0,0,0,0,0,0,0
0,0,0,0,0,0,0,0,0,0,0,0,0
0,0,0,0,9,9,9,9,9,0,0,0,0
0,0,0,9,9,10,10,10,9,9,0,0,0
0,0,0,9,10,2,2,2,10,9,0,0,0
0,0,0,9,10,2,2,2,10,9,0,0,0
0,0,0,9,10,2,2,2,10,9,0,0,0
0,0,0,9,9,10,10,10,9,9,0,0,0
0,0,0,0,9,9,9,9,9,0,0,0,0
0,0,0,0,0,0,0,0,0,0,0,0,0
0,0,0,0,0,0,0,0,0,0,0,0,0
0,0,0,0,0,0,0,0,0,0,0,0,0
endlayer

layer
0,0,0,0,0,0,0,0,0,0,0,0,0
0,0,0,0,0,0,0,0,0,0,0,0,0
0,0,0,0,0,0,0,0,0,0,0,0,0
0,0,0,0,9,9,9,9,9,0,0,0,0
0,0,0,9,9,10,10,10,9,9,0,0,0
0,0,0,9,10,2,2,2,10,9,0,0,0
0,0,0,9,10,2,2,2,10,9,0,0,0
0,0,0,9,10,2,2,2,10,9,0,0,0
0,0,0,9,9,10,10,10,9,9,0,0,0
0,0,0,0,9,9,9,9,9,0,0,0,0
0,0,0,0,0,0,0,0,0,0,0,0,0
0,0,0,0,0,0,0,0,0,0,0,0,0
0,0,0,0,0,0,0,0,0,0,0,0,0
endlayer

layer
0,0,0,0,0,0,0,0,0,0,0,0,0
0,0,0,0,0,0,0,0,0,0,0,0,0
0,0,0,0,0,0,0,0,0,0,0,0,0
0,0,0,0,9,9,9,9,9,0,0,0,0
0,0,0,9,9,10,10,10,9,9,0,0,0
0,0,0,9,10,2,2,2,10,9,0,0,0
0,0,0,9,10,2,2,2,10,9,0,0,0
0,0,0,9,10,2,2,2,10,9,0,0,0
0,0,0,9,9,10,10,10,9,9,0,0,0
0,0,0,0,9,9,9,9,9,0,0,0,0
0,0,0,0,0,0,0,0,0,0,0,0,0
0,0,0,0,0,0,0,0,0,0,0,0,0
0,0,0,0,0,0,0,0,0,0,0,0,0
endlayer

layer
0,0,0,0,0,0,0,0,0,0,0,0,0
0,0,0,0,0,0,0,0,0,0,0,0,0
0,0,0,0,0,0,0,0,0,0,0,0,0
0,0,0,0,9,9,9,9,9,0,0,0,0
0,0,0,9,9,10,10,10,9,9,0,0,0
0,0,0,9,10,2,2,2,10,9,0,0,0
0,0,0,9,10,2,2,2,10,9,0,0,0
0,0,0,9,10,2,2,2,10,9,0,0,0
0,0,0,9,9,10,10,10,9,9,0,0,0
0,0,0,0,9,9,9,9,9,0,0,0,0
0,0,0,0,0,0,0,0,0,0,0,0,0
0,0,0,0,0,0,0,0,0,0,0,0,0
0,0,0,0,0,0,0,0,0,0,0,0,0
endlayer

layer
0,0,0,0,0,0,0,0,0,0,0,0,0
0,0,0,0,0,0,0,0,0,0,0,0,0
0,0,0,0,0,0,0,0,0,0,0,0,0
0,0,0,0,9,9,9,9,9,0,0,0,0
0,0,0,9,9,3,3,3,9,9,0,0,0
0,0,0,9,3,3,2,3,3,9,0,0,0
0,0,0,9,3,2,2,2,3,9,0,0,0
0,0,0,9,3,3,2,3,3,9,0,0,0
0,0,0,9,9,3,3,3,9,9,0,0,0
0,0,0,0,9,9,9,9,9,0,0,0,0
0,0,0,0,0,0,0,0,0,0,0,0,0
0,0,0,0,0,0,0,0,0,0,0,0,0
0,0,0,0,0,0,0,0,0,0,0,0,0
endlayer

layer
0,0,0,0,0,0,0,0,0,0,0,0,0
0,0,0,0,0,0,0,0,0,0,0,0,0
0,0,0,0,0,0,0,0,0,0,0,0,0
0,0,0,0,0,0,0,0,0,0,0,0,0
0,0,0,0,0,11,11,11,0,0,0,0,0
0,0,0,0,11,11,12,11,11,0,0,0,0
0,0,0,0,11,12,2,12,11,0,0,0,0
0,0,0,0,11,11,12,11,11,0,0,0,0
0,0,0,0,0,11,11,11,0,0,0,0,0
0,0,0,0,0,0,0,0,0,0,0,0,0
0,0,0,0,0,0,0,0,0,0,0,0,0
0,0,0,0,0,0,0,0,0,0,0,0,0
0,0,0,0,0,0,0,0,0,0,0,0,0
endlayer

layer
0,0,0,0,0,0,0,0,0,0,0,0,0
0,0,0,0,0,0,0,0,0,0,0,0,0
0,0,0,0,0,0,0,0,0,0,0,0,0
0,0,0,0,0,0,0,0,0,0,0,0,0
0,0,0,0,0,11,11,11,0,0,0,0,0
0,0,0,0,11,11,12,11,11,0,0,0,0
0,0,0,0,11,12,2,12,11,0,0,0,0
0,0,0,0,11,11,12,11,11,0,0,0,0
0,0,0,0,0,11,11,11,0,0,0,0,0
0,0,0,0,0,0,0,0,0,0,0,0,0
0,0,0,0,0,0,0,0,0,0,0,0,0
0,0,0,0,0,0,0,0,0,0,0,0,0
0,0,0,0,0,0,0,0,0,0,0,0,0
endlayer

layer
0,0,0,0,0,0,0,0,0,0,0,0,0
0,0,0,0,0,0,0,0,0,0,0,0,0
0,0,0,0,0,0,0,0,0,0,0,0,0
0,0,0,0,0,0,0,0,0,0,0,0,0
0,0,0,0,0,11,11,11,0,0,0,0,0
0,0,0,0,11,11,12,11,11,0,0,0,0
0,0,0,0,11,12,2,12,11,0,0,0,0
0,0,0,0,11,11,12,11,11,0,0,0,0
0,0,0,0,0,11,11,11,0,0,0,0,0
0,0,0,0,0,0,0,0,0,0,0,0,0
0,0,0,0,0,0,0,0,0,0,0,0,0
0,0,0,0,0,0,0,0,0,0,0,0,0
0,0,0,0,0,0,0,0,0,0,0,0,0
endlayer

layer
0,0,0,0,0,0,0,0,0,0,0,0,0
0,0,0,0,0,0,0,0,0,0,0,0,0
0,0,0,0,0,0,0,0,0,0,0,0,0
0,0,0,0,0,0,0,0,0,0,0,0,0
0,0,0,0,0,11,11,11,0,0,0,0,0
0,0,0,0,11,11,12,11,11,0,0,0,0
0,0,0,0,11,12,2,12,11,0,0,0,0
0,0,0,0,11,11,12,11,11,0,0,0,0
0,0,0,0,0,11,11,11,0,0,0,0,0
0,0,0,0,0,0,0,0,0,0,0,0,0
0,0,0,0,0,0,0,0,0,0,0,0,0
0,0,0,0,0,0,0,0,0,0,0,0,0
0,0,0,0,0,0,0,0,0,0,0,0,0
endlayer

layer
0,0,0,0,0,0,0,0,0,0,0,0,0
0,0,0,0,0,0,0,0,0,0,0,0,0
0,0,0,0,0,0,0,0,0,0,0,0,0
0,0,0,0,0,0,0,0,0,0,0,0,0
0,0,0,0,0,11,11,11,0,0,0,0,0
0,0,0,0,11,3,3,3,11,0,0,0,0
0,0,0,0,11,3,2,3,11,0,0,0,0
0,0,0,0,11,3,3,3,11,0,0,0,0
0,0,0,0,0,11,11,11,0,0,0,0,0
0,0,0,0,0,0,0,0,0,0,0,0,0
0,0,0,0,0,0,0,0,0,0,0,0,0
0,0,0,0,0,0,0,0,0,0,0,0,0
0,0,0,0,0,0,0,0,0,0,0,0,0
endlayer

layer
0,0,0,0,0,0,0,0,0,0,0,0,0
0,0,0,0,0,0,0,0,0,0,0,0,0
0,0,0,0,0,0,0,0,0,0,0,0,0
0,0,0,0,0,0,0,0,0,0,0,0,0
0,0,0,0,0,0,0,0,0,0,0,0,0
0,0,0,0,0,13,13,13,0,0,0,0,0
0,0,0,0,0,13,14,13,0,0,0,0,0
0,0,0,0,0,13,13,13,0,0,0,0,0
0,0,0,0,0,0,0,0,0,0,0,0,0
0,0,0,0,0,0,0,0,0,0,0,0,0
0,0,0,0,0,0,0,0,0,0,0,0,0
0,0,0,0,0,0,0,0,0,0,0,0,0
0,0,0,0,0,0,0,0,0,0,0,0,0
endlayer

layer
0,0,0,0,0,0,0,0,0,0,0,0,0
0,0,0,0,0,0,0,0,0,0,0,0,0
0,0,0,0,0,0,0,0,0,0,0,0,0
0,0,0,0,0,0,0,0,0,0,0,0,0
0,0,0,0,0,0,0,0,0,0,0,0,0
0,0,0,0,0,13,13,13,0,0,0,0,0
0,0,0,0,0,13,14,13,0,0,0,0,0
0,0,0,0,0,13,13,13,0,0,0,0,0
0,0,0,0,0,0,0,0,0,0,0,0,0
0,0,0,0,0,0,0,0,0,0,0,0,0
0,0,0,0,0,0,0,0,0,0,0,0,0
0,0,0,0,0,0,0,0,0,0,0,0,0
0,0,0,0,0,0,0,0,0,0,0,0,0
endlayer

layer
0,0,0,0,0,0,0,0,0,0,0,0,0
0,0,0,0,0,0,0,0,0,0,0,0,0
0,0,0,0,0,0,0,0,0,0,0,0,0
0,0,0,0,0,0,0,0,0,0,0,0,0
0,0,0,0,0,0,0,0,0,0,0,0,0
0,0,0,0,0,13,13,13,0,0,0,0,0
0,0,0,0,0,13,14,13,0,0,0,0,0
0,0,0,0,0,13,13,13,0,0,0,0,0
0,0,0,0,0,0,0,0,0,0,0,0,0
0,0,0,0,0,0,0,0,0,0,0,0,0
0,0,0,0,0,0,0,0,0,0,0,0,0
0,0,0,0,0,0,0,0,0,0,0,0,0
0,0,0,0,0,0,0,0,0,0,0,0,0
endlayer

layer
0,0,0,0,0,0,0,0,0,0,0,0,0
0,0,0,0,0,0,0,0,0,0,0,0,0
0,0,0,0,0,0,0,0,0,0,0,0,0
0,0,0,0,0,0,0,0,0,0,0,0,0
0,0,0,0,0,0,0,0,0,0,0,0,0
0,0,0,0,0,13,13,13,0,0,0,0,0
0,0,0,0,0,13,14,13,0,0,0,0,0
0,0,0,0,0,13,13,13,0,0,0,0,0
0,0,0,0,0,0,0,0,0,0,0,0,0
0,0,0,0,0,0,0,0,0,0,0,0,0
0,0,0,0,0,0,0,0,0,0,0,0,0
0,0,0,0,0,0,0,0,0,0,0,0,0
0,0,0,0,0,0,0,0,0,0,0,0,0
endlayer

layer
0,0,0,0,0,0,0,0,0,0,0,0,0
0,0,0,0,0,0,0,0,0,0,0,0,0
0,0,0,0,0,0,0,0,0,0,0,0,0
0,0,0,0,0,0,0,0,0,0,0,0,0
0,0,0,0,0,0,0,0,0,0,0,0,0
0,0,0,0,0,13,13,13,0,0,0,0,0
0,0,0,0,0,13,14,13,0,0,0,0,0
0,0,0,0,0,13,13,13,0,0,0,0,0
0,0,0,0,0,0,0,0,0,0,0,0,0
0,0,0,0,0,0,0,0,0,0,0,0,0
0,0,0,0,0,0,0,0,0,0,0,0,0
0,0,0,0,0,0,0,0,0,0,0,0,0
0,0,0,0,0,0,0,0,0,0,0,0,0
endlayer

layer
0,0,0,0,0,0,0,0,0,0,0,0,0
0,0,0,0,0,0,0,0,0,0,0,0,0
0,0,0,0,0,0,0,0,0,0,0,0,0
0,0,0,0,0,0,0,0,0,0,0,0,0
0,0,0,0,0,0,0,0,0,0,0,0,0
0,0,0,0,0,15,15,15,0,0,0,0,0
0,0,0,0,0,15,15,15,0,0,0,0,0
0,0,0,0,0,15,15,15,0,0,0,0,0
0,0,0,0,0,0,0,0,0,0,0,0,0
0,0,0,0,0,0,0,0,0,0,0,0,0
0,0,0,0,0,0,0,0,0,0,0,0,0
0,0,0,0,0,0,0,0,0,0,0,0,0
0,0,0,0,0,0,0,0,0,0,0,0,0
endlayer

layer
0,0,0,0,0,0,0,0,0,0,0,0,0
0,0,0,0,0,0,0,0,0,0,0,0,0
0,0,0,0,0,0,0,0,0,0,0,0,0
0,0,0,0,0,0,0,0,0,0,0,0,0
0,0,0,0,0,0,0,0,0,0,0,0,0
0,0,0,0,0,0,0,0,0,0,0,0,0
0,0,0,0,0,0,15,0,0,0,0,0,0
0,0,0,0,0,0,0,0,0,0,0,0,0
0,0,0,0,0,0,0,0,0,0,0,0,0
0,0,0,0,0,0,0,0,0,0,0,0,0
0,0,0,0,0,0,0,0,0,0,0,0,0
0,0,0,0,0,0,0,0,0,0,0,0,0
0,0,0,0,0,0,0,0,0,0,0,0,0
endlayer

