# Converted from schematic
# THIS TEMPLATE USES DEFAULTS!  Please edit for corrections.
# If you need help, consult template_rules.txt
biomesToSpawnIn=autumn hills,autumn woods,bamboo forest,birch forest,bog,boneyard,boreal forest,brushland,chaparral,cherry blossom grove,coniferous forest,deciduous forest,extreme hills,extreme hills edge,fen,field,forest,forested field,forested hills,forested island,foresthills,fungi forest,garden,grassland,green hills,green swamplands,grove,heathland,hell,highland,hot springs,jade cliffs,jungle,junglehills,lavender fields,lush redwoods,lush swamp,magical forest,majestic meadow,mangrove,maplewoods,marsh,meadow,meadow forest,mesa,mini jungle,mountain, mountain ridge,mountain taiga,mystic grove,orchard,outback,overgrown beach,overgrown greens,pasture,pasture meadow,pine forest,plains,prarie,quagmire,rainforest,redwood forest,sacred springs,savanna,savanna plateau,scrubland,seasonal forest,seasonal spruce forest,shield,spruce woods,steppe,sublime shrubland,swampland,taiga,taigahills,temperate rainforest,thick shrubland,thicket,thinned mystic grove,thinned pasture,thinned timber,timber,tropical rainforest,tropics mountain,tundra,wonderous woods,woodland,woodlands,wyvern biome,wetland
weight=1
embed_into_distance=10
acceptable_target_blocks=stone,grass,dirt,sand,gravel
dimensions=12,17,14
allowable_overhang=0
max_cut_in=0
cut_in_buffer=0
max_leveling=0
leveling_buffer=0
preserve_water=0
preserve_lava=0
preserve_plants=0


rule1=0,100,dirt
rule2=0,100,stone
rule3=0,100,lava
rule4=0,100,grass
rule5=0,100,stonebrick-1
rule6=0,100,redstone_wire
rule7=0,100,redstone_torch-5
rule8=0,100,stonebrick-2
rule9=0,100,redstone_wire-15
rule10=0,100,glass
rule11=0,100,MobSpawner:Creeper
rule12=0,100,redstone_wire-14
rule13=0,100,sticky_piston-11
rule14=0,100,vine-4
rule15=0,100,piston_head-11
rule16=0,100,wool-15
rule17=0,100,stone_slab-5
rule18=0,100,stone_pressure_plate
rule19=0,100,piston_head-10
rule20=0,100,vine-1
rule21=0,100,vine-8
rule22=0,100,sticky_piston-10
rule23=0,100,vine-11
rule24=0,100,MediumChest
rule25=0,100,vine-2
rule26=0,100,vine-3
rule27=0,100,redstone_wire-13
rule28=0,100,preserveBlock


layer
1,1,1,1,1,1,1,1,1,1,1,1,1,1
1,1,1,1,1,1,1,1,1,1,1,1,1,1
1,1,1,1,1,1,1,1,1,1,1,1,1,1
1,1,1,3,1,1,1,1,1,1,3,1,1,1
1,1,1,1,1,1,1,1,1,1,1,1,1,1
1,1,1,1,1,1,1,1,1,1,1,1,1,1
1,1,1,1,1,1,1,1,1,1,1,1,1,1
1,1,1,1,1,1,1,1,1,1,1,1,1,1
1,1,1,1,1,1,1,1,1,1,1,1,1,1
1,1,1,1,1,1,1,1,1,1,1,1,1,1
1,1,1,1,1,1,1,1,1,1,1,1,1,1
2,2,2,2,2,2,2,2,2,2,2,2,2,2
2,2,2,2,2,2,2,2,2,2,2,2,2,2
2,2,2,2,2,2,2,2,2,2,2,2,2,2
2,2,2,2,2,2,2,2,2,2,2,2,2,2
2,2,2,2,2,2,2,2,2,2,2,2,2,2
2,2,2,2,2,2,2,2,2,2,2,2,2,2
endlayer

layer
1,1,1,1,1,1,1,1,1,1,1,1,1,1
1,1,1,1,1,1,1,1,1,1,1,1,1,1
1,1,1,5,1,1,1,1,1,1,5,1,1,1
1,1,5,0,5,1,1,1,1,5,0,5,1,1
1,1,1,5,1,1,1,1,1,1,5,1,1,1
1,1,1,1,1,1,1,1,1,1,1,1,1,1
1,1,1,1,1,1,1,1,1,1,1,1,1,1
1,1,1,1,1,1,1,1,1,1,1,1,1,1
1,4,4,4,4,4,4,4,4,4,4,4,4,1
1,4,4,4,4,4,4,4,4,4,4,4,4,1
1,1,1,1,1,1,1,1,1,1,1,1,1,1
2,2,2,2,2,2,2,2,2,2,2,2,2,2
2,2,2,2,2,2,2,2,2,2,2,2,2,2
2,2,2,2,2,2,2,2,2,2,2,2,2,2
2,2,2,2,2,2,2,2,2,2,2,2,2,2
2,2,2,2,2,2,2,2,2,2,2,2,2,2
2,2,2,2,2,2,2,2,2,2,2,2,2,2
endlayer

layer
1,1,1,1,1,1,1,1,1,1,1,1,1,1
1,1,1,1,1,1,1,1,1,1,1,1,1,1
1,1,1,5,1,1,1,1,1,1,5,1,1,1
1,1,5,0,5,1,1,1,1,5,0,5,1,1
1,1,1,5,1,1,1,1,1,1,5,1,1,1
1,1,1,1,1,1,1,1,1,1,1,1,1,1
1,1,1,1,1,1,1,1,1,1,1,1,1,1
1,4,4,1,1,1,1,1,1,1,1,4,4,1
1,6,0,0,0,0,6,6,0,0,0,0,6,1
1,6,6,6,6,6,6,6,6,6,6,6,6,1
1,1,1,1,1,1,1,1,1,1,1,1,1,1
2,1,1,1,1,2,2,2,2,2,2,2,2,2
2,2,2,1,1,2,2,2,2,2,2,2,2,2
2,2,2,2,2,2,2,2,2,2,2,2,2,2
2,2,2,2,2,2,2,2,2,2,2,2,2,2
2,2,2,2,2,2,2,2,2,2,2,2,2,2
2,2,2,2,2,2,2,2,2,2,2,2,2,2
endlayer

layer
1,1,1,1,1,1,1,1,1,1,1,1,1,1
1,1,8,5,5,5,5,5,5,5,5,5,1,1
1,8,8,8,8,5,5,8,5,5,5,5,5,1
1,8,8,10,11,8,5,5,8,11,10,8,5,1
1,8,8,8,5,8,5,5,5,8,5,5,5,1
1,1,5,5,5,8,5,5,5,5,5,5,1,1
1,1,1,1,1,1,5,8,1,1,1,1,1,1
1,7,9,4,4,4,2,2,4,4,4,9,7,1
1,1,1,1,1,1,2,2,1,1,1,1,1,1
1,1,1,1,1,5,5,5,5,1,1,1,1,1
1,1,1,1,5,5,5,5,5,5,1,1,1,1
2,1,1,1,1,1,2,2,2,2,2,2,2,2
2,2,1,1,5,1,2,2,2,2,2,2,2,2
2,2,2,2,1,1,2,2,2,2,2,2,2,2
2,2,2,2,2,2,2,2,2,2,2,2,2,2
2,2,2,2,2,2,2,2,2,2,2,2,2,2
2,2,2,2,2,2,2,2,2,2,2,2,2,2
endlayer

layer
5,5,5,5,5,5,5,5,5,5,5,5,5,5
5,5,0,0,0,0,5,5,0,0,0,0,5,5
5,0,0,0,5,0,17,17,0,5,0,0,0,5
5,0,0,0,5,0,0,0,0,5,0,0,0,5
5,0,0,0,5,0,0,0,0,5,0,0,0,5
2,5,0,0,0,0,0,0,0,0,0,0,5,5
5,5,8,5,5,5,0,0,5,5,5,5,5,5
5,2,0,12,22,19,5,5,15,13,12,0,2,5
1,5,2,2,2,16,18,18,16,2,2,2,5,1
1,1,5,5,5,20,0,0,0,5,8,8,1,1
1,1,1,5,23,21,0,0,0,14,5,1,1,1
2,1,1,1,5,5,5,5,5,5,2,2,2,2
2,2,1,1,5,1,2,2,2,2,2,2,2,2
2,1,1,2,1,1,2,2,2,2,2,2,2,2
2,1,1,1,2,2,2,2,2,2,2,2,2,2
2,2,1,1,1,1,2,2,2,2,2,2,2,2
2,2,2,1,1,1,2,2,2,2,2,2,2,2
endlayer

layer
5,5,5,5,5,5,5,5,5,5,5,5,5,5
5,5,0,0,0,0,24,24,0,0,0,0,5,5
5,0,0,0,0,0,0,0,0,0,0,0,0,5
5,0,0,0,0,0,0,0,0,0,0,0,0,5
5,0,0,0,0,0,0,0,0,0,0,0,0,5
2,5,0,0,0,0,0,0,0,0,0,0,5,5
5,5,5,5,8,8,0,0,5,5,8,5,5,5
5,9,2,2,22,19,16,16,15,13,2,2,9,8
1,5,2,2,2,16,0,0,16,2,2,2,8,1
1,1,5,5,5,0,0,0,0,5,5,8,1,1
1,1,1,5,26,0,25,0,0,14,5,1,1,1
1,1,1,1,5,20,0,0,0,5,1,1,1,1
1,1,1,1,5,5,5,5,5,1,1,1,1,1
1,1,1,1,5,1,1,1,1,1,1,1,1,1
1,1,1,1,1,1,1,1,1,1,1,1,1,1
1,1,1,1,1,1,1,1,1,1,1,1,1,1
1,1,1,1,1,1,1,1,1,1,1,1,1,1
endlayer

layer
5,5,5,5,5,5,5,5,5,5,5,5,5,5
5,5,0,0,0,0,0,0,0,0,0,0,5,5
5,0,0,0,0,0,0,0,0,0,0,0,0,5
5,0,0,0,0,0,0,0,0,0,0,0,0,5
5,0,0,0,0,0,0,0,0,0,0,0,0,5
2,5,0,0,0,0,0,0,0,0,0,0,5,5
5,5,8,5,8,8,0,0,5,8,8,5,8,5
5,0,12,27,22,19,16,16,15,13,27,12,0,8
1,5,2,2,2,16,0,0,16,2,2,2,5,1
1,1,5,5,5,0,0,0,0,5,8,5,1,1
1,1,1,5,26,25,25,0,25,14,5,1,1,1
1,1,1,5,5,20,0,0,0,5,1,1,1,1
1,1,1,1,5,21,0,0,21,5,1,1,1,1
1,1,1,1,5,5,5,5,5,5,1,1,1,1
1,1,1,1,1,1,1,1,1,1,1,1,1,1
1,1,1,1,1,1,1,1,1,1,1,1,1,1
1,1,1,1,1,1,1,1,1,1,1,1,1,1
endlayer

layer
5,5,5,5,5,5,5,5,5,5,5,5,5,5
5,5,5,5,5,5,5,5,5,5,5,5,5,5
5,5,5,5,5,5,5,5,5,5,5,5,5,5
5,5,5,5,5,5,5,5,5,5,5,5,5,5
5,5,5,5,5,5,5,5,5,5,5,5,5,5
5,5,5,5,5,5,5,5,5,5,5,5,5,5
5,5,5,5,8,8,5,5,8,5,5,8,8,5
5,2,2,2,2,2,2,2,2,2,2,2,2,8
1,5,2,2,2,16,16,16,16,2,2,2,5,1
1,1,5,8,5,0,0,0,0,5,5,5,1,1
1,1,1,5,25,25,25,0,25,14,5,1,1,1
1,1,1,5,20,0,0,0,0,14,5,1,1,1
1,1,1,5,5,21,0,0,21,5,5,1,1,1
1,1,1,5,5,5,0,0,5,5,5,1,1,1
1,1,1,1,1,5,5,5,1,1,1,1,1,1
1,1,1,1,1,1,1,1,1,1,1,1,1,1
1,1,1,1,1,1,1,1,1,1,1,1,1,1
endlayer

layer
28,28,28,28,28,28,28,28,28,28,28,28,28,28
28,28,28,28,28,28,28,28,28,28,28,28,28,28
28,28,28,28,28,28,28,28,28,28,28,28,28,28
28,28,28,28,28,28,28,28,28,28,28,28,28,28
28,28,28,28,28,28,28,28,28,28,28,28,28,28
28,28,28,28,28,28,28,28,28,28,28,28,28,28
28,28,28,28,28,28,28,28,28,28,28,28,28,28
28,28,5,5,8,5,8,5,5,5,5,5,28,28
28,28,2,2,2,2,16,16,2,2,2,2,28,28
28,28,5,8,5,5,0,0,8,5,5,5,28,28
28,28,5,0,25,25,25,0,25,25,25,5,28,28
28,28,5,0,0,0,0,0,0,0,0,5,28,28
28,28,5,0,0,0,0,0,0,0,0,5,28,28
28,28,5,5,0,0,0,0,0,5,0,5,28,28
28,28,5,5,5,5,0,0,5,5,5,5,28,28
28,28,5,5,5,5,5,5,5,5,5,5,28,28
1,1,1,1,1,1,1,1,1,1,1,1,1,1
endlayer

layer
28,28,28,28,28,28,28,28,28,28,28,28,28,28
28,28,28,28,28,28,28,28,28,28,28,28,28,28
28,28,28,28,28,28,28,28,28,28,28,28,28,28
28,28,28,28,28,28,28,28,28,28,28,28,28,28
28,28,28,28,28,28,28,28,28,28,28,28,28,28
28,28,28,28,28,28,28,28,28,28,28,28,28,28
28,28,28,28,28,28,28,28,28,28,28,28,28,28
28,28,5,5,8,8,8,5,5,5,5,5,28,28
28,28,5,5,16,16,0,0,16,16,5,5,28,28
28,28,8,5,0,0,5,5,0,0,8,5,28,28
28,28,5,25,0,0,25,25,25,25,25,5,28,28
28,28,5,0,0,0,0,0,0,0,0,5,28,28
28,28,5,0,0,0,0,0,0,0,0,5,28,28
28,28,5,0,0,0,0,0,0,0,0,5,28,28
28,28,5,5,0,0,0,0,0,0,5,5,28,28
28,28,5,5,5,5,0,0,5,5,5,5,28,28
28,28,5,5,5,5,5,5,5,5,5,5,28,28
endlayer

layer
28,28,28,28,28,28,28,28,28,28,28,28,28,28
28,28,28,28,28,28,28,28,28,28,28,28,28,28
28,28,28,28,28,28,28,28,28,28,28,28,28,28
28,28,28,28,28,28,28,28,28,28,28,28,28,28
28,28,28,28,28,28,28,28,28,28,28,28,28,28
28,28,28,28,28,28,28,28,28,28,28,28,28,28
28,28,28,28,28,28,28,28,28,28,28,28,28,28
28,28,5,5,5,5,5,5,5,5,5,5,28,28
28,28,5,0,16,16,0,0,16,16,5,5,28,28
28,28,5,8,0,0,8,5,0,0,5,8,28,28
0,0,25,25,0,0,25,25,25,25,25,25,0,0
0,0,0,0,0,0,0,0,0,0,0,0,0,0
0,0,0,0,0,0,0,0,0,0,0,0,0,0
0,0,0,0,0,0,0,0,0,0,0,0,0,0
0,0,0,0,0,0,0,0,0,0,0,0,0,0
0,0,0,0,0,0,0,0,0,0,0,0,0,0
0,0,0,0,0,0,0,0,0,0,0,0,0,0
endlayer

layer
0,0,0,0,0,0,0,0,0,0,0,0,0,0
0,0,0,0,0,0,0,0,0,0,0,0,0,0
0,0,0,0,0,0,0,0,0,0,0,0,0,0
0,0,0,0,0,0,0,0,0,0,0,0,0,0
0,0,0,0,0,0,0,0,0,0,0,0,0,0
0,0,0,0,0,0,0,0,0,0,0,0,0,0
0,0,0,0,21,0,0,0,0,0,21,0,0,0
0,0,5,5,5,5,5,5,5,5,5,5,0,0
0,14,5,5,5,5,5,5,5,5,5,5,20,0
0,14,5,5,5,5,5,5,5,5,5,8,20,0
0,0,25,25,25,25,25,25,25,25,25,0,0,0
0,0,0,0,0,0,0,0,0,0,0,0,0,0
0,0,0,0,0,0,0,0,0,0,0,0,0,0
0,0,0,0,0,0,0,0,0,0,0,0,0,0
0,0,0,0,0,0,0,0,0,0,0,0,0,0
0,0,0,0,0,0,0,0,0,0,0,0,0,0
0,0,0,0,0,0,0,0,0,0,0,0,0,0
endlayer

