biomesToSpawnIn=autumn hills,autumn woods,bamboo forest,birch forest,bog,boneyard,boreal forest,brushland,chaparral,cherry blossom grove,coniferous forest,deciduous forest,extreme hills,extreme hills edge,fen,field,forest,forested field,forested hills,forested island,foresthills,fungi forest,garden,grassland,green hills,green swamplands,grove,heathland,hell,highland,hot springs,jade cliffs,jungle,junglehills,lavender fields,lush redwoods,lush swamp,magical forest,majestic meadow,mangrove,maplewoods,marsh,meadow,meadow forest,mesa,mini jungle,mountain, mountain ridge,mountain taiga,mystic grove,orchard,outback,overgrown beach,overgrown greens,pasture,pasture meadow,pine forest,plains,prarie,quagmire,rainforest,redwood forest,sacred springs,savanna,savanna plateau,scrubland,seasonal forest,seasonal spruce forest,shield,spruce woods,steppe,sublime shrubland,swampland,taiga,taigahills,temperate rainforest,thick shrubland,thicket,thinned mystic grove,thinned pasture,thinned timber,timber,tropical rainforest,tropics mountain,tundra,wonderous woods,woodland,woodlands,wyvern biome,wetland
weight=1
embed_into_distance=1
acceptable_target_blocks=1,2,3,12,13,24
dimensions=7,12,9
cut_in_buffer=1
max_leveling=2
leveling_buffer=1
preserve_water=0
preserve_lava=0
preserve_plants=0
max_cut_in=10


rule1=0,100,preserveBlock
rule2=0,100,4
rule3=0,100,13
rule4=0,100,5
rule5=0,100,3
rule6=0,100,43
rule7=0,100,53-3
rule8=0,100,85
rule9=0,100,53-1
rule10=0,100,64-2
rule11=0,100,17
rule12=0,100,102
rule13=0,100,72
rule14=0,100,64-8
rule15=0,100,53
rule16=0,100,50-2
rule17=0,100,50-1


layer
5,5,5,5,5,5,5,1,1
5,5,5,5,5,5,5,1,1
5,5,5,5,5,5,5,1,1
5,5,5,5,5,5,5,1,1
5,5,2,5,5,5,5,1,1
2,2,2,2,2,2,2,2,2
2,4,4,4,4,4,4,4,2
2,6,6,6,4,4,4,4,2
2,6,6,6,4,4,4,4,2
2,6,6,6,4,4,4,4,2
2,2,2,2,2,2,2,2,2
3,3,3,3,3,3,3,3,3
endlayer

layer
8,8,8,8,8,8,8,0,0
8,0,0,0,0,0,8,0,0
8,0,0,0,0,0,8,0,0
8,0,0,0,0,0,8,0,0
8,0,0,0,0,0,8,0,0
2,2,10,2,2,2,2,2,2
2,0,0,0,0,0,9,4,2
2,0,0,0,0,0,8,7,2
2,0,6,0,0,0,0,0,2
2,0,6,0,0,0,0,0,2
2,2,2,2,2,2,10,2,2
0,0,0,0,0,0,0,0,0
endlayer

layer
0,0,0,0,0,0,0,0,0
0,0,0,0,0,0,0,0,0
0,0,0,0,0,0,0,0,0
0,0,0,0,0,0,0,0,0
0,0,0,0,0,0,0,0,0
2,4,14,4,4,12,12,4,2
11,0,0,0,0,0,0,0,11
12,0,0,0,0,0,13,0,12
12,0,0,0,0,0,0,0,12
11,0,0,0,0,0,0,0,11
2,4,4,12,4,4,14,4,2
0,0,0,0,0,0,0,0,0
endlayer

layer
0,0,0,0,0,0,0,0,0
0,0,0,0,0,0,0,0,0
0,0,0,0,0,0,0,0,0
0,0,0,0,0,0,0,0,0
15,15,15,15,15,15,15,15,15
2,4,4,4,4,4,4,4,2
2,0,17,0,0,0,0,0,2
2,0,0,0,0,0,0,0,2
2,0,0,0,0,0,0,0,2
2,0,0,0,0,0,16,0,2
2,4,4,4,4,4,4,4,2
9,9,9,9,9,9,9,9,9
endlayer

layer
0,0,0,0,0,0,0,0,0
0,0,0,0,0,0,0,0,0
0,0,0,0,0,0,0,0,0
0,0,0,0,0,0,0,0,0
0,0,0,0,0,0,0,0,0
15,15,15,15,15,15,15,15,15
4,4,4,4,4,4,4,4,4
4,0,0,0,0,0,0,0,4
4,0,0,0,0,0,0,0,4
4,4,4,4,4,4,4,4,4
9,9,9,9,9,9,9,9,9
0,0,0,0,0,0,0,0,0
endlayer

layer
0,0,0,0,0,0,0,0,0
0,0,0,0,0,0,0,0,0
0,0,0,0,0,0,0,0,0
0,0,0,0,0,0,0,0,0
0,0,0,0,0,0,0,0,0
0,0,0,0,0,0,0,0,0
15,15,15,15,15,15,15,15,15
4,4,4,4,4,4,4,4,4
4,4,4,4,4,4,4,4,4
9,9,9,9,9,9,9,9,9
0,0,0,0,0,0,0,0,0
0,0,0,0,0,0,0,0,0
endlayer

layer
0,0,0,0,0,0,0,0,0
0,0,0,0,0,0,0,0,0
0,0,0,0,0,0,0,0,0
0,0,0,0,0,0,0,0,0
0,0,0,0,0,0,0,0,0
0,0,0,0,0,0,0,0,0
0,0,0,0,0,0,0,0,0
15,15,15,15,15,15,15,15,15
9,9,9,9,9,9,9,9,9
0,0,0,0,0,0,0,0,0
0,0,0,0,0,0,0,0,0
0,0,0,0,0,0,0,0,0
endlayer

