weight=1
embed_into_distance=1
acceptable_target_blocks=1,2,3,12,13,24
dimensions=9,8,9
cut_in_buffer=1
max_leveling=2
leveling_buffer=1
preserve_water=0
preserve_lava=0
preserve_plants=0
max_cut_in=10


rule1=0,100,preserveBlock
rule2=0,100,4
rule3=0,100,13
rule4=0,100,5
rule5=0,100,53-3
rule6=0,100,58
rule7=0,100,53-1
rule8=0,100,85
rule9=0,100,64
rule10=0,100,102
rule11=0,100,72
rule12=0,100,64-8
rule13=0,100,47
rule14=0,100,53


layer
1,1,1,1,1,1,1,1,1
2,2,2,2,2,2,2,2,2
2,2,2,2,2,2,2,2,2
2,2,2,2,2,2,2,2,2
2,2,2,2,2,2,2,2,2
2,2,2,2,2,2,2,2,2
2,2,2,2,2,2,2,2,2
3,3,3,3,3,3,3,3,3
endlayer

layer
0,0,0,0,0,0,0,0,0
2,2,2,2,2,2,2,2,2
2,0,0,7,7,7,7,4,2
2,0,0,0,8,0,8,5,2
2,0,0,0,0,0,0,0,2
2,0,0,0,0,0,0,6,2
2,9,2,2,2,2,2,2,2
0,0,0,0,0,0,0,0,0
endlayer

layer
0,0,0,0,0,0,0,0,0
2,4,10,10,4,10,10,4,2
4,0,0,0,0,0,0,0,4
10,0,0,0,11,0,11,0,10
10,0,0,0,0,0,0,0,10
4,0,0,0,0,0,0,0,4
2,12,4,4,10,10,10,4,2
0,0,0,0,0,0,0,0,0
endlayer

layer
0,0,0,0,0,0,0,0,0
2,4,4,4,4,4,4,4,2
4,13,13,13,13,13,13,13,4
10,0,0,0,0,0,0,0,10
10,0,0,0,0,0,0,0,10
4,0,0,0,0,0,0,0,4
2,4,4,4,10,10,10,4,2
0,0,0,0,0,0,0,0,0
endlayer

layer
0,0,0,0,0,0,0,0,0
2,4,4,4,4,4,4,4,2
4,4,4,4,4,4,4,4,4
4,0,0,0,0,0,0,0,4
4,0,0,0,0,0,0,0,4
4,4,4,4,4,4,4,4,4
2,4,4,4,4,4,4,4,2
0,0,0,0,0,0,0,0,0
endlayer

layer
14,14,14,14,14,14,14,14,14
2,2,2,2,2,2,2,2,2
2,2,2,2,2,2,2,2,2
2,2,2,2,2,2,2,2,2
2,2,2,2,2,2,2,2,2
2,2,2,2,2,2,2,2,2
2,2,2,2,2,2,2,2,2
7,7,7,7,7,7,7,7,7
endlayer

layer
0,0,0,0,0,0,0,0,0
14,14,14,14,14,14,14,14,14
2,2,2,2,2,2,2,2,2
2,2,2,2,2,2,2,2,2
2,2,2,2,2,2,2,2,2
2,2,2,2,2,2,2,2,2
7,7,7,7,7,7,7,7,7
0,0,0,0,0,0,0,0,0
endlayer

layer
0,0,0,0,0,0,0,0,0
0,0,0,0,0,0,0,0,0
14,14,14,14,14,14,14,14,14
2,2,2,2,2,2,2,2,2
2,2,2,2,2,2,2,2,2
7,7,7,7,7,7,7,7,7
0,0,0,0,0,0,0,0,0
0,0,0,0,0,0,0,0,0
endlayer

layer
0,0,0,0,0,0,0,0,0
0,0,0,0,0,0,0,0,0
0,0,0,0,0,0,0,0,0
14,14,14,14,14,14,14,14,14
7,7,7,7,7,7,7,7,7
0,0,0,0,0,0,0,0,0
0,0,0,0,0,0,0,0,0
0,0,0,0,0,0,0,0,0
endlayer

