# Author: d00dv4d3r
# From: Default Template

weight=5
embed_into_distance=5
acceptable_target_blocks=1,2,3,12,13
dimensions=9,7,7
allowable_overhang=2
max_cut_in=2
cut_in_buffer=1
max_leveling=2
leveling_buffer=1
preserve_water=0
preserve_lava=0
preserve_plants=0

rule1=0,100,0,43,44
rule2=0,100,4,48
rule3=1,50,4,48
rule4=1,50,5
rule5=2,33,5
rule6=0,100,67-1,0

layer
2,2,2,2,2,2,2
2,2,2,2,2,2,2
2,2,2,2,2,2,2
2,2,2,2,2,2,2
2,2,2,2,2,2,2
2,2,2,2,2,2,2
2,2,2,2,2,2,2
endlayer

layer
2,2,2,2,2,2,2
2,0,0,0,0,0,2
2,0,0,0,0,0,2
2,0,0,0,0,0,2
2,0,0,0,0,6,2
2,0,0,0,0,0,2
2,2,2,2,2,2,2
endlayer

layer
2,2,2,2,2,2,2
2,0,0,0,0,0,2
2,0,0,0,0,0,2
2,0,0,0,0,6,2
2,0,0,0,0,0,2
2,0,0,0,0,0,2
2,2,2,2,2,2,2
endlayer

layer
2,2,2,2,2,2,2
2,0,0,0,0,0,2
2,0,0,0,0,6,2
2,0,0,0,0,0,2
2,0,0,0,0,0,2
2,0,0,0,0,0,2
2,2,2,2,2,2,2
endlayer

layer
2,2,2,2,2,2,2
2,1,1,1,1,6,2
2,1,1,1,1,0,2
2,1,1,1,1,0,2
2,1,1,1,1,0,2
2,1,1,1,1,1,2
2,2,2,2,2,2,2
endlayer

layer
3,3,3,3,3,3,3
3,0,0,0,0,0,3
3,0,0,0,0,0,3
3,0,0,0,0,0,3
3,0,0,0,0,0,3
3,0,0,0,0,0,3
3,3,3,3,3,3,3
endlayer

layer
3,3,3,3,3,3,3
3,0,0,0,0,0,3
3,0,0,0,0,0,3
3,0,0,0,0,0,3
3,0,0,0,0,0,3
3,0,0,0,0,0,3
3,3,3,3,3,3,3
endlayer

layer
3,3,3,3,3,3,3
3,0,0,0,0,0,3
3,0,0,0,0,0,3
3,0,0,0,0,0,3
3,0,0,0,0,0,3
3,0,0,0,0,0,3
3,3,3,3,3,3,3
endlayer

layer
4,5,0,0,0,5,4
5,0,0,0,0,0,5
0,0,0,0,0,0,0
0,0,0,0,0,0,0
0,0,0,0,0,0,0
5,0,0,0,0,0,5
4,5,0,0,0,5,4
endlayer
