weight=5
embed_into_distance=1
acceptable_target_blocks=1,2,3,12,13
dimensions=5,11,7
cut_in_buffer=0
max_leveling=1
leveling_buffer=0
preserve_water=0
preserve_lava=0
preserve_plants=1
max_cut_in=0


rule1=0,50,4,48
rule2=0,30,4,4,48,5
rule3=0,100,45
rule4=0,20,4,48,44-3
rule5=0,0,35-4
rule6=0,100,108-1


layer
1,1,3,3,3,1,1
1,1,3,3,3,1,1
1,2,2,2,2,2,1
1,2,2,2,2,2,1
1,2,2,2,2,2,1
1,2,2,2,2,2,1
1,2,2,2,2,2,1
1,2,2,2,2,2,1
1,2,2,2,2,2,1
1,2,2,2,2,2,1
1,1,1,1,1,1,1
endlayer

layer
4,4,3,3,3,4,4
4,5,3,5,3,5,4
4,5,5,5,5,5,4
4,5,5,5,5,5,4
4,5,5,5,5,5,4
4,5,5,5,5,5,4
4,5,5,5,5,5,4
4,5,5,5,5,5,4
4,5,5,5,5,5,4
4,5,5,5,5,5,4
4,4,4,4,4,4,4
endlayer

layer
0,0,3,3,3,0,0
0,0,6,6,6,0,0
0,0,0,0,0,0,0
0,0,0,0,0,0,0
0,0,0,0,0,0,0
0,0,0,0,0,0,0
0,0,0,0,0,0,0
0,0,0,0,0,0,0
0,0,0,0,0,0,0
0,0,0,0,0,0,0
0,0,0,0,0,0,0
endlayer

layer
0,0,0,3,0,0,0
0,0,0,0,0,0,0
0,0,0,0,0,0,0
0,0,0,0,0,0,0
0,0,0,0,0,0,0
0,0,0,0,0,0,0
0,0,0,0,0,0,0
0,0,0,0,0,0,0
0,0,0,0,0,0,0
0,0,0,0,0,0,0
0,0,0,0,0,0,0
endlayer

layer
0,0,0,3,0,0,0
0,0,0,0,0,0,0
0,0,0,0,0,0,0
0,0,0,0,0,0,0
0,0,0,0,0,0,0
0,0,0,0,0,0,0
0,0,0,0,0,0,0
0,0,0,0,0,0,0
0,0,0,0,0,0,0
0,0,0,0,0,0,0
0,0,0,0,0,0,0
endlayer

