# Converted from schematic
# THIS TEMPLATE USES DEFAULTS!  Please edit for corrections.
# If you need help, consult template_rules.txt

biomesToSpawnIn=autumn hills,autumn woods,bamboo forest,birch forest,bog,boneyard,boreal forest,brushland,chaparral,cherry blossom grove,coniferous forest,deciduous forest,extreme hills,extreme hills edge,fen,field,forest,forested field,forested hills,forested island,foresthills,fungi forest,garden,grassland,green hills,green swamplands,grove,heathland,hell,highland,hot springs,jade cliffs,jungle,junglehills,lavender fields,lush redwoods,lush swamp,magical forest,majestic meadow,mangrove,maplewoods,marsh,meadow,meadow forest,mesa,mini jungle,mountain, mountain ridge,mountain taiga,mystic grove,orchard,outback,overgrown beach,overgrown greens,pasture,pasture meadow,pine forest,plains,prarie,quagmire,rainforest,redwood forest,sacred springs,savanna,savanna plateau,scrubland,seasonal forest,seasonal spruce forest,shield,spruce woods,steppe,sublime shrubland,swampland,taiga,taigahills,temperate rainforest,thick shrubland,thicket,thinned mystic grove,thinned pasture,thinned timber,timber,tropical rainforest,tropics mountain,tundra,wonderous woods,woodland,woodlands,wyvern biome,wetland
weight=1
embed_into_distance=1
acceptable_target_blocks=1,2,3,12,13
dimensions=19,31,30
allowable_overhang=0
max_cut_in=2
cut_in_buffer=1
max_leveling=2
leveling_buffer=1
preserve_water=0
preserve_lava=0
preserve_plants=0


rule1=0,100,2
rule2=0,100,98
rule3=0,100,98-1
rule4=0,100,98-2
rule5=0,100,3
rule6=0,100,60
rule7=0,100,24
rule8=0,100,87
rule9=0,100,4
rule10=0,100,31-1
rule11=0,100,43
rule12=0,100,85
rule13=0,100,65-4
rule14=0,100,65-5
rule15=0,100,59-7
rule16=0,100,59-5
rule17=0,100,44-3
rule18=0,100,59-2
rule19=0,100,59-6
rule20=0,100,59-4
rule21=0,100,59-3
rule22=0,100,98-3
rule23=0,100,54-3
rule24=0,100,109
rule25=0,100,109-1
rule26=0,100,109-2
rule27=0,100,38
rule28=0,100,37
rule29=0,100,86-3
rule30=0,100,47
rule31=0,100,44
rule32=0,100,11
rule33=0,100,54-2
rule34=0,100,51-15
rule35=0,100,9
rule36=0,100,39
rule37=0,100,20
rule38=0,100,44-5
rule39=0,100,50-3
rule40=0,100,50-4
rule41=0,100,109-5
rule42=0,100,109-4
rule43=0,100,50-1
rule44=0,100,50-2
rule45=0,100,5
rule46=0,100,53
rule47=0,100,53-1
rule48=0,100,89


layer
1,1,1,1,1,1,1,1,1,1,1,1,1,1,1,1,1,1,1,1,1,1,1,1,1,1,1,1,1,1
1,1,1,2,2,2,1,1,1,1,1,1,1,1,1,1,1,1,1,1,1,1,1,1,2,2,2,1,1,1
1,1,2,2,4,4,2,1,1,1,1,1,1,1,1,1,1,1,1,1,1,1,1,2,4,2,2,2,1,1
1,2,2,2,2,4,3,2,2,2,2,2,2,2,2,2,2,2,2,2,2,2,2,3,2,2,2,2,2,1
1,2,4,2,2,2,3,2,3,3,2,3,3,2,3,3,2,3,2,3,2,2,3,3,3,2,2,2,2,1
1,2,4,2,2,2,2,2,2,2,2,2,2,2,2,3,2,2,2,2,2,2,2,2,2,2,2,2,2,1
1,1,2,2,2,2,2,1,1,1,1,1,1,1,1,3,1,6,6,6,6,6,6,2,2,2,2,2,1,1
1,1,1,2,2,2,1,5,1,1,1,1,1,1,1,3,1,6,6,6,6,6,6,6,2,2,2,1,1,1
1,1,1,2,3,2,1,2,3,3,3,3,3,3,5,3,5,6,6,6,6,6,6,6,2,2,2,1,1,1
1,1,1,2,3,2,1,3,5,2,2,2,2,2,7,7,2,6,6,6,1,6,6,6,2,2,2,1,1,1
1,1,1,2,3,2,1,1,9,7,7,7,7,7,7,7,2,6,6,6,6,6,6,6,2,2,2,1,1,1
1,1,1,2,3,2,1,1,7,7,7,7,7,7,7,7,2,6,6,6,6,6,6,6,2,2,2,1,1,1
1,1,1,2,3,2,1,1,7,7,7,7,7,7,7,7,2,6,6,6,6,6,6,6,2,2,2,1,1,1
1,1,1,2,3,2,1,1,7,7,7,7,7,7,7,7,2,1,1,1,1,1,1,1,2,2,2,5,1,1
1,1,1,2,3,2,1,1,7,8,7,7,7,7,7,7,2,2,2,2,2,2,2,2,2,2,4,4,3,1
1,1,1,2,3,2,1,1,7,8,7,7,7,7,7,7,2,2,2,2,2,2,2,2,2,2,3,4,3,1
1,1,1,2,3,2,1,1,7,8,7,7,7,7,7,7,2,2,2,2,2,2,2,2,2,2,2,3,4,1
1,1,1,2,3,2,1,1,7,7,7,7,7,7,7,7,2,1,1,1,1,1,1,1,2,2,2,5,1,1
1,1,1,2,3,2,1,1,7,7,7,7,7,7,7,7,2,6,6,6,6,6,6,6,2,2,2,1,1,1
1,1,1,2,3,2,1,1,7,7,7,7,7,7,7,7,2,6,6,6,6,6,6,6,2,2,2,1,1,1
1,1,1,2,3,2,1,1,2,7,7,7,7,7,7,7,2,6,6,6,6,6,6,6,2,2,2,1,1,1
1,1,1,2,3,2,1,3,2,2,2,2,2,2,7,7,2,6,6,6,1,6,6,6,2,2,2,1,1,1
1,1,1,2,3,2,1,3,3,3,3,3,3,3,3,3,5,6,6,6,6,6,6,6,2,2,2,1,1,1
1,1,1,2,3,2,1,1,1,1,1,5,1,5,1,3,1,6,6,6,6,6,6,6,2,2,2,1,1,1
1,1,2,2,3,2,2,1,1,1,1,1,1,5,1,3,1,6,6,6,6,6,6,2,3,2,2,2,1,1
1,2,2,2,2,3,3,2,2,2,2,2,2,2,2,3,2,2,2,2,2,2,2,2,3,2,2,2,2,1
1,2,2,2,2,2,3,3,2,3,3,3,2,2,3,3,3,2,2,2,2,3,3,2,2,2,2,2,2,1
1,2,2,2,2,2,3,2,2,2,2,2,2,2,2,2,2,2,2,2,2,2,2,2,2,2,2,2,2,1
1,1,2,2,2,2,2,1,1,1,1,1,1,1,1,1,1,1,1,1,1,1,1,2,2,2,2,2,1,1
1,1,1,2,2,2,1,1,1,1,1,1,1,1,1,1,1,1,1,1,1,1,1,1,2,2,2,1,1,1
1,1,1,1,1,1,1,1,1,1,1,1,1,1,1,1,1,1,1,1,1,1,1,1,1,1,1,1,1,1
endlayer

layer
0,10,0,10,0,0,0,0,0,0,0,0,0,0,0,0,0,0,10,10,0,10,10,10,0,10,10,0,0,10
10,10,10,2,4,2,0,0,10,0,0,0,0,0,0,0,0,0,0,0,10,10,0,0,2,4,2,0,10,0
0,0,2,0,0,0,2,0,0,0,0,0,0,0,10,0,0,0,0,0,10,10,0,4,0,0,0,2,10,0
10,4,0,0,0,0,0,3,4,2,3,3,3,3,2,3,3,4,4,2,2,2,2,0,0,0,0,0,2,0
10,2,0,0,0,0,0,0,0,0,0,0,0,0,0,0,0,0,0,0,0,0,0,0,0,0,0,0,11,10
0,4,0,0,36,0,36,2,3,2,2,2,2,4,4,0,4,2,2,2,2,2,2,0,0,0,0,0,2,10
0,0,2,0,0,36,4,27,28,27,27,0,0,10,0,0,12,15,15,15,15,15,15,4,0,0,0,2,0,10
0,0,0,2,36,3,0,29,0,0,0,0,10,0,0,0,0,15,15,15,15,15,15,15,2,0,2,10,0,0
10,10,10,2,0,2,0,0,0,0,0,0,0,0,4,0,4,15,15,15,15,15,15,15,2,0,2,0,0,10
0,0,10,2,0,2,0,0,4,3,2,3,4,4,14,0,4,15,15,15,17,15,15,15,2,0,2,0,0,10
0,0,10,2,0,3,0,0,2,32,31,0,0,0,0,0,2,15,15,15,15,15,15,15,2,0,2,0,10,0
10,0,10,3,0,2,0,0,2,31,31,0,0,0,0,0,3,15,15,15,15,15,15,15,2,0,2,0,0,0
0,0,0,3,0,2,0,0,2,33,0,0,0,0,0,23,3,15,15,15,18,15,15,15,2,13,2,12,10,0
0,10,0,3,0,2,0,0,2,31,31,0,0,0,0,0,3,12,12,12,12,12,12,12,2,2,4,3,0,0
0,0,0,3,0,2,0,0,2,34,31,0,0,0,0,24,22,0,0,0,0,0,0,0,0,0,0,0,0,0
0,0,0,2,0,3,0,0,2,34,31,0,0,0,0,0,0,0,0,0,0,0,0,0,0,0,0,0,0,0
0,10,0,2,0,2,0,0,2,34,31,0,0,0,0,25,22,0,0,0,0,0,0,0,0,0,0,0,0,0
0,10,0,2,0,2,0,0,2,31,31,0,0,0,0,0,3,12,12,12,12,12,12,12,2,2,2,3,0,0
0,10,10,2,0,2,0,0,2,33,0,0,0,0,0,0,4,21,15,15,15,15,15,15,2,14,2,12,0,0
0,0,0,3,0,2,0,0,2,31,31,0,30,4,26,0,4,15,20,15,15,15,15,15,2,0,3,0,0,0
0,10,0,2,0,2,0,0,4,35,31,0,0,0,0,0,2,15,15,15,19,15,15,15,2,0,2,10,10,10
0,0,0,4,0,2,0,0,2,4,2,2,2,2,13,0,2,15,15,15,17,15,15,15,2,0,3,10,0,0
0,0,0,4,0,2,0,0,0,0,0,0,0,0,2,0,3,15,15,15,15,15,15,15,2,0,4,10,0,0
10,0,0,4,0,2,10,0,0,27,28,29,28,29,27,0,0,15,15,15,15,15,15,15,2,0,2,10,10,0
0,10,2,0,0,0,3,0,0,0,28,28,28,29,0,0,12,15,15,15,15,16,15,2,0,0,0,3,0,0
0,2,0,0,0,0,0,3,2,3,2,2,2,2,3,0,2,2,2,2,2,2,2,0,0,0,0,0,3,0
0,4,0,0,0,0,0,0,0,0,0,0,0,0,0,0,0,0,0,0,0,0,0,0,0,0,0,0,11,0
0,2,0,0,0,0,0,3,4,4,4,2,3,2,2,2,2,2,3,3,3,3,3,0,0,0,0,0,2,0
10,0,2,0,0,0,3,0,0,0,28,10,0,10,28,10,0,0,0,0,0,0,0,3,0,0,0,3,10,0
0,10,0,4,2,2,10,0,0,0,0,0,0,0,10,0,0,10,10,10,0,10,10,0,3,3,3,0,10,0
0,10,0,0,0,10,0,0,10,0,10,0,0,0,28,10,0,0,0,0,10,10,0,0,0,0,0,10,0,0
endlayer

layer
0,0,0,0,0,0,0,0,0,0,0,0,0,0,0,0,0,0,0,0,0,0,0,0,0,0,0,0,0,0
0,0,0,2,2,2,0,0,0,0,0,0,0,0,0,0,0,0,0,0,0,0,0,0,2,4,2,0,0,0
0,0,2,0,0,0,2,0,0,0,0,0,0,0,0,0,0,0,0,0,0,0,0,2,0,0,0,4,0,0
0,3,0,0,0,0,0,4,4,2,2,2,2,3,2,2,2,3,4,2,2,2,2,0,0,0,0,0,2,0
0,2,0,0,0,0,0,0,0,0,0,0,0,0,0,0,0,0,0,0,0,0,0,0,0,0,0,0,11,0
0,2,0,0,0,0,0,2,2,2,2,2,2,4,4,0,2,2,2,2,2,2,2,0,0,0,0,0,2,0
0,0,2,0,0,0,4,0,0,0,0,0,0,0,0,0,0,0,0,0,0,0,0,2,0,0,0,2,0,0
0,0,0,2,0,2,0,0,0,0,0,0,0,0,0,0,0,0,0,0,0,0,0,0,2,0,2,0,0,0
0,0,0,2,0,2,0,0,0,0,0,0,0,0,2,0,0,0,0,0,0,0,0,0,2,0,2,0,0,0
0,0,0,2,0,2,0,0,4,2,2,37,4,2,14,0,4,0,0,0,0,0,0,0,2,0,2,0,0,0
0,0,0,2,0,2,0,0,4,0,0,0,0,0,0,0,37,0,0,0,0,0,0,0,2,0,2,0,0,0
0,0,0,2,0,2,0,0,2,0,0,0,0,0,0,0,3,0,0,0,0,0,0,0,2,0,2,0,0,0
0,0,0,2,0,2,0,0,2,0,0,0,0,0,0,0,2,0,0,0,0,0,0,0,2,13,2,12,0,0
0,0,0,3,0,2,0,0,37,0,0,0,0,0,0,0,37,12,0,0,0,0,0,0,2,2,2,4,0,0
0,0,0,2,0,3,0,0,37,0,0,0,0,0,0,38,22,0,0,0,0,0,0,0,0,0,0,0,0,0
0,0,0,2,0,2,0,0,37,0,0,0,0,0,0,0,0,0,0,0,0,0,0,0,0,0,0,0,0,0
0,0,0,2,0,2,0,0,37,0,0,0,0,0,0,38,22,0,0,0,0,0,0,0,0,0,0,0,0,0
0,0,0,2,0,2,0,0,37,0,0,0,0,0,0,0,37,12,0,0,0,0,0,0,2,2,2,2,0,0
0,0,0,3,0,2,0,0,2,0,0,0,0,0,0,0,3,0,0,0,0,0,0,0,2,14,2,12,0,0
0,0,0,3,0,2,0,0,2,0,0,0,2,26,0,0,3,0,0,0,0,0,0,0,2,0,3,0,0,0
0,0,0,4,0,2,0,0,2,0,0,0,0,0,0,0,37,0,0,0,0,0,0,0,2,0,3,0,0,0
0,0,0,4,0,2,0,0,2,4,2,37,2,2,13,0,2,0,0,0,0,0,0,0,2,0,2,0,0,0
0,0,0,2,0,2,0,0,0,0,0,0,0,0,2,0,0,0,0,0,0,0,0,0,2,0,4,0,0,0
0,0,0,2,0,2,0,0,0,0,0,0,0,0,0,0,0,0,0,0,0,0,0,0,2,0,2,0,0,0
0,0,2,0,0,0,3,0,0,0,0,0,0,0,0,0,0,0,0,0,0,0,0,2,0,0,0,3,0,0
0,4,0,0,0,0,0,3,2,2,2,2,2,2,2,0,2,2,2,2,2,2,2,0,0,0,0,0,2,0
0,2,0,0,0,0,0,0,0,0,0,0,0,0,0,0,0,0,0,0,0,0,0,0,0,0,0,0,11,0
0,2,0,0,0,0,0,2,4,2,2,2,2,2,2,2,2,2,3,3,2,4,2,0,0,0,0,0,2,0
0,0,2,0,0,0,4,0,0,0,0,0,0,0,0,0,0,0,0,0,0,0,0,3,0,0,0,4,0,0
0,0,0,2,4,4,0,0,0,0,0,0,0,0,0,0,0,0,0,0,0,0,0,0,2,2,3,0,0,0
0,0,0,0,0,0,0,0,0,0,0,0,0,0,0,0,0,0,0,0,0,0,0,0,0,0,0,0,0,0
endlayer

layer
0,0,0,0,0,0,0,0,0,0,0,0,0,0,0,0,0,0,0,0,0,0,0,0,0,0,0,0,0,0
0,0,0,2,2,2,0,0,0,0,0,0,0,0,0,0,0,0,0,0,0,0,0,0,2,2,2,0,0,0
0,0,2,0,0,0,2,0,0,0,0,0,0,0,0,0,0,0,0,0,0,0,0,2,0,0,0,4,0,0
0,2,0,0,0,0,0,2,2,2,2,2,2,2,2,2,2,4,2,2,2,2,2,0,0,0,0,0,2,0
0,2,40,0,0,0,0,0,0,0,0,0,0,0,0,0,0,0,0,0,0,0,0,0,0,0,0,39,11,0
0,2,0,0,0,0,0,2,2,2,2,2,2,2,2,4,2,2,2,2,2,2,2,0,0,0,0,0,2,0
0,0,2,0,0,0,2,0,0,0,0,0,0,0,0,0,0,0,0,0,0,0,0,2,0,0,0,2,0,0
0,0,0,2,0,2,0,0,0,0,0,0,0,0,0,0,0,0,0,0,0,0,0,0,2,0,2,0,0,0
0,0,0,2,0,2,0,0,0,0,0,0,0,0,2,0,0,0,0,0,0,0,0,0,2,0,2,0,0,0
0,0,0,2,0,2,0,0,2,2,2,37,2,2,14,2,2,0,0,0,0,0,0,0,2,0,2,0,0,0
0,0,0,2,0,2,0,0,2,0,0,0,0,0,0,0,37,0,0,0,0,0,0,0,2,0,2,0,0,0
0,0,0,2,0,2,0,0,2,0,0,0,0,0,0,0,2,0,0,0,0,0,0,0,2,0,2,0,0,0
0,0,0,2,0,2,0,0,2,0,0,0,0,0,0,0,3,0,0,0,0,0,0,0,2,13,2,12,0,0
0,0,0,2,0,2,0,0,37,0,0,0,0,0,0,0,37,12,0,0,0,0,0,0,2,2,2,2,0,0
0,0,0,2,0,2,0,0,37,0,0,0,0,0,0,0,22,0,0,0,0,0,0,0,0,0,0,0,0,0
0,0,0,2,40,2,0,0,37,0,0,0,0,0,0,0,0,0,0,0,0,0,0,0,0,0,0,0,0,0
0,0,0,2,0,2,0,0,37,0,0,0,0,0,0,0,22,0,0,0,0,0,0,0,0,0,0,0,0,0
0,0,0,2,0,2,0,0,37,0,0,0,0,0,0,0,37,12,0,0,0,0,0,0,2,2,4,2,0,0
0,0,0,2,0,2,0,0,2,0,0,0,0,0,0,0,2,0,0,0,0,0,0,0,2,14,2,12,0,0
0,0,0,2,0,2,0,0,2,0,0,2,26,0,0,0,3,0,0,0,0,0,0,0,2,0,2,0,0,0
0,0,0,4,0,2,0,0,2,0,0,0,0,0,0,0,37,0,0,0,0,0,0,0,2,0,2,0,0,0
0,0,0,2,0,2,0,0,2,2,2,37,2,2,13,2,2,0,0,0,0,0,0,0,2,0,4,0,0,0
0,0,0,2,0,2,0,0,0,0,0,0,0,0,2,0,0,0,0,0,0,0,0,0,2,0,4,0,0,0
0,0,0,2,0,2,0,0,0,0,0,0,0,0,0,0,0,0,0,0,0,0,0,0,2,0,2,0,0,0
0,0,2,0,0,0,3,0,0,0,0,0,0,0,0,0,0,0,0,0,0,0,0,2,0,0,0,2,0,0
0,2,0,0,0,0,0,2,2,2,2,2,2,2,2,2,2,2,2,2,2,2,2,0,0,0,0,0,2,0
0,2,40,0,0,0,0,0,0,0,0,0,0,0,0,0,0,0,0,0,0,0,0,0,0,0,0,39,11,0
0,2,0,0,0,0,0,2,2,2,2,2,2,2,2,2,2,2,2,2,4,2,2,0,0,0,0,0,2,0
0,0,2,0,0,0,2,0,0,0,0,0,0,0,0,0,0,0,0,0,0,0,0,2,0,0,0,2,0,0
0,0,0,4,4,2,0,0,0,0,0,0,0,0,0,0,0,0,0,0,0,0,0,0,2,2,2,0,0,0
0,0,0,0,0,0,0,0,0,0,0,0,0,0,0,0,0,0,0,0,0,0,0,0,0,0,0,0,0,0
endlayer

layer
0,0,0,0,0,0,0,0,0,0,0,0,0,0,0,0,0,0,0,0,0,0,0,0,0,0,0,0,0,0
0,0,0,2,2,2,0,0,0,0,0,0,0,0,0,0,0,0,0,0,0,0,0,0,2,2,2,0,0,0
0,0,2,2,2,2,2,0,0,0,0,0,0,0,0,0,0,0,0,0,0,0,0,2,2,2,2,2,0,0
0,2,2,2,2,2,2,2,2,2,2,2,2,2,2,2,2,2,2,2,2,2,2,2,2,2,2,2,2,0
0,2,2,2,2,2,2,2,2,2,2,2,2,2,2,2,2,2,2,2,2,2,2,2,2,2,2,2,11,0
0,2,2,2,2,2,2,2,2,2,2,2,2,2,2,2,2,2,2,2,2,2,2,2,2,2,2,2,2,0
0,0,2,2,2,2,2,0,0,0,0,0,0,0,0,0,0,0,0,0,0,0,0,2,2,2,2,2,0,0
0,0,0,2,2,2,0,0,0,0,0,0,0,0,0,0,0,0,0,0,0,0,0,0,2,2,2,0,0,0
0,0,0,2,2,2,0,0,0,0,0,0,0,0,2,0,0,0,0,0,0,0,0,0,2,2,2,0,0,0
0,0,0,2,2,2,0,0,2,2,2,2,2,2,14,2,2,0,0,0,0,0,0,0,2,2,2,0,0,0
0,0,0,2,2,2,0,0,2,0,0,0,0,0,0,0,37,0,0,0,0,0,0,0,2,2,2,0,0,0
0,0,0,2,2,2,0,0,2,0,0,0,0,0,0,0,2,0,0,0,0,0,0,0,2,2,2,0,0,0
0,0,0,2,2,2,0,0,2,0,0,0,0,0,0,0,2,0,0,0,0,0,0,0,2,13,2,12,0,0
0,0,0,2,2,2,0,0,2,0,0,0,0,0,0,0,37,12,0,0,0,0,0,0,2,2,2,2,0,0
0,0,0,2,2,2,0,0,2,0,0,0,0,0,0,39,22,0,0,0,0,0,0,0,0,0,0,0,0,0
0,0,0,2,2,2,0,0,2,0,0,0,0,0,0,0,0,0,0,0,0,0,0,0,0,0,0,0,0,0
0,0,0,2,2,2,0,0,2,0,0,0,0,0,0,39,22,0,0,0,0,0,0,0,0,0,0,0,0,0
0,0,0,2,2,2,0,0,2,0,0,0,0,0,0,0,37,12,0,0,0,0,0,0,2,2,2,4,0,0
0,0,0,2,2,2,0,0,2,0,0,0,0,0,0,0,2,0,0,0,0,0,0,0,2,14,2,12,0,0
0,0,0,2,2,2,0,0,2,0,2,26,0,0,0,0,2,0,0,0,0,0,0,0,2,2,2,0,0,0
0,0,0,2,2,2,0,0,2,0,0,0,0,0,0,0,37,0,0,0,0,0,0,0,2,2,2,0,0,0
0,0,0,2,2,2,0,0,2,2,2,2,3,2,13,2,2,0,0,0,0,0,0,0,2,2,2,0,0,0
0,0,0,2,2,2,0,0,0,0,0,0,0,0,2,0,0,0,0,0,0,0,0,0,2,2,2,0,0,0
0,0,0,2,2,2,0,0,0,0,0,0,0,0,0,0,0,0,0,0,0,0,0,0,2,2,2,0,0,0
0,0,2,2,2,2,2,0,0,0,0,0,0,0,0,0,0,0,0,0,0,0,0,2,2,2,2,2,0,0
0,2,2,2,2,2,2,2,2,2,2,2,2,2,2,2,2,2,2,2,2,2,2,2,2,2,2,2,2,0
0,2,2,2,2,2,2,2,2,2,2,2,2,2,2,2,2,2,2,2,2,2,2,2,2,2,2,2,11,0
0,2,2,2,2,2,2,2,2,2,2,2,2,2,2,2,2,2,2,2,4,2,2,2,2,2,2,2,2,0
0,0,2,2,2,2,2,0,0,0,0,0,0,0,0,0,0,0,0,0,0,0,0,2,2,2,2,2,0,0
0,0,0,2,2,2,0,0,0,0,0,0,0,0,0,0,0,0,0,0,0,0,0,0,2,2,2,0,0,0
0,0,0,0,0,0,0,0,0,0,0,0,0,0,0,0,0,0,0,0,0,0,0,0,0,0,0,0,0,0
endlayer

layer
0,0,0,0,0,0,0,0,0,0,0,0,0,0,0,0,0,0,0,0,0,0,0,0,0,0,0,0,0,0
0,0,0,2,37,2,0,0,0,0,0,0,0,0,0,0,0,0,0,0,0,0,0,0,2,37,2,0,0,0
0,0,2,0,0,0,2,0,0,0,0,0,0,0,0,0,0,0,0,0,0,0,0,2,0,0,0,2,0,0
0,2,0,0,0,0,0,2,2,0,2,0,2,0,2,2,0,2,0,2,0,2,2,0,0,0,0,0,2,0
0,37,0,0,0,0,0,0,0,0,0,0,0,0,0,0,0,0,0,0,0,0,0,0,0,0,0,0,37,0
0,2,0,0,0,0,13,2,0,0,0,0,0,0,0,0,0,0,0,0,0,0,2,0,0,0,0,0,2,0
0,0,2,0,0,0,2,0,0,0,0,0,0,0,0,0,0,0,0,0,0,0,0,2,0,0,13,2,0,0
0,0,0,2,0,2,0,0,0,0,0,0,0,0,0,0,0,0,0,0,0,0,0,0,2,0,2,0,0,0
0,0,0,2,0,0,0,0,0,0,0,0,0,0,2,0,0,0,0,0,0,0,0,0,0,0,0,0,0,0
0,0,0,0,0,0,0,0,2,2,2,2,2,2,14,2,2,0,0,0,0,0,0,0,0,0,2,0,0,0
0,0,0,2,0,0,0,0,2,0,0,43,0,0,0,0,22,0,0,0,0,0,0,0,0,0,0,0,0,0
0,0,0,0,0,0,0,0,2,40,0,0,0,0,0,0,2,0,0,0,0,0,0,0,0,0,2,0,0,0
0,0,0,2,0,0,0,0,2,0,0,0,0,0,0,0,2,0,0,0,0,0,0,0,2,13,2,2,0,0
0,0,0,0,0,0,0,0,2,0,0,0,0,0,0,0,41,2,0,0,0,0,0,0,2,2,2,2,0,0
0,0,0,2,0,0,0,0,2,0,0,0,0,0,0,0,42,2,0,0,0,0,0,0,2,2,2,2,0,0
0,0,0,0,0,0,0,0,2,0,0,0,0,0,0,0,2,2,0,0,0,0,0,0,2,2,2,2,0,0
0,0,0,2,0,0,0,0,2,0,0,0,0,0,0,0,41,2,0,0,0,0,0,0,2,2,2,4,0,0
0,0,0,0,0,0,0,0,2,0,0,0,0,0,0,0,42,2,0,0,0,0,0,0,2,2,2,2,0,0
0,0,0,2,0,0,0,0,2,40,0,0,0,0,0,0,2,0,0,0,0,0,0,0,2,14,2,2,0,0
0,0,0,0,0,0,0,0,2,0,26,0,0,0,0,0,2,0,0,0,0,0,0,0,0,0,2,0,0,0
0,0,0,2,0,0,0,0,2,0,0,44,0,0,0,0,22,0,0,0,0,0,0,0,0,0,0,0,0,0
0,0,0,0,0,0,0,0,2,2,2,2,2,2,13,2,2,0,0,0,0,0,0,0,0,0,2,0,0,0
0,0,0,2,0,0,0,0,0,0,0,0,0,0,2,0,0,0,0,0,0,0,0,0,0,0,0,0,0,0
0,0,0,2,0,2,0,0,0,0,0,0,0,0,0,0,0,0,0,0,0,0,0,0,2,0,2,0,0,0
0,0,2,0,0,14,2,0,0,0,0,0,0,0,0,0,0,0,0,0,0,0,0,2,0,0,14,2,0,0
0,2,0,0,0,0,0,2,0,0,0,0,0,0,0,0,0,0,0,0,0,0,2,0,0,0,0,0,2,0
0,37,0,0,0,0,0,0,0,0,0,0,0,0,0,0,0,0,0,0,0,0,0,0,0,0,0,0,37,0
0,2,0,0,0,0,0,2,2,0,2,0,2,0,2,2,0,2,0,2,0,2,2,0,0,0,0,0,2,0
0,0,2,0,0,0,2,0,0,0,0,0,0,0,0,0,0,0,0,0,0,0,0,2,0,0,0,2,0,0
0,0,0,2,37,2,0,0,0,0,0,0,0,0,0,0,0,0,0,0,0,0,0,0,2,37,2,0,0,0
0,0,0,0,0,0,0,0,0,0,0,0,0,0,0,0,0,0,0,0,0,0,0,0,0,0,0,0,0,0
endlayer

layer
0,0,0,0,0,0,0,0,0,0,0,0,0,0,0,0,0,0,0,0,0,0,0,0,0,0,0,0,0,0
0,0,0,2,37,2,0,0,0,0,0,0,0,0,0,0,0,0,0,0,0,0,0,0,2,37,2,0,0,0
0,0,2,0,0,0,2,0,0,0,0,0,0,0,0,0,0,0,0,0,0,0,0,2,0,0,0,2,0,0
0,2,0,0,0,0,0,2,0,0,0,0,0,0,0,0,0,0,0,0,0,0,2,0,0,0,0,0,2,0
0,37,0,0,0,0,0,0,0,0,0,0,0,0,0,0,0,0,0,0,0,0,0,0,0,0,0,0,37,0
0,2,0,0,0,0,13,2,0,0,0,0,0,0,0,0,0,0,0,0,0,0,2,0,0,0,0,0,2,0
0,0,2,0,0,0,2,0,0,0,0,0,0,0,0,0,0,0,0,0,0,0,0,2,0,0,13,2,0,0
0,0,0,2,0,2,0,0,0,0,0,0,0,0,0,0,0,0,0,0,0,0,0,0,2,0,2,0,0,0
0,0,0,0,0,0,0,0,0,0,0,0,0,0,2,0,0,0,0,0,0,0,0,0,0,0,0,0,0,0
0,0,0,0,0,0,0,0,2,2,2,2,2,2,14,2,2,22,0,0,0,0,0,0,0,0,0,0,0,0
0,0,0,0,0,0,0,0,2,2,2,2,2,2,2,3,2,0,0,0,0,0,0,0,0,0,0,0,0,0
0,0,0,0,0,0,0,0,2,2,2,2,2,2,2,2,2,22,0,0,0,0,0,0,0,0,0,0,0,0
0,0,0,0,0,0,0,0,2,2,2,2,2,2,2,2,2,0,0,0,0,0,0,2,2,0,2,2,2,0
0,0,0,0,0,0,2,2,2,2,2,2,2,2,2,2,2,0,0,0,0,0,0,37,0,0,0,0,37,0
0,0,0,0,0,0,2,2,2,2,2,2,2,2,2,2,2,31,0,0,0,0,0,37,0,0,0,0,37,0
0,0,0,0,0,0,2,2,2,2,2,2,2,2,2,2,2,11,0,0,0,0,0,37,0,0,0,0,37,0
0,0,0,0,0,0,2,2,2,2,2,2,2,2,2,2,2,31,0,0,0,0,0,37,0,0,0,0,37,0
0,0,0,0,0,0,2,2,2,2,2,2,2,2,2,2,2,0,0,0,0,0,0,37,0,0,0,0,37,0
0,0,0,0,0,0,0,0,2,2,2,2,2,2,2,2,2,0,0,0,0,0,0,2,2,0,2,2,2,0
0,0,0,0,0,0,0,0,2,26,0,0,0,2,2,2,2,22,0,0,0,0,0,0,0,0,0,0,0,0
0,0,0,0,0,0,0,0,2,2,2,2,2,2,2,2,2,0,0,0,0,0,0,0,0,0,0,0,0,0
0,0,0,0,0,0,0,0,2,2,2,2,2,2,13,2,2,22,0,0,0,0,0,0,0,0,0,0,0,0
0,0,0,0,0,0,0,0,0,0,0,0,0,0,2,0,0,0,0,0,0,0,0,0,0,0,0,0,0,0
0,0,0,2,0,2,0,0,0,0,0,0,0,0,0,0,0,0,0,0,0,0,0,0,2,0,2,0,0,0
0,0,2,0,0,14,2,0,0,0,0,0,0,0,0,0,0,0,0,0,0,0,0,2,0,0,14,2,0,0
0,2,0,0,0,0,0,2,0,0,0,0,0,0,0,0,0,0,0,0,0,0,2,0,0,0,0,0,2,0
0,37,0,0,0,0,0,0,0,0,0,0,0,0,0,0,0,0,0,0,0,0,0,0,0,0,0,0,37,0
0,2,0,0,0,0,0,2,0,0,0,0,0,0,0,0,0,0,0,0,0,0,2,0,0,0,0,0,2,0
0,0,2,0,0,0,2,0,0,0,0,0,0,0,0,0,0,0,0,0,0,0,0,2,0,0,0,2,0,0
0,0,0,2,37,2,0,0,0,0,0,0,0,0,0,0,0,0,0,0,0,0,0,0,2,37,2,0,0,0
0,0,0,0,0,0,0,0,0,0,0,0,0,0,0,0,0,0,0,0,0,0,0,0,0,0,0,0,0,0
endlayer

layer
0,0,0,2,0,2,0,0,0,0,0,0,0,0,0,0,0,0,0,0,0,0,0,0,2,0,2,0,0,0
0,0,2,2,2,2,2,0,0,0,0,0,0,0,0,0,0,0,0,0,0,0,0,2,2,2,2,2,0,0
0,2,2,0,0,0,2,2,0,0,0,0,0,0,0,0,0,0,0,0,0,0,2,2,0,0,0,2,2,0
2,2,0,0,0,0,0,2,2,0,0,0,0,0,0,0,0,0,0,0,0,2,2,0,0,0,0,0,2,2
0,2,0,0,0,0,0,11,0,0,0,0,0,0,0,0,0,0,0,0,0,0,2,0,0,0,0,0,11,0
2,2,0,0,0,0,13,2,2,0,0,0,0,0,0,0,0,0,0,0,0,2,2,0,0,0,0,0,2,2
0,2,2,0,0,0,2,2,0,0,0,0,0,0,0,0,0,0,0,0,0,0,2,2,0,0,13,2,2,0
0,0,2,2,2,2,2,0,0,0,0,0,0,0,0,0,0,0,0,0,0,0,0,2,2,2,2,2,0,0
0,0,0,2,0,2,0,0,0,0,0,0,0,0,2,0,0,0,0,0,0,0,0,0,2,43,2,0,0,0
0,0,0,0,0,0,0,46,46,46,46,46,46,2,14,2,2,26,0,0,0,0,0,0,0,0,0,0,0,0
0,0,0,0,0,0,0,0,2,2,2,2,2,2,0,2,45,26,0,0,0,0,0,0,0,0,0,0,0,0
0,0,0,0,0,0,0,0,2,30,30,30,0,0,0,45,0,26,0,0,0,0,0,0,0,0,0,0,0,0
0,0,0,0,0,0,0,0,2,30,0,0,0,30,2,0,0,26,0,0,0,0,0,2,2,0,2,2,2,0
0,0,0,0,0,0,12,12,12,0,0,0,0,0,2,0,0,26,0,0,0,0,0,37,0,0,0,0,37,0
0,0,0,0,0,0,12,0,0,0,0,0,0,0,2,0,0,26,0,0,0,0,0,37,0,0,0,0,37,0
0,0,0,0,0,0,12,0,0,0,0,0,0,0,0,0,0,26,0,0,0,0,0,37,0,0,0,0,37,0
0,0,0,0,0,0,12,0,0,0,0,0,0,30,2,0,0,26,0,0,0,0,0,37,0,0,0,0,37,0
0,0,0,0,0,0,12,12,12,0,0,0,0,30,2,0,0,26,0,0,0,0,0,37,0,0,0,0,37,0
0,0,0,0,0,0,0,0,2,0,0,0,0,0,2,0,0,26,0,0,0,0,0,2,2,0,2,2,2,0
0,0,0,0,0,0,0,0,2,0,0,0,0,0,0,45,0,26,0,0,0,0,0,0,0,0,0,0,0,0
0,0,0,0,0,0,0,0,2,2,2,2,2,2,0,2,45,26,0,0,0,0,0,0,0,0,0,0,0,0
0,0,0,0,0,0,0,47,47,47,47,47,47,2,13,2,2,26,0,0,0,0,0,0,0,0,0,0,0,0
0,0,0,2,0,2,0,0,0,0,0,0,0,0,2,0,0,0,0,0,0,0,0,0,2,44,2,0,0,0
0,0,2,2,2,2,2,0,0,0,0,0,0,0,0,0,0,0,0,0,0,0,0,2,2,2,2,2,0,0
0,2,2,0,0,14,2,2,0,0,0,0,0,0,0,0,0,0,0,0,0,0,2,2,0,0,14,2,2,0
2,2,0,0,0,0,0,2,2,0,0,0,0,0,0,0,0,0,0,0,0,2,2,0,0,0,0,0,2,2
0,2,0,0,0,0,0,11,0,0,0,0,0,0,0,0,0,0,0,0,0,0,2,0,0,0,0,0,11,0
2,2,0,0,0,0,0,2,2,0,0,0,0,0,0,0,0,0,0,0,0,2,2,0,0,0,0,0,2,2
0,2,2,0,0,0,2,2,0,0,0,0,0,0,0,0,0,0,0,0,0,0,2,2,0,0,0,2,2,0
0,0,2,2,2,2,2,0,0,0,0,0,0,0,0,0,0,0,0,0,0,0,0,2,2,2,2,2,0,0
0,0,0,2,0,2,0,0,0,0,0,0,0,0,0,0,0,0,0,0,0,0,0,0,2,0,2,0,0,0
endlayer

layer
0,0,0,2,2,2,0,0,0,0,0,0,0,0,0,0,0,0,0,0,0,0,0,0,2,2,2,0,0,0
0,0,2,2,2,2,2,0,0,0,0,0,0,0,0,0,0,0,0,0,0,0,0,2,2,2,2,2,0,0
0,2,2,0,0,0,2,2,0,0,0,0,0,0,0,0,0,0,0,0,0,0,2,2,0,0,0,2,2,0
2,2,0,0,0,0,0,2,2,0,0,0,0,0,0,0,0,0,0,0,0,2,2,0,0,0,0,0,2,2
2,2,0,0,0,0,0,11,2,0,0,0,0,0,0,0,0,0,0,0,0,2,2,0,0,0,0,0,11,2
2,2,0,0,0,0,13,2,2,0,0,0,0,0,0,0,0,0,0,0,0,2,2,0,0,0,0,0,2,2
0,2,2,0,0,0,2,2,0,0,0,0,0,0,0,0,0,0,0,0,0,0,2,2,0,0,13,2,2,0
0,0,2,2,2,2,2,0,0,0,0,0,0,0,0,0,0,0,0,0,0,0,0,2,2,2,2,2,0,0
0,0,0,2,2,2,0,0,0,0,0,0,0,0,2,0,0,0,0,0,0,0,0,0,2,2,2,0,0,0
0,0,0,0,0,0,0,0,0,0,0,0,0,2,14,2,0,0,0,0,0,0,0,0,0,0,0,0,0,0
0,0,0,0,0,0,0,45,45,45,45,45,45,45,0,45,45,0,0,0,0,0,0,0,0,0,0,0,0,0
0,0,0,0,0,0,0,0,2,30,30,0,0,0,0,45,0,0,0,0,0,0,17,17,17,17,17,17,17,17
0,0,0,0,0,0,0,0,2,0,0,0,0,0,2,0,0,0,0,0,0,0,2,2,2,2,2,2,2,2
0,0,0,0,0,0,0,0,0,0,0,0,0,0,37,0,0,0,0,0,0,0,0,2,0,0,0,39,2,0
0,0,0,0,0,0,0,0,0,0,0,0,0,0,2,0,0,0,0,0,0,0,0,2,0,0,0,0,2,0
0,0,0,0,0,0,0,0,0,0,0,0,0,0,0,0,0,0,0,0,0,0,0,2,0,0,0,0,2,0
0,0,0,0,0,0,0,0,0,0,0,0,0,30,2,0,0,0,0,0,0,0,0,2,0,0,0,0,2,0
0,0,0,0,0,0,0,0,0,0,0,0,0,0,37,0,0,0,0,0,0,0,0,2,0,0,0,39,2,0
0,0,0,0,0,0,0,0,2,0,0,0,0,0,2,0,0,0,0,0,0,0,2,2,2,2,2,2,2,2
0,0,0,0,0,0,0,0,2,0,0,0,0,0,0,45,0,0,0,0,0,0,17,17,17,17,17,17,17,17
0,0,0,0,0,0,0,45,45,45,45,45,45,45,0,45,45,0,0,0,0,0,0,0,0,0,0,0,0,0
0,0,0,0,0,0,0,0,0,0,0,0,0,2,13,2,0,0,0,0,0,0,0,0,0,0,0,0,0,0
0,0,0,2,2,2,0,0,0,0,0,0,0,0,2,0,0,0,0,0,0,0,0,0,2,2,2,0,0,0
0,0,2,2,2,2,2,0,0,0,0,0,0,0,0,0,0,0,0,0,0,0,0,2,2,2,2,2,0,0
0,2,2,0,0,14,2,2,0,0,0,0,0,0,0,0,0,0,0,0,0,0,2,2,0,0,14,2,2,0
2,2,0,0,0,0,0,2,2,0,0,0,0,0,0,0,0,0,0,0,0,2,2,0,0,0,0,0,2,2
2,2,0,0,0,0,0,11,2,0,0,0,0,0,0,0,0,0,0,0,0,2,2,0,0,0,0,0,11,2
2,2,0,0,0,0,0,2,2,0,0,0,0,0,0,0,0,0,0,0,0,2,2,0,0,0,0,0,2,2
0,2,2,0,0,0,2,2,0,0,0,0,0,0,0,0,0,0,0,0,0,0,2,2,0,0,0,2,2,0
0,0,2,2,2,2,2,0,0,0,0,0,0,0,0,0,0,0,0,0,0,0,0,2,2,2,2,2,0,0
0,0,0,2,2,2,0,0,0,0,0,0,0,0,0,0,0,0,0,0,0,0,0,0,2,2,2,0,0,0
endlayer

layer
0,0,0,2,37,2,0,0,0,0,0,0,0,0,0,0,0,0,0,0,0,0,0,0,2,37,2,0,0,0
0,0,2,0,0,0,2,0,0,0,0,0,0,0,0,0,0,0,0,0,0,0,0,2,0,0,0,2,0,0
0,2,0,0,0,0,0,2,0,0,0,0,0,0,0,0,0,0,0,0,0,0,2,0,0,0,0,0,2,0
2,0,0,0,0,0,0,0,2,0,0,0,0,0,0,0,0,0,0,0,0,2,0,0,0,0,0,0,0,2
37,0,0,0,0,0,0,0,37,0,0,0,0,0,0,0,0,0,0,0,0,37,0,0,0,0,0,0,0,37
2,0,0,0,0,0,0,0,2,0,0,0,0,0,0,0,0,0,0,0,0,2,0,0,0,0,0,0,0,2
0,2,0,0,0,0,13,2,0,0,0,0,0,0,0,0,0,0,0,0,0,0,2,0,0,0,0,0,2,0
0,0,2,0,0,0,2,0,0,0,0,0,0,0,0,0,0,0,0,0,0,0,0,2,0,0,13,2,0,0
0,0,0,2,37,2,0,0,0,0,0,0,0,0,2,0,0,0,0,0,0,0,0,0,2,37,2,0,0,0
0,0,0,0,0,0,0,0,0,0,0,0,0,2,14,2,0,0,0,0,0,0,0,0,0,0,0,0,0,0
0,0,0,0,0,0,0,0,0,0,0,0,0,0,2,0,0,0,0,0,0,0,0,0,0,0,0,0,0,0
0,0,0,0,0,0,0,45,45,45,45,45,45,45,45,45,45,0,0,0,0,0,0,0,0,0,0,0,0,0
0,0,0,0,0,0,0,0,2,0,0,0,0,0,2,0,0,0,0,0,0,0,0,0,0,0,0,0,0,0
0,0,0,0,0,0,0,0,2,0,0,0,0,0,37,0,0,0,0,0,0,0,17,17,17,17,17,17,17,17
0,0,0,0,0,0,0,0,2,0,0,0,0,0,2,0,0,0,0,0,0,0,45,45,45,45,45,45,45,45
0,0,0,0,0,0,0,0,37,0,0,0,0,0,0,0,0,0,0,0,0,0,45,45,45,45,45,45,45,45
0,0,0,0,0,0,0,0,2,0,0,0,0,0,2,0,0,0,0,0,0,0,45,45,45,45,45,45,45,45
0,0,0,0,0,0,0,0,2,0,0,0,0,0,37,0,0,0,0,0,0,0,17,17,17,17,17,17,17,17
0,0,0,0,0,0,0,0,2,0,0,0,0,0,2,0,0,0,0,0,0,0,0,0,0,0,0,0,0,0
0,0,0,0,0,0,0,45,45,45,45,45,45,45,45,45,45,0,0,0,0,0,0,0,0,0,0,0,0,0
0,0,0,0,0,0,0,0,0,0,0,0,0,0,2,0,0,0,0,0,0,0,0,0,0,0,0,0,0,0
0,0,0,0,0,0,0,0,0,0,0,0,0,2,13,2,0,0,0,0,0,0,0,0,0,0,0,0,0,0
0,0,0,2,37,2,0,0,0,0,0,0,0,0,2,0,0,0,0,0,0,0,0,0,2,37,2,0,0,0
0,0,2,0,0,14,2,0,0,0,0,0,0,0,0,0,0,0,0,0,0,0,0,2,0,0,14,2,0,0
0,2,0,0,0,0,0,2,0,0,0,0,0,0,0,0,0,0,0,0,0,0,2,0,0,0,0,0,2,0
2,0,0,0,0,0,0,0,2,0,0,0,0,0,0,0,0,0,0,0,0,2,0,0,0,0,0,0,0,2
37,0,0,0,0,0,0,0,37,0,0,0,0,0,0,0,0,0,0,0,0,37,0,0,0,0,0,0,0,37
2,0,0,0,0,0,0,0,2,0,0,0,0,0,0,0,0,0,0,0,0,2,0,0,0,0,0,0,0,2
0,2,0,0,0,0,0,2,0,0,0,0,0,0,0,0,0,0,0,0,0,0,2,0,0,0,0,0,2,0
0,0,2,0,0,0,2,0,0,0,0,0,0,0,0,0,0,0,0,0,0,0,0,2,0,0,0,2,0,0
0,0,0,2,37,2,0,0,0,0,0,0,0,0,0,0,0,0,0,0,0,0,0,0,2,37,2,0,0,0
endlayer

layer
0,0,0,2,37,2,0,0,0,0,0,0,0,0,0,0,0,0,0,0,0,0,0,0,2,37,2,0,0,0
0,0,2,0,0,0,2,0,0,0,0,0,0,0,0,0,0,0,0,0,0,0,0,2,0,0,0,2,0,0
0,2,0,0,0,0,0,2,0,0,0,0,0,0,0,0,0,0,0,0,0,0,2,0,0,0,0,0,2,0
2,0,0,0,0,0,0,0,2,0,0,0,0,0,0,0,0,0,0,0,0,2,0,0,0,0,0,0,0,2
37,0,0,0,0,0,0,0,37,0,0,0,0,0,0,0,0,0,0,0,0,37,0,0,0,0,0,0,0,37
2,0,0,0,0,0,0,0,2,0,0,0,0,0,0,0,0,0,0,0,0,2,0,0,0,0,0,0,0,2
0,2,0,0,0,0,13,2,0,0,0,0,0,0,0,0,0,0,0,0,0,0,2,0,0,0,0,0,2,0
0,0,2,0,0,0,2,0,0,0,0,0,0,0,0,0,0,0,0,0,0,0,0,2,0,0,13,2,0,0
0,0,0,2,37,2,0,0,0,0,0,0,0,0,2,0,0,0,0,0,0,0,0,0,2,37,2,0,0,0
0,0,0,0,0,0,0,0,0,0,0,0,0,2,14,2,0,0,0,0,0,0,0,0,0,0,0,0,0,0
0,0,0,0,0,0,0,0,0,0,0,0,0,0,2,0,0,0,0,0,0,0,0,0,0,0,0,0,0,0
0,0,0,0,0,0,0,0,0,0,0,0,0,0,0,0,0,0,0,0,0,0,0,0,0,0,0,0,0,0
0,0,0,0,0,0,0,45,45,45,45,45,45,45,45,45,45,0,0,0,0,0,0,0,0,0,0,0,0,0
0,0,0,0,0,0,0,0,2,0,0,0,0,0,2,0,0,0,0,0,0,0,0,0,0,0,0,0,0,0
0,0,0,0,0,0,0,0,2,0,0,12,0,0,2,0,0,0,0,0,0,0,0,0,0,0,0,0,0,0
0,0,0,0,0,0,0,0,37,0,12,12,12,0,2,0,0,0,0,0,0,0,0,0,0,0,0,0,0,0
0,0,0,0,0,0,0,0,2,0,0,12,0,0,2,0,0,0,0,0,0,0,0,0,0,0,0,0,0,0
0,0,0,0,0,0,0,0,2,0,0,0,0,0,2,0,0,0,0,0,0,0,0,0,0,0,0,0,0,0
0,0,0,0,0,0,0,45,45,45,45,45,45,45,45,45,45,0,0,0,0,0,0,0,0,0,0,0,0,0
0,0,0,0,0,0,0,0,0,0,0,0,0,0,0,0,0,0,0,0,0,0,0,0,0,0,0,0,0,0
0,0,0,0,0,0,0,0,0,0,0,0,0,0,2,0,0,0,0,0,0,0,0,0,0,0,0,0,0,0
0,0,0,0,0,0,0,0,0,0,0,0,0,2,13,2,0,0,0,0,0,0,0,0,0,0,0,0,0,0
0,0,0,2,37,2,0,0,0,0,0,0,0,0,2,0,0,0,0,0,0,0,0,0,2,37,2,0,0,0
0,0,2,0,0,14,2,0,0,0,0,0,0,0,0,0,0,0,0,0,0,0,0,2,0,0,14,2,0,0
0,2,0,0,0,0,0,2,0,0,0,0,0,0,0,0,0,0,0,0,0,0,2,0,0,0,0,0,2,0
2,0,0,0,0,0,0,0,2,0,0,0,0,0,0,0,0,0,0,0,0,2,0,0,0,0,0,0,0,2
37,0,0,0,0,0,0,0,37,0,0,0,0,0,0,0,0,0,0,0,0,37,0,0,0,0,0,0,0,37
2,0,0,0,0,0,0,0,2,0,0,0,0,0,0,0,0,0,0,0,0,2,0,0,0,0,0,0,0,2
0,2,0,0,0,0,0,2,0,0,0,0,0,0,0,0,0,0,0,0,0,0,2,0,0,0,0,0,2,0
0,0,2,0,0,0,2,0,0,0,0,0,0,0,0,0,0,0,0,0,0,0,0,2,0,0,0,2,0,0
0,0,0,2,37,2,0,0,0,0,0,0,0,0,0,0,0,0,0,0,0,0,0,0,2,37,2,0,0,0
endlayer

layer
0,0,0,11,11,11,0,0,0,0,0,0,0,0,0,0,0,0,0,0,0,0,0,0,11,11,11,0,0,0
0,0,11,45,45,45,11,0,0,0,0,0,0,0,0,0,0,0,0,0,0,0,0,11,45,45,45,11,0,0
0,11,45,45,45,45,45,11,0,0,0,0,0,0,0,0,0,0,0,0,0,0,11,45,45,45,45,45,11,0
11,45,45,45,45,45,45,45,11,0,0,0,0,0,0,0,0,0,0,0,0,11,45,45,45,45,45,45,45,11
11,45,45,45,45,45,45,45,11,0,0,0,0,0,0,0,0,0,0,0,0,11,45,45,45,45,45,45,45,11
11,45,45,45,45,45,45,45,11,0,0,0,0,0,0,0,0,0,0,0,0,11,45,45,45,45,45,45,45,11
0,11,45,45,45,45,13,11,0,0,0,0,0,0,0,0,0,0,0,0,0,0,11,45,45,45,45,45,11,0
0,0,11,45,45,45,11,0,0,0,0,0,0,0,0,0,0,0,0,0,0,0,0,11,45,45,13,11,0,0
0,0,0,11,11,11,0,0,0,0,0,0,0,0,2,0,0,0,0,0,0,0,0,0,11,11,11,0,0,0
0,0,0,0,0,0,0,0,0,0,0,0,0,2,14,2,0,0,0,0,0,0,0,0,0,0,0,0,0,0
0,0,0,0,0,0,0,0,0,0,0,0,0,0,2,0,0,0,0,0,0,0,0,0,0,0,0,0,0,0
0,0,0,0,0,0,0,0,0,0,0,0,0,0,0,0,0,0,0,0,0,0,0,0,0,0,0,0,0,0
0,0,0,0,0,0,0,0,0,0,0,0,0,0,0,0,0,0,0,0,0,0,0,0,0,0,0,0,0,0
0,0,0,0,0,0,0,45,45,45,45,45,45,45,45,45,45,0,0,0,0,0,0,0,0,0,0,0,0,0
0,0,0,0,0,0,0,0,2,40,0,0,0,0,2,0,0,0,0,0,0,0,0,0,0,0,0,0,0,0
0,0,0,0,0,0,0,0,2,0,0,12,0,0,2,0,0,0,0,0,0,0,0,0,0,0,0,0,0,0
0,0,0,0,0,0,0,0,2,40,0,0,0,0,2,0,0,0,0,0,0,0,0,0,0,0,0,0,0,0
0,0,0,0,0,0,0,45,45,45,45,45,45,45,45,45,45,0,0,0,0,0,0,0,0,0,0,0,0,0
0,0,0,0,0,0,0,0,0,0,0,0,0,0,0,0,0,0,0,0,0,0,0,0,0,0,0,0,0,0
0,0,0,0,0,0,0,0,0,0,0,0,0,0,0,0,0,0,0,0,0,0,0,0,0,0,0,0,0,0
0,0,0,0,0,0,0,0,0,0,0,0,0,0,2,0,0,0,0,0,0,0,0,0,0,0,0,0,0,0
0,0,0,0,0,0,0,0,0,0,0,0,0,2,13,2,0,0,0,0,0,0,0,0,0,0,0,0,0,0
0,0,0,11,11,11,0,0,0,0,0,0,0,0,2,0,0,0,0,0,0,0,0,0,11,11,11,0,0,0
0,0,11,45,45,14,11,0,0,0,0,0,0,0,0,0,0,0,0,0,0,0,0,11,45,45,14,11,0,0
0,11,45,45,45,45,45,11,0,0,0,0,0,0,0,0,0,0,0,0,0,0,11,45,45,45,45,45,11,0
11,45,45,45,45,45,45,45,11,0,0,0,0,0,0,0,0,0,0,0,0,11,45,45,45,45,45,45,45,11
11,45,45,45,45,45,45,45,11,0,0,0,0,0,0,0,0,0,0,0,0,11,45,45,45,45,45,45,45,11
11,45,45,45,45,45,45,45,11,0,0,0,0,0,0,0,0,0,0,0,0,11,45,45,45,45,45,45,45,11
0,11,45,45,45,45,45,11,0,0,0,0,0,0,0,0,0,0,0,0,0,0,11,45,45,45,45,45,11,0
0,0,11,45,45,45,11,0,0,0,0,0,0,0,0,0,0,0,0,0,0,0,0,11,45,45,45,11,0,0
0,0,0,11,11,11,0,0,0,0,0,0,0,0,0,0,0,0,0,0,0,0,0,0,11,11,11,0,0,0
endlayer

layer
0,0,0,2,2,2,0,0,0,0,0,0,0,0,0,0,0,0,0,0,0,0,0,0,2,2,2,0,0,0
0,0,2,0,0,0,2,0,0,0,0,0,0,0,0,0,0,0,0,0,0,0,0,2,0,0,0,2,0,0
0,2,0,0,0,0,0,2,0,0,0,0,0,0,0,0,0,0,0,0,0,0,2,0,0,0,0,0,2,0
2,0,0,0,0,0,0,0,2,0,0,0,0,0,0,0,0,0,0,0,0,2,0,0,0,0,0,0,0,2
2,0,0,0,0,0,0,0,11,0,0,0,0,0,0,0,0,0,0,0,0,2,0,0,0,0,0,0,0,11
2,0,0,0,0,0,0,0,2,0,0,0,0,0,0,0,0,0,0,0,0,2,0,0,0,0,0,0,0,2
0,2,0,0,0,0,0,2,0,0,0,0,0,0,0,0,0,0,0,0,0,0,2,0,0,0,0,0,2,0
0,0,2,0,0,0,2,0,0,0,0,0,0,0,0,0,0,0,0,0,0,0,0,2,0,0,0,2,0,0
0,0,0,2,2,2,0,0,0,0,0,0,0,2,2,2,0,0,0,0,0,0,0,0,2,2,2,0,0,0
0,0,0,0,0,0,0,0,0,0,0,0,0,2,14,2,0,0,0,0,0,0,0,0,0,0,0,0,0,0
0,0,0,0,0,0,0,0,0,0,0,0,0,2,2,2,0,0,0,0,0,0,0,0,0,0,0,0,0,0
0,0,0,0,0,0,0,0,0,0,0,0,0,0,0,0,0,0,0,0,0,0,0,0,0,0,0,0,0,0
0,0,0,0,0,0,0,0,0,0,0,0,0,0,0,0,0,0,0,0,0,0,0,0,0,0,0,0,0,0
0,0,0,0,0,0,0,0,0,0,0,0,0,0,0,0,0,0,0,0,0,0,0,0,0,0,0,0,0,0
0,0,0,0,0,0,0,45,45,45,45,45,45,45,45,45,45,0,0,0,0,0,0,0,0,0,0,0,0,0
0,0,0,0,0,0,0,0,2,48,48,48,48,48,2,0,0,0,0,0,0,0,0,0,0,0,0,0,0,0
0,0,0,0,0,0,0,45,45,45,45,45,45,45,45,45,45,0,0,0,0,0,0,0,0,0,0,0,0,0
0,0,0,0,0,0,0,0,0,0,0,0,0,0,0,0,0,0,0,0,0,0,0,0,0,0,0,0,0,0
0,0,0,0,0,0,0,0,0,0,0,0,0,0,0,0,0,0,0,0,0,0,0,0,0,0,0,0,0,0
0,0,0,0,0,0,0,0,0,0,0,0,0,0,0,0,0,0,0,0,0,0,0,0,0,0,0,0,0,0
0,0,0,0,0,0,0,0,0,0,0,0,0,2,2,2,0,0,0,0,0,0,0,0,0,0,0,0,0,0
0,0,0,0,0,0,0,0,0,0,0,0,0,2,13,2,0,0,0,0,0,0,0,0,0,0,0,0,0,0
0,0,0,2,2,2,0,0,0,0,0,0,0,2,2,2,0,0,0,0,0,0,0,0,2,2,2,0,0,0
0,0,2,0,0,0,2,0,0,0,0,0,0,0,0,0,0,0,0,0,0,0,0,2,0,0,0,2,0,0
0,2,0,0,0,0,0,2,0,0,0,0,0,0,0,0,0,0,0,0,0,0,2,0,0,0,0,0,2,0
2,0,0,0,0,0,0,0,2,0,0,0,0,0,0,0,0,0,0,0,0,2,0,0,0,0,0,0,0,2
2,0,0,0,0,0,0,0,11,0,0,0,0,0,0,0,0,0,0,0,0,2,0,0,0,0,0,0,0,11
2,0,0,0,0,0,0,0,2,0,0,0,0,0,0,0,0,0,0,0,0,2,0,0,0,0,0,0,0,2
0,2,0,0,0,0,0,2,0,0,0,0,0,0,0,0,0,0,0,0,0,0,2,0,0,0,0,0,2,0
0,0,2,0,0,0,2,0,0,0,0,0,0,0,0,0,0,0,0,0,0,0,0,2,0,0,0,2,0,0
0,0,0,2,2,2,0,0,0,0,0,0,0,0,0,0,0,0,0,0,0,0,0,0,2,2,2,0,0,0
endlayer

layer
0,0,0,0,0,0,0,0,0,0,0,0,0,0,0,0,0,0,0,0,0,0,0,0,0,0,0,0,0,0
0,0,0,0,0,0,0,0,0,0,0,0,0,0,0,0,0,0,0,0,0,0,0,0,0,0,0,0,0,0
0,0,0,0,0,0,0,0,0,0,0,0,0,0,0,0,0,0,0,0,0,0,0,0,0,0,0,0,0,0
0,0,0,0,0,0,0,0,0,0,0,0,0,0,0,0,0,0,0,0,0,0,0,0,0,0,0,0,0,0
0,0,0,0,0,0,0,0,0,0,0,0,0,0,0,0,0,0,0,0,0,0,0,0,0,0,0,0,0,0
0,0,0,0,0,0,0,0,0,0,0,0,0,0,0,0,0,0,0,0,0,0,0,0,0,0,0,0,0,0
0,0,0,0,0,0,0,0,0,0,0,0,0,0,0,0,0,0,0,0,0,0,0,0,0,0,0,0,0,0
0,0,0,0,0,0,0,0,0,0,0,0,0,2,0,2,0,0,0,0,0,0,0,0,0,0,0,0,0,0
0,0,0,0,0,0,0,0,0,0,0,0,2,0,0,0,2,0,0,0,0,0,0,0,0,0,0,0,0,0
0,0,0,0,0,0,0,0,0,0,0,0,0,0,0,0,0,0,0,0,0,0,0,0,0,0,0,0,0,0
0,0,0,0,0,0,0,0,0,0,0,0,2,0,0,0,2,0,0,0,0,0,0,0,0,0,0,0,0,0
0,0,0,0,0,0,0,0,0,0,0,0,0,2,0,2,0,0,0,0,0,0,0,0,0,0,0,0,0,0
0,0,0,0,0,0,0,0,0,0,0,0,0,0,0,0,0,0,0,0,0,0,0,0,0,0,0,0,0,0
0,0,0,0,0,0,0,0,0,0,0,0,0,0,0,0,0,0,0,0,0,0,0,0,0,0,0,0,0,0
0,0,0,0,0,0,0,0,0,0,0,0,0,0,0,0,0,0,0,0,0,0,0,0,0,0,0,0,0,0
0,0,0,0,0,0,0,45,45,45,45,45,45,45,45,45,45,0,0,0,0,0,0,0,0,0,0,0,0,0
0,0,0,0,0,0,0,0,0,0,0,0,0,0,0,0,0,0,0,0,0,0,0,0,0,0,0,0,0,0
0,0,0,0,0,0,0,0,0,0,0,0,0,0,0,0,0,0,0,0,0,0,0,0,0,0,0,0,0,0
0,0,0,0,0,0,0,0,0,0,0,0,0,0,0,0,0,0,0,0,0,0,0,0,0,0,0,0,0,0
0,0,0,0,0,0,0,0,0,0,0,0,0,2,0,2,0,0,0,0,0,0,0,0,0,0,0,0,0,0
0,0,0,0,0,0,0,0,0,0,0,0,2,0,0,0,2,0,0,0,0,0,0,0,0,0,0,0,0,0
0,0,0,0,0,0,0,0,0,0,0,0,0,0,0,0,0,0,0,0,0,0,0,0,0,0,0,0,0,0
0,0,0,0,0,0,0,0,0,0,0,0,2,0,0,0,2,0,0,0,0,0,0,0,0,0,0,0,0,0
0,0,0,0,0,0,0,0,0,0,0,0,0,2,0,2,0,0,0,0,0,0,0,0,0,0,0,0,0,0
0,0,0,0,0,0,0,0,0,0,0,0,0,0,0,0,0,0,0,0,0,0,0,0,0,0,0,0,0,0
0,0,0,0,0,0,0,0,0,0,0,0,0,0,0,0,0,0,0,0,0,0,0,0,0,0,0,0,0,0
0,0,0,0,0,0,0,0,0,0,0,0,0,0,0,0,0,0,0,0,0,0,0,0,0,0,0,0,0,0
0,0,0,0,0,0,0,0,0,0,0,0,0,0,0,0,0,0,0,0,0,0,0,0,0,0,0,0,0,0
0,0,0,0,0,0,0,0,0,0,0,0,0,0,0,0,0,0,0,0,0,0,0,0,0,0,0,0,0,0
0,0,0,0,0,0,0,0,0,0,0,0,0,0,0,0,0,0,0,0,0,0,0,0,0,0,0,0,0,0
0,0,0,0,0,0,0,0,0,0,0,0,0,0,0,0,0,0,0,0,0,0,0,0,0,0,0,0,0,0
endlayer

layer
0,0,0,0,0,0,0,0,0,0,0,0,0,0,0,0,0,0,0,0,0,0,0,0,0,0,0,0,0,0
0,0,0,0,0,0,0,0,0,0,0,0,0,0,0,0,0,0,0,0,0,0,0,0,0,0,0,0,0,0
0,0,0,0,0,0,0,0,0,0,0,0,0,0,0,0,0,0,0,0,0,0,0,0,0,0,0,0,0,0
0,0,0,0,0,0,0,0,0,0,0,0,0,0,0,0,0,0,0,0,0,0,0,0,0,0,0,0,0,0
0,0,0,0,0,0,0,0,0,0,0,0,0,0,0,0,0,0,0,0,0,0,0,0,0,0,0,0,0,0
0,0,0,0,0,0,0,0,0,0,0,0,0,0,0,0,0,0,0,0,0,0,0,0,0,0,0,0,0,0
0,0,0,0,0,0,0,0,0,0,0,0,0,0,0,0,0,0,0,0,0,0,0,0,0,0,0,0,0,0
0,0,0,0,0,0,0,0,0,0,0,0,0,2,0,2,0,0,0,0,0,0,0,0,0,0,0,0,0,0
0,0,0,0,0,0,0,0,0,0,0,0,2,0,0,0,2,0,0,0,0,0,0,0,0,0,0,0,0,0
0,0,0,0,0,0,0,0,0,0,0,0,0,0,0,0,0,0,0,0,0,0,0,0,0,0,0,0,0,0
0,0,0,0,0,0,0,0,0,0,0,0,2,0,0,0,2,0,0,0,0,0,0,0,0,0,0,0,0,0
0,0,0,0,0,0,0,0,0,0,0,0,0,2,0,2,0,0,0,0,0,0,0,0,0,0,0,0,0,0
0,0,0,0,0,0,0,0,0,0,0,0,0,0,0,0,0,0,0,0,0,0,0,0,0,0,0,0,0,0
0,0,0,0,0,0,0,0,0,0,0,0,0,0,0,0,0,0,0,0,0,0,0,0,0,0,0,0,0,0
0,0,0,0,0,0,0,0,0,0,0,0,0,0,0,0,0,0,0,0,0,0,0,0,0,0,0,0,0,0
0,0,0,0,0,0,0,0,0,0,0,0,0,0,0,0,0,0,0,0,0,0,0,0,0,0,0,0,0,0
0,0,0,0,0,0,0,0,0,0,0,0,0,0,0,0,0,0,0,0,0,0,0,0,0,0,0,0,0,0
0,0,0,0,0,0,0,0,0,0,0,0,0,0,0,0,0,0,0,0,0,0,0,0,0,0,0,0,0,0
0,0,0,0,0,0,0,0,0,0,0,0,0,0,0,0,0,0,0,0,0,0,0,0,0,0,0,0,0,0
0,0,0,0,0,0,0,0,0,0,0,0,0,2,0,2,0,0,0,0,0,0,0,0,0,0,0,0,0,0
0,0,0,0,0,0,0,0,0,0,0,0,2,0,0,0,2,0,0,0,0,0,0,0,0,0,0,0,0,0
0,0,0,0,0,0,0,0,0,0,0,0,0,0,0,0,0,0,0,0,0,0,0,0,0,0,0,0,0,0
0,0,0,0,0,0,0,0,0,0,0,0,2,0,0,0,2,0,0,0,0,0,0,0,0,0,0,0,0,0
0,0,0,0,0,0,0,0,0,0,0,0,0,2,0,2,0,0,0,0,0,0,0,0,0,0,0,0,0,0
0,0,0,0,0,0,0,0,0,0,0,0,0,0,0,0,0,0,0,0,0,0,0,0,0,0,0,0,0,0
0,0,0,0,0,0,0,0,0,0,0,0,0,0,0,0,0,0,0,0,0,0,0,0,0,0,0,0,0,0
0,0,0,0,0,0,0,0,0,0,0,0,0,0,0,0,0,0,0,0,0,0,0,0,0,0,0,0,0,0
0,0,0,0,0,0,0,0,0,0,0,0,0,0,0,0,0,0,0,0,0,0,0,0,0,0,0,0,0,0
0,0,0,0,0,0,0,0,0,0,0,0,0,0,0,0,0,0,0,0,0,0,0,0,0,0,0,0,0,0
0,0,0,0,0,0,0,0,0,0,0,0,0,0,0,0,0,0,0,0,0,0,0,0,0,0,0,0,0,0
0,0,0,0,0,0,0,0,0,0,0,0,0,0,0,0,0,0,0,0,0,0,0,0,0,0,0,0,0,0
endlayer

layer
0,0,0,0,0,0,0,0,0,0,0,0,0,0,0,0,0,0,0,0,0,0,0,0,0,0,0,0,0,0
0,0,0,0,0,0,0,0,0,0,0,0,0,0,0,0,0,0,0,0,0,0,0,0,0,0,0,0,0,0
0,0,0,0,0,0,0,0,0,0,0,0,0,0,0,0,0,0,0,0,0,0,0,0,0,0,0,0,0,0
0,0,0,0,0,0,0,0,0,0,0,0,0,0,0,0,0,0,0,0,0,0,0,0,0,0,0,0,0,0
0,0,0,0,0,0,0,0,0,0,0,0,0,0,0,0,0,0,0,0,0,0,0,0,0,0,0,0,0,0
0,0,0,0,0,0,0,0,0,0,0,0,0,0,0,0,0,0,0,0,0,0,0,0,0,0,0,0,0,0
0,0,0,0,0,0,0,0,0,0,0,0,0,0,0,0,0,0,0,0,0,0,0,0,0,0,0,0,0,0
0,0,0,0,0,0,0,0,0,0,0,0,0,2,2,2,0,0,0,0,0,0,0,0,0,0,0,0,0,0
0,0,0,0,0,0,0,0,0,0,0,0,2,0,0,0,2,0,0,0,0,0,0,0,0,0,0,0,0,0
0,0,0,0,0,0,0,0,0,0,0,0,2,0,0,0,2,0,0,0,0,0,0,0,0,0,0,0,0,0
0,0,0,0,0,0,0,0,0,0,0,0,2,0,0,0,2,0,0,0,0,0,0,0,0,0,0,0,0,0
0,0,0,0,0,0,0,0,0,0,0,0,0,2,2,2,0,0,0,0,0,0,0,0,0,0,0,0,0,0
0,0,0,0,0,0,0,0,0,0,0,0,0,0,0,0,0,0,0,0,0,0,0,0,0,0,0,0,0,0
0,0,0,0,0,0,0,0,0,0,0,0,0,0,0,0,0,0,0,0,0,0,0,0,0,0,0,0,0,0
0,0,0,0,0,0,0,0,0,0,0,0,0,0,0,0,0,0,0,0,0,0,0,0,0,0,0,0,0,0
0,0,0,0,0,0,0,0,0,0,0,0,0,0,0,0,0,0,0,0,0,0,0,0,0,0,0,0,0,0
0,0,0,0,0,0,0,0,0,0,0,0,0,0,0,0,0,0,0,0,0,0,0,0,0,0,0,0,0,0
0,0,0,0,0,0,0,0,0,0,0,0,0,0,0,0,0,0,0,0,0,0,0,0,0,0,0,0,0,0
0,0,0,0,0,0,0,0,0,0,0,0,0,0,0,0,0,0,0,0,0,0,0,0,0,0,0,0,0,0
0,0,0,0,0,0,0,0,0,0,0,0,0,2,2,2,0,0,0,0,0,0,0,0,0,0,0,0,0,0
0,0,0,0,0,0,0,0,0,0,0,0,2,0,0,0,2,0,0,0,0,0,0,0,0,0,0,0,0,0
0,0,0,0,0,0,0,0,0,0,0,0,2,0,0,0,2,0,0,0,0,0,0,0,0,0,0,0,0,0
0,0,0,0,0,0,0,0,0,0,0,0,2,0,0,0,2,0,0,0,0,0,0,0,0,0,0,0,0,0
0,0,0,0,0,0,0,0,0,0,0,0,0,2,2,2,0,0,0,0,0,0,0,0,0,0,0,0,0,0
0,0,0,0,0,0,0,0,0,0,0,0,0,0,0,0,0,0,0,0,0,0,0,0,0,0,0,0,0,0
0,0,0,0,0,0,0,0,0,0,0,0,0,0,0,0,0,0,0,0,0,0,0,0,0,0,0,0,0,0
0,0,0,0,0,0,0,0,0,0,0,0,0,0,0,0,0,0,0,0,0,0,0,0,0,0,0,0,0,0
0,0,0,0,0,0,0,0,0,0,0,0,0,0,0,0,0,0,0,0,0,0,0,0,0,0,0,0,0,0
0,0,0,0,0,0,0,0,0,0,0,0,0,0,0,0,0,0,0,0,0,0,0,0,0,0,0,0,0,0
0,0,0,0,0,0,0,0,0,0,0,0,0,0,0,0,0,0,0,0,0,0,0,0,0,0,0,0,0,0
0,0,0,0,0,0,0,0,0,0,0,0,0,0,0,0,0,0,0,0,0,0,0,0,0,0,0,0,0,0
endlayer

layer
0,0,0,0,0,0,0,0,0,0,0,0,0,0,0,0,0,0,0,0,0,0,0,0,0,0,0,0,0,0
0,0,0,0,0,0,0,0,0,0,0,0,0,0,0,0,0,0,0,0,0,0,0,0,0,0,0,0,0,0
0,0,0,0,0,0,0,0,0,0,0,0,0,0,0,0,0,0,0,0,0,0,0,0,0,0,0,0,0,0
0,0,0,0,0,0,0,0,0,0,0,0,0,0,0,0,0,0,0,0,0,0,0,0,0,0,0,0,0,0
0,0,0,0,0,0,0,0,0,0,0,0,0,0,0,0,0,0,0,0,0,0,0,0,0,0,0,0,0,0
0,0,0,0,0,0,0,0,0,0,0,0,0,0,0,0,0,0,0,0,0,0,0,0,0,0,0,0,0,0
0,0,0,0,0,0,0,0,0,0,0,0,0,0,0,0,0,0,0,0,0,0,0,0,0,0,0,0,0,0
0,0,0,0,0,0,0,0,0,0,0,0,0,11,11,11,0,0,0,0,0,0,0,0,0,0,0,0,0,0
0,0,0,0,0,0,0,0,0,0,0,0,11,0,0,0,11,0,0,0,0,0,0,0,0,0,0,0,0,0
0,0,0,0,0,0,0,0,0,0,0,0,11,0,0,0,11,0,0,0,0,0,0,0,0,0,0,0,0,0
0,0,0,0,0,0,0,0,0,0,0,0,11,0,0,0,11,0,0,0,0,0,0,0,0,0,0,0,0,0
0,0,0,0,0,0,0,0,0,0,0,0,0,11,11,11,0,0,0,0,0,0,0,0,0,0,0,0,0,0
0,0,0,0,0,0,0,0,0,0,0,0,0,0,0,0,0,0,0,0,0,0,0,0,0,0,0,0,0,0
0,0,0,0,0,0,0,0,0,0,0,0,0,0,0,0,0,0,0,0,0,0,0,0,0,0,0,0,0,0
0,0,0,0,0,0,0,0,0,0,0,0,0,0,0,0,0,0,0,0,0,0,0,0,0,0,0,0,0,0
0,0,0,0,0,0,0,0,0,0,0,0,0,0,0,0,0,0,0,0,0,0,0,0,0,0,0,0,0,0
0,0,0,0,0,0,0,0,0,0,0,0,0,0,0,0,0,0,0,0,0,0,0,0,0,0,0,0,0,0
0,0,0,0,0,0,0,0,0,0,0,0,0,0,0,0,0,0,0,0,0,0,0,0,0,0,0,0,0,0
0,0,0,0,0,0,0,0,0,0,0,0,0,0,0,0,0,0,0,0,0,0,0,0,0,0,0,0,0,0
0,0,0,0,0,0,0,0,0,0,0,0,0,11,11,11,0,0,0,0,0,0,0,0,0,0,0,0,0,0
0,0,0,0,0,0,0,0,0,0,0,0,11,0,0,0,11,0,0,0,0,0,0,0,0,0,0,0,0,0
0,0,0,0,0,0,0,0,0,0,0,0,11,0,0,0,11,0,0,0,0,0,0,0,0,0,0,0,0,0
0,0,0,0,0,0,0,0,0,0,0,0,11,0,0,0,11,0,0,0,0,0,0,0,0,0,0,0,0,0
0,0,0,0,0,0,0,0,0,0,0,0,0,11,11,11,0,0,0,0,0,0,0,0,0,0,0,0,0,0
0,0,0,0,0,0,0,0,0,0,0,0,0,0,0,0,0,0,0,0,0,0,0,0,0,0,0,0,0,0
0,0,0,0,0,0,0,0,0,0,0,0,0,0,0,0,0,0,0,0,0,0,0,0,0,0,0,0,0,0
0,0,0,0,0,0,0,0,0,0,0,0,0,0,0,0,0,0,0,0,0,0,0,0,0,0,0,0,0,0
0,0,0,0,0,0,0,0,0,0,0,0,0,0,0,0,0,0,0,0,0,0,0,0,0,0,0,0,0,0
0,0,0,0,0,0,0,0,0,0,0,0,0,0,0,0,0,0,0,0,0,0,0,0,0,0,0,0,0,0
0,0,0,0,0,0,0,0,0,0,0,0,0,0,0,0,0,0,0,0,0,0,0,0,0,0,0,0,0,0
0,0,0,0,0,0,0,0,0,0,0,0,0,0,0,0,0,0,0,0,0,0,0,0,0,0,0,0,0,0
endlayer

layer
0,0,0,0,0,0,0,0,0,0,0,0,0,0,0,0,0,0,0,0,0,0,0,0,0,0,0,0,0,0
0,0,0,0,0,0,0,0,0,0,0,0,0,0,0,0,0,0,0,0,0,0,0,0,0,0,0,0,0,0
0,0,0,0,0,0,0,0,0,0,0,0,0,0,0,0,0,0,0,0,0,0,0,0,0,0,0,0,0,0
0,0,0,0,0,0,0,0,0,0,0,0,0,0,0,0,0,0,0,0,0,0,0,0,0,0,0,0,0,0
0,0,0,0,0,0,0,0,0,0,0,0,0,0,0,0,0,0,0,0,0,0,0,0,0,0,0,0,0,0
0,0,0,0,0,0,0,0,0,0,0,0,0,0,0,0,0,0,0,0,0,0,0,0,0,0,0,0,0,0
0,0,0,0,0,0,0,0,0,0,0,0,0,0,0,0,0,0,0,0,0,0,0,0,0,0,0,0,0,0
0,0,0,0,0,0,0,0,0,0,0,0,0,11,0,11,0,0,0,0,0,0,0,0,0,0,0,0,0,0
0,0,0,0,0,0,0,0,0,0,0,0,11,0,0,0,11,0,0,0,0,0,0,0,0,0,0,0,0,0
0,0,0,0,0,0,0,0,0,0,0,0,0,0,0,0,0,0,0,0,0,0,0,0,0,0,0,0,0,0
0,0,0,0,0,0,0,0,0,0,0,0,11,0,0,0,11,0,0,0,0,0,0,0,0,0,0,0,0,0
0,0,0,0,0,0,0,0,0,0,0,0,0,11,0,11,0,0,0,0,0,0,0,0,0,0,0,0,0,0
0,0,0,0,0,0,0,0,0,0,0,0,0,0,0,0,0,0,0,0,0,0,0,0,0,0,0,0,0,0
0,0,0,0,0,0,0,0,0,0,0,0,0,0,0,0,0,0,0,0,0,0,0,0,0,0,0,0,0,0
0,0,0,0,0,0,0,0,0,0,0,0,0,0,0,0,0,0,0,0,0,0,0,0,0,0,0,0,0,0
0,0,0,0,0,0,0,0,0,0,0,0,0,0,0,0,0,0,0,0,0,0,0,0,0,0,0,0,0,0
0,0,0,0,0,0,0,0,0,0,0,0,0,0,0,0,0,0,0,0,0,0,0,0,0,0,0,0,0,0
0,0,0,0,0,0,0,0,0,0,0,0,0,0,0,0,0,0,0,0,0,0,0,0,0,0,0,0,0,0
0,0,0,0,0,0,0,0,0,0,0,0,0,0,0,0,0,0,0,0,0,0,0,0,0,0,0,0,0,0
0,0,0,0,0,0,0,0,0,0,0,0,0,11,0,11,0,0,0,0,0,0,0,0,0,0,0,0,0,0
0,0,0,0,0,0,0,0,0,0,0,0,11,0,0,0,11,0,0,0,0,0,0,0,0,0,0,0,0,0
0,0,0,0,0,0,0,0,0,0,0,0,0,0,0,0,0,0,0,0,0,0,0,0,0,0,0,0,0,0
0,0,0,0,0,0,0,0,0,0,0,0,11,0,0,0,11,0,0,0,0,0,0,0,0,0,0,0,0,0
0,0,0,0,0,0,0,0,0,0,0,0,0,11,0,11,0,0,0,0,0,0,0,0,0,0,0,0,0,0
0,0,0,0,0,0,0,0,0,0,0,0,0,0,0,0,0,0,0,0,0,0,0,0,0,0,0,0,0,0
0,0,0,0,0,0,0,0,0,0,0,0,0,0,0,0,0,0,0,0,0,0,0,0,0,0,0,0,0,0
0,0,0,0,0,0,0,0,0,0,0,0,0,0,0,0,0,0,0,0,0,0,0,0,0,0,0,0,0,0
0,0,0,0,0,0,0,0,0,0,0,0,0,0,0,0,0,0,0,0,0,0,0,0,0,0,0,0,0,0
0,0,0,0,0,0,0,0,0,0,0,0,0,0,0,0,0,0,0,0,0,0,0,0,0,0,0,0,0,0
0,0,0,0,0,0,0,0,0,0,0,0,0,0,0,0,0,0,0,0,0,0,0,0,0,0,0,0,0,0
0,0,0,0,0,0,0,0,0,0,0,0,0,0,0,0,0,0,0,0,0,0,0,0,0,0,0,0,0,0
endlayer

layer
0,0,0,0,0,0,0,0,0,0,0,0,0,0,0,0,0,0,0,0,0,0,0,0,0,0,0,0,0,0
0,0,0,0,0,0,0,0,0,0,0,0,0,0,0,0,0,0,0,0,0,0,0,0,0,0,0,0,0,0
0,0,0,0,0,0,0,0,0,0,0,0,0,0,0,0,0,0,0,0,0,0,0,0,0,0,0,0,0,0
0,0,0,0,0,0,0,0,0,0,0,0,0,0,0,0,0,0,0,0,0,0,0,0,0,0,0,0,0,0
0,0,0,0,0,0,0,0,0,0,0,0,0,0,0,0,0,0,0,0,0,0,0,0,0,0,0,0,0,0
0,0,0,0,0,0,0,0,0,0,0,0,0,0,0,0,0,0,0,0,0,0,0,0,0,0,0,0,0,0
0,0,0,0,0,0,0,0,0,0,0,0,0,0,0,0,0,0,0,0,0,0,0,0,0,0,0,0,0,0
0,0,0,0,0,0,0,0,0,0,0,0,0,2,0,2,0,0,0,0,0,0,0,0,0,0,0,0,0,0
0,0,0,0,0,0,0,0,0,0,0,0,2,0,0,0,2,0,0,0,0,0,0,0,0,0,0,0,0,0
0,0,0,0,0,0,0,0,0,0,0,0,0,0,0,0,0,0,0,0,0,0,0,0,0,0,0,0,0,0
0,0,0,0,0,0,0,0,0,0,0,0,2,0,0,0,2,0,0,0,0,0,0,0,0,0,0,0,0,0
0,0,0,0,0,0,0,0,0,0,0,0,0,2,0,2,0,0,0,0,0,0,0,0,0,0,0,0,0,0
0,0,0,0,0,0,0,0,0,0,0,0,0,0,0,0,0,0,0,0,0,0,0,0,0,0,0,0,0,0
0,0,0,0,0,0,0,0,0,0,0,0,0,0,0,0,0,0,0,0,0,0,0,0,0,0,0,0,0,0
0,0,0,0,0,0,0,0,0,0,0,0,0,0,0,0,0,0,0,0,0,0,0,0,0,0,0,0,0,0
0,0,0,0,0,0,0,0,0,0,0,0,0,0,0,0,0,0,0,0,0,0,0,0,0,0,0,0,0,0
0,0,0,0,0,0,0,0,0,0,0,0,0,0,0,0,0,0,0,0,0,0,0,0,0,0,0,0,0,0
0,0,0,0,0,0,0,0,0,0,0,0,0,0,0,0,0,0,0,0,0,0,0,0,0,0,0,0,0,0
0,0,0,0,0,0,0,0,0,0,0,0,0,0,0,0,0,0,0,0,0,0,0,0,0,0,0,0,0,0
0,0,0,0,0,0,0,0,0,0,0,0,0,2,0,2,0,0,0,0,0,0,0,0,0,0,0,0,0,0
0,0,0,0,0,0,0,0,0,0,0,0,2,0,0,0,2,0,0,0,0,0,0,0,0,0,0,0,0,0
0,0,0,0,0,0,0,0,0,0,0,0,0,0,0,0,0,0,0,0,0,0,0,0,0,0,0,0,0,0
0,0,0,0,0,0,0,0,0,0,0,0,2,0,0,0,2,0,0,0,0,0,0,0,0,0,0,0,0,0
0,0,0,0,0,0,0,0,0,0,0,0,0,2,0,2,0,0,0,0,0,0,0,0,0,0,0,0,0,0
0,0,0,0,0,0,0,0,0,0,0,0,0,0,0,0,0,0,0,0,0,0,0,0,0,0,0,0,0,0
0,0,0,0,0,0,0,0,0,0,0,0,0,0,0,0,0,0,0,0,0,0,0,0,0,0,0,0,0,0
0,0,0,0,0,0,0,0,0,0,0,0,0,0,0,0,0,0,0,0,0,0,0,0,0,0,0,0,0,0
0,0,0,0,0,0,0,0,0,0,0,0,0,0,0,0,0,0,0,0,0,0,0,0,0,0,0,0,0,0
0,0,0,0,0,0,0,0,0,0,0,0,0,0,0,0,0,0,0,0,0,0,0,0,0,0,0,0,0,0
0,0,0,0,0,0,0,0,0,0,0,0,0,0,0,0,0,0,0,0,0,0,0,0,0,0,0,0,0,0
0,0,0,0,0,0,0,0,0,0,0,0,0,0,0,0,0,0,0,0,0,0,0,0,0,0,0,0,0,0
endlayer

