# Author: Arrrg
# From: Minecraft Forums

weight=4
embed_into_distance=22
acceptable_target_blocks=1,2,3,12,13,24,78
dimensions=29,5,5
allowable_overhang=10
unique=0
max_cut_in=0
cut_in_buffer=0
max_leveling=0
leveling_buffer=0
preserve_water=0
preserve_lava=0
preserve_plants=1

rule1=0,100,preserveBlock
rule2=0,100,44-3
rule3=0,100,50
rule4=0,100,4,48,48
rule5=0,100,17
rule6=0,100,67-0
rule7=0,100,67-1
rule8=0,100,8
rule9=0,100,20
rule10=0,100,10
rule11=0,100,65-2
rule12=0,100,65-3
rule13=0,100,13
rule14=0,100,14
rule15=0,100,65-4
rule16=0,100,65-5

layer
1,4,4,4,1
4,4,4,4,4
4,4,4,4,4
4,4,4,4,4
1,4,4,4,1
endlayer
 
layer
1,4,4,4,1
4,0,0,0,4
3,0,0,0,3
4,0,0,0,4
1,4,4,4,1
endlayer
 
layer
1,4,4,4,1
4,14,14,14,4
13,14,0,14,13
4,14,14,14,4
0,4,4,4,1
endlayer
 
layer
1,4,4,4,1
4,0,0,0,4
13,0,14,0,13
4,0,0,0,4
1,4,4,4,1
endlayer
 
layer
1,4,4,9,3
4,8,0,0,4
13,11,0,12,13
4,0,0,8,4
3,9,4,4,1
endlayer
 
layer
1,4,4,4,1
4,0,0,0,4
13,11,0,12,13
4,0,0,0,4
1,4,4,4,1
endlayer
 
layer
1,1,1,1,1
1,0,0,0,1
13,11,0,12,13
1,0,0,0,1
1,1,1,1,1
endlayer
 
layer
1,1,1,1,1
1,0,0,0,1
13,11,0,12,13
1,0,0,0,1
1,1,1,1,1
endlayer
 
layer
1,1,1,1,1
1,0,0,0,1
13,11,0,12,13
1,0,0,0,1
1,1,1,1,1
endlayer
 
layer
1,1,1,1,1
1,0,0,0,1
13,11,0,12,13
1,0,0,0,1
1,1,1,1,1
endlayer
 
layer
1,1,1,1,1
1,0,0,0,1
13,11,0,12,13
1,0,0,0,1
1,1,1,1,1
endlayer
 
layer
1,1,1,1,1
1,0,0,0,1
13,11,0,12,13
1,0,0,0,1
1,1,1,1,1
endlayer
 
layer
1,1,1,1,1
1,0,0,0,1
13,11,0,12,13
1,0,0,0,1
1,1,1,1,1
endlayer
 
layer
1,1,1,1,1
1,0,0,0,1
13,11,0,12,13
1,0,0,0,1
1,1,1,1,1
endlayer
 
layer
1,1,1,1,1
1,0,0,0,1
13,11,0,12,13
1,0,0,0,1
1,1,1,1,1
endlayer
 
layer
1,1,1,1,1
1,0,0,0,1
13,11,0,12,13
1,0,0,0,1
1,1,1,1,1
endlayer
 
layer
1,1,1,1,1
1,0,0,0,1
13,11,0,12,13
1,0,0,0,1
1,1,1,1,1
endlayer
 
layer
1,1,1,1,1
1,0,0,0,1
13,11,0,12,13
1,0,0,0,1
1,1,1,1,1
endlayer
 
layer
1,1,1,1,1
15,0,0,0,1
13,11,0,12,13
1,0,0,0,16
1,1,1,1,1
endlayer
 
layer
1,4,4,4,1
13,0,0,0,4
4,11,0,12,4
13,0,0,0,13
1,4,4,4,1
endlayer
 
layer
1,4,4,4,1
13,0,0,0,13
16,0,0,0,15
13,0,0,0,13
1,4,4,4,1
endlayer
 
layer
1,4,4,4,1
4,0,0,0,4
13,11,0,12,13
4,0,0,0,4
1,4,4,4,1
endlayer
 
layer
1,4,4,4,1
4,0,0,0,4
13,11,0,12,13
4,0,0,0,4
1,4,4,4,1
endlayer
 
layer
0,0,0,0,0
0,0,0,0,0
13,11,0,12,13
0,0,0,0,0
0,0,0,0,0
endlayer
 
layer
0,0,0,0,0
0,0,0,0,0
13,11,0,12,13
0,0,0,0,0
0,0,0,0,0
endlayer
 
layer
0,0,0,0,0
0,0,0,0,0
13,11,0,12,13
0,0,0,0,0
0,0,0,0,0
endlayer
 
layer
6,6,6,6,6
4,4,4,4,4
4,13,9,13,4
4,4,4,4,4
7,7,7,7,7
endlayer
 
layer
0,0,0,0,0
6,6,6,6,6
4,13,10,13,4
7,7,7,7,7
0,0,0,0,0
endlayer

layer
0,0,0,0,0
0,0,0,0,0
2,2,2,2,2
0,0,0,0,0
0,0,0,0,0
endlayer
