# Monolith
# Author: Arrrg
# From: Minecraft Forums

weight=1
embed_into_distance=58
acceptable_target_blocks=1,2,3,12,13,78
dimensions=75,5,7
allowable_overhang=300
unique=0
max_cut_in=10
cut_in_buffer=1
max_leveling=5
leveling_buffer=0
preserve_water=0
preserve_lava=0
preserve_plants=0

rule1=0,100,preserveBlock
rule2=0,100,21,preserveBlock,preserveBlock,preserveBlock
rule3=0,100,56,preserveBlock,preserveBlock,preserveBlock
rule4=0,100,14,preserveBlock,preserveBlock
rule5=0,100,15,preserveBlock
rule6=0,100,16,preserveBlock,preserveBlock,preserveBlock
rule7=0,100,49
rule8=0,100,8
rule9=1,100,9
rule10=1,100,10
rule11=0,100,11
rule12=0,100,12


layer
1,1,1,1,1,1,1
1,1,1,1,1,1,1
1,1,1,1,1,1,1
1,1,1,1,1,3,1
1,1,1,1,1,1,1
endlayer

layer
1,1,1,1,1,1,1
1,1,1,1,1,1,1
1,1,1,1,1,1,1
1,1,1,1,1,3,1
1,1,1,1,1,1,1
endlayer

layer
1,1,1,1,1,1,1
1,2,1,1,1,1,1
1,1,1,1,1,3,1
1,1,1,1,3,3,3
1,1,1,1,1,3,1
endlayer

layer
1,1,1,1,1,1,1
1,2,1,1,1,1,1
1,1,1,1,1,3,1
1,1,1,1,3,3,3
1,1,1,1,1,3,1
endlayer

layer
1,2,1,1,1,1,1
2,2,2,1,4,1,1
1,2,1,1,3,3,3
1,1,1,1,3,3,3
1,1,1,1,3,3,3
endlayer

layer
1,2,1,1,1,1,1
2,2,2,1,4,1,1
1,2,1,1,3,3,3
1,1,1,1,3,3,3
1,1,1,1,3,3,3
endlayer

layer
2,2,2,1,4,1,1
2,2,2,4,4,4,1
2,2,2,1,4,3,1
1,1,1,1,3,3,3
1,1,1,1,1,3,1
endlayer

layer
2,2,2,1,4,1,1
2,2,2,4,4,4,1
2,2,2,1,4,3,1
1,1,1,1,3,3,3
1,1,1,1,1,3,1
endlayer

layer
1,2,1,4,4,4,1
2,2,2,4,4,4,1
1,2,4,4,4,4,1
1,4,4,4,1,3,1
1,1,4,1,1,1,1
endlayer

layer
1,2,1,4,4,4,1
2,2,2,4,4,4,1
1,2,4,4,4,4,1
1,4,4,4,1,5,1
1,1,4,1,1,1,1
endlayer

layer
1,1,1,1,4,1,1
1,2,1,4,4,4,1
1,4,4,4,4,5,1
1,4,4,4,5,5,5
1,4,4,4,1,5,1
endlayer

layer
1,1,1,1,4,1,1
1,5,1,4,4,4,1
1,4,4,4,4,5,1
1,4,4,4,5,5,5
1,4,4,4,1,5,1
endlayer

layer
1,5,1,1,1,1,1
5,5,5,1,4,1,1
1,5,4,1,5,5,5
1,4,4,4,5,5,5
1,1,4,1,5,5,5
endlayer

layer
1,5,1,1,1,1,1
5,5,5,1,6,1,1
1,5,4,1,5,5,5
1,4,4,4,5,5,5
1,1,4,1,5,5,5
endlayer

layer
5,5,5,1,6,1,1
5,5,5,6,6,6,1
5,5,5,1,6,5,1
1,1,4,1,5,5,5
1,1,1,1,1,5,1
endlayer

layer
5,5,5,1,6,1,1
5,5,5,6,6,6,1
5,5,5,1,6,5,1
1,1,6,1,5,5,5
1,1,1,1,1,5,1
endlayer

layer
1,5,1,6,6,6,1
5,5,5,6,6,6,1
1,5,6,6,6,6,1
1,6,6,6,1,5,1
1,1,6,1,1,1,1
endlayer

layer
1,5,1,6,6,6,1
5,5,5,6,6,6,1
1,5,6,6,6,6,1
1,6,6,6,1,5,1
1,1,6,1,1,1,1
endlayer

layer
1,1,1,1,6,1,1
1,5,1,6,6,6,1
1,1,1,1,6,1,1
1,1,6,1,1,1,1
1,1,1,1,1,1,1
endlayer

layer
1,1,1,1,6,1,1
1,5,1,6,6,6,1
1,1,1,1,6,1,1
1,1,6,1,1,1,1
1,1,1,1,1,1,1
endlayer

layer
1,1,1,1,1,1,1
1,1,1,1,6,1,1
1,1,1,1,1,1,1
1,1,1,1,1,1,1
1,1,1,1,1,1,1
endlayer

layer
1,1,1,1,1,1,1
1,1,1,1,6,1,1
1,1,1,1,1,1,1
1,1,1,1,1,1,1
1,1,1,1,1,1,1
endlayer

layer
1,1,1,1,1,1,1
1,1,1,1,1,1,1
1,1,1,1,1,1,1
1,1,1,1,1,1,1
1,1,1,1,1,1,1
endlayer

layer
1,1,1,1,1,1,1
1,1,1,1,1,1,1
1,1,1,1,1,1,1
1,1,1,1,1,1,1
1,1,1,1,1,1,1
endlayer

layer
1,1,1,1,1,1,1
1,1,1,1,1,1,1
1,1,1,1,1,1,1
1,1,1,1,1,1,1
1,1,1,1,1,1,1
endlayer

layer
1,1,1,1,1,1,1
1,1,1,1,1,1,1
1,1,1,1,1,1,1
1,1,1,1,1,1,1
1,1,1,1,1,1,1
endlayer

layer
1,1,1,1,1,1,1
1,1,1,1,1,1,1
1,1,1,1,1,1,1
1,1,1,1,1,1,1
1,1,1,1,1,1,1
endlayer

layer
1,1,1,1,1,1,1
1,1,1,1,1,1,1
1,1,1,1,1,1,1
1,1,1,1,1,1,1
1,1,1,1,1,1,1
endlayer

layer
1,1,1,1,1,1,1
1,1,1,1,1,1,1
1,1,1,1,1,1,1
1,1,1,1,1,1,1
1,1,1,1,1,1,1
endlayer

layer
1,1,1,1,1,1,1
1,1,1,1,1,1,1
1,1,1,1,1,1,1
1,1,1,1,1,1,1
1,1,1,1,1,1,1
endlayer

layer
1,1,1,1,1,1,1
1,1,1,1,1,1,1
1,1,1,1,1,1,1
1,1,1,1,1,1,1
1,1,1,1,1,1,1
endlayer

layer
1,1,1,1,1,1,1
1,1,1,1,1,1,1
1,1,1,1,1,1,1
1,1,1,1,1,1,1
1,1,1,1,1,1,1
endlayer

layer
1,1,1,1,1,1,1
1,1,1,1,1,1,1
1,1,1,1,1,1,1
1,1,1,1,1,1,1
1,1,1,1,1,1,1
endlayer

layer
1,1,1,1,1,1,1
1,1,1,1,1,1,1
1,1,1,1,1,1,1
1,1,1,1,1,1,1
1,1,1,1,1,1,1
endlayer

layer
1,1,1,1,1,1,1
1,1,1,1,1,1,1
1,1,1,1,1,1,1
1,1,1,1,1,1,1
1,1,1,1,1,1,1
endlayer

layer
1,1,1,1,1,1,1
1,1,1,1,1,1,1
1,1,1,1,1,1,1
1,1,1,1,1,1,1
1,1,1,1,1,1,1
endlayer

layer
1,1,1,1,1,1,1
1,1,1,1,1,1,1
1,1,1,1,1,1,1
1,1,1,1,1,1,1
1,1,1,1,1,1,1
endlayer

layer
1,1,1,1,1,1,1
1,1,1,1,1,1,1
1,1,1,1,1,1,1
1,1,1,1,1,1,1
1,1,1,1,1,1,1
endlayer

layer
1,1,1,1,1,1,1
1,1,1,1,1,1,1
1,1,1,1,1,1,1
1,1,1,1,1,1,1
1,1,1,1,1,1,1
endlayer

layer
1,1,1,1,1,1,1
1,1,1,1,1,1,1
1,1,1,1,1,1,1
1,1,1,1,1,1,1
1,1,1,1,1,1,1
endlayer

layer
1,1,1,1,1,1,1
1,1,1,1,1,1,1
1,1,1,1,1,1,1
1,1,1,1,1,1,1
1,1,1,1,1,1,1
endlayer

layer
1,1,1,1,1,1,1
1,1,1,1,1,1,1
1,1,1,1,1,1,1
1,1,1,1,1,1,1
1,1,1,1,1,1,1
endlayer

layer
1,1,1,1,1,1,1
1,1,1,1,1,1,1
1,1,1,1,1,1,1
1,1,1,1,1,1,1
1,1,1,1,1,1,1
endlayer

layer
1,1,1,1,1,1,1
1,1,1,1,1,1,1
1,1,1,1,1,1,1
1,1,1,1,1,1,1
1,1,1,1,1,1,1
endlayer

layer
1,1,1,1,1,1,1
1,1,1,1,1,1,1
1,1,1,1,1,1,1
1,1,1,1,1,1,1
1,1,1,1,1,1,1
endlayer

layer
1,1,1,1,1,1,1
1,1,1,1,1,1,1
1,1,1,1,1,1,1
1,1,1,1,1,1,1
1,1,1,1,1,1,1
endlayer

layer
1,1,1,1,1,1,1
1,1,1,1,1,1,1
1,1,1,1,1,1,1
1,1,1,1,1,1,1
1,1,1,1,1,1,1
endlayer

layer
1,1,1,1,1,1,1
1,1,1,1,1,1,1
1,1,1,1,1,1,1
1,1,1,1,1,1,1
1,1,1,1,1,1,1
endlayer

layer
1,1,1,1,1,1,1
1,1,1,1,1,1,1
1,1,1,1,1,1,1
1,1,1,1,1,1,1
1,1,1,1,1,1,1
endlayer

layer
1,1,1,1,1,1,1
1,1,1,1,1,1,1
1,1,1,1,1,1,1
1,1,1,1,1,1,1
1,1,1,1,1,1,1
endlayer

layer
1,1,1,1,1,1,1
1,1,1,1,1,1,1
1,1,1,1,1,1,1
1,1,1,1,1,1,1
1,1,1,1,1,1,1
endlayer

layer
1,1,1,1,1,1,1
1,1,1,1,1,1,1
1,1,1,1,1,1,1
1,1,1,1,1,1,1
1,1,1,1,1,1,1
endlayer

layer
1,1,1,1,1,1,1
1,1,1,1,1,1,1
1,1,1,1,1,1,1
1,1,1,1,1,1,1
1,1,1,1,1,1,1
endlayer

layer
1,1,1,1,1,1,1
1,1,1,1,1,1,1
1,1,1,1,1,1,1
1,1,1,1,1,1,1
1,1,1,1,1,1,1
endlayer

layer
1,1,1,1,1,1,1
1,1,1,1,1,1,1
1,1,1,1,1,1,1
1,1,1,1,1,1,1
1,1,1,1,1,1,1
endlayer

layer
1,1,1,1,1,1,1
1,1,1,1,1,1,1
1,1,1,1,1,1,1
1,1,1,1,1,1,1
1,1,1,1,1,1,1
endlayer

layer
1,1,1,1,1,1,1
1,1,1,1,1,1,1
1,1,1,1,1,1,1
1,1,1,1,1,1,1
1,1,1,1,1,1,1
endlayer

layer
1,1,1,1,1,1,1
1,1,1,1,1,1,1
1,1,1,1,1,1,1
1,1,1,1,1,1,1
1,1,1,1,1,1,1
endlayer

layer
1,1,1,1,1,1,1
1,1,1,1,1,1,1
1,1,1,1,1,1,1
1,1,1,1,1,1,1
1,1,1,1,1,1,1
endlayer

layer
1,1,1,1,1,1,1
1,1,1,1,1,1,1
1,1,1,1,1,1,1
1,1,1,1,1,1,1
1,1,1,1,1,1,1
endlayer

layer
1,1,1,1,1,1,1
1,1,1,1,1,1,1
1,1,1,1,1,1,1
1,1,1,1,1,1,1
1,1,1,1,1,1,1
endlayer

layer
1,1,1,1,1,1,1
1,1,1,1,1,1,1
1,1,1,1,1,1,1
1,1,1,1,1,1,1
1,1,1,1,1,1,1
endlayer

layer
1,1,1,1,1,1,1
1,7,7,7,7,7,1
1,7,7,7,7,7,1
1,7,7,7,7,7,1
1,1,1,1,1,1,1
endlayer

layer
1,1,1,1,1,1,1
1,7,7,7,7,7,1
1,7,0,0,0,7,1
1,7,7,7,7,7,1
1,1,1,1,1,1,1
endlayer

layer
1,1,1,1,1,1,1
1,7,7,7,7,7,1
1,7,0,0,0,7,1
1,7,7,7,7,7,1
1,1,1,1,1,1,1
endlayer

layer
1,1,1,1,1,1,1
1,7,7,7,7,7,1
1,7,0,0,0,7,1
1,7,7,7,7,7,1
1,1,1,1,1,1,1
endlayer

layer
1,1,1,1,1,1,1
1,7,7,7,7,7,1
1,7,0,0,0,7,1
1,7,7,7,7,7,1
1,1,1,1,1,1,1
endlayer

layer
1,1,1,1,1,1,1
1,7,7,7,7,7,1
1,7,0,0,0,7,1
1,7,7,7,7,7,1
1,1,1,1,1,1,1
endlayer

layer
1,1,1,1,1,1,1
1,7,7,7,7,7,1
1,7,0,0,0,7,1
1,7,7,7,7,7,1
1,1,1,1,1,1,1
endlayer

layer
1,1,1,1,1,1,1
1,7,7,7,7,7,1
1,7,0,0,0,7,1
1,7,7,7,7,7,1
1,1,1,1,1,1,1
endlayer

layer
1,1,1,1,1,1,1
1,7,7,7,7,7,1
1,7,0,0,0,7,1
1,7,7,7,7,7,1
1,1,1,1,1,1,1
endlayer

layer
1,1,1,1,1,1,1
1,7,7,7,7,7,1
1,7,0,0,0,7,1
1,7,7,7,7,7,1
1,1,1,1,1,1,1
endlayer

layer
1,1,1,1,1,1,1
1,7,7,7,7,7,1
1,7,0,0,0,7,1
1,7,7,7,7,7,1
1,1,1,1,1,1,1
endlayer

layer
1,1,1,1,1,1,1
1,7,7,7,7,7,1
1,7,11,11,11,7,1
1,7,7,7,7,7,1
1,1,1,1,1,1,1
endlayer

layer
1,1,1,1,1,1,1
1,7,7,7,7,7,1
1,7,7,7,7,7,1
1,7,7,7,7,7,1
1,1,1,1,1,1,1
endlayer
