# Author: Arrrg
# edited by cavechunk

weight=2
embed_into_distance=3
acceptable_target_blocks=1,2,3,12,13,24
dimensions=46,12,12
allowable_overhang=0
max_cut_in=46
cut_in_buffer=0
max_leveling=0
leveling_buffer=0
preserve_water=0
preserve_lava=0
preserve_plants=1


rule1=0,0,35-14
#exterior
rule2=0,90,4,48
#floors
rule3=0,70,43
#spawners
rule4=0,50,MediumMobSpawn
#chest pedestal
rule5=0,100,43
#stairs
rule6=0,75,67-1,67-1,67-1
#window fence
rule7=0,0,113
#chest
rule8=0,100,HardMobSpawn,MediumChest,54
#roof chest
rule9=0,100,HardChest


layer
1,1,1,1,2,2,2,2,1,1,1,1
1,2,2,2,2,2,2,2,2,2,1,1
2,2,2,2,2,2,2,2,2,2,2,1
2,2,2,2,2,2,2,2,2,2,2,1
2,2,2,2,2,2,2,2,2,2,2,2
2,2,2,2,2,2,2,2,2,2,2,2
2,2,2,2,2,2,2,2,2,2,2,2
2,2,2,2,2,2,2,2,2,2,2,2
2,2,2,2,2,2,2,2,2,2,2,1
2,2,2,2,2,2,2,2,2,2,2,1
1,2,2,2,2,2,2,2,2,2,1,1
1,1,1,1,2,2,2,2,1,1,1,1
endlayer

layer
1,1,1,1,2,2,2,2,1,1,1,1
1,2,2,2,2,2,2,2,2,2,1,1
2,2,2,2,2,2,2,2,2,2,2,1
2,2,2,2,2,2,2,2,2,2,2,1
2,2,2,2,2,2,2,2,2,2,2,2
2,2,2,2,2,2,2,2,2,2,2,2
2,2,2,2,2,2,2,2,2,2,2,2
2,2,2,2,2,2,2,2,2,2,2,2
2,2,2,2,2,2,2,2,2,2,2,1
2,2,2,2,2,2,2,2,2,2,2,1
1,2,2,2,2,2,2,2,2,2,1,1
1,1,1,1,2,2,2,2,1,1,1,1
endlayer

layer
1,1,1,1,2,2,2,2,1,1,1,1
1,2,2,2,3,3,3,3,2,2,1,1
2,3,3,3,3,3,3,3,3,3,2,1
2,3,2,3,3,3,3,3,3,3,2,1
2,3,2,3,3,3,3,3,3,3,3,2
2,3,2,3,3,3,3,3,3,3,3,2
2,3,2,3,3,3,3,3,3,3,3,2
2,3,2,3,3,3,3,3,3,3,3,2
2,3,2,3,3,3,3,3,3,3,2,1
2,3,3,3,3,3,3,3,3,3,2,1
1,2,2,2,3,3,3,3,2,2,1,1
1,1,1,1,2,2,2,2,1,1,1,1
endlayer

layer
1,1,1,1,2,2,2,2,1,1,1,1
1,2,2,2,0,0,0,0,2,2,1,1
2,0,2,0,0,0,0,0,0,0,2,1
2,0,2,0,0,0,0,0,4,0,2,1
2,0,2,0,0,0,0,0,0,0,0,2
2,0,2,0,5,0,0,0,0,0,0,2
2,0,2,0,5,0,0,0,0,0,0,2
2,0,2,0,0,0,0,0,0,0,0,2
2,6,2,0,0,0,0,0,4,0,2,1
2,0,0,0,0,0,0,0,0,0,2,1
1,2,2,2,0,0,0,0,2,2,1,1
1,1,1,1,2,2,2,2,1,1,1,1
endlayer

layer
1,1,1,1,2,7,7,2,1,1,1,1
1,2,2,2,0,0,0,0,2,2,1,1
2,0,2,0,0,0,0,0,0,0,2,1
2,0,2,0,0,0,0,0,0,0,2,1
2,0,2,0,0,0,0,0,0,0,0,2
2,0,2,0,8,0,0,0,0,0,0,7
2,0,2,0,8,0,0,0,0,0,0,7
2,6,2,0,0,0,0,0,0,0,0,2
2,0,2,0,0,0,0,0,0,0,2,1
2,0,0,0,0,0,0,0,0,0,2,1
1,2,2,2,0,0,0,0,2,2,1,1
1,1,1,1,2,7,7,2,1,1,1,1
endlayer

layer
1,1,1,1,2,7,7,2,1,1,1,1
1,2,2,2,0,0,0,0,2,2,1,1
2,0,2,0,0,0,0,0,0,0,2,1
2,0,2,0,0,0,0,0,0,0,2,1
2,0,2,0,0,0,0,0,0,0,0,2
2,0,2,0,0,0,0,0,0,0,0,7
2,6,2,0,0,0,0,0,0,0,0,7
2,0,2,0,0,0,0,0,0,0,0,2
2,0,2,0,0,0,0,0,0,0,2,1
2,0,0,0,0,0,0,0,0,0,2,1
1,2,2,2,0,0,0,0,2,2,1,1
1,1,1,1,2,7,7,2,1,1,1,1
endlayer

layer
1,1,1,1,2,7,7,2,1,1,1,1
1,2,2,2,0,0,0,0,2,2,1,1
2,0,2,0,0,0,0,0,0,0,2,1
2,0,2,0,0,0,0,0,0,0,2,1
2,0,2,0,0,0,0,0,0,0,0,2
2,6,2,0,0,0,0,0,0,0,0,7
2,0,2,0,0,0,0,0,0,0,0,7
2,0,2,0,0,0,0,0,0,0,0,2
2,0,2,0,0,0,0,0,0,0,2,1
2,0,0,0,0,0,0,0,0,0,2,1
1,2,2,2,0,0,0,0,2,2,1,1
1,1,1,1,2,7,7,2,1,1,1,1
endlayer

layer
1,1,1,1,2,7,7,2,1,1,1,1
1,2,2,2,0,0,0,0,2,2,1,1
2,0,2,0,0,0,0,0,0,0,2,1
2,0,2,0,0,0,0,0,0,0,2,1
2,6,2,0,0,0,0,0,0,0,0,2
2,0,2,0,0,0,0,0,0,0,0,7
2,0,2,0,0,0,0,0,0,0,0,7
2,0,2,0,0,0,0,0,0,0,0,2
2,0,2,0,0,0,0,0,0,0,2,1
2,0,0,0,0,0,0,0,0,0,2,1
1,2,2,2,0,0,0,0,2,2,1,1
1,1,1,1,2,7,7,2,1,1,1,1
endlayer

layer
1,1,1,1,2,2,2,2,1,1,1,1
1,2,2,2,0,0,0,0,2,2,1,1
2,0,2,0,0,0,0,0,0,0,2,1
2,6,2,0,0,0,0,0,0,0,2,1
2,0,2,0,0,0,0,0,0,0,0,2
2,0,2,0,0,0,0,0,0,0,0,2
2,0,2,0,0,0,0,0,0,0,0,2
2,0,2,0,0,0,0,0,0,0,0,2
2,0,2,0,0,0,0,0,0,0,2,1
2,0,0,0,0,0,0,0,0,0,2,1
1,2,2,2,0,0,0,0,2,2,1,1
1,1,1,1,2,2,2,2,1,1,1,1
endlayer

layer
1,1,1,1,2,2,2,2,1,1,1,1
1,2,2,2,3,3,3,3,2,2,1,1
2,6,3,3,3,3,3,3,3,3,2,1
2,0,2,3,3,3,3,3,3,3,2,1
2,0,2,3,3,3,3,3,3,3,3,2
2,0,2,3,3,3,3,3,3,3,3,2
2,0,2,3,3,3,3,3,3,3,3,2
2,0,2,3,3,3,3,3,3,3,3,2
2,0,2,3,3,3,3,3,3,3,2,1
2,3,3,3,3,3,3,3,3,3,2,1
1,2,2,2,3,3,3,3,2,2,1,1
1,1,1,1,2,2,2,2,1,1,1,1
endlayer

layer
1,1,1,1,2,2,2,2,1,1,1,1
1,2,2,2,0,0,0,0,2,2,1,1
2,0,0,0,0,0,0,0,0,0,2,1
2,0,2,0,0,0,0,0,4,0,2,1
2,0,2,0,0,0,0,0,0,0,0,2
2,0,2,0,5,0,0,0,0,0,0,2
2,0,2,0,5,0,0,0,0,0,0,2
2,0,2,0,0,0,0,0,0,0,0,2
2,6,2,0,0,0,0,0,4,0,2,1
2,0,0,0,0,0,0,0,0,0,2,1
1,2,2,2,0,0,0,0,2,2,1,1
1,1,1,1,2,2,2,2,1,1,1,1
endlayer

layer
1,1,1,1,2,7,7,2,1,1,1,1
1,2,2,2,0,0,0,0,2,2,1,1
2,0,0,0,0,0,0,0,0,0,2,1
2,0,2,0,0,0,0,0,0,0,2,1
2,0,2,0,0,0,0,0,0,0,0,2
2,0,2,0,8,0,0,0,0,0,0,7
2,0,2,0,8,0,0,0,0,0,0,7
2,6,2,0,0,0,0,0,0,0,0,2
2,0,2,0,0,0,0,0,0,0,2,1
2,0,0,0,0,0,0,0,0,0,2,1
1,2,2,2,0,0,0,0,2,2,1,1
1,1,1,1,2,7,7,2,1,1,1,1
endlayer

layer
1,1,1,1,2,7,7,2,1,1,1,1
1,2,2,2,0,0,0,0,2,2,1,1
2,0,0,0,0,0,0,0,0,0,2,1
2,0,2,0,0,0,0,0,0,0,2,1
2,0,2,0,0,0,0,0,0,0,0,2
2,0,2,0,0,0,0,0,0,0,0,7
2,6,2,0,0,0,0,0,0,0,0,7
2,0,2,0,0,0,0,0,0,0,0,2
2,0,2,0,0,0,0,0,0,0,2,1
2,0,0,0,0,0,0,0,0,0,2,1
1,2,2,2,0,0,0,0,2,2,1,1
1,1,1,1,2,7,7,2,1,1,1,1
endlayer

layer
1,1,1,1,2,7,7,2,1,1,1,1
1,2,2,2,0,0,0,0,2,2,1,1
2,0,0,0,0,0,0,0,0,0,2,1
2,0,2,0,0,0,0,0,0,0,2,1
2,0,2,0,0,0,0,0,0,0,0,2
2,6,2,0,0,0,0,0,0,0,0,7
2,0,2,0,0,0,0,0,0,0,0,7
2,0,2,0,0,0,0,0,0,0,0,2
2,0,2,0,0,0,0,0,0,0,2,1
2,0,0,0,0,0,0,0,0,0,2,1
1,2,2,2,0,0,0,0,2,2,1,1
1,1,1,1,2,7,7,2,1,1,1,1
endlayer

layer
1,1,1,1,2,7,7,2,1,1,1,1
1,2,2,2,0,0,0,0,2,2,1,1
2,0,0,0,0,0,0,0,0,0,2,1
2,0,2,0,0,0,0,0,0,0,2,1
2,6,2,0,0,0,0,0,0,0,0,2
2,0,2,0,0,0,0,0,0,0,0,7
2,0,2,0,0,0,0,0,0,0,0,7
2,0,2,0,0,0,0,0,0,0,0,2
2,0,2,0,0,0,0,0,0,0,2,1
2,0,0,0,0,0,0,0,0,0,2,1
1,2,2,2,0,0,0,0,2,2,1,1
1,1,1,1,2,7,7,2,1,1,1,1
endlayer

layer
1,1,1,1,2,2,2,2,1,1,1,1
1,2,2,2,0,0,0,0,2,2,1,1
2,0,0,0,0,0,0,0,0,0,2,1
2,6,2,0,0,0,0,0,0,0,2,1
2,0,2,0,0,0,0,0,0,0,0,2
2,0,2,0,0,0,0,0,0,0,0,2
2,0,2,0,0,0,0,0,0,0,0,2
2,0,2,0,0,0,0,0,0,0,0,2
2,0,2,0,0,0,0,0,0,0,2,1
2,0,0,0,0,0,0,0,0,0,2,1
1,2,2,2,0,0,0,0,2,2,1,1
1,1,1,1,2,2,2,2,1,1,1,1
endlayer

layer
1,1,1,1,2,2,2,2,1,1,1,1
1,2,2,2,3,3,3,3,2,2,1,1
2,6,3,3,3,3,3,3,3,3,2,1
2,0,2,3,3,3,3,3,3,3,2,1
2,0,2,3,3,3,3,3,3,3,3,2
2,0,2,3,3,3,3,3,3,3,3,2
2,0,2,3,3,3,3,3,3,3,3,2
2,0,2,3,3,3,3,3,3,3,3,2
2,0,2,3,3,3,3,3,3,3,2,1
2,3,3,3,3,3,3,3,3,3,2,1
1,2,2,2,3,3,3,3,2,2,1,1
1,1,1,1,2,2,2,2,1,1,1,1
endlayer

layer
1,1,1,1,2,2,2,2,1,1,1,1
1,2,2,2,0,0,0,0,2,2,1,1
2,0,0,0,0,0,0,0,0,0,2,1
2,0,2,0,0,0,0,0,4,0,2,1
2,0,2,0,0,0,0,0,0,0,0,2
2,0,2,0,5,0,0,0,0,0,0,2
2,0,2,0,5,0,0,0,0,0,0,2
2,0,2,0,0,0,0,0,0,0,0,2
2,6,2,0,0,0,0,0,4,0,2,1
2,0,0,0,0,0,0,0,0,0,2,1
1,2,2,2,0,0,0,0,2,2,1,1
1,1,1,1,2,2,2,2,1,1,1,1
endlayer

layer
1,1,1,1,2,7,7,2,1,1,1,1
1,2,2,2,0,0,0,0,2,2,1,1
2,0,0,0,0,0,0,0,0,0,2,1
2,0,2,0,0,0,0,0,0,0,2,1
2,0,2,0,0,0,0,0,0,0,0,2
2,0,2,0,8,0,0,0,0,0,0,7
2,0,2,0,8,0,0,0,0,0,0,7
2,6,2,0,0,0,0,0,0,0,0,2
2,0,2,0,0,0,0,0,0,0,2,1
2,0,0,0,0,0,0,0,0,0,2,1
1,2,2,2,0,0,0,0,2,2,1,1
1,1,1,1,2,7,7,2,1,1,1,1
endlayer

layer
1,1,1,1,2,7,7,2,1,1,1,1
1,2,2,2,0,0,0,0,2,2,1,1
2,0,0,0,0,0,0,0,0,0,2,1
2,0,2,0,0,0,0,0,0,0,2,1
2,0,2,0,0,0,0,0,0,0,0,2
2,0,2,0,0,0,0,0,0,0,0,7
2,6,2,0,0,0,0,0,0,0,0,7
2,0,2,0,0,0,0,0,0,0,0,2
2,0,2,0,0,0,0,0,0,0,2,1
2,0,0,0,0,0,0,0,0,0,2,1
1,2,2,2,0,0,0,0,2,2,1,1
1,1,1,1,2,7,7,2,1,1,1,1
endlayer

layer
1,1,1,1,2,7,7,2,1,1,1,1
1,2,2,2,0,0,0,0,2,2,1,1
2,0,0,0,0,0,0,0,0,0,2,1
2,0,2,0,0,0,0,0,0,0,2,1
2,0,2,0,0,0,0,0,0,0,0,2
2,6,2,0,0,0,0,0,0,0,0,7
2,0,2,0,0,0,0,0,0,0,0,7
2,0,2,0,0,0,0,0,0,0,0,2
2,0,2,0,0,0,0,0,0,0,2,1
2,0,0,0,0,0,0,0,0,0,2,1
1,2,2,2,0,0,0,0,2,2,1,1
1,1,1,1,2,7,7,2,1,1,1,1
endlayer

layer
1,1,1,1,2,7,7,2,1,1,1,1
1,2,2,2,0,0,0,0,2,2,1,1
2,0,0,0,0,0,0,0,0,0,2,1
2,0,2,0,0,0,0,0,0,0,2,1
2,6,2,0,0,0,0,0,0,0,0,2
2,0,2,0,0,0,0,0,0,0,0,7
2,0,2,0,0,0,0,0,0,0,0,7
2,0,2,0,0,0,0,0,0,0,0,2
2,0,2,0,0,0,0,0,0,0,2,1
2,0,0,0,0,0,0,0,0,0,2,1
1,2,2,2,0,0,0,0,2,2,1,1
1,1,1,1,2,7,7,2,1,1,1,1
endlayer

layer
1,1,1,1,2,2,2,2,1,1,1,1
1,2,2,2,0,0,0,0,2,2,1,1
2,0,0,0,0,0,0,0,0,0,2,1
2,6,2,0,0,0,0,0,0,0,2,1
2,0,2,0,0,0,0,0,0,0,0,2
2,0,2,0,0,0,0,0,0,0,0,2
2,0,2,0,0,0,0,0,0,0,0,2
2,0,2,0,0,0,0,0,0,0,0,2
2,0,2,0,0,0,0,0,0,0,2,1
2,0,0,0,0,0,0,0,0,0,2,1
1,2,2,2,0,0,0,0,2,2,1,1
1,1,1,1,2,2,2,2,1,1,1,1
endlayer

layer
1,1,1,1,2,2,2,2,1,1,1,1
1,2,2,2,3,3,3,3,2,2,1,1
2,6,3,3,3,3,3,3,3,3,2,1
2,0,2,3,3,3,3,3,3,3,2,1
2,0,2,3,3,3,3,3,3,3,3,2
2,0,2,3,3,3,3,3,3,3,3,2
2,0,2,3,3,3,3,3,3,3,3,2
2,0,2,3,3,3,3,3,3,3,3,2
2,0,2,3,3,3,3,3,3,3,2,1
2,3,3,3,3,3,3,3,3,3,2,1
1,2,2,2,3,3,3,3,2,2,1,1
1,1,1,1,2,2,2,2,1,1,1,1
endlayer

layer
1,1,1,1,2,2,2,2,1,1,1,1
1,2,2,2,0,0,0,0,2,2,1,1
2,0,0,0,0,0,0,0,0,0,2,1
2,0,2,0,0,0,0,0,4,0,2,1
2,0,2,0,0,0,0,0,0,0,0,2
2,0,2,0,5,0,0,0,0,0,0,2
2,0,2,0,5,0,0,0,0,0,0,2
2,0,2,0,0,0,0,0,0,0,0,2
2,6,2,0,0,0,0,0,4,0,2,1
2,0,0,0,0,0,0,0,0,0,2,1
1,2,2,2,0,0,0,0,2,2,1,1
1,1,1,1,2,2,2,2,1,1,1,1
endlayer

layer
1,1,1,1,2,7,7,2,1,1,1,1
1,2,2,2,0,0,0,0,2,2,1,1
2,0,0,0,0,0,0,0,0,0,2,1
2,0,2,0,0,0,0,0,0,0,2,1
2,0,2,0,0,0,0,0,0,0,0,2
2,0,2,0,8,0,0,0,0,0,0,7
2,0,2,0,8,0,0,0,0,0,0,7
2,6,2,0,0,0,0,0,0,0,0,2
2,0,2,0,0,0,0,0,0,0,2,1
2,0,0,0,0,0,0,0,0,0,2,1
1,2,2,2,0,0,0,0,2,2,1,1
1,1,1,1,2,7,7,2,1,1,1,1
endlayer

layer
1,1,1,1,2,7,7,2,1,1,1,1
1,2,2,2,0,0,0,0,2,2,1,1
2,0,0,0,0,0,0,0,0,0,2,1
2,0,2,0,0,0,0,0,0,0,2,1
2,0,2,0,0,0,0,0,0,0,0,2
2,0,2,0,0,0,0,0,0,0,0,7
2,6,2,0,0,0,0,0,0,0,0,7
2,0,2,0,0,0,0,0,0,0,0,2
2,0,2,0,0,0,0,0,0,0,2,1
2,0,0,0,0,0,0,0,0,0,2,1
1,2,2,2,0,0,0,0,2,2,1,1
1,1,1,1,2,7,7,2,1,1,1,1
endlayer

layer
1,1,1,1,2,7,7,2,1,1,1,1
1,2,2,2,0,0,0,0,2,2,1,1
2,0,0,0,0,0,0,0,0,0,2,1
2,0,2,0,0,0,0,0,0,0,2,1
2,0,2,0,0,0,0,0,0,0,0,2
2,6,2,0,0,0,0,0,0,0,0,7
2,0,2,0,0,0,0,0,0,0,0,7
2,0,2,0,0,0,0,0,0,0,0,2
2,0,2,0,0,0,0,0,0,0,2,1
2,0,0,0,0,0,0,0,0,0,2,1
1,2,2,2,0,0,0,0,2,2,1,1
1,1,1,1,2,7,7,2,1,1,1,1
endlayer

layer
1,1,1,1,2,7,7,2,1,1,1,1
1,2,2,2,0,0,0,0,2,2,1,1
2,0,0,0,0,0,0,0,0,0,2,1
2,0,2,0,0,0,0,0,0,0,2,1
2,6,2,0,0,0,0,0,0,0,0,2
2,0,2,0,0,0,0,0,0,0,0,7
2,0,2,0,0,0,0,0,0,0,0,7
2,0,2,0,0,0,0,0,0,0,0,2
2,0,2,0,0,0,0,0,0,0,2,1
2,0,0,0,0,0,0,0,0,0,2,1
1,2,2,2,0,0,0,0,2,2,1,1
1,1,1,1,2,7,7,2,1,1,1,1
endlayer

layer
1,1,1,1,2,2,2,2,1,1,1,1
1,2,2,2,0,0,0,0,2,2,1,1
2,0,0,0,0,0,0,0,0,0,2,1
2,6,2,0,0,0,0,0,0,0,2,1
2,0,2,0,0,0,0,0,0,0,0,2
2,0,2,0,0,0,0,0,0,0,0,2
2,0,2,0,0,0,0,0,0,0,0,2
2,0,2,0,0,0,0,0,0,0,0,2
2,0,2,0,0,0,0,0,0,0,2,1
2,0,0,0,0,0,0,0,0,0,2,1
1,2,2,2,0,0,0,0,2,2,1,1
1,1,1,1,2,2,2,2,1,1,1,1
endlayer

layer
1,1,1,1,2,2,2,2,1,1,1,1
1,2,2,2,3,3,3,3,2,2,1,1
2,6,3,3,3,3,3,3,3,3,2,1
2,0,2,3,3,3,3,3,3,3,2,1
2,0,2,3,3,3,3,3,3,3,3,2
2,0,2,3,3,3,3,3,3,3,3,2
2,0,2,3,3,3,3,3,3,3,3,2
2,0,2,3,3,3,3,3,3,3,3,2
2,0,2,3,3,3,3,3,3,3,2,1
2,3,3,3,3,3,3,3,3,3,2,1
1,2,2,2,3,3,3,3,2,2,1,1
1,1,1,1,2,2,2,2,1,1,1,1
endlayer

layer
1,1,1,1,2,2,2,2,1,1,1,1
1,2,2,2,0,0,0,0,2,2,1,1
2,0,0,0,0,0,0,0,0,0,2,1
2,0,2,0,0,0,0,0,4,0,2,1
2,0,2,0,0,0,0,0,0,0,0,2
2,0,2,0,5,0,0,0,0,0,0,2
2,0,2,0,5,0,0,0,0,0,0,2
2,0,2,0,0,0,0,0,0,0,0,2
2,6,2,0,0,0,0,0,4,0,2,1
2,0,0,0,0,0,0,0,0,0,2,1
1,2,2,2,0,0,0,0,2,2,1,1
1,1,1,1,2,2,2,2,1,1,1,1
endlayer

layer
1,1,1,1,2,7,7,2,1,1,1,1
1,2,2,2,0,0,0,0,2,2,1,1
2,0,0,0,0,0,0,0,0,0,2,1
2,0,2,0,0,0,0,0,0,0,2,1
2,0,2,0,0,0,0,0,0,0,0,2
2,0,2,0,8,0,0,0,0,0,0,7
2,0,2,0,8,0,0,0,0,0,0,7
2,6,2,0,0,0,0,0,0,0,0,2
2,0,2,0,0,0,0,0,0,0,2,1
2,0,0,0,0,0,0,0,0,0,2,1
1,2,2,2,0,0,0,0,2,2,1,1
1,1,1,1,2,7,7,2,1,1,1,1
endlayer

layer
1,1,1,1,2,7,7,2,1,1,1,1
1,2,2,2,0,0,0,0,2,2,1,1
2,0,0,0,0,0,0,0,0,0,2,1
2,0,2,0,0,0,0,0,0,0,2,1
2,0,2,0,0,0,0,0,0,0,0,2
2,0,2,0,0,0,0,0,0,0,0,7
2,6,2,0,0,0,0,0,0,0,0,7
2,0,2,0,0,0,0,0,0,0,0,2
2,0,2,0,0,0,0,0,0,0,2,1
2,0,0,0,0,0,0,0,0,0,2,1
1,2,2,2,0,0,0,0,2,2,1,1
1,1,1,1,2,7,7,2,1,1,1,1
endlayer

layer
1,1,1,1,2,7,7,2,1,1,1,1
1,2,2,2,0,0,0,0,2,2,1,1
2,0,0,0,0,0,0,0,0,0,2,1
2,0,2,0,0,0,0,0,0,0,2,1
2,0,2,0,0,0,0,0,0,0,0,2
2,6,2,0,0,0,0,0,0,0,0,7
2,0,2,0,0,0,0,0,0,0,0,7
2,0,2,0,0,0,0,0,0,0,0,2
2,0,2,0,0,0,0,0,0,0,2,1
2,0,0,0,0,0,0,0,0,0,2,1
1,2,2,2,0,0,0,0,2,2,1,1
1,1,1,1,2,7,7,2,1,1,1,1
endlayer

layer
1,1,1,1,2,7,7,2,1,1,1,1
1,2,2,2,0,0,0,0,2,2,1,1
2,0,0,0,0,0,0,0,0,0,2,1
2,0,2,0,0,0,0,0,0,0,2,1
2,6,2,0,0,0,0,0,0,0,0,2
2,0,2,0,0,0,0,0,0,0,0,7
2,0,2,0,0,0,0,0,0,0,0,7
2,0,2,0,0,0,0,0,0,0,0,2
2,0,2,0,0,0,0,0,0,0,2,1
2,0,0,0,0,0,0,0,0,0,2,1
1,2,2,2,0,0,0,0,2,2,1,1
1,1,1,1,2,7,7,2,1,1,1,1
endlayer

layer
1,1,1,1,2,2,2,2,1,1,1,1
1,2,2,2,0,0,0,0,2,2,1,1
2,0,0,0,0,0,0,0,0,0,2,1
2,6,2,0,0,0,0,0,0,0,2,1
2,0,2,0,0,0,0,0,0,0,0,2
2,0,2,0,0,0,0,0,0,0,0,2
2,0,2,0,0,0,0,0,0,0,0,2
2,0,2,0,0,0,0,0,0,0,0,2
2,0,2,0,0,0,0,0,0,0,2,1
2,0,0,0,0,0,0,0,0,0,2,1
1,2,2,2,0,0,0,0,2,2,1,1
1,1,1,1,2,2,2,2,1,1,1,1
endlayer

layer
1,1,1,1,2,2,2,2,1,1,1,1
1,2,2,2,3,3,3,3,2,2,1,1
2,6,3,3,3,3,3,3,3,3,2,1
2,0,2,3,3,3,3,3,3,3,2,1
2,0,2,3,3,3,3,3,3,3,3,2
2,0,2,3,3,3,3,3,3,3,3,2
2,0,2,3,3,3,3,3,3,3,3,2
2,0,2,3,3,3,3,3,3,3,3,2
2,0,2,3,3,3,3,3,3,3,2,1
2,3,3,3,3,3,3,3,3,3,2,1
1,2,2,2,3,3,3,3,2,2,1,1
1,1,1,1,2,2,2,2,1,1,1,1
endlayer

layer
1,1,1,1,2,2,2,2,1,1,1,1
1,2,2,2,0,0,0,0,2,2,1,1
2,0,0,0,0,0,0,0,0,0,2,1
2,0,2,0,0,0,0,0,4,0,2,1
2,0,2,0,0,0,0,0,0,0,0,2
2,0,2,0,5,0,0,0,0,0,0,2
2,0,2,0,5,0,0,0,0,0,0,2
2,0,2,0,0,0,0,0,0,0,0,2
2,6,2,0,0,0,0,0,4,0,2,1
2,0,0,0,0,0,0,0,0,0,2,1
1,2,2,2,0,0,0,0,2,2,1,1
1,1,1,1,2,2,2,2,1,1,1,1
endlayer

layer
1,1,1,1,2,7,7,2,1,1,1,1
1,2,2,2,0,0,0,0,2,2,1,1
2,0,0,0,0,0,0,0,0,0,2,1
2,0,2,0,0,0,0,0,0,0,2,1
2,0,2,0,0,0,0,0,0,0,0,2
2,0,2,0,8,0,0,0,0,0,0,7
2,0,2,0,8,0,0,0,0,0,0,7
2,6,2,0,0,0,0,0,0,0,0,2
2,0,2,0,0,0,0,0,0,0,2,1
2,0,0,0,0,0,0,0,0,0,2,1
1,2,2,2,0,0,0,0,2,2,1,1
1,1,1,1,2,7,7,2,1,1,1,1
endlayer

layer
1,1,1,1,2,7,7,2,1,1,1,1
1,2,2,2,0,0,0,0,2,2,1,1
2,0,0,0,0,0,0,0,0,0,2,1
2,0,2,0,0,0,0,0,0,0,2,1
2,0,2,0,0,0,0,0,0,0,0,2
2,0,2,0,0,0,0,0,0,0,0,7
2,6,2,0,0,0,0,0,0,0,0,7
2,0,2,0,0,0,0,0,0,0,0,2
2,0,2,0,0,0,0,0,0,0,2,1
2,0,0,0,0,0,0,0,0,0,2,1
1,2,2,2,0,0,0,0,2,2,1,1
1,1,1,1,2,7,7,2,1,1,1,1
endlayer

layer
1,1,1,1,2,7,7,2,1,1,1,1
1,2,2,2,0,0,0,0,2,2,1,1
2,0,0,0,0,0,0,0,0,0,2,1
2,0,2,0,0,0,0,0,0,0,2,1
2,0,2,0,0,0,0,0,0,0,0,2
2,6,2,0,0,0,0,0,0,0,0,7
2,0,2,0,0,0,0,0,0,0,0,7
2,0,2,0,0,0,0,0,0,0,0,2
2,0,2,0,0,0,0,0,0,0,2,1
2,0,0,0,0,0,0,0,0,0,2,1
1,2,2,2,0,0,0,0,2,2,1,1
1,1,1,1,2,7,7,2,1,1,1,1
endlayer

layer
1,1,1,1,2,7,7,2,1,1,1,1
1,2,2,2,0,0,0,0,2,2,1,1
2,0,0,0,0,0,0,0,0,0,2,1
2,0,2,0,0,0,0,0,0,0,2,1
2,6,2,0,0,0,0,0,0,0,0,2
2,0,2,0,0,0,0,0,0,0,0,7
2,0,2,0,0,0,0,0,0,0,0,7
2,0,2,0,0,0,0,0,0,0,0,2
2,0,2,0,0,0,0,0,0,0,2,1
2,0,0,0,0,0,0,0,0,0,2,1
1,2,2,2,0,0,0,0,2,2,1,1
1,1,1,1,2,7,7,2,1,1,1,1
endlayer

layer
1,1,1,1,2,2,2,2,1,1,1,1
1,2,2,2,0,0,0,0,2,2,1,1
2,0,0,0,0,0,0,0,0,0,2,1
2,6,2,0,0,0,0,0,0,0,2,1
2,0,2,0,0,0,0,0,0,0,0,2
2,0,2,0,0,0,0,0,0,0,0,2
2,0,2,0,0,0,0,0,0,0,0,2
2,0,2,0,0,0,0,0,0,0,0,2
2,0,2,0,0,0,0,0,0,0,2,1
2,0,0,0,0,0,0,0,0,0,2,1
1,2,2,2,0,0,0,0,2,2,1,1
1,1,1,1,2,2,2,2,1,1,1,1
endlayer

layer
1,1,1,1,2,2,2,2,1,1,1,1
1,2,2,2,3,3,3,3,2,2,1,1
2,6,3,3,3,3,3,3,3,3,2,1
2,0,3,3,3,3,3,3,3,3,2,1
2,0,3,3,3,3,3,3,3,3,3,2
2,0,3,3,3,3,3,3,3,3,3,2
2,3,3,3,3,3,3,3,3,3,3,2
2,3,3,3,3,3,3,3,3,3,3,2
2,3,3,3,3,3,3,3,3,3,2,1
2,3,3,3,3,3,3,3,3,3,2,1
1,2,2,2,3,3,3,3,2,2,1,1
1,1,1,1,2,2,2,2,1,1,1,1
endlayer

layer
1,1,1,1,2,2,2,2,1,1,1,1
1,2,2,2,0,0,0,0,2,2,1,1
2,0,0,0,0,0,0,0,0,0,2,1
2,0,0,0,0,0,0,0,4,0,2,1
2,0,0,0,0,0,0,0,0,0,0,2
2,2,0,0,0,0,0,0,0,9,0,2
2,2,0,0,0,0,0,0,0,9,0,2
2,2,0,0,0,0,0,0,0,0,0,2
2,2,0,0,0,0,0,0,4,0,2,1
2,2,0,0,0,0,0,0,0,0,2,1
1,2,2,2,0,0,0,0,2,2,1,1
1,1,1,1,2,2,2,2,1,1,1,1
endlayer

