weight=1
embed_into_distance=1
acceptable_target_blocks=1,2,3,12,13,24
dimensions=12,9,5
cut_in_buffer=1
max_leveling=2
leveling_buffer=1
preserve_water=0
preserve_lava=0
preserve_plants=0
max_cut_in=10


rule1=0,100,preserveBlock
rule2=0,100,4
rule3=0,100,67-1
rule4=0,100,65-3
rule5=0,100,64-2
rule6=0,100,102
rule7=0,100,67-3
rule8=0,100,64-8
rule9=0,100,67-2
rule10=0,100,50-3
rule11=0,100,50-1
rule12=0,100,50-2
rule13=0,100,50-4


layer
1,2,2,2,1
2,2,2,2,2
2,2,2,2,2
2,2,2,2,2
2,2,2,2,2
1,2,2,2,1
1,2,2,2,1
1,2,2,2,1
1,2,2,2,1
endlayer

layer
0,2,2,2,0
2,2,2,2,2
2,2,3,2,2
2,3,0,3,2
2,0,0,0,2
2,0,0,4,2
2,0,0,0,2
2,0,0,0,2
0,2,5,2,0
endlayer

layer
0,2,2,2,0
2,9,0,7,2
2,0,0,0,2
2,0,0,0,2
2,0,0,0,2
2,0,0,4,2
6,0,0,0,6
2,0,0,0,2
0,2,8,2,0
endlayer

layer
0,2,6,2,0
2,0,0,0,2
6,0,0,0,6
2,0,0,0,2
2,0,0,0,2
2,0,0,4,2
6,0,0,0,6
2,0,0,0,2
0,2,2,2,0
endlayer

layer
0,2,2,2,0
2,0,11,0,2
2,13,0,10,2
2,0,12,0,2
2,2,2,2,2
2,2,2,4,2
2,2,2,2,2
2,2,2,2,2
2,2,2,2,2
endlayer

layer
0,0,0,0,0
0,2,2,2,0
0,2,2,2,0
0,2,2,2,0
0,2,2,2,0
2,0,0,4,2
2,0,0,0,2
2,0,0,0,2
0,2,2,2,0
endlayer

layer
0,0,0,0,0
0,0,0,0,0
0,0,0,0,0
0,0,0,0,0
0,2,6,2,0
2,0,0,4,2
6,0,0,0,6
2,0,0,0,2
0,2,6,2,0
endlayer

layer
0,0,0,0,0
0,0,0,0,0
0,0,0,0,0
0,0,0,0,0
0,2,6,2,0
2,0,0,4,2
6,0,0,0,6
2,0,0,0,2
0,2,6,2,0
endlayer

layer
0,0,0,0,0
0,0,0,0,0
0,0,0,0,0
0,0,0,0,0
0,2,2,2,0
2,0,0,4,2
2,0,0,0,2
2,0,0,0,2
0,2,2,2,0
endlayer

layer
0,0,0,0,0
0,0,0,0,0
0,0,0,0,0
0,0,0,0,0
2,2,2,2,2
2,2,2,4,2
2,2,2,2,2
2,2,2,2,2
2,2,2,2,2
endlayer

layer
0,0,0,0,0
0,0,0,0,0
0,0,0,0,0
0,0,0,0,0
0,2,2,2,0
2,0,0,0,2
2,0,0,0,2
2,0,0,0,2
0,2,2,2,0
endlayer

layer
0,0,0,0,0
0,0,0,0,0
0,0,0,0,0
0,0,0,0,0
0,0,2,0,0
0,0,0,0,0
2,0,0,0,2
0,0,0,0,0
0,0,2,0,0
endlayer

