weight=2
embed_into_distance=11
acceptable_target_blocks=1,2,3,12,13,24
dimensions=16,6,6
cut_in_buffer=0
max_leveling=2
leveling_buffer=0
preserve_water=0
preserve_lava=0
preserve_plants=0
max_cut_in=10


rule1=0,100,preserveBlock
rule2=0,100,4
rule3=0,100,9
rule4=0,100,13
rule5=0,100,85


layer
1,1,1,1,1,1
1,2,2,2,2,1
1,2,2,2,2,1
1,2,2,2,2,1
1,2,2,2,2,1
1,1,1,1,1,1
endlayer

layer
1,1,1,1,1,1
1,2,2,2,2,1
1,2,3,3,2,1
1,2,3,3,2,1
1,2,2,2,2,1
1,1,1,1,1,1
endlayer

layer
1,1,1,1,1,1
1,2,2,2,2,1
1,2,3,3,2,1
1,2,3,3,2,1
1,2,2,2,2,1
1,1,1,1,1,1
endlayer

layer
1,1,1,1,1,1
1,2,2,2,2,1
1,2,3,3,2,1
1,2,3,3,2,1
1,2,2,2,2,1
1,1,1,1,1,1
endlayer

layer
1,1,1,1,1,1
1,2,2,2,2,1
1,2,3,3,2,1
1,2,3,3,2,1
1,2,2,2,2,1
1,1,1,1,1,1
endlayer

layer
1,1,1,1,1,1
1,2,2,2,2,1
1,2,3,3,2,1
1,2,3,3,2,1
1,2,2,2,2,1
1,1,1,1,1,1
endlayer

layer
1,1,1,1,1,1
1,2,2,2,2,1
1,2,3,3,2,1
1,2,3,3,2,1
1,2,2,2,2,1
1,1,1,1,1,1
endlayer

layer
1,1,1,1,1,1
1,2,2,2,2,1
1,2,3,3,2,1
1,2,3,3,2,1
1,2,2,2,2,1
1,1,1,1,1,1
endlayer

layer
1,1,1,1,1,1
1,2,2,2,2,1
1,2,3,3,2,1
1,2,3,3,2,1
1,2,2,2,2,1
1,1,1,1,1,1
endlayer

layer
4,4,4,4,4,4
4,2,2,2,2,4
4,2,3,3,2,4
4,2,3,3,2,4
4,2,2,2,2,4
4,4,4,4,4,4
endlayer

layer
4,4,4,4,4,4
4,2,2,2,2,4
4,2,3,3,2,4
4,2,3,3,2,4
4,2,2,2,2,4
4,4,4,4,4,4
endlayer

layer
4,4,4,4,4,4
4,2,2,2,2,4
4,2,3,3,2,4
4,2,3,3,2,4
4,2,2,2,2,4
4,4,4,4,4,4
endlayer

layer
0,0,0,0,0,0
0,2,2,2,2,0
0,2,0,0,2,0
0,2,0,0,2,0
0,2,2,2,2,0
0,0,0,0,0,0
endlayer

layer
0,0,0,0,0,0
0,5,0,0,5,0
0,0,0,0,0,0
0,0,0,0,0,0
0,5,0,0,5,0
0,0,0,0,0,0
endlayer

layer
0,0,0,0,0,0
0,5,0,0,5,0
0,0,0,0,0,0
0,0,0,0,0,0
0,5,0,0,5,0
0,0,0,0,0,0
endlayer

layer
0,0,0,0,0,0
0,2,2,2,2,0
0,2,2,2,2,0
0,2,2,2,2,0
0,2,2,2,2,0
0,0,0,0,0,0
endlayer

