weight=1
embed_into_distance=1
acceptable_target_blocks=1,2,3,12,13,24
dimensions=7,12,9
cut_in_buffer=1
max_leveling=2
leveling_buffer=1
preserve_water=0
preserve_lava=0
preserve_plants=0
max_cut_in=10


rule1=0,100,4
rule2=0,100,13
rule3=0,100,5
rule4=0,100,preserveBlock
rule5=0,100,preserveBlock
rule6=0,100,64
rule7=0,100,17
rule8=0,100,102
rule9=0,100,64-8
rule10=0,100,53-1
rule11=0,100,50-2
rule12=0,100,53-3
rule13=0,100,53
rule14=0,100,53-2


layer
4,4,1,1,1,1,1,1,1
4,4,1,3,3,3,3,3,1
4,4,1,3,3,3,3,3,1
4,4,1,3,3,3,3,3,1
4,4,1,3,3,3,3,3,1
1,1,1,3,3,3,3,3,1
1,3,3,3,3,3,3,3,1
1,3,3,3,3,3,3,3,1
1,3,3,3,3,3,3,3,1
1,3,3,3,3,3,3,3,1
1,1,1,1,1,1,1,1,1
2,2,2,2,2,2,2,2,2
endlayer

layer
0,0,1,1,1,1,1,1,1
0,0,1,0,0,0,0,0,1
0,0,1,0,0,0,0,0,1
0,0,1,0,0,0,0,0,1
0,0,1,0,0,0,0,0,1
1,1,1,0,0,0,0,0,1
1,0,0,0,0,0,0,0,1
1,0,0,0,0,0,0,0,1
1,0,0,0,0,0,0,0,1
1,0,0,0,0,0,0,0,1
1,1,6,1,1,1,1,1,1
0,0,0,0,0,0,0,0,0
endlayer

layer
0,0,1,1,1,1,1,1,1
0,0,7,0,0,0,0,0,7
0,0,8,0,0,0,0,0,8
0,0,8,0,0,0,0,0,8
0,0,7,0,0,0,0,0,7
1,3,3,0,0,0,0,0,3
7,0,0,0,0,0,0,0,7
8,0,0,0,0,0,0,0,8
8,0,0,0,0,0,0,0,8
7,0,0,0,0,0,0,0,7
1,3,9,3,7,8,7,3,1
0,0,0,0,0,0,0,0,0
endlayer

layer
0,12,1,1,1,1,1,1,1
0,12,1,0,0,0,0,0,1
0,12,1,0,0,0,0,0,1
0,12,1,0,0,0,0,0,1
13,3,1,0,0,0,0,0,1
1,3,3,0,0,0,0,0,1
1,0,0,0,0,0,0,0,1
1,0,0,0,0,0,0,0,1
1,0,0,0,0,0,0,0,1
1,0,11,0,0,0,0,0,1
1,3,3,3,3,3,3,3,1
10,10,10,10,10,10,10,10,10
endlayer

layer
0,0,12,3,7,8,7,3,14
0,0,12,3,0,0,0,3,14
0,0,12,3,0,0,0,3,14
0,0,12,3,0,0,0,3,14
0,0,12,3,0,0,0,3,14
13,13,3,3,0,0,0,3,14
3,3,3,3,0,0,0,3,3
3,0,0,0,0,0,0,3,3
3,0,0,0,0,0,0,3,3
3,3,3,3,3,3,3,3,3
10,10,10,10,10,10,10,10,10
0,0,0,0,0,0,0,0,0
endlayer

layer
0,0,0,12,3,3,3,14,0
0,0,0,12,3,0,3,14,0
0,0,0,12,3,0,3,14,0
0,0,0,12,3,0,3,14,0
0,0,0,12,3,0,3,14,0
0,0,0,12,3,0,3,14,0
13,13,13,3,3,0,3,3,13
3,3,3,3,3,3,3,3,3
3,3,3,3,3,3,3,3,3
10,10,10,10,10,10,10,10,10
0,0,0,0,0,0,0,0,0
0,0,0,0,0,0,0,0,0
endlayer

layer
0,0,0,0,12,3,14,0,0
0,0,0,0,12,3,14,0,0
0,0,0,0,12,3,14,0,0
0,0,0,0,12,3,14,0,0
0,0,0,0,12,3,14,0,0
0,0,0,0,12,3,14,0,0
0,0,0,0,12,3,14,0,0
13,13,13,13,3,3,3,13,13
10,10,10,10,10,10,10,10,10
0,0,0,0,0,0,0,0,0
0,0,0,0,0,0,0,0,0
0,0,0,0,0,0,0,0,0
endlayer

