# Author: GnomeWorks
# From: Minecraft Forums

weight=20
embed_into_distance=1
acceptable_target_blocks=1,12,24
dimensions=10,5,5
allowable_overhang=1
max_cut_in=2
cut_in_buffer=1
max_leveling=2
leveling_buffer=1
preserve_water=0
preserve_lava=0
preserve_plants=0

rule1=1,95,4,4,24
rule2=2,80,4,4,24
rule3=1,25,22,22,22,41

layer
2,2,2,2,2
2,1,1,1,2
2,1,1,1,2
2,1,1,1,2
2,2,2,2,2
endlayer

layer
0,0,0,0,0
0,2,2,2,0
0,2,1,2,0
0,2,2,2,0
0,0,0,0,0
endlayer

layer
0,0,0,0,0
0,0,0,0,0
0,0,1,0,0
0,0,0,0,0
0,0,0,0,0
endlayer

layer
0,0,0,0,0
0,2,2,2,0
0,2,1,2,0
0,2,2,2,0
0,0,0,0,0
endlayer

layer
0,0,0,0,0
0,2,2,2,0
0,2,1,2,0
0,2,2,2,0
0,0,0,0,0
endlayer

layer
0,0,0,0,0
0,2,2,2,0
0,2,1,2,0
0,2,2,2,0
0,0,0,0,0
endlayer

layer
0,0,0,0,0
0,3,2,3,0
0,2,1,2,0
0,3,2,3,0
0,0,0,0,0
endlayer

layer
0,0,0,0,0
0,0,2,0,0
0,2,1,2,0
0,0,2,0,0
0,0,0,0,0
endlayer

layer
0,0,0,0,0
0,0,3,0,0
0,3,2,3,0
0,0,3,0,0
0,0,0,0,0
endlayer

layer
0,0,0,0,0
0,0,0,0,0
0,0,3,0,0
0,0,0,0,0
0,0,0,0,0
endlayer
