weight=10
embed_into_distance=1
acceptable_target_blocks=1,12,13,24
dimensions=4,19,11
cut_in_buffer=0
max_leveling=2
leveling_buffer=1
preserve_water=0
preserve_lava=0
preserve_plants=0
max_cut_in=10


rule1=0,100,24,24,24,preserveBlock,preserveBlock,preserveBlock
rule2=0,100,24
rule3=0,100,12
rule4=0,75,44-1
rule5=0,100,24-2
rule6=0,35,12
rule7=0,100,24-2
rule8=1,10,32
rule9=0,75,24-2
rule10=1,30,8


layer
1,1,1,1,1,1,1,1,1,1,1
1,2,2,2,2,2,2,2,2,2,1
1,2,3,3,3,3,3,3,3,2,1
1,2,3,3,3,3,3,3,3,2,1
1,2,3,3,3,3,3,3,3,2,1
1,2,3,3,3,3,3,3,3,2,1
1,2,3,3,3,3,3,3,3,2,1
1,2,3,3,3,3,3,3,3,2,1
1,2,3,3,3,3,3,3,3,2,1
1,2,3,3,3,3,3,3,3,2,1
1,2,3,3,3,3,3,3,3,2,1
1,2,3,3,3,3,3,3,3,2,1
1,2,3,3,3,3,3,3,3,2,1
1,2,3,3,3,3,3,3,3,2,1
1,2,3,3,3,3,3,3,3,2,1
1,2,3,3,3,3,3,3,3,2,1
1,2,3,3,3,3,3,3,3,2,1
1,2,2,2,2,2,2,2,2,2,1
1,1,1,1,1,1,1,1,1,1,1
endlayer

layer
0,0,0,0,0,0,0,0,0,0,0
0,4,4,4,4,4,4,4,4,4,0
0,4,5,5,5,5,5,5,5,4,0
0,4,5,6,6,6,6,6,5,4,0
0,4,5,6,6,6,6,6,5,4,0
0,4,5,6,6,7,6,6,5,4,0
0,4,5,6,6,6,6,6,5,4,0
0,4,5,6,6,6,6,6,5,4,0
0,4,5,6,6,6,6,6,5,4,0
0,4,5,6,6,7,6,6,5,4,0
0,4,5,6,6,6,6,6,5,4,0
0,4,5,6,6,6,6,6,5,4,0
0,4,5,6,6,6,6,6,5,4,0
0,4,5,6,6,7,6,6,5,4,0
0,4,5,6,6,6,6,6,5,4,0
0,4,5,6,6,6,6,6,5,4,0
0,4,5,5,5,5,5,5,5,4,0
0,4,4,4,4,4,4,4,4,4,0
0,0,0,0,0,0,0,0,0,0,0
endlayer

layer
0,0,0,0,0,0,0,0,0,0,0
0,0,0,0,0,0,0,0,0,0,0
0,0,0,0,0,0,0,0,0,0,0
0,0,0,8,8,8,8,8,0,0,0
0,0,0,8,8,8,8,8,0,0,0
0,0,0,8,8,9,8,8,0,0,0
0,0,0,8,8,8,8,8,0,0,0
0,0,0,8,8,8,8,8,0,0,0
0,0,0,8,8,8,8,8,0,0,0
0,0,0,8,8,9,8,8,0,0,0
0,0,0,8,8,8,8,8,0,0,0
0,0,0,8,8,8,8,8,0,0,0
0,0,0,8,8,8,8,8,0,0,0
0,0,0,8,8,9,8,8,0,0,0
0,0,0,8,8,8,8,8,0,0,0
0,0,0,8,8,8,8,8,0,0,0
0,0,0,0,0,0,0,0,0,0,0
0,0,0,0,0,0,0,0,0,0,0
0,0,0,0,0,0,0,0,0,0,0
endlayer

layer
0,0,0,0,0,0,0,0,0,0,0
0,0,0,0,0,0,0,0,0,0,0
0,0,0,0,0,0,0,0,0,0,0
0,0,0,0,0,0,0,0,0,0,0
0,0,0,0,0,0,0,0,0,0,0
0,0,0,0,0,10,0,0,0,0,0
0,0,0,0,0,0,0,0,0,0,0
0,0,0,0,0,0,0,0,0,0,0
0,0,0,0,0,0,0,0,0,0,0
0,0,0,0,0,10,0,0,0,0,0
0,0,0,0,0,0,0,0,0,0,0
0,0,0,0,0,0,0,0,0,0,0
0,0,0,0,0,0,0,0,0,0,0
0,0,0,0,0,10,0,0,0,0,0
0,0,0,0,0,0,0,0,0,0,0
0,0,0,0,0,0,0,0,0,0,0
0,0,0,0,0,0,0,0,0,0,0
0,0,0,0,0,0,0,0,0,0,0
0,0,0,0,0,0,0,0,0,0,0
endlayer

