weight=1
embed_into_distance=1
acceptable_target_blocks=1,2,3,12,13,24
dimensions=7,8,10
cut_in_buffer=1
max_leveling=2
leveling_buffer=1
preserve_water=0
preserve_lava=0
preserve_plants=1
max_cut_in=10


rule1=0,100,preserveBlock
rule2=0,90,4,4,4,48,97-1
rule3=0,50,67-1
rule4=0,50,4,4,4,48,97-1
rule5=0,100,43
rule6=0,80,5
rule7=0,80,17
rule8=0,50,101
rule9=0,50,61-5
rule10=0,10,102
rule11=1,80,44


layer
1,1,1,1,1,1,1,1,1,1
1,1,1,1,1,1,1,1,1,1
1,1,1,1,1,1,1,1,1,1
1,1,1,1,1,1,1,1,1,1
1,1,1,1,1,1,1,1,1,1
1,1,1,1,1,1,1,1,1,1
1,1,1,1,1,1,1,1,1,1
1,1,1,1,1,1,1,1,1,1
endlayer

layer
2,2,2,2,2,2,2,2,2,2
2,2,2,2,2,2,2,2,2,2
2,2,2,2,2,2,2,2,2,2
2,2,2,2,2,2,2,2,2,2
2,2,2,2,2,2,2,2,2,2
2,2,2,2,2,2,2,2,2,2
2,2,2,2,2,2,2,2,2,2
0,0,0,0,0,0,3,3,3,0
endlayer

layer
7,6,6,6,6,6,2,2,2,2
6,0,0,0,0,0,2,0,0,2
6,0,0,0,0,0,2,2,2,2
6,0,0,0,6,6,2,0,0,0
6,0,0,6,0,0,0,0,4,4
6,0,0,0,0,0,4,4,5,4
7,6,6,7,0,4,4,4,4,4
0,0,0,0,0,0,0,0,0,0
endlayer

layer
7,6,10,6,10,6,2,2,2,2
6,0,0,0,0,0,2,0,0,8
10,0,0,0,0,0,2,0,0,8
6,0,0,0,6,6,9,0,0,0
10,0,0,6,0,0,0,0,0,0
6,0,0,0,0,0,0,0,4,0
7,6,6,7,0,0,0,0,0,0
0,0,0,0,0,0,0,0,0,0
endlayer

layer
7,6,6,6,6,6,2,2,2,2
6,0,0,0,0,0,2,2,2,2
6,0,0,0,0,0,2,2,2,2
6,0,0,0,6,6,9,0,0,0
6,0,0,6,0,0,0,0,0,0
6,0,0,6,0,0,0,0,0,0
7,6,6,7,0,0,0,0,0,0
0,0,0,0,0,0,0,0,0,0
endlayer

layer
7,4,4,4,4,4,4,4,4,4
4,4,4,4,4,4,4,4,4,4
4,4,4,4,4,4,4,4,4,4
4,4,4,4,4,4,4,4,4,4
4,4,4,4,4,4,4,4,0,0
4,4,4,4,4,4,0,0,0,0
7,4,4,7,4,0,0,0,0,0
0,0,0,0,0,0,0,0,0,0
endlayer

layer
11,11,11,11,11,11,11,11,11,11
11,0,0,0,0,0,0,0,0,11
11,0,0,0,0,0,0,0,0,11
11,0,0,0,0,0,0,0,0,11
11,0,0,0,0,0,0,0,0,0
11,0,0,0,0,0,0,0,0,0
11,11,11,11,11,0,0,0,0,0
0,0,0,0,0,0,0,0,0,0
endlayer

