# Converted from schematic
# THIS TEMPLATE USES DEFAULTS!  Please edit for corrections.
# If you need help, consult template_rules.txt

weight=1
embed_into_distance=1
acceptable_target_blocks=1,2,3,12,13
dimensions=9,12,11
allowable_overhang=0
max_cut_in=2
cut_in_buffer=1
max_leveling=2
leveling_buffer=1
preserve_water=0
preserve_lava=0
preserve_plants=0


rule1=0,100,2
rule2=0,100,12
rule3=0,100,1
rule4=0,100,3
rule5=0,100,55
rule6=0,100,31-1
rule7=0,100,70
rule8=0,100,106-8
rule9=0,100,29-5
rule10=0,100,29-4
rule11=0,100,54-2
rule12=0,100,106-2
rule13=0,100,93-2
rule14=0,100,93-1
rule15=0,100,93-3
rule16=0,100,106-4
rule17=0,100,106-1
rule18=0,100,76-5
rule19=0,100,50-1
rule20=0,100,50-2
rule21=0,100,29-13
rule22=0,100,34-13
rule23=0,100,34-12
rule24=0,100,29-12
rule25=0,100,55-8
rule26=0,100,55-9
rule27=0,100,55-10
rule28=0,100,55-11
rule29=0,100,55-12
rule30=0,100,55-13
rule31=0,100,55-14
rule32=0,100,55-15
rule33=0,100,55-4
rule34=0,100,55-5
rule35=0,100,55-6
rule36=0,100,55-7
rule37=0,100,9
rule38=0,100,53
rule39=0,100,53-1


layer
0,0,0,0,0,0,0,0,0,0,0
0,3,3,3,3,3,3,3,3,3,0
0,3,4,1,1,1,1,1,1,4,1
0,3,1,1,1,5,1,4,1,4,1
0,3,1,1,4,5,5,4,4,3,1
0,3,1,1,4,3,3,3,3,3,1
0,3,1,1,4,3,3,3,3,3,1
6,3,1,5,4,5,5,4,4,3,1
0,3,1,5,5,5,1,4,1,4,1
0,3,4,4,1,1,1,1,4,4,1
0,3,3,3,3,3,3,3,3,4,2
0,0,0,0,0,0,0,0,0,0,0
endlayer

layer
0,0,0,8,0,0,0,0,8,0,0
0,0,0,3,3,3,3,3,3,3,0
0,0,3,0,0,0,0,0,0,3,0
0,3,0,5,5,0,5,1,9,3,0
16,3,5,5,3,3,3,3,3,0,0
16,3,5,14,3,11,7,7,0,7,0
0,3,15,5,3,11,7,7,0,7,0
0,3,5,0,3,3,3,3,3,0,0
0,3,0,0,0,0,5,1,10,3,0
0,0,3,1,13,5,0,0,3,3,0
0,0,0,3,3,3,3,3,3,3,0
0,0,0,0,0,12,0,0,0,0,0
endlayer

layer
0,0,0,0,0,0,8,0,0,0,0
0,0,0,3,3,3,3,3,3,3,0
0,0,3,0,0,0,0,0,0,3,0
0,3,0,0,0,0,0,5,9,3,17
0,3,0,0,3,3,3,3,3,0,0
16,3,0,0,3,0,0,0,0,0,0
0,3,0,0,3,0,0,0,0,0,0
0,3,0,0,3,3,3,3,3,0,0
16,3,0,0,0,0,0,5,10,3,0
0,0,3,18,0,0,0,0,3,3,17
0,0,0,3,3,3,3,3,3,3,0
0,0,0,0,0,12,0,12,0,12,0
endlayer

layer
0,0,0,0,0,0,0,0,0,8,0
0,0,8,3,3,3,3,3,3,3,0
0,0,3,4,0,0,0,0,0,3,0
16,3,0,4,3,3,3,3,3,3,0
0,3,0,4,3,3,3,3,3,0,0
0,3,0,4,3,0,0,19,3,0,0
0,3,0,4,3,0,0,20,3,0,0
0,3,0,4,3,3,3,3,3,17,0
0,3,0,4,3,3,3,3,3,3,0
0,0,3,4,0,0,0,0,3,3,0
0,0,0,3,3,3,3,3,3,3,0
0,0,0,12,0,0,0,0,0,12,0
endlayer

layer
0,0,0,0,8,0,8,0,0,0,0
0,0,0,3,3,3,3,3,0,0,0
0,0,3,25,4,4,4,3,3,17,0
0,3,0,26,21,21,21,21,3,0,0
0,3,0,27,22,22,22,22,18,0,0
0,3,0,28,3,3,3,3,3,17,0
16,3,0,29,3,3,3,3,3,0,0
0,3,0,30,23,23,23,23,18,0,0
0,3,0,31,24,24,24,24,3,0,0
0,0,3,32,4,4,4,3,3,0,0
0,0,12,3,3,3,3,3,0,0,0
0,0,0,0,12,0,12,0,0,0,0
endlayer

layer
0,0,0,0,8,0,0,0,0,0,0
0,0,0,3,3,3,3,3,0,0,0
0,0,3,0,36,35,34,33,3,17,0
0,0,3,3,0,0,0,0,3,0,0
0,0,3,3,3,3,3,3,3,0,0
0,0,3,3,2,2,2,2,3,0,0
0,0,3,3,2,2,2,2,3,0,0
0,0,3,3,3,3,3,3,3,0,0
0,0,3,3,0,0,0,0,3,0,0
0,0,3,0,31,30,29,28,3,0,0
0,0,0,3,3,3,3,3,12,0,0
0,0,0,0,12,0,0,0,0,0,0
endlayer

layer
0,0,0,0,0,0,0,0,0,0,0
0,0,0,0,0,0,8,0,0,0,0
0,0,0,3,3,3,3,3,0,0,0
0,0,0,0,3,3,3,3,17,0,0
0,0,0,0,3,3,3,3,0,0,0
0,0,0,3,37,37,37,37,3,0,0
0,0,0,3,37,37,37,37,3,17,0
0,0,0,0,3,3,3,3,0,0,0
0,0,0,0,3,3,3,3,17,0,0
0,0,0,3,3,3,3,3,0,0,0
0,0,0,0,0,12,12,0,0,0,0
0,0,0,0,0,0,0,0,0,0,0
endlayer

layer
0,0,0,0,0,0,0,0,0,0,0
0,0,0,0,0,0,0,0,0,0,0
0,0,0,0,0,0,0,0,0,0,0
0,0,0,0,0,0,0,0,0,0,0
0,0,0,0,0,0,8,0,0,0,0
0,0,0,0,3,3,3,3,0,0,0
0,0,0,0,3,3,3,3,0,0,0
0,0,0,0,0,12,0,0,0,0,0
0,0,0,0,0,0,0,0,0,0,0
0,0,0,0,0,0,0,0,0,0,0
0,0,0,0,0,0,0,0,0,0,0
0,0,0,0,0,0,0,0,0,0,0
endlayer

layer
0,0,0,0,0,0,0,0,0,0,0
0,0,0,0,0,0,0,0,0,0,0
0,0,0,0,0,0,0,0,0,0,0
0,0,0,0,0,0,0,0,0,0,0
0,0,0,0,0,0,0,0,0,0,0
0,0,0,0,0,38,38,0,0,0,0
0,0,0,0,0,39,39,0,0,0,0
0,0,0,0,0,0,0,0,0,0,0
0,0,0,0,0,0,0,0,0,0,0
0,0,0,0,0,0,0,0,0,0,0
0,0,0,0,0,0,0,0,0,0,0
0,0,0,0,0,0,0,0,0,0,0
endlayer

