weight=1
embed_into_distance=5
acceptable_target_blocks=1,2,3,12,13
dimensions=10,7,7
allowable_overhang=0
max_cut_in=5
cut_in_buffer=0
max_leveling=2
leveling_buffer=1
preserve_water=0
preserve_lava=0
preserve_plants=0

rule1=0,100,4,48
rule2=1,90,4,48
rule3=3,90,4,48
rule4=2,90,43,44
rule5=0,100,43,44
rule6=0,100,MobSpawner:Skeleton
rule7=0,100,MediumChest
layer
1,1,1,1,1,1,1
1,1,1,1,1,1,1
1,1,1,1,1,1,1
1,1,1,1,1,1,1
1,1,1,1,1,1,1
1,1,1,1,1,1,1
1,1,1,1,1,1,1
endlayer

layer
3,3,3,3,3,3,3
3,1,1,1,1,1,3
3,0,0,0,0,0,3
3,0,0,0,0,0,3
3,7,0,0,0,7,3
3,0,0,6,0,0,3
3,3,3,3,3,3,3
endlayer

layer
3,3,3,3,3,3,3
3,0,1,1,1,0,3
3,0,0,0,0,0,3
3,0,0,0,0,0,3
3,0,0,0,0,0,3
3,0,0,0,0,0,3
3,3,3,3,3,3,3
endlayer
layer
3,3,3,3,3,3,3
3,0,0,1,0,0,3
3,0,0,0,0,0,3
3,0,0,0,0,0,3
3,0,0,0,0,0,3
3,0,0,0,0,0,3
3,3,3,3,3,3,3
endlayer
layer
1,1,1,1,1,1,1
1,0,0,0,0,0,1
1,5,5,5,5,5,1
1,5,5,5,5,5,1
1,5,5,5,5,5,1
1,1,1,1,1,1,1
1,1,1,1,1,1,1
endlayer

layer
2,2,2,2,2,2,2
2,0,0,0,0,0,2
2,0,0,0,0,0,2
0,0,0,0,0,0,0
2,0,0,0,0,0,2
2,1,1,1,1,1,2
2,2,2,2,2,2,2
endlayer
layer
2,2,2,2,2,2,2
2,0,0,0,0,0,2
2,0,0,0,0,0,2
0,0,0,0,0,0,0
2,0,0,0,0,0,2
2,0,1,1,1,0,2
2,2,2,2,2,2,2
endlayer

layer
2,2,2,1,2,2,2
2,0,0,0,0,0,2
2,0,0,0,0,0,2
1,0,0,0,0,0,1
2,0,0,0,0,0,2
2,0,0,1,0,0,2
2,2,2,1,2,2,2
endlayer

layer
1,1,1,1,1,1,1
1,4,4,4,4,4,1
1,4,4,4,4,4,1
1,4,4,4,4,4,1
1,4,4,4,4,4,1
1,0,0,0,0,0,1
1,1,1,1,1,1,1
endlayer
layer
2,2,2,2,2,2,2
2,0,0,0,0,0,2
2,0,0,0,0,0,2
2,0,0,0,0,0,2
2,0,0,0,0,0,2
2,0,0,0,0,0,2
2,2,2,2,2,2,2
endlayer